File: Projekt_andmed1/1732_200xFe+100xCo+Oat350C_32nm_VSM_Hys300K_5T_14012023.DAT
[Header]
; VSM Data File (default extension .dat)
; Copyright (c) 2003-2013, Quantum Design, Inc. All rights reserved.
TITLE,1732_200xFe+100xCo+Oat350C_32nm_VSM_Hys300K_5T_14012023
FILEOPENTIME,12648573.69,01/14/2023,11:08 am
BYAPP,VSM,2.0,2.0
INFO,PPMS VSM Option Release 1.4.10 Build 1,APPNAME
INFO,Quantum Design Linear Motor Servo Controller,MOTOR_MODULE_NAME
INFO,3101-100 C1,MOTOR_HW_VERSION
INFO,074,MOTOR_SERIAL_NUMBER
INFO,SRV No X-over 01.01.11,MOTOR_SOFTWARE_VERSION
INFO,Quantum Design VSM Detection Module,VSM_MODULE_NAME
INFO,3101-150 E1,VSM_HW_VERSION
INFO,VSM061,VSM_SERIAL_NUMBER
INFO,VSM No X-over 01.02.05 May 20 2008 13:51:47,VSM_SOFTWARE_VERSION
INFO,113,PREAMP_SERIAL_NUMBER
INFO,Quantum Design VSM Oven,OVEN_MODULE_NAME
INFO,3101-200 B0,OVEN_HW_VERSION
INFO,OVN054,OVEN_SERIAL_NUMBER
INFO,01.01.00,OVEN_SOFTWARE_VERSION
INFO,221,COIL_SERIAL_NUMBER
INFO,0,MOMENT_UNITS
INFO,1732_200xFe+100xCo+Oat350C_32nm_VSM_Hys300K_5T_14012023,SAMPLE_MATERIAL
INFO,thin film Fe&FeCo ratio 0.53,SAMPLE_COMMENT
INFO,9.5,SAMPLE_MASS
INFO,,SAMPLE_VOLUME
INFO,,SAMPLE_MOLECULAR_WEIGHT
INFO,8.39 mm2,SAMPLE_SIZE
INFO,,SAMPLE_SHAPE
DATATYPE,COMMENT,1
DATATYPE,TIME,2
STARTUPAXIS,X,2
STARTUPAXIS,Y1,5
[Data]
Comment,Time Stamp (sec),Temperature (K),Magnetic Field (Oe),Moment (emu),M. Std. Err. (emu),Transport Action,Averaging Time (sec),Frequency (Hz),Peak Amplitude (mm),Center Position (mm),Coil Signal' (mV),Coil Signal" (mV),Range (mV),M. Quad. Signal (emu),M. Raw' (emu),M. Raw" (emu),Min. Temperature (K),Max. Temperature (K),Min. Field (Oe),Max. Field (Oe),Mass (grams),Motor Lag (deg),Pressure (Torr),VSM Status (code),Motor Status (code),Measure Status (code),Measure Count,PPMS Status (code),System Temp. (K),System Field (Oe),Sample Position (deg),Bridge 1 Resistance (ohms),Bridge 1 Excitation (에),Bridge 2 Resistance (ohms),Bridge 2 Excitation (에),Bridge 3 Resistance (ohms),Bridge 3 Excitation (에),Bridge 4 Resistance (ohms),Bridge 4 Excitation (에),Signal 1 Vin (V),Signal 2 Vin (V),Digital Inputs (code),Drive 1 Iout (mA),Drive 1 Ipower (W),Drive 2 Iout (mA),Drive 2 Ipower (W),Pressure (),Map 20 (),Map 21 (),Map 22 (),Map 23 (),Map 24 (),Map 25 (),Map 26 (),Map 27 (),Map 28 (),Map 29 ()
,12649797.605,300.00646975,50004.8225,5.13148696206114E-5,5.78773823896648E-7,1,60.005163911891,40.0298881530762,1.99389501445966,5.16000017523766,0.000528119334090351,0.000215522857488993,0.25,1.12892636813162E-5,5.13059326003072E-5,1.13226686168224E-5,300.0037537,300.0091858,50004.711,50004.934,52.9756545193902,18.4982179314084,35.926437,0,0,0,2402,4929,300.0026,50004.8225,,,,,,,,,,,,,0,,,,5.28534935,,,,,,300.00646975,,,,
,12650875.225,299.99681095,34998.6485,7.03306542846985E-5,4.68294900127485E-7,1,60.005163911891,40.0298881530762,1.99376819564616,5.16000017523766,0.000736244220243702,0.000223159685179493,0.25,8.72213483916971E-6,7.03228326510584E-5,8.76827342529944E-6,299.9957886,299.9978333,34997.918,34999.379,52.9959768608902,18.5085281590102,35.926437,0,0,0,2402,4929,300.03085,34998.6485,,,,,,,,,,,,,0,,,,5.31161665,,,,,,299.99681095,,,,
,12651955.38,299.996933,20001.102,8.47138999769964E-5,2.633494902718E-7,1,60.005163911891,40.0298881530762,1.99393691287373,5.16000017523766,0.000897392021923706,0.00020794192882596,0.25,4.8152449074355E-6,8.47082072274282E-5,4.87115713223848E-6,299.99646,299.997406,20000.688,20001.516,52.6622214831786,18.5138806845305,35.926437,0,0,0,2402,4929,300.05625,20001.102,,,,,,,,,,,,,0,,,,5.4732127,,,,,,299.996933,,,,
,12653247.535,299.9996643,4999.7375,7.72299133042613E-5,8.22603480883062E-8,1,60.005163911891,40.0298881530762,1.99394934885774,5.16000017523766,0.000824912595599613,0.000148727966310015,2.5,5.75991473849386E-7,7.72272272586139E-5,6.27210670958094E-7,299.9996643,299.9996643,4999.725,4999.75,52.6794173106017,18.5180110742958,35.926437,0,0,0,2402,4929,300.0745,4999.7375,,,,,,,,,,,,,0,,,,5.5005507,,,,,,299.9996643,,,,
,12655107.79,300.0023499,-10000.1735,-7.50140898550272E-5,1.21501640902274E-7,1,60.005163911891,40.0298881530762,1.99402883561715,5.16000017523766,-0.000793581329615374,-0.00018904273957446,2.5,-4.72730614984208E-6,-7.50087153913636E-5,-4.77689179108522E-6,300.0023499,300.0023499,-10000.188,-10000.159,52.8138574159094,18.5206236497766,35.926437,0,0,0,2402,4929,300.069,-10000.1735,,,,,,,,,,,,,0,,,,5.3381476,,,,,,300.0023499,,,,
,12656455.79,299.9991913,-25002.8625,-7.6438633172886E-5,2.89990088961603E-7,1,60.005163911891,40.0298881530762,1.9941384484393,5.16000017523766,-0.000803105897724382,-0.000226482425701533,0.25,-7.97463601737201E-6,-7.64310992590478E-5,-8.02492703941118E-6,299.9967041,300.0016785,-25002.969,-25002.756,52.6989580235825,18.5225631468687,35.545227,0,0,0,2402,4929,300.05905,-25002.8625,,,,,,,,,,,,,0,,,,5.0942857,,,,,,299.9991913,,,,
,12657595.895,300.0032654,-40001.084,-5.96676461410578E-5,4.68733405981156E-7,1,60.005163911891,40.0298881530762,1.99436670073978,5.16000017523766,-0.000615520459397677,-0.000243144871960961,0.25,-1.24243303809298E-5,-5.96576965472135E-5,-1.24632802092007E-5,299.9995728,300.006958,-40001.418,-40000.75,52.1291508330632,18.5312452739474,35.926437,0,0,0,2402,4929,300.0303,-40001.084,,,,,,,,,,,,,0,,,,5.5005507,,,,,,300.0032654,,,,
,12658675.98,300.0029602,-44998.553,-5.34961822759545E-5,8.07237351255795E-7,1,60.005163911891,40.0298881530762,1.99414940372929,5.1699997857213,-0.000547629382217512,-0.000242132427669502,0.25,-1.33973116691579E-5,-5.34857874496193E-5,-1.34321288031878E-5,300.0022583,300.0036621,-45000.379,-44996.727,52.5520118619671,18.5287954653528,35.164013,0,0,0,2402,4929,300.0151,-44998.553,,,,,,,,,,,,,0,,,,5.5281634,,,,,,300.0029602,,,,
,12659756.11,299.99617005,-30000.6425,-7.16311493410242E-5,3.77562293677633E-7,1,60.005163911891,40.0298881530762,1.99416555157547,5.16000017523766,-0.000747784274844483,-0.00024017554645524,0.25,-1.00839951858638E-5,-7.16223809659959E-5,-1.01310015362275E-5,299.995697,299.9966431,-30000.691,-30000.594,52.7270966502748,18.5253292988243,35.926437,0,0,0,2402,4929,300.03755,-30000.6425,,,,,,,,,,,,,0,,,,5.3654802,,,,,,299.99617005,,,,
,12660836.19,299.99760435,-14998.4495,-8.33887075669089E-5,1.98193959408266E-7,1,60.005163911891,40.0298881530762,1.99413059113077,5.16000017523766,-0.000881234070287703,-0.000217466416798942,0.25,-5.93232538532311E-6,-8.33823047316683E-5,-5.98737893901997E-6,299.9961853,299.9990234,-14999.161,-14997.738,53.0037931460825,18.5197327380718,36.307648,0,0,0,2402,4929,300.064,-14998.4495,,,,,,,,,,,,,0,,,,5.043648,,,,,,299.99760435,,,,
,12662368.62,300.0010071,0.175,-4.21514192434576E-5,5.40712808487322E-8,1,60.005163911891,40.0298881530762,1.99414900185629,5.16000017523766,-0.000446811882795579,-0.000101236603147623,2.5,-2.18928613573581E-6,-4.2148705057061E-5,-2.21720245962164E-6,300.0010071,300.0010071,0.118,0.232,52.5098039219286,18.529019689659,35.926437,0,0,0,2402,4929,300.0759,0.175,,,,,,,,,,,,,0,,,,5.2916801,,,,,,300.0010071,,,,
,12664228.23,300.0013123,14999.087,8.56648995364529E-5,1.79052354273477E-7,1,60.005163911891,40.0298881530762,1.99404744072116,5.16000017523766,0.000910800528443736,0.00018961162033708,2.5,2.94200785743812E-6,8.56603997712265E-5,2.99865512694442E-6,300.0013123,300.0013123,14998.799,14999.375,52.8419960426017,18.5150369288581,35.164013,0,0,0,2402,4929,300.0738,14999.087,,,,,,,,,,,,,0,,,,5.2916801,,,,,,300.0013123,,,,
,12665336.72,300.0028992,30002.8135,7.75028192914521E-5,3.85570650529982E-7,1,60.005163911891,40.0298881530762,1.99404435874373,5.16000017523766,0.000817698846429771,0.000209643434912769,0.25,6.21803994133581E-6,7.74964146072224E-5,6.2690340923605E-6,300.0006409,300.0051575,30002.574,30003.053,53.4954374846787,18.5250602071655,35.164013,0,0,0,2402,4929,300.0483,30002.8135,,,,,,,,,,,,,0,,,,5.5557761,,,,,,300.0028992,,,,
,12666416.735,300.00279235,45001.879,6.05042958857085E-5,5.1432075184522E-7,1,60.005163911891,40.0298881530762,1.99384073031168,5.16000017523766,0.000636740341120944,0.000172639300482982,0.25,5.69498129032601E-6,6.04987646771696E-5,5.73463808955847E-6,300.0012817,300.004303,45001.406,45002.352,53.0624152850248,18.5207075625739,35.164013,0,0,0,2402,4929,300.01615,45001.879,,,,,,,,,,,,,0,,,,5.5008254,,,,,,300.00279235,,,,
,12674697.555,5.000016,91995.336,1.12683203653939E-5,2.40046830702831E-7,1,60.005163911891,40.0298881530762,1.99336320310719,6.70999987050891,0.000115440543305665,5.03419487091958E-5,0.25,2.68563176387596E-6,1.12681740543536E-5,2.76903758025366E-6,4.9998007,5.0002313,91993.469,91997.203,53.6783385581788,18.507874019595,35.926437,0,0,0,2402,4929,5.0205,91995.336,,,,,,,,,,,,,0,,,,1.29242105,,,,,,5.000016,,,,
,12676317.695,4.99988415,67994.5585,4.651590761875E-5,3.67486156246734E-7,1,60.005163911891,40.0298881530762,1.99344098230957,6.70999987050891,0.000486429943275142,0.000147431067363496,0.25,5.4495705927284E-6,4.64688478603312E-5,5.79325712802148E-6,4.9991179,5.0006504,67993.984,67995.133,53.3055017545056,18.5114109752759,35.926437,0,0,0,2402,4929,4.99905,67994.5585,,,,,,,,,,,,,0,,,,1.14641415,,,,,,4.99988415,,,,
,12677877.87,5.0004094,43997.643,7.46883088912708E-5,2.48857497553571E-7,1,60.005163911891,40.0298881530762,1.99358866186986,6.70999987050891,0.00078908034331849,0.000181635887787245,0.25,3.6411113432094E-6,7.44778839727995E-5,4.1742435120841E-6,5.0003529,5.0004659,43995.977,43999.309,53.516541454698,18.5245038826543,35.926437,0,0,0,2402,4929,4.98645,43997.643,,,,,,,,,,,,,0,,,,0.92969505,,,,,,5.0004094,,,,
,12679317.97,4.9999778,19999.254,9.30562227389453E-5,7.33249677577667E-8,1,60.005163911891,40.0298881530762,1.99350385320706,6.71999994665384,0.000989932094125518,0.000173868577944204,0.25,-2.43538698327196E-7,9.25962809538368E-5,3.33896197565739E-7,4.9995112,5.0004444,19999.242,19999.266,53.0639785420633,18.5277543052663,36.307648,0,0,0,2402,4929,4.9772,19999.254,,,,,,,,,,,,,0,,,,1.0797179,,,,,,4.9999778,,,,
,12680913.135,5.0001364,-3999.8835,6.41741981848511E-5,2.9068845119706E-8,1,60.005163911891,40.0298881530762,1.99366572393939,6.70999987050891,0.000684375873150414,0.000105296314493816,0.25,-1.45589247316105E-6,6.37775200311922E-5,-1.12242691189072E-6,5.0001364,5.0001364,-3999.896,-3999.871,53.7275811548903,18.5214945826148,35.164013,0,0,0,2402,4929,4.98075,-3999.8835,,,,,,,,,,,,,0,,,,1.0852463,,,,,,5.0001364,,,,
,12682378.25,4.99975635,-28000.2255,-6.09845251355583E-5,1.0409112848865E-7,1,60.005163911891,40.0298881530762,1.99339831937805,6.70999987050891,-0.000643781460034404,-0.000144613481466557,0.25,-2.68619890759611E-6,-6.07134851488998E-5,-3.081171461311E-6,4.9988327,5.00068,-28001.92,-27998.531,52.7966615884864,18.5310385092127,35.164013,0,0,0,2402,4929,4.9776,-28000.2255,,,,,,,,,,,,,0,,,,1.095814,,,,,,4.99975635,,,,
,12683758.41,4.99870325,-52003.4885,-5.71887541261098E-5,2.92903870501508E-7,1,60.005163911891,40.0298881530762,1.99329612053036,6.70999987050891,-0.000612663428298247,-9.43026126996139E-5,0.25,1.42659323992383E-6,-5.71053600951682E-5,1.00137875113166E-6,4.9983616,4.9990449,-52004.5,-52002.477,52.5676444323517,18.5297138815685,35.164013,0,0,0,2402,4929,4.98755,-52003.4885,,,,,,,,,,,,,0,,,,1.0849214,,,,,,4.99870325,,,,
,12685378.61,4.997829,-76002.75,-2.74402681579241E-5,4.69062177357407E-7,1,60.005163911891,40.0298881530762,1.99341284908613,6.70999987050891,-0.000313307736230919,5.87881227606102E-5,0.25,1.04241665244898E-5,-2.75307252612847E-5,1.02288947242809E-5,4.9974666,4.9981914,-76003.164,-76002.336,52.6270481998133,18.5372534098273,35.164013,0,0,0,2402,4929,5.00665,-76002.75,,,,,,,,,,,,,0,,,,1.0116459,,,,,,4.997829,,,,
,12687058.72,4.9991035,-100001.082,9.55148982771518E-6,6.7663739624864E-7,1,60.005163911891,40.0298881530762,1.99351144693664,6.70999987050891,5.97555963987746E-5,0.000255934837798492,0.25,2.21924991239073E-5,9.4206705173592E-6,2.23050865528388E-5,4.9988441,4.9993629,-100001.219,-100000.945,52.4386757266786,18.5366519026921,35.926437,0,0,0,2402,4929,5.0283,-100001.082,,,,,,,,,,,,,0,,,,0.9386544,,,,,,4.9991035,,,,
,12688678.9,4.99993775,-75992.844,-2.84854541422421E-5,4.2033455278565E-7,1,60.005163911891,40.0298881530762,1.99342983745898,6.70999987050891,-0.000330600214217854,9.08751442630316E-5,0.25,1.36135193371528E-5,-2.85997569718797E-5,1.34122423397746E-5,4.9995117,5.0003638,-75993.602,-75992.086,52.5543567475248,18.5367373295056,35.164013,0,0,0,2402,4929,5.00695,-75992.844,,,,,,,,,,,,,0,,,,0.9386544,,,,,,4.99993775,,,,
,12690119.015,5.00129985,-51997.203,-6.25059590862581E-5,3.11474429132085E-7,1,60.005163911891,40.0298881530762,1.99329271081841,6.70999987050891,-0.000673052332199547,-8.39834327787294E-5,0.25,3.34886656012684E-6,-6.24280048607276E-5,2.88117953567619E-6,5.000699,5.0019007,-51997.23,-51997.176,53.0616336565056,18.5280951704676,36.307648,0,0,0,2402,4929,4.9931,-51997.203,,,,,,,,,,,,,0,,,,0.81212695,,,,,,5.00129985,,,,
,12691559.16,5.00019315,-27998.3975,-8.61239583976248E-5,9.82628498202808E-8,1,60.005163911891,40.0298881530762,1.9932957886127,6.70999987050891,-0.000911882770791427,-0.000188767278297806,0.25,-2.34146651826709E-6,-8.57508422924014E-5,-2.90527620215101E-6,4.9993587,5.0010276,-27999.066,-27997.729,53.0374031724095,18.5288551590297,35.164013,0,0,0,2402,4929,4.97935,-27998.3975,,,,,,,,,,,,,0,,,,0.92969505,,,,,,5.00019315,,,,
,12692999.285,4.99890755,-3999.7375,-8.40602047632196E-5,3.05847792398052E-8,1,60.005163911891,40.0298881530762,1.99332413539046,6.70999987050891,-0.000888085103274298,-0.000184270320273501,0.25,-2.45909644187457E-6,-8.35185411397516E-5,-2.8684050954991E-6,4.9981217,4.9996934,-3999.785,-3999.69,53.4985639987557,18.5212461071547,36.307648,0,0,0,2402,4929,4.9803,-3999.7375,,,,,,,,,,,,,0,,,,0.99163405,,,,,,4.99890755,,,,
,12694739.5,4.9998562,20001.495,5.25196577525337E-5,7.94202903722169E-8,1,60.005163911891,40.0298881530762,1.99304802263477,6.70999987050891,0.000557885123419042,0.000102013321187393,0.25,2.29948377511778E-7,5.2257809288227E-5,5.54030518146134E-7,4.9996347,5.0000777,20001.242,20001.748,52.4730673815248,18.5223439459996,35.926437,0,0,0,2402,4929,4.97855,20001.495,,,,,,,,,,,,,0,,,,1.0066431,,,,,,4.9998562,,,,
,12696179.65,4.99861525,44001.287,7.15709251041857E-5,3.92777621835158E-7,1,60.005163911891,40.0298881530762,1.99326909408746,6.70999987050891,0.000743474019612659,0.000244003632483641,0.25,1.00555654287783E-5,7.13216490508957E-5,1.0550278751213E-5,4.9984808,4.9987497,44000.742,44001.832,52.8662265266979,18.5264253691738,35.926437,0,0,0,2402,4929,4.98365,44001.287,,,,,,,,,,,,,0,,,,0.967356,,,,,,4.99861525,,,,
,12697619.75,4.9980614,68001.473,4.92100263749005E-5,8.89837161091427E-7,1,60.005163911891,40.0298881530762,1.9931254834909,6.70999987050891,0.000480003241118951,0.000348208473518769,0.25,2.3766639815145E-5,4.90269628128938E-5,2.41276494465862E-5,4.9979982,4.9981246,68001.391,68001.555,53.0889906546787,18.520047495665,35.926437,0,0,0,2402,4929,4.9999,68001.473,,,,,,,,,,,,,0,,,,1.02180275,,,,,,4.9980614,,,,
,12699239.885,4.9977024,92004.125,1.4413548900348E-5,6.75304150228881E-7,1,60.005163911891,40.0298881530762,1.99302302667931,6.70999987050891,9.89894244888949E-5,0.000335963663118899,0.25,2.88170029817367E-5,1.42355287709097E-5,2.89657599374798E-5,4.9974933,4.9979115,92003.781,92004.469,53.2984670978326,18.5167893028796,35.164013,0,0,0,2402,4929,5.02265,92004.125,,,,,,,,,,,,,0,,,,0.8930546,,,,,,4.9977024,,,,
,12742952.625,7.31012725,999.795,2.43475906615045E-5,3.89196541294754E-8,1,30.0025819559455,40.0298881530762,1.98185441533191,6.70999987050891,0.000259674542044639,3.09782224558054E-5,0.25,-1.37505743745706E-6,2.41967919758273E-5,-1.24778185494662E-6,6.8160639,7.8041906,999.795,999.795,52.1479099175247,18.5051647674571,35.164013,0,0,0,1201,4882,7.37595,999.795,,,,,,,,,,,,,0,,,,1.96617755,,,,,,7.31012725,,,,
,12743132.59,13.278635,999.795,2.44994034312834E-5,3.89787612598093E-8,1,30.0025819559455,40.0298881530762,1.98206935007687,6.70999987050891,0.000261489434159982,3.02089848847343E-5,0.25,-1.47504187472147E-6,2.43478962826115E-5,-1.34636968123479E-6,12.7795906,13.7776794,999.795,999.795,52.8130757873902,18.5136291683671,35.926437,0,0,0,1201,4882,13.4109,999.795,,,,,,,,,,,,,0,,,,2.58732975,,,,,,13.278635,,,,
,12743402.675,22.2253075,999.795,2.54820919838197E-5,3.76963393283599E-8,1,30.0025819559455,40.0298881530762,1.98197180821402,6.50000013411045,0.00027185284058977,3.2162896048505E-5,0.25,-1.46663589028137E-6,2.53259309182244E-5,-1.33070967828464E-6,21.7295132,22.7211018,999.795,999.795,52.4918264659863,18.5087132649089,35.926437,0,0,0,1201,4882,22.47445,999.795,,,,,,,,,,,,,0,,,,3.05230045,,,,,,22.2253075,,,,
touchdown = 1.36999995447695 mm,12743692.105,31.7569914,999.795,2.58427191780508E-5,3.68994101214968E-8,1,30.0025819559455,40.0298881530762,1.992972773868,6.51999982073903,0.000277320636480008,3.32613134290477E-5,0.25,-1.46624342283959E-6,2.5705474895184E-5,-1.30927467247773E-6,31.7407875,31.7731953,999.795,999.795,52.9256302941594,18.5083407742077,35.926437,0,0,0,1201,4882,32.22155,999.795,,,,,,,,,,,,,0,,,,3.4053066,,,,,,31.7569914,,,,
,12743852.65,37.05117035,999.795,2.6053072325587E-5,4.87793622590374E-8,1,30.0025819559455,40.0298881530762,1.99297258701883,6.51999982073903,0.000279775708718368,3.39848243888127E-5,0.25,-1.45610496262785E-6,2.59397426114126E-5,-1.28189905879782E-6,36.558075,37.5442657,999.795,999.795,52.013469812217,18.5007983775057,35.926437,0,0,0,1201,4882,37.6217,999.795,,,,,,,,,,,,,0,,,,3.5797191,,,,,,37.05117035,,,,
,12744122.675,45.88448715,999.795,2.62197878188661E-5,3.67363882218451E-8,1,30.0025819559455,40.0298881530762,1.9929919959484,6.5399999730289,0.000282181130154424,3.48069010462967E-5,0.25,-1.44031503732286E-6,2.61707932024662E-5,-1.24478476047065E-6,45.3789101,46.3900642,999.795,999.795,52.9357914649095,18.4967737878844,36.307648,0,0,0,1201,4886,46.7681,999.795,,,,,,,,,,,,,0,,,,3.72584485,,,,,,45.88448715,,,,
,12744392.69,54.7195015,999.795,2.65511373758934E-5,3.86806528868391E-8,1,30.0025819559455,40.0298881530762,1.98205794384,6.51999982073903,0.000285103473870252,3.48014203847223E-5,0.25,-1.48944728643315E-6,2.6576065891346E-5,-1.29774540282873E-6,54.2296829,55.2093201,999.795,999.795,52.6067258583133,18.5082267664293,36.307648,0,0,0,1201,4886,55.9197,999.795,,,,,,,,,,,,,0,,,,3.7647544,,,,,,54.7195015,,,,
touchdown = 1.3899999903515 mm,12744676.46,63.977829,999.795,2.67384714988443E-5,3.94147343538838E-8,1,30.0025819559455,40.0298881530762,1.99307178668402,6.5399999730289,0.000289460704549867,3.42526632550674E-5,0.25,-1.57211236951401E-6,2.68222307298166E-5,-1.40872719043267E-6,63.977829,63.977829,999.795,999.795,53.0577255139095,18.5132696012248,36.688858,0,0,0,1201,4886,65.5484,999.795,,,,,,,,,,,,,0,,,,3.9957154,,,,,,63.977829,,,,
,12744812.75,68.4207993,999.795,2.70041633314663E-5,3.91312917502624E-8,1,30.0025819559455,40.0298881530762,1.99296049433112,6.5399999730289,0.000292364593737658,3.54818104353625E-5,0.25,-1.49149507190365E-6,2.71065912192152E-5,-1.34251266880182E-6,67.9501038,68.8914948,999.795,999.795,53.3140996682172,18.5085601465753,35.926437,0,0,0,1201,4886,70.1732,999.795,,,,,,,,,,,,,0,,,,3.79555025,,,,,,68.4207993,,,,
,12745082.83,77.26600265,999.795,2.74192643075005E-5,3.93615770133422E-8,1,30.0025819559455,40.0298881530762,1.99287166516147,6.51999982073903,0.000297253670451641,3.51324158101581E-5,0.25,-1.57212418212497E-6,2.75463402114473E-5,-1.45064468781946E-6,76.7752762,77.7567291,999.795,999.795,53.5743819651211,18.5073874922168,35.164013,0,0,0,1201,4886,79.33125,999.795,,,,,,,,,,,,,0,,,,4.13774015,,,,,,77.26600265,,,,
,12745390.695,87.35396575,999.795,2.77937911170995E-5,4.18622234948689E-8,1,30.0025819559455,40.0298881530762,1.98207680848919,6.51999982073903,0.000299920791015195,3.51653880375441E-5,0.25,-1.59405198602353E-6,2.79343374655665E-5,-1.49708019042381E-6,87.1264572,87.5814743,999.795,999.795,52.7661780762363,18.5123086834097,35.545227,0,0,0,1201,4886,89.74315,999.795,,,,,,,,,,,,,0,,,,4.2216637,,,,,,87.35396575,,,,
touchdown = 1.3399999588728 mm,12745707.995,97.77251055,999.795,2.84011204599392E-5,4.10167347501546E-8,1,30.0025819559455,40.0298881530762,1.98221930407543,6.49000005796552,0.000306449579637807,3.64347721204415E-5,0.25,-1.56326396209516E-6,2.85483612357087E-5,-1.48356223532289E-6,97.7578888,97.7871323,999.795,999.795,52.8498123277941,18.5068652943361,36.307648,0,0,0,1201,4886,100.4471,999.795,,,,,,,,,,,,,0,,,,3.7630644,,,,,,97.77251055,,,,
,12745864.11,102.8944244,999.795,,,2,,,,6.46999996326864,,,,,,,102.8944244,102.8944244,999.795,999.795,,,35.926437,,,,-99999999,4886,105.7629,999.795,,,,,,,,,,,,,,,,,,,,,,,102.8944244,,,,
,12746102.86,110.817112,999.795,2.93717441747084E-5,4.18104392252031E-8,1,30.0025819559455,40.0298881530762,1.99303078495052,6.45999982953072,0.00031853714254857,3.8052913447089E-5,0.25,-1.58251537035024E-6,2.95227305713469E-5,-1.51761106727049E-6,110.315239,111.318985,999.795,999.795,52.5692076893902,18.5073741227734,35.926437,0,0,0,1201,4886,113.89005,999.795,,,,,,,,,,,,,0,,,,4.2849197,,,,,,110.817112,,,,
,12746342.865,118.77952195,999.795,2.99715149773596E-5,4.2710045986501E-8,1,30.0025819559455,40.0298881530762,1.9821792623329,6.4300000667572,0.000323101320766247,3.98422381977021E-5,0.25,-1.49275654194599E-6,3.01226033044024E-5,-1.43386632373788E-6,118.2679596,119.2910843,999.795,999.795,53.2179593603518,18.5008011671634,35.545227,0,0,0,1201,4886,122.01115,999.795,,,,,,,,,,,,,0,,,,4.4824438,,,,,,118.77952195,,,,
,12746524.22,124.7978897,999.795,,,2,,,,6.40999997206033,,,,,,,124.7978897,124.7978897,999.795,999.795,,,36.307648,,,,-99999999,4886,128.1668,999.795,,,,,,,,,,,,,,,,,,,,,,,124.7978897,,,,
,12746762.89,132.76906585,999.795,3.06722583381799E-5,4.43459536876721E-8,1,30.0025819559455,40.0298881530762,1.98198708668861,6.3999998383224,0.000330575408790359,4.06122751341706E-5,0.25,-1.53064742754904E-6,3.08198988812167E-5,-1.48101370333502E-6,132.2710419,133.2670898,999.795,999.795,53.1397965084287,18.503257885238,35.926437,0,0,0,1201,4886,136.23445,999.795,,,,,,,,,,,,,0,,,,4.37924695,,,,,,132.76906585,,,,
,12747002.93,140.7615509,999.795,3.11214132608424E-5,4.58373604298024E-8,1,30.0025819559455,40.0298881530762,1.98190169939884,6.34999992325902,0.00033527918421011,4.16032916441773E-5,0.25,-1.51034737509722E-6,3.12662152982629E-5,-1.46442672276625E-6,140.2452698,141.277832,999.795,999.795,52.7771208755056,18.5022669211988,36.307648,0,0,0,1201,4886,144.3452,999.795,,,,,,,,,,,,,0,,,,4.6183531,,,,,,140.7615509,,,,
,12747184.58,146.7854919,999.795,,,2,,,,6.31999998524785,,,,,,,146.7854919,146.7854919,999.795,999.795,,,36.307648,,,,-99999999,4886,150.4993,999.795,,,,,,,,,,,,,,,,,,,,,,,146.7854919,,,,
,12747423.01,154.7496719,999.795,3.18305743622351E-5,4.73383459727991E-8,1,30.0025819559455,40.0298881530762,1.99311261247177,6.31000008434057,0.000344568405131093,4.33754670381228E-5,0.25,-1.48142330490229E-6,3.19686562831014E-5,-1.44061364339574E-6,154.2524261,155.2469177,999.795,999.795,52.5027692652556,18.5096078658613,36.307648,0,0,0,1201,4886,158.4918,999.795,,,,,,,,,,,,,0,,,,4.7350883,,,,,,154.7496719,,,,
,12747663.02,162.7055969,999.795,3.22949091978385E-5,4.71384780685481E-8,1,30.0025819559455,40.0298881530762,1.99310905470178,6.26999977976084,0.000349453518944756,4.44240156795039E-5,0.25,-1.46032061827899E-6,3.24287166311799E-5,-1.42166423580453E-6,162.2046661,163.2065277,999.795,999.795,53.2156144747941,18.5145371290203,36.307648,0,0,0,1201,4886,166.54265,999.795,,,,,,,,,,,,,0,,,,4.6211188,,,,,,162.7055969,,,,
,12747844.45,168.6924438,999.795,,,2,,,,6.23999995816499,,,,,,,168.6924438,168.6924438,999.795,999.795,,,35.926437,,,,-99999999,4886,172.6312,999.795,,,,,,,,,,,,,,,,,,,,,,,168.6924438,,,,
,12748083.055,176.6490326,999.795,3.29153496490563E-5,5.02117437136412E-8,1,30.0025819559455,40.0298881530762,1.98202215868741,6.22999994084239,0.000354241624847503,4.44232322754211E-5,0.25,-1.53954235893935E-6,3.30399460997594E-5,-1.50452480717144E-6,176.1478424,177.1502228,999.795,999.795,52.8107309018325,18.5145366193109,35.926437,0,0,0,1201,4886,180.61515,999.795,,,,,,,,,,,,,0,,,,4.43313815,,,,,,176.6490326,,,,
,12748323.07,184.6096115,999.795,3.33620288208189E-5,5.02465912719993E-8,1,30.0025819559455,40.0298881530762,1.99278904248071,6.18000002577901,0.000360760229976238,4.57289031815544E-5,0.25,-1.51362330764957E-6,3.34810506528571E-5,-1.4799207936604E-6,184.1049347,185.1142883,999.795,999.795,52.9389179789864,18.5097169934424,35.926437,0,0,0,1201,4886,188.6652,999.795,,,,,,,,,,,,,0,,,,4.8791447,,,,,,184.6096115,,,,
,12748504.75,190.6349182,999.795,,,2,,,,6.14000001162291,,,,,,,190.6349182,190.6349182,999.795,999.795,,,36.307648,,,,-99999999,4886,194.7492,999.795,,,,,,,,,,,,,,,,,,,,,,,190.6349182,,,,
,12748743.085,198.5647354,999.795,3.40958987580682E-5,5.4421892415584E-8,1,30.0025819559455,40.0298881530762,1.98209355022311,6.14000018686056,0.000366498159075604,4.73670344684803E-5,0.25,-1.45992673994239E-6,3.42040061098919E-5,-1.42808984684336E-6,198.0709381,199.0585327,999.795,999.795,52.514493693044,18.5127989421361,35.164013,0,0,0,1201,4886,202.7172,999.795,,,,,,,,,,,,,0,,,,4.55778265,,,,,,198.5647354,,,,
,12748983.145,206.5435791,999.795,3.4529167901702E-5,5.35406334031099E-8,1,30.0025819559455,40.0298881530762,2.00677093804419,6.07000011950731,0.00037560350328087,4.79349095912929E-5,0.25,-1.53192186710671E-6,3.46306649364E-5,-1.5012351716437E-6,206.0484314,207.0387268,999.795,999.795,52.6864519672748,18.517876993973,35.926437,0,0,0,1201,4886,210.7586,999.795,,,,,,,,,,,,,0,,,,4.92837695,,,,,,206.5435791,,,,
,12749165.39,212.5628357,999.795,,,2,,,,6.04000000687316,,,,,,,212.5628357,212.5628357,999.795,999.795,,,36.307648,,,,-99999999,4886,216.8556,999.795,,,,,,,,,,,,,,,,,,,,,,,212.5628357,,,,
,12749403.175,220.5039444,999.795,3.51360183414822E-5,5.68732412437802E-8,1,30.0025819559455,40.0298881530762,1.99270697301332,6.02999981492758,0.000379305454808222,4.94205504798609E-5,0.25,-1.46365799214889E-6,3.52245066535965E-5,-1.43426265770609E-6,220.0045166,221.0033722,999.795,999.795,52.8474674422364,18.5071273813831,35.164013,0,0,0,1201,4886,224.79875,999.795,,,,,,,,,,,,,0,,,,4.9778576,,,,,,220.5039444,,,,
,12749643.175,228.4921112,999.795,3.55396992863248E-5,5.57025939825874E-8,1,30.0025819559455,40.0298881530762,1.99270178086927,5.96999982371926,0.000383657116277585,4.94646683109494E-5,0.25,-1.52681313810995E-6,3.56205511810949E-5,-1.49821416342179E-6,227.9972534,228.986969,999.795,999.795,52.6418991416786,18.5111190456382,36.307648,0,0,0,1201,4886,232.82825,999.795,,,,,,,,,,,,,0,,,,5.00309585,,,,,,228.4921112,,,,
,12749825.3,234.5045471,999.795,,,2,,,,5.91000000651926,,,,,,,234.5045471,234.5045471,999.795,999.795,,,35.926437,,,,-99999999,4886,238.9173,999.795,,,,,,,,,,,,,,,,,,,,,,,234.5045471,,,,
,12750063.235,242.446167,999.795,3.62160262005276E-5,5.85854934295654E-8,1,30.0025819559455,40.0298881530762,1.99291229376695,5.9000002220273,0.000390657825485668,5.13750266229811E-5,0.25,-1.46163368238859E-6,3.62825897515513E-5,-1.43387082052218E-6,241.9467926,242.9455414,999.795,999.795,52.7200619936017,18.5084584250505,36.307648,0,0,0,1201,4886,246.87645,999.795,,,,,,,,,,,,,0,,,,4.78644705,,,,,,242.446167,,,,
,12750303.525,250.43358615,999.795,3.62528700786663E-5,6.01298146118009E-8,1,30.0025819559455,40.0298881530762,1.98197201045619,5.81000000238419,0.000389180514745408,4.95004359156641E-5,0.25,-1.61620569275573E-6,3.63104824054816E-5,-1.58943345736871E-6,249.9400635,250.9271088,999.795,999.795,52.8466858137171,18.5098596973555,36.307648,0,0,0,1201,4886,254.9048,999.795,,,,,,,,,,,,,0,,,,4.9798446,,,,,,250.43358615,,,,
,12750485.36,256.4593506,999.795,,,2,,,,5.76999998822809,,,,,,,256.4593506,256.4593506,999.795,999.795,,,36.307648,,,,-99999999,4886,261.0046,999.795,,,,,,,,,,,,,,,,,,,,,,,256.4593506,,,,
,12750723.295,264.41160585,999.795,3.6994725460574E-5,6.24356541109431E-8,1,30.0025819559455,40.0298881530762,1.99319567261231,5.7600000873208,0.000399029444222953,5.13187640994356E-5,0.25,-1.59572842562407E-6,3.70369870767376E-5,-1.56948387285077E-6,263.9085083,264.9147034,999.795,999.795,52.771649475871,18.5119361962039,35.164013,0,0,0,1201,4886,268.95135,999.795,,,,,,,,,,,,,0,,,,5.1805391,,,,,,264.41160585,,,,
,12750963.33,272.40647885,999.795,3.7555316242138E-5,6.37533519772695E-8,1,30.0025819559455,40.0298881530762,2.0071572670787,5.71000017225742,0.000407540136416954,5.33155565384279E-5,0.25,-1.53701504990822E-6,3.75885262595442E-5,-1.51087737746435E-6,271.9156799,272.8972778,999.795,999.795,52.5668628038325,18.5172659501672,36.307648,0,0,0,1201,4886,276.97775,999.795,,,,,,,,,,,,,0,,,,4.93034435,,,,,,272.40647885,,,,
touchdown = 0.500000023748726 mm,12751275.83,282.7962036,999.795,3.80768392396045E-5,6.07980499676289E-8,1,30.0025819559455,40.0298881530762,1.98207356885745,5.65000018104911,0.000407956153174795,5.42687779300637E-5,0.25,-1.47456767594724E-6,3.80977349895985E-5,-1.44871894722242E-6,282.7962036,282.7962036,999.795,999.795,52.588748402371,18.5135592590674,35.164013,0,0,0,1201,4886,287.4341,999.795,,,,,,,,,,,,,0,,,,4.9281311,,,,,,282.7962036,,,,
,12751413.345,287.3896332,999.795,3.83380120416335E-5,6.30401665383635E-8,1,30.0025819559455,40.0298881530762,1.98232616700845,5.65000018104911,0.000410933532849095,5.35416436151491E-5,0.25,-1.58734702606177E-6,3.83534599749654E-5,-1.56164815892703E-6,286.8884888,287.8907776,999.795,999.795,52.761488305121,18.5179565823329,36.307648,0,0,0,1201,4886,292.03955,999.795,,,,,,,,,,,,,0,,,,5.2325511,,,,,,287.3896332,,,,
,12751653.375,295.38259885,999.795,3.90427708582717E-5,6.52976277069952E-8,1,30.0025819559455,40.0298881530762,1.98242899589067,5.57000003755093,0.000418080808144547,5.63699927895357E-5,0.25,-1.44130437258056E-6,3.90483623218937E-5,-1.41555621592478E-6,294.8868713,295.8783264,999.795,999.795,52.741165963621,18.5158620310049,35.164013,0,0,0,1201,4886,300.07985,999.795,,,,,,,,,,,,,0,,,,4.70107915,,,,,,295.38259885,,,,
touchdown = 0.349999987520278 mm,12751935.595,304.7689209,999.795,3.95699957776798E-5,6.55227061324104E-8,1,30.0025819559455,40.0298881530762,1.99357215278677,5.49999997019768,0.000426086197004776,5.6251371932487E-5,0.25,-1.56929255736713E-6,3.95638445937861E-5,-1.54369061830439E-6,304.7689209,304.7689209,999.795,999.795,52.7224068791594,18.5173279772497,35.926437,0,0,0,1201,4886,309.52935,999.795,,,,,,,,,,,,,0,,,,5.2588184,,,,,,304.7689209,,,,
,12752073.45,309.36288455,999.795,3.99298531916465E-5,6.84407657073442E-8,1,30.0025819559455,40.0298881530762,1.99351415257926,5.51000004634261,0.000429551910478714,5.86896758994164E-5,0.25,-1.4020103895078E-6,3.99176830230524E-5,-1.37644488061648E-6,308.8677979,309.8579712,999.795,999.795,52.8154206729479,18.5168926552071,35.545227,0,0,0,1201,4886,314.1402,999.795,,,,,,,,,,,,,0,,,,5.3381476,,,,,,309.36288455,,,,
,12752313.48,317.34561155,999.795,4.04175110451475E-5,6.99153904452706E-8,1,30.0025819559455,40.0298881530762,1.9931073366769,5.42999990284443,0.000434199864401752,6.17145210615012E-5,0.25,-1.19995787478648E-6,4.03948246589247E-5,-1.17458505917395E-6,316.8468933,317.8443298,999.795,999.795,52.8498123277941,18.5164076353983,35.164013,0,0,0,1201,4886,322.18205,999.795,,,,,,,,,,,,,0,,,,5.31161665,,,,,,317.34561155,,,,
touchdown = 0.199999994947575 mm,12752597.72,326.8025513,999.795,4.14313177314261E-5,6.73113779645307E-8,1,30.0025819559455,40.0298881530762,1.99341186301797,5.35000022500753,0.000445615380318148,5.98246081788314E-5,0.25,-1.55005226403169E-6,4.139593410602E-5,-1.52422053966278E-6,326.8025513,326.8025513,999.795,999.795,52.8482490707556,18.5269275294238,35.926437,0,0,0,1201,4886,331.7101,999.795,,,,,,,,,,,,,0,,,,5.3392129,,,,,,326.8025513,,,,
,12752733.49,331.3193512,999.795,4.17429942946019E-5,6.8942721666731E-8,1,30.0025819559455,40.0298881530762,1.99332074201715,5.35000022500753,0.000448560772850506,6.21406897733099E-5,0.25,-1.38565748354546E-6,4.17013611372132E-5,-1.35995844069178E-6,330.8187561,331.8199463,999.795,999.795,52.4957346085825,18.5133161648709,35.545227,0,0,0,1201,4886,336.2516,999.795,,,,,,,,,,,,,0,,,,5.44614645,,,,,,331.3193512,,,,
,12752973.515,339.29959105,999.795,4.23925293772808E-5,6.97817801458727E-8,1,30.0025819559455,40.0298881530762,1.98236003700688,5.28999976813793,0.000453124919810087,6.21755958909687E-5,0.25,-1.46151572300879E-6,4.23398224927065E-5,-1.43561821696832E-6,338.8001709,339.7990112,999.795,999.795,52.8787325830056,18.5171799430417,35.545227,0,0,0,1201,4886,344.30285,999.795,,,,,,,,,,,,,0,,,,5.52871515,,,,,,339.29959105,,,,
touchdown = 0.0499999987368938 mm,12753257.625,348.739624,999.795,4.29102465669304E-5,6.91684726575146E-8,1,30.0025819559455,40.0298881530762,1.98277229012923,5.2000000141561,0.000458516377989343,6.35192020845016E-5,0.25,-1.42319053196249E-6,4.28445201531225E-5,-1.39730068325934E-6,348.739624,348.739624,999.795,999.795,53.0702315702172,18.5159346237099,35.164013,0,0,0,1201,4886,353.8442,999.795,,,,,,,,,,,,,0,,,,5.7822771,,,,,,348.739624,,,,
,12753393.575,353.23321535,999.795,4.34042079134575E-5,7.24182724254043E-8,1,30.0025819559455,40.0298881530762,1.98260514862491,5.21000009030104,0.000463591089393687,6.48345761743901E-5,0.25,-1.38303208052021E-6,4.3331825073275E-5,-1.35698618152803E-6,352.7530823,353.7133484,999.795,999.795,52.4191350136979,18.5141607876595,36.307648,0,0,0,1201,4886,357.6203,999.795,,,,,,,,,,,,,0,,,,5.7825656,,,,,,353.23321535,,,,
touchdown = -0.039999998989515 mm,12753674.025,354.764679,999.795,4.37993501703966E-5,7.3485807511309E-8,1,30.0025819559455,40.0298881530762,1.99379877689734,5.10999979451299,0.000470380814811173,6.54496027152541E-5,0.25,-1.42631813066899E-6,4.37243113762411E-5,-1.39981123592494E-6,354.764679,354.764679,999.795,999.795,53.0530357427941,18.5103870695175,36.307648,0,0,0,1201,4885,355.9003,999.795,,,,,,,,,,,,,0,,,,5.86964895,,,,,,354.764679,,,,
,12758616.62,5.4324987,999.795,4.13457055041289E-5,3.68678424527942E-8,1,30.0025819559455,40.0298881530762,2.00719123385074,6.47999998182058,0.000444417519554113,6.42971759775346E-5,0.25,-1.30161738712122E-6,4.10846465574239E-5,-1.09217071557215E-6,5.0134859,5.8515115,999.795,999.795,51.8516727087362,18.5150177028516,36.307648,0,0,0,1201,4882,5.45285,999.795,,,,,,,,,,,,,0,,,,1.7017377,,,,,,5.4324987,,,,
,12758794.085,11.3140244,999.795,4.14121704464086E-5,3.65965068436704E-8,1,30.0025819559455,40.0298881530762,1.99339880813424,6.47999998182058,0.000442342452005524,6.31438428370522E-5,0.25,-1.38204490384176E-6,4.11508248012693E-5,-1.17174787637538E-6,10.8165483,11.8115005,999.795,999.795,52.8505939563133,18.5087184082231,35.926437,0,0,0,1201,4882,11.4066,999.795,,,,,,,,,,,,,0,,,,2.2608724,,,,,,11.3140244,,,,
touchdown = 1.3899999903515 mm,12759085.145,20.9377785,999.795,4.12754445146949E-5,3.74440772394419E-8,1,30.0025819559455,40.0298881530762,1.98243434775346,6.5399999730289,0.00043852203509708,6.28485664655456E-5,0.25,-1.35671791680406E-6,4.10158667371882E-5,-1.14496492745443E-6,20.9377785,20.9377785,999.795,999.795,52.6325195994479,18.5130906239997,36.307648,0,0,0,1201,4882,21.17635,999.795,,,,,,,,,,,,,0,,,,2.9905784,,,,,,20.9377785,,,,
,12759244.13,26.17994115,999.795,4.12880854592804E-5,3.8708831205741E-8,1,30.0025819559455,40.0298881530762,1.98253066499888,6.5399999730289,0.000438588844237445,6.40085460273359E-5,0.25,-1.26269388988902E-6,4.10382551168537E-5,-1.04007861752793E-6,25.6891155,26.6707668,999.795,999.795,52.9928503468133,18.5123002340224,35.926437,0,0,0,1201,4882,26.51825,999.795,,,,,,,,,,,,,0,,,,3.19125225,,,,,,26.17994115,,,,
,12759514.13,35.07486725,999.795,4.12818048499157E-5,3.57100083281653E-8,1,30.0025819559455,40.0298881530762,1.99354703186267,6.56000012531877,0.000441310710002427,6.47349116201558E-5,0.25,-1.27222941693251E-6,4.10790486565885E-5,-1.01109901898785E-6,34.5764694,35.5732651,999.795,999.795,53.1140027672941,18.5052220657857,35.926437,0,0,0,1201,4882,35.6153,999.795,,,,,,,,,,,,,0,,,,3.20017375,,,,,,35.07486725,,,,
,12759784.16,43.92487335,999.795,4.12534195241053E-5,3.81008034439698E-8,1,30.0025819559455,40.0298881530762,1.98282458629095,6.5700002014637,0.000439808685887594,6.40412035135338E-5,0.25,-1.35695602413143E-6,4.11442565835563E-5,-1.05609010270976E-6,43.4366608,44.4130859,999.795,999.795,52.903744695621,18.5101520995005,36.307648,0,0,0,1201,4882,44.7451,999.795,,,,,,,,,,,,,0,,,,3.6341722,,,,,,43.92487335,,,,
touchdown = 1.41000002622604 mm,12760070.07,53.2745361,999.795,4.11878762060525E-5,3.85553312445338E-8,1,30.0025819559455,40.0298881530762,2.0073688905155,6.56000012531877,0.000445564480716669,6.54008980500831E-5,0.25,-1.31238707646316E-6,4.12017252896225E-5,-1.01031340139619E-6,53.2745361,53.2745361,999.795,999.795,52.9115609808133,18.5207509936503,35.545227,0,0,0,1201,4886,54.4333,999.795,,,,,,,,,,,,,0,,,,3.8582771,,,,,,53.2745361,,,,
,12760234.195,58.6300316,999.795,4.12509568063548E-5,4.03640989840742E-8,1,30.0025819559455,40.0298881530762,1.99344379662904,6.56000012531877,0.00044417159295222,6.38412630391157E-5,0.25,-1.41936604595627E-6,4.13269048237333E-5,-1.13695099224213E-6,58.1414719,59.1185913,999.795,999.795,52.5473220908517,18.5094833199491,35.926437,0,0,0,1201,4886,60.0004,999.795,,,,,,,,,,,,,0,,,,3.72584485,,,,,,58.6300316,,,,
,12760504.28,67.453846,999.795,4.12815225175455E-5,3.84520983354681E-8,1,30.0025819559455,40.0298881530762,2.00740531625578,6.55000004917383,0.000448320966154165,6.39863925581538E-5,0.25,-1.41659274193335E-6,4.14276911720135E-5,-1.18061722861671E-6,66.9606476,67.9470444,999.795,999.795,52.6145421435056,18.5241112895387,35.926437,0,0,0,1201,4886,69.1704,999.795,,,,,,,,,,,,,0,,,,3.9565897,,,,,,67.453846,,,,
,12760774.24,76.266922,999.795,4.14173258316443E-5,4.22312430467516E-8,1,30.0025819559455,40.0298881530762,1.99349242657843,6.55000004917383,0.000447287983944918,6.33999223818515E-5,0.25,-1.41772226561249E-6,4.16020066878864E-5,-1.22564351657644E-6,75.7770233,76.7568207,999.795,999.795,53.0506908572364,18.5034151309924,35.926437,0,0,0,1201,4886,78.3196,999.795,,,,,,,,,,,,,0,,,,4.0769619,,,,,,76.266922,,,,
touchdown = 1.36999995447695 mm,12761102.28,87.0323029,999.795,4.14252486257799E-5,4.23708157883195E-8,1,30.0025819559455,40.0298881530762,1.99355118652275,6.51999982073903,0.000447725932355204,6.27772466769193E-5,0.25,-1.4390398587097E-6,4.16308737133255E-5,-1.2889804147626E-6,87.0323029,87.0323029,999.795,999.795,52.6747275394863,18.5013253203344,36.307648,0,0,0,1201,4886,89.42875,999.795,,,,,,,,,,,,,0,,,,4.2423267,,,,,,87.0323029,,,,
,12761256.58,92.0803223,999.795,,,2,,,,6.51000003501773,,,,,,,92.0803223,92.0803223,999.795,999.795,,,35.164013,,,,-99999999,4886,94.6356,999.795,,,,,,,,,,,,,,,,,,,,,,,92.0803223,,,,
,12761554.33,101.86650085,999.795,4.16205536686306E-5,4.24234589821295E-8,1,30.0025819559455,40.0298881530762,1.98250085117289,6.50000013411045,0.000447726316938743,6.15540358227609E-5,0.25,-1.51914336325671E-6,4.18343968216924E-5,-1.40753581938079E-6,101.3700409,102.3629608,999.795,999.795,52.8591918700248,18.5082616011248,36.307648,0,0,0,1201,4886,104.7108,999.795,,,,,,,,,,,,,0,,,,4.32794,,,,,,101.86650085,,,,
,12761794.37,109.8145981,999.795,4.17101752988025E-5,4.40452180899077E-8,1,30.0025819559455,40.0298881530762,2.00746860354249,6.46999990567565,0.000454067330208989,6.25899561140961E-5,0.25,-1.49314112947176E-6,4.1923053607504E-5,-1.39562840270106E-6,109.3190613,110.3101349,999.795,999.795,52.0197228403709,18.5215343133318,35.545227,0,0,0,1201,4886,112.87815,999.795,,,,,,,,,,,,,0,,,,4.26617645,,,,,,109.8145981,,,,
,12762049.735,118.30409625,999.795,4.18267172830187E-5,4.34635592943317E-8,1,30.0025819559455,40.0298881530762,1.99340968672016,6.44000014290214,0.000452104727247807,6.31002248419785E-5,0.25,-1.41416649204644E-6,4.20363474670703E-5,-1.32809725615669E-6,118.2854996,118.3226929,999.795,999.795,52.1424385178901,18.4983812356097,36.307648,0,0,0,1201,4886,121.5364,999.795,,,,,,,,,,,,,0,,,,4.4596095,,,,,,118.30409625,,,,
,12762214.385,123.76770785,999.795,4.17599639874676E-5,4.50400741608593E-8,1,30.0025819559455,40.0298881530762,1.99367553145232,6.44000014290214,0.000451563651008287,6.21000684308672E-5,0.25,-1.48940086187243E-6,4.19662347086105E-5,-1.4102849368563E-6,123.2716446,124.2637711,999.795,999.795,53.1022783395056,18.5175793820529,35.926437,0,0,0,1201,4886,127.1154,999.795,,,,,,,,,,,,,0,,,,4.2330432,,,,,,123.76770785,,,,
,12762454.415,131.7532196,999.795,4.19139520555602E-5,4.58935940384994E-8,1,30.0025819559455,40.0298881530762,1.9935159279628,6.38000015169382,0.000453021411203011,6.29609776323765E-5,0.25,-1.42680767930539E-6,4.21152554751917E-5,-1.3549816659176E-6,131.2550354,132.2514038,999.795,999.795,52.8162023014671,18.5060162558055,36.307648,0,0,0,1201,4886,135.24105,999.795,,,,,,,,,,,,,0,,,,4.48333835,,,,,,131.7532196,,,,
,12762709.11,140.25068665,999.795,4.20254235822984E-5,4.78434619811692E-8,1,30.0025819559455,40.0298881530762,1.9934233172509,6.35999999940395,0.000454291103897571,6.21974327694917E-5,0.25,-1.50899053964837E-6,4.22205013443413E-5,-1.44419236555925E-6,140.2321014,140.2692719,999.795,999.795,52.8341797574094,18.5003836726412,36.307648,0,0,0,1201,4886,143.83675,999.795,,,,,,,,,,,,,0,,,,4.6414213,,,,,,140.25068665,,,,
,12762874.525,145.7622223,999.795,4.20184741043093E-5,4.74509986480856E-8,1,30.0025819559455,40.0298881530762,1.9936301915,6.35999999940395,0.000454073580801637,6.29638120057934E-5,0.25,-1.43241650787668E-6,4.22085111248913E-5,-1.37107307644549E-6,145.2623444,146.2621002,999.795,999.795,52.9498607782556,18.5103219443853,35.545227,0,0,0,1201,4886,149.43425,999.795,,,,,,,,,,,,,0,,,,4.6183531,,,,,,145.7622223,,,,
,12763144.525,154.73677825,999.795,4.22418972258504E-5,4.82561582884752E-8,1,30.0025819559455,40.0298881530762,1.98256105727746,6.32000016048551,0.000454027142974094,6.25815084627671E-5,0.25,-1.46885783414482E-6,4.24244229620649E-5,-1.41258607256226E-6,154.2373352,155.2362213,999.795,999.795,52.7708678473517,18.5044076314386,36.307648,0,0,0,1201,4886,158.5059,999.795,,,,,,,,,,,,,0,,,,4.7115545,,,,,,154.73677825,,,,
,12763384.735,162.69577025,999.795,4.22955157603579E-5,4.97330202182562E-8,1,30.0025819559455,40.0298881530762,1.99335193027545,6.26999977976084,0.000456881349358769,6.30298184315585E-5,0.25,-1.46155051504187E-6,4.24701484768503E-5,-1.40909530266565E-6,162.200058,163.1914825,999.795,999.795,52.5027692652556,18.5020801467874,35.926437,0,0,0,1201,4886,166.56675,999.795,,,,,,,,,,,,,0,,,,4.7826281,,,,,,162.69577025,,,,
,12763566.47,168.7106781,999.795,,,2,,,,6.23999995816499,,,,,,,168.7106781,168.7106781,999.795,999.795,,,36.307648,,,,-99999999,4886,172.6639,999.795,,,,,,,,,,,,,,,,,,,,,,,168.7106781,,,,
,12763804.54,176.63768005,999.795,4.24690997646138E-5,5.19087942836655E-8,1,30.0025819559455,40.0298881530762,1.98244394886703,6.22999994084239,0.000456284638839928,6.23517080312035E-5,0.25,-1.51599809962477E-6,4.26292925108519E-5,-1.46907086910825E-6,176.1350861,177.140274,999.795,999.795,52.544977205294,18.5152104369408,36.307648,0,0,0,1201,4886,180.63375,999.795,,,,,,,,,,,,,0,,,,4.78286695,,,,,,176.63768005,,,,
,12764044.585,184.61128235,999.795,4.25212308462528E-5,5.04628531097065E-8,1,30.0025819559455,40.0298881530762,1.99325574171225,6.18000002577901,0.000458984650211832,6.36215080900628E-5,0.25,-1.43296193205053E-6,4.26723470242603E-5,-1.38826709641054E-6,184.1209106,185.1016541,999.795,999.795,52.4824469237556,18.5181066196482,37.070068,0,0,0,1201,4886,188.678,999.795,,,,,,,,,,,,,0,,,,4.8308864,,,,,,184.61128235,,,,
,12764226.19,190.6234894,999.795,,,2,,,,6.14000001162291,,,,,,,190.6234894,190.6234894,999.795,999.795,,,35.926437,,,,-99999999,4886,194.7651,999.795,,,,,,,,,,,,,,,,,,,,,,,190.6234894,,,,
,12764464.665,198.56170655,999.795,4.26371983512816E-5,5.38239049421714E-8,1,30.0025819559455,40.0298881530762,1.98254703013123,6.13000011071563,0.000457815410982657,6.26804120070036E-5,0.25,-1.50382842402454E-6,4.27720483259046E-5,-1.46301604773782E-6,198.0702667,199.0531464,999.795,999.795,52.2471767394671,18.5240172394543,37.070068,0,0,0,1201,4886,202.73665,999.795,,,,,,,,,,,,,0,,,,4.9036379,,,,,,198.56170655,,,,
,12764704.83,206.5523605,999.795,4.27728622065095E-5,5.53976143967486E-8,1,30.0025819559455,40.0298881530762,1.98239119855575,6.07000011950731,0.00045903953748069,6.33884402670674E-5,0.25,-1.45698915633399E-6,4.28981322663393E-5,-1.41770554058275E-6,206.0453033,207.0594177,999.795,999.795,52.8177655585056,18.5184043847595,35.545227,0,0,0,1201,4886,210.7791,999.795,,,,,,,,,,,,,0,,,,4.9281311,,,,,,206.5523605,,,,
,12764886.42,212.5561523,999.795,,,2,,,,6.02999998893589,,,,,,,212.5561523,212.5561523,999.795,999.795,,,36.307648,,,,-99999999,4886,216.8612,999.795,,,,,,,,,,,,,,,,,,,,,,,212.5561523,,,,
,12765124.735,220.50847625,999.795,4.27601640869581E-5,5.70013210888213E-8,1,30.0025819559455,40.0298881530762,1.99301104097144,6.02000020444393,0.000461223069957716,6.27859925518093E-5,0.25,-1.53563760178991E-6,4.28676171064373E-5,-1.49926017284579E-6,220.0218658,220.9950867,999.795,999.795,52.7450741062171,18.5049765332517,36.307648,0,0,0,1201,4886,224.82435,999.795,,,,,,,,,,,,,0,,,,4.63126445,,,,,,220.50847625,,,,
,12765364.71,228.49557495,999.795,4.29648268674186E-5,5.67806445783339E-8,1,30.0025819559455,40.0298881530762,1.98210082081894,5.96999982371926,0.000460850947230499,6.2925438976915E-5,0.25,-1.52389892213955E-6,4.30622763868181E-5,-1.48860789112491E-6,227.9872894,229.0038605,999.795,999.795,52.3480068184478,18.5118854870549,35.545227,0,0,0,1201,4886,232.84325,999.795,,,,,,,,,,,,,0,,,,4.9533644,,,,,,228.49557495,,,,
,12765546.28,234.4884796,999.795,,,2,,,,5.91000000651926,,,,,,,234.4884796,234.4884796,999.795,999.795,,,37.070068,,,,-99999999,4886,238.9264,999.795,,,,,,,,,,,,,,,,,,,,,,,234.4884796,,,,
,12765784.805,242.4657364,999.795,4.30321806895226E-5,6.00994217388158E-8,1,30.0025819559455,40.0298881530762,1.9826034932881,5.9000002220273,0.000461410603741011,6.34451917971889E-5,0.25,-1.48303151443814E-6,4.31110325511602E-5,-1.44958714254795E-6,241.9674683,242.9640045,999.795,999.795,52.3065805069286,18.5210253204039,35.926437,0,0,0,1201,4886,246.8894,999.795,,,,,,,,,,,,,0,,,,4.9776092,,,,,,242.4657364,,,,
,12766024.765,250.43177035,999.795,4.29866628578357E-5,6.17279033706376E-8,1,30.0025819559455,40.0298881530762,1.99321119982481,5.83000015467405,0.000463083153025664,6.42072027166699E-5,0.25,-1.43159366477369E-6,4.30545873603934E-5,-1.39909664647353E-6,249.9211426,250.9423981,999.795,999.795,52.6841070817171,18.5019234262057,36.307648,0,0,0,1201,4886,254.9106,999.795,,,,,,,,,,,,,0,,,,5.1035521,,,,,,250.43177035,,,,
,12766206.64,256.4467468,999.795,,,2,,,,5.76999998822809,,,,,,,256.4467468,256.4467468,999.795,999.795,,,35.926437,,,,-99999999,4886,261.0033,999.795,,,,,,,,,,,,,,,,,,,,,,,256.4467468,,,,
,12766444.82,264.42915345,999.795,4.30599072323836E-5,6.12921631594648E-8,1,30.0025819559455,40.0298881530762,1.99335847048178,5.7600000873208,0.00046358352370696,6.4958831808385E-5,0.25,-1.36964498327702E-6,4.3108704065094E-5,-1.33855880331594E-6,263.9307556,264.9275513,999.795,999.795,52.4199166422171,18.5103495554905,36.307648,0,0,0,1201,4886,268.97235,999.795,,,,,,,,,,,,,0,,,,4.7372148,,,,,,264.42915345,,,,
,12766684.81,272.41567995,999.795,4.3152939598507E-5,6.44899370478088E-8,1,30.0025819559455,40.0298881530762,1.99371995889568,5.71000017225742,0.000464656580945911,6.44602164117348E-5,0.25,-1.4306592519434E-6,4.31908417848314E-5,-1.40034225621278E-6,271.905304,272.9260559,999.795,999.795,52.8232369581402,18.5129662591819,35.926437,0,0,0,1201,4886,277.0035,999.795,,,,,,,,,,,,,0,,,,5.12929985,,,,,,272.41567995,,,,
,12766867.08,278.4484863,999.795,,,2,,,,5.66000002374873,,,,,,,278.4484863,278.4484863,999.795,999.795,,,35.926437,,,,-99999999,4886,283.0952,999.795,,,,,,,,,,,,,,,,,,,,,,,278.4484863,,,,
,12767104.885,286.4076233,999.795,4.3165813663401E-5,6.41950870285325E-8,1,30.0025819559455,40.0298881530762,1.99330099043721,5.65000018104911,0.000464701764602166,6.32269151326729E-5,0.25,-1.54241890911958E-6,4.31844012027834E-5,-1.51332021400193E-6,285.9085999,286.9066467,999.795,999.795,52.9811259190248,18.5080263712165,35.545227,0,0,0,1201,4886,291.05395,999.795,,,,,,,,,,,,,0,,,,4.9815836,,,,,,286.4076233,,,,
,12767344.885,294.38819885,999.795,4.31248613797144E-5,6.53680288726909E-8,1,30.0025819559455,40.0298881530762,1.99374190465568,5.59000018984079,0.000464004025580006,6.45339197270469E-5,0.25,-1.41198112825326E-6,4.31322931684913E-5,-1.38345108999833E-6,293.8743896,294.9020081,999.795,999.795,52.8373062714864,18.5130910676904,35.926437,0,0,0,1201,4886,299.08995,999.795,,,,,,,,,,,,,0,,,,4.78286695,,,,,,294.38819885,,,,
,12767527.13,300.4264526,999.795,,,2,,,,5.49999999868684,,,,,,,300.4264526,300.4264526,999.795,999.795,,,36.307648,,,,-99999999,4886,305.1966,999.795,,,,,,,,,,,,,,,,,,,,,,,300.4264526,,,,
,12767764.945,308.3832092,999.795,4.33389878808905E-5,6.8002092661001E-8,1,30.0025819559455,40.0298881530762,1.98265743115381,5.48999989405274,0.000463458568507519,6.53685668931803E-5,0.25,-1.33387944239217E-6,4.33270117202337E-5,-1.30613338843657E-6,307.8814392,308.8849792,999.795,999.795,52.6723826539286,18.5120872138866,35.545227,0,0,0,1201,4886,313.1551,999.795,,,,,,,,,,,,,0,,,,5.31161665,,,,,,308.3832092,,,,
,12767857.05,311.4071655,999.795,,,2,,,,5.44000000747852,,,,,,,311.4071655,311.4071655,999.795,999.795,,,35.926437,,,,-99999999,4886,316.2504,999.795,,,,,,,,,,,,,,,,,,,,,,,311.4071655,,,,