File: Projekt_andmed1/1880_200xFe+Co+O3_at400C_72nm_VSM_Hys300K_5T_17012023.DAT
[Header]
; VSM Data File (default extension .dat)
; Copyright (c) 2003-2013, Quantum Design, Inc. All rights reserved.
TITLE,1880_200xFe+Co+O3_at400C_72nm_VSM_Hys300K_5T_17012023
FILEOPENTIME,12904878.17,01/17/2023,10:20 am
BYAPP,VSM,2.0,2.0
INFO,PPMS VSM Option Release 1.4.10 Build 1,APPNAME
INFO,Quantum Design Linear Motor Servo Controller,MOTOR_MODULE_NAME
INFO,3101-100 C1,MOTOR_HW_VERSION
INFO,074,MOTOR_SERIAL_NUMBER
INFO,SRV No X-over 01.01.11,MOTOR_SOFTWARE_VERSION
INFO,Quantum Design VSM Detection Module,VSM_MODULE_NAME
INFO,3101-150 E1,VSM_HW_VERSION
INFO,VSM061,VSM_SERIAL_NUMBER
INFO,VSM No X-over 01.02.05 May 20 2008 13:51:47,VSM_SOFTWARE_VERSION
INFO,113,PREAMP_SERIAL_NUMBER
INFO,Quantum Design VSM Oven,OVEN_MODULE_NAME
INFO,3101-200 B0,OVEN_HW_VERSION
INFO,OVN054,OVEN_SERIAL_NUMBER
INFO,01.01.00,OVEN_SOFTWARE_VERSION
INFO,221,COIL_SERIAL_NUMBER
INFO,0,MOMENT_UNITS
INFO,1880_200xFe+Co+O3_at400C_72nm_VSM_Hys300K_5T_17012023,SAMPLE_MATERIAL
INFO,thin film Fe&FeCo ratio 42,SAMPLE_COMMENT
INFO,13.4,SAMPLE_MASS
INFO,,SAMPLE_VOLUME
INFO,,SAMPLE_MOLECULAR_WEIGHT
INFO,8.5 mm2,SAMPLE_SIZE
INFO,,SAMPLE_SHAPE
DATATYPE,COMMENT,1
DATATYPE,TIME,2
STARTUPAXIS,X,2
STARTUPAXIS,Y1,5
[Data]
Comment,Time Stamp (sec),Temperature (K),Magnetic Field (Oe),Moment (emu),M. Std. Err. (emu),Transport Action,Averaging Time (sec),Frequency (Hz),Peak Amplitude (mm),Center Position (mm),Coil Signal' (mV),Coil Signal" (mV),Range (mV),M. Quad. Signal (emu),M. Raw' (emu),M. Raw" (emu),Min. Temperature (K),Max. Temperature (K),Min. Field (Oe),Max. Field (Oe),Mass (grams),Motor Lag (deg),Pressure (Torr),VSM Status (code),Motor Status (code),Measure Status (code),Measure Count,PPMS Status (code),System Temp. (K),System Field (Oe),Sample Position (deg),Bridge 1 Resistance (ohms),Bridge 1 Excitation (에),Bridge 2 Resistance (ohms),Bridge 2 Excitation (에),Bridge 3 Resistance (ohms),Bridge 3 Excitation (에),Bridge 4 Resistance (ohms),Bridge 4 Excitation (에),Signal 1 Vin (V),Signal 2 Vin (V),Digital Inputs (code),Drive 1 Iout (mA),Drive 1 Ipower (W),Drive 2 Iout (mA),Drive 2 Ipower (W),Pressure (),Map 20 (),Map 21 (),Map 22 (),Map 23 (),Map 24 (),Map 25 (),Map 26 (),Map 27 (),Map 28 (),Map 29 ()
,12911730.25,4.999598,999.675,,,2,,,,5.8000000109151,,,,,,,4.999598,4.999598,999.675,999.675,,,35.926437,,,,-99999999,4881,4.9946,999.675,,,,,,,,,,,,,,,,,,,,,,,4.999598,,,,
,12912203.9,13.9651456,999.675,1.49792216766941E-5,3.67552436123841E-8,1,30.0025819559455,40.0298881530762,1.98259567813114,5.78999985009432,0.000161146781618094,1.15323662209369E-5,0.25,-1.55907092359268E-6,1.48897611069963E-5,-1.47614041233956E-6,13.4658108,14.4644804,999.675,999.675,51.2576350341208,18.495671923004,35.545227,0,0,0,1201,4882,14.09925,999.675,,,,,,,,,,,,,0,,,,2.3767879,,,,,,13.9651456,,,,
touchdown = 0.7999999797903 mm,12912732.365,31.3794556,999.675,1.58373472936237E-5,3.64576903760145E-8,1,30.0025819559455,40.0298881530762,1.982479763617,5.8699999935925,0.00017025910651195,1.36767735135976E-5,0.25,-1.52262692586048E-6,1.57560304567204E-5,-1.42348140763638E-6,31.3794556,31.3794556,999.675,999.675,53.3320771241595,18.5044219193436,35.164013,0,0,0,1201,4882,31.8685,999.675,,,,,,,,,,,,,0,,,,3.0815613,,,,,,31.3794556,,,,
,12913133.975,44.58683015,999.675,1.63081212537449E-5,3.72365606331381E-8,1,30.0025819559455,40.0298881530762,2.00719855000933,5.9000002220273,0.000177931389225305,1.45721524111002E-5,0.25,-1.56729320601602E-6,1.62757684223294E-5,-1.44487346361637E-6,44.0944481,45.0792122,999.675,999.675,52.8419960426017,18.5086642605882,35.926437,0,0,0,1201,4886,45.42485,999.675,,,,,,,,,,,,,0,,,,3.2759979,,,,,,44.58683015,,,,
,12913554.025,58.31624985,999.675,1.66116534536439E-5,3.95485111471794E-8,1,30.0025819559455,40.0298881530762,2.00704990846073,5.90999983251095,0.000181930007537545,1.52238077673995E-5,0.25,-1.56104292395545E-6,1.6647739903426E-5,-1.44820509690281E-6,57.8251457,58.807354,999.675,999.675,52.5785872316209,18.51231519592,35.926437,0,0,0,1201,4886,59.6587,999.675,,,,,,,,,,,,,0,,,,3.63380955,,,,,,58.31624985,,,,
,12914064.945,75.01979445,999.675,1.72082095707346E-5,4.16169868646001E-8,1,30.0025819559455,40.0298881530762,1.98240553672231,5.89000014588237,0.000186718246130181,1.5532037103191E-5,0.25,-1.59058771141503E-6,1.72881714188949E-5,-1.51248217940009E-6,74.5650024,75.4745865,999.675,999.675,53.2179593603518,18.5039500288204,35.164013,0,0,0,1201,4886,76.9805,999.675,,,,,,,,,,,,,0,,,,3.7823322,,,,,,75.01979445,,,,
,12914514.16,89.75123595,999.675,1.80276809874046E-5,4.30152043408564E-8,1,30.0025819559455,40.0298881530762,1.98260397371818,5.85999991744757,0.00019557047314761,1.72585013017385E-5,0.25,-1.5508045936644E-6,1.81215924990811E-5,-1.49366452627326E-6,89.2696838,90.2327881,999.675,999.675,52.7857187892171,18.5074401748174,35.926437,0,0,0,1201,4886,92.17325,999.675,,,,,,,,,,,,,0,,,,3.8038801,,,,,,89.75123595,,,,
,12915037.875,106.9745636,999.675,1.97157079335938E-5,4.22727579058406E-8,1,30.0025819559455,40.0298881530762,1.98238262268203,5.81000000238419,0.000213467768694679,2.11695907046321E-5,0.25,-1.46224764734346E-6,1.981867305001E-5,-1.41767917801353E-6,106.9227295,107.0263977,999.675,999.675,52.6372093705633,18.5049891637305,35.545227,0,0,0,1201,4886,109.9387,999.675,,,,,,,,,,,,,0,,,,4.076148,,,,,,106.9745636,,,,
,12915414.22,119.46931835,999.675,2.24406290418438E-5,4.50103846041105E-8,1,30.0025819559455,40.0298881530762,1.99323279867172,5.77999977394938,0.000243642590291607,2.74985623239058E-5,0.25,-1.34914717558639E-6,2.2554047433684E-5,-1.30663647352148E-6,118.9709396,119.9676971,999.675,999.675,53.2218675029479,18.509349256377,35.545227,0,0,0,1201,4886,122.69505,999.675,,,,,,,,,,,,,0,,,,4.11727785,,,,,,119.46931835,,,,
,12915804.225,132.44618225,999.675,2.46177469284751E-5,4.45954350753396E-8,1,30.0025819559455,40.0298881530762,1.98245545703607,5.73999993503094,0.000265532623235095,3.17464383361814E-5,0.25,-1.30885182498687E-6,2.47365412375207E-5,-1.26922747745502E-6,131.9428864,132.9494781,999.675,999.675,53.0436562005633,18.5076852968767,35.926437,0,0,0,1201,4886,135.89915,999.675,,,,,,,,,,,,,0,,,,4.2001576,,,,,,132.44618225,,,,
,12916194.28,145.44688415,999.675,2.54794177351831E-5,4.81113753376034E-8,1,30.0025819559455,40.0298881530762,1.99319358302258,5.69000001996756,0.000276204757419146,3.28905263400783E-5,0.25,-1.36051891979883E-6,2.55956209155265E-5,-1.32538529046668E-6,144.9477386,145.9460297,999.675,999.675,52.9975401179287,18.5056901963007,35.164013,0,0,0,1201,4886,149.0828,999.675,,,,,,,,,,,,,0,,,,4.24253865,,,,,,145.44688415,,,,
touchdown = 0.549999997019768 mm,12916689.15,161.8863068,999.675,2.6332827201904E-5,4.96118348346368E-8,1,30.0025819559455,40.0298881530762,1.99326485879276,5.61999995261431,0.000285221371518023,3.47573613182002E-5,0.25,-1.32777253200361E-6,2.64426569422415E-5,-1.29658311023838E-6,161.8863068,161.8863068,999.675,999.675,52.3331558765825,18.5093171771676,35.926437,0,0,0,1201,4886,165.70285,999.675,,,,,,,,,,,,,0,,,,4.3496659,,,,,,161.8863068,,,,
,12917064.32,174.33865355,999.675,2.7188184123199E-5,5.04833305323236E-8,1,30.0025819559455,40.0298881530762,1.98231044651422,5.58000011369586,0.000292873652226978,3.54877403114209E-5,0.25,-1.38588407002818E-6,2.72929137986314E-5,-1.35688258652343E-6,173.8437805,174.8335266,999.675,999.675,53.8088705208903,18.512498415077,35.164013,0,0,0,1201,4886,178.27725,999.675,,,,,,,,,,,,,0,,,,4.1602752,,,,,,174.33865355,,,,
,12917454.39,187.2789917,999.675,2.80774371072638E-5,5.09227087131009E-8,1,30.0025819559455,40.0298881530762,1.99319706226057,5.52000012248754,0.000303897586421214,3.70746017855363E-5,0.25,-1.40518907074148E-6,2.81756795076661E-5,-1.37777417460614E-6,186.780777,187.7772064,999.675,999.675,53.0671050561402,18.5146024256835,35.926437,0,0,0,1201,4886,191.3404,999.675,,,,,,,,,,,,,0,,,,4.3501,,,,,,187.2789917,,,,
,12917844.425,200.23158265,999.675,2.89266185292923E-5,5.19286772514406E-8,1,30.0025819559455,40.0298881530762,1.98221629911598,5.47999981790781,0.000311264109810056,3.829488931227E-5,0.25,-1.41551971702239E-6,2.90171282458899E-5,-1.38931461924734E-6,199.7327728,200.7303925,999.675,999.675,52.7325680499094,18.5121305319515,35.545227,0,0,0,1201,4886,204.411,999.675,,,,,,,,,,,,,0,,,,4.4824438,,,,,,200.23158265,,,,
touchdown = 0.300000014249235 mm,12918336.97,216.6100006,999.675,3.00306014823943E-5,5.40270692557908E-8,1,30.0025819559455,40.0298881530762,1.99304913043363,5.37999998778105,0.000324508737145991,4.09417372297758E-5,0.25,-1.37375216204597E-6,3.01098915600867E-5,-1.34848197971001E-6,216.5965729,216.6234283,999.675,999.675,52.8951467819094,18.5140551013026,35.545227,0,0,0,1201,4886,220.8762,999.675,,,,,,,,,,,,,0,,,,4.6414213,,,,,,216.6100006,,,,
,12918684.74,228.1577377,999.675,3.10673503278782E-5,5.62845562213749E-8,1,30.0025819559455,40.0298881530762,1.98227979993762,5.3099999204278,0.000333890970972535,4.19017084969318E-5,0.25,-1.43992512930259E-6,3.11384432107493E-5,-1.41512853332702E-6,227.6617584,228.653717,999.675,999.675,53.0522541142748,18.5187179771477,35.545227,0,0,0,1201,4886,232.50745,999.675,,,,,,,,,,,,,0,,,,4.31287765,,,,,,228.1577377,,,,
,12919074.55,241.1222534,999.675,3.216956015456E-5,5.54279782658572E-8,1,30.0025819559455,40.0298881530762,1.98221236116965,5.24999992921948,0.00034542678452539,4.42920392542313E-5,0.25,-1.40260140084506E-6,3.22301125555225E-5,-1.3780122459213E-6,240.6279449,241.6165619,999.675,999.675,53.0835192550441,18.5168689840956,35.545227,0,0,0,1201,4886,245.558,999.675,,,,,,,,,,,,,0,,,,4.6651866,,,,,,241.1222534,,,,
,12919464.65,254.10632325,999.675,3.33382021469728E-5,5.65137751587668E-8,1,30.0025819559455,40.0298881530762,1.98195058832529,5.16000017523766,0.000357752470732807,4.6054447257723E-5,0.25,-1.43515551636897E-6,3.33872524001373E-5,-1.41075059806402E-6,253.6232605,254.589386,999.675,999.675,53.0069196601595,18.523766693406,35.926437,0,0,0,1201,4886,258.59215,999.675,,,,,,,,,,,,,0,,,,4.6651866,,,,,,254.10632325,,,,
,12919856.16,267.110321,999.675,,,2,,,,5.0300000012631,,,,,,,267.110321,267.110321,999.675,999.675,,,35.926437,,,,-99999999,4886,271.6998,999.675,,,,,,,,,,,,,,,,,,,,,,,267.110321,,,,
,12920318.5,282.5330963,999.675,3.61591622697019E-5,6.44480830723544E-8,1,30.0025819559455,40.0298881530762,2.00700786232747,4.96000004932284,0.000391877193496267,5.3378910939448E-5,0.25,-1.28697368525759E-6,3.61792322575458E-5,-1.26235113022888E-6,282.4955444,282.5706482,999.675,999.675,52.8638816411402,18.5252858382374,35.545227,0,0,0,1201,4886,287.17555,999.675,,,,,,,,,,,,,0,,,,4.78286695,,,,,,282.5330963,,,,
,12920694.805,295.07302855,999.675,3.77534142652021E-5,6.26538069797065E-8,1,30.0025819559455,40.0298881530762,1.99292539347618,4.88999998196959,0.000406360066039566,5.46247523332967E-5,0.25,-1.40880893630743E-6,3.77592059415806E-5,-1.38389496439478E-6,294.5708008,295.5752563,999.675,999.675,53.5141965691403,18.5198257357913,35.926437,0,0,0,1201,4886,299.761,999.675,,,,,,,,,,,,,0,,,,4.714376,,,,,,295.07302855,,,,
,12921084.765,308.05513,999.675,3.95722399440767E-5,6.48320087675918E-8,1,30.0025819559455,40.0298881530762,1.98231626740072,4.82999999076128,0.000423577435678459,5.69821339268091E-5,0.25,-1.47144446994503E-6,3.95618781885882E-5,-1.44601877844446E-6,307.5568237,308.5534363,999.675,999.675,52.768522961794,18.5208340403869,35.926437,0,0,0,1201,4886,312.81945,999.675,,,,,,,,,,,,,0,,,,4.87938835,,,,,,308.05513,,,,
,12921474.795,321.03988645,999.675,4.14221257150416E-5,6.897006622423E-8,1,30.0025819559455,40.0298881530762,1.98119311769981,4.75999992340803,0.000442664042093002,6.1274283743137E-5,0.25,-1.38040974315465E-6,4.13941404161216E-5,-1.35448701554543E-6,320.5406799,321.539093,999.675,999.675,52.6559684550248,18.539300582651,35.926437,0,0,0,1201,4886,325.8801,999.675,,,,,,,,,,,,,0,,,,5.00259665,,,,,,321.03988645,,,,
touchdown = -0.44000000343658 mm,12921968.465,337.4417114,999.675,4.42072401090152E-5,7.01101173930549E-8,1,30.0025819559455,40.0298881530762,2.00722535555336,4.62999986484647,0.000477783762758282,6.82321298642176E-5,0.25,-1.28141629707417E-6,4.41546655227037E-5,-1.2546444561422E-6,337.4417114,337.4417114,999.675,999.675,53.4743335146595,18.5238820119589,35.926437,0,0,0,1201,4886,342.41445,999.675,,,,,,,,,,,,,0,,,,5.07831385,,,,,,337.4417114,,,,
,12922314.88,348.95942685,999.675,4.66103813715595E-5,7.2875149128503E-8,1,30.0025819559455,40.0298881530762,1.99327105990796,4.54000011086464,0.000500468602537661,7.00012709951522E-5,0.25,-1.48458757549305E-6,4.65386440635437E-5,-1.45656545936181E-6,348.4538574,349.4649963,999.675,999.675,53.1999819044095,18.524814515278,35.545227,0,0,0,1201,4886,354.0574,999.675,,,,,,,,,,,,,0,,,,5.3917422,,,,,,348.95942685,,,,
,12922734.895,354.7711487,999.675,4.83424714829513E-5,7.23585731690887E-8,1,30.0025819559455,40.0298881530762,1.98241613313557,4.47000004351139,0.000515471130353561,7.68006120378303E-5,0.25,-1.10744215749597E-6,4.8259383759318E-5,-1.07899527150514E-6,354.7328186,354.8094788,999.675,999.675,53.2804896418903,18.5334589798758,35.926437,0,0,0,1201,4885,355.92235,999.675,,,,,,,,,,,,,0,,,,5.4458747,,,,,,354.7711487,,,,
,12927955.4,12.2541118,999.675,4.16890960320812E-5,3.88883129501483E-8,1,30.0025819559455,40.0298881530762,1.98197988919188,5.78999985009432,0.000442888743411673,6.30040183859252E-5,0.25,-1.41140324645314E-6,4.14260301062453E-5,-1.19956796738594E-6,11.7415276,12.766696,999.675,999.675,52.7982248455248,18.5073158822518,35.545227,0,0,0,1201,4882,12.3835,999.675,,,,,,,,,,,,,0,,,,2.2162597,,,,,,12.2541118,,,,
,12928375.455,26.148324,999.675,4.15750613211931E-5,3.90196835970676E-8,1,30.0025819559455,40.0298881530762,1.99304750177057,5.8699999935925,0.000444058808697653,6.37986646083204E-5,0.25,-1.36391581747007E-6,4.13238813614251E-5,-1.13927559249954E-6,25.657547,26.639101,999.675,999.675,52.6137605149863,18.5064669869928,35.926437,0,0,0,1201,4882,26.4866,999.675,,,,,,,,,,,,,0,,,,2.94613615,,,,,,26.148324,,,,
,12928886.875,42.9523869,999.675,4.13883568121499E-5,3.86550366473602E-8,1,30.0025819559455,40.0298881530762,1.99301350676236,5.9000002220273,0.000443230832554765,6.4891074375309E-5,0.25,-1.32579873421542E-6,4.12664191403306E-5,-1.02715634500996E-6,42.496769,43.4080048,999.675,999.675,53.3992971768133,18.5087836053272,35.926437,0,0,0,1201,4882,43.7443,999.675,,,,,,,,,,,,,0,,,,3.3883821,,,,,,42.9523869,,,,
,12929305.51,56.6477585,999.675,4.13087118009048E-5,4.08057450290932E-8,1,30.0025819559455,40.0298881530762,2.0068632139289,5.90999983251095,0.000447273855806129,6.52115792787428E-5,0.25,-1.34580331565789E-6,4.13629561295595E-5,-1.05414993443679E-6,56.1586914,57.1368256,999.675,999.675,53.2687652141018,18.5184769603029,35.164013,0,0,0,1201,4886,57.93115,999.675,,,,,,,,,,,,,0,,,,3.52652155,,,,,,56.6477585,,,,
,12929727.48,70.4289474,999.675,,,2,,,,5.88999999772757,,,,,,,70.4289474,70.4289474,999.675,999.675,,,35.926437,,,,-99999999,4886,72.2498,999.675,,,,,,,,,,,,,,,,,,,,,,,70.4289474,,,,
,12930265.65,88.0714798,999.675,4.12629125170588E-5,4.16466400253307E-8,1,30.0025819559455,40.0298881530762,1.98225192731161,5.8699999935925,0.000443325999290614,6.35013632602439E-5,0.25,-1.30774125439492E-6,4.14682947794098E-5,-1.16086952201471E-6,87.5832367,88.5597229,999.675,999.675,53.2820528989287,18.5097581359693,35.926437,0,0,0,1201,4886,90.4606,999.675,,,,,,,,,,,,,0,,,,3.8777423,,,,,,88.0714798,,,,
,12930717.17,102.8985519,999.675,,,2,,,,5.81999998858198,,,,,,,102.8985519,102.8985519,999.675,999.675,,,35.926437,,,,-99999999,4886,105.7545,999.675,,,,,,,,,,,,,,,,,,,,,,,102.8985519,,,,
,12931180.115,118.25120925,999.675,4.21474227919979E-5,4.54714906958976E-8,1,30.0025819559455,40.0298881530762,1.98209833341137,5.77999977394938,0.000452830401245303,6.47285348016029E-5,0.25,-1.2856062114589E-6,4.23583722023534E-5,-1.19809989555935E-6,118.2330627,118.2693558,999.675,999.675,53.6259694473903,18.5196246511306,35.926437,0,0,0,1201,4886,121.46585,999.675,,,,,,,,,,,,,0,,,,3.9400685,,,,,,118.25120925,,,,
,12931555.73,130.73825835,999.675,4.27955750763491E-5,4.68928935706941E-8,1,30.0025819559455,40.0298881530762,1.9822570041382,5.7600000873208,0.000459759134641281,6.56169018522836E-5,0.25,-1.30069569318152E-6,4.30015885718594E-5,-1.22565384059847E-6,130.235672,131.2408447,999.675,999.675,52.3847433588517,18.5151341059615,35.926437,0,0,0,1201,4886,134.184,999.675,,,,,,,,,,,,,0,,,,4.17928265,,,,,,130.73825835,,,,
,12931945.77,143.73391725,999.675,4.29584338273985E-5,4.62631533879901E-8,1,30.0025819559455,40.0298881530762,1.98221578170017,5.70000009611249,0.000461411953996819,6.56806993989479E-5,0.25,-1.3105775315444E-6,4.31543385734862E-5,-1.24579540411196E-6,143.2311249,144.2367096,999.675,999.675,52.4152268711017,18.5143430618924,35.926437,0,0,0,1201,4886,147.37305,999.675,,,,,,,,,,,,,0,,,,4.20099615,,,,,,143.73391725,,,,
,12932335.805,156.7029877,999.675,4.3050642718047E-5,4.97899086720836E-8,1,30.0025819559455,40.0298881530762,1.98206830249917,5.66999986767769,0.000462134547986908,6.63759010483098E-5,0.25,-1.25110303341133E-6,4.32343058222527E-5,-1.19375521762875E-6,156.2016144,157.204361,999.675,999.675,53.1437046510249,18.5231408234183,36.688858,0,0,0,1201,4886,160.4819,999.675,,,,,,,,,,,,,0,,,,4.24253865,,,,,,156.7029877,,,,
touchdown = 0.500000023748726 mm,12932827.81,173.0314178,999.675,4.31320339637067E-5,4.95769873411854E-8,1,30.0025819559455,40.0298881530762,1.98215675273781,5.57000003755093,0.000462924357839986,6.59907643495037E-5,0.25,-1.29119742041186E-6,4.32985142895505E-5,-1.24126176028452E-6,173.0314178,173.0314178,999.675,999.675,53.2789263848518,18.5179070141174,35.926437,0,0,0,1201,4886,176.9744,999.675,,,,,,,,,,,,,0,,,,4.1584077,,,,,,173.0314178,,,,
,12933176.165,184.5848312,999.675,4.33181514256642E-5,5.10996513133323E-8,1,30.0025819559455,40.0298881530762,2.0066418065141,5.52000012248754,0.000470432329459231,6.6191243018995E-5,0.25,-1.37095601815287E-6,4.34720270840522E-5,-1.32510115091237E-6,184.0919189,185.0777435,999.675,999.675,53.5517147380633,18.5267150593285,35.926437,0,0,0,1201,4886,188.64615,999.675,,,,,,,,,,,,,0,,,,4.4374449,,,,,,184.5848312,,,,
,12933565.945,197.53064725,999.675,4.34967866062299E-5,5.23096655539604E-8,1,30.0025819559455,40.0298881530762,1.99285494894218,5.47000020742416,0.000469065406594743,6.61380182537506E-5,0.25,-1.35982346508665E-6,4.36354577391749E-5,-1.3173823790439E-6,197.0325012,198.0287933,999.675,999.675,52.771649475871,18.5151710160518,35.164013,0,0,0,1201,4886,201.69395,999.675,,,,,,,,,,,,,0,,,,4.4374449,,,,,,197.53064725,,,,
,12933956.015,210.49336245,999.675,4.36891633190073E-5,5.34922031884668E-8,1,30.0025819559455,40.0298881530762,1.99283630062124,5.42999990284443,0.0004710749711122,6.57276793252494E-5,0.25,-1.42550486400151E-6,4.38119618643186E-5,-1.38604262414786E-6,209.9934845,210.9932404,999.675,999.675,53.1515209362172,18.5188150645121,35.545227,0,0,0,1201,4886,214.7477,999.675,,,,,,,,,,,,,0,,,,4.46049955,,,,,,210.49336245,,,,
,12934347.77,223.4944916,999.675,,,2,,,,5.31000000510365,,,,,,,223.4944916,223.4944916,999.675,999.675,,,35.545227,,,,-99999999,4886,227.8546,999.675,,,,,,,,,,,,,,,,,,,,,,,223.4944916,,,,
,12934809.975,238.88258365,999.675,4.43163663112799E-5,5.56463773053939E-8,1,30.0025819559455,40.0298881530762,1.98206030251661,5.24999992921948,0.00047491436579488,6.64521400091111E-5,0.25,-1.42252482649093E-6,4.44024598799773E-5,-1.38739617631292E-6,238.8481293,238.917038,999.675,999.675,52.6426807701979,18.5240451051717,35.545227,0,0,0,1201,4886,243.32475,999.675,,,,,,,,,,,,,0,,,,4.2954005,,,,,,238.88258365,,,,
,12935186.185,251.41783905,999.675,4.46014666612583E-5,5.83399885877214E-8,1,30.0025819559455,40.0298881530762,1.9820100203361,5.14000002294779,0.000477525723740092,6.82636547109117E-5,0.25,-1.29690957167272E-6,4.46703976195016E-5,-1.26302558853413E-6,250.9182739,251.9174042,999.675,999.675,53.0037931460825,18.5238070753131,35.545227,0,0,0,1201,4886,255.89735,999.675,,,,,,,,,,,,,0,,,,4.6416528,,,,,,251.41783905,,,,
,12935576.16,264.3631744,999.675,4.49554651472425E-5,5.85659291428266E-8,1,30.0025819559455,40.0298881530762,1.9930094046578,5.09000010788441,0.00048376995303357,6.86228891244322E-5,0.25,-1.3537452899781E-6,4.50064476565356E-5,-1.32120457263879E-6,263.8622131,264.8641357,999.675,999.675,53.2351551877748,18.525880247731,35.164013,0,0,0,1201,4886,268.9435,999.675,,,,,,,,,,,,,0,,,,4.7115545,,,,,,264.3631744,,,,
,12935966.265,277.38804625,999.675,4.54160452863507E-5,6.05436702588298E-8,1,30.0025819559455,40.0298881530762,1.98204678814098,5.02000004053116,0.000485925446005577,6.9033274586064E-5,0.25,-1.35612733326423E-6,4.54485770238507E-5,-1.32458290559746E-6,276.8873596,277.8887329,999.675,999.675,53.2515693866787,18.5301454831485,35.926437,0,0,0,1201,4886,281.9952,999.675,,,,,,,,,,,,,0,,,,4.7350883,,,,,,277.38804625,,,,
touchdown = -0.180000002728775 mm,12936459.3,293.7911377,999.675,4.59119061745848E-5,6.15692884237801E-8,1,30.0025819559455,40.0298881530762,1.99300319106361,4.88999998196959,0.000493628361628413,6.98218945804874E-5,0.25,-1.39668016239628E-6,4.59206263095628E-5,-1.36624277550077E-6,293.7755127,293.8067627,999.675,999.675,53.3703769216018,18.520730055082,35.926437,0,0,0,1201,4886,298.48535,999.675,,,,,,,,,,,,,0,,,,4.8791447,,,,,,293.7911377,,,,
,12936806.29,305.35784915,999.675,4.66113242612411E-5,6.74724896824745E-8,1,30.0025819559455,40.0298881530762,1.98206874352781,4.81999991461635,0.000498359804821935,7.0281960819425E-5,0.25,-1.43578394695265E-6,4.66029384169212E-5,-1.4057386171003E-6,304.864563,305.8511353,999.675,999.675,52.4457103833517,18.523634446517,35.926437,0,0,0,1201,4886,310.0981,999.675,,,,,,,,,,,,,0,,,,4.8791447,,,,,,305.35784915,,,,
,12937196.28,318.3394012,999.675,4.73528733499178E-5,6.52230281260294E-8,1,30.0025819559455,40.0298881530762,1.98212711339564,4.7499998472631,0.000505905801917551,7.24629991184132E-5,0.25,-1.35465724847607E-6,4.73247768347898E-5,-1.32501882486646E-6,317.8424377,318.8363647,999.675,999.675,53.3344220097172,18.5280189148197,35.926437,0,0,0,1201,4886,323.16315,999.675,,,,,,,,,,,,,0,,,,4.8308864,,,,,,318.3394012,,,,
,12937586.32,331.30235295,999.675,4.78631524165979E-5,6.78908984039765E-8,1,30.0025819559455,40.0298881530762,1.98228845221288,4.66000009328127,0.000511161465104134,7.33829685789866E-5,0.25,-1.35264425438656E-6,4.78153031164832E-5,-1.32341767400125E-6,330.8016663,331.8030396,999.675,999.675,53.2163961033133,18.5262216745061,35.164013,0,0,0,1201,4886,336.24625,999.675,,,,,,,,,,,,,0,,,,4.8114345,,,,,,331.30235295,,,,
,12937978.72,344.3110962,999.675,,,2,,,,4.5400000209175,,,,,,,344.3110962,344.3110962,999.675,999.675,,,35.164013,,,,-99999999,4886,349.3964,999.675,,,,,,,,,,,,,,,,,,,,,,,344.3110962,,,,
,12938366.405,354.3206482,999.675,4.93346126823408E-5,7.23757232586092E-8,1,30.0025819559455,40.0298881530762,1.98238931575169,4.53000003471971,0.000526001958937533,7.86583168809828E-5,0.25,-1.10366420451464E-6,4.92504704003514E-5,-1.0746985258811E-6,354.2472839,354.3940125,999.675,999.675,53.5665656799287,18.5303120777836,35.926437,0,0,0,1201,4886,355.9871,999.675,,,,,,,,,,,,,0,,,,5.4458747,,,,,,354.3206482,,,,
,12963863.33,300.0005035,39997.436,0.000311678423771332,6.15679376880008E-7,1,60.005163911891,40.0298881530762,1.98229792657104,4.51999995857477,0.00330088949319185,0.000658147510734643,0.25,8.0703629407381E-6,0.000311663924956409,8.27550419471557E-6,299.9993896,300.0016174,39996.895,39997.977,53.6314408470249,18.507835992966,35.545227,0,0,0,2402,4929,300.02525,39997.436,,,,,,,,,,,,,0,,,,5.01308415,,,,,,300.0005035,,,,
,12965843.5,299.99734495,12500.017,0.000295914667040919,2.06422964954872E-7,1,60.005163911891,40.0298881530762,1.98223992805773,4.51999995857477,0.00314562535921492,0.000556629027438525,0.25,1.24879821716103E-6,0.00029590505556889,1.44483855056479E-6,299.9965515,299.9981384,12499.939,12500.095,53.5634391658518,18.5196926970807,35.545227,0,0,0,2402,4929,300.0659,12500.017,,,,,,,,,,,,,0,,,,5.2081041,,,,,,299.99734495,,,,
,12968995.595,299.9985199,-14999.992,-0.000259860004206811,2.41434001894581E-7,1,60.005163911891,40.0298881530762,1.98249827722126,4.51999995857477,-0.00275326901977111,-0.000538593942537835,2.5,-5.78552733570812E-6,-0.000259848455696287,-5.95746578083036E-6,299.9982605,299.9987793,-15000.55,-14999.434,53.4618274583518,18.5276087315535,34.020382,0,0,0,2402,4929,300.0621,-14999.992,,,,,,,,,,,,,0,,,,5.1805391,,,,,,299.9985199,,,,
,12971003.935,300.00411985,-42500.8025,-0.000283689230710087,6.3962434848485E-7,1,60.005163911891,40.0298881530762,1.98245486407016,4.51999995857477,-0.00299847993125976,-0.000635086033325629,0.25,-1.07290959095248E-5,-0.000283673785089783,-1.09156072452262E-5,300.0032043,300.0050354,-42501.707,-42499.898,53.2922140696787,18.5324514402546,35.926437,0,0,0,2402,4929,300.02585,-42500.8025,,,,,,,,,,,,,0,,,,5.3381476,,,,,,300.00411985,,,,
,12972984.17,299.99617005,-29997.508,-0.00029781414536923,4.81916733010941E-7,1,60.005163911891,40.0298881530762,1.98230746482846,4.53000003471971,-0.00315297737294005,-0.000635214538468916,0.25,-8.30693490492709E-6,-0.000297799890766524,-8.50335699646586E-6,299.9951477,299.9971924,-29999.213,-29995.803,53.6165899051595,18.5355585685438,35.164013,0,0,0,2402,4929,300.03995,-29997.508,,,,,,,,,,,,,0,,,,5.2588184,,,,,,299.99617005,,,,
,12975296.725,299.99563595,-2499.877,-0.000246534961883542,9.64082998218205E-8,1,60.005163911891,40.0298881530762,1.98246515466092,4.51999995857477,-0.00261649070932097,-0.00048521404191712,2.5,-3.06712854181242E-6,-0.000246525598635731,-3.2306511834914E-6,299.9952087,299.9960632,-2499.906,-2499.848,53.0944620543133,18.5311489799718,35.926437,0,0,0,2402,4929,300.07785,-2499.877,,,,,,,,,,,,,0,,,,5.28534935,,,,,,299.99563595,,,,
,12978024.61,299.9987793,25001.864,0.000371255452020156,1.56042289746847E-6,1,60.005163911891,40.0298881530762,1.98235482225937,4.51999995857477,0.00393599753353746,0.000760575069807088,0.25,7.41285252125547E-6,0.000371239567559622,7.65804144978954E-6,299.9985962,299.9989624,25001.322,25002.406,53.1562107073326,18.5328883721977,35.545227,0,0,0,2402,4929,300.0561,25001.864,,,,,,,,,,,,,0,,,,5.3381476,,,,,,299.9987793,,,,
,13022890.23,4.9972405,999.788,,,2,,,,5.81000002481043,,,,,,,4.9972405,4.9972405,999.788,999.788,,,117.505661,,,,-99999999,4881,4.9958,999.788,,,,,,,,,,,,,,,,,,,,,,,4.9972405,,,,
,13023361.395,13.85140465,999.788,0.000240471889528944,1.08751066344343E-7,1,30.0025819559455,40.0298881530762,1.98173767504776,5.79999992623925,0.0025393069926497,0.000448504695731322,0.25,-7.92586948215665E-8,0.000238914472837452,1.09045174998538E-6,13.3527784,14.3500309,999.788,999.788,52.5762423460633,18.495849164584,116.74324,0,0,0,1201,4882,13.98595,999.788,,,,,,,,,,,,,0,,,,27.62374115,,,,,,13.85140465,,,,
touchdown = 0.920000020414591 mm,13023888.83,31.2833881,999.788,0.000242170623871229,2.86949858200264E-7,1,30.0025819559455,40.0298881530762,2.00664849082173,5.83000015467405,0.00258966019594081,0.000459954966243659,0.25,-4.97708730970027E-8,0.00024078894627046,1.3295014960217E-6,31.2833881,31.2833881,999.788,999.788,52.4371124696402,18.5021272187004,116.74324,0,0,0,1201,4882,31.69585,999.788,,,,,,,,,,,,,0,,,,40.3599472,,,,,,31.2833881,,,,
,13024291.51,44.5284691,999.788,0.000135187434357822,4.32536943494945E-7,1,30.0025819559455,40.0298881530762,1.98195629061789,5.83000015467405,0.00143378493289592,0.000249336296375564,0.25,-7.21484202075539E-7,0.000134824190349501,2.59033670315224E-7,44.0359459,45.0209923,999.788,999.788,52.9819075475441,18.499565681211,117.124451,0,0,0,1201,4882,45.27695,999.788,,,,,,,,,,,,,0,,,,40.16716385,,,,,,44.5284691,,,,
,13024711.54,58.30090335,999.788,0.000184148047935045,7.17840697496085E-8,1,30.0025819559455,40.0298881530762,1.98192880360207,5.83000015467405,0.00196176029998845,0.000338213792013873,0.25,-1.19242402321544E-6,0.000184428040391716,8.61859286503853E-8,57.8094864,58.7923203,999.788,999.788,52.7036477946979,18.5013287765171,116.36203,0,0,0,1201,4886,59.48195,999.788,,,,,,,,,,,,,0,,,,41.6301708,,,,,,58.30090335,,,,
,13025221.88,75.0155716,999.788,0.000132329130921828,8.41729500888108E-7,1,30.0025819559455,40.0298881530762,1.99260686314149,5.79999992623925,0.00142160443018095,0.000240361591999252,0.25,-1.01826662251408E-6,0.000132885868472966,-3.67299151650654E-7,74.5262985,75.5048447,999.788,999.788,53.0975885683902,18.4942579538303,115.980812,0,0,0,1201,4886,76.74725,999.788,,,,,,,,,,,,,0,,,,53.3862858,,,,,,75.0155716,,,,
,13025671.635,89.78121565,999.788,0.00012512599417368,5.7851168427988E-8,1,30.0025819559455,40.0298881530762,1.98195611026679,5.78999985009432,0.00133869378866869,0.000223829170642693,0.25,-1.02367401011891E-6,0.000125741608685187,-5.77207117977771E-7,89.2920303,90.270401,999.788,999.788,52.7591434195633,18.502601815256,116.74324,0,0,0,1201,4886,91.92915,999.788,,,,,,,,,,,,,0,,,,47.21279715,,,,,,89.78121565,,,,
,13026195.63,107.057045,999.788,0.000146493942597264,5.1898843126651E-8,1,30.0025819559455,40.0298881530762,1.98205786084794,5.73999993503094,0.00156738774442223,0.00026313681079811,0.25,-9.60747241504457E-7,0.00014723204737784,-5.78082023544299E-7,107.0021439,107.1119461,999.788,999.788,52.3878698729286,18.5041048863468,117.124451,0,0,0,1201,4886,109.65535,999.788,,,,,,,,,,,,,0,,,,48.35106275,,,,,,107.057045,,,,
,13026571.705,119.55203245,999.788,0.000149120021758188,5.17312238159725E-8,1,30.0025819559455,40.0298881530762,1.98199077642282,5.70000009611249,0.00159543168179219,0.000266848688194406,0.25,-1.00245597637641E-6,0.000149855578362717,-6.79400362500055E-7,119.0587616,120.0453033,999.788,999.788,52.7857187892171,18.5071487512288,116.74324,0,0,0,1201,4886,122.3819,999.788,,,,,,,,,,,,,0,,,,57.31030845,,,,,,119.55203245,,,,
,13026961.75,132.52986145,999.788,0.000149685602632558,5.32669098184117E-8,1,30.0025819559455,40.0298881530762,1.98184896382148,5.65999979153276,0.00160111462857601,0.000267460807367417,0.25,-9.87723162437062E-7,0.000150394386032128,-7.1276603672919E-7,132.0302277,133.0294952,999.788,999.788,52.829489986294,18.5093842740309,117.124451,0,0,0,1201,4886,135.5618,999.788,,,,,,,,,,,,,0,,,,47.66740035,,,,,,132.52986145,,,,
,13027351.79,145.5258255,999.788,0.000153897904017305,5.27186990510714E-8,1,30.0025819559455,40.0298881530762,1.98167545840932,5.60999987646937,0.0016458347159903,0.000273643087797551,0.25,-1.09532884658209E-6,0.00015458776582398,-8.50356621310571E-7,145.0308685,146.0207825,999.788,999.788,53.0319317727748,18.5093063212673,116.74324,0,0,0,1201,4886,148.72055,999.788,,,,,,,,,,,,,0,,,,61.4062557,,,,,,145.5258255,,,,
touchdown = 0.609999988228083 mm,13027845.93,161.9575806,999.788,0.000146894355467058,1.05792193594913E-7,1,30.0025819559455,40.0298881530762,1.99269819383167,5.52000012248754,0.00157928275790681,0.000259313210535978,0.25,-1.3078558487217E-6,0.000147498140860277,-1.10817455779024E-6,161.9575806,161.9575806,999.788,999.788,53.0069196601595,18.5067943983391,117.124451,0,0,0,1201,4886,165.3037,999.788,,,,,,,,,,,,,0,,,,62.9552078,,,,,,161.9575806,,,,
,13028221.87,174.423996,999.788,0.000123273855438346,2.43405582897639E-7,1,30.0025819559455,40.0298881530762,1.98192555451826,5.47999981790781,0.00131850287633836,0.000213774938254848,0.25,-1.32898517151184E-6,0.000123742105925064,-1.17827611117251E-6,173.9277649,174.9202271,999.788,999.788,53.0413113150056,18.5108199300729,117.124451,0,0,0,1201,4886,177.8952,999.788,,,,,,,,,,,,,0,,,,62.676733,,,,,,174.423996,,,,
,13028611.89,187.38124085,999.788,0.000127370689566846,1.19788041246753E-7,1,30.0025819559455,40.0298881530762,1.98191216680665,5.42999990284443,0.00136197640925485,0.000220014903232702,0.25,-1.43270921126791E-6,0.0001278102531788,-1.29096390234835E-6,186.8836517,187.87883,999.788,999.788,52.7982248455248,18.513538960693,116.74324,0,0,0,1201,4886,190.9643,999.788,,,,,,,,,,,,,0,,,,57.69940565,,,,,,187.38124085,,,,
,13029001.93,200.3373566,999.788,0.000126455035380114,5.28627590878174E-8,1,30.0025819559455,40.0298881530762,1.99271145069106,5.35999983549118,0.00135957320001647,0.000214801960183882,0.25,-1.84845045042248E-6,0.000126845683534143,-1.7202167865555E-6,199.838028,200.8366852,999.788,999.788,52.8396511570441,18.5111289730525,116.74324,0,0,0,1201,4886,204.023,999.788,,,,,,,,,,,,,0,,,,64.5449066,,,,,,200.3373566,,,,
touchdown = 0.339999998686835 mm,13029493.965,216.6856232,999.788,0.000126871071420768,5.41650069538311E-8,1,30.0025819559455,40.0298881530762,1.98176857215699,5.24999992921948,0.00135606616972559,0.000215070685768274,0.25,-1.76724060303008E-6,0.000127201850184439,-1.64973916889397E-6,216.6856232,216.6856232,999.788,999.788,52.9248486656402,18.5165429256556,116.74324,0,0,0,1201,4886,220.49245,999.788,,,,,,,,,,,,,0,,,,65.23196985,,,,,,216.6856232,,,,
,13029842.055,228.2538223,999.788,0.000130985996490909,6.92151971364832E-8,1,30.0025819559455,40.0298881530762,1.99305044613043,5.17999986186624,0.00140716242008946,0.000223423389155715,0.25,-1.7943841241985E-6,0.000131281461608335,-1.67999578304707E-6,227.761734,228.7459106,999.788,999.788,53.0913355402364,18.5111783292344,116.36203,0,0,0,1201,4886,232.1345,999.788,,,,,,,,,,,,,0,,,,64.37957,,,,,,228.2538223,,,,
,13030262.065,242.20796965,999.788,0.000127951875104854,5.58591328665524E-8,1,30.0025819559455,40.0298881530762,1.98229272240125,5.10999979451299,0.00136686536333014,0.000216963419233843,0.25,-1.75061971099923E-6,0.000128185110773155,-1.64602352270664E-6,241.7102661,242.7056732,999.788,999.788,53.0123910597941,18.5178152457709,116.74324,0,0,0,1201,4886,246.1794,999.788,,,,,,,,,,,,,0,,,,58.5787563,,,,,,242.20796965,,,,
,13030652.09,255.18111415,999.788,0.00012729103914965,5.89874330609831E-8,1,30.0025819559455,40.0298881530762,2.00711500243299,5.03000011667609,0.00137570188114667,0.000217616558356835,0.25,-1.80284564761417E-6,0.000127471043612089,-1.70461146239361E-6,254.6778564,255.6843719,999.788,999.788,52.9819075475441,18.5243345678225,115.980812,0,0,0,1201,4886,259.216,999.788,,,,,,,,,,,,,0,,,,70.2641754,,,,,,255.18111415,,,,
touchdown = -0.0299999992421363 mm,13031146.07,271.6283569,999.788,0.000132379363554701,6.12894440353366E-8,1,30.0025819559455,40.0298881530762,1.98222006008046,4.87999990582466,0.00141297608012984,0.000223204637269921,0.25,-1.89563124506905E-6,0.000132497134790011,-1.80002144807148E-6,271.6283569,271.6283569,999.788,999.788,52.8607551270633,18.5203974511726,117.124451,0,0,0,1201,4886,275.75765,999.788,,,,,,,,,,,,,0,,,,70.26774595,,,,,,271.6283569,,,,
,13031492.24,283.15487675,999.788,0.000136160796925384,6.44735542742464E-8,1,30.0025819559455,40.0298881530762,1.99309950893054,4.82999999076128,0.0014603771648498,0.000231146302589833,0.25,-1.90369181431766E-6,0.000136231582755455,-1.80944551493794E-6,282.6589661,283.6507874,999.788,999.788,52.6950498809863,18.5151422079773,116.74324,0,0,0,1201,4886,287.3486,999.788,,,,,,,,,,,,,0,,,,60.1292553,,,,,,283.15487675,,,,
,13031882.225,296.1214142,999.788,0.000135857520731686,6.27983213741497E-8,1,30.0025819559455,40.0298881530762,1.98230315680451,4.75999992340803,0.00144915699103081,0.000228113903713154,0.25,-2.00951231599471E-6,0.000135871757960904,-1.91963119351962E-6,295.6228333,296.6199951,999.788,999.788,53.1890391051402,18.5213516189213,116.74324,0,0,0,1201,4886,300.40955,999.788,,,,,,,,,,,,,0,,,,71.6821442,,,,,,296.1214142,,,,
,13032272.26,309.1125946,999.788,0.000136344955389452,6.65498741548923E-8,1,30.0025819559455,40.0298881530762,1.98239850928356,4.68999985605478,0.00145402240196172,0.000227679239654864,0.25,-2.12220487408462E-6,0.000136302798018698,-2.03557745329156E-6,308.6115723,309.6136169,999.788,999.788,52.9178140089671,18.5209334386575,117.124451,0,0,0,1201,4886,313.4548,999.788,,,,,,,,,,,,,0,,,,67.7275276,,,,,,309.1125946,,,,
touchdown = -0.36000000545755 mm,13032796.015,326.5498657,999.788,0.000138044064211785,6.9212068513692E-8,1,30.0025819559455,40.0298881530762,1.98233970483655,4.54000011086464,0.00147144740254832,0.000229473597187415,0.25,-2.22897754262573E-6,0.000137925518202877,-2.14530626940222E-6,326.5498657,326.5498657,999.788,999.788,53.1194741669287,18.517291377804,116.74324,0,0,0,1201,4886,331.0062,999.788,,,,,,,,,,,,,0,,,,70.6874161,,,,,,326.5498657,,,,
,13033142.555,338.0776825,999.788,0.000138191341770961,6.71473268137969E-8,1,30.0025819559455,40.0298881530762,1.98237318949707,4.47000004351139,0.00147234287278254,0.000230632744880861,0.25,-2.13493292388757E-6,0.000138023216551347,-2.05351152699448E-6,337.5927734,338.5625916,999.788,999.788,53.0327134012941,18.5186077995064,116.36203,0,0,0,1201,4886,342.6289,999.788,,,,,,,,,,,,,0,,,,72.77258305,,,,,,338.0776825,,,,
,13033532.46,351.05537415,999.788,0.000132596405829883,7.09950567626574E-8,1,30.0025819559455,40.0298881530762,1.98241348680179,4.41000005230308,0.00141354196294383,0.000213441279759272,0.25,-2.77728685050953E-6,0.000132383155034391,-2.69996992108235E-6,350.5534973,351.557251,999.788,999.788,53.2031084184864,18.5225943214888,117.124451,0,0,0,1201,4886,355.69625,999.788,,,,,,,,,,,,,0,,,,69.92196655,,,,,,351.05537415,,,,
,13033922.41,354.83706665,999.788,0.000133618179172448,7.28242141241287E-8,1,30.0025819559455,40.0298881530762,1.99327657008745,4.33999998494983,0.00143170463937585,0.000216527299178795,0.25,-2.76729314338147E-6,0.000133388100612083,-2.68916448906857E-6,354.8078918,354.8662415,999.788,999.788,52.9905054612556,18.5158480876816,117.124451,0,0,0,1201,4881,355.89745,999.788,,,,,,,,,,,,,0,,,,68.53023335,,,,,,354.83706665,,,,
,13039202.945,13.2711873,999.788,0.000145275758237376,3.83821758697698E-8,1,30.0025819559455,40.0298881530762,1.98199001305819,5.65000018104911,0.00153618467984223,0.000260086210859448,0.25,-1.08017805024577E-6,0.000144340083188876,-3.66836579740187E-7,12.7779369,13.7644377,999.788,999.788,52.3995943007171,18.4966576424977,116.74324,0,0,0,1201,4882,13.4164,999.788,,,,,,,,,,,,,0,,,,24.0937805,,,,,,13.2711873,,,,
,13039624,27.1858559,999.788,,,2,,,,5.74000001566485,,,,,,,27.1858559,27.1858559,999.788,999.788,,,116.74324,,,,-99999999,4882,27.5543,999.788,,,,,,,,,,,,,,,,,,,,,,,27.1858559,,,,
,13040132.98,43.9508972,999.788,0.000144949651369292,3.96688918994439E-8,1,30.0025819559455,40.0298881530762,1.98179974351186,5.729999858886,0.00153754966963759,0.000263861629044807,0.25,-1.08951400672996E-6,0.000144537295360621,-4.35615337968427E-8,43.4541168,44.4476776,999.788,999.788,53.1710616491979,18.5012453651153,117.124451,0,0,0,1201,4882,44.6932,999.788,,,,,,,,,,,,,0,,,,44.45706365,,,,,,43.9508972,,,,
,13040553.07,57.7214451,999.788,0.000145810792952207,4.20307422693415E-8,1,30.0025819559455,40.0298881530762,1.98185658693647,5.71999978274107,0.00155365640889406,0.000264478681955229,0.25,-1.26028505997769E-6,0.000146013682269455,-2.40060693949263E-7,57.2266541,58.2162361,999.788,999.788,53.1429230225056,18.5070135959848,116.74324,0,0,0,1201,4886,58.9018,999.788,,,,,,,,,,,,,0,,,,51.0388222,,,,,,57.7214451,,,,
touchdown = 0.809999997727573 mm,13041079.11,74.9672775,999.788,0.000145450639590332,4.37130198745607E-8,1,30.0025819559455,40.0298881530762,1.99262192941981,5.729999858886,0.00156296896490941,0.000261958813242951,0.25,-1.32858920389489E-6,0.000146063010874653,-6.13137494839927E-7,74.9672775,74.9672775,999.788,999.788,52.6684745113325,18.5040872799434,116.74324,0,0,0,1201,4886,76.6962,999.788,,,,,,,,,,,,,0,,,,53.6529694,,,,,,74.9672775,,,,
,13041513.205,89.23563,999.788,0.000144627275333648,4.55762110400286E-8,1,30.0025819559455,40.0298881530762,2.00666668616588,5.71000017225742,0.00156596088203519,0.000260986353718041,0.25,-1.26475701092493E-6,0.000145337210438529,-7.43170747542588E-7,88.7364883,89.7347717,999.788,999.788,52.8959284104287,18.5096632870492,116.74324,0,0,0,1201,4886,91.35045,999.788,,,,,,,,,,,,,0,,,,55.84305575,,,,,,89.23563,,,,
touchdown = 0.750000006519258 mm,13042068.36,107.5146332,999.788,0.000140574562462706,4.6292059557222E-8,1,30.0025819559455,40.0298881530762,1.98182313155858,5.65999979153276,0.00150470899850656,0.000247730869867551,0.25,-1.36316761711416E-6,0.000141283755478536,-1.00092011315953E-6,107.5146332,107.5146332,999.788,999.788,53.0264603731402,18.5074681916391,115.980812,0,0,0,1201,4886,110.129,999.788,,,,,,,,,,,,,0,,,,50.16602705,,,,,,107.5146332,,,,
,13042473.27,120.97078705,999.788,0.000141730021023102,4.58066595075056E-8,1,30.0025819559455,40.0298881530762,1.9817695441569,5.61999995261431,0.00151698410877664,0.000248954531545246,0.25,-1.38093318686922E-6,0.000142427501629023,-1.08191273674535E-6,120.4675369,121.4740372,999.788,999.788,53.0248971161018,18.5108199085014,117.124451,0,0,0,1201,4886,123.83235,999.788,,,,,,,,,,,,,0,,,,51.03108405,,,,,,120.97078705,,,,
,13042863.36,133.9639282,999.788,0.000145262184915583,5.81114185218527E-8,1,30.0025819559455,40.0298881530762,1.98188291886469,5.58000011369586,0.00155462291479451,0.000254735082973932,0.25,-1.40522407864477E-6,0.000145947116169603,-1.14489087322752E-6,133.4495544,134.478302,999.788,999.788,52.690360109871,18.5061500453765,116.36203,0,0,0,1201,4886,137.00805,999.788,,,,,,,,,,,,,0,,,,55.8849125,,,,,,133.9639282,,,,
,13043254.67,146.9983826,999.788,,,2,,,,5.52000002849847,,,,,,,146.9983826,146.9983826,999.788,999.788,,,117.124451,,,,-99999999,4886,150.2178,999.788,,,,,,,,,,,,,,,,,,,,,,,146.9983826,,,,
,13043717.56,162.37363435,999.788,0.000140293625335342,4.9098424824689E-8,1,30.0025819559455,40.0298881530762,2.00667969991418,5.47000020742416,0.00151908920205158,0.000245643082881291,0.25,-1.58907799531432E-6,0.000140869335772381,-1.40045099981104E-6,162.3551941,162.3920746,999.788,999.788,52.9264119226787,18.5126706732784,116.36203,0,0,0,1201,4886,165.73415,999.788,,,,,,,,,,,,,0,,,,63.2681141,,,,,,162.37363435,,,,
,13044093.44,174.87335205,999.788,0.000140227285008845,5.04659188262321E-8,1,30.0025819559455,40.0298881530762,1.98177165136436,5.42999990284443,0.00149983556381504,0.000242386133620376,0.25,-1.58310221944314E-6,0.000140758370710825,-1.41247859904171E-6,174.3748474,175.3718567,999.788,999.788,52.9053079526594,18.5115554982202,117.886871,0,0,0,1201,4886,178.3193,999.788,,,,,,,,,,,,,0,,,,53.9671993,,,,,,174.87335205,,,,
,13044483.445,187.8080597,999.788,0.000139745483320587,5.12235671130204E-8,1,30.0025819559455,40.0298881530762,1.98196325795602,5.36999991163611,0.00149451187637568,0.000240283387549486,0.25,-1.6754882216654E-6,0.000140226225481603,-1.5207694279441E-6,187.3266449,188.2894745,999.788,999.788,52.8373062714864,18.5153448744728,116.74324,0,0,0,1201,4886,191.3918,999.788,,,,,,,,,,,,,0,,,,65.8474617,,,,,,187.8080597,,,,
,13044873.475,200.7809601,999.788,0.000139264287288343,5.33903634871256E-8,1,30.0025819559455,40.0298881530762,1.98201149917612,5.33000007271767,0.00148904589018907,0.000238278941610357,0.25,-1.759647442909E-6,0.000139692432021166,-1.61794471077315E-6,200.2785187,201.2834015,999.788,999.788,52.6645663687363,18.5170347550168,116.74324,0,0,0,1201,4886,204.45735,999.788,,,,,,,,,,,,,0,,,,53.7383022,,,,,,200.7809601,,,,
touchdown = 0.300000014249235 mm,13045366.115,217.1349182,999.788,0.000139015451513189,5.66745499797975E-8,1,30.0025819559455,40.0298881530762,1.98204866175171,5.21000009030104,0.00148583528300427,0.000236948347729346,0.25,-1.81775072318357E-6,0.000139375903389333,-1.68900350433061E-6,217.1349182,217.1349182,999.788,999.788,52.9115609808133,18.5180286842104,117.124451,0,0,0,1201,4886,220.9447,999.788,,,,,,,,,,,,,0,,,,57.67990685,,,,,,217.1349182,,,,
,13045713.53,228.696167,999.788,0.000138469299809738,5.72323117068071E-8,1,30.0025819559455,40.0298881530762,1.98184529232319,5.15000009909272,0.00147926560226933,0.0002363036076797,0.25,-1.76588099166997E-6,0.000138779644170658,-1.6449094747247E-6,228.2052765,229.1870575,999.788,999.788,52.8748244404094,18.5207667183042,117.124451,0,0,0,1201,4886,232.54915,999.788,,,,,,,,,,,,,0,,,,64.94826695,,,,,,228.696167,,,,
,13046103.595,241.65985105,999.788,0.000137779188141689,5.82189107613208E-8,1,30.0025819559455,40.0298881530762,1.99274491893101,5.06999995559454,0.00147918768353354,0.000235580831005957,0.25,-1.81376204064415E-6,0.000138032639815863,-1.70070584855327E-6,241.1627197,242.1569824,999.788,999.788,52.9912870897748,18.5191186034027,116.74324,0,0,0,1201,4886,245.60135,999.788,,,,,,,,,,,,,0,,,,64.6093273,,,,,,241.65985105,,,,
,13046493.635,254.63613895,999.788,0.000137139768045248,6.08407085521956E-8,1,30.0025819559455,40.0298881530762,1.9819591086346,5.00999996438622,0.00146410372494314,0.000233010836093246,0.25,-1.81374316053988E-6,0.000137335966607959,-1.70746333164687E-6,254.1377106,255.1345673,999.788,999.788,52.8920202678325,18.5244801170478,116.74324,0,0,0,1201,4886,258.62925,999.788,,,,,,,,,,,,,0,,,,69.91498945,,,,,,254.63613895,,,,
,13046885.08,267.6111755,999.788,,,2,,,,4.88000000101049,,,,,,,267.6111755,267.6111755,999.788,999.788,,,117.124451,,,,-99999999,4886,271.7463,999.788,,,,,,,,,,,,,,,,,,,,,,,267.6111755,,,,
,13047348.625,283.08618165,999.788,0.000135744243523468,6.28682366201427E-8,1,30.0025819559455,40.0298881530762,2.0070351167233,4.79000015184283,0.00146552377107733,0.000232858695685935,0.25,-1.81677338885408E-6,0.000135815054241314,-1.72273877178029E-6,283.0671692,283.1051941,999.788,999.788,53.0897722831979,18.5272970375092,117.124451,0,0,0,1201,4886,287.2496,999.788,,,,,,,,,,,,,0,,,,50.5541859,,,,,,283.08618165,,,,
,13047723.73,295.57858275,999.788,0.000134938805194235,6.48950039072619E-8,1,30.0025819559455,40.0298881530762,1.98193712597,4.72000008448958,0.00143921837908802,0.00022600622644027,0.25,-2.04584767268385E-6,0.000134955322602368,-1.95640320195318E-6,295.081604,296.0755615,999.788,999.788,53.2343735592556,18.5233319250377,117.124451,0,0,0,1201,4886,299.81655,999.788,,,,,,,,,,,,,0,,,,71.6857948,,,,,,295.57858275,,,,
,13048113.765,308.55743405,999.788,0.000130835467505708,6.44840937853009E-8,1,30.0025819559455,40.0298881530762,1.98220034689055,4.66000009328127,0.00139580738019678,0.00021470093291031,0.25,-2.39027581560165E-6,0.000130797545768921,-2.30690097068608E-6,308.0526733,309.0621948,999.788,999.788,53.0131726883133,18.5240224657274,117.124451,0,0,0,1201,4886,312.883,999.788,,,,,,,,,,,,,0,,,,65.7279415,,,,,,308.55743405,,,,
,13048503.8,321.53865055,999.788,0.000130337164636272,6.6920737517638E-8,1,30.0025819559455,40.0298881530762,2.00712953692118,4.59000002592802,0.00140689622633373,0.000215159253160112,0.25,-2.49033087199721E-6,0.000130245938768188,-2.41003056880883E-6,321.04422,322.0330811,999.788,999.788,53.1952921332941,18.5277575740599,116.36203,0,0,0,1201,4886,325.9381,999.788,,,,,,,,,,,,,0,,,,67.7275276,,,,,,321.53865055,,,,
touchdown = -0.47999998787418 mm,13048997.005,337.9426575,999.788,0.00013608632009772,6.99238348647489E-8,1,30.0025819559455,40.0298881530762,1.98229583154534,4.42000012844801,0.00144984584710271,0.000227233916262063,0.25,-2.09098068202647E-6,0.000135921313970563,-2.01078248920627E-6,337.9426575,337.9426575,999.788,999.788,52.9428261215825,18.5257086806258,116.36203,0,0,0,1201,4886,342.4625,999.788,,,,,,,,,,,,,0,,,,73.8630219,,,,,,337.9426575,,,,
,13049343.9,349.4817352,999.788,0.000134947066423628,7.19177214540258E-8,1,30.0025819559455,40.0298881530762,1.99316187527534,4.37999982386827,0.00144475685658051,0.000226471654235631,0.25,-2.06770995811361E-6,0.000134736009725144,-1.99003054016196E-6,348.9925842,349.9708862,999.788,999.788,53.2804896418903,18.5206782540212,117.124451,0,0,0,1201,4886,354.1072,999.788,,,,,,,,,,,,,0,,,,72.41635515,,,,,,349.4817352,,,,
,13049673.915,354.54244995,999.788,0.000134845320058424,7.25311787501799E-8,1,30.0025819559455,40.0298881530762,1.99318321340741,4.37999982386827,0.00144337496105252,0.000226776256767823,0.25,-2.01827511953508E-6,0.000134613890884342,-1.94077446425116E-6,354.4947205,354.5901794,999.788,999.788,53.1311985947172,18.5158632550865,117.124451,0,0,0,1201,4885,355.8263,999.788,,,,,,,,,,,,,0,,,,72.8088989,,,,,,354.54244995,,,,
,13092932.915,5.00055525,75994.891,-0.0013286521768337,7.98675898832142E-7,1,60.005163911891,40.0298881530762,1.98109499656081,6.19000010192394,-0.014097504727598,-0.00264688754898511,0.25,-1.06666631714673E-5,-0.00132926204310604,-2.03889856921623E-5,5.000411,5.0006995,75994.469,75995.313,53.2101430751595,18.5004054679708,35.926437,0,0,0,2402,4929,5.00625,75994.891,,,,,,,,,,,,,0,,,,0.9020208,,,,,,5.00055525,,,,
,13096859.17,5.001482,75995.2345,0.00109561142534579,3.7393307411472E-7,1,60.005163911891,40.0298881530762,1.98105087052593,6.27999985590577,0.0116143553217096,0.00223970387686281,0.25,1.41712951897598E-5,0.00109607504008359,2.21911356722925E-5,5.0007071,5.0022569,75994.961,75995.508,53.0108278027556,18.5058697659294,60.705173,0,0,0,2402,4417,5.0089,75995.2345,,,,,,,,,,,,,0,,,,18.2402782,,,,,,5.001482,,,,
,13099679.51,5.0005586,31997.752,0.000397685650123187,2.59467226069836E-7,1,60.005163911891,40.0298881530762,1.98109210388296,6.27999985590577,0.00419897000819302,0.000803966777406956,0.25,4.78952106692726E-6,0.000396168674961342,7.49657105511772E-6,5.0000086,5.0011086,31997.055,31998.449,52.7607066766017,18.517510587712,60.705173,0,0,0,2402,4417,4.97775,31997.752,,,,,,,,,,,,,0,,,,23.89231875,,,,,,5.0005586,,,,
,13102319.74,5.00051215,-12000.4605,0.000254593049913611,6.69008057836794E-8,1,60.005163911891,40.0298881530762,1.9811794759607,6.27999985590577,0.00269292920222534,0.000457696395613318,0.25,-1.92813171210321E-6,0.000253155050172908,-4.82040500435317E-7,5.0001965,5.0008278,-12000.562,-12000.359,52.6114156294286,18.5184330783525,61.467594,0,0,0,2402,4417,4.9782,-12000.4605,,,,,,,,,,,,,0,,,,28.0277519,,,,,,5.00051215,,,,
,13104900,4.99857545,-56003.285,-5.49922150369655E-5,6.47245723302903E-7,1,60.005163911891,40.0298881530762,1.98118906820164,6.27999985590577,-0.000569843947602826,-0.000179755063286441,0.25,-7.07061173302996E-6,-5.48710797451031E-5,-7.47019583056199E-6,4.9982624,4.9988885,-56004.406,-56002.164,52.727878278794,18.5252300888527,59.942749,0,0,0,2402,4417,4.9896,-56003.285,,,,,,,,,,,,,0,,,,26.7273912,,,,,,4.99857545,,,,
,13107660.26,4.99682715,-99999.9495,0.000148715158568713,2.21209217650716E-6,1,60.005163911891,40.0298881530762,1.98122438585197,6.27999985590577,0.00160589271536409,0.000155312507580926,0.25,-1.20191175621679E-5,0.000149115287465599,-1.10312325354844E-5,4.9937029,4.9999514,-100000.063,-99999.836,53.0436562005633,18.5308489209821,60.705173,0,0,0,2402,4417,5.0301,-99999.9495,,,,,,,,,,,,,0,,,,21.1278353,,,,,,4.99682715,,,,
,13110720.625,5.0004857,-55998.098,3.6919725369641E-5,2.92070465727076E-7,1,60.005163911891,40.0298881530762,1.98113328874706,6.27999985590577,0.000408207421991016,-2.21272029616862E-5,0.25,-8.71643681471502E-6,3.69383684852075E-5,-8.43136670139334E-6,5.0002766,5.0006948,-55998.262,-55997.934,52.7020845376594,18.5244198615885,60.705173,0,0,0,2402,4417,4.99395,-55998.098,,,,,,,,,,,,,0,,,,24.3708563,,,,,,5.0004857,,,,
,13113300.82,4.99983665,-11999.835,-0.000253581114597188,3.07558077146018E-7,1,60.005163911891,40.0298881530762,1.98089350805982,6.27999985590577,-0.00266815054007497,-0.000532899827845977,0.25,-5.37816467090778E-6,-0.000252107675577252,-6.77696027417672E-6,4.9993181,5.0003552,-11999.896,-11999.774,52.8498123277941,18.5221709091808,59.561539,0,0,0,2402,4417,4.97885,-11999.835,,,,,,,,,,,,,0,,,,27.20159055,,,,,,4.99983665,,,,
,13116001.04,4.99959305,32001.2255,6.53162554632735E-5,5.74080793441593E-8,1,60.005163911891,40.0298881530762,1.98083095230046,6.27999985590577,0.000692166382118962,0.000117443351216561,0.25,-5.91846687710092E-7,6.50765754253668E-5,-1.42083945667001E-7,4.9995871,4.999599,32000.939,32001.512,53.2163961033133,18.5166824099643,60.705173,0,0,0,2402,4417,4.98045,32001.2255,,,,,,,,,,,,,0,,,,28.7369213,,,,,,4.99959305,,,,
,13118881.3,4.9984195,75999.8595,5.75550840607105E-5,2.31291685229792E-7,1,60.005163911891,40.0298881530762,1.98091292856481,6.27999985590577,0.000599611833942113,0.000176033132878373,0.25,6.23954389491087E-6,5.75392732059098E-5,6.66368873798307E-6,4.9972949,4.9995441,75999.172,76000.547,53.3055017545056,18.5140338272346,60.323963,0,0,0,2402,4417,5.00705,75999.8595,,,,,,,,,,,,,0,,,,28.3091755,,,,,,4.9984195,,,,
,13120261.51,4.9993081,100002.1445,-0.00027362803935156,2.62829752283984E-7,1,60.005163911891,40.0298881530762,1.98102966827958,6.27999985590577,-0.00292201455904251,-0.00046717571090795,0.25,5.06791067884772E-6,-0.000274248103871904,3.21379482824664E-6,4.9992981,4.9993181,100001.742,100002.547,53.2781447563326,18.5126504947285,60.705173,0,0,0,2402,4417,5.03075,100002.1445,,,,,,,,,,,,,0,,,,23.08087925,,,,,,4.9993081,,,,