File: Projekt_andmed1/PDCALIBRATION_ HYS 300K 1000 OE SWEEP 10 OE-SEC _15112018.DAT
[Header]
; VSM Data File (default extension .dat)
; Copyright (c) 2003, Quantum Design, Inc. All rights reserved.
TITLE,1000 OE
FILEOPENTIME,27552298.06,11/15/2018,8:14 pm
BYAPP,VSM,1.0,1.0
INFO,PPMS VSM Option Release 1.3.6 Build 0,APPNAME
INFO,221,COIL_SERIAL_NUMBER
INFO,0,MOMENT_UNITS
INFO,PdCalibration_ Hys 300K Sweep 10 Oe-Sec _15112018,SAMPLE_MATERIAL
INFO,Pd Calibration - 2173,SAMPLE_COMMENT
INFO,314.3,SAMPLE_MASS
INFO,,SAMPLE_VOLUME
INFO,,SAMPLE_MOLECULAR_WEIGHT
INFO,,SAMPLE_SIZE
INFO,Cylinder,SAMPLE_SHAPE
INFO,35.38,SAMPLE_OFFSET
DATATYPE,COMMENT,1
DATATYPE,TIME,2
STARTUPAXIS,X,2
STARTUPAXIS,Y1,5
[Data]
Comment,Time Stamp (sec),Temperature (K),Magnetic Field (Oe),Moment (emu),M. Std. Err. (emu),Transport Action,Averaging Time (sec),Frequency (Hz),Peak Amplitude (mm),Center Position (mm),Coil Signal' (mV),Coil Signal" (mV),Range (mV),M. Quad. Signal (emu),M. Raw' (emu),M. Raw" (emu),Min. Temperature (K),Max. Temperature (K),Min. Field (Oe),Max. Field (Oe),Mass (grams),Motor Lag (deg),Pressure (Torr),VSM Status (code),Motor Status (code),Measure Status (code),PPMS Status (code),System Temp. (K),System Field (Oe),Sample Position (deg),Bridge 1 Resistance (ohms),Bridge 1 Excitation (에),Bridge 2 Resistance (ohms),Bridge 2 Excitation (에),Bridge 3 Resistance (ohms),Bridge 3 Excitation (에),Bridge 4 Resistance (ohms),Bridge 4 Excitation (에),Signal 1 Vin (V),Signal 2 Vin (V),Digital Inputs (code),Drive 1 Iout (mA),Drive 1 Ipower (W),Drive 2 Iout (mA),Drive 2 Ipower (W),Pressure (),Map 20 (),Map 21 (),Map 22 (),Map 23 (),Map 24 (),Map 25 (),Map 26 (),Map 27 (),Map 28 (),Map 29 ()
"1000",27552299.36
,27552344.59,299.994873,976.8215,0.00174739806126363,7.54534885344072E-7,1,1.99850670813958,40.0298881530762,1.98105485582168,8.8600018620491,0.0185772023951214,0.00321138274853399,0.25,4.43077896612947E-7,0.00174734582412814,1.60326430517794E-6,299.994873,299.994873,975.226,978.417,52.1393120038132,18.4024051894414,12.3545799,0,0,0,4449,300.0085,976.8215,,,,,,,,,,,,,,,,,21.440407,,,,,,299.994873,,,,
,27552346.31,299.9944763,955.721,0.00170216935637332,1.61137929827595E-6,1,1.99850670813958,40.0298881530762,1.98113682573943,8.85000178590417,0.0180971770586222,0.00312781946538189,0.25,3.78389315273199E-7,0.00170211852896855,1.50854090195862E-6,299.9936218,299.9953308,947.514,963.928,51.8243157105632,18.4045395719106,12.5412607,0,0,0,4449,300.0106,955.721,,,,,,,,,,,,,,,,,21.440407,,,,,,299.9944763,,,,
,27552349.975,299.99557495,909.3095,0.00161483388678336,1.62508677811857E-6,1,1.99850670813958,40.0298881530762,1.98114580546885,8.85000178590417,0.0171679439857589,0.00297181727890773,0.25,7.79230072079427E-7,0.00161478533182242,1.85137599828973E-6,299.9954224,299.9957275,896.555,922.064,52.1823015723709,18.4041188826819,12.5412607,0,0,0,4449,300.0135,909.3095,,,,,,,,,,,,,,,,,21.440407,,,,,,299.99557495,,,,
,27552353.975,299.99664305,860.5565,0.00152506770885389,1.6311718163351E-6,1,1.99850670813958,40.0298881530762,1.98115027099174,8.85000178590417,0.0162145621130047,0.0028012730489334,0.25,2.32604554529844E-7,0.00152502213508985,1.24516330679025E-6,299.9961548,299.9971313,847.802,873.311,51.7109795752747,18.4052386112831,12.4786186,0,0,0,4449,300.0156,860.5565,,,,,,,,,,,,,,,,,21.440407,,,,,,299.99664305,,,,
,27552357.96,299.99742125,809.5955,0.00143719559682145,1.77491028206161E-6,1,1.99850670813958,40.0298881530762,1.98114187393469,8.85000178590417,0.0152796637037257,0.00264320066484752,0.25,5.33686885190888E-7,0.00143715240515312,1.4878836043666E-6,299.9964294,299.9984131,796.786,822.405,52.0713103226401,18.4037007191716,12.4786186,0,0,0,4449,300.01975,809.5955,,,,,,,,,,,,,,,,,20.677984,,,,,,299.99742125,,,,
,27552361.965,299.99697875,759.978,0.00135107677489254,1.57904865410025E-6,1,1.99850670813958,40.0298881530762,1.98115576553317,8.85000178590417,0.014365052459804,0.00247978566543865,0.25,2.6986229197615E-8,0.00135103650566632,9.24021016859673E-7,299.9968872,299.9970703,748.452,771.504,51.8680869076401,18.4057598188678,12.6039028,0,0,0,4449,300.02085,759.978,,,,,,,,,,,,,,,,,20.677984,,,,,,299.99697875,,,,
,27552365.98,299.99798585,710.15,0.00126554620293667,1.39867994038658E-6,1,1.99850670813958,40.0298881530762,1.98118989419043,8.85000178590417,0.0134563351271372,0.00232024927962064,0.25,-2.18392685712231E-7,0.00126550860264116,6.21874895020912E-7,299.9979553,299.9980164,697.1,723.2,52.1205529193517,18.4061162724025,12.3545799,0,0,0,4449,300.0183,710.15,,,,,,,,,,,,,,,,,21.440407,,,,,,299.99798585,,,,
,27552369.96,299.99954225,661.534,0.00117722014632342,1.43465469575948E-6,1,1.99850670813958,40.0298881530762,1.98108777106338,8.85000178590417,0.0125155943846156,0.00216379518095344,0.25,3.22587580173645E-7,0.00117718476254322,1.10419213990522E-6,299.9993286,299.9997559,648.936,674.132,52.6716010254094,18.4084435760401,12.47924135,0,0,0,4449,300.0204,661.534,,,,,,,,,,,,,,,,,21.059195,,,,,,299.99954225,,,,
,27552373.98,300.0003052,612.1855,0.00109104018220446,1.54127659240005E-6,1,1.99850670813958,40.0298881530762,1.9811219875979,8.8600018620491,0.0116003438422819,0.00200091696219906,0.25,-1.25033820712503E-7,0.00109100764203478,5.99381306885635E-7,299.9994812,300.0011292,600.689,623.682,51.7461528586401,18.4069187899867,12.29317665,0,0,0,4449,300.01595,612.1855,,,,,,,,,,,,,,,,,20.677984,,,,,,300.0003052,,,,
,27552377.97,300.00039675,562.877,0.00100474719917766,1.44219500381659E-6,1,1.99850670813958,40.0298881530762,1.98114226557392,8.85000178590417,0.0106830603703874,0.00184203717147272,0.25,-1.75398436558666E-7,0.00100471726924459,4.91728241010029E-7,300.0003052,300.0004883,550.319,575.435,51.8923173917363,18.4049468553767,12.4786186,0,0,0,4449,300.0151,562.877,,,,,,,,,,,,,,,,,21.440407,,,,,,300.00039675,,,,
,27552381.96,300.00152585,512.525,0.000918232157996413,1.53320249673361E-6,1,1.99850670813958,40.0298881530762,1.9812816941786,8.85000178590417,0.00976447768004824,0.00167985257544326,0.25,-5.07083418070039E-7,0.000918205001669912,1.02615209384449E-7,300.0014038,300.0016479,500.011,525.039,52.3503517040055,18.4068005877659,12.5412607,0,0,0,4449,300.0141,512.525,,,,,,,,,,,,,,,,,21.440407,,,,,,300.00152585,,,,
,27552385.98,300.0022583,463.3865,0.000832701463462558,1.56507861324795E-6,1,1.99850670813958,40.0298881530762,1.98118836547115,8.85000178590417,0.00885420260136603,0.00152528708020019,0.25,-2.73928915535256E-7,0.000832676692828491,2.78981262665093E-7,300.0021057,300.0024109,451.904,474.869,52.0994489493324,18.4084945260334,12.47924135,0,0,0,4449,300.01125,463.3865,,,,,,,,,,,,,,,,,21.059195,,,,,,300.0022583,,,,
,27552389.955,300.00100705,414.2765,0.000745883378581671,1.46154700382782E-6,1,1.99850670813958,40.0298881530762,1.98122641589917,8.85000178590417,0.00793210072522317,0.00136108554647814,0.25,-7.34355537393986E-7,0.00074586154481841,-2.39072942409675E-7,300.0003967,300.0016174,401.735,426.818,52.4988611226594,18.4100321895137,12.41659925,0,0,0,4449,300.01005,414.2765,,,,,,,,,,,,,,,,,21.440407,,,,,,300.00100705,,,,
,27552393.94,300.00256345,365.971,0.000658523866604939,1.50159986597138E-6,1,1.99850670813958,40.0298881530762,1.98131584528018,8.8600018620491,0.00700344583037933,0.00120133535848234,0.25,-6.84919592882537E-7,0.000658504581139464,-2.47641532173524E-7,300.0025024,300.0026245,353.09,378.852,52.3855249873709,18.410532049517,12.41659925,0,0,0,4449,300.00945,365.971,,,,,,,,,,,,,,,,,21.440407,,,,,,300.00256345,,,,
,27552397.96,300.0025177,316.578,0.000574035675953014,1.4163866359031E-6,1,1.99850670813958,40.0298881530762,1.98124434100559,8.85000178590417,0.00610474196559416,0.0010469060537976,0.25,-6.21730964909485E-7,0.000574018881840841,-2.40552470392389E-7,300.0020752,300.0029602,305.15,328.006,51.9181111328709,18.4088059722556,12.41659925,0,0,0,4449,300.0091,316.578,,,,,,,,,,,,,,,,,21.440407,,,,,,300.0025177,,,,
,27552401.96,300.00248715,267.6245,0.000488945686966319,1.36671134376113E-6,1,1.99850670813958,40.0298881530762,1.98119131976143,8.85000178590417,0.00520056905375014,0.000886636353427586,0.25,-1.00572074389383E-6,0.000488931698834285,-6.81029670613541E-7,300.0022888,300.0026855,255.181,280.068,52.1705771445824,18.4076376679148,12.6039028,0,0,0,4449,300.0095,267.6245,,,,,,,,,,,,,,,,,21.440407,,,,,,300.00248715,,,,
,27552405.94,300.0027313,217.582,0.000401706620786813,1.45583927838498E-6,1,1.99850670813958,40.0298881530762,1.98129211481586,8.85000178590417,0.00427315842125438,0.000726848662849515,0.25,-9.79304273651779E-7,0.000401695226693134,-7.12538379137582E-7,300.0026245,300.0028381,205.068,230.096,52.494171351544,18.4105333922882,12.4786186,0,0,0,4449,300.00815,217.582,,,,,,,,,,,,,,,,,21.440407,,,,,,300.0027313,,,,
,27552409.935,300.00190735,169.727,0.000316969315276252,1.45433278658565E-6,1,1.99850670813958,40.0298881530762,1.98122593511063,8.85000178590417,0.00337217140503265,0.000570522654832152,0.25,-1.05335209906827E-6,0.00031696051937437,-8.42849736912856E-7,300.0017395,300.0020752,157.243,182.211,51.820407567967,18.4094227720622,12.41659925,0,0,0,4449,300.00845,169.727,,,,,,,,,,,,,,,,,20.677984,,,,,,300.00190735,,,,
,27552413.96,300.0028534,119.798,0.000231144695845708,1.39949377143243E-6,1,1.99850670813958,40.0298881530762,1.98124561571789,8.8600018620491,0.00245996698462939,0.000411166134113688,0.25,-1.2272994145161E-6,0.000231138579421229,-1.07378004237528E-6,300.002655,300.0030518,107.27,132.326,51.5538722429093,18.4080652181624,12.3545799,0,0,0,4449,300.0091,119.798,,,,,,,,,,,,,,,,,21.440407,,,,,,300.0028534,,,,
,27552417.945,300.0016785,72.086,0.000145295295758566,1.42870596660305E-6,1,1.99850670813958,40.0298881530762,1.98121082939437,8.85000178590417,0.00154782999325553,0.000249500725157049,0.25,-1.61321276935588E-6,0.000145292015394418,-1.51668613113223E-6,300.0010071,300.0023499,59.699,84.473,51.8930990202555,18.4099442332185,12.6039028,0,0,0,4449,300.00815,72.086,,,,,,,,,,,,,,,,,21.059195,,,,,,300.0016785,,,,
,27552421.915,300.0028534,24.0615,5.96640711639399E-5,1.40466513041124E-6,1,1.99850670813958,40.0298881530762,1.98126006273674,8.8600018620491,0.000637408813506006,9.20716525452788E-5,0.25,-1.63921211923114E-6,5.9663370430241E-5,-1.59954482907793E-6,300.002533,300.0031738,11.251,36.872,51.9259274180632,18.4139702800003,12.41659925,0,0,0,4449,300.00715,24.0615,,,,,,,,,,,,,,,,,21.440407,,,,,,300.0028534,,,,
,27552425.91,300.00146485,-26.1365,-2.59561726231604E-5,1.47570408493908E-6,1,1.99850670813958,40.0298881530762,1.98127280423463,8.8600018620491,-0.000273066762464424,-6.45754987809421E-5,0.25,-1.59297124324219E-6,-2.59543376415816E-5,-1.61015898006335E-6,300.0013733,300.0015564,-38.666,-13.607,52.4105370999863,18.4111916083077,12.4786186,0,0,0,4449,300.00685,-26.1365,,,,,,,,,,,,,,,,,21.440407,,,,,,300.00146485,,,,
,27552429.98,300.00263975,-74.443,-0.000110996262255533,1.38578341329592E-6,1,1.99850670813958,40.0298881530762,1.98122430001587,8.85000178590417,-0.00117674608898501,-0.000223651134478015,0.25,-1.87570269272226E-6,-0.000110991688996263,-1.94934988224674E-6,300.0024414,300.0028381,-85.7,-63.186,52.1799566868132,18.4116603501608,12.5412607,0,0,0,4449,300.00745,-74.443,,,,,,,,,,,,,,,,,21.440407,,,,,,300.00263975,,,,
,27552433.93,300.00164795,-122.7205,-0.000195483791542517,1.42837691970426E-6,1,1.99850670813958,40.0298881530762,1.98124282791361,8.85000178590417,-0.00207413656607553,-0.000384259694432047,0.25,-2.39751263078944E-6,-0.000195476345143047,-2.52724420245025E-6,300.0014954,300.0018005,-135.024,-110.417,52.2776602517171,18.4103774353867,12.4786186,0,0,0,4449,300.009,-122.7205,,,,,,,,,,,,,,,,,21.440407,,,,,,300.00164795,,,,
,27552437.91,300.00195315,-171.04,-0.000281268633991138,1.39263501181179E-6,1,1.99850670813958,40.0298881530762,1.98130017406093,8.85000178590417,-0.00298638841138312,-0.000541497892423077,0.25,-2.37719459801928E-6,-0.000281258629221453,-2.56388866977312E-6,300.0013733,300.002533,-182.227,-159.853,52.3339375051017,18.4110807421561,12.47924135,0,0,0,4449,300.0083,-171.04,,,,,,,,,,,,,,,,,22.202829,,,,,,300.00195315,,,,
,27552441.915,300.0015869,-219.4455,-0.000365430121916212,1.45192005294637E-6,1,1.99850670813958,40.0298881530762,1.98126742663692,8.8600018620491,-0.00388117256386028,-0.00069624053538867,0.25,-2.40442402211525E-6,-0.000365417582246287,-2.64699933285414E-6,300.0014648,300.001709,-231.861,-207.03,52.2088769420248,18.4129728629041,12.47924135,0,0,0,4449,300.0095,-219.4455,,,,,,,,,,,,,,,,,20.677984,,,,,,300.0015869,,,,
,27552445.92,300.0019989,-267.695,-0.00045116781432963,1.40261894779874E-6,1,1.99850670813958,40.0298881530762,1.98124014647713,8.85000178590417,-0.0047927024095713,-0.000853860968274236,0.25,-2.43049430652235E-6,-0.000451152683880361,-2.72999908042786E-6,300.0016785,300.0023193,-279.009,-256.381,51.9884576996017,18.4107120854198,12.3545799,0,0,0,4449,300.00845,-267.695,,,,,,,,,,,,,,,,,21.440407,,,,,,300.0019989,,,,
,27552449.915,300.00120545,-316.7055,-0.000536006857971097,1.44043233740935E-6,1,1.99850670813958,40.0298881530762,1.98123457921338,8.85000178590417,-0.00569483920900292,-0.00100910905894846,0.25,-2.38794962006441E-6,-0.000535989227939423,-2.74378714489775E-6,300.0009766,300.0014343,-328.98,-304.431,52.3229947058325,18.4125424238806,12.6039028,0,0,0,4449,300.0089,-316.7055,,,,,,,,,,,,,,,,,20.677984,,,,,,300.00120545,,,,
,27552453.895,300.002121,-363.896,-0.000620420289966896,1.39920521529514E-6,1,1.99850670813958,40.0298881530762,1.98130510422822,8.85000178590417,-0.00659213924125124,-0.00116680042321641,0.25,-2.64469284496316E-6,-0.000620399944524597,-3.05657220220587E-6,300.0018921,300.0023499,-376.072,-351.72,52.0603675233709,18.4130370538734,12.5412607,0,0,0,4449,300.00845,-363.896,,,,,,,,,,,,,,,,,21.440407,,,,,,300.002121,,,,
,27552457.895,300.00138855,-413.021,-0.000704800995652796,1.3577589941065E-6,1,1.99850670813958,40.0298881530762,1.98117414883442,8.85000178590417,-0.00748862032697179,-0.00132316245712245,0.25,-2.79320353317486E-6,-0.000704778040075177,-3.26110571412211E-6,300.000946,300.0018311,-425.337,-400.705,51.6867490911785,18.4126627537302,12.47924135,0,0,0,4449,300.00815,-413.021,,,,,,,,,,,,,,,,,21.440407,,,,,,300.00138855,,,,
,27552461.89,300.0011902,-459.986,-0.000789688083345837,1.33331547362885E-6,1,1.99850670813958,40.0298881530762,1.98127336843924,8.85000178590417,-0.00839108112417382,-0.00148190928844466,0.25,-3.064952970247E-6,-0.000789662412377652,-3.58919658669645E-6,300.0009766,300.0014038,-472.261,-447.711,52.013469812217,18.412637706061,12.6039028,0,0,0,4449,300.0144,-459.986,,,,,,,,,,,,,,,,,21.440407,,,,,,300.0011902,,,,
,27552465.895,300.0019531,-509.0815,-0.000872603474618624,1.47764037659298E-6,1,1.99850670813958,40.0298881530762,1.98125764118363,8.85000178590417,-0.00927316038238305,-0.00163108386804453,0.25,-2.78392263510222E-6,-0.000872575486618811,-3.36323410729988E-6,300.0018005,300.0021057,-521.384,-496.779,52.2002790283132,18.414687582221,12.47924135,0,0,0,4449,300.0108,-509.0815,,,,,,,,,,,,,,,,,21.440407,,,,,,300.0019531,,,,
,27552469.9,300.00164795,-556.95,-0.000957324506050062,1.36915119955786E-6,1,1.99850670813958,40.0298881530762,1.98129258460918,8.85000178590417,-0.010173710208584,-0.0017892053613465,0.25,-3.02875297505731E-6,-0.000957293826667286,-3.66431403835759E-6,300.0013733,300.0019226,-568.164,-545.736,52.1025754634094,18.416467600765,12.47924135,0,0,0,4449,300.00825,-556.95,,,,,,,,,,,,,,,,,21.440407,,,,,,300.00164795,,,,
,27552473.885,300.00117495,-605.0855,-0.00104041756233413,1.36757087004988E-6,1,1.99850670813958,40.0298881530762,1.9812307771863,8.85000178590417,-0.0110568573376895,-0.00194196014948442,0.25,-3.05793597754084E-6,-0.00104038439144211,-3.74866491349069E-6,300.0006714,300.0016785,-617.628,-592.543,52.0627124089286,18.4121466460072,12.47924135,0,0,0,4449,300.00855,-605.0855,,,,,,,,,,,,,,,,,21.440407,,,,,,300.00117495,,,,
,27552477.9,300.0010376,-652.9685,-0.00112373849552998,1.41096238342122E-6,1,1.99850670813958,40.0298881530762,1.98128328802169,8.85000178590417,-0.0119430932831315,-0.00209490813698384,0.25,-3.05589544692281E-6,-0.00112370283668739,-3.80195261119545E-6,300.0001221,300.0019531,-664.213,-641.724,51.9228009039863,18.4122551751763,12.47924135,0,0,0,4449,300.00585,-652.9685,,,,,,,,,,,,,,,,,20.677984,,,,,,300.0010376,,,,
,27552481.915,300.00146485,-700.665,-0.00120500308153671,1.42836082442757E-6,1,1.99850670813958,40.0298881530762,1.9812483955916,8.8600018620491,-0.0128063099207713,-0.0022477952865078,0.25,-3.41131066310224E-6,-0.00120496473906518,-4.21130627120553E-6,300.0011292,300.0018005,-710.65,-690.68,51.9024785624863,18.417180159089,12.41659925,0,0,0,4449,300.00765,-700.665,,,,,,,,,,,,,,,,,21.440407,,,,,,300.00146485,,,,
,27552485.9,299.9996033,-747.927,-0.00128940780456498,1.20797071379609E-6,1,1.99850670813958,40.0298881530762,1.98134885749989,8.85000178590417,-0.0137043019201001,-0.00240360440055873,0.25,-3.48516193630134E-6,-0.0012893669629574,-4.34120073314714E-6,299.999054,300.0001526,-758.959,-736.895,52.2002790283132,18.4140655149984,12.6039028,0,0,0,4449,300.0058,-747.927,,,,,,,,,,,,,,,,,21.440407,,,,,,299.9996033,,,,
,27552489.91,300.0001068,-795.2865,-0.0013720463606464,1.52484197773889E-6,1,1.99850670813958,40.0298881530762,1.98129622118309,8.85000178590417,-0.0145817972105881,-0.00256016826953634,0.25,-3.9513029909754E-6,-0.00137200271868666,-4.86219179073741E-6,299.9997253,300.0004883,-807.35,-783.223,51.9376518458516,18.4134441239326,12.47924135,0,0,0,4449,300.00635,-795.2865,,,,,,,,,,,,,,,,,21.440407,,,,,,300.0001068,,,,
,27552493.895,299.9992218,-842.435,-0.00145587742711486,1.45989212481476E-6,1,1.99850670813958,40.0298881530762,1.98126887833683,8.85000178590417,-0.0154734400005428,-0.00271128564769923,0.25,-3.6969908275218E-6,-0.00145583148994035,-4.66354158734191E-6,299.9989929,299.9994507,-853.369,-831.501,51.9493762736401,18.4129461701413,12.5412607,0,0,0,4449,300.0071,-842.435,,,,,,,,,,,,,,,,,21.059195,,,,,,299.9992218,,,,
,27552497.86,299.9993744,-889.4875,-0.00153282582822667,1.81256004333562E-6,1,1.99850670813958,40.0298881530762,1.9812796262169,8.8600018620491,-0.0162910985009636,-0.00285607160578574,0.25,-4.03063211043206E-6,-0.00153277736466424,-5.04825511463625E-6,299.999176,299.9995728,-901.453,-877.522,52.0791266078324,18.4156367842072,12.6039028,0,0,0,4449,300.00815,-889.4875,,,,,,,,,,,,,,,,,20.677984,,,,,,299.9993744,,,,
,27552501.875,299.99926755,-935.567,-0.00162048499789214,1.43628660369241E-6,1,1.99850670813958,40.0298881530762,1.98130411615306,8.85000178590417,-0.0172231970656317,-0.00301805266134625,0.25,-4.13064368752938E-6,-0.00162043385626873,-5.20645276579618E-6,299.9988708,299.9996643,-947.891,-923.243,51.935306960294,18.4151666282185,12.6039028,0,0,0,4449,300.0101,-935.567,,,,,,,,,,,,,,,,,21.440407,,,,,,299.99926755,,,,
,27552505.85,299.9994507,-971.1695,-0.00169186728917404,1.15309466836091E-6,1,1.99850670813958,40.0298881530762,1.98130673269703,8.85000178590417,-0.0179831929713153,-0.00314351562219402,0.25,-3.60857086248645E-6,-0.00169181435310055,-4.73178106393268E-6,299.9994202,299.9994812,-977.79,-964.549,51.993147470717,18.4171289007627,12.47924135,0,0,0,4449,300.0112,-971.1695,,,,,,,,,,,,,,,,,21.440407,,,,,,299.9994507,,,,
,27552529.86,299.9981079,-999.9555,-0.00175429389933399,8.31277501879056E-7,1,1.99850670813958,40.0298881530762,1.98128136574869,8.85000178590417,-0.0186454714062294,-0.00326547875585695,0.25,-4.3072713627122E-6,-0.00175423871059736,-5.47190528744759E-6,299.9979553,299.9982605,-1000.05,-999.861,52.1651057449478,18.4186358061545,12.47924135,0,0,0,4417,300.01125,-999.9555,,,,,,,,,,,,,,,,,21.440407,,,,,,299.9981079,,,,
,27552542.69,300.00004575,-970.781,-0.0017467642432288,1.43516110413922E-6,1,1.99850670813958,40.0298881530762,1.98132427988861,8.8600018620491,-0.0185660675597024,-0.0032501401101078,0.25,-4.15804318537615E-6,-0.00174670926952501,-5.31768034196319E-6,299.9996948,300.0003967,-976.417,-965.145,52.3378456476978,18.417212453315,12.47924135,0,0,0,4449,300.0124,-970.781,,,,,,,,,,,,,,,,,21.440407,,,,,,300.00004575,,,,
,27552545.81,299.9998169,-932.0385,-0.00166093413944319,1.54488432160409E-6,1,1.99850670813958,40.0298881530762,1.98136123267096,8.85000178590417,-0.0176545233340352,-0.00308809923546394,0.25,-3.72845962454506E-6,-0.00166088202803702,-4.83113057096072E-6,299.999054,300.0005798,-943.818,-920.259,51.9689169866209,18.4163515996428,12.6039028,0,0,0,4449,300.0117,-932.0385,,,,,,,,,,,,,,,,,20.677984,,,,,,299.9998169,,,,
,27552549.82,300.0000763,-881.4175,-0.00157226344998108,1.32415490105341E-6,1,1.99850670813958,40.0298881530762,1.98135139779383,8.8600018620491,-0.0167114334620833,-0.00292615001995888,0.25,-3.80459469423651E-6,-0.00157221392473163,-4.84839066132166E-6,299.9996643,300.0004883,-894.356,-868.479,51.6914388622939,18.4159884999272,12.6039028,0,0,0,4449,300.01295,-881.4175,,,,,,,,,,,,,,,,,20.677984,,,,,,300.0000763,,,,
,27552553.83,299.9995117,-830.8945,-0.00148291630289907,1.51610525475366E-6,1,1.99850670813958,40.0298881530762,1.98132463802403,8.85000178590417,-0.0157620075612262,-0.00275727906710722,0.25,-3.34851114599925E-6,-0.00148286977776984,-4.33300317536816E-6,299.9995117,299.9995117,-842.547,-819.242,52.4066289573901,18.4155303904878,12.6039028,0,0,0,4449,300.0131,-830.8945,,,,,,,,,,,,,,,,,21.440407,,,,,,299.9995117,,,,
,27552557.835,300.0002594,-779.8065,-0.00139588237353975,1.53330099248187E-6,1,1.99850670813958,40.0298881530762,1.98135094558954,8.85000178590417,-0.0148366639684179,-0.00259805366733242,0.25,-3.39359029241195E-6,-0.00139583838403797,-4.32030512395107E-6,300.0002441,300.0002747,-792.603,-767.01,52.1221161763901,18.4196153001008,12.5412607,0,0,0,4449,300.01145,-779.8065,,,,,,,,,,,,,,,,,21.440407,,,,,,300.0002594,,,,
,27552561.82,299.99942015,-729.524,-0.00130581357452334,1.39920799153227E-6,1,1.99850670813958,40.0298881530762,1.98132583895958,8.8600018620491,-0.0138792968211385,-0.00242962287606839,0.25,-3.10287391622447E-6,-0.00130577250568019,-3.9698016303195E-6,299.9993286,299.9995117,-741.275,-717.773,52.605944229794,18.4159947960999,12.6039028,0,0,0,4449,300.01085,-729.524,,,,,,,,,,,,,,,,,21.440407,,,,,,299.99942015,,,,
,27552565.82,300.00071715,-679.2835,-0.00121709366722839,1.40153287179826E-6,1,1.99850670813958,40.0298881530762,1.98136761233993,8.85000178590417,-0.0129353292621456,-0.0022717687660664,0.25,-3.56673472927617E-6,-0.00121705488957742,-4.37474555190473E-6,299.9997253,300.001709,-692.066,-666.501,52.3636393888325,18.4191314231791,12.6039028,0,0,0,4449,300.01075,-679.2835,,,,,,,,,,,,,,,,,20.677984,,,,,,300.00071715,,,,
,27552569.82,300.00024415,-630.3555,-0.00113107526819426,1.55175475319122E-6,1,1.99850670813958,40.0298881530762,1.98125290097368,8.85000178590417,-0.0120209512578442,-0.0021082100525691,0.25,-3.04345485324784E-6,-0.00113103942780912,-3.79437414193703E-6,300,300.0004883,-643.195,-617.516,52.4918264659863,18.4154544658966,12.6039028,0,0,0,4449,300.00975,-630.3555,,,,,,,,,,,,,,,,,21.440407,,,,,,300.00024415,,,,
,27552573.805,299.99925235,-579.241,-0.00104203500206247,1.68591144268707E-6,1,1.99850670813958,40.0298881530762,1.98123112381586,8.85000178590417,-0.0110739874933099,-0.00194533557559742,0.25,-3.09616845669348E-6,-0.00104200182152424,-3.78797301866911E-6,299.9989319,299.9995728,-591.981,-566.501,52.0760000937555,18.4197173946197,12.5412607,0,0,0,4449,300.00825,-579.241,,,,,,,,,,,,,,,,,20.677984,,,,,,299.99925235,,,,
,27552577.835,299.99986265,-528.1525,-0.00095613059882254,1.57040290226155E-6,1,1.99850670813958,40.0298881530762,1.98129222977567,8.85000178590417,-0.0101613845647953,-0.00178486814864391,0.25,-2.82695277599705E-6,-0.000956100144515684,-3.46172233920684E-6,299.9998169,299.9999084,-540.908,-515.397,52.2213829983325,18.4161748935553,12.6039028,0,0,0,4449,300.01095,-528.1525,,,,,,,,,,,,,,,,,21.440407,,,,,,299.99986265,,,,
,27552581.805,300.00082395,-478.93,-0.000867533834039079,1.48754777776934E-6,1,1.99850670813958,40.0298881530762,1.98133919848655,8.85000178590417,-0.00921962589768342,-0.00162181161976449,0.25,-2.78090329744698E-6,-0.000867506031664579,-3.35684591991008E-6,300.0005493,300.0010986,-492.094,-465.766,52.3636393888325,18.4181261066073,12.3545799,0,0,0,4449,300.0128,-478.93,,,,,,,,,,,,,,,,,21.440407,,,,,,300.00082395,,,,
,27552585.82,300.0006714,-428.674,-0.000779806238306167,1.35861408586449E-6,1,1.99850670813958,40.0298881530762,1.98141700226594,8.85000178590417,-0.00828687832571114,-0.00146217548669175,0.25,-2.90512309816344E-6,-0.00077978098155481,-3.42281746606146E-6,300.0005188,300.000824,-440.171,-417.177,52.5840586312556,18.4184668709608,12.47924135,0,0,0,4449,300.0116,-428.674,,,,,,,,,,,,,,,,,21.440407,,,,,,300.0006714,,,,
,27552589.8,300.00068665,-378.913,-0.000693625384753863,1.36095790513725E-6,1,1.99850670813958,40.0298881530762,1.98136847992408,8.85000178590417,-0.00737096898709123,-0.00130000473939244,0.25,-2.53263758019119E-6,-0.000693602952776501,-2.99312329896934E-6,300.0005493,300.000824,-391.64,-366.186,52.3784903306978,18.421181368617,12.41659925,0,0,0,4449,300.011,-378.913,,,,,,,,,,,,,,,,,20.677984,,,,,,300.00068665,,,,
,27552593.79,300.00045775,-329.336,-0.000603243671224598,1.4046176134264E-6,1,1.99850670813958,40.0298881530762,1.98131500879916,8.85000178590417,-0.00641000925837377,-0.00113250208782199,0.25,-2.3833430955596E-6,-0.000603224046419397,-2.78382307286643E-6,300.0002441,300.0006714,-340.875,-317.797,51.5960801829478,18.4169856227951,12.6039028,0,0,0,4449,300.01055,-329.336,,,,,,,,,,,,,,,,,20.677984,,,,,,300.00045775,,,,
,27552597.83,300.0001373,-279.605,-0.000518737368174308,1.47162220618828E-6,1,1.99850670813958,40.0298881530762,1.98137715153141,8.85000178590417,-0.00551135860419061,-0.000978870574922117,0.25,-2.51849504105023E-6,-0.00051872018609042,-2.86286296647391E-6,299.9999084,300.0003662,-292.261,-266.949,52.0298840111209,18.4171011915371,12.6039028,0,0,0,4449,300.00885,-279.605,,,,,,,,,,,,,,,,,21.440407,,,,,,300.0001373,,,,
,27552601.785,300.00074765,-230.873,-0.000431551577992578,1.40835420885598E-6,1,1.99850670813958,40.0298881530762,1.98130200573877,8.85000178590417,-0.00458450568433401,-0.000816490580788267,0.25,-2.29942247657949E-6,-0.000431537139678589,-2.58590535258851E-6,300.0004272,300.0010681,-243.557,-218.189,52.290947936544,18.4185623916782,12.3545799,0,0,0,4449,300.0098,-230.873,,,,,,,,,,,,,,,,,21.440407,,,,,,300.00074765,,,,
,27552605.805,300.0006256,-180.1955,-0.000344483244418147,1.41045385696198E-6,1,1.99850670813958,40.0298881530762,1.98138624250442,8.85000178590417,-0.00365874136540163,-0.00065734632653234,0.25,-2.35850418268596E-6,-0.000344471372954273,-2.58717419050745E-6,300.0001831,300.0010681,-192.879,-167.512,52.4863550663517,18.4203453906085,12.6039028,0,0,0,4449,300.008,-180.1955,,,,,,,,,,,,,,,,,21.440407,,,,,,300.0006256,,,,
,27552609.835,300.00039675,-128.8795,-0.000257953984992699,1.45813606539133E-6,1,1.99850670813958,40.0298881530762,1.98131104862248,8.85000178590417,-0.00273981640649343,-0.000491063496658101,0.25,-1.65803233924468E-6,-0.000257945169174236,-1.82926633650801E-6,299.9998169,300.0009766,-141.438,-116.321,52.1729220301401,18.4190203229614,12.5412607,0,0,0,4449,300.0099,-128.8795,,,,,,,,,,,,,,,,,20.677984,,,,,,300.00039675,,,,
,27552613.785,300.0008545,-81.618,-0.000170697664134327,1.45236804459858E-6,1,1.99850670813958,40.0298881530762,1.98138562195903,8.85000178590417,-0.00181162818697397,-0.00033351123093205,0.25,-1.90074031145555E-6,-0.000170691294242562,-2.01402867373931E-6,300.0003967,300.0013123,-93.215,-70.021,52.4926080945055,18.4224732484834,12.6039028,0,0,0,4449,300.00945,-81.618,,,,,,,,,,,,,,,,,21.440407,,,,,,300.0008545,,,,
,27552617.8,300.0007782,-31.308,-8.43240249614789E-5,1.37160709366358E-6,1,1.99850670813958,40.0298881530762,1.98127596158218,8.85000178590417,-0.00089403313142644,-0.000169709900487442,0.25,-1.40593332655664E-6,-8.43205683628386E-5,-1.46188363425243E-6,300.0007019,300.0008545,-42.735,-19.881,52.2745337376401,18.4200649533068,12.6039028,0,0,0,4449,300.00915,-31.308,,,,,,,,,,,,,,,,,21.440407,,,,,,300.0007782,,,,
,27552621.775,300.00076295,17.946,2.48477352598889E-6,1.05918865780259E-6,1,1.99850670813958,40.0298881530762,1.98134166931681,8.8600018620491,2.91304617822043E-5,-1.11350515157352E-5,0.25,-1.47607387195897E-6,2.48567931493554E-6,-1.47437978266607E-6,300.0003357,300.0011902,5.403,30.489,51.901696933967,18.4221590178525,12.6039028,0,0,0,4449,300.00945,17.946,,,,,,,,,,,,,,,,,21.440407,,,,,,300.00076295,,,,
,27552625.775,300.00076295,66.931,8.93432844044054E-5,1.43218576092707E-6,1,1.99850670813958,40.0298881530762,1.98136584597908,8.85000178590417,0.000951892818679522,0.000153154887830355,0.25,-1.01800028864197E-6,8.93412872286886E-5,-9.58645002456832E-7,300.0003052,300.0012207,55.432,78.43,52.2682807094863,18.4185743657501,12.41659925,0,0,0,4449,300.01035,66.931,,,,,,,,,,,,,,,,,20.677984,,,,,,300.00076295,,,,
,27552629.765,300.0004578,115.884,0.000174915716783495,1.34647555107615E-6,1,1.99850670813958,40.0298881530762,1.98134066469918,8.85000178590417,0.00186208233114608,0.000308559454381098,0.25,-1.17320949041739E-6,0.000174911264026492,-1.05702811571791E-6,299.9997559,300.0011597,103.37,128.398,52.402720814794,18.4229117379827,12.47924135,0,0,0,4449,300.0084,115.884,,,,,,,,,,,,,,,,,21.440407,,,,,,300.0004578,,,,
,27552633.775,299.9998627,163.556,0.000260941779600212,1.35341867341378E-6,1,1.99850670813958,40.0298881530762,1.98131707550042,8.85000178590417,0.00277543282013567,0.000474309185439334,0.25,-4.33478533900046E-7,0.000260934267755577,-2.60198892307292E-7,299.9996033,300.0001221,151,176.112,52.4246064133325,18.4216928280156,12.6039028,0,0,0,4449,300.01045,163.556,,,,,,,,,,,,,,,,,21.440407,,,,,,299.9998627,,,,
,27552637.775,300.00013735,213.007,0.000346139552594787,1.37676870745107E-6,1,1.99850670813958,40.0298881530762,1.98134106735548,8.85000178590417,0.00368221920204479,0.000625924189552631,0.25,-8.8110074743807E-7,0.000346129788425159,-6.51237214888759E-7,300,300.0002747,201.679,224.335,53.0116094312748,18.4197831018238,12.6039028,0,0,0,4449,300.01085,213.007,,,,,,,,,,,,,,,,,21.059195,,,,,,300.00013735,,,,
,27552641.79,300.00001525,262.8085,0.000432415808957334,1.41638208898222E-6,1,1.99850670813958,40.0298881530762,1.98135643220372,8.85000178590417,0.00459926238155563,0.000786546765780468,0.25,-6.67804147229232E-7,0.000432403324783088,-3.8065379294864E-7,299.9994507,300.0005798,251.396,274.221,52.2565562816978,18.419437109652,12.41659925,0,0,0,4449,300.00485,262.8085,,,,,,,,,,,,,,,,,20.677984,,,,,,300.00001525,,,,
,27552645.775,299.9999542,311.779,0.000518720292085307,1.41449067586002E-6,1,1.99850670813958,40.0298881530762,1.98141229157572,8.85000178590417,0.00551725924084549,0.000944162220353833,0.25,-7.44135456362684E-7,0.000518705279924995,-3.99680911444343E-7,299.9988403,300.0010681,299.307,324.251,52.3730189310632,18.4183196711366,12.47924135,0,0,0,4449,300.00785,311.779,,,,,,,,,,,,,,,,,21.440407,,,,,,299.9999542,,,,
,27552649.75,300.0000305,359.35,0.000604270865875608,1.3917127099401E-6,1,1.99850670813958,40.0298881530762,1.98146503497804,8.85000178590417,0.00642700114288667,0.00110201072788972,0.25,-6.6906628789658E-7,0.000604253245485768,-2.67813556999593E-7,300,300.000061,346.934,371.766,52.2245095124094,18.4219935815527,12.5412607,0,0,0,4449,300.01025,359.35,,,,,,,,,,,,,,,,,21.440407,,,,,,300.0000305,,,,
,27552653.76,299.99937435,408.9835,0.000688110492347826,1.40993649006664E-6,1,1.99850670813958,40.0298881530762,1.98138081093124,8.85000178590417,0.00731815359961024,0.0012563873877714,0.25,-6.18079641208348E-7,0.000688090346368278,-1.61160868076238E-7,299.9990234,299.9997253,396.597,421.37,52.6145421435056,18.4186627872093,12.47924135,0,0,0,4449,300.00995,408.9835,,,,,,,,,,,,,,,,,21.059195,,,,,,299.99937435,,,,
,27552657.765,299.9996338,457.53,0.000775332709780312,1.51865806635915E-6,1,1.99850670813958,40.0298881530762,1.98134128430924,8.85000178590417,0.00824464581815005,0.00142123791493193,0.25,-1.67621528333555E-7,0.00077530965308875,3.47193126472814E-7,299.9990845,300.0001831,444.139,470.921,52.1346222326978,18.4208274364003,12.47924135,0,0,0,4449,300.01155,457.53,,,,,,,,,,,,,,,,,21.440407,,,,,,299.9996338,,,,
,27552661.76,300.00013735,504.8185,0.000859167547074487,1.45149415284741E-6,1,1.99850670813958,40.0298881530762,1.98137513055148,8.85000178590417,0.00913613506307353,0.00157571468399812,0.25,-1.12768828570871E-7,0.000859141935238601,4.57706178013263E-7,300,300.0002747,493.632,516.005,51.8884092491401,18.417493064017,12.6039028,0,0,0,4449,300.0118,504.8185,,,,,,,,,,,,,,,,,21.440407,,,,,,300.00013735,,,,
,27552665.74,300.0005493,553.646,0.000943006699261484,1.61450398338934E-6,1,1.99850670813958,40.0298881530762,1.98133202857557,8.8600018620491,0.0100277441612579,0.0017277143988306,0.25,-2.86023820029216E-7,0.000942978683652815,3.40121459501811E-7,300.0002441,300.0008545,541.289,566.003,51.7633486860632,18.4209510993882,12.6039028,0,0,0,4449,300.01165,553.646,,,,,,,,,,,,,,,,,21.440407,,,,,,300.0005493,,,,
,27552669.74,300.00050355,601.8245,0.00102880702691489,1.52681170138871E-6,1,1.99850670813958,40.0298881530762,1.98143400217274,8.85000178590417,0.0109404365819959,0.00188634776485178,0.25,-1.8579134832904E-7,0.00102877638036155,4.97316113797663E-7,299.999939,300.0010681,590.667,612.982,52.5387241771402,18.423051833558,12.6039028,0,0,0,4449,300.0121,601.8245,,,,,,,,,,,,,,,,,20.677984,,,,,,300.00050355,,,,
,27552673.725,300.0003357,649.9335,0.00111277339307488,1.40378704124359E-6,1,1.99850670813958,40.0298881530762,1.98133384953574,8.85000178590417,0.0118323937321566,0.00204237791226035,0.25,3.53246995717141E-9,0.00111274011544807,7.42386659184672E-7,300.0002747,300.0003967,637.646,662.221,52.5903116594094,18.421851007924,12.6039028,0,0,0,4449,300.0106,649.9335,,,,,,,,,,,,,,,,,21.059195,,,,,,300.0003357,,,,
,27552677.74,300.0007782,698.945,0.00119717266286936,1.43605616832236E-6,1,1.99850670813958,40.0298881530762,1.98132152657206,8.8600018620491,0.0127295131779999,0.00219867614367753,0.25,1.35978525621655E-7,0.00119713675671061,9.30865262392957E-7,300.0005493,300.0010071,686.685,711.205,52.3917780155248,18.4213483771163,12.47924135,0,0,0,4449,300.01015,698.945,,,,,,,,,,,,,,,,,21.440407,,,,,,300.0007782,,,,
,27552681.73,300.0012207,745.6245,0.0012809894434614,1.34867938020788E-6,1,1.99850670813958,40.0298881530762,1.98140093317053,8.8600018620491,0.013621104390137,0.0023535985113268,0.25,2.29906015983525E-7,0.00128095094920184,1.08044166542999E-6,300.0010681,300.0013733,733.434,757.815,51.7758547423709,18.4216863034885,12.6039028,0,0,0,4449,300.00905,745.6245,,,,,,,,,,,,,,,,,21.440407,,,,,,300.0012207,,,,
,27552685.72,300.00132755,794.4405,0.00136557810338534,1.38404380056951E-6,1,1.99850670813958,40.0298881530762,1.98128025282066,8.85000178590417,0.0145192950772004,0.00251126735233848,0.25,4.70662996181593E-7,0.00136553691373664,1.37734498141014E-6,300.0013123,300.0013428,782.167,806.714,52.9412628645441,18.4231866341931,12.6039028,0,0,0,4449,300.01085,794.4405,,,,,,,,,,,,,,,,,21.821617,,,,,,300.00132755,,,,
,27552689.715,300.0016022,841.2495,0.00144740328732262,1.76121228059425E-6,1,1.99850670813958,40.0298881530762,1.98137922163073,8.85000178590417,0.0153897687082624,0.00266336325313608,0.25,6.393208799834E-7,0.00144735952311398,1.60033181573624E-6,300.0014954,300.001709,828.693,853.806,52.3003274787748,18.4214267150775,12.6039028,0,0,0,4449,300.0083,841.2495,,,,,,,,,,,,,,,,,21.059195,,,,,,300.0016022,,,,
,27552693.74,300.0012207,890.2935,0.00153101643324318,1.34454998987098E-6,1,1.99850670813958,40.0298881530762,1.98132272417252,8.85000178590417,0.0162791160210746,0.00281273125700553,0.25,2.61406381694047E-7,0.00153097043593766,1.27793581811998E-6,300.0009155,300.0015259,878.216,902.371,52.5184018356402,18.4201650513107,12.6039028,0,0,0,4449,300.0093,890.2935,,,,,,,,,,,,,,,,,21.440407,,,,,,300.0012207,,,,
,27552697.76,300.0022278,937.503,0.001614862324001,1.6214297842687E-6,1,1.99850670813958,40.0298881530762,1.98142531655544,8.85000178590417,0.0171706669090603,0.00297170101302816,0.25,7.25563663058339E-7,0.00161481345633945,1.79775375489142E-6,300.0020752,300.0023804,926.445,948.561,52.3550414751209,18.4225596140694,12.47924135,0,0,0,4449,300.00705,937.503,,,,,,,,,,,,,,,,,20.677984,,,,,,300.0022278,,,,
,27552701.71,300.0011749,975.88,0.00169186939438914,1.12466299506011E-6,1,1.99850670813958,40.0298881530762,1.9813098254383,8.85000178590417,0.0179881141953875,0.00311529260930139,0.25,9.53505574340614E-7,0.00169181812528538,2.07681887895172E-6,300.0010681,300.0012817,969.252,982.508,51.6421962655824,18.4188159127812,12.6039028,0,0,0,4449,300.006,975.88,,,,,,,,,,,,,,,,,21.059195,,,,,,300.0011749,,,,
,27552725.7,300.00157165,1000.131,0.00174624172852593,8.26079929016956E-7,1,1.99850670813958,40.0298881530762,1.98140142168479,8.85000178590417,0.018567672651682,0.00321182895888759,0.25,6.33969003472824E-7,0.0017461890234652,1.79337703958516E-6,300.0015564,300.0015869,1000.102,1000.16,52.6286114568517,18.4218814319328,12.6039028,0,0,0,4417,300.00885,1000.131,,,,,,,,,,,,,,,,,21.059195,,,,,,300.00157165,,,,