File: Projekt_andmed1/PDCALIBRATION_ HYS 300K 10000 OE SWEEP 10 OE-SEC _15112018.DAT
[Header]
; VSM Data File (default extension .dat)
; Copyright (c) 2003, Quantum Design, Inc. All rights reserved.
TITLE,10000 OE
FILEOPENTIME,27569651.13,11/16/2018,1:03 am
BYAPP,VSM,1.0,1.0
INFO,PPMS VSM Option Release 1.3.6 Build 0,APPNAME
INFO,221,COIL_SERIAL_NUMBER
INFO,0,MOMENT_UNITS
INFO,PdCalibration_ Hys 300K Sweep 10 Oe-Sec _15112018,SAMPLE_MATERIAL
INFO,Pd Calibration - 2173,SAMPLE_COMMENT
INFO,314.3,SAMPLE_MASS
INFO,,SAMPLE_VOLUME
INFO,,SAMPLE_MOLECULAR_WEIGHT
INFO,,SAMPLE_SIZE
INFO,Cylinder,SAMPLE_SHAPE
INFO,35.38,SAMPLE_OFFSET
DATATYPE,COMMENT,1
DATATYPE,TIME,2
STARTUPAXIS,X,2
STARTUPAXIS,Y1,5
[Data]
Comment,Time Stamp (sec),Temperature (K),Magnetic Field (Oe),Moment (emu),M. Std. Err. (emu),Transport Action,Averaging Time (sec),Frequency (Hz),Peak Amplitude (mm),Center Position (mm),Coil Signal' (mV),Coil Signal" (mV),Range (mV),M. Quad. Signal (emu),M. Raw' (emu),M. Raw" (emu),Min. Temperature (K),Max. Temperature (K),Min. Field (Oe),Max. Field (Oe),Mass (grams),Motor Lag (deg),Pressure (Torr),VSM Status (code),Motor Status (code),Measure Status (code),PPMS Status (code),System Temp. (K),System Field (Oe),Sample Position (deg),Bridge 1 Resistance (ohms),Bridge 1 Excitation (에),Bridge 2 Resistance (ohms),Bridge 2 Excitation (에),Bridge 3 Resistance (ohms),Bridge 3 Excitation (에),Bridge 4 Resistance (ohms),Bridge 4 Excitation (에),Signal 1 Vin (V),Signal 2 Vin (V),Digital Inputs (code),Drive 1 Iout (mA),Drive 1 Ipower (W),Drive 2 Iout (mA),Drive 2 Ipower (W),Pressure (),Map 20 (),Map 21 (),Map 22 (),Map 23 (),Map 24 (),Map 25 (),Map 26 (),Map 27 (),Map 28 (),Map 29 ()
"10000",27569652.28
,27569799.09,300.00267025,9647.9185,0.016611921467366,9.07074172840089E-6,1,1.99850670813958,40.0298881530762,1.98124124906733,8.85000178590417,0.176563522109939,0.0305620932032957,2.5,7.89010445050361E-6,0.0166114195088016,1.8905729025638E-5,300.0021362,300.0032043,9636.155,9659.682,52.3495700754863,18.406561265259,16.0188007,0,0,0,4449,299.9966,9647.9185,,,,,,,,,,,,,,,,,20.677984,,,,,,300.00267025,,,,
,27569831.05,300.0015411,9243.708,0.0158969275840998,9.10393069509043E-6,1,1.99850670813958,40.0298881530762,1.98120366765421,8.85000178590417,0.168961773832584,0.0292415261652369,2.5,7.11602687310346E-6,0.0158964480415191,1.76581362631159E-5,300.0014648,300.0016174,9230.842,9256.574,52.0158146977747,18.408677882894,16.0188007,0,0,0,4449,299.99985,9243.708,,,,,,,,,,,,,,,,,21.440407,,,,,,300.0015411,,,,
,27569863.025,300.0014038,8846.2945,0.0152406842780806,6.50434861932407E-6,1,1.99850670813958,40.0298881530762,1.98122347625645,8.8600018620491,0.161987492417473,0.0280398959215057,2.5,7.31292476859628E-6,0.0152402241987948,1.74206531150931E-5,300.0006409,300.0021667,8834.771,8857.818,51.5616885281016,18.4087615445368,16.0188007,0,0,0,4449,299.9963,8846.2945,,,,,,,,,,,,,,,,,20.296772,,,,,,300.0014038,,,,
,27569895,299.9993744,8454.175,0.0145168659333776,8.66241261720199E-6,1,1.99850670813958,40.0298881530762,1.98134660153037,8.85000178590417,0.154311009665686,0.0266663952560277,2.5,2.88133522105203E-6,0.0145164313141716,1.25096532761515E-5,299.9987488,300,8441.579,8466.771,52.006435155544,18.4121888582751,15.86036345,0,0,0,4449,299.99965,8454.175,,,,,,,,,,,,,,,,,20.677984,,,,,,299.9993744,,,,
,27569926.985,299.9976959,8063.553,0.0138712340463973,5.71250491085093E-6,1,1.99850670813958,40.0298881530762,1.98132064673272,8.85000178590417,0.14743761217538,0.0255300914714725,2.5,7.45567108623979E-6,0.013870816339804,1.66561447209562E-5,299.9971313,299.9982605,8050.078,8077.028,52.3245579628709,18.4096065889219,15.86036345,0,0,0,4449,300.0021,8063.553,,,,,,,,,,,,,,,,,21.440407,,,,,,299.9976959,,,,
,27569958.93,299.99906925,7678.918,0.0132131431941688,5.82466376016708E-6,1,1.99850670813958,40.0298881530762,1.98129705151238,8.85000178590417,0.140443355168715,0.0243057560440091,2.5,5.89426779733662E-6,0.0132127455092622,1.4658427048947E-5,299.9987183,299.9994202,7666.603,7691.233,52.1369671182555,18.4119664451251,16.0188007,0,0,0,4449,300.01395,7678.918,,,,,,,,,,,,,,,,,21.440407,,,,,,299.99906925,,,,
,27569990.96,300.0056,7294.8075,0.0125497330372449,5.21911945900333E-6,1,1.99850670813958,40.0298881530762,1.98138908082816,8.85000178590417,0.133395273467642,0.0231013317077064,2.5,6.9990381737452E-6,0.0125493516451792,1.53243414902002E-5,300.005127,300.006073,7281.573,7308.042,52.494171351544,18.411240421471,16.0188007,0,0,0,4449,299.99265,7294.8075,,,,,,,,,,,,,,,,,19.915562,,,,,,300.0056,,,,
,27570022.885,300.002182,6915.6245,0.0118624585520315,7.09427315393816E-6,1,1.99850670813958,40.0298881530762,1.98121926337462,8.8600018620491,0.12608296383778,0.0218151660735608,2.5,4.80423496870662E-6,0.0118621004876155,1.26743718266643E-5,300.0020752,300.0022888,6903.125,6928.124,51.7273937741786,18.4133511679749,16.0188007,0,0,0,4449,299.9855,6915.6245,,,,,,,,,,,,,,,,,20.677984,,,,,,300.002182,,,,
,27570054.86,299.99697875,6537.7685,0.0112090468049947,5.34601819066087E-6,1,1.99850670813958,40.0298881530762,1.98130484932522,8.8600018620491,0.119138481539336,0.020640476221926,2.5,6.99324512912479E-6,0.0112087087134015,1.4429771120149E-5,299.9967651,299.9971924,6525.779,6549.758,52.6020360871979,18.4153285210231,16.0188007,0,0,0,4449,300.002,6537.7685,,,,,,,,,,,,,,,,,21.440407,,,,,,299.99697875,,,,
,27570086.93,299.9976959,6160.5905,0.0105621773497887,5.33848578583681E-6,1,1.99850670813958,40.0298881530762,1.98136516367924,8.8600018620491,0.112267946394439,0.0194405122909268,2.5,5.70705427469146E-6,0.010561859079013,1.27148049340917E-5,299.9976196,299.9977722,6148.741,6172.44,52.6098523723902,18.4138994458865,15.86036345,0,0,0,4449,300.0042,6160.5905,,,,,,,,,,,,,,,,,21.440407,,,,,,299.9976959,,,,
,27570118.84,300.0010834,5789.627,0.00991482288930504,5.73108838279517E-6,1,1.99850670813958,40.0298881530762,1.98135070206839,8.8600018620491,0.105384473412738,0.0182595058834205,2.5,6.35677776017271E-6,0.00991452233937028,1.29354696271906E-5,300.0006104,300.0015564,5777.805,5801.449,51.7406814590055,18.4175538951125,16.0188007,0,0,0,4449,300.00055,5789.627,,,,,,,,,,,,,,,,,21.440407,,,,,,300.0010834,,,,
,27570150.87,299.99853515,5417.3775,0.00926465365469387,4.83368664979321E-6,1,1.99850670813958,40.0298881530762,1.98136954114571,8.85000178590417,0.0984747679653874,0.017062143405768,2.5,5.92605839972822E-6,0.00926437355026343,1.20736944709167E-5,299.9980774,299.9989929,5406.786,5427.969,52.3956861581209,18.4166912445056,16.0196004,0,0,0,4449,300.00095,5417.3775,,,,,,,,,,,,,,,,,21.440407,,,,,,299.99853515,,,,
,27570182.82,299.9976654,5048.3745,0.00862258275650666,4.4877109962498E-6,1,1.99850670813958,40.0298881530762,1.98135237683204,8.85000178590417,0.0916497517559585,0.0158774155743453,2.5,5.31449231273678E-6,0.0086223224244462,1.10362388495022E-5,299.9971924,299.9981384,5036.186,5060.563,52.4589980681786,18.4178193520335,16.09921455,0,0,0,4449,300.0083,5048.3745,,,,,,,,,,,,,,,,,21.440407,,,,,,299.9976654,,,,
,27570214.8,299.99638365,4679.7255,0.00799780171644632,4.51041897220463E-6,1,1.99850670813958,40.0298881530762,1.98127154745701,8.85000178590417,0.0850047812184622,0.0147311494908042,2.5,5.37740304903902E-6,0.00799756023769707,1.06850109834744E-5,299.9960022,299.9967651,4667.961,4691.49,52.8709162978133,18.4184487635184,15.93918655,0,0,0,4449,300.00015,4679.7255,,,,,,,,,,,,,,,,,21.440407,,,,,,299.99638365,,,,
,27570246.76,299.99645995,4314.8455,0.0073573848345192,5.00579583266125E-6,1,1.99850670813958,40.0298881530762,1.98138332075065,8.85000178590417,0.0782035511378727,0.0135452500441942,2.5,4.2834265986499E-6,0.00735716309474551,9.16626637767191E-6,299.9959717,299.9969482,4303.151,4326.54,52.4746306385632,18.4165785466711,15.93918655,0,0,0,4449,300.0027,4314.8455,,,,,,,,,,,,,,,,,21.059195,,,,,,299.99645995,,,,
,27570278.775,299.9967041,3946.9005,0.00672187311096762,3.09328135599343E-6,1,1.99850670813958,40.0298881530762,1.98142904281358,8.85000178590417,0.0714503800002743,0.0123739835192753,2.5,3.76869537852972E-6,0.00672167055544083,8.22990873872105E-6,299.9967041,299.9967041,3935.292,3958.509,52.4988611226594,18.4209196276886,16.1796284,0,0,0,4449,300.0085,3946.9005,,,,,,,,,,,,,,,,,21.440407,,,,,,299.9967041,,,,
,27570310.685,299.9986267,3583.0095,0.00608453069303913,3.03582821175078E-6,1,1.99850670813958,40.0298881530762,1.98147826644342,8.8600018620491,0.0646776884379763,0.0111985454555083,2.5,3.18056962179064E-6,0.00608434709450082,7.21907793257539E-6,299.9975586,299.9996948,3570.286,3595.733,52.7169354795248,18.4198043176964,16.0196004,0,0,0,4449,300.00385,3583.0095,,,,,,,,,,,,,,,,,21.440407,,,,,,299.9986267,,,,
,27570342.65,300.00192265,3220.26,0.00545015900674409,2.93548397271303E-6,1,1.99850670813958,40.0298881530762,1.98135860828779,8.85000178590417,0.0579305940705358,0.0100330048116567,2.5,3.09335905746306E-6,0.00544999379566847,6.71096961367393E-6,300.0011292,300.0027161,3208.665,3231.855,52.7020845376594,18.4205861008747,15.93918655,0,0,0,4449,300.0052,3220.26,,,,,,,,,,,,,,,,,21.440407,,,,,,300.00192265,,,,
,27570374.625,300.00306705,2856.9585,0.00482956287182308,2.36635537823528E-6,1,1.99850670813958,40.0298881530762,1.98137312828493,8.85000178590417,0.0513334292198917,0.00889706680278845,2.5,3.34609019844953E-6,0.00482941587389916,6.55197209439184E-6,300.0028687,300.0032654,2845.49,2868.427,52.4777571526402,18.4198503883943,16.0188007,0,0,0,4449,300.00055,2856.9585,,,,,,,,,,,,,,,,,21.440407,,,,,,300.00306705,,,,
,27570406.62,299.9983673,2495.9725,0.00419846753627211,2.81748307075378E-6,1,1.99850670813958,40.0298881530762,1.98136268591216,8.85000178590417,0.0446260320748661,0.00773016011174263,2.5,2.50808014528161E-6,0.00419834063557453,5.29518051309793E-6,299.99823,299.9985046,2484.49,2507.455,52.6489337983517,18.4248342738305,16.1796284,0,0,0,4449,300.001,2495.9725,,,,,,,,,,,,,,,,,21.440407,,,,,,299.9983673,,,,
,27570442.56,299.99871825,2092.785,0.00349754153381249,2.46162493904463E-6,1,1.99850670813958,40.0298881530762,1.98139763677074,8.85000178590417,0.0371874340093782,0.00644238749155137,0.25,2.1575866427798E-6,0.00349743572891862,4.47944203562676E-6,299.9983215,299.999115,2081.345,2104.225,52.2800051372748,18.423974373725,16.09921455,0,0,0,4449,300.00785,2092.785,,,,,,,,,,,,,,,,,21.440407,,,,,,299.99871825,,,,
,27570474.54,300.000885,1736.8635,0.00287854367871634,1.65387653578206E-6,1,1.99850670813958,40.0298881530762,1.98139246757241,8.85000178590417,0.0306067210479036,0.00529738928243691,0.25,1.32371609760808E-6,0.00287845668855792,3.23477465377285E-6,300.0005188,300.0012512,1726.581,1747.146,52.605944229794,18.4247036150964,16.1796284,0,0,0,4449,300.004,1736.8635,,,,,,,,,,,,,,,,,21.440407,,,,,,300.000885,,,,
,27570506.525,300.0005493,1382.5525,0.00225913110329041,1.94772228630065E-6,1,1.99850670813958,40.0298881530762,1.9813839547371,8.85000178590417,0.0240219783937496,0.00414940897227456,0.25,2.81126412161975E-7,0.00225906335554181,1.78102328410962E-6,300.0001831,300.0009155,1372.383,1392.722,52.0181595833324,18.42117221034,16.1796284,0,0,0,4449,300.0076,1382.5525,,,,,,,,,,,,,,,,,21.059195,,,,,,300.0005493,,,,
,27570538.475,300.0060425,1031.614,0.00165988320024678,1.36230412801199E-6,1,1.99850670813958,40.0298881530762,1.9813354608574,8.85000178590417,0.0176490808408093,0.00305162197054286,0.25,4.83009512175095E-7,0.00165983293873854,1.58512574939155E-6,300.0058594,300.0062256,1020.471,1042.757,53.3039384974672,18.4231362713062,16.1796284,0,0,0,4449,299.9983,1031.614,,,,,,,,,,,,,,,,,21.440407,,,,,,300.0060425,,,,
,27570570.46,300.00520325,683.8185,0.00105393884301297,1.18881795427748E-6,1,1.99850670813958,40.0298881530762,1.98142656942018,8.85000178590417,0.0112086010257015,0.00192690318688999,0.25,-7.09217025461175E-7,0.00105390762921907,-9.36311644903464E-9,300.0047607,300.0056458,672.816,694.821,52.6004728301594,18.4239772591505,16.1796284,0,0,0,4449,299.99415,683.8185,,,,,,,,,,,,,,,,,20.677984,,,,,,300.00520325,,,,
,27570609.32,300.00178525,266.601,0.000350883672328896,1.20091707927965E-6,1,1.99850670813958,40.0298881530762,1.98140566250511,8.85000178590417,0.00373358754486833,0.00062998103213625,0.25,-1.32030075603832E-6,0.000350874038580705,-1.0872649181784E-6,300.00177,300.0018005,258.551,274.651,52.6512786839094,18.4245619726073,16.26084995,0,0,0,4449,299.99995,266.601,,,,,,,,,,,,,,,,,21.440407,,,,,,300.00178525,,,,
,27570646.4,300.00088505,-122.685,-0.000359774796419167,0.000104751577038329,1,1.99850670813958,40.0298881530762,1.98139239689846,8.85000178590417,-0.00385399772020076,-0.000496301935070016,0.25,1.54260282141315E-5,-0.000359774273077619,1.51866607836862E-5,300.0004578,300.0013123,-132.135,-113.235,52.6098523723902,18.4239667140746,16.09921455,0,0,0,4449,299.99695,-122.685,,,,,,,,,,,,,,,,,21.440407,,,,,,300.00088505,,,,
,27570690.4,299.99942015,-577.6095,-0.00112775352758107,1.45634194918798E-6,1,1.99850670813958,40.0298881530762,1.98143568119292,8.85000178590417,-0.0119868229304955,-0.00210155152972142,0.25,-2.9730339439473E-6,-0.00112771785957805,-3.72178824870604E-6,299.9989929,299.9998474,-587.369,-567.85,52.9099977237748,18.425782458757,16.1796284,0,0,0,4449,299.9981,-577.6095,,,,,,,,,,,,,,,,,20.677984,,,,,,299.99942015,,,,
,27570730.92,299.99897765,-992.8325,-0.00183377227303285,1.51998947485963E-6,1,1.99850670813958,40.0298881530762,1.98136050849229,8.85000178590417,-0.0194914213891019,-0.003410835230672,0.25,-4.24686221369365E-6,-0.00183371469944053,-5.4642991440682E-6,299.9985657,299.9993896,-995.615,-990.05,52.4644694678132,18.4265975112211,15.8595724,0,0,0,4449,300.00485,-992.8325,,,,,,,,,,,,,,,,,21.440407,,,,,,299.99897765,,,,
,27570769.03,299.9948883,-1377.9825,-0.00249712060839498,1.6548166184062E-6,1,1.99850670813958,40.0298881530762,1.98134979732162,8.85000178590417,-0.0265442875314267,-0.00463202600543352,0.25,-4.59629202590046E-6,-0.0024970433285808,-6.2541148275856E-6,299.994751,299.9950256,-1383.52,-1372.445,52.727878278794,18.4242172039844,16.09921455,0,0,0,4449,300.0008,-1377.9825,,,,,,,,,,,,,,,,,20.677984,,,,,,299.9948883,,,,
,27570806.305,299.9953613,-1742.154,-0.00313853540879852,2.02719504404167E-6,1,1.99850670813958,40.0298881530762,1.98142180165425,8.85000178590417,-0.0333631352186815,-0.00582508206964126,0.25,-6.06508311790312E-6,-0.00313843805535201,-8.14855873943496E-6,299.9946594,299.9960632,-1752.577,-1731.731,52.761488305121,18.4238360682252,16.26084995,0,0,0,4449,300.0104,-1742.154,,,,,,,,,,,,,,,,,21.440407,,,,,,299.9953613,,,,
,27570844.26,300.00154115,-2120.222,-0.00379394677982958,2.0720542542438E-6,1,1.99850670813958,40.0298881530762,1.98133917137974,8.85000178590417,-0.0403292002583089,-0.00703799033616309,0.25,-7.02663713415922E-6,-0.00379382854918675,-9.5451634647959E-6,300.0007935,300.0022888,-2129.516,-2110.928,52.832616500371,18.4266868110439,16.1796284,0,0,0,4449,300.00275,-2120.222,,,,,,,,,,,,,,,,,21.440407,,,,,,300.00154115,,,,
,27570884.23,300.00006105,-2509.8925,-0.00446136777843771,1.95401566368215E-6,1,1.99850670813958,40.0298881530762,1.98144105779361,8.85000178590417,-0.0474286152633642,-0.00826221896063478,0.25,-6.91952255765518E-6,-0.00446122986472685,-9.88101369882534E-6,299.999115,300.0010071,-2520.26,-2499.525,52.8216737011017,18.4288444704526,16.26084995,0,0,0,4449,300.00095,-2509.8925,,,,,,,,,,,,,,,,,21.440407,,,,,,300.00006105,,,,
,27570920.21,300.00090025,-2841.25,-0.0050206761441386,2.49092318578055E-6,1,1.99850670813958,40.0298881530762,1.98137828323549,8.8600018620491,-0.0533590453951716,-0.00928313473797408,2.5,-6.67438344790881E-6,-0.00502052155485237,-1.00070600724379E-5,300.0007324,300.0010681,-2851.546,-2830.954,53.0897722831979,18.4265043828048,16.1796284,0,0,0,4449,299.99895,-2841.25,,,,,,,,,,,,,,,,,21.440407,,,,,,300.00090025,,,,
,27570952.19,299.9975281,-3146.264,-0.00554612971329212,2.59630085209048E-6,1,1.99850670813958,40.0298881530762,1.98142958612583,8.8600018620491,-0.0589458223378194,-0.0102499752587867,2.5,-6.90564790416339E-6,-0.00554595987322512,-1.0586945681452E-5,299.9974976,299.9975586,-3156.673,-3135.855,52.4347675840825,18.4271401118261,16.1804361,0,0,0,4449,300.00115,-3146.264,,,,,,,,,,,,,,,,,20.677984,,,,,,299.9975281,,,,
,27570984.195,299.9981689,-3459.7655,-0.00609109790918708,2.49698170749914E-6,1,1.99850670813958,40.0298881530762,1.98143005435312,8.85000178590417,-0.0647385327516929,-0.0112535468502998,2.5,-7.24545946715912E-6,-0.00609091150086028,-1.12882654342334E-5,299.9976501,299.9986877,-3469.708,-3449.823,52.8881121252364,18.4278023305898,16.26084995,0,0,0,4449,300.0045,-3459.7655,,,,,,,,,,,,,,,,,21.440407,,,,,,299.9981689,,,,
,27571016.135,299.99882505,-3741.8415,-0.00657378474753274,3.02745130269672E-6,1,1.99850670813958,40.0298881530762,1.98140361788215,8.8600018620491,-0.0698684560285413,-0.0121414768568954,2.5,-7.47199060457282E-6,-0.00657358367589772,-1.18349973430959E-5,299.9987793,299.9988708,-3751.106,-3732.577,52.5895300308902,18.4261077003654,16.1804361,0,0,0,4449,300.00485,-3741.8415,,,,,,,,,,,,,,,,,21.059195,,,,,,299.99882505,,,,
,27571048.12,299.998703,-4038.4235,-0.00690821032014225,0.000567323366012592,1,1.99850670813958,40.0298881530762,1.98137469581901,8.85000178590417,-0.0751322786484019,-0.00284931184938083,2.5,0.000924357660837873,-0.00690861777622378,0.000919745065670513,299.99823,299.999176,-4039.341,-4037.506,52.8076043877556,18.4278179373628,16.1804361,0,0,0,4449,300.00365,-4038.4235,,,,,,,,,,,,,,,,,21.440407,,,,,,299.998703,,,,
,27571080.125,300.00126645,-4329.3245,-0.00756822687382657,3.77037572390568E-6,1,1.99850670813958,40.0298881530762,1.98143619392723,8.85000178590417,-0.0804403365121071,-0.0139706099501292,2.5,-7.87126504234215E-6,-0.00756799530924496,-1.289394436447E-5,300.000885,300.0016479,-4339.437,-4319.212,52.2862581654286,18.4290984407578,16.1804361,0,0,0,4449,300.00135,-4329.3245,,,,,,,,,,,,,,,,,21.440407,,,,,,300.00126645,,,,
,27571120.045,300.00065615,-4704.232,-0.0081968979801482,4.34608976824396E-6,1,1.99850670813958,40.0298881530762,1.98139891200282,8.85000178590417,-0.0871215631547953,-0.015125920192956,2.5,-8.06296258708387E-6,-0.00819664767173647,-1.35026116289691E-5,300.0004883,300.000824,-4714.02,-4694.444,52.7833739036594,18.428905385432,16.26084995,0,0,0,4449,299.9996,-4704.232,,,,,,,,,,,,,,,,,21.440407,,,,,,300.00065615,,,,
,27571152.07,299.9998474,-4997.068,-0.00872272475480222,4.94957038430855E-6,1,1.99850670813958,40.0298881530762,1.98138304173713,8.85000178590417,-0.0927110953188625,-0.0160877790898367,2.5,-7.79619944300765E-6,-0.00872245916714237,-1.3584484031421E-5,299.9998474,299.9998474,-5007.025,-4987.111,52.6270481998133,18.428825760101,16.1804361,0,0,0,4449,300.0033,-4997.068,,,,,,,,,,,,,,,,,21.440407,,,,,,299.9998474,,,,
,27571190.085,299.99987795,-5321.7215,-0.00925802608981339,5.51143076354939E-6,1,1.99850670813958,40.0298881530762,1.98133519349,8.85000178590417,-0.098397931143437,-0.0170771702133976,2.5,-8.5103239968724E-6,-0.00925774406054538,-1.46535720479326E-5,299.9997559,300,-5331.665,-5311.778,52.0275391255632,18.4268541280595,16.0188007,0,0,0,4449,300.00105,-5321.7215,,,,,,,,,,,,,,,,,21.440407,,,,,,299.99987795,,,,
,27571228.75,300.0005188,-5675.147,-0.00985421206897266,4.60853709156681E-6,1,1.99850670813958,40.0298881530762,1.98143255049981,8.8600018620491,-0.104739964284044,-0.0181742930806368,2.5,-8.73452978736204E-6,-0.00985391193012711,-1.52729498663586E-5,300.0004578,300.0005798,-5680.57,-5669.724,53.1124395102556,18.4310065933745,16.3420715,0,0,0,4449,300.0044,-5675.147,,,,,,,,,,,,,,,,,21.440407,,,,,,300.0005188,,,,
,27571260.005,300.00315855,-5953.137,-0.0103364569208065,4.95688885919447E-6,1,1.99850670813958,40.0298881530762,1.98142217150504,8.85000178590417,-0.109865677122284,-0.0190606166383735,2.5,-8.88076376643723E-6,-0.0103361414204105,-1.57389808378134E-5,300.0029602,300.0033569,-5962.897,-5943.377,52.893583524871,18.4288302413145,16.26084995,0,0,0,4449,300.00035,-5953.137,,,,,,,,,,,,,,,,,21.440407,,,,,,300.00315855,,,,
,27571297.99,300.0007477,-6282.58,-0.0109164395511012,4.92025669513828E-6,1,1.99850670813958,40.0298881530762,1.9814696098557,8.8600018620491,-0.116032167760557,-0.0201351684721791,2.5,-9.8110533980991E-6,-0.0109161069373396,-1.70537440313056E-5,300.0007019,300.0007935,-6291.578,-6273.582,52.6114156294286,18.429926430296,16.1804361,0,0,0,4449,299.99885,-6282.58,,,,,,,,,,,,,,,,,21.440407,,,,,,300.0007477,,,,
,27571329.915,300.00061035,-6549.694,-0.0113123943112461,6.89289434343145E-6,1,1.99850670813958,40.0298881530762,1.98144674421073,8.85000178590417,-0.120239986682,-0.0208623773051471,2.5,-9.8951666388424E-6,-0.0113120498838081,-1.74003434493126E-5,300.0003357,300.000885,-6560.625,-6538.763,52.2893846795055,18.4259901663321,16.1804361,0,0,0,4449,299.9957,-6549.694,,,,,,,,,,,,,,,,,21.440407,,,,,,300.00061035,,,,
,27571361.965,300.0014038,-6846.1865,-0.0118575628027595,6.99201644580732E-6,1,1.99850670813958,40.0298881530762,1.98135082064822,8.85000178590417,-0.126029705618569,-0.021861212534537,2.5,-9.8503827412963E-6,-0.011857201864324,-1.77167817649673E-5,300.000946,300.0018616,-6856.172,-6836.201,52.4597796966979,18.4320376772655,16.1804361,0,0,0,4449,299.99925,-6846.1865,,,,,,,,,,,,,,,,,21.440407,,,,,,300.0014038,,,,
,27571393.905,300.00183105,-7142.0275,-0.0123621227516371,6.08640863416633E-6,1,1.99850670813958,40.0298881530762,1.98143236902121,8.8600018620491,-0.131398064184388,-0.0227901214606556,2.5,-1.00606849438152E-5,-0.0123617464578804,-1.82614403427945E-5,300.0015869,300.0020752,-7151.462,-7132.593,53.2242123885056,18.4287229011331,16.1804361,0,0,0,4449,299.99885,-7142.0275,,,,,,,,,,,,,,,,,21.440407,,,,,,300.00183105,,,,
,27571433.92,300.0013275,-7480.114,-0.0129411189673305,6.41683184426129E-6,1,1.99850670813958,40.0298881530762,1.98142882226043,8.85000178590417,-0.137550578204327,-0.0238659024325336,2.5,-1.13240388941773E-5,-0.0129407247732232,-1.99084254073563E-5,300.0012817,300.0013733,-7481.864,-7478.364,52.8888937537556,18.4296472690737,16.1804361,0,0,0,4449,299.99785,-7480.114,,,,,,,,,,,,,,,,,21.440407,,,,,,300.0013275,,,,
,27571465.845,300.0008545,-7742.524,-0.0133832341194058,6.43618272436669E-6,1,1.99850670813958,40.0298881530762,1.98138658402208,8.85000178590417,-0.142245397139755,-0.0246893996614951,2.5,-1.25256601155489E-5,-0.0133828261566518,-2.14029067835659E-5,299.9998474,300.0018616,-7750.885,-7734.163,53.0702315702172,18.4291767809658,16.3420715,0,0,0,4449,299.99805,-7742.524,,,,,,,,,,,,,,,,,21.059195,,,,,,300.0008545,,,,
,27571497.81,300.0035858,-8046.26,-0.0139152955364537,5.72440722976542E-6,1,1.99850670813958,40.0298881530762,1.98142770733735,8.85000178590417,-0.147902817393777,-0.0256749138806534,2.5,-1.33493486497817E-5,-0.0139148699605545,-2.25790296031974E-5,300.0032959,300.0038757,-8056.09,-8036.43,52.8560653559479,18.4306299644546,16.3420715,0,0,0,4449,299.9984,-8046.26,,,,,,,,,,,,,,,,,21.440407,,,,,,300.0035858,,,,
,27571529.81,300.003067,-8304.4485,-0.0143299820628836,6.07302321458904E-6,1,1.99850670813958,40.0298881530762,1.9814575465922,8.85000178590417,-0.152314423923204,-0.0264300953119564,2.5,-1.27751758620942E-5,-0.0143295446930859,-2.22798838977465E-5,300.0021667,300.0039673,-8314.461,-8294.436,52.6911417383902,18.4299700018742,16.42410755,0,0,0,4449,299.98895,-8304.4485,,,,,,,,,,,,,,,,,21.440407,,,,,,300.003067,,,,
,27571561.745,299.99754335,-8557.27,-0.0147651228498939,7.15377979269991E-6,1,1.99850670813958,40.0298881530762,1.98145085019275,8.8600018620491,-0.15693546416313,-0.0272535672456731,2.5,-1.51378729217658E-5,-0.0147646735764798,-2.49304200561194E-5,299.9968262,299.9982605,-8568.173,-8546.367,52.0447349529863,18.4321582755884,16.1804361,0,0,0,4449,299.99695,-8557.27,,,,,,,,,,,,,,,,,21.440407,,,,,,299.99754335,,,,
,27571593.745,300.00001525,-8868.7025,-0.0152957882944506,7.45731927136652E-6,1,1.99850670813958,40.0298881530762,1.9813971581815,8.85000178590417,-0.162572860798706,-0.0282247785963318,2.5,-1.49718087420107E-5,-0.0152953222070328,-2.51154748839456E-5,299.9998474,300.0001831,-8879.111,-8858.294,52.6630031116979,18.4291566451583,16.1804361,0,0,0,4449,300.00485,-8868.7025,,,,,,,,,,,,,,,,,21.440407,,,,,,300.00001525,,,,
,27571625.68,300.0041962,-9151.5075,-0.0157764320555871,7.31810329450678E-6,1,1.99850670813958,40.0298881530762,1.98143886591192,8.85000178590417,-0.167686790217616,-0.0291007424882215,2.5,-1.43571383066104E-5,-0.0157759499212901,-2.48195863776475E-5,300.0039063,300.0044861,-9160.899,-9142.116,52.8302716148133,18.4305624047993,16.3420715,0,0,0,4449,299.99255,-9151.5075,,,,,,,,,,,,,,,,,21.440407,,,,,,300.0041962,,,,
,27571657.68,300.0036621,-9427.859,-0.016225135391647,7.73870241839592E-6,1,1.99850670813958,40.0298881530762,1.9814196299885,8.8600018620491,-0.172453442253599,-0.0299338392460042,2.5,-1.53029142388476E-5,-0.0162246394930196,-2.6062626074577E-5,300.0032959,300.0040283,-9437.293,-9418.425,53.414929747198,18.4280535552182,16.26084995,0,0,0,4449,299.98735,-9427.859,,,,,,,,,,,,,,,,,21.440407,,,,,,300.0036621,,,,
,27571689.65,299.9988098,-9717.966,-0.0167555890339722,8.22559394796424E-6,1,1.99850670813958,40.0298881530762,1.98139138416552,8.85000178590417,-0.178088194494054,-0.0309173613040156,2.5,-1.63031085869812E-5,-0.0167550792951763,-2.74135839983918E-5,299.9981079,299.9995117,-9727.104,-9708.828,53.0311501442556,18.4314033043268,16.1796284,0,0,0,4449,299.99745,-9717.966,,,,,,,,,,,,,,,,,21.440407,,,,,,299.9988098,,,,
,27571721.635,300.00042725,-9967.7435,-0.0171370213965445,9.31585613477478E-6,1,1.99850670813958,40.0298881530762,1.98142826924515,8.85000178590417,-0.182148969290988,-0.0316018018965674,2.5,-1.47989468523599E-5,-0.0171365004533023,-2.61618861204307E-5,299.9997864,300.0010681,-9973.143,-9962.344,52.9373547219479,18.4323250244927,16.5061436,0,0,0,4449,299.998,-9967.7435,,,,,,,,,,,,,,,,,21.440407,,,,,,300.00042725,,,,
,27571789.585,299.99868775,-9668.7095,-0.0166746527308061,7.29362264061061E-6,1,1.99850670813958,40.0298881530762,1.98145832173669,8.85000178590417,-0.17723797544305,-0.0307442788299698,2.5,-1.38972112813059E-5,-0.016674147045585,-2.49542777416197E-5,299.9983521,299.9990234,-9680.644,-9656.775,52.6082891153517,18.4292413030931,16.5061436,0,0,0,4449,299.99525,-9668.7095,,,,,,,,,,,,,,,,,21.440407,,,,,,299.99868775,,,,
,27571821.565,299.99905395,-9261.3085,-0.0159609072730113,8.93496731853167E-6,1,1.99850670813958,40.0298881530762,1.98132411244701,8.85000178590417,-0.169639872797961,-0.0294294704284528,2.5,-1.35923566865204E-5,-0.0159604227843333,-2.41768808601514E-5,299.9986877,299.9994202,-9274.656,-9247.961,52.9897238327364,18.4318572219584,16.5061436,0,0,0,4449,299.99485,-9261.3085,,,,,,,,,,,,,,,,,21.440407,,,,,,299.99905395,,,,
,27571853.515,300.0009918,-8857.876,-0.0152710920207322,6.99121520699477E-6,1,1.99850670813958,40.0298881530762,1.98142648333047,8.85000178590417,-0.16231685649948,-0.0281553818559067,2.5,-1.26684901633084E-5,-0.0152706276883766,-2.27961720970325E-5,300.000061,300.0019226,-8870.616,-8845.136,52.8920202678325,18.4302075592896,16.5061436,0,0,0,4449,299.99715,-8857.876,,,,,,,,,,,,,,,,,21.059195,,,,,,300.0009918,,,,
,27571885.5,300.0028992,-8459.544,-0.0145817994569861,6.61289409935632E-6,1,1.99850670813958,40.0298881530762,1.98150757370003,8.85000178590417,-0.154997980985666,-0.0268765826751747,2.5,-1.12491112829015E-5,-0.0145813556799597,-2.09204692608259E-5,300.0025635,300.0032349,-8472.17,-8446.918,52.9170323804479,18.4291100967826,16.342886,0,0,0,4449,299.99355,-8459.544,,,,,,,,,,,,,,,,,20.677984,,,,,,300.0028992,,,,
,27571917.49,299.99676515,-8065.0365,-0.013900049540202,6.30912725797036E-6,1,1.99850670813958,40.0298881530762,1.98148669967802,8.85000178590417,-0.147748893599882,-0.0256251194347987,2.5,-1.12273007689665E-5,-0.0138996288701352,-2.0446997437691E-5,299.9962769,299.9972534,-8077.507,-8052.566,52.2573379102171,18.4325649101867,16.5061436,0,0,0,4449,299.99595,-8065.0365,,,,,,,,,,,,,,,,,21.440407,,,,,,299.99676515,,,,
,27571949.445,299.9956665,-7674.2045,-0.0131973590408472,6.75471265931758E-6,1,1.99850670813958,40.0298881530762,1.98145993712497,8.85000178590417,-0.140276229540608,-0.0243391430779313,2.5,-1.15782241239827E-5,-0.0131969594671251,-2.03321022769111E-5,299.9956055,299.9957275,-7686.521,-7661.888,52.1823015723709,18.4312023122954,16.342886,0,0,0,4449,300.00385,-7674.2045,,,,,,,,,,,,,,,,,21.440407,,,,,,299.9956665,,,,
,27571981.435,300.00286865,-7287.492,-0.0125241285120846,7.00972305347896E-6,1,1.99850670813958,40.0298881530762,1.98143522258012,8.85000178590417,-0.133116485854142,-0.0231104348400284,2.5,-1.22262061079147E-5,-0.0125237455355213,-2.05342026416939E-5,300.0028076,300.0029297,-7298.662,-7276.322,53.0045747746017,18.4358824645787,16.1796284,0,0,0,4449,299.998,-7287.492,,,,,,,,,,,,,,,,,21.440407,,,,,,300.00286865,,,,
,27572013.385,300.00086975,-6902.716,-0.0118549412275501,6.16007944889054E-6,1,1.99850670813958,40.0298881530762,1.9813919569071,8.85000178590417,-0.126001927156153,-0.0218708861310203,2.5,-1.11717661444499E-5,-0.0118545796871035,-1.90364658504015E-5,300.0002747,300.0014648,-6914.905,-6890.527,52.8419960426017,18.4288906480039,16.5061436,0,0,0,4449,299.9944,-6902.716,,,,,,,,,,,,,,,,,21.059195,,,,,,300.00086975,,,,
,27572045.375,300.0014038,-6520.3135,-0.0112056461632043,4.8798139114596E-6,1,1.99850670813958,40.0298881530762,1.9814696617489,8.8600018620491,-0.119106195839727,-0.0206685178640204,2.5,-1.00630400345366E-5,-0.0112053045284624,-1.7497368774355E-5,300.0009155,300.0018921,-6532.502,-6508.125,52.4652510963325,18.4318171173061,16.5061436,0,0,0,4449,299.9975,-6520.3135,,,,,,,,,,,,,,,,,21.059195,,,,,,300.0014038,,,,
,27572077.365,299.9993744,-6140.2255,-0.0105413433732859,4.48660986855024E-6,1,1.99850670813958,40.0298881530762,1.98148936239304,8.8600018620491,-0.112047500071023,-0.0194365559005182,2.5,-8.82072332046549E-6,-0.0105410230644709,-1.58148185251932E-5,299.999115,299.9996338,-6152.329,-6128.122,52.8068227592364,18.4302120698907,16.1796284,0,0,0,4449,299.99555,-6140.2255,,,,,,,,,,,,,,,,,20.677984,,,,,,299.9993744,,,,
,27572109.335,300.00082395,-5762.2265,-0.00987341500013157,4.57095350704323E-6,1,1.99850670813958,40.0298881530762,1.98146821099822,8.85000178590417,-0.104945652749604,-0.0182113621882234,2.5,-8.87733055856352E-6,-0.00987311408590454,-1.54286002073068E-5,300.0004272,300.0012207,-5774.303,-5750.15,52.9623668345633,18.4315168067884,16.5061436,0,0,0,4449,299.99665,-5762.2265,,,,,,,,,,,,,,,,,21.440407,,,,,,300.00082395,,,,
,27572141.305,300.0005951,-5386.2345,-0.00922879156456424,4.68835363429658E-6,1,1.99850670813958,40.0298881530762,1.98145841038853,8.8600018620491,-0.0980925509819121,-0.0170272679820474,2.5,-8.76629094520433E-6,-0.00922851002314844,-1.48901567694991E-5,299.9996338,300.0015564,-5398.282,-5374.187,52.423043156294,18.4312006743286,16.3420715,0,0,0,4449,299.9975,-5386.2345,,,,,,,,,,,,,,,,,21.440407,,,,,,300.0005951,,,,
,27572173.305,300.0021973,-5011.454,-0.00856788904979491,4.96957406426516E-6,1,1.99850670813958,40.0298881530762,1.98148759398477,8.8600018620491,-0.0910692116485084,-0.0158075878183939,2.5,-8.08855693080124E-6,-0.00856762722894612,-1.37742412474081E-5,300.0020142,300.0023804,-5023.333,-4999.575,53.0592887709479,18.4291536394034,16.5061436,0,0,0,4449,299.9956,-5011.454,,,,,,,,,,,,,,,,,21.440407,,,,,,300.0021973,,,,
,27572205.24,299.99858095,-4639.639,-0.00792843519751479,4.60062784348264E-6,1,1.99850670813958,40.0298881530762,1.9815048328271,8.85000178590417,-0.0842712111614021,-0.0146387970148279,2.5,-8.50653851295258E-6,-0.00792819312662738,-1.37682251072853E-5,299.9984436,299.9987183,-4650.585,-4628.693,53.0116094312748,18.4320885898292,16.5061436,0,0,0,4449,299.99165,-4639.639,,,,,,,,,,,,,,,,,21.440407,,,,,,299.99858095,,,,
,27572237.23,299.9949951,-4267.0495,-0.00727868504782318,3.85865202253368E-6,1,1.99850670813958,40.0298881530762,1.98142751070467,8.85000178590417,-0.0773624620456321,-0.0134367361012212,2.5,-7.63223592583464E-6,-0.00727846375884103,-1.24628637018961E-5,299.9949646,299.9950256,-4278.828,-4255.271,52.7841555321787,18.4275924828635,16.58900455,0,0,0,4449,299.99825,-4267.0495,,,,,,,,,,,,,,,,,21.440407,,,,,,299.9949951,,,,
,27572269.215,299.9981842,-3896.4625,-0.00664540428782188,2.82230800527871E-6,1,1.99850670813958,40.0298881530762,1.98147351663731,8.85000178590417,-0.0706313459636476,-0.0122782336976243,2.5,-7.93564133091694E-6,-0.00664520091502678,-1.23461018441743E-5,299.9977112,299.9986572,-3908.312,-3884.613,52.6942682524671,18.4284554243523,16.5061436,0,0,0,4449,300.0032,-3896.4625,,,,,,,,,,,,,,,,,21.440407,,,,,,299.9981842,,,,
,27572301.195,299.99845885,-3527.0745,-0.00599134140271548,3.8494661799667E-6,1,1.99850670813958,40.0298881530762,1.98150997823349,8.85000178590417,-0.063679334720693,-0.0110778586731583,2.5,-7.89690524687591E-6,-0.00599115747732129,-1.18735096754419E-5,299.9975281,299.9993896,-3538.839,-3515.31,52.3777087021786,18.4322515559977,16.58900455,0,0,0,4449,300.00005,-3527.0745,,,,,,,,,,,,,,,,,21.440407,,,,,,299.99845885,,,,
,27572333.22,299.9958954,-3158.1525,-0.00535866473138402,2.46622667236599E-6,1,1.99850670813958,40.0298881530762,1.98145258611706,8.85000178590417,-0.0569570297895416,-0.00988624505461641,2.5,-5.03721475296153E-6,-0.00535850199773242,-8.59413962116978E-6,299.9953308,299.99646,-3167.758,-3148.547,52.9490791497364,18.4312186492452,16.5061436,0,0,0,4449,300.00005,-3158.1525,,,,,,,,,,,,,,,,,21.440407,,,,,,299.9958954,,,,
,27572365.17,299.99658205,-2793.325,-0.00473158633883574,2.20584107459428E-6,1,1.99850670813958,40.0298881530762,1.98150077156739,8.85000178590417,-0.0502896319615406,-0.00874912975705703,2.5,-6.28973853099263E-6,-0.00473144131112788,-9.43048400263534E-6,299.99646,299.9967041,-2805.032,-2781.618,52.9787810334671,18.4285089251417,16.342886,0,0,0,4449,300.0036,-2793.325,,,,,,,,,,,,,,,,,20.677984,,,,,,299.99658205,,,,
,27572397.18,299.99679565,-2427.3385,-0.00408456100696979,2.72276937139726E-6,1,1.99850670813958,40.0298881530762,1.98147267496962,8.85000178590417,-0.0434126202880638,-0.00754981475542823,2.5,-5.16576799975321E-6,-0.00408443594743165,-7.87715624470209E-6,299.9967041,299.9968872,-2437.989,-2416.688,52.8255818436979,18.4338010049626,16.5069685,0,0,0,4449,300.00475,-2427.3385,,,,,,,,,,,,,,,,,21.440407,,,,,,299.99679565,,,,
,27572431.1,299.9989624,-2042.367,-0.00341862780764933,2.30056915912898E-6,1,1.99850670813958,40.0298881530762,1.98148651249636,8.85000178590417,-0.0363426702669916,-0.00633949420061397,0.25,-6.07655841079025E-6,-0.00341852172423119,-8.34596166327896E-6,299.9987488,299.999176,-2053.878,-2030.856,52.9889422042171,18.4317855328383,16.5069685,0,0,0,4449,300.0035,-2042.367,,,,,,,,,,,,,,,,,21.440407,,,,,,299.9989624,,,,
,27572463.115,299.99656675,-1681.9695,-0.00279539616278398,2.14759785782038E-6,1,1.99850670813958,40.0298881530762,1.98145060745641,8.85000178590417,-0.0297172346711981,-0.00518069618020946,0.25,-4.68760977018461E-6,-0.00279530981449682,-6.54336742759142E-6,299.9960022,299.9971313,-1693.383,-1670.556,52.9936319753325,18.4310251602807,16.42410755,0,0,0,4449,300.0055,-1681.9695,,,,,,,,,,,,,,,,,21.440407,,,,,,299.99656675,,,,
,27572495.065,299.9975281,-1323.659,-0.00217437034496402,1.7362307064115E-6,1,1.99850670813958,40.0298881530762,1.9814376469714,8.85000178590417,-0.0231146320871625,-0.00403244535677234,0.25,-3.90187899926018E-6,-0.00217430293885503,-5.34539735116063E-6,299.9966431,299.9984131,-1333.023,-1314.295,53.2523510151979,18.4286357125313,16.58900455,0,0,0,4449,300.00855,-1323.659,,,,,,,,,,,,,,,,,21.440407,,,,,,299.9975281,,,,
,27572527.165,300.00021365,-968.213,-0.00156293643023262,1.41105248136106E-6,1,1.99850670813958,40.0298881530762,1.98147500957799,8.85000178590417,-0.0166142685964444,-0.00290331083457254,0.25,-3.25022626396966E-6,-0.00156288754238138,-4.2878740954427E-6,300.0000916,300.0003357,-978.51,-957.916,52.8365246429671,18.4275272565495,16.58900455,0,0,0,4449,300.00375,-968.213,,,,,,,,,,,,,,,,,21.821617,,,,,,300.00021365,,,,
,27572567.015,299.99935915,-536.7695,-0.000811555283474867,1.21545967046489E-6,1,1.99850670813958,40.0298881530762,1.98150221345932,8.85000178590417,-0.00862575597775697,-0.00151522807575142,0.25,-2.40824969281974E-6,-0.000811529438816865,-2.94706451749174E-6,299.9992371,299.9994812,-546.925,-526.614,53.0788294839287,18.4317632123029,16.6718655,0,0,0,4449,299.9975,-536.7695,,,,,,,,,,,,,,,,,21.440407,,,,,,299.99935915,,,,
,27572598.96,299.9968872,-191.0585,-0.000212155220418342,1.24530387351863E-6,1,1.99850670813958,40.0298881530762,1.98151765483982,8.85000178590417,-0.0022526403301031,-0.000409466575873831,0.25,-1.88546722759425E-6,-0.000212147647034826,-2.02628614907758E-6,299.9964294,299.997345,-201.016,-181.101,52.7927534458902,18.4299957683929,16.6718655,0,0,0,4449,300.00465,-191.0585,,,,,,,,,,,,,,,,,20.677984,,,,,,299.9968872,,,,
,27572638.98,299.9990692,231.6185,0.000519513496705055,1.1904224623172E-6,1,1.99850670813958,40.0298881530762,1.98148143013994,8.85000178590417,0.00552567886416548,0.000946810450334358,0.25,-6.34992174573285E-7,0.000519498402992249,-2.90012559747498E-7,299.9988098,299.9993286,220.744,242.493,52.8951467819094,18.4292511800219,16.6718655,0,0,0,4449,300.00835,231.6185,,,,,,,,,,,,,,,,,21.059195,,,,,,299.9990692,,,,
,27572676.96,300.00016785,629.5325,0.00120498038364572,1.38448180902061E-6,1,1.99850670813958,40.0298881530762,1.98144211004746,8.85000178590417,0.0128138702410258,0.00220973383080299,0.25,-1.83931600428707E-7,0.00120494447748342,6.16176258261114E-7,299.9989624,300.0013733,619.814,639.251,52.7122457084094,18.4298080888253,16.5069685,0,0,0,4449,300.00325,629.5325,,,,,,,,,,,,,,,,,21.440407,,,,,,300.00016785,,,,
,27572721.08,299.99842835,1080.855,0.00198492457979659,1.38917026129913E-6,1,1.99850670813958,40.0298881530762,1.98147171645323,8.85000178590417,0.0211053856270522,0.00365621343387798,0.25,1.21474807248707E-6,0.00198486453955514,2.53265466124319E-6,299.9980164,299.9988403,1072.127,1089.583,52.2854765369094,18.4317119311074,16.6718655,0,0,0,4449,299.99875,1080.855,,,,,,,,,,,,,,,,,20.677984,,,,,,299.99842835,,,,
,27572757.5,300.0018311,1442.401,0.00256133281527627,1.97025527400952E-6,1,1.99850670813958,40.0298881530762,1.98147488511661,8.85000178590417,0.0272259623500251,0.00471753003685215,2.5,1.66005985713406E-6,0.0025612550085893,3.36055970307761E-6,300.0018311,300.0018311,1442.401,1442.401,53.0397480579671,18.4307766782469,16.6718655,0,0,0,4449,300.0053,1442.401,,,,,,,,,,,,,,,,,21.440407,,,,,,300.0018311,,,,
,27572796.88,300.00398255,1845.4545,0.00330443971055649,1.9884726664638E-6,1,1.99850670813958,40.0298881530762,1.98144770069799,8.85000178590417,0.0351352392232853,0.00608624098153943,0.25,1.9815032056139E-6,0.00330433921302888,4.1753103719372E-6,300.0035095,300.0044556,1835.977,1854.932,52.6450256557556,18.433563902601,16.6718655,0,0,0,4449,299.9993,1845.4545,,,,,,,,,,,,,,,,,20.296772,,,,,,300.00398255,,,,
,27572834.8,299.9999237,2219.0425,0.00395314576972743,2.12268264557089E-6,1,1.99850670813958,40.0298881530762,1.98137557233237,8.85000178590417,0.0420286636317793,0.00729605364661409,0.25,3.80525314520271E-6,0.0039530251180791,6.42956318485304E-6,299.9996643,300.0001831,2208.647,2229.438,52.9381363504671,18.4305001290372,16.6718655,0,0,0,4449,299.9998,2219.0425,,,,,,,,,,,,,,,,,21.440407,,,,,,299.9999237,,,,
,27572870.76,300.00256345,2572.022,0.00454804911556427,2.56469172784024E-6,1,1.99850670813958,40.0298881530762,1.98150060190207,8.85000178590417,0.0483445676202863,0.00837688315844347,2.5,2.95398936064089E-6,0.00454791088290555,5.97309131569989E-6,300.0025024,300.0026245,2561.485,2582.559,52.9436077501018,18.4285160097865,16.6718655,0,0,0,4449,300.00315,2572.022,,,,,,,,,,,,,,,,,21.440407,,,,,,300.00256345,,,,
,27572902.75,300.00071715,2877.842,0.00507726129693665,2.28966352750298E-6,1,1.99850670813958,40.0298881530762,1.98151390789149,8.85000178590417,0.0539695142512963,0.0093562641780911,2.5,3.72903644013957E-6,0.00507710700753404,7.09928555706732E-6,300,300.0014343,2868.619,2887.065,53.2132695892364,18.4288201693638,16.6718655,0,0,0,4449,300.0036,2877.842,,,,,,,,,,,,,,,,,21.440407,,,,,,300.00071715,,,,
,27572934.725,300.00079345,3181.978,0.00559840382434977,2.70063283562272E-6,1,1.99850670813958,40.0298881530762,1.98154782515363,8.8600018620491,0.0595108191791187,0.0103123581707377,2.5,3.69564793297479E-6,0.00559823397191256,7.41171801374278E-6,300.0007324,300.0008545,3171.712,3192.244,52.9819075475441,18.4330930907619,16.6718655,0,0,0,4449,300.0014,3181.978,,,,,,,,,,,,,,,,,21.440407,,,,,,300.00079345,,,,
,27572966.73,299.99993895,3465.496,0.00609196594073666,3.00735684602353E-6,1,1.99850670813958,40.0298881530762,1.98143837347114,8.8600018620491,0.0647545490361598,0.011217344201814,2.5,3.68577342242191E-6,0.00609178150967711,7.72940495177698E-6,299.9993286,300.0005493,3453.562,3477.43,52.1783934297748,18.4315772536825,16.6718655,0,0,0,4449,299.9953,3465.496,,,,,,,,,,,,,,,,,21.440407,,,,,,299.99993895,,,,
,27572998.675,300.0027313,3785.477,0.00662753644159888,3.70263912623513E-6,1,1.99850670813958,40.0298881530762,1.98150693050403,8.85000178590417,0.0704494149284697,0.012205737340801,2.5,4.18177745304863E-6,0.00662733511881991,8.58055057874689E-6,300.0026855,300.0027771,3775.464,3795.49,52.8505939563133,18.4298175222196,16.6718655,0,0,0,4449,300.0037,3785.477,,,,,,,,,,,,,,,,,21.440407,,,,,,300.0027313,,,,
,27573036.63,300.00413515,4131.8415,0.00723063388438374,3.05608780374822E-6,1,1.99850670813958,40.0298881530762,1.98152460771024,8.85000178590417,0.0768601445756724,0.0133208050607492,2.5,4.961995007622E-6,0.00723041366258729,9.76089949540886E-6,300.0037537,300.0045166,4121.743,4141.94,52.5809321171786,18.430828013737,16.58900455,0,0,0,4449,299.9984,4131.8415,,,,,,,,,,,,,,,,,21.440407,,,,,,300.00413515,,,,
,27573068.625,300.00061035,4422.6295,0.00771196845711405,4.30591174070001E-6,1,1.99850670813958,40.0298881530762,1.98147032428801,8.85000178590417,0.0819743360539831,0.0142080444740121,2.5,5.37352481403762E-6,0.00771173441067937,1.0491715061052E-5,300.0000305,300.0011902,4413.422,4431.837,52.6333012279671,18.4305662896033,16.6727047,0,0,0,4449,299.99605,4422.6295,,,,,,,,,,,,,,,,,21.059195,,,,,,300.00061035,,,,
,27573100.585,299.9983978,4700.9465,0.0081924069335809,4.27389271790451E-6,1,1.99850670813958,40.0298881530762,1.98141635534545,8.85000178590417,0.0870792396458303,0.0150907198456254,2.5,5.51485175615999E-6,0.00819215905450387,1.09514936216586E-5,299.998291,299.9985046,4690.382,4711.511,52.8505939563133,18.4336352807047,16.75556565,0,0,0,4449,300.00455,4700.9465,,,,,,,,,,,,,,,,,21.440407,,,,,,299.9983978,,,,
,27573132.585,300.00485225,4998.119,0.00747712010731496,0.00057279044925823,1,1.99850670813958,40.0298881530762,1.98151927032431,8.85000178590417,0.0811080439037871,0.00434289664314607,2.5,-0.000882079699521938,0.00747748104011837,-0.0008770912116129,300.0042419,300.0054626,4997.031,4999.207,53.1601188499287,18.4324363270217,16.75556565,0,0,0,4449,299.99845,4998.119,,,,,,,,,,,,,,,,,21.440407,,,,,,300.00485225,,,,
,27573164.555,300.0048218,5304.9215,0.00922432499972638,4.90124562709406E-6,1,1.99850670813958,40.0298881530762,1.98145364146146,8.85000178590417,0.098046988919548,0.0170065115583761,2.5,7.58842443903307E-6,0.00922404309825669,1.37096013572126E-5,300.0047913,300.0048523,5294.667,5315.176,52.8545020989094,18.4312993153773,16.8392658,0,0,0,4449,299.99065,5304.9215,,,,,,,,,,,,,,,,,21.440407,,,,,,300.0048218,,,,
,27573196.51,300.00042725,5585.893,0.00968845002640644,4.86935667372054E-6,1,1.99850670813958,40.0298881530762,1.98143031884665,8.85000178590417,0.102981732858666,0.0178467896080925,2.5,6.53979620902211E-6,0.00968815629817257,1.29685722042117E-5,300.0003967,300.0004578,5575.837,5595.949,52.7622699336402,18.4276617126614,16.58900455,0,0,0,4449,299.99685,5585.893,,,,,,,,,,,,,,,,,21.440407,,,,,,300.00042725,,,,
,27573228.5,299.99868775,5878.6835,0.0101973856759345,4.93067567483533E-6,1,1.99850670813958,40.0298881530762,1.98149024809205,8.8600018620491,0.108394715627356,0.0187837675130485,2.5,6.78371356557636E-6,0.0101970771891774,1.35498143460689E-5,299.9981995,299.999176,5868.697,5888.67,52.1846464579286,18.4302780191788,16.75556565,0,0,0,4449,299.9997,5878.6835,,,,,,,,,,,,,,,,,20.677984,,,,,,299.99868775,,,,
,27573260.465,300.00094605,6136.3225,0.010638598180321,5.29232008928031E-6,1,1.99850670813958,40.0298881530762,1.98138533283747,8.85000178590417,0.113078452111314,0.0195980634321474,2.5,7.31940058799498E-6,0.0106382754317205,1.43780409352577E-5,300.0005188,300.0013733,6126.705,6145.94,53.1640269925249,18.4318594976692,16.75556565,0,0,0,4449,299.99675,6136.3225,,,,,,,,,,,,,,,,,20.677984,,,,,,300.00094605,,,,
,27573292.45,299.99890135,6451.6135,0.0111827680193417,4.49651290556508E-6,1,1.99850670813958,40.0298881530762,1.98148905856121,8.85000178590417,0.118867008005031,0.0206099453331902,2.5,8.48374727733991E-6,0.0111824290078275,1.59030323956212E-5,299.9986877,299.999115,6441.798,6461.429,52.6825438246787,18.4310797382467,16.8392658,0,0,0,4449,299.9973,6451.6135,,,,,,,,,,,,,,,,,21.440407,,,,,,299.99890135,,,,
,27573324.425,299.99925235,6740.957,0.0116581935265558,6.99966035160335E-6,1,1.99850670813958,40.0298881530762,1.98142551681106,8.85000178590417,0.1239196312389,0.0214686148257931,2.5,7.25678751044695E-6,0.0116578410660824,1.49910818031061E-5,299.9990845,299.9994202,6732.033,6749.881,52.9772177764287,18.432685834511,16.75556565,0,0,0,4449,300.00075,6740.957,,,,,,,,,,,,,,,,,21.440407,,,,,,299.99925235,,,,
,27573356.41,299.99816895,7013.862,0.0121365720768431,5.49043672433366E-6,1,1.99850670813958,40.0298881530762,1.98150458665245,8.85000178590417,0.12900946692184,0.0223503517297382,2.5,7.54946144381683E-6,0.0121362055991467,1.560090781528E-5,299.9972229,299.999115,7003.989,7023.735,52.9936319753325,18.4328521540819,16.75556565,0,0,0,4449,299.9964,7013.862,,,,,,,,,,,,,,,,,21.440407,,,,,,299.99816895,,,,
,27573388.38,299.9974365,7300.777,0.0126147347199672,6.23756883949305E-6,1,1.99850670813958,40.0298881530762,1.98150986860757,8.85000178590417,0.134089629169746,0.0232481487828374,2.5,9.46216118566873E-6,0.0126143530718652,1.78303028547874E-5,299.997406,299.997467,7291.004,7310.55,52.8552837274287,18.4306176082431,16.8392658,0,0,0,4449,299.9989,7300.777,,,,,,,,,,,,,,,,,21.440407,,,,,,299.9974365,,,,
,27573420.38,299.99864195,7588.1735,0.0131123447575435,5.84714872878157E-6,1,1.99850670813958,40.0298881530762,1.98144994561082,8.85000178590417,0.139377780844584,0.0241482505448941,2.5,8.30641032116764E-6,0.0131119486020924,1.70042395529111E-5,299.9981079,299.999176,7579.065,7597.282,52.8248002151787,18.4320688895543,16.8392658,0,0,0,4449,300.0002,7588.1735,,,,,,,,,,,,,,,,,21.440407,,,,,,299.99864195,,,,
,27573452.32,299.99887085,7854.9905,0.0135366813979629,6.91187797940472E-6,1,1.99850670813958,40.0298881530762,1.98153308501348,8.85000178590417,0.14389351926365,0.0249339049264772,2.5,8.87403816901492E-6,0.0135362721501366,1.78530514806946E-5,299.9988403,299.9989014,7845.825,7864.156,52.8873304967171,18.4336130128314,16.8392658,0,0,0,4449,299.99705,7854.9905,,,,,,,,,,,,,,,,,21.821617,,,,,,299.99887085,,,,
,27573484.33,300.00047305,8141.9335,0.0140189645311649,7.94972838072656E-6,1,1.99850670813958,40.0298881530762,1.98144329022094,8.85000178590417,0.149013150174635,0.0258240044232065,2.5,9.46194826862934E-6,0.0140185398558564,1.87602463988083E-5,300.0003052,300.0006409,8132.048,8151.819,52.924067037121,18.4334429026684,16.8392658,0,0,0,4449,300.0016,8141.9335,,,,,,,,,,,,,,,,,21.440407,,,,,,300.00047305,,,,
,27573516.29,300.00308225,8446.97,0.0145734610539989,7.41026379845678E-6,1,1.99850670813958,40.0298881530762,1.98144960542716,8.85000178590417,0.154909883709786,0.026832138155815,2.5,8.57884262825475E-6,0.0145730192331863,1.82445145372098E-5,300.0029907,300.0031738,8437.535,8456.405,52.6012544586786,18.4326498901005,16.6727047,0,0,0,4449,300.00025,8446.97,,,,,,,,,,,,,,,,,21.059195,,,,,,300.00308225,,,,
,27573548.3,299.99806215,8742.3295,0.0150808367122991,7.89738023583109E-6,1,1.99850670813958,40.0298881530762,1.98140142121375,8.85000178590417,0.160298871646423,0.0277684917666487,2.5,9.1446742030712E-6,0.0150803818050956,1.9146416474706E-5,299.9975281,299.9985962,8733.022,8751.637,52.7333496784287,18.4282944005821,16.8392658,0,0,0,4449,299.9987,8742.3295,,,,,,,,,,,,,,,,,21.440407,,,,,,299.99806215,,,,
,27573580.28,299.99694825,9010.684,0.0155191705239845,0.00053337237263016,1,1.99850670813958,40.0298881530762,1.98145565528008,8.85000178590417,0.165592490646683,0.0249258685227213,2.5,-0.000333979528890357,0.0155189307420908,-0.000323677549166557,299.9967957,299.9971008,9005.881,9015.487,52.9514240352941,18.4330984547148,16.75556565,0,0,0,4449,300.00385,9010.684,,,,,,,,,,,,,,,,,20.677984,,,,,,299.99694825,,,,
,27573612.25,300.00338745,9302.983,0.0160234604919182,7.73644964199056E-6,1,1.99850670813958,40.0298881530762,1.98146853735537,8.85000178590417,0.17032143603745,0.029518934151131,2.5,1.10177627726929E-5,0.016022973636366,2.16436138225865E-5,300.0029297,300.0038452,9293.519,9312.447,52.7044294232171,18.4293427069666,16.8392658,0,0,0,4449,299.99855,9302.983,,,,,,,,,,,,,,,,,21.440407,,,,,,300.00338745,,,,
,27573644.26,300.0047455,9596.197,0.0165263600412674,7.1961885153093E-6,1,1.99850670813958,40.0298881530762,1.98148151592091,8.8600018620491,0.175664441938066,0.0304668113861347,2.5,1.33608355701751E-5,0.0165258558889944,2.43197989286938E-5,300.0044556,300.0050354,9586.889,9605.505,53.1890391051402,18.4328455894259,16.92378995,0,0,0,4449,299.99325,9596.197,,,,,,,,,,,,,,,,,20.677984,,,,,,300.0047455,,,,
,27573676.24,299.9999695,9874.8695,0.0170087000520094,0.000329377549550941,1,1.99850670813958,40.0298881530762,1.98150669875239,8.85000178590417,0.180710918160828,0.0318356429075459,2.5,5.88307954920773E-5,0.0170081539671102,7.01075707088248E-5,299.9994507,300.0004883,9871.732,9878.007,52.8248002151787,18.4321414588238,16.8400898,0,0,0,4449,299.99675,9874.8695,,,,,,,,,,,,,,,,,21.440407,,,,,,299.9999695,,,,
,27573714.22,300.0000458,9999.8985,0.0172450569269437,7.31806222289251E-6,1,1.99850670813958,40.0298881530762,1.98146913468753,8.8600018620491,0.18330361507837,0.0317859771246232,2.5,1.34176481516486E-5,0.0172445339193708,2.48519295312115E-5,299.9995728,300.0005188,9999.839,9999.958,53.1773146773518,18.4314661211798,16.75556565,0,0,0,4417,300.00405,9999.8985,,,,,,,,,,,,,,,,,21.440407,,,,,,300.0000458,,,,