File: Projekt_andmed1/andmed töötlemiseks/2_CuFe2O4_derivative_Hys_at300K_2TSweep_19062023(1).DAT
[Header]
; VSM Data File (default extension .dat)
; Copyright (c) 2003-2013, Quantum Design, Inc. All rights reserved.
TITLE,2_CuFe2O4_derivative_Hys_at300K_2TSweep_19062023
FILEOPENTIME,26133551.13,06/19/2023,1:57 pm
BYAPP,VSM,2.0,2.0
INFO,PPMS VSM Option Release 1.4.10 Build 1,APPNAME
INFO,Quantum Design Linear Motor Servo Controller,MOTOR_MODULE_NAME
INFO,3101-100 C1,MOTOR_HW_VERSION
INFO,074,MOTOR_SERIAL_NUMBER
INFO,SRV No X-over 01.01.11,MOTOR_SOFTWARE_VERSION
INFO,Quantum Design VSM Detection Module,VSM_MODULE_NAME
INFO,3101-150 E1,VSM_HW_VERSION
INFO,VSM061,VSM_SERIAL_NUMBER
INFO,VSM No X-over 01.02.05 May 20 2008 13:51:47,VSM_SOFTWARE_VERSION
INFO,113,PREAMP_SERIAL_NUMBER
INFO,Quantum Design VSM Oven,OVEN_MODULE_NAME
INFO,3101-200 B0,OVEN_HW_VERSION
INFO,OVN054,OVEN_SERIAL_NUMBER
INFO,01.01.00,OVEN_SOFTWARE_VERSION
INFO,818,COIL_SERIAL_NUMBER
INFO,0,MOMENT_UNITS
INFO,2_CuFe2O4_derivative_Hys_at300K_2TSweep_19062023,SAMPLE_MATERIAL
INFO,granular powder in plastic holder,SAMPLE_COMMENT
INFO,20,SAMPLE_MASS
INFO,,SAMPLE_VOLUME
INFO,,SAMPLE_MOLECULAR_WEIGHT
INFO,,SAMPLE_SIZE
INFO,,SAMPLE_SHAPE
DATATYPE,COMMENT,1
DATATYPE,TIME,2
STARTUPAXIS,X,2
STARTUPAXIS,Y1,5
[Data]
Comment,Time Stamp (sec),Temperature (K),Magnetic Field (Oe),Moment (emu),M. Std. Err. (emu),Transport Action,Averaging Time (sec),Frequency (Hz),Peak Amplitude (mm),Center Position (mm),Coil Signal' (mV),Coil Signal" (mV),Range (mV),M. Quad. Signal (emu),M. Raw' (emu),M. Raw" (emu),Min. Temperature (K),Max. Temperature (K),Min. Field (Oe),Max. Field (Oe),Mass (grams),Motor Lag (deg),Pressure (Torr),VSM Status (code),Motor Status (code),Measure Status (code),Measure Count,PPMS Status (code),System Temp. (K),System Field (Oe),Sample Position (deg),Bridge 1 Resistance (ohms),Bridge 1 Excitation (에),Bridge 2 Resistance (ohms),Bridge 2 Excitation (에),Bridge 3 Resistance (ohms),Bridge 3 Excitation (에),Bridge 4 Resistance (ohms),Bridge 4 Excitation (에),Signal 1 Vin (V),Signal 2 Vin (V),Digital Inputs (code),Drive 1 Iout (mA),Drive 1 Ipower (W),Drive 2 Iout (mA),Drive 2 Ipower (W),Pressure (),Map 20 (),Map 21 (),Map 22 (),Map 23 (),Map 24 (),Map 25 (),Map 26 (),Map 27 (),Map 28 (),Map 29 ()
,26133741.985,299.9670105,20003.2275,0.122521475296138,3.69427018446599E-6,1,4.99626677034896,40.0298881530762,1.99064928027729,9.68000013381243,1.35996723573512,0.236253180794817,25,-2.87789817066935E-5,0.122517604360654,5.05433338913298E-5,299.9670105,299.9670105,20003.223,20003.232,51.9345253317747,18.3637182876582,38.213703,0,0,0,200,4417,300.1204,20003.2275,,,,,,,,,,,,,0,,,,9.433816,,,,,,299.9670105,,,,
,26133872.4,300.01425175,8762.075,0.1168100363814,5.9820261163519E-6,1,4.99626677034896,40.0298881530762,1.990902780115,9.68000013381243,1.29671574456692,0.225335691455204,25,-2.13608892534342E-5,0.11680616571212,5.43554707803877E-5,300.0134583,300.0150452,8762.028,8762.122,51.8032117405439,18.3681195071222,38.213703,0,0,0,200,4417,300.0643,8762.075,,,,,,,,,,,,,0,,,,9.6246767,,,,,,300.01425175,,,,
,26133957.335,300.01887515,3838.7135,0.108487546507807,4.49481431144254E-6,1,4.99626677034896,40.0298881530762,1.991087725521,9.68000013381243,1.20444947230952,0.209212602254209,25,-2.77060731368602E-5,0.10848393814718,4.26494176606049E-5,300.018219,300.0195313,3838.659,3838.768,51.904823448044,18.3728803157312,38.594913,0,0,0,200,4417,300.0372,3838.7135,,,,,,,,,,,,,0,,,,9.7213078,,,,,,300.01887515,,,,
,26134017.215,300.01469425,1681.7605,0.0957640296341258,4.04633835880189E-6,1,4.99626677034896,40.0298881530762,1.99109851563513,9.68999974429607,1.0631745574785,0.184801398413314,25,-1.3254077412084E-5,0.0957608485098406,4.88575945437817E-5,300.0136414,300.0157471,1681.698,1681.823,51.5601252710631,18.371660278599,38.594913,0,0,0,200,4417,300.03975,1681.7605,,,,,,,,,,,,,0,,,,9.7696209,,,,,,300.01469425,,,,
,26134062.18,300.00502015,736.5805,0.0807542039523003,4.32034604445856E-6,1,4.99626677034896,40.0298881530762,1.99106034274098,9.68000013381243,0.896536624220756,0.155731276529106,25,-2.03657068301421E-5,0.0807515506387774,3.20148241626993E-5,300.0043335,300.0057068,736.559,736.602,51.9298355606593,18.3758404160491,38.594913,0,0,0,200,4417,300.0344,736.5805,,,,,,,,,,,,,0,,,,9.8184195,,,,,,300.00502015,,,,
,26134102.15,300.006546,322.746,0.0665538368952781,3.00491940579044E-6,1,4.99626677034896,40.0298881530762,1.99110518400236,9.68000013381243,0.738891821976364,0.128393157397074,25,-1.28239625618707E-5,0.0665516446109081,3.03445678815666E-5,300.0064697,300.0066223,322.735,322.757,52.4527450400248,18.3722598275355,38.213703,0,0,0,200,4417,300.0446,322.746,,,,,,,,,,,,,0,,,,9.35682535,,,,,,300.006546,,,,
,26134137.09,300.00885005,141.6205,0.0555012736277778,2.80583139928917E-6,1,4.99626677034896,40.0298881530762,1.99119377354752,9.68000013381243,0.616200860832735,0.107131888182829,25,-5.62084243458431E-6,0.0554994379626682,3.03814307053052E-5,300.0082397,300.0094604,141.581,141.66,52.4527450400248,18.3747656184353,37.451283,0,0,0,200,4417,300.02605,141.6205,,,,,,,,,,,,,0,,,,8.0854728,,,,,,300.00885005,,,,
,26134172.095,300.00262455,62.075,0.0491284559943472,3.47194518507468E-6,1,4.99626677034896,40.0298881530762,1.99108079316971,9.68999974429607,0.545420228020638,0.0948087551153202,25,-6.48807059453955E-6,0.0491268413635284,2.53801281008852E-5,300.0020142,300.0032349,61.949,62.201,51.9204560184286,18.3779926961852,38.594913,0,0,0,200,4417,300.02865,62.075,,,,,,,,,,,,,0,,,,9.916995,,,,,,300.00262455,,,,
,26134207.09,300.00047305,27.3915,0.046157242263593,3.26119925625894E-6,1,4.99626677034896,40.0298881530762,1.99113374725468,9.68999974429607,0.512446664922274,0.0890799511450868,25,-5.84274589096075E-6,0.0461557281394099,2.40979460985953E-5,300.0000916,300.0008545,27.318,27.465,52.1924627431209,18.3725579503073,37.451283,0,0,0,200,4417,300.03025,27.3915,,,,,,,,,,,,,0,,,,8.24349355,,,,,,300.00047305,,,,
,26134237.055,299.9955597,11.901,0.0446082365104025,3.13798034530226E-6,1,4.99626677034896,40.0298881530762,1.9910970434514,9.68000013381243,0.495231757553864,0.086139925569876,25,-1.0573812393093E-6,0.0446067768774438,2.78781282494272E-5,299.9955444,299.995575,11.875,11.927,52.3003274787748,18.3737093759945,38.213703,0,0,0,200,4417,300.0325,11.901,,,,,,,,,,,,,0,,,,9.536139,,,,,,299.9955597,,,,
,26134267.025,299.99331665,5.2915,0.0438449654068185,2.62888767287079E-6,1,4.99626677034896,40.0298881530762,1.99117164075384,9.68999974429607,0.48678754157488,0.0846004190602762,25,-7.22236986158841E-6,0.043843537811174,2.12174871636561E-5,299.9928894,299.9937439,5.257,5.326,52.1823015723709,18.3791809117879,38.594913,0,0,0,200,4417,300.03925,5.2915,,,,,,,,,,,,,0,,,,9.96677825,,,,,,299.99331665,,,,
,26134296.99,299.9925537,2.4705,0.0433743783509449,2.1172612718102E-6,1,4.99626677034896,40.0298881530762,1.9911354662684,9.68999974429607,0.481545623638821,0.0837418724628866,25,-2.55717777077492E-6,0.0433729641772547,2.55765539763369E-5,299.9918213,299.9932861,2.397,2.544,52.2002790283132,18.3781911433503,38.594913,0,0,0,200,4417,300.04585,2.4705,,,,,,,,,,,,,0,,,,8.60902715,,,,,,299.9925537,,,,
,26134326.995,299.9937897,0.152,0.0430772593118897,2.19367216169701E-6,1,4.99626677034896,40.0298881530762,1.99117415228566,9.68000013381243,0.478263642323578,0.0831251570008495,25,-6.5586398822433E-6,0.0430758558416654,2.13823055788275E-5,299.9935303,299.9940491,0.108,0.196,52.2159115986978,18.3807364922375,37.832493,0,0,0,200,4417,300.04765,0.152,,,,,,,,,,,,,0,,,,9.916995,,,,,,299.9937897,,,,
,26134361.945,299.9938965,-2.416,0.0427968435873427,2.61143023344922E-6,1,4.99626677034896,40.0298881530762,1.99129256812098,9.68000013381243,0.475180356994709,0.0825719730977003,25,-8.02723647427817E-6,0.0427954501224469,1.97316046264384E-5,299.9930725,299.9947205,-2.437,-2.395,52.5121488074863,18.3858772579803,38.213703,0,0,0,200,4417,300.0501,-2.416,,,,,,,,,,,,,0,,,,10.0165615,,,,,,299.9938965,,,,
,26134391.94,299.99557495,-5.1345,0.0424909457467749,2.44429321289774E-6,1,4.99626677034896,40.0298881530762,1.99121398412337,9.68000013381243,0.471755391634745,0.0820398944438742,25,-2.45508610556848E-6,0.0424895565187191,2.51050523033325E-5,299.9949646,299.9961853,-5.201,-5.068,52.9897238327364,18.3783550037273,37.832493,0,0,0,200,4417,300.0511,-5.1345,,,,,,,,,,,,,0,,,,10.01706075,,,,,,299.99557495,,,,
,26134421.915,299.99928285,-11.8785,0.0418731750177567,2.91984895807864E-6,1,4.99626677034896,40.0298881530762,1.99112783285156,9.68999974429607,0.464876472126786,0.0808482516432762,25,-2.01536129650234E-6,0.0418718009942997,2.51444069474428E-5,299.9984741,300.0000916,-11.945,-11.812,52.3902147584863,18.3781827900548,38.594913,0,0,0,200,4417,300.0479,-11.8785,,,,,,,,,,,,,0,,,,10.066844,,,,,,299.99928285,,,,
,26134451.885,300.00126645,-26.966,0.0403719340668161,3.37137704476212E-6,1,4.99626677034896,40.0298881530762,1.99111908347105,9.68000013381243,0.448212651076027,0.0779212336197338,25,-4.47491425093012E-6,0.0403706085062045,2.17113832170028E-5,300.000885,300.0016479,-27.034,-26.898,52.3847433588517,18.3805256332162,38.213703,0,0,0,200,4417,300.04605,-26.966,,,,,,,,,,,,,0,,,,10.0165615,,,,,,300.00126645,,,,
,26134486.86,300.00483705,-61.7445,0.036497526480715,3.6016608904481E-6,1,4.99626677034896,40.0298881530762,1.99115367945485,9.68000013381243,0.405202433290857,0.0704612704950562,25,-2.53205609889259E-6,0.0364963231923092,2.1141296634865E-5,300.0047913,300.0048828,-61.763,-61.726,52.5426323197363,18.3791375612537,38.213703,0,0,0,200,4417,300.0442,-61.7445,,,,,,,,,,,,,0,,,,9.9174905,,,,,,300.00483705,,,,
,26134522.64,300.0054016,-141.2235,0.0266007134898576,2.96499889769027E-6,1,4.99626677034896,40.0298881530762,1.99107492925491,9.68999974429607,0.295231201018918,0.0513109119929746,2.5,-4.23287842266981E-6,0.0265998375389678,1.30216386702041E-5,300.0053406,300.0054626,-141.26,-141.187,52.5387241771402,18.3748623691927,38.213703,0,0,0,200,4417,300.037,-141.2235,,,,,,,,,,,,,0,,,,10.1171265,,,,,,300.0054016,,,,
,26134562.86,300.00447085,-322.706,-0.000674121548359433,2.60895437782797E-6,1,4.99626677034896,40.0298881530762,1.99114347486767,9.68999974429607,-0.00748195615921548,-0.00131426969379223,0.25,-1.10912007370367E-6,-0.000674098580643428,-1.54633963107855E-6,300.0042725,300.0046692,-322.72,-322.692,52.4605613252171,18.3771657387743,37.832493,0,0,0,200,4417,300.04005,-322.706,,,,,,,,,,,,,0,,,,9.967773,,,,,,300.00447085,,,,
,26134593.225,300.0020599,-736.9205,-0.0563486470583802,7.57970217216388E-6,1,4.99626677034896,40.0298881530762,1.99127973026704,9.68000013381243,-0.625464920086302,-0.108640324258484,2.5,1.46422245872076E-5,-0.0563468009338532,-2.19080804895266E-5,300.0019531,300.0021667,-736.99,-736.851,52.7544536484479,18.3846897621153,38.213703,0,0,0,200,4417,300.0329,-736.9205,,,,,,,,,,,,,0,,,,9.01899525,,,,,,300.0020599,,,,
,26134631.76,300.00170895,-1681.9435,-0.0947942281807613,2.870142929372E-6,1,4.99626677034896,40.0298881530762,1.99125322065052,9.68000013381243,-1.05218124557525,-0.182834474323756,2.5,1.80222964372882E-5,-0.094791119719122,-4.34602354045066E-5,300.0016479,300.00177,-1681.955,-1681.932,52.494171351544,18.3763787252557,38.594913,0,0,0,200,4417,300.04105,-1681.9435,,,,,,,,,,,,,0,,,,9.96677825,,,,,,300.00170895,,,,
,26134681.725,300.0062103,-3838.8065,-0.108931266031985,4.13638120651674E-6,1,4.99626677034896,40.0298881530762,1.99117214308679,9.68999974429607,-1.20941108724555,-0.210159021420361,25,2.04250653887285E-5,-0.108927679724761,-5.02191952209042E-5,300.0057373,300.0066833,-3838.886,-3838.727,52.5848402597748,18.3755904489535,38.213703,0,0,0,200,4417,300.03275,-3838.8065,,,,,,,,,,,,,0,,,,10.01706075,,,,,,300.0062103,,,,
,26134766.65,300.0021362,-8762.278,-0.116820983666228,4.54544865433049E-6,1,4.99626677034896,40.0298881530762,1.99127463725392,9.68000013381243,-1.29707022719885,-0.225396234727454,25,2.14654851270629E-5,-0.116817154479678,-5.42682094846118E-5,300.0021362,300.0021362,-8762.311,-8762.245,52.5223099782363,18.3773197730985,38.213703,0,0,0,200,4417,300.0301,-8762.278,,,,,,,,,,,,,0,,,,10.0165615,,,,,,300.0021362,,,,
,26134916.595,300.00312805,-19999.945,-0.122433210684689,4.71446266228114E-6,1,4.99626677034896,40.0298881530762,1.99128982315857,9.68999974429607,-1.35942216943332,-0.236059205435729,25,3.7466384598298E-5,-0.122429211580963,-4.18269802638964E-5,300.0028076,300.0034485,-20001.109,-19998.781,51.8571441083709,18.3843998670966,38.594913,0,0,0,200,4417,300.03095,-19999.945,,,,,,,,,,,,,0,,,,9.2010045,,,,,,300.00312805,,,,
,26135056.46,299.9988861,-8762.315,-0.11676870939881,4.56953258152864E-6,1,4.99626677034896,40.0298881530762,1.99116234819633,9.68000013381243,-1.29642780113264,-0.225237407642135,25,2.55806002526834E-5,-0.116764896196464,-5.01181962178129E-5,299.9985962,299.999176,-8762.327,-8762.303,52.6755091680056,18.3780823507183,38.594913,0,0,0,200,4417,300.03395,-8762.315,,,,,,,,,,,,,0,,,,9.1294866,,,,,,299.9988861,,,,
,26135141.42,299.9976959,-3838.638,-0.108505194840307,5.50512658244318E-6,1,4.99626677034896,40.0298881530762,1.99119422241053,9.68000013381243,-1.20470124315927,-0.209296199885463,25,2.42266718747108E-5,-0.108501652999058,-4.61416633419449E-5,299.997467,299.9979248,-3838.656,-3838.62,52.8076043877556,18.3838013842716,38.213703,0,0,0,200,4417,300.03185,-3838.638,,,,,,,,,,,,,0,,,,10.16791395,,,,,,299.9976959,,,,
,26135201.415,299.9974365,-1681.787,-0.0957782788678856,4.47667745354949E-6,1,4.99626677034896,40.0298881530762,1.99136168990098,9.68000013381243,-1.06350247538271,-0.184654841028135,25,3.10520002940048E-5,-0.0957751587239488,-3.10704052262739E-5,299.9970703,299.9978027,-1681.793,-1681.781,52.7661780762363,18.3932729028728,38.594913,0,0,0,200,4417,300.03615,-1681.787,,,,,,,,,,,,,0,,,,10.16791395,,,,,,299.9974365,,,,
,26135241.35,299.99699405,-736.813,-0.0807566747109621,2.85047083046826E-6,1,4.99626677034896,40.0298881530762,1.99129485766852,9.68000013381243,-0.896644015713308,-0.155877472916977,25,9.21669595485925E-6,-0.0807540336104654,-4.31658755060738E-5,299.9967957,299.9971924,-736.854,-736.772,52.7630515621594,18.381355328235,38.594913,0,0,0,200,4417,300.03055,-736.813,,,,,,,,,,,,,0,,,,9.25179195,,,,,,299.99699405,,,,
,26135281.32,299.9938507,-322.813,-0.0664021530328303,2.75517766420644E-6,1,4.99626677034896,40.0298881530762,1.99115239663847,9.68999974429607,-0.737211961817385,-0.128177575209817,25,6.12427344912762E-6,-0.0663999867111073,-3.69477132525883E-5,299.9937439,299.9939575,-322.84,-322.786,52.6051626012748,18.3876083136432,38.213703,0,0,0,200,4417,300.03255,-322.813,,,,,,,,,,,,,0,,,,9.967773,,,,,,299.9938507,,,,
,26135316.305,299.99824525,-141.4955,-0.0555115129771778,3.44196334286564E-6,1,4.99626677034896,40.0298881530762,1.9911277433933,9.68000013381243,-0.616281594109627,-0.107226153499,25,-1.39474438273311E-6,-0.0555096904508362,-3.74012643329905E-5,299.9978638,299.9986267,-141.55,-141.441,52.4629062107748,18.3775004732102,38.594913,0,0,0,200,4417,300.04135,-141.4955,,,,,,,,,,,,,0,,,,10.16791395,,,,,,299.99824525,,,,
,26135346.26,299.99987795,-62.248,-0.0488198430703439,4.22631493202046E-6,1,4.99626677034896,40.0298881530762,1.99119255275913,9.68999974429607,-0.542019193866551,-0.0942416156820451,25,4.34397683030742E-6,-0.0488182413261276,-2.73234538836397E-5,299.9996033,300.0001526,-62.369,-62.127,52.3300293625055,18.3835480580977,37.832493,0,0,0,200,4417,300.03275,-62.248,,,,,,,,,,,,,0,,,,9.7725463,,,,,,299.99987795,,,,
,26135381.2,300.00334165,-27.13,-0.0453509577648908,2.55347157219582E-6,1,4.99626677034896,40.0298881530762,1.99127630626748,9.68999974429607,-0.503525881881567,-0.0875516569115587,25,3.77897761125008E-6,-0.0453494649703177,-2.56377665054743E-5,300.0028381,300.0038452,-27.14,-27.12,52.6215768001786,18.382664036973,37.832493,0,0,0,200,4417,300.03775,-27.13,,,,,,,,,,,,,0,,,,10.16791395,,,,,,300.00334165,,,,
,26135411.18,300.0038452,-12.0325,-0.043843791826163,2.98945650754967E-6,1,4.99626677034896,40.0298881530762,1.99113300246094,9.68999974429607,-0.48675405858149,-0.0846611529272322,25,1.4041953665558E-6,-0.0438423464488305,-2.70355118447636E-5,300.0032043,300.0044861,-12.09,-11.975,52.5559200045633,18.3850158247476,38.213703,0,0,0,200,4417,300.032,-12.0325,,,,,,,,,,,,,0,,,,9.9189744,,,,,,300.0038452,,,,
,26135441.165,300.00473025,-5.4855,-0.0430621705293358,2.55912489445614E-6,1,4.99626677034896,40.0298881530762,1.99125868311184,9.68000013381243,-0.478103415798088,-0.0831684310363933,25,3.40482547850643E-7,-0.0430607490592672,-2.75925122989315E-5,300.0037842,300.0056763,-5.532,-5.439,52.9608035775248,18.3820626565378,38.213703,0,0,0,200,4417,300.02905,-5.4855,,,,,,,,,,,,,0,,,,10.16791395,,,,,,300.00473025,,,,
,26135471.21,300.00260925,-2.3685,-0.0426292509590038,2.48465426434506E-6,1,4.99626677034896,40.0298881530762,1.99121960293119,9.68999974429607,-0.4732858910934,-0.0823428359029354,25,-7.50505698539205E-7,-0.0426278458367182,-2.84023745379609E-5,300.0018921,300.0033264,-2.378,-2.359,52.4629062107748,18.3794073324552,38.594913,0,0,0,200,4417,300.03155,-2.3685,,,,,,,,,,,,,0,,,,10.26999905,,,,,,300.00260925,,,,
,26135501.135,300.00126645,0.004,-0.0423169572415612,1.50633748546546E-6,1,4.99626677034896,40.0298881530762,1.99125941233008,9.68000013381243,-0.469834614057584,-0.0817015325807221,25,2.82585823946795E-6,-0.0423155664496846,-2.46235415614112E-5,300.0010986,300.0014343,-0.037,0.045,52.6801989391209,18.3846599627028,38.213703,0,0,0,200,4417,300.0317,0.004,,,,,,,,,,,,,0,,,,10.01856045,,,,,,300.00126645,,,,
,26135531.075,299.9995117,2.13,-0.0420471253424117,1.53083506958055E-6,1,4.99626677034896,40.0298881530762,1.9913109091527,9.68000013381243,-0.466849734865316,-0.0811860750763353,25,2.49325596434791E-6,-0.0420457454702963,-2.47808728849741E-5,299.9994812,299.9995422,2.114,2.146,52.9600219490056,18.385833781206,38.594913,0,0,0,200,4417,300.03385,2.13,,,,,,,,,,,,,0,,,,9.72518875,,,,,,299.9995117,,,,
,26135561.085,299.996109,5.1955,-0.0417379216820183,1.6724435664294E-6,1,4.99626677034896,40.0298881530762,1.99129708626344,9.68000013381243,-0.46341561710061,-0.0805769621950497,25,3.51629348797626E-6,-0.0417365569392484,-2.35572021899279E-5,299.995636,299.996582,5.168,5.223,52.8498123277941,18.3867033440082,38.594913,0,0,0,200,4417,300.0348,5.1955,,,,,,,,,,,,,0,,,,10.16791395,,,,,,299.996109,,,,
,26135591.04,299.9957428,11.852,-0.0411344537245845,1.52637641432572E-6,1,4.99626677034896,40.0298881530762,1.99118274144689,9.68000013381243,-0.456689985942098,-0.0794086404353363,25,3.36846340746943E-6,-0.0411331091396927,-2.3313262255992E-5,299.9956665,299.9958191,11.819,11.885,52.7638331906787,18.3844823000076,38.594913,0,0,0,200,4417,300.03785,11.852,,,,,,,,,,,,,0,,,,10.26999905,,,,,,299.9957428,,,,
,26135621.015,299.99946595,27.344,-0.0396149533401981,2.73237013614455E-6,1,4.99626677034896,40.0298881530762,1.99120704554708,9.68000013381243,-0.439824912762861,-0.0764768449809664,25,3.18427661501419E-6,-0.0396136539477582,-2.25115880631152E-5,299.9987183,300.0002136,27.304,27.384,52.1346222326978,18.3867277379552,38.594913,0,0,0,200,4417,300.0401,27.344,,,,,,,,,,,,,0,,,,9.967773,,,,,,299.99946595,,,,
,26135661.655,299.9977112,61.8675,-0.0355741320409108,2.02890772525199E-6,1,4.99626677034896,40.0298881530762,1.9911775320235,9.68999974429607,-0.394843724987903,-0.0686213482955192,2.5,5.84727277640621E-6,-0.035572968966025,-1.72281429085112E-5,299.9972229,299.9981995,61.756,61.979,52.4246064133325,18.3817144712514,38.594913,0,0,0,200,4417,300.03445,61.8675,,,,,,,,,,,,,0,,,,10.11763145,,,,,,299.9977112,,,,
,26135696.735,299.9975891,141.4085,-0.0257095666780101,4.10832796566188E-6,1,4.99626677034896,40.0298881530762,1.9912517004695,9.68999974429607,-0.285440117368808,-0.0496704823466728,25,-1.26387401073906E-6,-0.0257087226710293,-1.7940213369779E-5,299.997467,299.9977112,141.361,141.456,52.3917780155248,18.38537349577,38.213703,0,0,0,200,4417,300.03645,141.4085,,,,,,,,,,,,,0,,,,10.2192116,,,,,,299.9975891,,,,
,26135746.97,299.9975586,322.7565,0.00168589404901002,2.82562948169353E-6,1,4.99626677034896,40.0298881530762,1.99119550043209,9.68999974429607,0.0187167807875741,0.00325892896224603,0.25,2.53655767169741E-7,0.00168583859589566,1.34717930569636E-6,299.9972534,299.9978638,322.715,322.798,52.219819741294,18.3798221092357,38.213703,0,0,0,200,4417,300.0381,322.7565,,,,,,,,,,,,,0,,,,10.26999905,,,,,,299.9975586,,,,
,26135777.245,299.9975281,736.67,0.0570849512443804,5.15448762235303E-6,1,4.99626677034896,40.0298881530762,1.99118087361014,9.68999974429607,0.63359903689466,0.1101047710558,2.5,-1.0320939477523E-5,0.0570830859797131,2.67059884716218E-5,299.997345,299.9977112,736.65,736.69,52.1979341427555,18.3839290396806,38.594913,0,0,0,200,4417,300.0386,736.67,,,,,,,,,,,,,0,,,,10.11763145,,,,,,299.9975281,,,,
,26135815.905,299.9975891,1681.6215,0.095042007590286,4.92179113805417E-6,1,4.99626677034896,40.0298881530762,1.99115661786792,9.68000013381243,1.0552093338998,0.183294851606046,25,-2.38231561649192E-5,0.0950389065380137,3.78206916709844E-5,299.9961853,299.9989929,1681.512,1681.731,52.7950983314479,18.3844610277501,38.594913,0,0,0,200,4417,300.03935,1681.6215,,,,,,,,,,,,,0,,,,8.69708325,,,,,,299.9975891,,,,
,26135870.85,299.99650575,3838.9625,0.108958860665008,3.5919109258848E-6,1,4.99626677034896,40.0298881530762,1.99110093360281,9.68000013381243,1.2096882041449,0.210136804399354,25,-2.65809864228508E-5,0.108955309629521,4.40793634860021E-5,299.9961853,299.9968262,3838.925,3839,52.7677413332748,18.3865244847548,38.213703,0,0,0,200,4417,300.04,3838.9625,,,,,,,,,,,,,0,,,,10.26999905,,,,,,299.99650575,,,,
,26135955.81,299.9981079,8762.399,0.116863149288554,5.48652312080889E-6,1,4.99626677034896,40.0298881530762,1.9911468588181,9.68999974429607,1.29747597531604,0.225364436566338,25,-3.04148958221164E-5,0.116859339066016,4.53433847797588E-5,299.9977112,299.9985046,8762.294,8762.504,52.1557262027171,18.3813318192141,38.213703,0,0,0,200,4417,300.0403,8762.399,,,,,,,,,,,,,0,,,,10.26999905,,,,,,299.9981079,,,,
,26136100.695,300.0101318,19999.373,0.122461450388499,5.24123257105388E-6,1,4.99626677034896,40.0298881530762,1.99111525128177,9.68999974429607,1.35960307673285,0.236197379563982,25,-2.81443571563391E-5,0.12245741799113,5.11707654362332E-5,300.0090942,300.0111694,19998.713,20000.033,52.6043809727556,18.3807050574356,38.213703,0,0,0,200,4417,300.01885,19999.373,,,,,,,,,,,,,0,,,,9.50767855,,,,,,300.0101318,,,,