File: Projekt_andmed1/andmed töötlemiseks/3_CuFe2O4_derivative_Hys_at300K_5TSweep_19062023.DAT
[Header]
; VSM Data File (default extension .dat)
; Copyright (c) 2003-2013, Quantum Design, Inc. All rights reserved.
TITLE,3_CuFe2O4_derivative_Hys_at300K_5TSweep_19062023
FILEOPENTIME,26209502.50,06/20/2023,11:02 am
BYAPP,VSM,2.0,2.0
INFO,PPMS VSM Option Release 1.4.10 Build 1,APPNAME
INFO,Quantum Design Linear Motor Servo Controller,MOTOR_MODULE_NAME
INFO,3101-100 C1,MOTOR_HW_VERSION
INFO,074,MOTOR_SERIAL_NUMBER
INFO,SRV No X-over 01.01.11,MOTOR_SOFTWARE_VERSION
INFO,Quantum Design VSM Detection Module,VSM_MODULE_NAME
INFO,3101-150 E1,VSM_HW_VERSION
INFO,VSM061,VSM_SERIAL_NUMBER
INFO,VSM No X-over 01.02.05 May 20 2008 13:51:47,VSM_SOFTWARE_VERSION
INFO,113,PREAMP_SERIAL_NUMBER
INFO,Quantum Design VSM Oven,OVEN_MODULE_NAME
INFO,3101-200 B0,OVEN_HW_VERSION
INFO,OVN054,OVEN_SERIAL_NUMBER
INFO,01.01.00,OVEN_SOFTWARE_VERSION
INFO,818,COIL_SERIAL_NUMBER
INFO,0,MOMENT_UNITS
INFO,3_CuFe2O4_derivative_Hys_at300K_5TSweep_19062023,SAMPLE_MATERIAL
INFO,granular powder in plastic holder,SAMPLE_COMMENT
INFO,16.6,SAMPLE_MASS
INFO,,SAMPLE_VOLUME
INFO,,SAMPLE_MOLECULAR_WEIGHT
INFO,,SAMPLE_SIZE
INFO,,SAMPLE_SHAPE
DATATYPE,COMMENT,1
DATATYPE,TIME,2
STARTUPAXIS,X,2
STARTUPAXIS,Y1,5
[Data]
Comment,Time Stamp (sec),Temperature (K),Magnetic Field (Oe),Moment (emu),M. Std. Err. (emu),Transport Action,Averaging Time (sec),Frequency (Hz),Peak Amplitude (mm),Center Position (mm),Coil Signal' (mV),Coil Signal" (mV),Range (mV),M. Quad. Signal (emu),M. Raw' (emu),M. Raw" (emu),Min. Temperature (K),Max. Temperature (K),Min. Field (Oe),Max. Field (Oe),Mass (grams),Motor Lag (deg),Pressure (Torr),VSM Status (code),Motor Status (code),Measure Status (code),Measure Count,PPMS Status (code),System Temp. (K),System Field (Oe),Sample Position (deg),Bridge 1 Resistance (ohms),Bridge 1 Excitation (에),Bridge 2 Resistance (ohms),Bridge 2 Excitation (에),Bridge 3 Resistance (ohms),Bridge 3 Excitation (에),Bridge 4 Resistance (ohms),Bridge 4 Excitation (에),Signal 1 Vin (V),Signal 2 Vin (V),Digital Inputs (code),Drive 1 Iout (mA),Drive 1 Ipower (W),Drive 2 Iout (mA),Drive 2 Ipower (W),Pressure (),Map 20 (),Map 21 (),Map 22 (),Map 23 (),Map 24 (),Map 25 (),Map 26 (),Map 27 (),Map 28 (),Map 29 ()
,26210032.075,300.01589965,50003.8085,0.0750073280399334,3.81838650176941E-6,1,4.99626677034896,40.0298881530762,1.99152424067498,9.01999976485968,0.832918488421624,0.144693177098128,25,-1.75990262810176E-5,0.0750048600752949,3.08356215130615E-5,300.0155945,300.0162048,50003.078,50004.539,52.5340344060248,18.3635869005351,38.594913,0,0,0,200,4417,299.9781,50003.8085,,,,,,,,,,,,,0,,,,10.424922,,,,,,300.01589965,,,,
,26210356.86,299.98609925,20293.13,0.0674021868599519,3.32048575595898E-6,1,4.99626677034896,40.0298881530762,1.99176895937483,9.01999976485968,0.748553794005886,0.130050376533692,25,-1.48201978170938E-5,0.0674000158810829,2.88357774839611E-5,299.9856873,299.9865112,20292.631,20293.629,52.260464424294,18.3784857202988,38.976128,0,0,0,200,4417,300.0041,20293.13,,,,,,,,,,,,,0,,,,10.424922,,,,,,299.98609925,,,,
,26210506.76,299.9927063,8237.793,0.0583947810998871,3.44872857115863E-6,1,4.99626677034896,40.0298881530762,1.99172304096513,9.0300003066659,0.648504913410143,0.11266899657565,25,-1.28193274270016E-5,0.058392884746207,2.50402471331361E-5,299.9920654,299.9933472,8237.781,8237.805,51.9611007014286,18.3764131454361,38.594913,0,0,0,200,4417,300.02175,8237.793,,,,,,,,,,,,,0,,,,8.96000505,,,,,,299.9927063,,,,
,26210591.675,299.9921112,3343.428,0.0487271022636533,2.23923523027192E-6,1,4.99626677034896,40.0298881530762,1.99169439142875,9.01999976485968,0.541124761231161,0.0940605258806171,25,-6.56522269316856E-6,0.0487255170440434,2.50363405362646E-5,299.9917297,299.9924927,3343.402,3343.454,52.9201588945248,18.3769344669737,38.976128,0,0,0,200,4417,300.03265,3343.428,,,,,,,,,,,,,0,,,,10.4772544,,,,,,299.9921112,,,,
,26210641.68,299.99220275,1357.013,0.0392519082191627,2.11565690234936E-6,1,4.99626677034896,40.0298881530762,1.99167885726535,9.0300003066659,0.435900793324389,0.0757503545969289,25,-7.0142814689812E-6,0.039250631965128,1.84452133755246E-5,299.9920654,299.9923401,1356.94,1357.086,52.0752184652363,18.383855039457,38.213703,0,0,0,200,4417,300.03445,1357.013,,,,,,,,,,,,,0,,,,10.424922,,,,,,299.99220275,,,,
,26210686.62,299.993927,550.7535,0.0297067773266674,1.90884377430762E-6,1,4.99626677034896,40.0298881530762,1.99175077470954,9.01999976485968,0.329901534352795,0.0573888833460616,25,-1.55350446936258E-7,0.0297058064993527,1.91131856976986E-5,299.9936523,299.9942017,550.737,550.77,52.2995458502555,18.3789124666921,38.976128,0,0,0,200,4417,300.0403,550.7535,,,,,,,,,,,,,0,,,,10.26999905,,,,,,299.993927,,,,
,26210731.635,300.0003052,223.607,0.0216365769373807,1.32091219425875E-6,1,4.99626677034896,40.0298881530762,1.99170846830137,9.01999976485968,0.2402127514282,0.041729239652726,2.5,-5.14948394329905E-6,0.021635868878823,8.88528079989834E-6,300.0001221,300.0004883,223.592,223.622,53.0592887709479,18.3786537209345,38.213703,0,0,0,200,4417,300.03315,223.607,,,,,,,,,,,,,0,,,,10.4772544,,,,,,300.0003052,,,,
,26210766.56,299.99882505,90.8955,0.0168972727295792,2.20085239666259E-6,1,4.99626677034896,40.0298881530762,1.99182514080811,9.01999976485968,0.187606176944397,0.0325941262997537,2.5,-3.70795753389338E-6,0.0168967203151694,7.25263448880238E-6,299.9982605,299.9993896,90.766,91.025,52.6051626012748,18.3838821060661,38.594913,0,0,0,200,4417,300.03365,90.8955,,,,,,,,,,,,,0,,,,10.3212967,,,,,,299.99882505,,,,
,26210801.595,300.0007782,36.931,0.0146609110082268,1.87801638120519E-6,1,4.99626677034896,40.0298881530762,1.99179261804783,9.01999976485968,0.162774396183958,0.0282767265864591,2.5,-3.49718459405697E-6,0.0146604310161461,6.01282985464376E-6,300.0004578,300.0010986,36.864,36.998,52.8162023014671,18.3829589915569,38.976128,0,0,0,200,4417,300.03265,36.931,,,,,,,,,,,,,0,,,,10.12167075,,,,,,300.0007782,,,,
,26210831.54,299.994812,14.876,0.0136676507141576,1.60419418090145E-6,1,4.99626677034896,40.0298881530762,1.99185161053083,9.01999976485968,0.151750719681493,0.0263630932951953,2.5,-3.14042425344989E-6,0.0136672056364176,5.7252311054752E-6,299.9936523,299.9959717,14.856,14.896,52.7911901888517,18.3813128370329,38.594913,0,0,0,200,4417,300.0346,14.876,,,,,,,,,,,,,0,,,,10.4772544,,,,,,299.994812,,,,
,26210861.525,299.9934082,6.348,0.0131445880470437,1.05652975299776E-6,1,4.99626677034896,40.0298881530762,1.99178976681429,9.01999976485968,0.1459403194975,0.0253450405164774,2.5,-3.77493914025958E-6,0.0131441610623329,4.7513317414336E-6,299.9927368,299.9940796,6.27,6.426,52.7216252506402,18.3837234189624,38.594913,0,0,0,200,4417,300.0382,6.348,,,,,,,,,,,,,0,,,,9.7329512,,,,,,299.9934082,,,,
,26210891.54,300.0003204,2.5335,0.0128484249926664,7.32675408093817E-7,1,4.99626677034896,40.0298881530762,1.9917610466533,9.0300003066659,0.14265015262784,0.024773392527595,2.5,-3.71201667778266E-6,0.0128480049645078,4.62206534117653E-6,299.9998779,300.0007629,2.498,2.569,53.0342766583325,18.3866739167272,38.976128,0,0,0,200,4417,300.0407,2.5335,,,,,,,,,,,,,0,,,,9.50767855,,,,,,300.0003204,,,,
,26210921.46,300.0013275,0.196,0.0126470982211061,6.3973468808387E-7,1,4.99626677034896,40.0298881530762,1.9916900900446,9.01999976485968,0.140408940029988,0.0243911125055055,2.5,-3.04719269706259E-6,0.0126466839722333,5.15651118761717E-6,300.0012817,300.0013733,0.17,0.222,52.2721888520825,18.3781283256811,38.976128,0,0,0,200,4417,300.03355,0.196,,,,,,,,,,,,,0,,,,9.4821196,,,,,,300.0013275,,,,
,26210956.465,299.99752805,-2.4685,0.0124584449654648,5.27126451330105E-7,1,4.99626677034896,40.0298881530762,1.99183322157856,9.0300003066659,0.138325854185914,0.0240185513665781,2.5,-3.936949363147E-6,0.0124580389471453,4.14428713744114E-6,299.9971008,299.9979553,-2.489,-2.448,52.7474189917748,18.3859187715064,38.976128,0,0,0,200,4417,300.0375,-2.4685,,,,,,,,,,,,,0,,,,10.3218117,,,,,,299.99752805,,,,
,26210986.475,299.99746705,-5.879,0.0122750869139686,4.91889540009202E-7,1,4.99626677034896,40.0298881530762,1.99170409443268,9.01999976485968,0.136279987703574,0.0236726252159655,2.5,-3.06462826429171E-6,0.0122746863757439,4.89754588167035E-6,299.9967346,299.9981995,-5.88,-5.878,52.6833254531979,18.3890181937281,38.594913,0,0,0,200,4417,300.04065,-5.879,,,,,,,,,,,,,0,,,,8.68409825,,,,,,299.99746705,,,,
,26211016.45,300.0012207,-14.738,0.011952907029049,7.26532354456073E-7,1,4.99626677034896,40.0298881530762,1.99181769988288,9.0300003066659,0.132709630590392,0.0230566284760886,2.5,-2.61752868063776E-6,0.0119525153978271,5.1357581722045E-6,300.0010376,300.0014038,-14.745,-14.731,52.2760969946786,18.3819549639366,38.594913,0,0,0,200,4417,300.03715,-14.738,,,,,,,,,,,,,0,,,,9.18078425,,,,,,300.0012207,,,,
,26211046.345,299.99917605,-36.8855,0.0112303735722328,9.60172029572094E-7,1,4.99626677034896,40.0298881530762,1.9917768576893,9.01999976485968,0.124686300054092,0.0216556199953571,2.5,-3.07622717640165E-6,0.0112300067058653,4.20844022586314E-6,299.9987183,299.9996338,-36.934,-36.837,52.9983217464479,18.3773749693503,38.976128,0,0,0,200,4417,300.03585,-36.8855,,,,,,,,,,,,,0,,,,10.32335665,,,,,,299.99917605,,,,
,26211081.32,299.9938812,-90.549,0.00921595650925014,1.85383086698406E-6,1,4.99626677034896,40.0298881530762,1.99172716128238,9.0300003066659,0.102318381466082,0.0177720917719621,2.5,-2.40617566407563E-6,0.00921565686708079,3.57163249110325E-6,299.9935913,299.9941711,-90.588,-90.51,52.6841070817171,18.3846327332208,38.976128,0,0,0,200,4417,300.04345,-90.549,,,,,,,,,,,,,0,,,,10.424922,,,,,,299.9938812,,,,
,26211116.35,299.9951935,-223.403,0.00390297063771814,2.9784282292202E-6,1,4.99626677034896,40.0298881530762,1.99176279998413,9.01999976485968,0.0433343078478173,0.00751751579928284,2.5,-1.84034832777658E-6,0.00390284412321081,6.91223682495422E-7,299.9949646,299.9954224,-223.421,-223.385,52.700521280621,18.3806061182567,38.594913,0,0,0,200,4417,300.04875,-223.403,,,,,,,,,,,,,0,,,,9.396492,,,,,,299.9951935,,,,
,26211151.3,299.99894715,-550.7035,-0.0083094990473847,3.29569133730873E-6,1,4.99626677034896,40.0298881530762,1.99174684501349,9.01999976485968,-0.0922705896766882,-0.0161008536354091,0.25,-4.29893182949371E-6,-0.00830922341532795,-9.68849592451155E-6,299.9975891,300.0003052,-550.727,-550.68,52.5113671789671,18.3863254727088,38.594913,0,0,0,200,4417,300.04195,-550.7035,,,,,,,,,,,,,0,,,,9.2325969,,,,,,299.99894715,,,,
,26211196.25,300.0000458,-1357.0975,-0.0273376289976894,1.10812259661205E-6,1,4.99626677034896,40.0298881530762,1.99180670641039,9.0300003066659,-0.303512274328859,-0.0527778089927717,2.5,1.9310515146058E-6,-0.0273367317757484,-1.58000545070549E-5,299.9996338,300.0004578,-1357.107,-1357.088,52.6137605149863,18.3821016063655,38.976128,0,0,0,200,4417,300.0412,-1357.0975,,,,,,,,,,,,,0,,,,10.3218117,,,,,,300.0000458,,,,
,26211256.225,300.00228885,-3343.6495,-0.0443842312132285,1.18308824727504E-6,1,4.99626677034896,40.0298881530762,1.99172475573241,9.01999976485968,-0.49288497885644,-0.0857838905366074,25,-3.51313278397785E-6,-0.0443827675424968,-3.22970018433785E-5,300.0016785,300.0028992,-3343.675,-3343.624,52.9537689208517,18.3780409331616,37.832493,0,0,0,200,4417,300.04005,-3343.6495,,,,,,,,,,,,,0,,,,10.26999905,,,,,,300.00228885,,,,
,26211346.135,300.00253295,-8237.808,-0.0585088068198637,2.82056419114407E-6,1,4.99626677034896,40.0298881530762,1.99180466300285,9.01999976485968,-0.649789466826549,-0.112934274569446,25,9.1617883144096E-6,-0.0585068872391741,-2.87690631885689E-5,300.0022888,300.0027771,-8237.913,-8237.703,52.5418506912171,18.3866543704065,38.976128,0,0,0,200,4417,300.0386,-8237.808,,,,,,,,,,,,,0,,,,10.424922,,,,,,300.00253295,,,,
,26211501,300.0089264,-20296.3455,-0.067437870876676,2.45261136817764E-6,1,4.99626677034896,40.0298881530762,1.99180225019084,9.01999976485968,-0.748957160304749,-0.130146664970461,25,1.25328285982098E-5,-0.0674356511417741,-3.11417440409904E-5,300.0085449,300.0093079,-20297.539,-20295.152,53.0272420016595,18.3860215686405,38.976128,0,0,0,200,4417,300.0297,-20296.3455,,,,,,,,,,,,,0,,,,10.424922,,,,,,300.0089264,,,,
,26211835.775,300.01304625,-50000,-0.0750113067025618,3.85231618441826E-6,1,4.99626677034896,40.0298881530762,1.99196619169144,9.01999976485968,-0.833140923209379,-0.144726469958915,25,1.80660314378324E-5,-0.0750088455176658,-3.03698647639163E-5,300.0118103,300.0142822,-50002.266,-49997.734,53.0303685157364,18.3994210817316,38.976128,0,0,0,200,4417,299.98525,-50000,,,,,,,,,,,,,0,,,,10.27102425,,,,,,300.01304625,,,,
,26212160.54,299.9898987,-20294.126,-0.0674107824849878,3.19694064277216E-6,1,4.99626677034896,40.0298881530762,1.99168368800266,9.0300003066659,-0.748594828600484,-0.130197284651074,25,2.60327499239031E-6,-0.0674085956620988,-4.10569344354403E-5,299.9897766,299.9900208,-20294.363,-20293.889,52.4472736403902,18.3818917530408,38.976128,0,0,0,200,4417,300.0095,-20294.126,,,,,,,,,,,,,0,,,,10.37310935,,,,,,299.9898987,,,,
,26212300.455,299.98983765,-8238.3715,-0.0584028590314201,2.37138432189494E-6,1,4.99626677034896,40.0298881530762,1.99167069136902,9.01999976485968,-0.648558073488306,-0.112798204889793,25,2.33271609645952E-6,-0.0584009608558162,-3.55300594764291E-5,299.9890137,299.9906616,-8238.984,-8237.759,52.5598281471594,18.3816148683398,37.832493,0,0,0,200,4417,300.0331,-8238.3715,,,,,,,,,,,,,0,,,,10.3741441,,,,,,299.98983765,,,,
,26212380.405,299.9876099,-3343.763,-0.0487159099220272,1.36978307724835E-6,1,4.99626677034896,40.0298881530762,1.99160612984376,9.0300003066659,-0.54097019857324,-0.0940772005737361,25,2.75591545087007E-6,-0.0487143294153813,-2.88364476249664E-5,299.9874573,299.9877625,-3343.785,-3343.741,52.1760485442171,18.3873132699822,38.976128,0,0,0,200,4417,300.04725,-3343.763,,,,,,,,,,,,,0,,,,10.37310935,,,,,,299.9876099,,,,
,26212445.32,299.9931488,-1357.231,-0.0392363041823237,1.90912377101737E-6,1,4.99626677034896,40.0298881530762,1.99164922975281,9.01999976485968,-0.435699981347445,-0.0758415898137136,25,-4.01490993174901E-6,-0.039235020290179,-2.94626520672321E-5,299.9928894,299.9934082,-1357.385,-1357.077,52.9936319753325,18.3813990250766,39.357338,0,0,0,200,4417,300.0471,-1357.231,,,,,,,,,,,,,0,,,,9.0104747,,,,,,299.9931488,,,,
,26212490.28,299.99931335,-550.9115,-0.0296352293370369,6.13514807797949E-7,1,4.99626677034896,40.0298881530762,1.99168018314857,9.01999976485968,-0.329002823936092,-0.0571997338099915,2.5,3.02398947361132E-6,-0.0296342578593511,-1.61984347765379E-5,299.9992065,299.9994202,-550.942,-550.881,52.189336229044,18.3848722963917,38.594913,0,0,0,200,4417,300.0376,-550.9115,,,,,,,,,,,,,0,,,,10.11763145,,,,,,299.99931335,,,,
,26212525.285,300.00048825,-223.4865,-0.0215848229329973,1.72073525596671E-6,1,4.99626677034896,40.0298881530762,1.99165298127523,9.0300003066659,-0.239621861153783,-0.0416852507568228,2.5,7.98485850658867E-9,-0.0215841131448206,-1.39928111452875E-5,299.9995422,300.0014343,-223.57,-223.403,52.616105400544,18.3831483829114,37.832493,0,0,0,200,4417,300.0373,-223.4865,,,,,,,,,,,,,0,,,,9.34467935,,,,,,300.00048825,,,,
,26212560.305,300.00086975,-91.037,-0.0170414117374774,2.25627959925063E-6,1,4.99626677034896,40.0298881530762,1.99171672468303,9.0300003066659,-0.189193497855716,-0.0328884362952751,2.5,2.11925557533787E-6,-0.0170408524924318,-8.93491082537159E-6,300.0006714,300.0010681,-91.077,-90.997,52.4699408674479,18.3889588408233,38.594913,0,0,0,200,4417,300.03065,-91.037,,,,,,,,,,,,,0,,,,10.12167075,,,,,,300.00086975,,,,
,26212595.235,299.99694825,-36.906,-0.0147702742654638,1.72378233731713E-6,1,4.99626677034896,40.0298881530762,1.9916451025091,9.01999976485968,-0.163972846741413,-0.0285094268616538,2.5,1.38002417296613E-6,-0.0147697910432497,-8.20057147553217E-6,299.996521,299.9973755,-37.002,-36.81,52.7067743087748,18.3875332667667,38.594913,0,0,0,200,4417,300.0403,-36.906,,,,,,,,,,,,,0,,,,10.4772544,,,,,,299.99694825,,,,
,26212625.195,299.9969788,-14.978,-0.0137799081811881,1.66116190149288E-6,1,4.99626677034896,40.0298881530762,1.99162971963682,9.01999976485968,-0.152975131797266,-0.0266090697290918,2.5,2.57563761940572E-7,-0.0137794566740675,-8.68065397726168E-6,299.9962769,299.9976807,-15.035,-14.921,52.8662265266979,18.3844404862723,38.594913,0,0,0,200,4417,300.0391,-14.978,,,,,,,,,,,,,0,,,,9.1274543,,,,,,299.9969788,,,,
,26212655.19,299.9949341,-6.2955,-0.0132561418618361,1.05454229098178E-6,1,4.99626677034896,40.0298881530762,1.99160700916975,9.01999976485968,-0.147159651319469,-0.0255938566821682,2.5,5.66503514937556E-7,-0.0132557085532635,-8.03188673256622E-6,299.9942017,299.9956665,-6.328,-6.263,52.8193288155441,18.3862477705413,38.594913,0,0,0,200,4417,300.04215,-6.2955,,,,,,,,,,,,,0,,,,10.0678482,,,,,,299.9949341,,,,
,26212685.17,299.99726865,-2.557,-0.0129586823640687,7.69912798790595E-7,1,4.99626677034896,40.0298881530762,1.9917314878003,9.01999976485968,-0.143865073345474,-0.0250269138263052,2.5,2.49451042470435E-8,-0.0129582575383019,-8.38030947122916E-6,299.9967651,299.9977722,-2.617,-2.497,52.7802473895825,18.3843004642745,37.451283,0,0,0,200,4417,300.04745,-2.557,,,,,,,,,,,,,0,,,,10.42544175,,,,,,299.99726865,,,,
,26212720.125,299.9989166,-0.008,-0.0127286281281784,7.59875978147278E-7,1,4.99626677034896,40.0298881530762,1.99170299021928,9.0300003066659,-0.141308187100099,-0.0245875469244003,2.5,-4.50181908730038E-7,-0.0127282098809828,-8.70640841681723E-6,299.9986572,299.999176,-0.009,-0.007,52.5301262634286,18.3874115601459,38.594913,0,0,0,200,4417,300.04115,-0.008,,,,,,,,,,,,,0,,,,10.3218117,,,,,,299.9989166,,,,
,26212750.095,300.00048825,2.295,-0.0125668828027061,5.25704265470326E-7,1,4.99626677034896,40.0298881530762,1.99171659575332,9.01999976485968,-0.139514281539792,-0.0242705548414202,2.5,-2.01916629740762E-8,-0.0125664695550519,-8.17144870341051E-6,299.9997253,300.0012512,2.222,2.368,52.4472736403902,18.3862298457795,37.832493,0,0,0,200,4417,300.0433,2.295,,,,,,,,,,,,,0,,,,10.27102425,,,,,,300.00048825,,,,
,26212785.07,300.0014496,6.0415,-0.0123640760785095,6.83540709599342E-7,1,4.99626677034896,40.0298881530762,1.99170046382022,9.01999976485968,-0.13726325142619,-0.0238697874419856,2.5,7.8175960058482E-7,-0.0123636696515352,-7.23806360567539E-6,300.0013428,300.0015564,6.04,6.043,52.6293930853709,18.3848879885776,38.594913,0,0,0,200,4417,300.04055,6.0415,,,,,,,,,,,,,0,,,,9.86770725,,,,,,300.0014496,,,,
,26212815.025,300.00157165,14.831,-0.0120487299339918,6.89155310739353E-7,1,4.99626677034896,40.0298881530762,1.99167148553434,9.01999976485968,-0.133760208579597,-0.0232622283945596,2.5,6.20880697479072E-7,-0.0120483337310827,-7.19445073144977E-6,300.0012512,300.0018921,14.768,14.894,52.7810290181017,18.3890445533244,38.976128,0,0,0,200,4417,300.0386,14.831,,,,,,,,,,,,,0,,,,10.4772544,,,,,,300.00157165,,,,
,26212850.01,300.0005646,36.876,-0.0112872140220899,9.37722032008155E-7,1,4.99626677034896,40.0298881530762,1.99172064225854,9.0300003066659,-0.12531021967158,-0.021786247716328,2.5,1.1450139422525E-6,-0.0112868435699327,-6.17638121502296E-6,299.9998169,300.0013123,36.765,36.987,52.9185956374864,18.3904391881837,38.594913,0,0,0,200,4417,300.03855,36.876,,,,,,,,,,,,,0,,,,10.4772544,,,,,,300.0005646,,,,
,26212884.985,300.00144955,90.6435,-0.00929771455845509,1.79038495157005E-6,1,4.99626677034896,40.0298881530762,1.99170577009398,9.01999976485968,-0.103219474250208,-0.0179613153338231,2.5,-4.32353329517533E-7,-0.00929740827137724,-6.46312755199798E-6,300.0012512,300.0016479,90.639,90.648,52.5934381734863,18.387749973466,38.976128,0,0,0,200,4417,300.0422,90.6435,,,,,,,,,,,,,0,,,,10.424922,,,,,,300.00144955,,,,
,26212919.96,300.00231935,223.512,-0.00387362468283352,2.83175986207885E-6,1,4.99626677034896,40.0298881530762,1.9917035810096,9.0300003066659,-0.0430004099095592,-0.0075000785895388,2.5,-1.71338962522579E-6,-0.00387349597363301,-4.22595659668225E-6,300.0022888,300.0023499,223.47,223.554,52.6645663687363,18.3891803066531,38.594913,0,0,0,200,4417,300.034,223.512,,,,,,,,,,,,,0,,,,9.70728015,,,,,,300.00231935,,,,
,26212954.94,299.99578855,550.981,0.00843121975576711,2.96640193495E-6,1,4.99626677034896,40.0298881530762,1.99170372124312,9.01999976485968,0.0936089232231745,0.0162356693317542,2.5,-4.26824680687369E-6,0.00843094649564931,1.20048756755031E-6,299.9956665,299.9959106,550.966,550.996,52.4206982707363,18.3895620350465,38.594913,0,0,0,200,4417,300.0448,550.981,,,,,,,,,,,,,0,,,,9.97672655,,,,,,299.99578855,,,,
,26212994.915,299.9959717,1356.9695,0.0272970057121425,1.54274081223935E-6,1,4.99626677034896,40.0298881530762,1.99167797846135,9.01999976485968,0.303051946633547,0.0526418962616474,2.5,-6.81224906212725E-6,0.0272961164031814,1.08921990805962E-5,299.9956055,299.9963379,1356.961,1356.978,52.8771693259671,18.3893998637963,37.832493,0,0,0,200,4417,300.04795,1356.9695,,,,,,,,,,,,,0,,,,10.42544175,,,,,,299.9959717,,,,
,26213035.855,299.9965973,3342.993,0.0442924742797875,3.64797290193736E-6,1,4.99626677034896,40.0298881530762,1.99167764953733,9.0300003066659,0.491884452071379,0.0854350376719271,25,-1.17641617647695E-5,0.0442910312612009,1.69597448291712E-5,299.9965515,299.9966431,3342.386,3343.6,52.8130757873902,18.3897083853435,38.594913,0,0,0,200,4417,300.04855,3342.993,,,,,,,,,,,,,0,,,,10.4772544,,,,,,299.9965973,,,,
,26213124.81,300.0059357,8237.7065,0.0585099740057039,3.75223461861474E-6,1,4.99626677034896,40.0298881530762,1.99164204561516,9.01999976485968,0.649751050136847,0.112930160422488,25,-8.93797260640697E-6,0.0585080482180788,2.89936330070607E-5,300.0058289,300.0060425,8237.665,8237.748,52.5746790890248,18.3844744177462,38.594913,0,0,0,200,4417,300.03855,8237.7065,,,,,,,,,,,,,0,,,,10.3218117,,,,,,300.0059357,,,,
,26213279.72,300.00672915,20295.7345,0.0674344958698723,3.5074023080576E-6,1,4.99626677034896,40.0298881530762,1.99158893632356,9.01999976485968,0.748837096009222,0.130159615324745,25,-9.57615125288008E-6,0.0674322788440703,3.40958416609549E-5,300.0063782,300.0070801,20294.496,20296.973,52.5371609201017,18.3824651031476,37.451283,0,0,0,200,4417,300.03145,20295.7345,,,,,,,,,,,,,0,,,,10.5295868,,,,,,300.00672915,,,,
,26213614.5,300.0128479,50001.5195,0.0750136213036947,4.29804072728123E-6,1,4.99626677034896,40.0298881530762,1.99148527506046,9.01999976485968,0.832984887158565,0.144633250546079,25,-2.38451851687044E-5,0.0750111643170962,2.45914750683409E-5,300.0127869,300.0129089,50001.359,50001.68,52.5582648901209,18.3846813923759,38.594913,0,0,0,200,4417,299.99005,50001.5195,,,,,,,,,,,,,0,,,,10.5295868,,,,,,300.0128479,,,,