File: Projekt_andmed1/andmed töötlemiseks/3_CuFe2O4_derivative_Hys_at300K_2TSweep_19062023.DAT
[Header]
; VSM Data File (default extension .dat)
; Copyright (c) 2003-2013, Quantum Design, Inc. All rights reserved.
TITLE,3_CuFe2O4_derivative_Hys_at300K_2TSweep_19062023
FILEOPENTIME,26137655.55,06/19/2023,3:05 pm
BYAPP,VSM,2.0,2.0
INFO,PPMS VSM Option Release 1.4.10 Build 1,APPNAME
INFO,Quantum Design Linear Motor Servo Controller,MOTOR_MODULE_NAME
INFO,3101-100 C1,MOTOR_HW_VERSION
INFO,074,MOTOR_SERIAL_NUMBER
INFO,SRV No X-over 01.01.11,MOTOR_SOFTWARE_VERSION
INFO,Quantum Design VSM Detection Module,VSM_MODULE_NAME
INFO,3101-150 E1,VSM_HW_VERSION
INFO,VSM061,VSM_SERIAL_NUMBER
INFO,VSM No X-over 01.02.05 May 20 2008 13:51:47,VSM_SOFTWARE_VERSION
INFO,113,PREAMP_SERIAL_NUMBER
INFO,Quantum Design VSM Oven,OVEN_MODULE_NAME
INFO,3101-200 B0,OVEN_HW_VERSION
INFO,OVN054,OVEN_SERIAL_NUMBER
INFO,01.01.00,OVEN_SOFTWARE_VERSION
INFO,818,COIL_SERIAL_NUMBER
INFO,0,MOMENT_UNITS
INFO,3_CuFe2O4_derivative_Hys_at300K_2TSweep_19062023,SAMPLE_MATERIAL
INFO,granular powder in plastic holder,SAMPLE_COMMENT
INFO,16.6,SAMPLE_MASS
INFO,,SAMPLE_VOLUME
INFO,,SAMPLE_MOLECULAR_WEIGHT
INFO,,SAMPLE_SIZE
INFO,,SAMPLE_SHAPE
DATATYPE,COMMENT,1
DATATYPE,TIME,2
STARTUPAXIS,X,2
STARTUPAXIS,Y1,5
[Data]
Comment,Time Stamp (sec),Temperature (K),Magnetic Field (Oe),Moment (emu),M. Std. Err. (emu),Transport Action,Averaging Time (sec),Frequency (Hz),Peak Amplitude (mm),Center Position (mm),Coil Signal' (mV),Coil Signal" (mV),Range (mV),M. Quad. Signal (emu),M. Raw' (emu),M. Raw" (emu),Min. Temperature (K),Max. Temperature (K),Min. Field (Oe),Max. Field (Oe),Mass (grams),Motor Lag (deg),Pressure (Torr),VSM Status (code),Motor Status (code),Measure Status (code),Measure Count,PPMS Status (code),System Temp. (K),System Field (Oe),Sample Position (deg),Bridge 1 Resistance (ohms),Bridge 1 Excitation (에),Bridge 2 Resistance (ohms),Bridge 2 Excitation (에),Bridge 3 Resistance (ohms),Bridge 3 Excitation (에),Bridge 4 Resistance (ohms),Bridge 4 Excitation (에),Signal 1 Vin (V),Signal 2 Vin (V),Digital Inputs (code),Drive 1 Iout (mA),Drive 1 Ipower (W),Drive 2 Iout (mA),Drive 2 Ipower (W),Pressure (),Map 20 (),Map 21 (),Map 22 (),Map 23 (),Map 24 (),Map 25 (),Map 26 (),Map 27 (),Map 28 (),Map 29 ()
,26137905.39,299.99928285,20004.5985,0.0672969253234893,2.72781020236433E-6,1,4.99626677034896,40.0298881530762,2.00486083537376,9.01999976485968,0.75185814385491,0.130680534875845,2.5,-9.91258972664073E-6,0.0672947289902827,3.36626236244156E-5,299.9992371,299.9993286,20004.582,20004.615,52.0205044688901,18.3671266138617,38.594913,0,0,0,200,4417,300.08335,20004.5985,,,,,,,,,,,,,0,,,,9.3405085,,,,,,299.99928285,,,,
,26138040.32,300.0175171,8761.8785,0.059015194696183,2.08339604825784E-6,1,4.99626677034896,40.0298881530762,2.00495233086308,9.01999976485968,0.65938444142763,0.11446874289039,2.5,-2.0806680503531E-5,0.0590132394976169,1.74503815054834E-5,300.0174561,300.0175781,8761.851,8761.906,51.1474254129093,18.3784363100021,38.594913,0,0,0,200,4417,300.0442,8761.8785,,,,,,,,,,,,,0,,,,9.4342871,,,,,,300.0175171,,,,
,26138120.235,300.00852965,3838.611,0.0501523261154442,1.76778191300974E-6,1,4.99626677034896,40.0298881530762,2.00522120080852,9.01999976485968,0.560416750438245,0.097369921064041,2.5,-1.05798682208813E-5,0.0501506722093886,2.19450471299928E-5,300.0081787,300.0088806,3838.601,3838.621,52.321431448794,18.376992984888,37.832493,0,0,0,200,4417,300.0326,3838.611,,,,,,,,,,,,,0,,,,9.52900605,,,,,,300.00852965,,,,
,26138171.14,300.0083771,1681.8425,0.041389334677142,2.66578250796614E-6,1,4.99626677034896,40.0298881530762,2.00540722652617,9.01999976485968,0.46265916160098,0.0804848993351061,25,-5.79521003166144E-8,0.0413879639462229,2.67873595037455E-5,300.0083313,300.0084229,1681.724,1681.961,52.1361854897363,18.3751878627858,38.594913,0,0,0,200,4417,300.03265,1681.8425,,,,,,,,,,,,,0,,,,9.6725092,,,,,,300.0083771,,,,
,26138219.765,300.0008545,736.719,0.0326841455194924,8.63199883731827E-7,1,4.99626677034896,40.0298881530762,2.00525617188153,9.01999976485968,0.365235294226285,0.0634170464142356,2.5,-1.045695588189E-5,0.0326830771985054,1.07432538257886E-5,300.0008545,300.0008545,736.705,736.733,52.2291992835248,18.3789635049841,38.213703,0,0,0,200,4417,300.0363,736.719,,,,,,,,,,,,,0,,,,9.6241961,,,,,,300.0008545,,,,
,26138250.075,299.9984894,322.7355,0.0245019179642436,1.3301968521311E-6,1,4.99626677034896,40.0298881530762,2.00526218693713,9.01999976485968,0.273803452528067,0.0475341203205346,2.5,-8.47365349186529E-6,0.0245011192547984,7.41925677585709E-6,299.9978943,299.9990845,322.732,322.739,52.6301747138902,18.380571804486,39.357338,0,0,0,200,4417,300.04125,322.7355,,,,,,,,,,,,,0,,,,9.6246767,,,,,,299.9984894,,,,
,26138285.085,300.00028995,141.475,0.0187995209398932,2.11207748664385E-6,1,4.99626677034896,40.0298881530762,2.00531109947225,9.01999976485968,0.210083068776229,0.0364852738662358,2.5,-5.33423502105795E-6,0.0187989063125344,6.8600599428391E-6,299.9997864,300.0007935,141.456,141.494,52.1651057449478,18.3772594696305,38.594913,0,0,0,200,4417,300.0384,141.475,,,,,,,,,,,,,0,,,,8.8247633,,,,,,300.00028995,,,,
,26138320.04,299.9972839,62.078,0.0157274362734721,1.90568418257775E-6,1,4.99626677034896,40.0298881530762,2.00532594220289,9.01999976485968,0.175754211784358,0.030522354267686,2.5,-4.54981180327414E-6,0.0157269235567927,5.65192058266815E-6,299.9966125,299.9979553,62.032,62.124,52.9154691234094,18.3749167089389,37.832493,0,0,0,200,4417,300.0356,62.078,,,,,,,,,,,,,0,,,,9.06608725,,,,,,299.9972839,,,,
,26138355.03,299.9918518,27.3055,0.014213843351491,1.56062902808574E-6,1,4.99626677034896,40.0298881530762,2.00546179928513,9.01999976485968,0.158851040437073,0.0275815035022489,2.5,-4.57726301526739E-6,0.0142133826549147,4.64229298291479E-6,299.991333,299.9923706,27.228,27.383,52.4644694678132,18.3792977325162,38.213703,0,0,0,200,4417,300.0465,27.3055,,,,,,,,,,,,,0,,,,9.6734753,,,,,,299.9918518,,,,
,26138385.015,299.99269105,11.869,0.0134868229093005,1.29371182273015E-6,1,4.99626677034896,40.0298881530762,2.00534347029808,9.01999976485968,0.150720399389938,0.0261525060088431,2.5,-5.84259370921978E-6,0.0134863864279489,2.90523483253806E-6,299.9926453,299.9927368,11.825,11.913,52.4097554714671,18.3838343011016,38.213703,0,0,0,200,4417,300.0526,11.869,,,,,,,,,,,,,0,,,,9.7208223,,,,,,299.99269105,,,,
,26138414.955,299.9924011,5.309,0.0130727701397513,8.55509686658378E-7,1,4.99626677034896,40.0298881530762,2.0054104572891,9.0300003066659,0.146095202385157,0.0253657990455517,2.5,-4.28716542769886E-6,0.0130723462765756,4.19209643710362E-6,299.9922485,299.9925537,5.287,5.331,51.3584651131016,18.3792467641587,38.213703,0,0,0,200,4417,300.0514,5.309,,,,,,,,,,,,,0,,,,9.6246767,,,,,,299.9924011,,,,
,26138447.46,299.9940796,2.501,0.0128073364422267,6.65763097436756E-7,1,4.99626677034896,40.0298881530762,2.00537204063826,9.01999976485968,0.143125948300796,0.0248517831154782,2.5,-4.06781864017201E-6,0.0128069204654334,4.23911277591925E-6,299.9940491,299.9941101,2.456,2.546,53.0905539117171,18.3816033709758,38.213703,0,0,0,200,4417,300.0563,2.501,,,,,,,,,,,,,0,,,,9.6725092,,,,,,299.9940796,,,,
,26138479.9,299.9967804,0.1835,0.0126317338722408,6.74130159706224E-7,1,4.99626677034896,40.0298881530762,2.00537314566673,9.01999976485968,0.141163858722855,0.0245095513625075,2.5,-4.1460792386937E-6,0.01263132265204,4.04697717051226E-6,299.9966736,299.9968872,0.112,0.255,52.2088769420248,18.3829944163891,38.213703,0,0,0,200,4417,300.05575,0.1835,,,,,,,,,,,,,0,,,,9.8184195,,,,,,299.9967804,,,,
,26138514.9,299.9958954,-2.247,0.012530039852564,5.97917672788478E-7,1,4.99626677034896,40.0298881530762,2.00545358729584,9.01999976485968,0.14003253768065,0.0243145507997962,2.5,-3.98898024957827E-6,0.0125296321936409,4.1381572491466E-6,299.9958496,299.9959412,-2.294,-2.2,51.8970071628516,18.3837326376347,38.594913,0,0,0,200,4417,300.05435,-2.247,,,,,,,,,,,,,0,,,,9.6241961,,,,,,299.9958954,,,,
,26138544.88,299.9977417,-5.021,0.0123799026940576,6.10005026564424E-7,1,4.99626677034896,40.0298881530762,2.00538902462771,9.01999976485968,0.138350176187673,0.0240235732429084,2.5,-3.84218217325691E-6,0.0123794991680245,4.18753263585828E-6,299.9969788,299.9985046,-5.034,-5.008,52.9209405230441,18.3771227723615,38.594913,0,0,0,200,4417,300.05555,-5.021,,,,,,,,,,,,,0,,,,9.7696209,,,,,,299.9977417,,,,
,26138574.835,299.9996643,-11.78,0.0121295955507976,5.84689716025132E-7,1,4.99626677034896,40.0298881530762,2.00548858301438,9.01999976485968,0.135559159664736,0.0235399767607488,2.5,-3.67378635649836E-6,0.0121291994164272,4.19360223853307E-6,299.9995117,299.9998169,-11.812,-11.748,52.2377971972363,18.385779817228,37.832493,0,0,0,200,4417,300.0546,-11.78,,,,,,,,,,,,,0,,,,9.44134905,,,,,,299.9996643,,,,
,26138609.845,300.00170895,-27.034,0.011607543959865,6.63741003954883E-7,1,4.99626677034896,40.0298881530762,2.0053957268577,9.01999976485968,0.129719449226019,0.0225232509016806,2.5,-3.7463142504629E-6,0.0116071643005285,3.7825330031666E-6,300.0012512,300.0021667,-27.093,-26.975,52.6981763950633,18.3841797481042,38.594913,0,0,0,200,4417,300.0525,-27.034,,,,,,,,,,,,,0,,,,9.7213078,,,,,,300.00170895,,,,
,26138644.78,300.00082395,-61.8535,0.0103905814144535,1.11046195287204E-6,1,4.99626677034896,40.0298881530762,2.00549904221129,9.01999976485968,0.116124734181812,0.0201648835810867,2.5,-3.17203064555146E-6,0.0103902417206095,3.56746191373928E-6,299.9998474,300.0018005,-61.86,-61.847,52.4285145559286,18.37935692328,38.594913,0,0,0,200,4417,300.0525,-61.8535,,,,,,,,,,,,,0,,,,9.6725092,,,,,,300.00082395,,,,
,26138679.75,300.00227355,-141.3545,0.00731876945446676,2.27089863017188E-6,1,4.99626677034896,40.0298881530762,2.00547855654248,9.01999976485968,0.0817962496551807,0.014187387232465,2.5,-3.65940954051343E-6,0.00731853078722032,1.08772431655061E-6,300.0018921,300.002655,-141.4,-141.309,52.8029146166402,18.3845076368356,38.594913,0,0,0,200,4417,300.0508,-141.3545,,,,,,,,,,,,,0,,,,9.72276305,,,,,,300.00227355,,,,
,26138720.79,300.00541685,-322.679,-4.77567625081314E-5,2.3710546435442E-6,1,4.99626677034896,40.0298881530762,2.00537121613277,9.01999976485968,-0.000530266699215162,-0.000113328740532574,0.25,-1.83061658100762E-6,-4.7753997592201E-5,-1.86153276378661E-6,300.0052185,300.0056152,-322.748,-322.61,52.8365246429671,18.3856579249075,38.213703,0,0,0,200,4417,300.03895,-322.679,,,,,,,,,,,,,0,,,,9.7213078,,,,,,300.00541685,,,,
,26138755.65,300.006897,-736.544,-0.0138245690632909,2.98530508946492E-6,1,4.99626677034896,40.0298881530762,2.00543972753589,9.01999976485968,-0.154496151465029,-0.0268415804333783,2.5,3.04267613793181E-6,-0.0138241137970669,-5.92414641618988E-6,300.006897,300.006897,-736.546,-736.542,52.626266571294,18.3903801820018,38.213703,0,0,0,200,4417,300.04435,-736.544,,,,,,,,,,,,,0,,,,9.916995,,,,,,300.006897,,,,
,26138794.695,300.0065308,-1681.808,-0.0316898340094847,1.57429303555098E-6,1,4.99626677034896,40.0298881530762,2.00541468054639,9.01999976485968,-0.354144560813648,-0.0615290033354511,2.5,6.86502795214806E-6,-0.031688790719923,-1.36891751711864E-5,300.006012,300.0070496,-1681.851,-1681.765,52.3972494151594,18.3838328850302,38.213703,0,0,0,200,4417,300.03505,-1681.808,,,,,,,,,,,,,0,,,,8.73347525,,,,,,300.0065308,,,,
,26138844.685,299.99890135,-3838.6575,-0.0465784058072894,2.90059485101664E-6,1,4.99626677034896,40.0298881530762,2.00545192730996,9.01999976485968,-0.520681329050394,-0.0905411709909662,25,3.30361478887288E-6,-0.0465768791879796,-2.69024302412007E-5,299.9986267,299.999176,-3838.687,-3838.628,52.6176686575825,18.3868833945511,38.594913,0,0,0,200,4417,300.0401,-3838.6575,,,,,,,,,,,,,0,,,,9.916995,,,,,,299.99890135,,,,
,26138929.595,300.0054016,-8762.2175,-0.0591639553240082,1.80201851940506E-6,1,4.99626677034896,40.0298881530762,2.0055305351736,9.01999976485968,-0.661409909566082,-0.11492331276643,25,1.19209967532218E-5,-0.0591620109627135,-2.64334289307107E-5,300.0048218,300.0059814,-8762.253,-8762.182,53.0569438853902,18.3823022325039,38.594913,0,0,0,200,4417,300.03615,-8762.2175,,,,,,,,,,,,,0,,,,9.433816,,,,,,300.0054016,,,,
,26139074.54,300.00473025,-19999.8535,-0.067293940991722,2.34709993152264E-6,1,4.99626677034896,40.0298881530762,2.00554503165295,9.01999976485968,-0.752299836568099,-0.130731657168781,25,1.21476748496355E-5,-0.0672917342518966,-3.14341923210976E-5,300.0041199,300.0053406,-20000.592,-19999.115,52.3964677866402,18.381086184123,38.594913,0,0,0,200,4417,300.03385,-19999.8535,,,,,,,,,,,,,0,,,,9.77059555,,,,,,300.00473025,,,,
,26139204.415,300.00404355,-8762.1365,-0.0590065337165691,3.17338581146611E-6,1,4.99626677034896,40.0298881530762,2.00549098378972,9.01999976485968,-0.659630255004775,-0.114657696864021,25,8.10054590470428E-6,-0.0590045947177992,-3.0149523612686E-5,300.0040283,300.0040588,-8762.238,-8762.035,53.0428745720441,18.3901319976252,38.594913,0,0,0,200,4417,300.0506,-8762.1365,,,,,,,,,,,,,0,,,,9.9174905,,,,,,300.00404355,,,,
,26139289.355,299.992157,-3838.7765,-0.0501235690415751,2.23682158030629E-6,1,4.99626677034896,40.0298881530762,2.00542352456978,9.01999976485968,-0.560315818399113,-0.0973620415736116,25,9.73276575491595E-6,-0.0501219406144594,-2.27710071972299E-5,299.9916077,299.9927063,-3838.844,-3838.709,51.9470313880824,18.3874546153856,38.594913,0,0,0,200,4417,300.0519,-3838.7765,,,,,,,,,,,,,0,,,,9.96677825,,,,,,299.992157,,,,
,26139339.39,299.996048,-1681.66,-0.0413787312730632,1.8549289727136E-6,1,4.99626677034896,40.0298881530762,2.00545677948354,9.0300003066659,-0.46255950887465,-0.080421648752932,25,4.04406325446142E-6,-0.0413773789773091,-2.27938602160224E-5,299.995636,299.99646,-1681.689,-1681.631,52.7263150217556,18.3920181539713,38.213703,0,0,0,200,4417,300.0388,-1681.66,,,,,,,,,,,,,0,,,,9.81890865,,,,,,299.996048,,,,
,26139379.335,299.9915466,-736.6,-0.0326794001574467,1.65642606985305E-6,1,4.99626677034896,40.0298881530762,2.00532901632244,9.01999976485968,-0.365183105577988,-0.0634788832622333,2.5,4.29616524197142E-6,-0.0326783372594422,-1.69001620929092E-5,299.9913635,299.9917297,-736.66,-736.54,52.3628577603132,18.377493172535,39.357338,0,0,0,200,4417,300.04355,-736.6,,,,,,,,,,,,,0,,,,9.96677825,,,,,,299.9915466,,,,
,26139419.24,299.996521,-322.7215,-0.0242904975437532,1.29614442768035E-6,1,4.99626677034896,40.0298881530762,2.00547329143053,9.01999976485968,-0.271459919635282,-0.0471767023090041,2.5,4.10590445812063E-6,-0.0242897044566099,-1.16490426977799E-5,299.9957275,299.9973145,-322.818,-322.625,53.1655902495633,18.3847137500578,38.976128,0,0,0,200,4417,300.0523,-322.7215,,,,,,,,,,,,,0,,,,9.7208223,,,,,,299.996521,,,,
,26139454.265,299.9989624,-141.397,-0.0186125873743391,2.12063939023842E-6,1,4.99626677034896,40.0298881530762,2.00552140774735,9.01999976485968,-0.208011663999755,-0.0361453248639895,2.5,3.5616809750486E-6,-0.0186119785227931,-8.51098658785444E-6,299.9984741,299.9994507,-141.525,-141.269,52.6114156294286,18.3873810066986,38.594913,0,0,0,200,4417,300.04505,-141.397,,,,,,,,,,,,,0,,,,9.81890865,,,,,,299.9989624,,,,
,26139499.71,300.0013428,-61.9515,-0.0155314640233899,1.72339741662826E-6,1,4.99626677034896,40.0298881530762,2.00544778556537,9.01999976485968,-0.173569687772729,-0.0301703018722383,2.5,2.11956761692893E-6,-0.0155309542756739,-7.95470250741126E-6,300.0013428,300.0013428,-61.966,-61.937,52.809167644794,18.3873587971575,37.451283,0,0,0,200,4417,300.04225,-61.9515,,,,,,,,,,,,,0,,,,9.6754055,,,,,,300.0013428,,,,
,26139529.135,300.00341795,-27.4155,-0.0142013296837902,1.64221277105292E-6,1,4.99626677034896,40.0298881530762,2.00535862035083,9.01999976485968,-0.15869507868848,-0.0276031856667017,2.5,3.37467842846961E-7,-0.0142008616834935,-8.87376281587338E-6,300.0031433,300.0036926,-27.507,-27.324,52.4081922144286,18.3804602507434,38.213703,0,0,0,200,4417,300.04835,-27.4155,,,,,,,,,,,,,0,,,,8.90972255,,,,,,300.00341795,,,,
,26139559.2,300.0058441,-11.9635,-0.0134687420573345,1.21336362969894E-6,1,4.99626677034896,40.0298881530762,2.00557294282383,9.01999976485968,-0.150526623421727,-0.0261671713148631,2.5,1.64097432343671E-6,-0.0134682980365614,-7.09543518209169E-6,300.0056152,300.006073,-11.986,-11.941,52.7059926802556,18.387934164447,38.213703,0,0,0,200,4417,300.0396,-11.9635,,,,,,,,,,,,,0,,,,9.01922845,,,,,,300.0058441,,,,
,26139589.11,300.00302125,-5.3675,-0.0130579269057016,8.48706819828427E-7,1,4.99626677034896,40.0298881530762,2.0054490600611,9.01999976485968,-0.145925280245386,-0.0253758799373837,2.5,8.44755214020719E-7,-0.0130574970244678,-7.62549996518066E-6,300.0027161,300.0033264,-5.377,-5.358,52.118208033794,18.3832462502804,38.594913,0,0,0,200,4417,300.0294,-5.3675,,,,,,,,,,,,,0,,,,9.9174905,,,,,,300.00302125,,,,
,26139624.12,299.9989929,-2.2075,-0.0127832511041105,5.70723535240105E-7,1,4.99626677034896,40.0298881530762,2.00547184096733,9.01999976485968,-0.142858126646729,-0.0248375487136119,2.5,1.25786758802298E-6,-0.0127828321327731,-7.03393353924983E-6,299.9983215,299.9996643,-2.269,-2.146,52.0197228403709,18.3859280329682,38.594913,0,0,0,200,4417,300.03845,-2.2075,,,,,,,,,,,,,0,,,,9.01899525,,,,,,299.9989929,,,,
,26139659.05,300.0017395,0.068,-0.012589379032079,6.20226045826097E-7,1,4.99626677034896,40.0298881530762,2.00539396799775,9.01999976485968,-0.140684611000654,-0.0244695486799581,2.5,3.79525373336576E-7,-0.0125889648254508,-7.78635582559778E-6,300.0010071,300.0024719,0.031,0.105,52.9772177764287,18.3775154972638,38.594913,0,0,0,200,4417,300.0427,0.068,,,,,,,,,,,,,0,,,,9.05976245,,,,,,300.0017395,,,,
,26139689.03,300.00302125,2.201,-0.0124418662536517,4.95350241991624E-7,1,4.99626677034896,40.0298881530762,2.00550049748396,9.0300003066659,-0.139043115272783,-0.0241848101389066,2.5,3.08184923607155E-7,-0.0124414563760623,-7.76199762097549E-6,300.0023804,300.0036621,2.198,2.204,52.9381363504671,18.3844715711518,38.594913,0,0,0,200,4417,300.04315,2.201,,,,,,,,,,,,,0,,,,9.62611775,,,,,,300.00302125,,,,
,26139724.025,299.9982605,5.27,-0.01227066454477,6.33119261707573E-7,1,4.99626677034896,40.0298881530762,2.00526211278739,9.01999976485968,-0.137118402737504,-0.0238255495889306,2.5,2.43060986867927E-6,-0.0122702634382988,-5.52874876961936E-6,299.9978333,299.9986877,5.2,5.34,52.6075074868325,18.3926597162423,38.213703,0,0,0,200,4417,300.0383,5.27,,,,,,,,,,,,,0,,,,9.2545848,,,,,,299.9982605,,,,
,26139753.975,299.9980774,11.8305,-0.0120272579420416,5.22668368107471E-7,1,4.99626677034896,40.0298881530762,2.00539352426566,9.01999976485968,-0.134406887275992,-0.0233544540594478,2.5,2.37742501853298E-6,-0.0120268648790243,-5.42381595106926E-6,299.9978638,299.998291,11.778,11.883,53.1945105047749,18.3847031355423,38.594913,0,0,0,200,4417,300.0458,11.8305,,,,,,,,,,,,,0,,,,9.96677825,,,,,,299.9980774,,,,
,26139783.96,299.9983368,27.252,-0.0115280704919305,7.43715867858548E-7,1,4.99626677034896,40.0298881530762,2.00550790950589,9.01999976485968,-0.128832124896296,-0.0224052465170833,2.5,5.88654959085506E-7,-0.011527692546256,-6.8888401537776E-6,299.9980164,299.9986572,27.172,27.332,52.9873789471787,18.3861884672962,38.594913,0,0,0,200,4417,300.0424,27.252,,,,,,,,,,,,,0,,,,10.0165615,,,,,,299.9983368,,,,
,26139818.92,299.9978638,61.864,-0.0103021845898324,1.24876844558857E-6,1,4.99626677034896,40.0298881530762,2.00540480979116,9.01999976485968,-0.115126213685974,-0.0200236411950104,2.5,3.52692048248715E-7,-0.0103018468762426,-6.32958074231557E-6,299.9978638,299.9978638,61.829,61.899,52.7435108491787,18.3836430748211,38.594913,0,0,0,200,4417,300.04465,61.864,,,,,,,,,,,,,0,,,,9.96677825,,,,,,299.9978638,,,,
,26139853.925,300.00111385,141.2355,-0.00721488952955913,2.32568729740321E-6,1,4.99626677034896,40.0298881530762,2.00542039052329,9.01999976485968,-0.0806247479691744,-0.0140332138452614,2.5,-6.50561793020145E-7,-0.00721465172276798,-5.33035757990197E-6,300.0005798,300.0016479,141.218,141.253,52.6168870290633,18.3838701880787,38.213703,0,0,0,200,4417,300.041,141.2355,,,,,,,,,,,,,0,,,,9.77059555,,,,,,300.00111385,,,,
,26139894.595,300.0019836,322.628,0.000164033832280909,2.31425882786662E-6,1,4.99626677034896,40.0298881530762,2.00546794341564,9.01999976485968,0.00183658792152092,0.000302156837494932,0.25,-1.50575274724857E-6,0.000164029407643272,-1.39930591090169E-6,300.000946,300.0030212,322.572,322.684,52.1174264052747,18.382158963389,38.594913,0,0,0,200,4417,300.0405,322.628,,,,,,,,,,,,,0,,,,9.8686919,,,,,,300.0019836,,,,
,26139929.74,300.0004425,736.7645,0.0140317381139117,2.63492730742766E-6,1,4.99626677034896,40.0298881530762,2.00541651750929,9.01999976485968,0.156815609545362,0.0272092982923726,2.5,-6.15088994194465E-6,0.0140312807263201,2.95065523543427E-6,300.0002441,300.0006409,736.741,736.788,52.8373062714864,18.3872950488164,37.832493,0,0,0,200,4417,300.03745,736.7645,,,,,,,,,,,,,0,,,,10.1171265,,,,,,300.0004425,,,,
,26139968.81,300.00212095,1681.6245,0.0317979424433751,1.56990181417943E-6,1,4.99626677034896,40.0298881530762,2.0053373400695,9.01999976485968,0.355343640136129,0.061713575421137,2.5,-8.951630696959E-6,0.0317969012084448,1.16724283696364E-5,300.0019226,300.0023193,1681.572,1681.677,52.3050172498901,18.389073570172,37.451283,0,0,0,200,4417,300.03915,1681.6245,,,,,,,,,,,,,0,,,,9.6754055,,,,,,300.00212095,,,,
,26140028.79,299.99937435,3838.8845,0.0466109001987533,2.90938531030281E-6,1,4.99626677034896,40.0298881530762,2.005380615179,9.01999976485968,0.521043711186376,0.0905041233354745,25,-1.19945220646777E-5,0.0466093775026324,1.82326771836238E-5,299.9992065,299.9995422,3838.878,3838.891,52.5606097756786,18.3858719504604,38.213703,0,0,0,200,4417,300.0418,3838.8845,,,,,,,,,,,,,0,,,,9.02841665,,,,,,299.99937435,,,,
,26140118.725,299.99691775,8762.4335,0.0591705391830255,3.27445336035209E-6,1,4.99626677034896,40.0298881530762,2.0054528226099,9.01999976485968,0.661461974579433,0.114915516918617,25,-1.33830895691155E-5,0.0591686109110248,2.49739483416378E-5,299.9963074,299.9975281,8762.368,8762.499,52.4777571526402,18.3878564961042,38.213703,0,0,0,200,4417,300.04745,8762.4335,,,,,,,,,,,,,0,,,,9.81890865,,,,,,299.99691775,,,,
,26140263.625,300.006546,19997.1785,0.0673024325649351,2.79117946248413E-6,1,4.99626677034896,40.0298881530762,2.00535925687977,9.01999976485968,0.752351677224724,0.130600234009461,25,-2.4342372643674E-5,0.067300229893906,1.92439368438223E-5,300.0057983,300.0072937,19996.021,19998.336,53.7103853274672,18.3835067380947,38.594913,0,0,0,200,4417,300.0424,19997.1785,,,,,,,,,,,,,0,,,,9.8203788,,,,,,300.006546,,,,