File: DataFailid_Testimiseks/uued TEST failid/FSpoly_FeS2_VSM_M_vs_H_300K_090523_Katse2_slow____komaga eraldatud mass.DAT
[Header]
; VSM Data File (default extension .dat)
; Copyright (c) 2003-2013, Quantum Design, Inc. All rights reserved.
TITLE,FSpoly_FeS2_VSM_M_vs_H_300K_090523_Katse2
FILEOPENTIME,22587146.98,05/09/2023,12:50 pm
BYAPP,VSM,2.0,2.0
INFO,PPMS VSM Option Release 1.4.10 Build 1,APPNAME
INFO,Quantum Design Linear Motor Servo Controller,MOTOR_MODULE_NAME
INFO,3101-100 C1,MOTOR_HW_VERSION
INFO,074,MOTOR_SERIAL_NUMBER
INFO,SRV No X-over 01.01.11,MOTOR_SOFTWARE_VERSION
INFO,Quantum Design VSM Detection Module,VSM_MODULE_NAME
INFO,3101-150 E1,VSM_HW_VERSION
INFO,VSM061,VSM_SERIAL_NUMBER
INFO,VSM No X-over 01.02.05 May 20 2008 13:51:47,VSM_SOFTWARE_VERSION
INFO,113,PREAMP_SERIAL_NUMBER
INFO,Quantum Design VSM Oven,OVEN_MODULE_NAME
INFO,3101-200 B0,OVEN_HW_VERSION
INFO,OVN054,OVEN_SERIAL_NUMBER
INFO,01.01.00,OVEN_SOFTWARE_VERSION
INFO,818,COIL_SERIAL_NUMBER
INFO,0,MOMENT_UNITS
INFO,FeS2 FSpoly,SAMPLE_MATERIAL
INFO,in powder capsule,SAMPLE_COMMENT
INFO,35,7 mg,SAMPLE_MASS
INFO,,SAMPLE_VOLUME
INFO,,SAMPLE_MOLECULAR_WEIGHT
INFO,,SAMPLE_SIZE
INFO,,SAMPLE_SHAPE
DATATYPE,COMMENT,1
DATATYPE,TIME,2
STARTUPAXIS,X,2
STARTUPAXIS,Y1,5
[Data]
Comment,Time Stamp (sec),Temperature (K),Magnetic Field (Oe),Moment (emu),M. Std. Err. (emu),Transport Action,Averaging Time (sec),Frequency (Hz),Peak Amplitude (mm),Center Position (mm),Coil Signal' (mV),Coil Signal" (mV),Range (mV),M. Quad. Signal (emu),M. Raw' (emu),M. Raw" (emu),Min. Temperature (K),Max. Temperature (K),Min. Field (Oe),Max. Field (Oe),Mass (grams),Motor Lag (deg),Pressure (Torr),VSM Status (code),Motor Status (code),Measure Status (code),Measure Count,PPMS Status (code),System Temp. (K),System Field (Oe),Sample Position (deg),Bridge 1 Resistance (ohms),Bridge 1 Excitation (에),Bridge 2 Resistance (ohms),Bridge 2 Excitation (에),Bridge 3 Resistance (ohms),Bridge 3 Excitation (에),Bridge 4 Resistance (ohms),Bridge 4 Excitation (에),Signal 1 Vin (V),Signal 2 Vin (V),Digital Inputs (code),Drive 1 Iout (mA),Drive 1 Ipower (W),Drive 2 Iout (mA),Drive 2 Ipower (W),Pressure (),Map 20 (),Map 21 (),Map 22 (),Map 23 (),Map 24 (),Map 25 (),Map 26 (),Map 27 (),Map 28 (),Map 29 ()
,22587176.455,304.9970703,20000.8095,0.00239973917460068,1.91047997561216E-6,1,1.99850670813958,40.0298881530762,1.98085420516253,9.30999964475632,0.0263100957205446,0.00573629050707977,0.25,0.000101908727493979,0.00239923663622641,0.000103413970899542,304.9963684,304.9977722,20000.676,20000.943,52.2932928221017,18.4518841515192,37.832493,0,0,0,80,4929,305.04595,20000.8095,,,,,,,,,,,,,0,,,,4.7115545,,,,,,304.9970703,,,,
,22587320.475,304.9967804,13458.15,0.00232087961418022,1.52495867415706E-6,1,1.99850670813958,40.0298881530762,1.98127822640256,9.30999964475632,0.0254666013302062,0.00545767361159603,0.25,9.02990814519099E-5,0.00232039874125718,9.17571934521475E-5,304.996582,304.9969788,13458.119,13458.181,52.1533813171594,18.458266641015,37.070068,0,0,0,80,4929,305.0518,13458.15,,,,,,,,,,,,,0,,,,4.80663685,,,,,,304.9967804,,,,
,22587434.345,304.9930115,9056.2095,0.00225212273154214,8.97815929321427E-7,1,1.99850670813958,40.0298881530762,1.98122386781543,9.30000003427267,0.0247149351278388,0.00527607561190198,0.25,8.58335970087483E-5,0.0022516574361231,8.72492973124572E-5,304.9928284,304.9931946,9056.207,9056.212,53.0608520279864,18.453904915467,37.832493,0,0,0,80,4929,305.06445,9056.2095,,,,,,,,,,,,,0,,,,4.8308864,,,,,,304.9930115,,,,
,22587522.275,304.99908445,6094.032,0.0021803774339234,7.25565128858287E-7,1,1.99850670813958,40.0298881530762,1.98120903271661,9.30000003427267,0.0239408854531611,0.00503055394628105,0.25,7.60920610802616E-5,0.00217993096315123,7.74643130334633E-5,304.9989929,304.999176,6093.923,6094.141,52.1447834034478,18.4652386799437,38.594913,0,0,0,80,4929,305.05035,6094.032,,,,,,,,,,,,,0,,,,4.8308864,,,,,,304.99908445,,,,
,22587590.22,305.0023651,4100.721,0.00209702454744606,6.2466163908013E-7,1,1.99850670813958,40.0298881530762,1.98125416925416,9.30999964475632,0.0230299664583112,0.00481645821290299,0.25,7.12015813254724E-5,0.00209659617600398,7.25218848370106E-5,305.0021667,305.0025635,4100.7,4100.742,53.1155660243325,18.4627475058809,37.070068,0,0,0,80,4929,305.0563,4100.721,,,,,,,,,,,,,0,,,,4.8306456,,,,,,305.0023651,,,,
,22587639.295,305.00009155,2759.375,0.00199231982691184,5.11909855227869E-7,1,1.99850670813958,40.0298881530762,1.98130418979146,9.30000003427267,0.0218806879917054,0.00457562696643658,0.25,6.7605076967886E-5,0.00199191299051983,6.88595931099028E-5,304.9997864,305.0003967,2759.216,2759.534,52.9099977237748,18.4613650536937,37.070068,0,0,0,80,4929,305.05365,2759.375,,,,,,,,,,,,,0,,,,4.7372148,,,,,,305.00009155,,,,
,22587679.155,304.99688725,1856.545,0.00184667594344961,4.71742729920413E-7,1,1.99850670813958,40.0298881530762,1.9812004782715,9.30999964475632,0.0202808875628453,0.00423659325184825,0.25,6.22708995731638E-5,0.001846299266822,6.34338508524443E-5,304.99646,304.9973145,1856.522,1856.568,52.1314957186209,18.4632677373574,37.070068,0,0,0,80,4929,305.05315,1856.545,,,,,,,,,,,,,0,,,,4.6693771,,,,,,304.99688725,,,,
,22587715.305,304.99516295,1249.2455,0.0016313427287272,3.39504106894858E-7,1,1.99850670813958,40.0298881530762,1.9813163327385,9.30000003427267,0.0179218730158167,0.00371491615416527,0.25,5.24865271623807E-5,0.0016310116615552,5.35143546240691E-5,304.9949646,304.9953613,1249.233,1249.258,53.3125364111787,18.4638863663862,37.070068,0,0,0,80,4929,305.05695,1249.2455,,,,,,,,,,,,,0,,,,4.8791447,,,,,,304.99516295,,,,
,22587746.135,304.99890135,840.7805,0.00136452857180831,3.7190962878976E-7,1,1.99850670813958,40.0298881530762,1.981157085583,9.30999964475632,0.0149879550681509,0.00311598743814229,0.25,4.4708124131353E-5,0.00136425098462069,4.5567702747696E-5,304.9984131,304.9993896,840.728,840.833,53.4008604338518,18.4652242110914,38.213703,0,0,0,80,4929,305.0595,840.7805,,,,,,,,,,,,,0,,,,4.22124215,,,,,,304.99890135,,,,
,22587774.405,305.0005646,565.943,0.00107092373468372,3.57065174020522E-7,1,1.99850670813958,40.0298881530762,1.98104701637917,9.30999964475632,0.0117656174148973,0.00242676525830545,0.25,3.34020812072011E-5,0.00107070689191975,3.40770296608798E-5,305.0004883,305.0006409,565.854,566.032,53.178096305871,18.4645624579025,38.213703,0,0,0,80,4929,305.05575,565.943,,,,,,,,,,,,,0,,,,4.85489515,,,,,,305.0005646,,,,
,22587801.2,304.9996643,380.6865,0.000783090170020794,3.53996142566253E-7,1,1.99850670813958,40.0298881530762,1.9811551421461,9.30000003427267,0.00860467253566068,0.00176964394949186,0.25,2.39747066798754E-5,0.000782931915348154,2.44683339762005E-5,304.9996643,304.9996643,380.644,380.729,52.7396027065825,18.4629658492414,38.213703,0,0,0,80,4929,305.0564,380.6865,,,,,,,,,,,,,0,,,,4.8308864,,,,,,304.9996643,,,,
,22587828.04,305.0001831,256.225,0.000527449317042046,3.35978513351347E-7,1,1.99850670813958,40.0298881530762,1.98119122862828,9.30000003427267,0.00579660148923149,0.00118716324282764,0.25,1.57137487900886E-5,0.000527342994927549,1.60462935875336E-5,304.9996643,305.0007019,256.141,256.309,52.8271451007364,18.4656668558615,38.213703,0,0,0,80,4929,305.0703,256.225,,,,,,,,,,,,,0,,,,4.8306456,,,,,,305.0001831,,,,
,22587856.03,304.9957581,172.712,0.000324803575610833,3.02847465792276E-7,1,1.99850670813958,40.0298881530762,1.98128368130005,9.30000003427267,0.00357037365172006,0.000727277383650706,0.25,9.33153789704463E-6,0.000324738363130722,9.53639896730379E-6,304.9957581,304.9957581,172.644,172.78,52.7013029091402,18.4600784054875,37.070068,0,0,0,80,4929,305.0516,172.712,,,,,,,,,,,,,0,,,,4.8308864,,,,,,304.9957581,,,,
,22587875.99,304.9916992,116.457,0.000127509183517633,3.37165963966518E-7,1,1.99850670813958,40.0298881530762,1.98113365194214,9.30000003427267,0.00140229516845124,0.000281097913785635,0.25,3.26582630773102E-6,0.000127483851683144,3.34631869914303E-6,304.991394,304.9920044,116.136,116.778,51.9313988176978,18.4604618897922,38.213703,0,0,0,80,4929,305.0634,116.457,,,,,,,,,,,,,0,,,,4.8308864,,,,,,304.9916992,,,,
,22587896,304.99201965,78.6625,3.17437176261915E-6,2.33707126460291E-7,1,1.99850670813958,40.0298881530762,1.98133981215756,9.30000003427267,3.75952451532089E-5,-8.4154013655364E-6,0.25,-1.31390011811512E-6,3.17462835196719E-6,-1.31164177804906E-6,304.991394,304.9926453,78.508,78.817,53.2437531014864,18.4666489295502,38.213703,0,0,0,80,4929,305.0644,78.6625,,,,,,,,,,,,,0,,,,4.8791447,,,,,,304.99201965,,,,
,22587923.97,304.9966736,52.7805,-9.19277593179846E-5,2.64943153732685E-7,1,1.99850670813958,40.0298881530762,1.98129102453223,9.30000003427267,-0.00100840897275509,-0.000217923435471091,0.25,-3.73492242602721E-6,-9.19086048996652E-5,-3.79269948915811E-6,304.9963074,304.9970398,52.698,52.863,53.1413597654671,18.4672454747386,37.832493,0,0,0,80,4929,305.07105,52.7805,,,,,,,,,,,,,0,,,,4.80663685,,,,,,304.9966736,,,,
,22587951.95,305.0006409,35.293,-0.000162879869294559,3.12070113034661E-7,1,1.99850670813958,40.0298881530762,1.98101242976605,9.30000003427267,-0.00178829118927432,-0.000375672126308512,0.25,-5.67631843268407E-6,-0.000162846509716793,-5.77886347940656E-6,305.0001526,305.0011292,35.281,35.305,52.2635909383709,18.4635261006421,37.451283,0,0,0,80,4929,305.0634,35.293,,,,,,,,,,,,,0,,,,4.5187762,,,,,,305.0006409,,,,
,22587971.965,304.99913025,23.9155,-0.000203052145736225,2.53405549763556E-7,1,1.99850670813958,40.0298881530762,1.98120095525432,9.30999964475632,-0.00222922032073032,-0.000470291014671583,0.25,-7.25022326030206E-6,-0.000203010456703443,-7.37803117313813E-6,304.9989319,304.9993286,23.856,23.975,52.7958799599671,18.4667051159863,37.832493,0,0,0,80,4929,305.05775,23.9155,,,,,,,,,,,,,0,,,,4.47764635,,,,,,304.99913025,,,,
,22587991.925,304.996582,16.1505,-0.000233644033979268,2.64082748457142E-7,1,1.99850670813958,40.0298881530762,1.98135973112782,9.30999964475632,-0.00256700740350996,-0.000531214699676767,0.25,-7.43992800886906E-6,-0.000233596656371874,-7.5871544085393E-6,304.9964294,304.9967346,16.12,16.181,53.5282658824864,18.466436584887,37.451283,0,0,0,80,4929,305.06215,16.1505,,,,,,,,,,,,,0,,,,4.9036379,,,,,,304.996582,,,,
,22588011.905,304.99769595,11.0875,-0.000263343283674114,3.0703646860636E-7,1,1.99850670813958,40.0298881530762,1.98120957661358,9.30000003427267,-0.00289122884661634,-0.000609437792566816,0.25,-9.35803583627522E-6,-0.000263289256652926,-9.5237978070502E-6,304.9973145,304.9980774,11.075,11.1,53.2734549852172,18.4650898606317,38.213703,0,0,0,80,4929,305.0638,11.0875,,,,,,,,,,,,,0,,,,4.8316097,,,,,,304.99769595,,,,
,22588031.885,304.99699405,7.486,-0.000283944236138758,3.2585422612114E-7,1,1.99850670813958,40.0298881530762,1.98123366185593,9.30000003427267,-0.00311760413266474,-0.000656187759728554,0.25,-1.00056370691863E-5,-0.00028388604265959,-1.01843799842663E-5,304.9968262,304.9971619,7.445,7.527,53.3805380923518,18.4638450569522,37.832493,0,0,0,80,4929,305.0667,7.486,,,,,,,,,,,,,0,,,,4.57290245,,,,,,304.99699405,,,,
,22588059.9,304.9987793,4.8155,-0.00031951105161875,2.6894511866115E-7,1,1.99850670813958,40.0298881530762,1.98114483781545,9.30000003427267,-0.00350814903312134,-0.000737284085590212,0.25,-1.11624556385533E-5,-0.000319445612681661,-1.13636071450758E-5,304.9986572,304.9989014,4.745,4.886,53.0202073449864,18.4643920106524,37.070068,0,0,0,80,4929,305.0638,4.8155,,,,,,,,,,,,,0,,,,4.71625735,,,,,,304.9987793,,,,
,22588079.89,304.998703,3.2695,-0.000336868844100924,2.68016382646223E-7,1,1.99850670813958,40.0298881530762,1.9811917885567,9.30999964475632,-0.00369928876853645,-0.000774645020163915,0.25,-1.15235087104752E-5,-0.000336800007012323,-1.17356322106741E-5,304.9980164,304.9993896,3.259,3.28,52.649715426871,18.465367042113,37.832493,0,0,0,80,4929,305.06455,3.2695,,,,,,,,,,,,,0,,,,4.8791447,,,,,,304.998703,,,,
,22588099.85,305.00135805,2.271,-0.000348019470718053,2.73246980394474E-7,1,1.99850670813958,40.0298881530762,1.98123432155891,9.30000003427267,-0.00382296082476959,-0.000793725030961997,0.25,-1.13095296013263E-5,-0.000347948705939196,-1.15287816735056E-5,305.0009766,305.0017395,2.234,2.308,53.0303685157364,18.4678857877984,38.213703,0,0,0,80,4929,305.06535,2.271,,,,,,,,,,,,,0,,,,4.80663685,,,,,,305.00135805,,,,
,22588119.825,305.0024109,1.5805,-0.000356890073067816,3.12460445485409E-7,1,1.99850670813958,40.0298881530762,1.98117982363632,9.30000003427267,-0.00391892840462238,-0.000821819072755658,0.25,-1.23115074752274E-5,-0.000356817038896294,-1.25362207913204E-5,305.0019531,305.0028687,1.574,1.587,53.2234307599864,18.4655825416658,38.213703,0,0,0,80,4929,305.0613,1.5805,,,,,,,,,,,,,0,,,,4.7826281,,,,,,305.0024109,,,,
,22588150.96,305.0026703,-0.0355,-0.000372556718511202,2.89851602293075E-7,1,1.99850670813958,40.0298881530762,1.98116365487125,9.30000003427267,-0.0040908314706772,-0.000858444222763684,0.25,-1.29022739181404E-5,-0.000372480442815941,-1.31368466220162E-5,305.0020447,305.0032959,-0.145,0.074,53.188257476621,18.4667618599889,38.213703,0,0,0,80,4929,305.0566,-0.0355,,,,,,,,,,,,,0,,,,4.8308864,,,,,,305.0026703,,,,
,22588181.785,305.0005951,-1.496,-0.000379131571533932,2.85777418267901E-7,1,1.99850670813958,40.0298881530762,1.98131538924761,9.30000003427267,-0.00416359456408005,-0.000872151570500758,0.25,-1.29935969611433E-5,-0.000379054060735871,-1.32323310436027E-5,305.0005798,305.0006104,-1.53,-1.462,52.771649475871,18.4697142271588,37.832493,0,0,0,80,4929,305.061,-1.496,,,,,,,,,,,,,0,,,,4.7120247,,,,,,305.0005951,,,,
,22588201.805,304.9991455,-2.0845,-0.000383648438474755,2.92263368750811E-7,1,1.99850670813958,40.0298881530762,1.98122108592896,9.30000003427267,-0.00421265058738903,-0.000884545960331912,0.25,-1.33334345565032E-5,-0.000383569903789855,-1.35749762635337E-5,304.9991455,304.9991455,-2.126,-2.043,53.198418647371,18.4601429752083,37.832493,0,0,0,80,4929,305.0646,-2.0845,,,,,,,,,,,,,0,,,,4.8791447,,,,,,304.9991455,,,,
,22588223.73,304.99971005,-3.162,-0.000385252692586649,3.19239383412629E-7,1,1.99850670813958,40.0298881530762,1.98127441802737,9.30000003427267,-0.00423078213799961,-0.000885929019769224,0.25,-1.3177496377736E-5,-0.00038517395730223,-1.34200885131372E-5,304.9989929,305.0004272,-3.236,-3.088,53.4297806890633,18.4641529763343,37.832493,0,0,0,80,4929,305.0625,-3.162,,,,,,,,,,,,,0,,,,4.8791447,,,,,,304.99971005,,,,
,22588243.74,305.00112915,-4.814,-0.000387755008121003,2.92717748560027E-7,1,1.99850670813958,40.0298881530762,1.98114391220856,9.30999964475632,-0.00425733631633558,-0.000895400550943221,0.25,-1.36046881269664E-5,-0.000387675527663022,-1.3848792503175E-5,305.0007019,305.0015564,-4.835,-4.793,53.4430683738903,18.4653241681366,38.213703,0,0,0,80,4929,305.063,-4.814,,,,,,,,,,,,,0,,,,4.714376,,,,,,305.00112915,,,,
,22588263.74,305.0007477,-7.1985,-0.000397379585605089,3.18508634941123E-7,1,1.99850670813958,40.0298881530762,1.98122116932055,9.30000003427267,-0.00436294540585841,-0.000918963920567277,0.25,-1.40604130754985E-5,-0.00039729806176112,-1.43105556605006E-5,305.0007019,305.0007935,-7.233,-7.164,52.717717108044,18.4640801738217,37.832493,0,0,0,80,4929,305.06235,-7.1985,,,,,,,,,,,,,0,,,,4.3107281,,,,,,305.0007477,,,,
,22588285.71,305.00401305,-10.5035,-0.000402932051563509,2.86470239945664E-7,1,1.99850670813958,40.0298881530762,1.98134852763671,9.30000003427267,-0.00442330588955229,-0.000936887220457153,0.25,-1.4711754413999E-5,-0.000402849059698596,-1.49653072951784E-5,305.0039978,305.0040283,-10.536,-10.471,53.0835192550441,18.4670336003561,38.213703,0,0,0,80,4929,305.06265,-10.5035,,,,,,,,,,,,,0,,,,4.64350585,,,,,,305.00401305,,,,
,22588307.685,305.00598145,-16.0045,-0.000415860877050624,2.85033578106073E-7,1,1.99850670813958,40.0298881530762,1.98126537769264,9.30999964475632,-0.00456670925566445,-0.000957381143825084,0.25,-1.432126771469E-5,-0.00041577574488977,-1.45831219034643E-5,305.0056458,305.0063171,-16.055,-15.954,53.3750666927172,18.4675604039022,37.832493,0,0,0,80,4929,305.05395,-16.0045,,,,,,,,,,,,,0,,,,4.8306456,,,,,,305.00598145,,,,
,22588327.68,305.00526425,-23.607,-0.000432273639504814,3.11843706190803E-7,1,1.99850670813958,40.0298881530762,1.98115625891166,9.30000003427267,-0.00474604618939644,-0.0009988290459419,0.25,-1.52228295257836E-5,-0.000432184942982823,-1.54949564129706E-5,305.005249,305.0052795,-23.664,-23.55,52.7958799599671,18.4643253375096,37.832493,0,0,0,80,4929,305.0546,-23.607,,,,,,,,,,,,,0,,,,4.5989542,,,,,,305.00526425,,,,
,22588349.695,305.0036926,-35.2365,-0.000449935488567295,2.72539134514245E-7,1,1.99850670813958,40.0298881530762,1.98111526229627,9.30000003427267,-0.0049396412322631,-0.0010408900156498,0.25,-1.59598935458691E-5,-0.000449843115873517,-1.62431212394452E-5,305.0035095,305.0038757,-35.251,-35.222,52.8787325830056,18.464279610119,37.832493,0,0,0,80,4929,305.05225,-35.2365,,,,,,,,,,,,,0,,,,4.8791447,,,,,,305.0036926,,,,
,22588383.64,305.0043945,-52.5415,-0.000479696038540541,2.86267681905661E-7,1,1.99850670813958,40.0298881530762,1.98126885021416,9.30999964475632,-0.00526738546225582,-0.00110623045378287,0.25,-1.66905155501232E-5,-0.000479597752636456,-1.69925350799769E-5,305.0040588,305.0047302,-52.544,-52.539,52.6817621961594,18.466816314007,38.594913,0,0,0,80,4929,305.053,-52.5415,,,,,,,,,,,,,0,,,,4.9036379,,,,,,305.0043945,,,,
,22588411.61,305.0058441,-77.9555,-0.000529225981638514,3.38989082512204E-7,1,1.99850670813958,40.0298881530762,1.98138475129271,9.30000003427267,-0.00581221356422655,-0.00121689897532514,0.25,-1.80860798757902E-5,-0.00052911773241363,-1.84193454576463E-5,305.0052795,305.0064087,-77.996,-77.915,52.8138574159094,18.4678195166692,37.832493,0,0,0,80,4929,305.0508,-77.9555,,,,,,,,,,,,,0,,,,4.8791447,,,,,,305.0058441,,,,
,22588438.315,305.0067139,-115.938,-0.000597152290851014,2.95647051170867E-7,1,1.99850670813958,40.0298881530762,1.98126478823997,9.30999964475632,-0.00655958061929326,-0.00136295353555395,0.25,-1.94972794735695E-5,-0.000597030711015103,-1.98734853396426E-5,305.0067139,305.0067139,-115.938,-115.938,53.1218190524864,18.4691743956404,37.832493,0,0,0,80,4929,305.0507,-115.938,,,,,,,,,,,,,0,,,,4.8791447,,,,,,305.0067139,,,,
,22588457.58,305.00386045,-171.849,-0.000706917201908983,3.27887125659176E-7,1,1.99850670813958,40.0298881530762,1.98117802554156,9.30000003427267,-0.00776312494577199,-0.00162417866685622,0.25,-2.40554238838603E-5,-0.000706772713685185,-2.45006171184473E-5,305.0032959,305.004425,-171.989,-171.709,53.1593372214095,18.4607131563562,37.832493,0,0,0,80,4929,305.04355,-171.849,,,,,,,,,,,,,0,,,,4.85489515,,,,,,305.00386045,,,,
,22588485.555,305.0013275,-256.0995,-0.000856846413464757,2.85181474573487E-7,1,1.99850670813958,40.0298881530762,1.98133260887674,9.30999964475632,-0.00941373646554716,-0.0019490533915154,0.25,-2.7370287465752E-5,-0.000856672484686035,-2.79102162298507E-5,305.000885,305.00177,-256.169,-256.03,53.4563560587172,18.4684085029655,38.213703,0,0,0,80,4929,305.04925,-256.0995,,,,,,,,,,,,,0,,,,4.87938835,,,,,,305.0013275,,,,
,22588515.55,304.99790955,-380.615,-0.00104610633523997,3.39109842171911E-7,1,1.99850670813958,40.0298881530762,1.98141121931119,9.30000003427267,-0.0114955479072018,-0.0023677510536877,0.25,-3.2338789571357E-5,-0.00104589478162773,-3.29981800409156E-5,304.9978943,304.9979248,-380.677,-380.553,52.9764361479095,18.4698825981562,37.070068,0,0,0,80,4929,305.04705,-380.615,,,,,,,,,,,,,0,,,,4.5820322,,,,,,304.99790955,,,,
,22588543.41,304.9935303,-565.722,-0.00127081058664627,2.85284542341962E-7,1,1.99850670813958,40.0298881530762,1.98145671149631,9.30000003427267,-0.013965698164601,-0.00287301621625921,0.25,-3.89781254190063E-5,-0.00127055395918638,-3.97791773034317E-5,304.9934998,304.9935608,-565.873,-565.571,53.4774600287364,18.4694795659923,38.976128,0,0,0,80,4929,305.05695,-565.722,,,,,,,,,,,,,0,,,,4.50213955,,,,,,304.9935303,,,,
,22588574.64,304.99555965,-840.489,-0.00149763534658379,3.5281608636256E-7,1,1.99850670813958,40.0298881530762,1.98132830338989,9.30000003427267,-0.0164576315117324,-0.00338419649486623,0.25,-4.58078225879394E-5,-0.00149733291077274,-4.67518177291492E-5,304.9945068,304.9966125,-840.494,-840.484,52.473849010044,18.4639870281263,38.213703,0,0,0,80,4929,305.0687,-840.489,,,,,,,,,,,,,0,,,,4.8791447,,,,,,304.99555965,,,,
,22588605.47,304.9997406,-1249.1405,-0.00170615720212634,3.09615191784822E-7,1,1.99850670813958,40.0298881530762,1.98142173927614,9.30000003427267,-0.0187505715495657,-0.00385193942890382,0.25,-5.18575578446369E-5,-0.00170581264623751,-5.29330757766048E-5,304.999054,305.0004272,-1249.184,-1249.097,52.4965162371017,18.4641660659997,37.070068,0,0,0,80,4929,305.0553,-1249.1405,,,,,,,,,,,,,0,,,,4.85489515,,,,,,304.9997406,,,,
,22588647.44,304.9988556,-1856.9165,-0.00187460593301378,3.60593196587526E-7,1,1.99850670813958,40.0298881530762,1.98132552496025,9.30999964475632,-0.0206014405965328,-0.00422867144739149,0.25,-5.66722269686992E-5,-0.00187422760783145,-5.78539530650832E-5,304.9985657,304.9991455,-1856.936,-1856.897,53.4782416572557,18.4694818523249,37.832493,0,0,0,80,4929,305.05415,-1856.9165,,,,,,,,,,,,,0,,,,4.7388692,,,,,,304.9988556,,,,
,22588695.435,304.99684145,-2759.46,-0.00199663817539939,4.34670711820968E-7,1,1.99850670813958,40.0298881530762,1.98144557474957,9.30000003427267,-0.021945200316185,-0.00449628252377311,0.25,-5.96440049976302E-5,-0.00199623580680608,-6.09027384089825E-5,304.9966736,304.9970093,-2759.47,-2759.45,53.3055017545056,18.4637051639349,37.832493,0,0,0,80,4929,305.0513,-2759.46,,,,,,,,,,,,,0,,,,4.85489515,,,,,,304.99684145,,,,
,22588745.395,304.9933014,-4100.4095,-0.00209066992524237,4.88421702758711E-7,1,1.99850670813958,40.0298881530762,1.9814121751843,9.30000003427267,-0.0229788964364314,-0.00470476812394513,0.25,-6.21642861265861E-5,-0.00209024903984385,-6.34821585684178E-5,304.9924011,304.9942017,-4100.449,-4100.37,52.8740428118902,18.4637187296122,38.213703,0,0,0,80,4929,305.06785,-4100.4095,,,,,,,,,,,,,0,,,,4.7372148,,,,,,304.9933014,,,,
,22588811.35,305.000885,-6094.062,-0.0021682233257593,6.6542279629808E-7,1,1.99850670813958,40.0298881530762,1.98153145648233,9.30000003427267,-0.0238321664979856,-0.00488246995694745,0.25,-6.47327371040521E-5,-0.00216778619312618,-6.6099215381831E-5,305.000885,305.000885,-6094.145,-6093.979,53.1163476528518,18.4661902380756,37.070068,0,0,0,80,4929,305.07245,-6094.062,,,,,,,,,,,,,0,,,,4.85489515,,,,,,305.000885,,,,
,22588903.255,305.00076295,-9056.266,-0.00223312626967269,9.43894847539846E-7,1,1.99850670813958,40.0298881530762,1.98126766676624,9.30000003427267,-0.02454150403941,-0.00498949454312646,2.5,-6.33224121245774E-5,-0.00223267821826836,-6.47301740625273E-5,305.0003052,305.0012207,-9056.335,-9056.197,53.1468311651018,18.4707076539006,37.832493,0,0,0,80,4929,305.0563,-9056.266,,,,,,,,,,,,,0,,,,4.5432694,,,,,,305.00076295,,,,
,22589027.15,305.00527955,-13458.357,-0.00229866338344036,1.14188519408499E-6,1,1.99850670813958,40.0298881530762,1.98141421425308,9.30000003427267,-0.0252744309714179,-0.00511863828693698,0.25,-6.34445608776927E-5,-0.00229820303754153,-6.48934406531572E-5,305.0050354,305.0055237,-13458.399,-13458.315,52.9975401179287,18.4669862083915,37.832493,0,0,0,80,4929,305.0519,-13458.357,,,,,,,,,,,,,0,,,,4.87938835,,,,,,305.00527955,,,,
,22589199.095,305.0024719,-20000.873,-0.00237269466300284,1.72140032158744E-6,1,1.99850670813958,40.0298881530762,1.98131558867989,9.30000003427267,-0.0260856219146241,-0.00529220752990723,0.25,-6.63005830069229E-5,-0.00237221928770944,-6.77951059495252E-5,305.0017395,305.0032043,-20001.984,-19999.762,52.9779994049479,18.4702320364412,37.451283,0,0,0,80,4929,305.0516,-20000.873,,,,,,,,,,,,,0,,,,4.73603345,,,,,,305.0024719,,,,
,22589334.98,304.99790955,-13458.3415,-0.00230152602682579,1.29381015113238E-6,1,1.99850670813958,40.0298881530762,1.98134219868929,9.30000003427267,-0.0252961511051399,-0.00517587371319509,0.25,-6.8143279417213E-5,-0.00230106267973923,-6.95931677820863E-5,304.9978943,304.9979248,-13458.363,-13458.32,53.1890391051402,18.4662678953038,38.213703,0,0,0,80,4929,305.04605,-13458.3415,,,,,,,,,,,,,0,,,,4.9281311,,,,,,304.99790955,,,,
,22589440.865,305.0006714,-9056.213,-0.00223459665275272,1.01212864532926E-6,1,1.99850670813958,40.0298881530762,1.98140516301474,9.30999964475632,-0.024561854699154,-0.00502217457119927,0.25,-6.58592891844822E-5,-0.0022341467246021,-6.72675381627379E-5,305.0004578,305.000885,-9056.339,-9056.087,53.3586524938133,18.4713603123013,37.832493,0,0,0,80,4929,305.05345,-9056.213,,,,,,,,,,,,,0,,,,4.80663685,,,,,,305.0006714,,,,
,22589526.775,304.99420165,-6093.933,-0.00216759699106097,7.78292525176438E-7,1,1.99850670813958,40.0298881530762,1.98142416057006,9.30999964475632,-0.0238266273833004,-0.0048659813553948,0.25,-6.33721080056165E-5,-0.00216716126687929,-6.47385096380942E-5,304.9940491,304.9943542,-6094.015,-6093.851,53.2523510151979,18.4704045146925,37.070068,0,0,0,80,4929,305.06115,-6093.933,,,,,,,,,,,,,0,,,,4.95287015,,,,,,304.99420165,,,,
,22589594.73,304.99632265,-4100.7325,-0.00208682544454788,6.17769860228268E-7,1,1.99850670813958,40.0298881530762,1.98130394755743,9.30999964475632,-0.0229398434365593,-0.0046705349065735,0.25,-5.97566967771043E-5,-0.00208640659610308,-6.10725966077257E-5,304.9960938,304.9965515,-4100.772,-4100.693,52.6215768001786,18.4658831359792,37.832493,0,0,0,80,4929,305.0604,-4100.7325,,,,,,,,,,,,,0,,,,4.52260185,,,,,,304.99632265,,,,
,22589642.705,304.99661255,-2759.3525,-0.00198457247237967,4.850986896841E-7,1,1.99850670813958,40.0298881530762,1.9812646124758,9.30999964475632,-0.0218134197896858,-0.00445293085013089,0.25,-5.7854462656641E-5,-0.00198417346602879,-5.9105786647092E-5,304.9963684,304.9968567,-2759.421,-2759.284,52.7099008228517,18.4669826315969,37.832493,0,0,0,80,4929,305.0645,-2759.3525,,,,,,,,,,,,,0,,,,4.87938835,,,,,,304.99661255,,,,
,22589690.67,304.99510195,-1856.778,-0.00183977958574894,4.12867943646951E-7,1,1.99850670813958,40.0298881530762,1.98134841456598,9.30000003427267,-0.0202218807470544,-0.00413322057513977,0.25,-5.40863545014677E-5,-0.00183940947883917,-5.52463613559845E-5,304.9950867,304.9951172,-1856.78,-1856.776,52.7575801625248,18.4670346923012,37.832493,0,0,0,80,4929,305.06555,-1856.778,,,,,,,,,,,,,0,,,,4.88011865,,,,,,304.99510195,,,,
,22589738.64,304.9994049,-1249.439,-0.00162916101833725,4.28844027294424E-7,1,1.99850670813958,40.0298881530762,1.98140340508806,9.30000003427267,-0.0179025235125018,-0.00368787968023999,0.25,-5.04048148087473E-5,-0.00162883147074232,-5.14315818781684E-5,304.9989014,304.9999084,-1249.482,-1249.396,53.9073557143134,18.4711319720348,37.832493,0,0,0,80,4929,305.06855,-1249.439,,,,,,,,,,,,,0,,,,4.85489515,,,,,,304.9994049,,,,
,22589768.63,305.0001068,-840.618,-0.00136371729871754,3.53332844784902E-7,1,1.99850670813958,40.0298881530762,1.98128794679687,9.30000003427267,-0.0149849417222281,-0.00308588447600879,0.25,-4.21065430385747E-5,-0.00136344146481275,-4.2966076885921E-5,304.9997864,305.0004272,-840.689,-840.547,52.731004792871,18.4688616683685,38.213703,0,0,0,80,4929,305.0602,-840.618,,,,,,,,,,,,,0,,,,4.87938835,,,,,,305.0001068,,,,
,22589796.985,304.99850465,-565.8665,-0.00107466961300339,3.9216000780922E-7,1,1.99850670813958,40.0298881530762,1.98138636841638,9.30000003427267,-0.0118098779682534,-0.00242895897146215,0.25,-3.29129338780966E-5,-0.00107445246659749,-3.35903352756796E-5,304.9975891,304.9994202,-565.878,-565.855,53.4594825727941,18.4694829720876,37.451283,0,0,0,80,4929,305.0636,-565.8665,,,,,,,,,,,,,0,,,,4.9036379,,,,,,304.99850465,,,,
,22589824.575,304.9975586,-380.977,-0.000786091781790034,3.63797431333381E-7,1,1.99850670813958,40.0298881530762,1.98131999387975,9.30000003427267,-0.00863851883270753,-0.00177556983422582,0.25,-2.39761683583762E-5,-0.000785933029422549,-2.44716945453081E-5,304.9968262,304.998291,-380.979,-380.975,52.4441471263132,18.4651939234778,37.832493,0,0,0,80,4929,305.06225,-380.977,,,,,,,,,,,,,0,,,,4.95287015,,,,,,304.9975586,,,,
,22589851.71,305.0006714,-256.2635,-0.000551544029075676,3.16205337591533E-7,1,1.99850670813958,40.0298881530762,1.98148624987191,9.30000003427267,-0.00605942437037161,-0.00125790599769039,0.25,-1.7909928594662E-5,-0.000551431901866401,-1.82573935526501E-5,305.0000916,305.0012512,-256.315,-256.212,52.822455329621,18.4677497055274,38.213703,0,0,0,80,4929,305.07085,-256.2635,,,,,,,,,,,,,0,,,,4.5888834,,,,,,305.0006714,,,,
,22589876.58,305.00335695,-172.335,-0.000350032458435095,2.88621529766959E-7,1,1.99850670813958,40.0298881530762,1.98133432146618,9.30999964475632,-0.00384291721105982,-0.000811819108163278,0.25,-1.25936738552447E-5,-0.000349960487362662,-1.28139769437597E-5,305.0031433,305.0035706,-172.425,-172.245,52.3018907358132,18.4673270731774,37.832493,0,0,0,80,4929,305.05675,-172.335,,,,,,,,,,,,,0,,,,4.40561815,,,,,,305.00335695,,,,
,22589896.525,305.0037384,-116.4755,-0.000157095939895291,3.31179303248437E-7,1,1.99850670813958,40.0298881530762,1.98142536021357,9.30000003427267,-0.00172231143854307,-0.000378625941974593,0.25,-6.94298444235914E-6,-0.000157062816326009,-7.04162076828181E-6,305.0032654,305.0042114,-116.834,-116.117,53.6580162166788,18.4682668624827,38.213703,0,0,0,80,4929,305.0588,-116.4755,,,,,,,,,,,,,0,,,,4.87938835,,,,,,305.0037384,,,,
,22589916.49,305.0061493,-78.695,-3.50066852037052E-5,3.07735043212443E-7,1,1.99850670813958,40.0298881530762,1.98135547823649,9.30000003427267,-0.00037997697834365,-0.000106234741600786,0.25,-3.52632939918431E-6,-3.49980428729868E-5,-3.54794717685666E-6,305.0060425,305.0062561,-78.811,-78.579,53.1147843958133,18.4687019014657,37.832493,0,0,0,80,4929,305.0596,-78.695,,,,,,,,,,,,,0,,,,4.80663685,,,,,,305.0061493,,,,
,22589951.49,305.00505065,-52.581,6.12912135860373E-5,3.08139682902079E-7,1,1.99850670813958,40.0298881530762,1.98118201339377,9.30000003427267,0.000678431170976757,0.00011006073065463,0.25,-6.9872426268243E-7,6.12804548150818E-5,-6.59616612956666E-7,305.0047302,305.0053711,-52.616,-52.546,53.425090917948,18.4657613015293,37.832493,0,0,0,80,4929,305.0473,-52.581,,,,,,,,,,,,,0,,,,4.75933315,,,,,,305.00505065,,,,
,22589978.51,304.99676515,-35.377,0.000112400937706897,2.60515008961329E-7,1,1.99850670813958,40.0298881530762,1.98125072143378,9.30000003427267,0.00124023317086187,0.000224680642020415,0.25,7.8564755471277E-7,0.000112379921147494,8.56986268354062E-7,304.9967346,304.9967957,-35.413,-35.341,53.6009573347749,18.4723960847064,37.451283,0,0,0,80,4929,305.05665,-35.377,,,,,,,,,,,,,0,,,,4.9041274,,,,,,304.99676515,,,,
,22589998.46,304.9932556,-23.8275,0.000149010416565271,3.05419130089269E-7,1,1.99850670813958,40.0298881530762,1.98119552349533,9.30000003427267,0.00164291333995173,0.000304896844029804,0.25,1.67922425133827E-6,0.000148982164719782,1.77368505705605E-6,304.9928589,304.9936523,-23.863,-23.792,53.0749213413325,18.4693691023893,37.451283,0,0,0,80,4929,305.0486,-23.8275,,,,,,,,,,,,,0,,,,4.83281495,,,,,,304.9932556,,,,
,22590018.475,304.99357605,-16.079,0.000172588010138291,2.81234110278162E-7,1,1.99850670813958,40.0298881530762,1.98145679204373,9.30000003427267,0.00190202661432537,0.000359405992773624,0.25,2.50802277870633E-6,0.00017255492968797,2.61731483888979E-6,304.9931946,304.9939575,-16.177,-15.981,52.5574832616017,18.4697259169016,38.213703,0,0,0,80,4929,305.07775,-16.079,,,,,,,,,,,,,0,,,,4.7388692,,,,,,304.99357605,,,,
,22590038.405,304.99864195,-10.9435,0.0001914665861473,2.69802483349693E-7,1,1.99850670813958,40.0298881530762,1.98137315401773,9.30000003427267,0.00210914763158648,0.000403571226352181,0.25,3.22295539066975E-6,0.000191429577272603,3.34412566584939E-6,304.9981689,304.999115,-11.085,-10.802,52.7849371606979,18.466575904431,37.832493,0,0,0,80,4929,305.0689,-10.9435,,,,,,,,,,,,,0,,,,4.9041274,,,,,,304.99864195,,,,
,22590060.395,305.0018616,-7.383,0.000205932128047409,2.66548094669115E-7,1,1.99850670813958,40.0298881530762,1.98144107779973,9.30999964475632,0.00226800274564188,0.000437341501136327,0.25,3.7620336377762E-6,0.0002058921149661,3.89230563187315E-6,305.0010071,305.0027161,-7.448,-7.318,52.883422354121,18.4717275486347,37.832493,0,0,0,80,4929,305.06595,-7.383,,,,,,,,,,,,,0,,,,4.56800845,,,,,,305.0018616,,,,
,22590082.39,305.0009918,-5.0685,0.000219613792602207,2.87834916419594E-7,1,1.99850670813958,40.0298881530762,1.9813534854297,9.30000003427267,0.00241829281078146,0.000468035252668572,0.25,4.16200222526546E-6,0.000219571030982865,4.30090621499481E-6,305.0007629,305.0012207,-5.1,-5.037,53.3766299497556,18.4689537511261,38.213703,0,0,0,80,4929,305.05795,-5.0685,,,,,,,,,,,,,0,,,,4.71625735,,,,,,305.0009918,,,,
,22590104.405,304.99923705,-3.4125,0.00022922431640336,3.24517225415533E-7,1,1.99850670813958,40.0298881530762,1.98128215094519,9.30000003427267,0.00252325734652099,0.000492957319629738,0.25,4.74759428979613E-6,0.000229179439379434,4.89250061708854E-6,304.9989319,304.9995422,-3.423,-3.402,52.8591918700248,18.4684033592657,38.213703,0,0,0,80,4929,305.06295,-3.4125,,,,,,,,,,,,,0,,,,4.88011865,,,,,,304.99923705,,,,
,22590124.37,304.9989166,-2.2285,0.000238271859440281,2.93489582290025E-7,1,1.99850670813958,40.0298881530762,1.981267688281,9.30000003427267,0.0026228846134211,0.000512111964083256,0.25,4.90792654240478E-6,0.000238225230786171,5.05855595032358E-6,304.9988403,304.9989929,-2.329,-2.128,52.2667174524478,18.4671619129387,37.832493,0,0,0,80,4929,305.06535,-2.2285,,,,,,,,,,,,,0,,,,4.9041274,,,,,,304.9989166,,,,
,22590144.325,304.9967804,-1.474,0.000240835889529257,2.90616258400315E-7,1,1.99850670813958,40.0298881530762,1.98136711510392,9.30999964475632,0.00265066264387877,0.000520950745313559,0.25,5.25970670396072E-6,0.000240788584419467,5.41190343617532E-6,304.9959412,304.9976196,-1.534,-1.414,52.9154691234094,18.4699596830316,37.832493,0,0,0,80,4929,305.06425,-1.474,,,,,,,,,,,,,0,,,,4.95287015,,,,,,304.9967804,,,,
,22590164.34,304.9972839,-0.2485,0.000247644145472938,2.93956043861343E-7,1,1.99850670813958,40.0298881530762,1.98134837722768,9.30000003427267,0.00272564141507948,0.000535263212977618,0.25,5.371324075864E-6,0.000247595522955155,5.52782949866694E-6,304.9967651,304.9978027,-0.288,-0.209,53.3922625201403,18.4670532248455,38.213703,0,0,0,80,4929,305.06505,-0.2485,,,,,,,,,,,,,0,,,,4.85489515,,,,,,304.9972839,,,,
,22590192.33,304.99809265,1.3585,0.000254458221725683,2.91904609956648E-7,1,1.99850670813958,40.0298881530762,1.98138547947832,9.30999964475632,0.00280156909695578,0.000544943636277238,0.25,5.06135043462111E-6,0.00025440854657246,5.22224282474803E-6,304.9978027,304.9983826,1.275,1.442,52.9076528382171,18.4684157858417,37.832493,0,0,0,80,4929,305.06955,1.3585,,,,,,,,,,,,,0,,,,4.50213955,,,,,,304.99809265,,,,
,22590214.275,305.0007324,2.12,0.00026074278079593,2.88108896728814E-7,1,1.99850670813958,40.0298881530762,1.98129144203483,9.30000003427267,0.00286933675155287,0.000565815604455859,0.25,5.85966641992685E-6,0.000260691429596217,6.024411103629E-6,305.0005188,305.000946,2.008,2.232,52.9154691234094,18.467390457275,37.070068,0,0,0,80,4929,305.0664,2.12,,,,,,,,,,,,,0,,,,4.87938835,,,,,,305.0007324,,,,
,22590242.29,305.0018463,3.235,0.000267050953783204,2.90731247006776E-7,1,1.99850670813958,40.0298881530762,1.98145410718503,9.30999964475632,0.00293812145790326,0.000584522193888507,0.25,6.45145151108688E-6,0.000266998064675209,6.62010276041153E-6,305.0012207,305.0024719,3.219,3.251,53.638475503698,18.4702224845158,37.832493,0,0,0,80,4929,305.06135,3.235,,,,,,,,,,,,,0,,,,4.78644705,,,,,,305.0018463,,,,
,22590262.285,305.00247195,4.793,0.000277788924389403,2.590112217187E-7,1,1.99850670813958,40.0298881530762,1.98137680806622,9.30000003427267,0.00305661239457162,0.000605328364005697,0.25,6.46879634303663E-6,0.000277734057418476,6.64427241028258E-6,305.0018921,305.0030518,4.763,4.823,52.9326649508325,18.4692863759423,37.832493,0,0,0,80,4929,305.0623,4.793,,,,,,,,,,,,,0,,,,4.95287015,,,,,,305.00247195,,,,
,22590282.265,305.00369265,7.13,0.00028034507988623,2.96046148670068E-7,1,1.99850670813958,40.0298881530762,1.98131318212658,9.30000003427267,0.00308553353843734,0.000605763006284145,0.25,6.06518534858627E-6,0.000280289992169984,6.24236114206106E-6,305.0031128,305.0042725,7.126,7.134,53.1343251087941,18.4730593405714,36.307648,0,0,0,80,4929,305.06135,7.13,,,,,,,,,,,,,0,,,,4.47764635,,,,,,305.00369265,,,,
,22590302.215,305.00271605,10.6515,0.000289887008332394,3.29122872762206E-7,1,1.99850670813958,40.0298881530762,1.98137734291179,9.30999964475632,0.0031898561868015,0.000630982136105583,0.25,6.68632671917599E-6,0.000289829790850789,6.86945399969207E-6,305.0019226,305.0035095,10.611,10.692,53.1530841932556,18.4696264773085,37.832493,0,0,0,80,4929,305.06605,10.6515,,,,,,,,,,,,,0,,,,4.78644705,,,,,,305.00271605,,,,
,22590322.25,305.0020294,15.6915,0.000298293174106092,2.97157930840596E-7,1,1.99850670813958,40.0298881530762,1.98118568437588,9.30999964475632,0.0032821224768055,0.000648809216286305,0.25,6.84310308754767E-6,0.000298234326203258,7.03155580243195E-6,305.00177,305.0022888,15.633,15.75,53.1280720806402,18.4634014987589,37.832493,0,0,0,80,4929,305.05485,15.6915,,,,,,,,,,,,,0,,,,4.95287015,,,,,,305.0020294,,,,
,22590342.195,304.99984745,23.715,0.000319309277500802,3.41141085346671E-7,1,1.99850670813958,40.0298881530762,1.98131710431163,9.30000003427267,0.00351276185854248,0.000699307411606577,0.25,7.75449580579972E-6,0.000319246032100009,7.95614323366775E-6,304.9996033,305.0000916,23.628,23.802,53.1530841932556,18.4678604287477,37.070068,0,0,0,80,4929,305.06085,23.715,,,,,,,,,,,,,0,,,,4.92837695,,,,,,304.99984745,,,,
,22590370.725,305.0014954,35.3725,0.000343868095780914,2.88530839130823E-7,1,1.99850670813958,40.0298881530762,1.98119154774287,9.30000003427267,0.00378412932369316,0.00074486589813699,0.25,7.61035483692793E-6,0.000343800439845929,7.82764669186276E-6,305.0014954,305.0014954,35.33,35.415,53.1827860769864,18.4720499743274,37.832493,0,0,0,80,4929,305.0603,35.3725,,,,,,,,,,,,,0,,,,4.95287015,,,,,,305.0014954,,,,
,22590398.06,305.0022125,52.399,0.00038006806674984,2.50524504506114E-7,1,1.99850670813958,40.0298881530762,1.98116238268826,9.30000003427267,0.00418106695953425,0.000831139690632736,0.25,9.12404797104134E-6,0.000379992827076406,9.36408483965481E-6,305.0019836,305.0024414,52.387,52.411,53.577508479198,18.4691331011975,37.832493,0,0,0,80,4929,305.0597,52.399,,,,,,,,,,,,,0,,,,4.92837695,,,,,,305.0022125,,,,
,22590424.15,305.00376895,77.8605,0.000440986801990845,3.31959729226336E-7,1,1.99850670813958,40.0298881530762,1.98137070387223,9.30999964475632,0.00485175289998592,0.000964228600689427,0.25,1.05659873309577E-5,0.000440899496234172,1.08444911294185E-5,305.0036316,305.0039063,77.793,77.928,53.455574430198,18.4728707366496,37.451283,0,0,0,80,4929,305.06905,77.8605,,,,,,,,,,,,,0,,,,4.9281311,,,,,,305.00376895,,,,
,22590452.14,305,115.9245,0.0005306708871502,2.99943809742314E-7,1,1.99850670813958,40.0298881530762,1.98144063062723,9.30000003427267,0.00583793433216054,0.0011645298792968,0.25,1.30917927893923E-5,0.000530565643700167,1.34268912692088E-5,304.9995422,305.0004578,115.902,115.947,52.9475158926979,18.4719608305026,37.832493,0,0,0,80,4929,305.05155,115.9245,,,,,,,,,,,,,0,,,,4.85634875,,,,,,305,,,,
,22590480.145,304.99591065,172.429,0.000654966033529901,2.5071467445753E-7,1,1.99850670813958,40.0298881530762,1.98123640378832,9.30000003427267,0.00720384397379228,0.00144148695542531,0.25,1.6551036687665E-5,0.000654835972221529,1.69645403201074E-5,304.9956665,304.9961548,172.349,172.509,52.7356945639863,18.4692522884548,37.832493,0,0,0,80,4929,305.05905,172.429,,,,,,,,,,,,,0,,,,4.85634875,,,,,,304.99591065,,,,
,22590507.32,304.9986725,256.286,0.00081462492326278,3.23148838432693E-7,1,1.99850670813958,40.0298881530762,1.98142173698591,9.30000003427267,0.00896005649733256,0.00179676148740708,0.25,2.09230059126664E-5,0.000814462877886614,2.14372211098576E-5,304.99823,304.999115,256.211,256.361,53.3469280660249,18.4707713678869,37.070068,0,0,0,80,4929,305.07,256.286,,,,,,,,,,,,,0,,,,4.62803555,,,,,,304.9986725,,,,
,22590534.11,304.9997406,380.6905,0.00102662045576068,3.10791355340889E-7,1,1.99850670813958,40.0298881530762,1.98129640463347,9.30000003427267,0.0112870489861149,0.00228754539843846,0.25,2.84803702518187E-5,0.00102641486054289,2.91280420107965E-5,304.9995728,304.9999084,380.688,380.693,52.7755576184671,18.4646639291646,37.451283,0,0,0,80,4929,305.0586,380.6905,,,,,,,,,,,,,0,,,,4.9776092,,,,,,304.9997406,,,,
,22590562.08,305.0001984,565.7245,0.00125933186243337,2.91780400655204E-7,1,1.99850670813958,40.0298881530762,1.98128118105813,9.30000003427267,0.0138463400889582,0.0028010159656724,0.25,3.44797440876827E-5,0.0012590799366774,3.5274308799259E-5,304.9996033,305.0007935,565.669,565.78,53.333640381198,18.4715620884662,37.070068,0,0,0,80,4929,305.05725,565.7245,,,,,,,,,,,,,0,,,,4.62526825,,,,,,305.0001984,,,,
,22590592.07,304.9972992,840.7105,0.00149379547412183,2.99211625294303E-7,1,1.99850670813958,40.0298881530762,1.98138417544758,9.30000003427267,0.0164268936619677,0.00331228580560807,0.25,3.99586278313907E-5,0.00149349737695974,4.09012722516053E-5,304.9972839,304.9973145,840.655,840.766,53.6501999314864,18.4663113806142,37.070068,0,0,0,80,4929,305.06165,840.7105,,,,,,,,,,,,,0,,,,4.95287015,,,,,,304.9972992,,,,
,22590624.045,304.99847415,1249.53,0.00170431940708687,3.91257878377118E-7,1,1.99850670813958,40.0298881530762,1.98137686970215,9.30000003427267,0.0187341423277971,0.00382370916147756,0.25,4.96296440588855E-5,0.00170397667492247,5.07043538519823E-5,304.9978943,304.999054,1249.506,1249.554,52.9357914649095,18.469531101976,38.213703,0,0,0,80,4929,305.06685,1249.53,,,,,,,,,,,,,0,,,,4.9281311,,,,,,304.99847415,,,,
,22590660,305.0005188,1856.848,0.0018730302223031,3.68116058147092E-7,1,1.99850670813958,40.0298881530762,1.9815685866638,9.30000003427267,0.0205904890233364,0.00420295156548444,0.25,5.45735563505175E-5,0.00187265343243229,5.57546067181754E-5,305.0003357,305.0007019,1856.799,1856.897,53.3688136645633,18.4764214170286,37.070068,0,0,0,80,4929,305.06595,1856.848,,,,,,,,,,,,,0,,,,4.9776092,,,,,,305.0005188,,,,
,22590701.025,304.99754335,2759.42,0.00199334448181525,4.61759835641218E-7,1,1.99850670813958,40.0298881530762,1.98163468563278,9.30000003427267,0.0219177864391295,0.00445029596242848,0.25,5.60178500512482E-5,0.001992944983985,5.72751031130826E-5,304.9973145,304.9977722,2759.405,2759.435,52.5942198020056,18.4770402190498,37.832493,0,0,0,80,4929,305.06085,2759.42,,,,,,,,,,,,,0,,,,4.9041274,,,,,,304.99754335,,,,
,22590750.07,304.996521,4101.0055,0.002088621026975,4.78845373476367E-7,1,1.99850670813958,40.0298881530762,1.98148395020888,9.30999964475632,0.0229620462511873,0.00467230310893025,0.25,5.95675840574249E-5,0.00208820196547455,6.0884605950616E-5,304.996521,304.996521,4100.984,4101.027,52.4105370999863,18.477668013741,37.832493,0,0,0,80,4929,305.0709,4101.0055,,,,,,,,,,,,,0,,,,4.95287015,,,,,,304.996521,,,,
,22590819.82,305.0023651,6094.1285,0.00216705768941599,7.03427208641908E-7,1,1.99850670813958,40.0298881530762,1.98128750146775,9.30999964475632,0.0238209128098068,0.00485412042307874,0.25,6.24215846874078E-5,0.0021666221362553,6.3787786572577E-5,305.0022278,305.0025024,6094.059,6094.198,52.7224068791594,18.4815618966235,37.451283,0,0,0,80,4929,305.0639,6094.1285,,,,,,,,,,,,,0,,,,4.87938835,,,,,,305.0023651,,,,
,22590911.775,305.00057985,9056.345,0.00223481499813003,1.1432309761549E-6,1,1.99850670813958,40.0298881530762,1.98137638690951,9.30999964475632,0.0245626946125838,0.00498583851944504,2.5,6.26738650709634E-5,0.00223436706567866,6.40827972355324E-5,305.0001221,305.0010376,9056.271,9056.419,53.1186925384095,18.4756580104476,37.832493,0,0,0,80,4929,305.0603,9056.345,,,,,,,,,,,,,0,,,,4.95287015,,,,,,305.00057985,,,,
,22591041.69,304.9993286,13458.471,0.00229996292489436,1.27907615590509E-6,1,1.99850670813958,40.0298881530762,1.98140747419157,9.30000003427267,0.0252802318619342,0.00512483017177139,2.5,6.39193065396445E-5,0.00229950246471878,6.53688424913391E-5,304.9986877,304.9999695,13458.423,13458.519,52.5457588338133,18.4766515262483,37.070068,0,0,0,80,4929,305.0687,13458.471,,,,,,,,,,,,,0,,,,4.9776092,,,,,,304.9993286,,,,
,22591205.555,305.00468445,20000.511,0.00237415289034052,1.85570762931634E-6,1,1.99850670813958,40.0298881530762,1.98146789116181,9.30999964475632,0.0260945035161452,0.00530152994135284,2.5,6.69989968440557E-5,0.00237367664630136,6.84943180324194E-5,305.0043945,305.0049744,19999.262,20001.76,52.6231400572171,18.4738417448671,37.832493,0,0,0,80,4929,305.05085,20000.511,,,,,,,,,,,,,0,,,,4.95287015,,,,,,305.00468445,,,,