File: DataFailid_Testimiseks/uued TEST failid/no1_TiO2withCuFeO3-Fe2O3after5recyclingcycles_05022024_2.txt
[Header]
; VSM Data File (default extension .dat)
; Copyright (c) 2003-2013, Quantum Design, Inc. All rights reserved.
TITLE,no1_TiO2withCuFeO3-Fe2O3after5recyclingcycles_05022024
FILEOPENTIME,14575754.19,02/05/2024,6:24 pm
BYAPP,VSM,2.0,2.0
INFO,PPMS VSM Option Release 1.4.10 Build 1,APPNAME
INFO,Quantum Design Linear Motor Servo Controller,MOTOR_MODULE_NAME
INFO,3101-100 C1,MOTOR_HW_VERSION
INFO,074,MOTOR_SERIAL_NUMBER
INFO,SRV No X-over 01.01.11,MOTOR_SOFTWARE_VERSION
INFO,Quantum Design VSM Detection Module,VSM_MODULE_NAME
INFO,3101-150 E1,VSM_HW_VERSION
INFO,VSM061,VSM_SERIAL_NUMBER
INFO,VSM No X-over 01.02.05 May 20 2008 13:51:47,VSM_SOFTWARE_VERSION
INFO,113,PREAMP_SERIAL_NUMBER
INFO,Quantum Design VSM Oven Module,OVEN_MODULE_NAME
INFO,unknown,OVEN_HW_VERSION
INFO,OVN054,OVEN_SERIAL_NUMBER
INFO,unknown,OVEN_SOFTWARE_VERSION
INFO,818,COIL_SERIAL_NUMBER
INFO,0,MOMENT_UNITS
INFO,no1_TiO2withCuFeO3-Fe2O3after5recyclingcycles_05022024,SAMPLE_MATERIAL
INFO,,SAMPLE_COMMENT
INFO,2.8 mg,SAMPLE_MASS
INFO,,SAMPLE_VOLUME
INFO,,SAMPLE_MOLECULAR_WEIGHT
INFO,,SAMPLE_SIZE
INFO,powder sample in plastic capusle,SAMPLE_SHAPE
DATATYPE,COMMENT,1
DATATYPE,TIME,2
STARTUPAXIS,X,2
STARTUPAXIS,Y1,5
[Data]
Comment,Time Stamp (sec),Temperature (K),Magnetic Field (Oe),Moment (emu),M. Std. Err. (emu),Transport Action,Averaging Time (sec),Frequency (Hz),Peak Amplitude (mm),Center Position (mm),Coil Signal' (mV),Coil Signal" (mV),Range (mV),M. Quad. Signal (emu),M. Raw' (emu),M. Raw" (emu),Min. Temperature (K),Max. Temperature (K),Min. Field (Oe),Max. Field (Oe),Mass (grams),Motor Lag (deg),Pressure (Torr),VSM Status (code),Motor Status (code),Measure Status (code),Measure Count,PPMS Status (code),System Temp. (K),System Field (Oe),Sample Position (deg),Bridge 1 Resistance (ohms),Bridge 1 Excitation (에),Bridge 2 Resistance (ohms),Bridge 2 Excitation (에),Bridge 3 Resistance (ohms),Bridge 3 Excitation (에),Bridge 4 Resistance (ohms),Bridge 4 Excitation (에),Signal 1 Vin (V),Signal 2 Vin (V),Digital Inputs (code),Drive 1 Iout (mA),Drive 1 Ipower (W),Drive 2 Iout (mA),Drive 2 Ipower (W),Pressure (),Map 20 (),Map 21 (),Map 22 (),Map 23 (),Map 24 (),Map 25 (),Map 26 (),Map 27 (),Map 28 (),Map 29 ()
,14577560.835,299.9974365,19998.9755,0.0220486622991856,2.2111588426411E-6,1,4.99626677034896,40.0298881530762,1.98218004395478,8.75999964773655,0.243669581469708,0.0422976161416992,2.5,-8.04739841076378E-6,0.0220479468055795,6.23181786200787E-6,299.9972839,299.9975891,19998.107,19999.844,52.1533813171594,18.4459189402784,27.920998,0,0,0,200,4929,300.0408,19998.9755,,,,,,,,,,,,,0,,,,5.39201115,,,,,,299.9974365,,,,
,14577955.54,299.99520875,141.5115,0.00378852305398407,3.9052573187644E-6,1,4.99626677034896,40.0298881530762,1.98210103330105,8.75999964773655,0.0418428439933367,0.00740668641302684,2.5,1.12065281868739E-5,0.00378839184861143,1.3663169484693E-5,299.9950867,299.9953308,141.466,141.557,52.7880636747748,18.4676038640867,27.920998,0,0,0,200,4929,300.07755,141.5115,,,,,,,,,,,,,0,,,,5.33841395,,,,,,299.99520875,,,,
,14578155.425,300.00215145,0.1855,-0.00650962642656474,1.35828512423852E-6,1,4.99626677034896,40.0298881530762,1.98224782805628,8.75999964773655,-0.0719688312851589,-0.0124680590845133,0.25,4.55255375000771E-6,-0.00650941505366733,3.30625492245182E-7,300.0014648,300.0028381,0.114,0.257,52.8951467819094,18.4625014820546,27.920998,0,0,0,200,4929,300.07695,0.1855,,,,,,,,,,,,,0,,,,5.4458747,,,,,,300.00215145,,,,
,14578345.275,299.9994965,-141.1105,-0.00884833291245488,1.41137009823658E-6,1,4.99626677034896,40.0298881530762,1.98253631130491,8.75999964773655,-0.09782723133662,-0.0170155585358708,0.25,2.41370021957544E-7,-0.00884804247823206,-5.49692928347548E-6,299.9992371,299.9997559,-141.116,-141.105,53.0694499416979,18.4649427677293,27.920998,0,0,0,200,4929,300.08655,-141.1105,,,,,,,,,,,,,0,,,,5.13544345,,,,,,299.9994965,,,,
,14578739.975,300.00500485,-19996.334,-0.022048773665483,2.13863650919629E-6,1,4.99626677034896,40.0298881530762,1.98245566170061,8.75999964773655,-0.243698172261462,-0.0423328127544132,2.5,5.39095624991106E-6,-0.0220480515151726,-8.88710483123657E-6,300.0045776,300.0054321,-19998.262,-19994.406,53.3992971768133,18.4640974423934,28.30221,0,0,0,200,4929,300.0611,-19996.334,,,,,,,,,,,,,0,,,,5.39201115,,,,,,300.00500485,,,,
,14579124.695,299.99882505,-141.6135,-0.00324495908074374,2.86183008577847E-6,1,4.99626677034896,40.0298881530762,1.98203804827077,8.75999964773655,-0.0358223676428278,-0.00643529204535528,2.5,-1.78777939049856E-5,-0.00324484096770003,-1.9981768699139E-5,299.9986877,299.9989624,-141.618,-141.609,52.9670566056787,18.4688967823961,27.920998,0,0,0,200,4929,300.0683,-141.6135,,,,,,,,,,,,,0,,,,5.41880845,,,,,,299.99882505,,,,
,14579319.53,299.9983368,0.025,0.00661642798086193,1.58802521748921E-6,1,4.99626677034896,40.0298881530762,1.98222976153912,8.75999964773655,0.0731420467438207,0.0127123160845236,0.25,-1.02622397730127E-6,0.00661621157059483,3.26482949656212E-6,299.9976196,299.999054,-0.005,0.055,53.0960253113518,18.4708586457438,25.63373,0,0,0,200,4929,300.0784,0.025,,,,,,,,,,,,,0,,,,5.3132069,,,,,,299.9983368,,,,
,14579509.4,299.9984894,141.0485,0.00896371522424008,1.55649392811088E-6,1,4.99626677034896,40.0298881530762,1.98226671881518,8.75999964773655,0.0990923136282632,0.0172217038026054,0.25,-1.46490263107805E-6,0.00896342204574521,4.34847658966517E-6,299.9977112,299.9992676,141.024,141.073,53.1077497391402,18.4688362065504,27.158575,0,0,0,200,4929,300.0773,141.0485,,,,,,,,,,,,,0,,,,5.4458747,,,,,,299.9984894,,,,
,14579919.095,300.006485,19998.757,0.0220713190949678,2.27553352999369E-6,1,4.99626677034896,40.0298881530762,1.98215073422769,8.75999964773655,0.243921202401613,0.0423131209276889,2.5,-1.05287775786574E-5,0.0220705985904138,3.76356718766023E-6,300.006012,300.006958,19997.225,20000.289,53.2570407863133,18.4644320973796,27.158575,0,0,0,200,4929,300.06965,19998.757,,,,,,,,,,,,,0,,,,5.26196765,,,,,,300.006485,,,,
,14586906.805,3.00783065,100.09,0.00525781042607611,1.64597956268751E-6,1,0.999253354069792,40.0298881530762,1.98185668932143,9.92999970912933,0.0576375179017706,0.0105639038377,2.5,3.92014005855969E-5,0.00522453855031866,5.05708637623691E-5,3.0058618,3.0097995,100.09,100.09,52.9396996075056,18.4449480529762,27.920998,0,0,0,40,4882,3.0061,100.09,,,,,,,,,,,,,0,,,,1.14060255,,,,,,3.00783065,,,,
,14586918.68,3.0388093,100.09,0.00525537349325323,1.67959381244143E-6,1,0.999253354069792,40.0298881530762,1.98184949930525,9.92999970912933,0.0576057989683654,0.0105863328291958,2.5,4.1675983383393E-5,0.00522211156352856,5.3024443993178E-5,3.0388093,3.0388093,100.09,100.09,52.6833254531979,18.4433879857251,27.920998,0,0,0,40,4886,3.0456,100.09,,,,,,,,,,,,,0,,,,1.181056,,,,,,3.0388093,,,,
,14586928.755,3.12572575,100.09,0.00524895144677981,1.89410340534575E-6,1,0.999253354069792,40.0298881530762,1.98135038326282,9.92999970912933,0.0575240936295123,0.0105560547752613,2.5,4.027770083052E-5,0.00521573322520534,5.16207984807136E-5,3.1195905,3.131861,100.09,100.09,52.6028177157171,18.4425725269829,27.920998,0,0,0,40,4886,3.134,100.09,,,,,,,,,,,,,0,,,,1.1929137,,,,,,3.12572575,,,,
,14586938.795,3.2287383,100.09,0.00524566034977815,2.00150891392535E-6,1,0.999253354069792,40.0298881530762,1.98196662759679,9.92999970912933,0.0575060810423299,0.0105475062195354,2.5,3.97897194024556E-5,0.0052124640682179,5.11286263464098E-5,3.2287383,3.2287383,100.09,100.09,53.4618274583518,18.4469069117991,27.539787,0,0,0,40,4886,3.2771,100.09,,,,,,,,,,,,,0,,,,1.2169875,,,,,,3.2287383,,,,
,14586947.445,3.353631,100.09,0.00525737554726713,2.17553636989351E-6,1,0.999253354069792,40.0298881530762,1.98185749583826,9.92999970912933,0.0576297639457671,0.0105801918188228,2.5,4.0761204492572E-5,0.00522410327067377,5.21198649469536E-5,3.3471138,3.3601482,100.09,100.09,53.0671050561402,18.4442663577996,27.158575,0,0,0,40,4886,3.4074,100.09,,,,,,,,,,,,,0,,,,1.22309675,,,,,,3.353631,,,,
,14586955.6,3.47763395,100.09,0.00525646853257219,1.69444996933362E-6,1,0.999253354069792,40.0298881530762,1.9815088532301,9.94000025093555,0.0576065477313831,0.010596771056364,2.5,4.259390002179E-5,0.00522319800573378,5.39389900777849E-5,3.4690123,3.4862556,100.09,100.09,52.5465404623325,18.4472688378518,27.158575,0,0,0,40,4886,3.5546,100.09,,,,,,,,,,,,,0,,,,1.2232188,,,,,,3.47763395,,,,
,14586964.9,3.64938375,100.09,0.00525960176367246,1.69428484488903E-6,1,0.999253354069792,40.0298881530762,1.9816540316861,9.92999970912933,0.0576471841196134,0.0105910514796368,2.5,4.14547169433395E-5,0.00522631405213185,5.28139204751199E-5,3.6386089,3.6601586,100.09,100.09,53.0264603731402,18.445430831612,27.920998,0,0,0,40,4886,3.7485,100.09,,,,,,,,,,,,,0,,,,1.2666023,,,,,,3.64938375,,,,
,14586974.32,3.8532605,100.09,0.00526221023251146,1.85497215961035E-6,1,0.999253354069792,40.0298881530762,1.98178824168858,9.92999970912933,0.0576810424838704,0.0105883432898016,2.5,4.06872415360755E-5,0.00522890779696241,5.20570527357905E-5,3.8532605,3.8532605,100.09,100.09,52.7849371606979,18.4434808857008,27.920998,0,0,0,40,4886,3.97105,100.09,,,,,,,,,,,,,0,,,,1.2793188,,,,,,3.8532605,,,,
,14586982.755,4.05043365,100.09,0.00526209466667015,1.5281556689449E-6,1,0.999253354069792,40.0298881530762,1.98171459453698,9.92999970912933,0.0576791195716321,0.0105797522747754,2.5,3.99592268142034E-5,0.00522879456591835,5.13333775246109E-5,4.0374179,4.0634494,100.09,100.09,52.7239701361979,18.4423362497125,27.920998,0,0,0,40,4886,4.18405,100.09,,,,,,,,,,,,,0,,,,1.22492805,,,,,,4.05043365,,,,
,14586992.155,4.3011689,100.09,0.00526486050623588,1.5027014082292E-6,1,0.999253354069792,40.0298881530762,1.98164933563133,9.92999970912933,0.0577067606568749,0.0105898256273268,2.5,4.04218662151732E-5,0.0052315418582487,5.1799207284976E-5,4.3011689,4.3011689,100.09,100.09,52.9115609808133,18.4477251978176,27.920998,0,0,0,40,4886,4.45695,100.09,,,,,,,,,,,,,0,,,,1.2793188,,,,,,4.3011689,,,,
,14587001.25,4.5356355,100.09,0.00525319541528942,1.64459840302037E-6,1,0.999253354069792,40.0298881530762,1.98173951892429,9.92999970912933,0.0575835875822852,0.0105544581716821,2.5,3.92057213204226E-5,0.00521995295001138,5.05649634022908E-5,4.5356355,4.5356355,100.09,100.09,52.0197228403709,18.4436691030087,27.920998,0,0,0,40,4886,4.6925,100.09,,,,,,,,,,,,,0,,,,1.3314749,,,,,,4.5356355,,,,
,14587012,4.5249505,100.09,0.00525730250126555,1.50690761474786E-6,1,0.999253354069792,40.0298881530762,1.98169737556557,9.92999970912933,0.0576261469690735,0.0105698111649325,2.5,3.99030072368443E-5,0.00522403258050682,5.12669228457225E-5,4.5249505,4.5249505,100.09,100.09,53.0280236301787,18.4440790991139,27.539787,0,0,0,40,4886,4.6483,100.09,,,,,,,,,,,,,0,,,,1.229206,,,,,,4.5249505,,,,
,14587022.85,4.51211505,100.09,0.00525491265485548,1.85275216554539E-6,1,0.999253354069792,40.0298881530762,1.9818019761939,9.92999970912933,0.057600769419599,0.0105775038615399,2.5,4.09746846543346E-5,0.00522165545845293,5.23265561424778E-5,4.5105062,4.5137239,100.09,100.09,52.8584102415056,18.4421877024235,27.920998,0,0,0,40,4886,4.67235,100.09,,,,,,,,,,,,,0,,,,1.1235121,,,,,,4.51211505,,,,
,14587034.905,4.6932559,100.09,0.00525629021041037,1.21167807631851E-6,1,0.999253354069792,40.0298881530762,1.98198474784895,9.92999970912933,0.0576278544997691,0.0105419925204062,2.5,3.74125594279399E-5,0.00522303205200803,4.87899558191004E-5,4.6932559,4.6932559,100.09,100.09,52.910779352294,18.4412994221627,27.539787,0,0,0,40,4886,4.76135,100.09,,,,,,,,,,,,,0,,,,1.069252,,,,,,4.6932559,,,,
,14587042.97,6.52159025,100.09,0.00525375228479443,1.7754730016977E-6,1,0.999253354069792,40.0298881530762,1.98165165168174,9.92999970912933,0.0575865622210379,0.0105587588016043,2.5,3.9541370701142E-5,0.00522050195586864,5.08996895187782E-5,6.4430256,6.6001549,100.09,100.09,52.544977205294,18.4497121564985,27.158575,0,0,0,40,4886,7.189,100.09,,,,,,,,,,,,,0,,,,1.1519392,,,,,,6.52159025,,,,
,14587052.345,7.6089916,100.09,0.00526029983569428,1.50385496850223E-6,1,0.999253354069792,40.0298881530762,1.98198198464651,9.92999970912933,0.0576629453708622,0.0105996138457694,2.5,4.19603051794973E-5,0.00522699895383403,5.33177820287296E-5,7.6089916,7.6089916,100.09,100.09,52.8545020989094,18.4332471541926,27.539787,0,0,0,40,4886,7.75795,100.09,,,,,,,,,,,,,0,,,,1.2793188,,,,,,7.6089916,,,,
,14587062,7.5800424,100.09,0.00525597347920773,1.35644240125958E-6,1,0.999253354069792,40.0298881530762,1.98171741777058,9.94000025093555,0.057610932705447,0.0105736316590452,2.5,4.04764563657435E-5,0.00522270330856957,5.18337430504775E-5,7.5800424,7.5800424,100.09,100.09,52.656750083544,18.4413607689037,27.158575,0,0,0,40,4886,7.6589,100.09,,,,,,,,,,,,,0,,,,1.3182398,,,,,,7.5800424,,,,
,14587073.115,8.170948,100.09,0.00525671851656945,1.45901377477801E-6,1,0.999253354069792,40.0298881530762,1.98189811571849,9.92999970912933,0.0576249603462867,0.0105712234251374,2.5,4.00424282482925E-5,0.00522344195332795,5.14040749966222E-5,8.170948,8.170948,100.09,100.09,51.7406814590055,18.4473078309308,27.920998,0,0,0,40,4886,8.4813,100.09,,,,,,,,,,,,,0,,,,1.3051363,,,,,,8.170948,,,,
,14587081.025,9.2164373,100.09,0.00525629965804224,1.6673723186551E-6,1,0.999253354069792,40.0298881530762,1.98186000207407,9.92999970912933,0.0576170363346337,0.0105827410547887,2.5,4.11840798416732E-5,0.00522301756681128,5.25375365369577E-5,9.2164373,9.2164373,100.09,100.09,52.829489986294,18.4396683426167,27.920998,0,0,0,40,4886,9.5593,100.09,,,,,,,,,,,,,0,,,,1.4422525,,,,,,9.2164373,,,,
,14587089.525,10.2203512,100.09,0.00524867946029225,1.87826185383763E-6,1,0.999253354069792,40.0298881530762,1.98189912361838,9.92999970912933,0.0575378852292864,0.0105484484484386,2.5,3.93809333934977E-5,0.00521544289854574,5.07288757723792E-5,10.2203512,10.2203512,100.09,100.09,52.9694014912364,18.4425262788162,27.920998,0,0,0,40,4882,10.4827,100.09,,,,,,,,,,,,,0,,,,1.4593502,,,,,,10.2203512,,,,
,14587099.79,11.1497574,100.09,0.00525491950049844,1.72399173542758E-6,1,0.999253354069792,40.0298881530762,1.98167071165946,9.92999970912933,0.0575982340521556,0.0105689526194145,2.5,4.02610547361379E-5,0.00522163448524992,5.16171553076516E-5,11.1497574,11.1497574,100.09,100.09,52.646588912794,18.4415712777948,27.920998,0,0,0,40,4886,11.45455,100.09,,,,,,,,,,,,,0,,,,1.6259372,,,,,,11.1497574,,,,
,14587108.35,11.9452548,100.09,0.00526311046073609,1.62426930504364E-6,1,0.999253354069792,40.0298881530762,1.98201513406664,9.92999970912933,0.0576975578298798,0.0105872016101335,2.5,4.03258964008324E-5,0.00522976670687356,5.16996170673871E-5,11.8946867,11.9958229,100.09,100.09,53.4000788053326,18.4480830012867,27.920998,0,0,0,40,4886,12.3138,100.09,,,,,,,,,,,,,0,,,,1.6670766,,,,,,11.9452548,,,,
,14587117.745,12.96993355,100.09,0.0052583479578227,1.94216144721241E-6,1,0.999253354069792,40.0298881530762,1.98181178578901,9.92999970912933,0.0576365162481698,0.0105939107292263,2.5,4.18701664245444E-5,0.00522502102761654,5.32235068594033E-5,12.9128199,13.0270472,100.09,100.09,51.6633002356016,18.4391267975021,27.920998,0,0,0,40,4886,13.36185,100.09,,,,,,,,,,,,,0,,,,1.6365462,,,,,,12.96993355,,,,
touchdown = 5.10000018402934 mm,14587153.935,16.506525,100.09,0.0052663014806108,1.75663179473168E-6,1,0.999253354069792,40.0298881530762,1.9925824861066,10.1699996739626,0.0580262041074509,0.0106537209548465,2.5,4.08893156903009E-5,0.00523288582017546,5.2272668699556E-5,16.506525,16.506525,100.09,100.09,52.1103917486017,18.4395014881272,27.920998,0,0,0,40,4886,17.01905,100.09,,,,,,,,,,,,,0,,,,1.9462451,,,,,,16.506525,,,,
,14587162.72,17.307209,100.09,0.00526583503626729,1.45269027634754E-6,1,0.999253354069792,40.0298881530762,1.99305828919676,10.1699996739626,0.0580335139051968,0.0106601823954833,2.5,4.12939358395151E-5,0.00523242441025291,5.27146167270643E-5,17.2673683,17.3470497,100.09,100.09,53.1796595629095,18.4415101398581,27.920998,0,0,0,40,4886,17.7743,100.09,,,,,,,,,,,,,0,,,,2.0357591,,,,,,17.307209,,,,
,14587172.555,18.142561,100.09,0.00526592767611137,1.62310872088855E-6,1,0.999253354069792,40.0298881530762,1.99281362058998,10.1699996739626,0.0580297620827239,0.0106489658622775,2.5,4.02674937075289E-5,0.00523254271039543,5.17974196808574E-5,18.0905457,18.1945763,100.09,100.09,52.6270481998133,18.4427990918702,28.30221,0,0,0,40,4886,18.8279,100.09,,,,,,,,,,,,,0,,,,2.09769335,,,,,,18.142561,,,,
,14587183.665,19.3343468,100.09,0.00527555687647624,1.96007493616822E-6,1,0.999253354069792,40.0298881530762,1.99279788877639,10.1699996739626,0.0581299847199379,0.0107027559071298,2.5,4.32532895315528E-5,0.00524215555442273,5.49807842491143E-5,19.3343468,19.3343468,100.09,100.09,53.0186440879479,18.4396332258175,27.920998,0,0,0,40,4886,20.08775,100.09,,,,,,,,,,,,,0,,,,2.1507175,,,,,,19.3343468,,,,
,14587193.775,20.31854915,100.09,0.00526914531572261,1.66166675828143E-6,1,0.999253354069792,40.0298881530762,1.99270870602693,10.1699996739626,0.0580604933361491,0.0106718345694415,2.5,4.14259938684203E-5,0.00523583901140539,5.33332224006527E-5,20.2600479,20.3770504,100.09,100.09,52.8810774685633,18.4421394105347,27.158575,0,0,0,40,4886,20.96255,100.09,,,,,,,,,,,,,0,,,,2.1511457,,,,,,20.31854915,,,,
,14587203.325,21.1967602,100.09,0.0052741094884783,1.80323152431823E-6,1,0.999253354069792,40.0298881530762,1.99292172067653,10.1699996739626,0.0581212841240117,0.0106871488332351,2.5,4.15861173192192E-5,0.00524084653608898,5.37454218259269E-5,21.1967602,21.1967602,100.09,100.09,53.0788294839287,18.4380777055767,28.30221,0,0,0,40,4886,21.90315,100.09,,,,,,,,,,,,,0,,,,2.22727405,,,,,,21.1967602,,,,
,14587213.18,22.1314754,100.09,0.0052744162338715,1.90137726384749E-6,1,0.999253354069792,40.0298881530762,1.99257217189114,10.1699996739626,0.0581153819769396,0.0106913259881266,2.5,4.16826059933497E-5,0.00524127560356363,5.42089455945494E-5,22.1314754,22.1314754,100.09,100.09,52.3151784206402,18.4432932510764,27.920998,0,0,0,40,4886,23.0728,100.09,,,,,,,,,,,,,0,,,,2.2835715,,,,,,22.1314754,,,,
,14587223.22,23.256773,100.09,0.00528136913733152,1.87132752507479E-6,1,0.999253354069792,40.0298881530762,1.99278026445555,10.1699996739626,0.0581990771809634,0.0107081071458375,2.5,4.1468323702538E-5,0.00524831920290289,5.44025280266101E-5,23.256773,23.256773,100.09,100.09,52.9623668345633,18.4439643731326,26.777365,0,0,0,40,4886,24.1125,100.09,,,,,,,,,,,,,0,,,,2.3064983,,,,,,23.256773,,,,
,14587233.45,24.1785851,100.09,0.00528422594070619,1.78662724005515E-6,1,0.999253354069792,40.0298881530762,1.9925989385643,10.1699996739626,0.0582292127069665,0.0107013070997015,2.5,4.00081271754509E-5,0.00525130805158037,5.33565212046313E-5,24.1785851,24.1785851,100.09,100.09,52.0689654370824,18.4385253454956,27.539787,0,0,0,40,4886,25.0383,100.09,,,,,,,,,,,,,0,,,,2.3413502,,,,,,24.1785851,,,,
,14587257.97,26.5427265,100.09,,,2,,,,10.2029998706579,,,,,,,26.5427265,26.5427265,100.09,100.09,,,27.920998,,,,-99999999,4886,27.6155,100.09,,,,,,,,,,,,,,,,,,,,,,,26.5427265,,,,
,14587280.59,28.7224865,100.09,0.00529742916849147,1.92114604562343E-6,1,0.999253354069792,40.0298881530762,1.99267648965661,10.1899998262525,0.0583846065074009,0.0107698948880813,2.5,4.06832557290537E-5,0.00526573174655255,5.69953728308974E-5,28.6639919,28.7809811,100.09,100.09,52.8646632696594,18.4449739691714,27.158575,0,0,0,40,4886,29.96705,100.09,,,,,,,,,,,,,0,,,,2.36721755,,,,,,28.7224865,,,,
,14587291.43,29.7031727,100.09,0.00529402741357173,1.60608201450184E-6,1,0.999253354069792,40.0298881530762,1.99272418823008,10.1899998262525,0.0583502791349784,0.0107818410135707,2.5,4.14219419458272E-5,0.00526279177210218,5.85579808230746E-5,29.7031727,29.7031727,100.09,100.09,52.4214798992556,18.4387175113203,27.920998,0,0,0,40,4886,31.0739,100.09,,,,,,,,,,,,,0,,,,2.5744064,,,,,,29.7031727,,,,
,14587302.47,30.8525372,100.09,0.00530552005316826,1.7469957636326E-6,1,0.999253354069792,40.0298881530762,1.9926786362069,10.1899998262525,0.0584824548136046,0.0108025304367567,2.5,4.02149483025328E-5,0.00527477218715903,5.83655995063778E-5,30.8525372,30.8525372,100.09,100.09,53.2781447563326,18.4446065109778,27.920998,0,0,0,40,4886,32.2629,100.09,,,,,,,,,,,,,0,,,,2.4549655,,,,,,30.8525372,,,,
,14587313.985,31.92282965,100.09,0.00530403390641122,1.82603255190929E-6,1,0.999253354069792,40.0298881530762,1.9929193912338,10.1899998262525,0.0584764365692666,0.0108217941070313,2.5,4.09666773825241E-5,0.00527392692340824,6.01333589067186E-5,31.8538342,31.9918251,100.09,100.09,52.555138376044,18.4517962556879,27.920998,0,0,0,40,4886,33.44395,100.09,,,,,,,,,,,,,0,,,,2.6527278,,,,,,31.92282965,,,,
,14587325.365,32.9996719,100.09,0.00530848839585218,1.95957760224643E-6,1,0.999253354069792,40.0298881530762,1.99287509545596,10.1899998262525,0.0585280832451867,0.0108547333329977,2.5,4.20123522665509E-5,0.00527905147924103,6.22310088915155E-5,32.9996719,32.9996719,100.09,100.09,53.1233823095249,18.4404827503994,27.920998,0,0,0,40,4886,34.583,100.09,,,,,,,,,,,,,0,,,,2.7062616,,,,,,32.9996719,,,,
,14587337.26,34.1734467,100.09,0.00531326596771974,1.57619609047742E-6,1,0.999253354069792,40.0298881530762,1.99285018712715,10.1899998262525,0.0585906472914545,0.0108625578787492,2.5,4.05096175816595E-5,0.00528470067861349,6.19680594181943E-5,34.1734467,34.1734467,100.09,100.09,52.3300293625055,18.4352354939189,27.158575,0,0,0,40,4886,35.8549,100.09,,,,,,,,,,,,,0,,,,2.78873395,,,,,,34.1734467,,,,
,14587348.33,35.1469536,100.09,0.00531048156903323,1.89511553231934E-6,1,0.999253354069792,40.0298881530762,1.99266535241617,10.1899998262525,0.0585626330799791,0.0108710695478125,2.5,4.05591422136997E-5,0.00528285131196472,6.31417548703562E-5,35.1469536,35.1469536,100.09,100.09,52.4183533851786,18.4453463527002,27.920998,0,0,0,40,4886,37.0112,100.09,,,,,,,,,,,,,0,,,,2.8734326,,,,,,35.1469536,,,,
,14587360.135,36.3000031,100.09,0.00531510675224053,2.36239635461482E-6,1,0.999253354069792,40.0298881530762,1.99285395941388,10.1899998262525,0.0586266774821497,0.0109082255203007,2.5,4.1595236053751E-5,0.00528853132863198,6.54131594961547E-5,36.3000031,36.3000031,100.09,100.09,52.9873789471787,18.4433516812967,28.30221,0,0,0,40,4886,38.23185,100.09,,,,,,,,,,,,,0,,,,2.8734326,,,,,,36.3000031,,,,
,14587396.835,39.8256302,100.09,0.00532171993718702,1.77667274006358E-6,1,0.999253354069792,40.0298881530762,1.98177365615662,10.2000003680587,0.0584292494649192,0.0108943206866269,2.5,3.98892809356047E-5,0.00529933921367599,6.75482591727648E-5,39.8256302,39.8256302,100.09,100.09,52.3331558765825,18.4395688242263,28.30221,0,0,0,40,4886,42.07865,100.09,,,,,,,,,,,,,0,,,,2.8104284,,,,,,39.8256302,,,,
,14587407.535,40.762146,100.09,0.00532487505465637,1.48650350164395E-6,1,0.999253354069792,40.0298881530762,1.98175124166416,10.1899998262525,0.0584787642933209,0.0109074441238212,2.5,3.92279505806219E-5,0.00530394687047974,6.79481153845841E-5,40.762146,40.762146,100.09,100.09,52.6270481998133,18.4434543426353,27.920998,0,0,0,40,4886,43.20455,100.09,,,,,,,,,,,,,0,,,,3.0509303,,,,,,40.762146,,,,
,14587418.83,41.8491287,100.09,0.00533034701566246,1.3319345666479E-6,1,0.999253354069792,40.0298881530762,1.98178462797916,10.1899998262525,0.0585559235141819,0.0109338235104916,2.5,3.93004641946014E-5,0.00531104174626425,6.90898741690373E-5,41.8491287,41.8491287,100.09,100.09,52.6333012279671,18.4444421701043,27.539787,0,0,0,40,4886,44.39595,100.09,,,,,,,,,,,,,0,,,,3.0815613,,,,,,41.8491287,,,,
,14587428.905,42.8034096,100.09,0.00532895601941095,1.77750480381443E-6,1,0.999253354069792,40.0298881530762,1.98196669932918,10.2000003680587,0.0585644080422149,0.0109248052455056,2.5,3.75305825518397E-5,0.00531118151574672,6.81623631235988E-5,42.8034096,42.8034096,100.09,100.09,52.3839617303325,18.443220751291,27.920998,0,0,0,40,4886,45.4392,100.09,,,,,,,,,,,,,0,,,,3.09703065,,,,,,42.8034096,,,,
,14587439.95,43.8748913,100.09,0.0053329433328347,1.83255637914829E-6,1,0.999253354069792,40.0298881530762,1.98197931722313,10.1899998262525,0.0586238381665289,0.0109603971267449,2.5,3.88762038306622E-5,0.00531691178933132,7.03839101305491E-5,43.8290215,43.9207611,100.09,100.09,53.1523025647364,18.4447174934895,27.920998,0,0,0,40,4886,46.6026,100.09,,,,,,,,,,,,,0,,,,3.1125,,,,,,43.8748913,,,,
,14587449.94,44.7734852,100.09,0.00534772776070415,1.03497429789673E-6,1,0.999253354069792,40.0298881530762,1.98147195705286,10.1899998262525,0.0587874577219927,0.0110066946480333,2.5,3.96950371876565E-5,0.00533330089594528,7.19778817643534E-5,44.7113724,44.835598,100.09,100.09,52.8060411307171,18.4484822884203,27.158575,0,0,0,40,4886,47.65205,100.09,,,,,,,,,,,,,0,,,,3.1753123,,,,,,44.7734852,,,,
,14587461.11,45.83574865,100.09,0.00532889799654441,1.63803049255826E-6,1,0.999253354069792,40.0298881530762,1.9819839620654,10.1899998262525,0.0586195980673047,0.0109543603094271,2.5,3.70753776615042E-5,0.00531643543824999,6.99179741419889E-5,45.7782669,45.8932304,100.09,100.09,52.2862581654286,18.4460023027853,27.920998,0,0,0,40,4886,48.8322,100.09,,,,,,,,,,,,,0,,,,3.1754707,,,,,,45.83574865,,,,
,14587471.155,46.7219353,100.09,0.00532933438032479,1.6837101571508E-6,1,0.999253354069792,40.0298881530762,1.98178505837338,10.1899998262525,0.0586338325738444,0.0109815479871545,2.5,3.87524344966336E-5,0.00531861214196385,7.20966244975751E-5,46.7219353,46.7219353,100.09,100.09,52.707555937294,18.4438803381304,27.539787,0,0,0,40,4886,49.9003,100.09,,,,,,,,,,,,,0,,,,3.1753123,,,,,,46.7219353,,,,
,14587482.28,47.7693214,100.09,0.00533074981805803,1.46504793748201E-6,1,0.999253354069792,40.0298881530762,1.98174091089645,10.1899998262525,0.0586694068056701,0.01098778959992,2.5,3.83170800782782E-5,0.00532194642604579,7.21049122444119E-5,47.7693214,47.7693214,100.09,100.09,52.0079984125824,18.4431143387936,28.30221,0,0,0,40,4886,51.062,100.09,,,,,,,,,,,,,0,,,,3.2071922,,,,,,47.7693214,,,,
,14587520.235,51.317215,100.09,0.0053499612935307,1.91726852275403E-6,1,0.999253354069792,40.0298881530762,2.00646058550892,10.2000003680587,0.0596577328348139,0.0111784492232873,2.5,3.84214959529755E-5,0.00534773763700188,7.29361849947494E-5,51.317215,51.317215,100.09,100.09,51.8594889939286,18.4485699414689,28.30221,0,0,0,40,4886,55.098,100.09,,,,,,,,,,,,,0,,,,3.3714576,,,,,,51.317215,,,,
,14587530.75,52.2858047,100.09,0.00533855601427311,1.79324866097483E-6,1,0.999253354069792,40.0298881530762,2.0066558422303,10.2000003680587,0.0595588233376108,0.0111422004219796,2.5,3.68948922424711E-5,0.00533810725052028,7.12705380276308E-5,52.2858047,52.2858047,100.09,100.09,53.1859125910633,18.4489975478047,27.920998,0,0,0,40,4886,56.22235,100.09,,,,,,,,,,,,,0,,,,2.8734326,,,,,,52.2858047,,,,
,14587541.78,53.35206225,100.09,0.00534855304410955,1.49442615492781E-6,1,0.999253354069792,40.0298881530762,2.00647791518289,10.2000003680587,0.059684555923456,0.0111689516498125,2.5,3.74318048504739E-5,0.00534987929166679,7.1707431167813E-5,53.2884827,53.4156418,100.09,100.09,53.1421413939864,18.4443086523972,27.158575,0,0,0,40,4886,57.3944,100.09,,,,,,,,,,,,,0,,,,3.3062494,,,,,,53.35206225,,,,
,14587553.095,54.3811035,100.09,0.00535584052384849,1.41218426661297E-6,1,0.999253354069792,40.0298881530762,2.00643684817151,10.2000003680587,0.059785856689337,0.0111794241219974,2.5,3.70332888981766E-5,0.00535893688632035,7.10939261018504E-5,54.3811035,54.3811035,100.09,100.09,52.8826407256018,18.4499372362605,27.920998,0,0,0,40,4886,58.59975,100.09,,,,,,,,,,,,,0,,,,3.3047652,,,,,,54.3811035,,,,
,14587563.885,55.4349518,100.09,0.00535039684089666,1.76647708419903E-6,1,0.999253354069792,40.0298881530762,2.00650590069811,10.2000003680587,0.0597453997123428,0.0111676672144023,2.5,3.69745603856899E-5,0.0053550709070288,7.06795451334701E-5,55.3890419,55.4808617,100.09,100.09,53.5149781976595,18.4489313197497,27.539787,0,0,0,40,4886,59.7319,100.09,,,,,,,,,,,,,0,,,,3.4394958,,,,,,55.4349518,,,,
,14587574.275,56.3958912,100.09,0.00535852238165622,1.43098754310449E-6,1,0.999253354069792,40.0298881530762,2.00661575349471,10.2000003680587,0.0598571983372387,0.0111815667361849,2.5,3.68260982563126E-5,0.00536470497710315,7.02005633853886E-5,56.3326035,56.4591789,100.09,100.09,52.8873304967171,18.4492663870825,27.920998,0,0,0,40,4886,60.85325,100.09,,,,,,,,,,,,,0,,,,3.4394958,,,,,,56.3958912,,,,
,14587586.36,57.51021005,100.09,0.005341564760188,1.80475750943465E-6,1,0.999253354069792,40.0298881530762,2.00651265558857,10.2000003680587,0.0596797218122279,0.0111632424684862,2.5,3.84960850878729E-5,0.00534928498134291,7.12833073613898E-5,57.4580841,57.562336,100.09,100.09,53.3774115782749,18.4447116180578,27.920998,0,0,0,40,4886,62.0966,100.09,,,,,,,,,,,,,0,,,,3.4054767,,,,,,57.51021005,,,,
,14587596.765,58.50120925,100.09,0.00536174495911362,2.02477709952767E-6,1,0.999253354069792,40.0298881530762,2.00639360351365,10.2000003680587,0.0599202600342169,0.0111900008810305,2.5,3.75807031848162E-5,0.00537087608087047,6.9991459200188E-5,58.4591789,58.5432396,100.09,100.09,52.5105855504479,18.4394669200942,27.920998,0,0,0,40,4886,63.24705,100.09,,,,,,,,,,,,,0,,,,3.43966725,,,,,,58.50120925,,,,
,14587607.35,59.4201164,100.09,0.00536837933488145,2.13281695303544E-6,1,0.999253354069792,40.0298881530762,2.00637691657492,10.2000003680587,0.0600078086705713,0.0112049063171894,2.5,3.80234044042107E-5,0.00537874451164813,6.99688964945546E-5,59.4201164,59.4201164,100.09,100.09,53.3469280660249,18.4485936545697,27.920998,0,0,0,40,4886,64.33155,100.09,,,,,,,,,,,,,0,,,,3.45710685,,,,,,59.4201164,,,,
,14587645.32,63.0461006,100.09,0.00536887015207978,1.80116947380896E-6,1,0.999253354069792,40.0298881530762,2.006610781559,10.219999589026,0.0600723845927132,0.0111663375086734,2.5,3.57688986669114E-5,0.00538316996222419,6.56412220005187E-5,63.0461006,63.0461006,100.09,100.09,52.8685714122556,18.4407290363849,27.920998,0,0,0,40,4886,68.3501,100.09,,,,,,,,,,,,,0,,,,3.5089071,,,,,,63.0461006,,,,
,14587656.22,64.010437,100.09,0.00535797982516064,1.95095982657193E-6,1,0.999253354069792,40.0298881530762,2.0062370963836,10.219999589026,0.0599545534584815,0.011121465556912,2.5,3.43485305060492E-5,0.00537322384786055,6.3529719432415E-5,64.010437,64.010437,100.09,100.09,52.3792719592171,18.4484794103469,27.158575,0,0,0,40,4886,69.5084,100.09,,,,,,,,,,,,,0,,,,3.5797191,,,,,,64.010437,,,,
,14587667.605,65.0861664,100.09,0.00537305130450847,1.65524737698267E-6,1,0.999253354069792,40.0298881530762,2.00659968971623,10.219999589026,0.0601421805564978,0.0111662776569597,2.5,3.59748921991833E-5,0.00538925692412182,6.45863177856752E-5,65.0861664,65.0861664,100.09,100.09,52.8349613859287,18.4430826077533,27.920998,0,0,0,40,4886,70.7097,100.09,,,,,,,,,,,,,0,,,,3.5797191,,,,,,65.0861664,,,,
,14587678.725,66.13690185,100.09,0.00537173654257048,1.49145297156683E-6,1,0.999253354069792,40.0298881530762,2.00656995240214,10.219999589026,0.0601394067422396,0.0111460997769334,2.5,3.49228988990539E-5,0.00538878903833274,6.28771917426E-5,66.0714493,66.2023544,100.09,100.09,52.9733096338325,18.444183897523,27.920998,0,0,0,40,4886,71.8938,100.09,,,,,,,,,,,,,0,,,,3.52652155,,,,,,66.13690185,,,,
,14587689.475,67.1580811,100.09,0.00535577260760223,1.71834484535262E-6,1,0.999253354069792,40.0298881530762,2.00663729320386,10.219999589026,0.0599718663674909,0.011110337268789,2.5,3.50441049752319E-5,0.00537353298260767,6.22910325690009E-5,67.1580811,67.1580811,100.09,100.09,52.0564593807747,18.4431712563195,27.920998,0,0,0,40,4886,73.0475,100.09,,,,,,,,,,,,,0,,,,3.56192755,,,,,,67.1580811,,,,
,14587699.615,68.089798,100.09,0.00535893280227914,2.17092382795632E-6,1,0.999253354069792,40.0298881530762,2.00664653177141,10.219999589026,0.0600170115996532,0.0111062831239355,2.5,3.45782222570415E-5,0.005377367505793,6.12596248159484E-5,68.089798,68.089798,100.09,100.09,52.8466858137171,18.4467054815978,27.158575,0,0,0,40,4886,74.12765,100.09,,,,,,,,,,,,,0,,,,3.59804805,,,,,,68.089798,,,,
,14587711.075,69.0980606,100.09,0.00537053909423942,2.26996814148858E-6,1,0.999253354069792,40.0298881530762,2.00667988631345,10.219999589026,0.0601555602178247,0.011132062902681,2.5,3.53111838431252E-5,0.00538969741275762,6.14123088460946E-5,69.0980606,69.0980606,100.09,100.09,52.5309078919479,18.4481836567521,27.920998,0,0,0,40,4886,75.3342,100.09,,,,,,,,,,,,,0,,,,3.3001614,,,,,,69.0980606,,,,
,14587722.065,70.2400894,100.09,0.00536574383330432,2.09371782690321E-6,1,0.999253354069792,40.0298881530762,2.00641623996797,10.219999589026,0.0601038725482966,0.0111048619730732,2.5,3.43599911401511E-5,0.005385478823558,5.98360642181783E-5,70.2400894,70.2400894,100.09,100.09,52.8099492733133,18.4438697304661,27.920998,0,0,0,40,4886,76.4821,100.09,,,,,,,,,,,,,0,,,,3.46193775,,,,,,70.2400894,,,,
touchdown = 5.14000002294779 mm,14587760.09,73.725235,100.09,0.0053638984521993,1.83316847986013E-6,1,0.999253354069792,40.0298881530762,1.98160479604264,10.2099999785423,0.059397206832015,0.0109313989483318,2.5,3.26077188361286E-5,0.00538538686987904,5.60730084697778E-5,73.725235,73.725235,100.09,100.09,52.575460717544,18.4410750154381,27.920998,0,0,0,40,4886,80.50105,100.09,,,,,,,,,,,,,0,,,,3.5804336,,,,,,73.725235,,,,
,14587776.45,75.2874184,100.09,0.00537815682654026,1.41617280436863E-6,1,0.999253354069792,40.0298881530762,1.98185029263601,10.2099999785423,0.0595750745895734,0.0109289681127628,2.5,3.04527471256559E-5,0.00540033604504597,5.31447895058432E-5,75.2255936,75.3492432,100.09,100.09,52.687233595794,18.4387392789684,27.920998,0,0,0,40,4886,82.27155,100.09,,,,,,,,,,,,,0,,,,3.6012801,,,,,,75.2874184,,,,
,14587793.08,76.8563309,100.09,0.00537924704960867,1.40412919918275E-6,1,0.999253354069792,40.0298881530762,1.98182238877635,10.2099999785423,0.0595912236708095,0.0109378218702566,2.5,3.1754449509149E-5,0.00540196261635892,5.36774926855796E-5,76.8563309,76.8563309,100.09,100.09,52.9725280053133,18.4420726483507,27.920998,0,0,0,40,4886,84.01465,100.09,,,,,,,,,,,,,0,,,,3.6886253,,,,,,76.8563309,,,,
,14587809.565,78.435936,100.09,0.00536407411928552,2.04055922209216E-6,1,0.999253354069792,40.0298881530762,1.98191088668937,10.2099999785423,0.0594327945876872,0.010897251345017,2.5,3.14047402497416E-5,0.00538719511468597,5.25229608867579E-5,78.435936,78.435936,100.09,100.09,53.1421413939864,18.4348948775978,27.920998,0,0,0,40,4886,85.7572,100.09,,,,,,,,,,,,,0,,,,3.70751225,,,,,,78.435936,,,,
,14587825.875,79.9738007,100.09,0.00537867899414336,1.43209420151834E-6,1,0.999253354069792,40.0298881530762,1.98179692362585,10.2099999785423,0.0595995566933224,0.0109055615458355,2.5,3.02410874429809E-5,0.0054022701871362,5.07169916213897E-5,79.9738007,79.9738007,100.09,100.09,52.677072425044,18.4419239730147,28.30221,0,0,0,40,4886,87.4616,100.09,,,,,,,,,,,,,0,,,,3.562994,,,,,,79.9738007,,,,
,14587842.89,81.522934,100.09,0.00536808246387112,1.56195875704692E-6,1,0.999253354069792,40.0298881530762,1.98185959803541,10.2099999785423,0.0594901247031741,0.0108729755386152,2.5,2.9770876935069E-5,0.00539199603223826,4.9518700892004E-5,81.522934,81.522934,100.09,100.09,52.5879667738517,18.4425313341859,27.920998,0,0,0,40,4886,89.2323,100.09,,,,,,,,,,,,,0,,,,3.62215605,,,,,,81.522934,,,,
,14587887.49,85.6016464,100.09,0.00538829674489255,1.35351094574075E-6,1,0.999253354069792,40.0298881530762,2.00657387738273,10.1899998262525,0.0604361183045461,0.0110214666116389,2.5,2.88089649211515E-5,0.00541266329109718,4.75928932379205E-5,85.6016464,85.6016464,100.09,100.09,52.9162507519287,18.44113064349,28.30221,0,0,0,40,4886,92.06615,100.09,,,,,,,,,,,,,0,,,,3.8199253,,,,,,85.6016464,,,,
,14587904.735,86.97527695,100.09,0.00537939857808807,1.81065174260258E-6,1,0.999253354069792,40.0298881530762,2.00656795874802,10.1899998262525,0.0603354505050467,0.0109944104782448,2.5,2.78840174441389E-5,0.00540353188486197,4.67586390960957E-5,86.9276657,87.0228882,100.09,100.09,52.758361791044,18.4449169438352,27.158575,0,0,0,40,4886,91.7045,100.09,,,,,,,,,,,,,0,,,,3.6536002,,,,,,86.97527695,,,,
,14587921.19,87.7798615,100.09,0.00538266388703053,1.33066615461286E-6,1,0.999253354069792,40.0298881530762,2.00619778066452,10.1899998262525,0.0603601197831052,0.0109893292373593,2.5,2.67759966229206E-5,0.00540655252160863,4.59544770083336E-5,87.7798615,87.7798615,100.09,100.09,52.8255818436979,18.4508584485421,28.30221,0,0,0,40,4886,90.86885,100.09,,,,,,,,,,,,,0,,,,3.8775487,,,,,,87.7798615,,,,
,14587937.71,88.5523987,100.09,0.00538580077848614,1.5564790294797E-6,1,0.999253354069792,40.0298881530762,2.00654612206713,10.1899998262525,0.0604273887286792,0.0109742209446181,2.5,2.71489341844056E-5,0.0054112663109781,4.36231067509101E-5,88.5523987,88.5523987,100.09,100.09,52.677072425044,18.4487383594733,27.920998,0,0,0,40,4886,99.35115,100.09,,,,,,,,,,,,,0,,,,3.8008451,,,,,,88.5523987,,,,
,14587948.93,89.8912201,100.09,0.0053779284528146,1.87218848457797E-6,1,0.999253354069792,40.0298881530762,2.00656220860139,10.1899998262525,0.0603415758104121,0.0109629105113766,2.5,2.81736944560648E-5,0.00540360458228647,4.39318832821046E-5,89.8912201,89.8912201,100.09,100.09,53.0170808309095,18.4497280133726,26.014942,0,0,0,40,4886,101.9073,100.09,,,,,,,,,,,,,0,,,,3.8777423,,,,,,89.8912201,,,,
,14587960.065,91.4090042,100.09,0.00537559212981162,1.59390152237346E-6,1,0.999253354069792,40.0298881530762,2.00648469640479,10.2000003680587,0.0603138003229431,0.0109484365507358,2.5,2.74415801482325E-5,0.00540117528799103,4.30947733448006E-5,91.4090042,91.4090042,100.09,100.09,52.5621730327171,18.4465783314019,27.539787,0,0,0,40,4886,102.2659,100.09,,,,,,,,,,,,,0,,,,3.8008451,,,,,,91.4090042,,,,
,14587970.39,92.6501389,100.09,0.00537965461230219,1.97918611745003E-6,1,0.999253354069792,40.0298881530762,2.0065244684423,10.1899998262525,0.0603623913893293,0.0109445327636969,2.5,2.65268745451105E-5,0.00540523261160383,4.20239726289938E-5,92.6501389,92.6501389,100.09,100.09,52.0947591782171,18.4491437865051,27.920998,0,0,0,40,4886,102.8968,100.09,,,,,,,,,,,,,0,,,,3.9164791,,,,,,92.6501389,,,,
,14587980.205,93.8151627,100.09,0.00537412020344748,1.40120949428276E-6,1,0.999253354069792,40.0298881530762,2.00638432878763,10.2000003680587,0.0602966974629103,0.0109302652496421,2.5,2.65124171644574E-5,0.005399675734406,4.17764612254763E-5,93.8151627,93.8151627,100.09,100.09,53.3140996682172,18.4467753764797,27.920998,0,0,0,40,4886,103.755,100.09,,,,,,,,,,,,,0,,,,3.8775487,,,,,,93.8151627,,,,
,14588017.375,97.6823807,100.09,0.00537904606813252,1.2994092321825E-6,1,0.999253354069792,40.0298881530762,1.99267774075269,10.1800002157688,0.0599565767120151,0.0108722351194647,2.5,2.76769713202852E-5,0.00540466336544455,4.21314510200346E-5,97.6823807,97.6823807,100.09,100.09,53.239063330371,18.4428066726313,27.158575,0,0,0,40,4886,107.2334,100.09,,,,,,,,,,,,,0,,,,3.8390055,,,,,,97.6823807,,,,
,14588026.955,98.6096802,100.09,0.00536390620820384,2.02720996866116E-6,1,0.999253354069792,40.0298881530762,1.99282671859629,10.1800002157688,0.0597950611079193,0.0108267714713002,2.5,2.64219001911283E-5,0.00538947249388914,4.06013869234026E-5,98.5613556,98.6580048,100.09,100.09,53.6251878188711,18.4424115692369,27.920998,0,0,0,40,4886,108.2586,100.09,,,,,,,,,,,,,0,,,,3.9955161,,,,,,98.6096802,,,,
,14588036.615,99.5234375,100.09,0.00537723491650762,1.96540227349348E-6,1,0.999253354069792,40.0298881530762,1.99287689264502,10.1899998262525,0.0599477545608132,0.0108396863343929,2.5,2.54305392962025E-5,0.00540288156071701,3.94166357987433E-5,99.4573746,99.5895004,100.09,100.09,52.2229462553709,18.4456427542596,27.920998,0,0,0,40,4886,109.287,100.09,,,,,,,,,,,,,0,,,,3.9172608,,,,,,99.5234375,,,,
,14588046.91,100.5006638,100.09,0.00537557432981715,1.88786318988334E-6,1,0.999253354069792,40.0298881530762,1.9927722101435,10.1800002157688,0.0599263028818319,0.0108360476771935,2.5,2.56798261386375E-5,0.00540122390800954,3.94255085910071E-5,100.5006638,100.5006638,100.09,100.09,52.5395058056594,18.4428041323926,27.158575,0,0,0,40,4886,110.4116,100.09,,,,,,,,,,,,,0,,,,4.0356307,,,,,,100.5006638,,,,
,14588057.25,101.5088654,100.09,0.00536689579461544,1.62427867120238E-6,1,0.999253354069792,40.0298881530762,1.99309110499564,10.1800002157688,0.0598370102458278,0.0108300045295223,2.5,2.67385391949017E-5,0.00539250135534495,4.02435152465344E-5,101.5088654,101.5088654,100.09,100.09,52.5324711489863,18.441587515755,28.30221,0,0,0,40,4886,111.50595,100.09,,,,,,,,,,,,,0,,,,4.0155734,,,,,,101.5088654,,,,
,14588066.895,102.4791565,100.09,0.00537311647893865,1.9040165023513E-6,1,0.999253354069792,40.0298881530762,1.99277656021167,10.1800002157688,0.0598984029374472,0.0108341783028282,2.5,2.63710679362015E-5,0.0053987460467967,3.96845918488263E-5,102.4791565,102.4791565,100.09,100.09,52.7779025040248,18.4419223932253,27.920998,0,0,0,40,4886,112.5373,100.09,,,,,,,,,,,,,0,,,,3.8775487,,,,,,102.4791565,,,,
,14588077.845,103.56121445,100.09,0.00537971003662055,1.93490466763323E-6,1,0.999253354069792,40.0298881530762,1.99274988276378,10.1800002157688,0.059972984637628,0.0108359833151254,2.5,2.56109509848223E-5,0.00540536065085536,3.87133193760248E-5,103.4944916,103.6279373,100.09,100.09,52.9248486656402,18.4472383606625,27.920998,0,0,0,40,4886,113.6936,100.09,,,,,,,,,,,,,0,,,,3.78988335,,,,,,103.56121445,,,,
,14588087.695,104.5403061,100.09,0.00538279115335307,1.55953401940953E-6,1,0.999253354069792,40.0298881530762,1.99255603076538,10.1800002157688,0.0600009200753129,0.0108448041209582,2.5,2.61510749695845E-5,0.00540844016022184,3.90647671904732E-5,104.5403061,104.5403061,100.09,100.09,53.2171777318326,18.4454228019231,27.920998,0,0,0,40,4886,114.75065,100.09,,,,,,,,,,,,,0,,,,4.076148,,,,,,104.5403061,,,,
,14588113.52,107.0339127,100.09,,,2,,,,10.1529999555945,,,,,,,107.0339127,107.0339127,100.09,100.09,,,27.920998,,,,-99999999,4886,117.512,100.09,,,,,,,,,,,,,,,,,,,,,,,107.0339127,,,,
,14588135.625,109.3257828,100.09,0.00536861843585163,2.18258912501686E-6,1,0.999253354069792,40.0298881530762,1.99261177067114,10.1399999111891,0.0598465939114538,0.0107957411184862,2.5,2.51133839897736E-5,0.00539406396700653,3.71130461520383E-5,109.3257828,109.3257828,100.09,100.09,52.9905054612556,18.4344946470448,27.920998,0,0,0,40,4886,119.80385,100.09,,,,,,,,,,,,,0,,,,4.03583205,,,,,,109.3257828,,,,
,14588146.415,110.3581619,100.09,0.00537455759560585,1.6455568881271E-6,1,0.999253354069792,40.0298881530762,1.99285037465278,10.1500004529953,0.0599247109333767,0.0107777463344935,2.5,2.25344521460757E-5,0.00539999871073375,3.43532200673208E-5,110.2932281,110.4230957,100.09,100.09,53.0780478554095,18.4426309546466,27.158575,0,0,0,40,4886,120.9397,100.09,,,,,,,,,,,,,0,,,,4.07635165,,,,,,110.3581619,,,,
,14588157.265,111.4648438,100.09,0.00537399377567131,2.02138511817798E-6,1,0.999253354069792,40.0298881530762,1.99280532153088,10.1399999111891,0.0599184854684381,0.0107654553108584,2.5,2.1740884460364E-5,0.00539938559160331,3.33741186463501E-5,111.4648438,111.4648438,100.09,100.09,51.7883607986786,18.4478791141102,27.920998,0,0,0,40,4886,122.10085,100.09,,,,,,,,,,,,,0,,,,3.82564485,,,,,,111.4648438,,,,
,14588167.485,112.4547043,100.09,0.0053766959119106,1.92201780701586E-6,1,0.999253354069792,40.0298881530762,1.99272231255965,10.1399999111891,0.0599429949604255,0.0107858032114768,2.5,2.32954444528774E-5,0.00540205144909351,3.47825530648976E-5,112.4547043,112.4547043,100.09,100.09,53.0592887709479,18.4452734347416,27.920998,0,0,0,40,4886,123.15345,100.09,,,,,,,,,,,,,0,,,,4.076148,,,,,,112.4547043,,,,
,14588177.405,113.3614197,100.09,0.00537957084521265,1.37212836497461E-6,1,0.999253354069792,40.0298881530762,1.99306491425743,10.1399999111891,0.0599863293424942,0.0107828442136969,2.5,2.25313198171981E-5,0.00540490272712562,3.38620682839343E-5,113.3614197,113.3614197,100.09,100.09,52.751327134371,18.4435111803205,27.920998,0,0,0,40,4886,124.2311,100.09,,,,,,,,,,,,,0,,,,4.1584077,,,,,,113.3614197,,,,
,14588186.955,114.36451335,100.09,0.00537547596431225,1.76288700543088E-6,1,0.999253354069792,40.0298881530762,1.99260087369625,10.1399999111891,0.0599252562616728,0.010780217755767,2.5,2.33853666383808E-5,0.00540073221393215,3.45650872951745E-5,114.2464828,114.4825439,100.09,100.09,53.3391117808326,18.4423116069921,27.920998,0,0,0,40,4886,125.2512,100.09,,,,,,,,,,,,,0,,,,4.07635165,,,,,,114.36451335,,,,
,14588198.055,115.477005,100.09,0.00537481176389105,1.25665939422839E-6,1,0.999253354069792,40.0298881530762,1.99292595469358,10.1399999111891,0.0599287812074447,0.0107676635356066,2.5,2.23997423951899E-5,0.0054000053214396,3.34092354510458E-5,115.4156265,115.5383835,100.09,100.09,52.7779025040248,18.4419533001217,27.920998,0,0,0,40,4886,126.426,100.09,,,,,,,,,,,,,0,,,,4.1170726,,,,,,115.477005,,,,
,14588208.42,116.5276794,100.09,0.00537392758974462,1.36488395926354E-6,1,0.999253354069792,40.0298881530762,1.99272922929019,10.1500004529953,0.0599134558347004,0.0107595759608931,2.5,2.20770842617408E-5,0.00539905470198999,3.29376922206796E-5,116.5276794,116.5276794,100.09,100.09,52.6575317120633,18.4414386028281,27.920998,0,0,0,40,4886,127.4961,100.09,,,,,,,,,,,,,0,,,,4.0374434,,,,,,116.5276794,,,,
,14588230.08,118.6137924,100.09,,,2,,,,10.1429998794496,,,,,,,118.6137924,118.6137924,100.09,100.09,,,28.30221,,,,-99999999,4886,129.7925,100.09,,,,,,,,,,,,,,,,,,,,,,,118.6137924,,,,