File: DataFailid_Testimiseks/uued TEST failid/no1_TiO2withCuFeO3-Fe2O3after5recyclingcycles_05022024.DAT
[Header]
; VSM Data File (default extension .dat)
; Copyright (c) 2003-2013, Quantum Design, Inc. All rights reserved.
TITLE,no1_TiO2withCuFeO3-Fe2O3after5recyclingcycles_05022024
FILEOPENTIME,14575754.19,02/05/2024,6:24 pm
BYAPP,VSM,2.0,2.0
INFO,PPMS VSM Option Release 1.4.10 Build 1,APPNAME
INFO,Quantum Design Linear Motor Servo Controller,MOTOR_MODULE_NAME
INFO,3101-100 C1,MOTOR_HW_VERSION
INFO,074,MOTOR_SERIAL_NUMBER
INFO,SRV No X-over 01.01.11,MOTOR_SOFTWARE_VERSION
INFO,Quantum Design VSM Detection Module,VSM_MODULE_NAME
INFO,3101-150 E1,VSM_HW_VERSION
INFO,VSM061,VSM_SERIAL_NUMBER
INFO,VSM No X-over 01.02.05 May 20 2008 13:51:47,VSM_SOFTWARE_VERSION
INFO,113,PREAMP_SERIAL_NUMBER
INFO,Quantum Design VSM Oven Module,OVEN_MODULE_NAME
INFO,unknown,OVEN_HW_VERSION
INFO,OVN054,OVEN_SERIAL_NUMBER
INFO,unknown,OVEN_SOFTWARE_VERSION
INFO,818,COIL_SERIAL_NUMBER
INFO,0,MOMENT_UNITS
INFO,no1_TiO2withCuFeO3-Fe2O3after5recyclingcycles_05022024,SAMPLE_MATERIAL
INFO,,SAMPLE_COMMENT
INFO,2.8 mg,SAMPLE_MASS
INFO,,SAMPLE_VOLUME
INFO,,SAMPLE_MOLECULAR_WEIGHT
INFO,,SAMPLE_SIZE
INFO,powder sample in plastic capusle,SAMPLE_SHAPE
DATATYPE,COMMENT,1
DATATYPE,TIME,2
STARTUPAXIS,X,2
STARTUPAXIS,Y1,5
[Data]
Comment,Time Stamp (sec),Temperature (K),Magnetic Field (Oe),Moment (emu),M. Std. Err. (emu),Transport Action,Averaging Time (sec),Frequency (Hz),Peak Amplitude (mm),Center Position (mm),Coil Signal' (mV),Coil Signal" (mV),Range (mV),M. Quad. Signal (emu),M. Raw' (emu),M. Raw" (emu),Min. Temperature (K),Max. Temperature (K),Min. Field (Oe),Max. Field (Oe),Mass (grams),Motor Lag (deg),Pressure (Torr),VSM Status (code),Motor Status (code),Measure Status (code),Measure Count,PPMS Status (code),System Temp. (K),System Field (Oe),Sample Position (deg),Bridge 1 Resistance (ohms),Bridge 1 Excitation (에),Bridge 2 Resistance (ohms),Bridge 2 Excitation (에),Bridge 3 Resistance (ohms),Bridge 3 Excitation (에),Bridge 4 Resistance (ohms),Bridge 4 Excitation (에),Signal 1 Vin (V),Signal 2 Vin (V),Digital Inputs (code),Drive 1 Iout (mA),Drive 1 Ipower (W),Drive 2 Iout (mA),Drive 2 Ipower (W),Pressure (),Map 20 (),Map 21 (),Map 22 (),Map 23 (),Map 24 (),Map 25 (),Map 26 (),Map 27 (),Map 28 (),Map 29 ()
,14577560.835,299.9974365,19998.9755,0.0220486622991856,2.2111588426411E-6,1,4.99626677034896,40.0298881530762,1.98218004395478,8.75999964773655,0.243669581469708,0.0422976161416992,2.5,-8.04739841076378E-6,0.0220479468055795,6.23181786200787E-6,299.9972839,299.9975891,19998.107,19999.844,52.1533813171594,18.4459189402784,27.920998,0,0,0,200,4929,300.0408,19998.9755,,,,,,,,,,,,,0,,,,5.39201115,,,,,,299.9974365,,,,
,14579224.61,300.0002289,-12.0295,0.00608602588209992,1.99394495133356E-6,1,4.99626677034896,40.0298881530762,1.98257874607002,8.75999964773655,0.0672901964831886,0.0116942126160636,0.25,-1.03465661317907E-6,0.00608582653530561,2.91236461305314E-6,300,300.0004578,-12.144,-11.915,52.8802958400441,18.4631657978109,27.920998,0,0,0,200,4929,300.08125,-12.0295,,,,,,,,,,,,,0,,,,5.41880845,,,,,,300.0002289,,,,
,14586928.755,3.12572575,100.09,0.00524895144677981,1.89410340534575E-6,1,0.999253354069792,40.0298881530762,1.98135038326282,9.92999970912933,0.0575240936295123,0.0105560547752613,2.5,4.027770083052E-5,0.00521573322520534,5.16207984807136E-5,3.1195905,3.131861,100.09,100.09,52.6028177157171,18.4425725269829,27.920998,0,0,0,40,4886,3.134,100.09,,,,,,,,,,,,,0,,,,1.1929137,,,,,,3.12572575,,,,
,14586978.335,3.94661735,100.09,0.00526018805611041,1.49377458647411E-6,1,0.999253354069792,40.0298881530762,1.98163973777146,9.92999970912933,0.0576542989674417,0.0105859652433708,2.5,4.08950265261237E-5,0.00522689792855975,5.22590584228197E-5,3.9325919,3.9606428,100.09,100.09,52.5402874341786,18.4443224243431,27.158575,0,0,0,40,4886,4.07775,100.09,,,,,,,,,,,,,0,,,,1.2921631,,,,,,3.94661735,,,,
,14587034.905,4.6932559,100.09,0.00525629021041037,1.21167807631851E-6,1,0.999253354069792,40.0298881530762,1.98198474784895,9.92999970912933,0.0576278544997691,0.0105419925204062,2.5,3.74125594279399E-5,0.00522303205200803,4.87899558191004E-5,4.6932559,4.6932559,100.09,100.09,52.910779352294,18.4412994221627,27.539787,0,0,0,40,4886,4.76135,100.09,,,,,,,,,,,,,0,,,,1.069252,,,,,,4.6932559,,,,
,14587084.54,9.7597938,100.09,0.00526204025177144,1.76612010521084E-6,1,0.999253354069792,40.0298881530762,1.98185375934942,9.92999970912933,0.0576818944352273,0.0105820456431719,2.5,4.01163047798926E-5,0.00522872084477369,5.14891537823138E-5,9.6879578,9.8316298,100.09,100.09,52.189336229044,18.4380483163483,28.68342,0,0,0,40,4886,10.07355,100.09,,,,,,,,,,,,,0,,,,1.4862046,,,,,,9.7597938,,,,
,14587162.72,17.307209,100.09,0.00526583503626729,1.45269027634754E-6,1,0.999253354069792,40.0298881530762,1.99305828919676,10.1699996739626,0.0580335139051968,0.0106601823954833,2.5,4.12939358395151E-5,0.00523242441025291,5.27146167270643E-5,17.2673683,17.3470497,100.09,100.09,53.1796595629095,18.4415101398581,27.920998,0,0,0,40,4886,17.7743,100.09,,,,,,,,,,,,,0,,,,2.0357591,,,,,,17.307209,,,,
,14587217.445,22.63866615,100.09,0.00528453258707667,1.80714489188582E-6,1,0.999253354069792,40.0298881530762,1.99266049299742,10.1800002157688,0.0582307167229717,0.010708003807953,2.5,4.11982309421953E-5,0.005251385361917,5.39174357413774E-5,22.5640793,22.713253,100.09,100.09,53.2179593603518,18.4458915925774,27.920998,0,0,0,40,4886,23.53335,100.09,,,,,,,,,,,,,0,,,,2.123197,,,,,,22.63866615,,,,
,14587302.47,30.8525372,100.09,0.00530552005316826,1.7469957636326E-6,1,0.999253354069792,40.0298881530762,1.9926786362069,10.1899998262525,0.0584824548136046,0.0108025304367567,2.5,4.02149483025328E-5,0.00527477218715903,5.83655995063778E-5,30.8525372,30.8525372,100.09,100.09,53.2781447563326,18.4446065109778,27.920998,0,0,0,40,4886,32.2629,100.09,,,,,,,,,,,,,0,,,,2.4549655,,,,,,30.8525372,,,,
touchdown = 5.11999987065792 mm,14587391.18,39.2897758,100.09,0.00533340397337517,1.4445208124181E-6,1,0.999253354069792,40.0298881530762,1.98151116747869,10.1899998262525,0.0585436663865191,0.010903775442604,2.5,3.95196171035458E-5,0.00531021070612302,6.66453734461403E-5,39.2897758,39.2897758,100.09,100.09,52.761488305121,18.4385786040778,27.158575,0,0,0,40,4886,41.45725,100.09,,,,,,,,,,,,,0,,,,2.9608517,,,,,,39.2897758,,,,
,14587449.94,44.7734852,100.09,0.00534772776070415,1.03497429789673E-6,1,0.999253354069792,40.0298881530762,1.98147195705286,10.1899998262525,0.0587874577219927,0.0110066946480333,2.5,3.96950371876565E-5,0.00533330089594528,7.19778817643534E-5,44.7113724,44.835598,100.09,100.09,52.8060411307171,18.4484822884203,27.158575,0,0,0,40,4886,47.65205,100.09,,,,,,,,,,,,,0,,,,3.1753123,,,,,,44.7734852,,,,
,14587536.03,52.8113861,100.09,0.00534513018356221,1.77157402699901E-6,1,0.999253354069792,40.0298881530762,2.00649411189735,10.2000003680587,0.0596392898875361,0.0111451794479088,2.5,3.59737180864483E-5,0.00534555028028013,7.03240266956344E-5,52.7475204,52.8752518,100.09,100.09,53.1429230225056,18.4479114631957,26.777365,0,0,0,40,4886,56.7867,100.09,,,,,,,,,,,,,0,,,,3.1125,,,,,,52.8113861,,,,
,14587596.765,58.50120925,100.09,0.00536174495911362,2.02477709952767E-6,1,0.999253354069792,40.0298881530762,2.00639360351365,10.2000003680587,0.0599202600342169,0.0111900008810305,2.5,3.75807031848162E-5,0.00537087608087047,6.9991459200188E-5,58.4591789,58.5432396,100.09,100.09,52.5105855504479,18.4394669200942,27.920998,0,0,0,40,4886,63.24705,100.09,,,,,,,,,,,,,0,,,,3.43966725,,,,,,58.50120925,,,,
,14587684.295,66.5873489,100.09,0.00536304803089834,1.97064023119664E-6,1,0.999253354069792,40.0298881530762,2.00639066242101,10.219999589026,0.0600418554971729,0.0111246500429746,2.5,3.48872384759436E-5,0.00538045774907605,6.24879922276679E-5,66.5873489,66.5873489,100.09,100.09,53.1022783395056,18.439204258781,28.30221,0,0,0,40,4886,72.4612,100.09,,,,,,,,,,,,,0,,,,3.44018235,,,,,,66.5873489,,,,
,14587776.45,75.2874184,100.09,0.00537815682654026,1.41617280436863E-6,1,0.999253354069792,40.0298881530762,1.98185029263601,10.2099999785423,0.0595750745895734,0.0109289681127628,2.5,3.04527471256559E-5,0.00540033604504597,5.31447895058432E-5,75.2255936,75.3492432,100.09,100.09,52.687233595794,18.4387392789684,27.920998,0,0,0,40,4886,82.27155,100.09,,,,,,,,,,,,,0,,,,3.6012801,,,,,,75.2874184,,,,
,14587896.555,86.3680573,100.09,0.00538449593991579,1.64361340881444E-6,1,0.999253354069792,40.0298881530762,2.00633272585097,10.1899998262525,0.0603885861924298,0.0110049087712963,2.5,2.83066921961375E-5,0.00540891025761414,4.68759096960822E-5,86.3680573,86.3680573,100.09,100.09,53.0350582868518,18.4405812750739,29.064632,0,0,0,40,4886,92.64065,100.09,,,,,,,,,,,,,0,,,,3.78195475,,,,,,86.3680573,,,,
,14587970.39,92.6501389,100.09,0.00537965461230219,1.97918611745003E-6,1,0.999253354069792,40.0298881530762,2.0065244684423,10.1899998262525,0.0603623913893293,0.0109445327636969,2.5,2.65268745451105E-5,0.00540523261160383,4.20239726289938E-5,92.6501389,92.6501389,100.09,100.09,52.0947591782171,18.4491437865051,27.920998,0,0,0,40,4886,102.8968,100.09,,,,,,,,,,,,,0,,,,3.9164791,,,,,,92.6501389,,,,
,14588052.085,101.0369492,100.09,0.00537986311013486,1.81354894080484E-6,1,0.999253354069792,40.0298881530762,1.99290326575991,10.1800002157688,0.0599756358330028,0.0108580172020002,2.5,2.69446514769688E-5,0.00540552705702207,4.05957903328082E-5,101.0369492,101.0369492,100.09,100.09,53.1319802232364,18.4366487529146,29.064632,0,0,0,40,4886,110.9512,100.09,,,,,,,,,,,,,0,,,,4.0356307,,,,,,101.0369492,,,,
,14588135.625,109.3257828,100.09,0.00536861843585163,2.18258912501686E-6,1,0.999253354069792,40.0298881530762,1.99261177067114,10.1399999111891,0.0598465939114538,0.0107957411184862,2.5,2.51133839897736E-5,0.00539406396700653,3.71130461520383E-5,109.3257828,109.3257828,100.09,100.09,52.9905054612556,18.4344946470448,27.920998,0,0,0,40,4886,119.80385,100.09,,,,,,,,,,,,,0,,,,4.03583205,,,,,,109.3257828,,,,
,14588191.715,114.8903122,100.09,0.0053704884648859,1.70054949723785E-6,1,0.999253354069792,40.0298881530762,1.99268034098175,10.1500004529953,0.059874181200103,0.0107558681669806,2.5,2.21178012308545E-5,0.00539569310740344,3.32092472752021E-5,114.8283463,114.9522781,100.09,100.09,53.0342766583325,18.4426191451373,27.920998,0,0,0,40,4886,125.76265,100.09,,,,,,,,,,,,,0,,,,4.03583205,,,,,,114.8903122,,,,
,14588275.695,123.1482239,100.09,0.00537282843995519,1.76892157808954E-6,1,0.999253354069792,40.0298881530762,1.98186796191884,10.1300003007054,0.0595873188388968,0.0106756988710593,2.5,2.07293595692104E-5,0.00539750960923844,3.07072393215148E-5,123.1482239,123.1482239,100.09,100.09,52.4519634115056,18.4451299974031,28.30221,0,0,0,40,4886,134.5661,100.09,,,,,,,,,,,,,0,,,,4.15923735,,,,,,123.1482239,,,,
,14588346.27,130.1726379,100.09,,,2,,,,10.1130001166761,,,,,,,130.1726379,130.1726379,100.09,100.09,,,27.158575,,,,-99999999,4886,141.9974,100.09,,,,,,,,,,,,,,,,,,,,,,,130.1726379,,,,
,14588414.14,137.0595627,100.09,0.00536895385283329,1.39768699207093E-6,1,0.999253354069792,40.0298881530762,1.98182725675594,10.0999996066093,0.0595376247090158,0.01062047142583,2.5,1.80653906693278E-5,0.00539240927713473,2.66123936560611E-5,136.9930878,137.1260376,100.09,100.09,52.6012544586786,18.4371775672322,27.920998,0,0,0,40,4886,149.0434,100.09,,,,,,,,,,,,,0,,,,4.28513335,,,,,,137.0595627,,,,
,14588496.905,145.4750214,100.09,0.00536042265702697,1.73632164445131E-6,1,0.999253354069792,40.0298881530762,1.98185549963908,10.0800003856421,0.0594373117802092,0.010584485626603,2.5,1.71019203224434E-5,0.00538297471240491,2.49777542791896E-5,145.4750214,145.4750214,100.09,100.09,53.1366699943518,18.4404437709349,27.920998,0,0,0,40,4886,157.5669,100.09,,,,,,,,,,,,,0,,,,4.39333605,,,,,,145.4750214,,,,
,14588554.305,151.2022858,100.09,0.00536273399826444,1.10247999084602E-6,1,0.999253354069792,40.0298881530762,1.98188479449516,10.0699998438358,0.059462148397569,0.0105571928104593,2.5,1.4720661835531E-5,0.00538466479606868,2.22015151827781E-5,151.2022858,151.2022858,100.09,100.09,52.6403358846402,18.4452492461012,27.920998,0,0,0,40,4886,163.37365,100.09,,,,,,,,,,,,,0,,,,4.24317385,,,,,,151.2022858,,,,
,14588637.37,159.3796539,100.09,0.00534882581086892,1.84394142402199E-6,1,0.999253354069792,40.0298881530762,1.99284193822863,10.0400000810623,0.0596144760354737,0.0105688903779218,2.5,1.38371310101017E-5,0.00536974635702435,2.07997585307096E-5,159.3796539,159.3796539,100.09,100.09,52.2698439665248,18.4396932746607,29.064632,0,0,0,40,4886,171.8044,100.09,,,,,,,,,,,,,0,,,,4.4596095,,,,,,159.3796539,,,,
,14588721.57,167.6858368,100.09,0.0053393605808346,1.57278485206672E-6,1,0.999253354069792,40.0298881530762,1.98183575599502,10.0100003182888,0.0591832365972102,0.0104870135848304,2.5,1.37669182463031E-5,0.00535922035333337,2.02828219771045E-5,167.6858368,167.6858368,100.09,100.09,52.8802958400441,18.4349722546077,27.920998,0,0,0,40,4886,180.3363,100.09,,,,,,,,,,,,,0,,,,4.48199655,,,,,,167.6858368,,,,
,14588779.47,173.3636322,100.09,0.00533393078662465,1.26522039720765E-6,1,0.999253354069792,40.0298881530762,1.98184743704258,10.0100003182888,0.0591198428099881,0.0104492667477384,2.5,1.16975531007034E-5,0.00535304590308144,1.79316245648141E-5,173.3636322,173.3636322,100.09,100.09,53.2320286736979,18.4416949289517,27.158575,0,0,0,40,4886,186.23845,100.09,,,,,,,,,,,,,0,,,,4.52699545,,,,,,173.3636322,,,,
,14588865.24,181.9147186,100.09,0.00532225661858672,1.59173124521521E-6,1,0.999253354069792,40.0298881530762,2.0068083063758,9.97999962419271,0.0596957487047647,0.0105170421633414,2.5,9.07934884080395E-6,0.00534020049206704,1.4937636448146E-5,181.9147186,181.9147186,100.09,100.09,52.8412144140825,18.4486988879686,27.920998,0,0,0,40,4886,194.93025,100.09,,,,,,,,,,,,,0,,,,4.2423267,,,,,,181.9147186,,,,
,14588949.065,190.1655579,100.09,0.00531614113530028,1.79026791027682E-6,1,0.999253354069792,40.0298881530762,1.98184756320104,9.94000025093555,0.0589015302917159,0.0103880370429664,2.5,1.03257819778394E-5,0.00533293358028633,1.58760616774427E-5,190.1655579,190.1655579,100.09,100.09,53.0741397128133,18.4400825111933,27.920998,0,0,0,40,4886,203.4041,100.09,,,,,,,,,,,,,0,,,,4.2902658,,,,,,190.1655579,,,,
,14589005.315,195.7773743,100.09,0.00530709126453615,1.96106662701975E-6,1,0.999253354069792,40.0298881530762,1.98192163396256,9.94000025093555,0.058799298152654,0.0103426877126058,2.5,8.10020306576138E-6,0.00532307061255898,1.34478866297577E-5,195.7773743,195.7773743,100.09,100.09,52.4410206122363,18.438376784485,28.30221,0,0,0,40,4886,209.0797,100.09,,,,,,,,,,,,,0,,,,4.2211332,,,,,,195.7773743,,,,
,14589090.29,204.2508087,100.09,0.00530744255397927,1.381951571604E-6,1,0.999253354069792,40.0298881530762,2.00656785028598,9.92999970912933,0.0594878277850709,0.0104801137130626,2.5,9.76702749283965E-6,0.0053222068551917,1.48614906805787E-5,204.2508087,204.2508087,100.09,100.09,53.228902159621,18.4422178390665,27.920998,0,0,0,40,4886,217.65515,100.09,,,,,,,,,,,,,0,,,,4.6880207,,,,,,204.2508087,,,,
touchdown = 4.80999983847141 mm,14589173.2,212.4922333,100.09,0.00529053577888225,1.27335249849396E-6,1,0.999253354069792,40.0298881530762,1.98187918432127,9.87999979406595,0.058587843082379,0.0103063459389561,2.5,8.62899010858429E-6,0.00530404971716759,1.34747203503755E-5,212.4922333,212.4922333,100.09,100.09,52.8615367555825,18.4330825028104,27.920998,0,0,0,40,4886,226.0642,100.09,,,,,,,,,,,,,0,,,,4.5952849,,,,,,212.4922333,,,,
,14589230.455,218.1901703,100.09,0.00528744954600398,1.2407636162294E-6,1,0.999253354069792,40.0298881530762,1.98202463110472,9.87999979406595,0.0585534133616293,0.0102708621031053,2.5,6.18902912647907E-6,0.00530011138234051,1.08807552659292E-5,218.1901703,218.1901703,100.09,100.09,52.873261183371,18.44774075936,27.920998,0,0,0,40,4886,231.80835,100.09,,,,,,,,,,,,,0,,,,4.5505154,,,,,,218.1901703,,,,
,14589315.93,226.5852814,100.09,0.00529596457612562,1.15294927885662E-6,1,0.999253354069792,40.0298881530762,1.9927674540663,9.84000042080879,0.0589393783831508,0.0103338066078186,2.5,5.982415582403E-6,0.00530737987566796,1.04800386540185E-5,226.5852814,226.5852814,100.09,100.09,52.5785872316209,18.4451133304335,27.158575,0,0,0,40,4886,240.3546,100.09,,,,,,,,,,,,,0,,,,4.5496073,,,,,,226.5852814,,,,
,14589372.95,232.2294006,100.09,0.00530464294769157,9.86686175639395E-7,1,0.999253354069792,40.0298881530762,1.99294317337888,9.84000042080879,0.0590317313837345,0.010347782619316,2.5,5.92550073817141E-6,0.00531521307400267,1.03019101721657E-5,232.2294006,232.2294006,100.09,100.09,53.3148812967364,18.4393641089378,27.920998,0,0,0,40,4886,246.1885,100.09,,,,,,,,,,,,,0,,,,4.7826281,,,,,,232.2294006,,,,
,14589455.555,240.4608154,100.09,0.0053078901033854,1.5037091214367E-6,1,0.999253354069792,40.0298881530762,2.00669811372606,9.8099997267127,0.0594470886795001,0.0104039221715743,2.5,4.65584665851433E-6,0.00531719310290158,8.85915907328303E-6,240.4608154,240.4608154,100.09,100.09,53.1960737618133,18.4423212343034,27.920998,0,0,0,40,4886,254.5814,100.09,,,,,,,,,,,,,0,,,,4.7826281,,,,,,240.4608154,,,,
,14589534.83,248.39910125,100.09,0.00533860675494845,1.2392853890584E-6,1,0.999253354069792,40.0298881530762,2.00666027215049,9.77000035345554,0.0597792292354971,0.0104432691995898,2.5,3.2074736508081E-6,0.00534671515382973,7.27835289159869E-6,248.333374,248.4648285,100.09,100.09,52.7192803650825,18.4466661138343,27.920998,0,0,0,40,4886,262.5633,100.09,,,,,,,,,,,,,0,,,,4.85489515,,,,,,248.39910125,,,,
,14589591.33,253.9467316,100.09,0.00536444331954316,1.33338108018381E-6,1,0.999253354069792,40.0298881530762,2.00664558837788,9.77000035345554,0.0600545917601273,0.0105129447113409,2.5,5.19580190826689E-6,0.00537170601839328,9.18453352730559E-6,253.9467316,253.9467316,100.09,100.09,52.619231914621,18.4465709407258,27.539787,0,0,0,40,4886,268.2635,100.09,,,,,,,,,,,,,0,,,,4.2001576,,,,,,253.9467316,,,,
,14589673.29,262.0768738,100.09,0.00541729967766833,1.78822399501595E-6,1,0.999253354069792,40.0298881530762,1.99292551717945,9.73999965935945,0.0602354455882719,0.0105374940556885,2.5,4.76856593288053E-6,0.00542331909203,8.65162485841145E-6,262.0768738,262.0768738,100.09,100.09,53.4446316309287,18.4409405080023,27.539787,0,0,0,40,4886,276.482,100.09,,,,,,,,,,,,,0,,,,4.9776092,,,,,,262.0768738,,,,
,14589743.34,268.9985352,100.09,,,2,,,,9.68300010207295,,,,,,,268.9985352,268.9985352,100.09,100.09,,,27.920998,,,,-99999999,4886,283.6142,100.09,,,,,,,,,,,,,,,,,,,,,,,268.9985352,,,,
,14589810.16,275.6779785,100.09,0.00542966512968056,1.6389114031936E-6,1,0.999253354069792,40.0298881530762,1.98185958081209,9.68000013381243,0.0600265698201544,0.0105021611359497,2.5,5.10515472223968E-6,0.00543347951413831,8.77388616059435E-6,275.6779785,275.6779785,100.09,100.09,52.6325195994479,18.4428784459836,27.920998,0,0,0,40,4886,290.3197,100.09,,,,,,,,,,,,,0,,,,4.9776092,,,,,,275.6779785,,,,
,14589892.56,283.8924255,100.09,0.00540231877397003,1.16823018970039E-6,1,0.999253354069792,40.0298881530762,1.98187519820067,9.63999982923269,0.0597158814402736,0.0104125235386723,2.5,2.10211864551435E-6,0.00540477864499609,5.62893340745549E-6,283.8924255,283.8924255,100.09,100.09,52.9537689208517,18.440942310872,27.920998,0,0,0,40,4886,298.60315,100.09,,,,,,,,,,,,,0,,,,4.92837695,,,,,,283.8924255,,,,
,14589947.935,289.3427734,100.09,0.00537017828264616,1.63626653171088E-6,1,0.999253354069792,40.0298881530762,1.98195160828935,9.63999982923269,0.0593534512824993,0.0103470086359325,2.5,1.96258352716766E-6,0.00537174164477888,5.39085803798508E-6,289.3427734,289.3427734,100.09,100.09,52.1393120038132,18.444472429077,26.396152,0,0,0,40,4886,304.2345,100.09,,,,,,,,,,,,,0,,,,4.5496073,,,,,,289.3427734,,,,
,14590028.47,297.3356018,100.09,0.00534014350000152,1.78298898276331E-6,1,0.999253354069792,40.0298881530762,1.9931036001136,9.58999991416931,0.0593246730821903,0.0103486634708367,2.5,2.63883298403686E-6,0.00534041300376206,5.94228080894928E-6,297.2599487,297.4112549,100.09,100.09,52.4378940981594,18.4450043313764,27.920998,0,0,0,40,4886,312.40975,100.09,,,,,,,,,,,,,0,,,,4.95287015,,,,,,297.3356018,,,,
,14590111.36,305.6039429,100.09,0.0053123679405498,9.64251686293907E-7,1,0.999253354069792,40.0298881530762,1.98185005655801,9.54999960958958,0.0586836709126685,0.0102258898215807,2.5,1.76163077377307E-6,0.00531131853538502,4.94751365273764E-6,305.6039429,305.6039429,100.09,100.09,53.1257271950825,18.4479456858664,27.920998,0,0,0,40,4886,320.7949,100.09,,,,,,,,,,,,,0,,,,5.05282235,,,,,,305.6039429,,,,
,14590166.945,311.0256348,100.09,0.00528727399545204,1.05676732579525E-6,1,0.999253354069792,40.0298881530762,1.98177097225163,9.5600001513958,0.0583958106120632,0.0101695397239624,2.5,1.27133979801936E-6,0.00528537320050903,4.37966573458006E-6,311.0256348,311.0256348,100.09,100.09,52.5066774078517,18.4426482905981,27.539787,0,0,0,40,4886,326.4099,100.09,,,,,,,,,,,,,0,,,,5.0780606,,,,,,311.0256348,,,,
,14590250.245,319.3514709,100.09,0.00523978051852298,1.47011176360599E-6,1,0.999253354069792,40.0298881530762,2.00651571493677,9.4999996945262,0.0585499144300856,0.0101935875597695,2.5,1.10190566608004E-6,0.00523659991701678,4.09713826636304E-6,319.3514709,319.3514709,100.09,100.09,52.2424869683517,18.4482224150452,27.920998,0,0,0,40,4886,334.6707,100.09,,,,,,,,,,,,,0,,,,5.0278349,,,,,,319.3514709,,,,
,14590304.05,324.5502625,100.09,0.005222049267067,1.65876761346073E-6,1,0.999253354069792,40.0298881530762,2.006903273271,9.51000023633242,0.0583526794295539,0.0101647739536924,2.5,1.62723545583765E-6,0.00521807734146393,4.56218091493891E-6,324.5502625,324.5502625,100.09,100.09,52.5676444323517,18.4472652330823,27.920998,0,0,0,40,4886,339.8714,100.09,,,,,,,,,,,,,0,,,,4.9776092,,,,,,324.5502625,,,,
,14590386.015,332.46017455,100.09,0.00517407406939551,1.3130124154826E-6,1,0.999253354069792,40.0298881530762,1.98210070343538,9.44999977946281,0.0571233176570187,0.0099193983323805,2.5,-1.0658064573914E-6,0.00516894056697344,1.77659091177978E-6,332.4104919,332.5098572,100.09,100.09,53.2953405837556,18.4409590641907,27.920998,0,0,0,40,4886,347.6258,100.09,,,,,,,,,,,,,0,,,,5.1805391,,,,,,332.46017455,,,,
,14590467.65,340.18707275,100.09,0.00513298226107245,1.2987673990221E-6,1,0.999253354069792,40.0298881530762,1.9818552486854,9.39000025391579,0.0566490689626784,0.00984379719199171,2.5,-4.04373529987579E-7,0.00512673918682409,2.35520848822753E-6,340.1365051,340.2376404,100.09,100.09,53.2984670978326,18.4465877172196,27.158575,0,0,0,40,4886,355.2368,100.09,,,,,,,,,,,,,0,,,,4.93206595,,,,,,340.18707275,,,,
,14590523.455,345.4195557,100.09,0.00509849006923142,1.49369439592807E-6,1,0.999253354069792,40.0298881530762,1.9820356027725,9.39000025391579,0.0562646117065058,0.0097784486630194,2.5,-2.37393644842906E-7,0.00509152328024589,2.46708770705474E-6,345.4195557,345.4195557,100.09,100.09,52.8763876974479,18.4452936864099,27.920998,0,0,0,40,4886,360.3828,100.09,,,,,,,,,,,,,0,,,,5.1805391,,,,,,345.4195557,,,,
,14590604.675,352.9551239,100.09,0.00505025933055518,1.67382610494978E-6,1,0.999253354069792,40.0298881530762,1.98231627803308,9.34000033885241,0.0557306292046625,0.00967007395683681,2.5,-1.55909154138642E-6,0.00504227949302745,1.07559730795036E-6,352.9026184,353.0076294,100.09,100.09,52.6551868265056,18.4453101997831,27.920998,0,0,0,40,4886,367.76585,100.09,,,,,,,,,,,,,0,,,,5.02858735,,,,,,352.9551239,,,,
,14590660.69,358.0797119,100.09,0.0050254920127062,1.26935314649729E-6,1,0.999253354069792,40.0298881530762,1.98202614962128,9.34000033885241,0.0554418787901164,0.00961804360690491,2.5,-1.69358362204297E-6,0.00501682994157259,9.00809254535395E-7,358.0797119,358.0797119,100.09,100.09,52.964711720121,18.4435485152677,27.920998,0,0,0,40,4886,372.83235,100.09,,,,,,,,,,,,,0,,,,4.4152803,,,,,,358.0797119,,,,
,14590742.25,365.5258484,100.09,0.00498293295742613,1.55050758843772E-6,1,0.999253354069792,40.0298881530762,1.98210009793681,9.29000042378902,0.0549624348424626,0.00953822655605786,2.5,-1.35056460673007E-6,0.00497331897703111,1.18785926747094E-6,365.5258484,365.5258484,100.09,100.09,52.8959284104287,18.4402747341109,27.920998,0,0,0,40,4886,380.0459,100.09,,,,,,,,,,,,,0,,,,5.2325511,,,,,,365.5258484,,,,
,14590797.705,370.4331055,100.09,0.00495253476115762,1.05535288235494E-6,1,0.999253354069792,40.0298881530762,1.9822429642048,9.29000042378902,0.0546233607052755,0.00948084251956671,2.5,-1.19541115595674E-6,0.00494231788265819,1.30861996671026E-6,370.4331055,370.4331055,100.09,100.09,53.0506908572364,18.4375938802294,27.920998,0,0,0,40,4886,384.9427,100.09,,,,,,,,,,,,,0,,,,5.0275841,,,,,,370.4331055,,,,
,14590877.9,377.26167295,100.09,0.00491696790219551,9.28047953434582E-7,1,0.999253354069792,40.0298881530762,1.98218020714302,9.22000035643578,0.0542232841113893,0.00938879867993472,2.5,-3.17694657306962E-6,0.00490592399061565,-6.86432276246721E-7,377.2325439,377.290802,100.09,100.09,52.8521572133517,18.4476536724927,27.920998,0,0,0,40,4886,384.874,100.09,,,,,,,,,,,,,0,,,,4.8791447,,,,,,377.26167295,,,,
,14590934.37,377.8676147,100.09,0.004899696232712,1.41168439719666E-6,1,0.999253354069792,40.0298881530762,1.98200462868776,9.22000035643578,0.054025188525883,0.00936726164438858,2.5,-2.05150345980283E-6,0.00488861094437555,4.37252765334711E-7,377.8676147,377.8676147,100.09,100.09,53.1460495365825,18.4515392226152,27.920998,0,0,0,40,4886,382.22245,100.09,,,,,,,,,,,,,0,,,,5.31161665,,,,,,377.8676147,,,,
,14590987.895,378.4776306,100.09,0.00488936702122158,1.57950832433906E-6,1,0.999253354069792,40.0298881530762,1.98194145137865,9.22999996691942,0.0539091093009821,0.00934514137218623,2.5,-2.22275376671948E-6,0.00487822611039411,2.61182863820186E-7,378.4776306,378.4776306,100.09,100.09,52.4699408674479,18.4448991297828,27.920998,0,0,0,40,4886,382.2134,100.09,,,,,,,,,,,,,0,,,,5.2850857,,,,,,378.4776306,,,,
,14591040.035,378.75549315,100.09,0.00488554904915657,1.40171864344341E-6,1,0.999253354069792,40.0298881530762,1.98211259640949,9.22999996691942,0.053870766274895,0.00934035161011295,2.5,-2.0586320656783E-6,0.00487438072379155,4.24100725411533E-7,378.7519531,378.7590332,100.09,100.09,52.3276844769478,18.4447893012617,27.920998,0,0,0,40,4886,381.9196,100.09,,,,,,,,,,,,,0,,,,5.2850857,,,,,,378.75549315,,,,
,14591092.335,379.1644897,100.09,0.00487816913785742,1.43259564807338E-6,1,0.999253354069792,40.0298881530762,1.982149735768,9.22000035643578,0.0537887224188407,0.00933237780966711,2.5,-1.50304370814407E-6,0.00486696479490582,9.72575421279854E-7,379.1644897,379.1644897,100.09,100.09,52.995195232371,18.4506537382391,27.920998,0,0,0,40,4886,382.4767,100.09,,,,,,,,,,,,,0,,,,5.2588184,,,,,,379.1644897,,,,
,14591143.015,379.5553436,100.09,0.00487593382187332,1.30919275060798E-6,1,0.999253354069792,40.0298881530762,1.98214627776359,9.22999996691942,0.0537653339242094,0.00931702407522585,2.5,-2.49737790147074E-6,0.00486468472859385,-2.00931478155229E-8,379.552124,379.5585632,100.09,100.09,53.2484428726018,18.447414161438,27.920998,0,0,0,40,4885,382.3385,100.09,,,,,,,,,,,,,0,,,,4.7847762,,,,,,379.5553436,,,,
,14591194.98,379.8061218,100.09,0.00487666226734133,1.10460407485148E-6,1,0.999253354069792,40.0298881530762,1.9821925709849,9.22000035643578,0.053771714494908,0.00933294635548923,2.5,-1.19363841386166E-6,0.00486537852356614,1.28139478366314E-6,379.8061218,379.8061218,100.09,100.09,52.9787810334671,18.449813823762,27.158575,0,0,0,40,4885,382.2326,100.09,,,,,,,,,,,,,0,,,,4.8791447,,,,,,379.8061218,,,,
,14591246.26,379.9658813,100.09,0.00487388378125438,1.16131327597497E-6,1,0.999253354069792,40.0298881530762,1.98222143524315,9.22000035643578,0.0537412658477421,0.00932965187534598,2.5,-1.01821851728579E-6,0.00486258580105693,1.45548327473777E-6,379.9658813,379.9658813,100.09,100.09,53.2804896418903,18.4505725372685,27.920998,0,0,0,40,4885,382.1022,100.09,,,,,,,,,,,,,0,,,,5.2850857,,,,,,379.9658813,,,,
,14597792.72,3.195511,100.09,0.00593751547169254,1.81849075401859E-6,1,0.999253354069792,40.0298881530762,1.99259168477043,9.90999955683947,0.0654267694579037,0.0119919617891663,2.5,4.430697157624E-5,0.00589994248411776,5.71459889766561E-5,3.1911466,3.1998754,100.09,100.09,52.0963224352555,18.4396879087296,27.920998,0,0,0,40,4886,3.21905,100.09,,,,,,,,,,,,,0,,,,1.2049506,,,,,,3.195511,,,,
,14597842.755,4.08729695,100.09,0.00594228043576379,1.77126186404772E-6,1,0.999253354069792,40.0298881530762,1.99274000500972,9.90999955683947,0.0654851752511044,0.011995484679704,2.5,4.37119341880536E-5,0.00590467903164004,5.65652384676604E-5,4.0765676,4.0980263,100.09,100.09,51.4921235898901,18.4397780601638,28.30221,0,0,0,40,4886,4.25795,100.09,,,,,,,,,,,,,0,,,,1.2737229,,,,,,4.08729695,,,,
,14597899.225,4.7341561,100.09,0.00593290415037283,2.10561765237249E-6,1,0.999253354069792,40.0298881530762,1.99253547604722,9.89999994635582,0.0653729664043884,0.0119892766972702,2.5,4.49027056970328E-5,0.00589535889872231,5.77277740604143E-5,4.7341561,4.7341561,100.09,100.09,53.3500545801018,18.43890431513,28.30221,0,0,0,40,4886,4.79425,100.09,,,,,,,,,,,,,0,,,,1.0742444,,,,,,4.7341561,,,,
,14597947.82,9.6597548,100.09,0.00593224089621032,2.04914414011451E-6,1,0.999253354069792,40.0298881530762,1.99249971832564,9.89999994635582,0.0653680472067946,0.01196637324234,2.5,4.29657893002156E-5,0.00589468348968901,5.58014220482355E-5,9.6597548,9.6597548,100.09,100.09,52.7669597047556,18.4380420538265,27.158575,0,0,0,40,4886,9.9326,100.09,,,,,,,,,,,,,0,,,,1.5161215,,,,,,9.6597548,,,,
,14598027.41,17.4504318,100.09,0.00592529213911067,1.6066593694071E-6,1,0.999253354069792,40.0298881530762,1.98162701559318,10.1500004529953,0.0649483005417816,0.0118928275204428,2.5,4.31311576592211E-5,0.00588770994506394,5.6024334077487E-5,17.4504318,17.4504318,100.09,100.09,52.829489986294,18.440201343284,27.920998,0,0,0,40,4886,18.016,100.09,,,,,,,,,,,,,0,,,,2.03596225,,,,,,17.4504318,,,,
,14598083.275,22.9184055,100.09,0.00592996533236933,1.82041736570126E-6,1,0.999253354069792,40.0298881530762,1.98178567991479,10.1500004529953,0.0650038683533089,0.0119362639833865,2.5,4.46236845867864E-5,0.00589280086237277,5.89902095224794E-5,22.9184055,22.9184055,100.09,100.09,53.2124879607172,18.4389225012784,27.920998,0,0,0,40,4886,23.7314,100.09,,,,,,,,,,,,,0,,,,2.0664685,,,,,,22.9184055,,,,
,14598167.645,31.0123119,100.09,0.00592249560340349,1.87694965226715E-6,1,0.999253354069792,40.0298881530762,1.98172149698215,10.1600000634789,0.064943821940313,0.0119747550078185,2.5,4.2823660993665E-5,0.00588829442137649,6.32881169883856E-5,31.0123119,31.0123119,100.09,100.09,53.3078466400633,18.4431525655912,27.920998,0,0,0,40,4886,32.46495,100.09,,,,,,,,,,,,,0,,,,2.7334323,,,,,,31.0123119,,,,
,14598257.42,39.6238174,100.09,0.00592910881839043,1.5238128596798E-6,1,0.999253354069792,40.0298881530762,1.99262774244405,10.1899998262525,0.0654391626971138,0.0121837262669271,2.5,4.31650908054704E-5,0.00590382766777482,7.37172539990599E-5,39.6238174,39.6238174,100.09,100.09,51.7852342846016,18.439763157032,27.158575,0,0,0,40,4886,41.82475,100.09,,,,,,,,,,,,,0,,,,2.9786853,,,,,,39.6238174,,,,
,14598317.35,45.2645302,100.09,0.00591915932324525,2.00218718162541E-6,1,0.999253354069792,40.0298881530762,1.99264033284641,10.1899998262525,0.0654365116428131,0.0122159903505918,2.5,4.05228600804959E-5,0.00590404885808982,7.65767803550922E-5,45.2645302,45.2645302,100.09,100.09,52.3659842743902,18.4395918646552,27.539787,0,0,0,40,4886,48.12565,100.09,,,,,,,,,,,,,0,,,,3.2073523,,,,,,45.2645302,,,,
,14598404.235,53.2782822,100.09,0.00589930590910502,1.90543006529768E-6,1,0.999253354069792,40.0298881530762,1.98157943717803,10.1899998262525,0.0650527839246959,0.0121384524685605,2.5,3.82094992150744E-5,0.00590076625703367,7.60167998644347E-5,53.2782822,53.2782822,100.09,100.09,53.1265088236018,18.4385381495116,27.920998,0,0,0,40,4886,57.3788,100.09,,,,,,,,,,,,,0,,,,2.9905784,,,,,,53.2782822,,,,
,14598464.985,58.915226,100.09,0.00590037255792267,1.89835700208095E-6,1,0.999253354069792,40.0298881530762,1.98169264728643,10.1899998262525,0.0651783330913619,0.0121173431940269,2.5,3.68692126207156E-5,0.00591115219738187,7.22463423134031E-5,58.915226,58.915226,100.09,100.09,52.6778540535633,18.44042242401,27.920998,0,0,0,40,4886,63.8035,100.09,,,,,,,,,,,,,0,,,,3.328318,,,,,,58.915226,,,,
,14598552.955,67.15980145,100.09,0.00590755870637319,1.33306129811886E-6,1,0.999253354069792,40.0298881530762,1.99262141636227,10.1800002157688,0.0657149795419555,0.0121357682679546,2.5,3.53523329745483E-5,0.00592722538107757,6.53485382085043E-5,67.1019821,67.2176208,100.09,100.09,52.6200135431402,18.441764137985,27.920998,0,0,0,40,4886,73.12625,100.09,,,,,,,,,,,,,0,,,,3.6519601,,,,,,67.15980145,,,,
,14598645.845,75.83994295,100.09,0.00589519970466339,2.11492640270987E-6,1,0.999253354069792,40.0298881530762,1.98147028490675,10.1899998262525,0.0652936916179542,0.011975156682331,2.5,3.34740950285736E-5,0.00591976041803171,5.80034558486089E-5,75.7621765,75.9177094,100.09,100.09,52.9975401179287,18.4386402666167,27.539787,0,0,0,40,4886,82.9659,100.09,,,,,,,,,,,,,0,,,,3.7071421,,,,,,75.83994295,,,,
,14598764.465,87.1334381,100.09,0.00588691197485276,1.97707825965249E-6,1,0.999253354069792,40.0298881530762,1.99248324668888,10.1699996739626,0.0655970683838696,0.0119264954165809,2.5,2.95400812190912E-5,0.00591414374049268,4.88474173429678E-5,87.1334381,87.1334381,100.09,100.09,52.4902632089479,18.4308972910901,27.920998,0,0,0,40,4886,95.3793,100.09,,,,,,,,,,,,,0,,,,3.9164791,,,,,,87.1334381,,,,
,14598838.11,94.117115,100.09,0.00588087695132068,1.40827490000014E-6,1,0.999253354069792,40.0298881530762,1.99278337629402,10.1699996739626,0.0655558768670652,0.0118622983245229,2.5,2.69563011400953E-5,0.00590871750479592,4.38538707886304E-5,94.0642776,94.1699524,100.09,100.09,52.5363792915825,18.4399638368154,26.396152,0,0,0,40,4886,103.0137,100.09,,,,,,,,,,,,,0,,,,3.4053066,,,,,,94.117115,,,,
,14598922.96,102.2544174,100.09,0.00586218862970471,1.57415821315087E-6,1,0.999253354069792,40.0298881530762,1.99243868463926,10.1600000634789,0.0653425240153877,0.0118021740792551,2.5,2.72244752545598E-5,0.00589013861475196,4.18375687099145E-5,102.2544174,102.2544174,100.09,100.09,53.0647601705825,18.4368746308878,27.158575,0,0,0,40,4886,112.09485,100.09,,,,,,,,,,,,,0,,,,4.05629435,,,,,,102.2544174,,,,
,14599005.84,110.3687592,100.09,0.00585320612595697,1.39378431601726E-6,1,0.999253354069792,40.0298881530762,1.98170749226095,10.1199997588992,0.0649159986436039,0.011647978584404,2.5,2.21340567217858E-5,0.00588091435637805,3.50013756347641E-5,110.3687592,110.3687592,100.09,100.09,52.7857187892171,18.4370131245524,28.30221,0,0,0,40,4886,120.8964,100.09,,,,,,,,,,,,,0,,,,4.0356307,,,,,,110.3687592,,,,
,14599063.445,116.0587006,100.09,0.00583577053524563,1.91655127848911E-6,1,0.999253354069792,40.0298881530762,1.98167640199823,10.1199997588992,0.0647154198317711,0.0116287353591621,2.5,2.44978586158541E-5,0.00586308666071954,3.63651732543489E-5,116.0587006,116.0587006,100.09,100.09,51.8719950502363,18.4449407881767,27.920998,0,0,0,40,4886,127.0129,100.09,,,,,,,,,,,,,0,,,,3.9955161,,,,,,116.0587006,,,,
,14599147.065,124.3700485,100.09,0.00579932945914408,1.53168387708083E-6,1,0.999253354069792,40.0298881530762,1.99267366215106,10.0999996066093,0.0646574684128276,0.01155603423699,2.5,2.00904421150589E-5,0.00582587301631518,3.06964587305759E-5,124.3700485,124.3700485,100.09,100.09,52.423043156294,18.4410897621033,27.920998,0,0,0,40,4886,135.8328,100.09,,,,,,,,,,,,,0,,,,4.2849197,,,,,,124.3700485,,,,
,14599232.15,132.937027,100.09,0.00580257894824146,1.26758385737698E-6,1,0.999253354069792,40.0298881530762,1.99249407971518,10.0800003856421,0.0646838727466105,0.0115340368878274,2.5,1.87339498695872E-5,0.00582835122489937,2.83765102312826E-5,132.937027,132.937027,100.09,100.09,52.7911901888517,18.4353011281221,27.920998,0,0,0,40,4886,144.707,100.09,,,,,,,,,,,,,0,,,,4.2640488,,,,,,132.937027,,,,
,14599290.36,138.7574615,100.09,0.00578794107825389,1.45716755398401E-6,1,0.999253354069792,40.0298881530762,1.99309767467267,10.0800003856421,0.0645377228793376,0.0114786809658113,2.5,1.66960810972237E-5,0.00581304993874691,2.57443756527614E-5,138.7574615,138.7574615,100.09,100.09,52.3284661054671,18.438957925623,27.920998,0,0,0,40,4886,150.7815,100.09,,,,,,,,,,,,,0,,,,4.3713918,,,,,,138.7574615,,,,
,14599374.875,147.2662125,100.09,0.00576217578136194,1.75505240224409E-6,1,0.999253354069792,40.0298881530762,1.98166512165138,10.0400000810623,0.0638905193074346,0.0113380770398969,2.5,1.50784729273632E-5,0.00578621528094653,2.33874358721744E-5,147.2005463,147.3318787,100.09,100.09,52.8740428118902,18.4377848459891,28.30221,0,0,0,40,4886,159.4922,100.09,,,,,,,,,,,,,0,,,,4.2254555,,,,,,147.2662125,,,,
,14599459.625,155.6448822,100.09,0.00575487166572594,1.20227327249172E-6,1,0.999253354069792,40.0298881530762,1.98168001388789,10.0100003182888,0.0638035112546498,0.0112941626347057,2.5,1.31387690951894E-5,0.00577786021303137,2.0853650732648E-5,155.6448822,155.6448822,100.09,100.09,52.5965646875633,18.4386949174774,27.920998,0,0,0,40,4886,168.0038,100.09,,,,,,,,,,,,,0,,,,4.4596095,,,,,,155.6448822,,,,
,14599516.86,161.3228455,100.09,0.00572890476361527,1.56302739308726E-6,1,0.999253354069792,40.0298881530762,1.98182173353968,10.0100003182888,0.0635152834932336,0.0112234555150529,2.5,1.17014332643626E-5,0.00575106462565477,1.9028442386106E-5,161.3228455,161.3228455,100.09,100.09,52.6950498809863,18.4367094813412,27.158575,0,0,0,40,4886,173.86195,100.09,,,,,,,,,,,,,0,,,,4.52699545,,,,,,161.3228455,,,,
,14599601.115,169.6428528,100.09,0.00570401545204781,2.01241611094321E-6,1,0.999253354069792,40.0298881530762,1.99273489093049,9.99000016599894,0.0635617580714494,0.0112276915523283,2.5,1.17469726595939E-5,0.0057249699245138,1.85948020502085E-5,169.6428528,169.6428528,100.09,100.09,53.3703769216018,18.4430318953567,27.158575,0,0,0,40,4886,182.3822,100.09,,,,,,,,,,,,,0,,,,4.4152803,,,,,,169.6428528,,,,
touchdown = 4.87999990582466 mm,14599684.675,177.9558563,100.09,0.00567170680230503,1.70038626055883E-6,1,0.999253354069792,40.0298881530762,1.98145096144317,9.9499998614192,0.062848214579993,0.0110862660837226,2.5,1.07197558440521E-5,0.00569139207360257,1.71347245695748E-5,177.9558563,177.9558563,100.09,100.09,52.5606097756786,18.4336505644506,27.539787,0,0,0,40,4886,190.9035,100.09,,,,,,,,,,,,,0,,,,4.57290245,,,,,,177.9558563,,,,
,14599741.825,183.5802612,100.09,0.00566019721823688,1.58641756408459E-6,1,0.999253354069792,40.0298881530762,1.98158860434977,9.96000040322542,0.0627178498519098,0.0110522751374843,2.5,9.9692314553714E-6,0.00567904044529266,1.61319638250821E-5,183.5802612,183.5802612,100.09,100.09,52.1596343453132,18.4408805037478,27.920998,0,0,0,40,4886,196.64015,100.09,,,,,,,,,,,,,0,,,,4.2849197,,,,,,183.5802612,,,,
,14599824.985,191.85794835,100.09,0.00564422194433142,1.97490367070116E-6,1,0.999253354069792,40.0298881530762,1.99269010946646,9.92999970912933,0.0628651069275474,0.0110687290214201,2.5,9.42417872481067E-6,0.00566180121000639,1.52534827525116E-5,191.7974854,191.9184113,100.09,100.09,52.1580710882748,18.4385311433616,27.539787,0,0,0,40,4886,205.0417,100.09,,,,,,,,,,,,,0,,,,4.5496073,,,,,,191.85794835,,,,
,14599882.955,197.5396118,100.09,0.00562219456282002,1.56280372178136E-6,1,0.999253354069792,40.0298881530762,1.99268083196125,9.92000009864569,0.0626155181419004,0.0109925785510972,2.5,6.78040924164978E-6,0.0056388599912008,1.23783799266122E-5,197.5396118,197.5396118,100.09,100.09,53.5798533647557,18.4428131639281,27.920998,0,0,0,40,4886,210.94645,100.09,,,,,,,,,,,,,0,,,,4.6880207,,,,,,197.5396118,,,,
,14599967.785,205.98547365,100.09,0.00560979802769006,1.09311156225258E-6,1,0.999253354069792,40.0298881530762,1.98171416342171,9.89999994635582,0.062130732871237,0.0109227826524714,2.5,8.36938998341573E-6,0.00562513911363644,1.36930176578983E-5,205.9125061,206.0584412,100.09,100.09,52.6880152243133,18.4352485489184,27.920998,0,0,0,40,4886,219.5131,100.09,,,,,,,,,,,,,0,,,,4.7115545,,,,,,205.98547365,,,,
,14600051.265,214.317215,100.09,0.00557483724439957,1.88076550479229E-6,1,0.999253354069792,40.0298881530762,1.98156033279432,9.87000018358231,0.0617275255188185,0.010835100178964,2.5,7.07760966357324E-6,0.00558879453605501,1.21292386049889E-5,214.317215,214.317215,100.09,100.09,52.7505455058517,18.441262087443,27.158575,0,0,0,40,4886,227.8808,100.09,,,,,,,,,,,,,0,,,,4.7826281,,,,,,214.317215,,,,
,14600107.195,219.87194825,100.09,0.00556895857413256,1.45317814971842E-6,1,0.999253354069792,40.0298881530762,1.9816456963651,9.85999964177608,0.0616572264066725,0.010811654979528,2.5,6.24309365873975E-6,0.00558202975394591,1.11391563186313E-5,219.822876,219.9210205,100.09,100.09,52.8756060689287,18.4407315546272,27.158575,0,0,0,40,4886,233.56045,100.09,,,,,,,,,,,,,0,,,,4.7826281,,,,,,219.87194825,,,,
,14600189.44,228.088562,100.09,0.0055391451770603,1.30003303426715E-6,1,0.999253354069792,40.0298881530762,1.98196573705411,9.82000026851892,0.0613227939116273,0.0107499341991183,2.5,6.13799877848144E-6,0.00555084515285072,1.08066433757613E-5,228.088562,228.088562,100.09,100.09,52.5355976630632,18.4365894782365,27.920998,0,0,0,40,4886,241.85695,100.09,,,,,,,,,,,,,0,,,,4.78286695,,,,,,228.088562,,,,
,14600271.78,236.12948605,100.09,0.0055256100969198,1.52395268663735E-6,1,0.999253354069792,40.0298881530762,1.98192996303947,9.77999996393919,0.0611604994188238,0.0107047216470068,2.5,4.83960923354518E-6,0.00553599522846932,9.30564991319278E-6,236.0621185,236.1968536,100.09,100.09,52.5613914041979,18.4327022125066,27.158575,0,0,0,40,4886,250.30215,100.09,,,,,,,,,,,,,0,,,,4.8308864,,,,,,236.12948605,,,,
,14600328.04,241.7074738,100.09,0.00550864430516664,1.16216917988874E-6,1,0.999253354069792,40.0298881530762,1.98195554528185,9.78999957442284,0.0609650309558059,0.0106615978163113,2.5,4.15908596486904E-6,0.00551809819498639,8.49290658996926E-6,241.7074738,241.7074738,100.09,100.09,53.0428745720441,18.4394648711392,28.30221,0,0,0,40,4886,255.9124,100.09,,,,,,,,,,,,,0,,,,4.8306456,,,,,,241.7074738,,,,
,14600409.06,249.7937622,100.09,0.00551132369307817,1.41204759750576E-6,1,0.999253354069792,40.0298881530762,1.98169748585205,9.75000020116568,0.0609765487079724,0.0106397736518501,2.5,2.22822896565342E-6,0.00551946758292144,6.40110479937287E-6,249.7937622,249.7937622,100.09,100.09,52.8662265266979,18.4383575536248,27.158575,0,0,0,40,4886,264.03025,100.09,,,,,,,,,,,,,0,,,,4.7826281,,,,,,249.7937622,,,,
,14600463.625,255.1886597,100.09,0.00550580245800643,1.51022453637853E-6,1,0.999253354069792,40.0298881530762,1.981602827496,9.75000020116568,0.0608995725309454,0.0106461308367388,2.5,4.06386762334996E-6,0.00551305393108224,8.13205665318447E-6,255.1886597,255.1886597,100.09,100.09,52.4105370999863,18.4434647894306,27.920998,0,0,0,40,4886,269.5706,100.09,,,,,,,,,,,,,0,,,,4.5952849,,,,,,255.1886597,,,,
,14600546.305,263.477417,100.09,0.00549766698780459,1.38050680190026E-6,1,0.999253354069792,40.0298881530762,1.98163000467279,9.68000013381243,0.0607958429740196,0.0106250087391044,2.5,3.9398866693321E-6,0.00550354565126905,7.85550271388132E-6,263.477417,263.477417,100.09,100.09,52.9334465793518,18.4361995508772,28.30221,0,0,0,40,4886,277.8859,100.09,,,,,,,,,,,,,0,,,,4.9776092,,,,,,263.477417,,,,
,14600627.14,271.54585265,100.09,0.00547557153096913,1.53976486360366E-6,1,0.999253354069792,40.0298881530762,1.98170758528076,9.65000037103891,0.0605416322070911,0.0105656995243263,2.5,2.75022466692027E-6,0.00548010068237961,6.5148215126765E-6,271.4786072,271.6130981,100.09,100.09,52.4675959818902,18.434492692937,27.920998,0,0,0,40,4886,286.0586,100.09,,,,,,,,,,,,,0,,,,4.85634875,,,,,,271.54585265,,,,
,14600684.235,277.1171875,100.09,0.0054529361497883,1.50855228988379E-6,1,0.999253354069792,40.0298881530762,1.98176959974786,9.65000037103891,0.0602818899889837,0.0105273460867816,2.5,3.43903423749249E-6,0.00545653169270281,7.09963201860042E-6,277.1171875,277.1171875,100.09,100.09,53.005356403121,18.4378222974119,28.30221,0,0,0,40,4886,291.8091,100.09,,,,,,,,,,,,,0,,,,4.9776092,,,,,,277.1171875,,,,
,14600766.75,285.3355713,100.09,0.00540308819954435,1.69767976608207E-6,1,0.999253354069792,40.0298881530762,1.98217927296012,9.61999967694282,0.0597311026965174,0.010412108753019,2.5,1.8534558685966E-6,0.00540531356450499,5.35996668811726E-6,285.3355713,285.3355713,100.09,100.09,52.0580226378132,18.4337491105968,27.920998,0,0,0,40,4886,300.0728,100.09,,,,,,,,,,,,,0,,,,4.2849197,,,,,,285.3355713,,,,
,14600836.23,292.1976013,100.09,,,2,,,,9.57300019580126,,,,,,,292.1976013,292.1976013,100.09,100.09,,,27.920998,,,,-99999999,4886,307.1917,100.09,,,,,,,,,,,,,,,,,,,,,,,292.1976013,,,,
,14600903.885,298.9696655,100.09,0.00534809534349746,1.15534172589439E-6,1,0.999253354069792,40.0298881530762,1.98186411674008,9.5600001513958,0.0590916411820605,0.010290213770447,2.5,1.09915672566343E-6,0.0053481035083106,4.38739493830531E-6,298.9696655,298.9696655,100.09,100.09,53.2773631278133,18.4413543002205,27.920998,0,0,0,40,4886,314.02745,100.09,,,,,,,,,,,,,0,,,,4.88011865,,,,,,298.9696655,,,,
,14600985.555,307.07878115,100.09,0.00529590731893741,2.02779919021561E-6,1,0.999253354069792,40.0298881530762,1.99272384992898,9.51999984681606,0.0588079167557658,0.0102430465248699,2.5,1.38023651549015E-6,0.00529462763936332,4.53930539958266E-6,307.0339966,307.1235657,100.09,100.09,53.1468311651018,18.4391218033072,27.539787,0,0,0,40,4886,322.28855,100.09,,,,,,,,,,,,,0,,,,5.0278349,,,,,,307.07878115,,,,
,14601042.24,312.6199341,100.09,0.00527675068101229,1.6806979167966E-6,1,0.999253354069792,40.0298881530762,1.9927581109793,9.53000038862228,0.0585877756200254,0.010196939163863,2.5,7.5934467009115E-7,0.00527460322221986,3.84375144107009E-6,312.6199341,312.6199341,100.09,100.09,52.0384819248324,18.4460194954095,27.158575,0,0,0,40,4886,328.0804,100.09,,,,,,,,,,,,,0,,,,4.6414213,,,,,,312.6199341,,,,
,14601126,320.9421234,100.09,0.00523113242565596,1.08908801088366E-6,1,0.999253354069792,40.0298881530762,1.98188051445642,9.46999993175268,0.0577642200116872,0.0100451348365949,2.5,9.06352854836478E-8,0.00522771145639257,3.06571684113049E-6,320.8823242,321.0019226,100.09,100.09,53.2539142722364,18.4411962231433,27.920998,0,0,0,40,4886,336.2945,100.09,,,,,,,,,,,,,0,,,,4.7350883,,,,,,320.9421234,,,,
,14601209.285,329.0751648,100.09,0.00518410638032025,1.17157919552821E-6,1,0.999253354069792,40.0298881530762,1.9817665438904,9.4200000166893,0.0572285843732432,0.00994892368761608,2.5,-1.0764794779867E-7,0.00517947520521029,2.76819814628068E-6,329.0751648,329.0751648,100.09,100.09,53.2437531014864,18.4343314036889,28.30221,0,0,0,40,4886,344.23765,100.09,,,,,,,,,,,,,0,,,,5.02858735,,,,,,329.0751648,,,,
,14601265.43,334.3997498,100.09,0.00516499229460773,1.11462168973709E-6,1,0.999253354069792,40.0298881530762,1.98171304327644,9.4200000166893,0.0570079382222742,0.0099063902255079,2.5,-4.3034613888361E-7,0.00515957574644247,2.39076588760834E-6,334.3997498,334.3997498,100.09,100.09,53.1530841932556,18.4448599498406,27.920998,0,0,0,40,4886,349.53735,100.09,,,,,,,,,,,,,0,,,,4.7912221,,,,,,334.3997498,,,,
,14601347.855,342.17451475,100.09,0.00511502394941579,1.37499329541161E-6,1,0.999253354069792,40.0298881530762,1.98186409234497,9.37999971210957,0.0564513059882073,0.009789160163333,2.5,-2.17206982666286E-6,0.00510851112516681,5.65986681385352E-7,342.1160583,342.2329712,100.09,100.09,52.8490306992748,18.4441736912133,27.920998,0,0,0,40,4886,357.1802,100.09,,,,,,,,,,,,,0,,,,4.61387085,,,,,,342.17451475,,,,
,14601404.01,347.4103088,100.09,0.00509149688816413,1.30152664658842E-6,1,0.999253354069792,40.0298881530762,1.98178415139004,9.37999971210957,0.0561788352758148,0.00975504906773129,2.5,-9.71360127353532E-7,0.00508425099071006,1.71752624316304E-6,347.4103088,347.4103088,100.09,100.09,52.6458072842748,18.4434531115175,27.920998,0,0,0,40,4886,362.3284,100.09,,,,,,,,,,,,,0,,,,5.2325511,,,,,,347.4103088,,,,
,14601486.765,355.09225465,100.09,0.00504411144320799,1.39007494258204E-6,1,0.999253354069792,40.0298881530762,1.98197068521026,9.30999964475632,0.0556480566789945,0.00966799749533223,2.5,-4.67541634312223E-7,0.00503583780927971,2.15043383160504E-6,355.0477905,355.1367188,100.09,100.09,53.2679835855826,18.4448297825162,27.158575,0,0,0,40,4886,369.83695,100.09,,,,,,,,,,,,,0,,,,5.0275841,,,,,,355.09225465,,,,
,14601569.095,362.6378174,100.09,0.00499999400445939,1.82538427853777E-6,1,0.999253354069792,40.0298881530762,1.98211805242588,9.27000027149916,0.0551538063032491,0.00958138945780283,2.5,-4.91786898362935E-7,0.00499074348274701,2.06621289175339E-6,362.6378174,362.6378174,100.09,100.09,52.6676928828133,18.4359371723205,27.920998,0,0,0,40,4886,377.1863,100.09,,,,,,,,,,,,,0,,,,5.1290436,,,,,,362.6378174,,,,
,14601624.56,367.5801086,100.09,0.00497640514035259,1.35421519309231E-6,1,0.999253354069792,40.0298881530762,1.98210921935533,9.27000027149916,0.0548876693654901,0.00952477293414115,2.5,-1.38267943729871E-6,0.00496652453903671,1.14418226776864E-6,367.5801086,367.5801086,100.09,100.09,52.5488853478902,18.4398453695798,27.920998,0,0,0,40,4886,382.11535,100.09,,,,,,,,,,,,,0,,,,5.2325511,,,,,,367.5801086,,,,
,14601707.46,374.9832153,100.09,0.00493350648335223,1.43517547796377E-6,1,0.999253354069792,40.0298881530762,1.98169059608972,9.20999981462956,0.0543910952979278,0.00944748119957857,2.5,-5.65089145969403E-7,0.00492272501805433,1.91425325780721E-6,374.9832153,374.9832153,100.09,100.09,52.4972978656209,18.4413450517653,26.014942,0,0,0,40,4886,389.31035,100.09,,,,,,,,,,,,,0,,,,5.2850857,,,,,,374.9832153,,,,
,14601760.495,377.8305969,100.09,0.00491336372019949,1.45361927583976E-6,1,0.999253354069792,40.0298881530762,1.98216031072371,9.22000035643578,0.0541770009797022,0.00941151650734,2.5,-4.78905907681655E-7,0.00490225150116883,2.01367070940531E-6,377.8305969,377.8305969,100.09,100.09,53.0702315702172,18.4428363803873,27.539787,0,0,0,40,4886,382.1042,100.09,,,,,,,,,,,,,0,,,,4.77596545,,,,,,377.8305969,,,,
,14601817.255,378.07174685,100.09,0.0048970846774231,1.68889565538313E-6,1,0.999253354069792,40.0298881530762,1.98197471123072,9.20999981462956,0.05399094594018,0.00938724393242081,2.5,2.33914694600817E-7,0.00488597779167312,2.71399287718494E-6,378.0643616,378.0791321,100.09,100.09,52.4574348111402,18.4381195070969,27.920998,0,0,0,40,4886,382.80485,100.09,,,,,,,,,,,,,0,,,,5.2588184,,,,,,378.07174685,,,,
,14601867.76,378.6334839,100.09,0.00489870214714994,1.54725016118349E-6,1,0.999253354069792,40.0298881530762,1.98203044997411,9.20999981462956,0.054013894207155,0.00936476006618042,2.5,-2.10048630640226E-6,0.00488751956141539,3.89429435704978E-7,378.6309204,378.6360474,100.09,100.09,52.7825922751402,18.4395311745355,27.158575,0,0,0,40,4886,381.81085,100.09,,,,,,,,,,,,,0,,,,4.887912,,,,,,378.6334839,,,,
,14601919.64,378.88339235,100.09,0.00488940523441625,1.6701616144253E-6,1,0.999253354069792,40.0298881530762,1.98182670052477,9.20999981462956,0.0539039611442314,0.00935606204519244,2.5,-1.1824684083088E-6,0.00487821119513608,1.29902015265182E-6,378.8806458,378.8861389,100.09,100.09,52.3261212199094,18.4409103069404,27.920998,0,0,0,40,4886,382.23545,100.09,,,,,,,,,,,,,0,,,,5.2850857,,,,,,378.88339235,,,,
,14601971.695,379.3519287,100.09,0.0048910644342611,1.84988973487101E-6,1,0.999253354069792,40.0298881530762,1.98188909249643,9.20999981462956,0.053922003649483,0.00936636466515064,2.5,-5.50933070946151E-7,0.00487980573044139,1.9294091704133E-6,379.3519287,379.3519287,100.09,100.09,52.9584586919671,18.4479961063451,27.920998,0,0,0,40,4886,382.3736,100.09,,,,,,,,,,,,,0,,,,5.0780606,,,,,,379.3519287,,,,
,14602024.04,379.6729126,100.09,0.00488347257021221,1.67341944304362E-6,1,0.999253354069792,40.0298881530762,1.98193482350335,9.20999981462956,0.0538388672067469,0.00935295461979005,2.5,-4.59617952443061E-7,0.00487218987896905,2.0169598700444E-6,379.6706238,379.6752014,100.09,100.09,52.6145421435056,18.4459802361133,27.158575,0,0,0,40,4885,382.2904,100.09,,,,,,,,,,,,,0,,,,5.25934335,,,,,,379.6729126,,,,
,14602076.385,379.8787537,100.09,0.00488755103326458,1.70432106363818E-6,1,0.999253354069792,40.0298881530762,1.98216426810736,9.20999981462956,0.0538916141312038,0.00934973428226286,2.5,-1.55068775382556E-6,0.00487623289151482,9.30920737790045E-7,379.8787537,379.8787537,100.09,100.09,52.7138089654479,18.4459893109964,27.920998,0,0,0,40,4885,382.1712,100.09,,,,,,,,,,,,,0,,,,5.28534935,,,,,,379.8787537,,,,
,14602119.25,379.9859924,100.09,0.00488928686370296,1.43020563030428E-6,1,0.999253354069792,40.0298881530762,1.98207426767853,9.22000035643578,0.0539094230144496,0.00934587950995233,2.5,-2.16308435165131E-6,0.00487795115228038,3.21232150715733E-7,379.9859924,379.9859924,100.09,100.09,52.2417053398324,18.4430464928724,27.158575,0,0,0,40,4881,382.0623,100.09,,,,,,,,,,,,,0,,,,5.3381476,,,,,,379.9859924,,,,