File: 2023 VSM Calibration/PD-2173_CALIBRATION_17_11_2023_55000GAUSS.DAT
[Header]
; VSM Data File (default extension .dat)
; Copyright (c) 2003-2013, Quantum Design, Inc. All rights reserved.
TITLE,
FILEOPENTIME,7640192.56,11/17/2023,11:52 am
BYAPP,VSM,2.0,2.0
INFO,PPMS VSM Option Release 1.4.10 Build 1,APPNAME
INFO,Quantum Design Linear Motor Servo Controller,MOTOR_MODULE_NAME
INFO,3101-100 C1,MOTOR_HW_VERSION
INFO,074,MOTOR_SERIAL_NUMBER
INFO,SRV No X-over 01.01.11,MOTOR_SOFTWARE_VERSION
INFO,Quantum Design VSM Detection Module,VSM_MODULE_NAME
INFO,3101-150 E1,VSM_HW_VERSION
INFO,VSM061,VSM_SERIAL_NUMBER
INFO,VSM No X-over 01.02.05 May 20 2008 13:51:47,VSM_SOFTWARE_VERSION
INFO,113,PREAMP_SERIAL_NUMBER
INFO,Quantum Design VSM Oven,OVEN_MODULE_NAME
INFO,3101-200 B0,OVEN_HW_VERSION
INFO,OVN054,OVEN_SERIAL_NUMBER
INFO,01.01.00,OVEN_SOFTWARE_VERSION
INFO,818,COIL_SERIAL_NUMBER
INFO,0,MOMENT_UNITS
INFO,Palladium,SAMPLE_MATERIAL
INFO,Silindrical sample shape,SAMPLE_COMMENT
INFO,314.3,SAMPLE_MASS
INFO,,SAMPLE_VOLUME
INFO,,SAMPLE_MOLECULAR_WEIGHT
INFO,,SAMPLE_SIZE
INFO,,SAMPLE_SHAPE
DATATYPE,COMMENT,1
DATATYPE,TIME,2
STARTUPAXIS,X,2
STARTUPAXIS,Y1,5
[Data]
Comment,Time Stamp (sec),Temperature (K),Magnetic Field (Oe),Moment (emu),M. Std. Err. (emu),Transport Action,Averaging Time (sec),Frequency (Hz),Peak Amplitude (mm),Center Position (mm),Coil Signal' (mV),Coil Signal" (mV),Range (mV),M. Quad. Signal (emu),M. Raw' (emu),M. Raw" (emu),Min. Temperature (K),Max. Temperature (K),Min. Field (Oe),Max. Field (Oe),Mass (grams),Motor Lag (deg),Pressure (Torr),VSM Status (code),Motor Status (code),Measure Status (code),Measure Count,PPMS Status (code),System Temp. (K),System Field (Oe),Sample Position (deg),Bridge 1 Resistance (ohms),Bridge 1 Excitation (에),Bridge 2 Resistance (ohms),Bridge 2 Excitation (에),Bridge 3 Resistance (ohms),Bridge 3 Excitation (에),Bridge 4 Resistance (ohms),Bridge 4 Excitation (에),Signal 1 Vin (V),Signal 2 Vin (V),Digital Inputs (code),Drive 1 Iout (mA),Drive 1 Ipower (W),Drive 2 Iout (mA),Drive 2 Ipower (W),Pressure (),Map 20 (),Map 21 (),Map 22 (),Map 23 (),Map 24 (),Map 25 (),Map 26 (),Map 27 (),Map 28 (),Map 29 ()
,7640685.265,298.01979065,54998.6815,0.0895803822938702,4.74470755192711E-6,1,4.99626677034896,40.0298881530762,1.99221227541239,8.7500000372529,0.994916719239969,0.172359677664184,2.5,-6.30168400858513E-5,0.0895828303612775,-4.73941779055139E-6,298.0192566,298.0203247,54998.371,54998.992,52.1901178575632,18.4033284805053,32.876747,0,0,0,200,4417,297.947,54998.6815,,,,,,,,,,,,,0,,,,41.0453148,,,,,,298.01979065,,,,
,7640755.18,298.01426695,52498.363,0.0854379109818649,4.50564895582543E-6,1,4.99626677034896,40.0298881530762,1.99222548289367,8.74000042676926,0.94892035156431,0.164358935687597,2.5,-6.29455102834821E-5,0.0854402601831343,-7.34530049679246E-6,298.0141296,298.0144043,52497.949,52498.777,52.4058473288709,18.4036121985778,33.257957,0,0,0,200,4417,297.93965,52498.363,,,,,,,,,,,,,0,,,,48.8007145,,,,,,298.01426695,,,,
,7640830.135,298.0035248,49997.9315,0.0813455272639305,5.54067417913966E-6,1,4.99626677034896,40.0298881530762,1.99231152833074,8.74000042676926,0.903501182586826,0.156519332566591,2.5,-5.75609430918684E-5,0.0813477873312286,-4.60876475174879E-6,298.0028687,298.0041809,49996.242,49999.621,52.2831316513517,18.4066620846781,32.495537,0,0,0,200,4417,297.94045,49997.9315,,,,,,,,,,,,,0,,,,49.5319519,,,,,,298.0035248,,,,
,7640905.075,297.9983368,47497.7245,0.0772645082524912,4.47222235655321E-6,1,4.99626677034896,40.0298881530762,1.99228440317771,8.74000042676926,0.858168573095303,0.148629508981056,2.5,-5.78834846882721E-5,0.0772666677211131,-7.57370896967592E-6,297.9978333,297.9988403,47497.582,47497.867,52.4058473288709,18.4079008603848,33.257957,0,0,0,200,4417,297.94105,47497.7245,,,,,,,,,,,,,0,,,,41.319685,,,,,,297.9983368,,,,
,7640982.54,297.9962158,44998.7265,0.0732020146221095,4.12781539571932E-6,1,4.99626677034896,40.0298881530762,1.99225054940548,8.74000042676926,0.813031258589361,0.140826363240742,2.5,-5.35966741279726E-5,0.0732040632427731,-5.92028376200337E-6,297.9960022,297.9964294,44998.461,44998.992,52.4886999519094,18.4091769857711,32.495537,0,0,0,200,4417,297.94975,44998.7265,,,,,,,,,,,,,0,,,,41.62246705,,,,,,297.9962158,,,,
,7641064.96,297.9942627,42499.2185,0.0691305966372539,3.63446066610781E-6,1,4.99626677034896,40.0298881530762,1.99228458015534,8.74000042676926,0.767823969339967,0.13299575052815,2.5,-5.06440058943136E-5,0.0691325342394845,-5.60764471517787E-6,297.9940796,297.9944458,42498.664,42499.773,52.4543082970632,18.411086037014,33.257957,0,0,0,200,4417,297.9548,42499.2185,,,,,,,,,,,,,0,,,,40.64260485,,,,,,297.9942627,,,,
,7641139.91,297.9937286,39996.6055,0.0650385229094756,2.94467868096506E-6,1,4.99626677034896,40.0298881530762,1.99233250371053,8.74000042676926,0.722410381513565,0.125012089260125,2.5,-5.79299019251559E-5,0.0650403524021831,-1.55481346445366E-5,297.9936218,297.9938354,39996.598,39996.613,52.4668143533709,18.4103851957152,32.495537,0,0,0,200,4417,297.95585,39996.6055,,,,,,,,,,,,,0,,,,38.6927624,,,,,,297.9937286,,,,
,7641214.885,297.9968262,37498.666,0.0609657290707405,3.27478858778358E-6,1,4.99626677034896,40.0298881530762,1.99236059208492,8.74000042676926,0.677182405651229,0.117178420078316,2.5,-5.49274856369522E-5,0.0609674376218564,-1.51892052456534E-5,297.9960938,297.9975586,37497.406,37499.926,52.4832285522748,18.4127683690191,32.114323,0,0,0,200,4417,297.9578,37498.666,,,,,,,,,,,,,0,,,,48.09111405,,,,,,297.9968262,,,,
,7641289.825,297.99415585,34996.799,0.056906122406147,2.82239809547729E-6,1,4.99626677034896,40.0298881530762,1.99233722325131,8.74000042676926,0.63207171054336,0.109438707828068,2.5,-4.54964423096588E-5,0.0569077170364809,-8.39434491944085E-6,297.9938354,297.9944763,34995.672,34997.926,52.568426060871,18.4139405645441,32.495537,0,0,0,200,4417,297.9594,34996.799,,,,,,,,,,,,,0,,,,44.64557265,,,,,,297.99415585,,,,
,7641364.765,297.995224,32497.9885,0.0528421309530848,3.23735463282625E-6,1,4.99626677034896,40.0298881530762,1.99234567875045,8.7500000372529,0.586926353084559,0.101668688956727,2.5,-3.81828298859817E-5,0.0528436066400757,-3.72336729963711E-6,297.9952087,297.9952393,32497.84,32498.137,52.5715525749479,18.4145407012899,33.257957,0,0,0,200,4417,297.97565,32497.9885,,,,,,,,,,,,,0,,,,46.73410035,,,,,,297.995224,,,,
,7641434.695,297.99269105,29997.137,0.0487512681625995,2.49099859007332E-6,1,4.99626677034896,40.0298881530762,1.99239205487277,8.7500000372529,0.541515612233738,0.0937135144157944,2.5,-4.30168297395383E-5,0.0487526375592158,-1.12167583053757E-5,297.9922791,297.993103,29995.848,29998.426,52.7950983314479,18.4138690519417,32.876747,0,0,0,200,4417,297.97375,29997.137,,,,,,,,,,,,,0,,,,49.0420456,,,,,,297.99269105,,,,
,7641509.65,297.99131775,27498.59,0.0446929013234714,2.59057057620564E-6,1,4.99626677034896,40.0298881530762,1.99236751759154,8.74000042676926,0.496417914826993,0.0859837953211603,2.5,-3.29045692322771E-5,0.044694153690477,-3.74534513057364E-6,297.9913025,297.991333,27497.742,27499.438,52.7458557347364,18.4150921821741,32.876747,0,0,0,200,4417,297.98485,27498.59,,,,,,,,,,,,,0,,,,43.0042286,,,,,,297.99131775,,,,
,7641584.615,297.99414065,24998.414,0.0406143656955161,1.99289112175699E-6,1,4.99626677034896,40.0298881530762,1.99233105954456,8.74000042676926,0.451114930295408,0.0780982249380046,2.5,-3.32912464378439E-5,0.0406155019180115,-6.78720687405468E-6,297.9933472,297.9949341,24998.262,24998.566,52.5699893179094,18.4154918534709,33.257957,0,0,0,200,4417,297.99255,24998.414,,,,,,,,,,,,,0,,,,45.9707527,,,,,,297.99414065,,,,
,7641659.595,297.99482725,22498.5,0.0365350597999812,1.97282236051585E-6,1,4.99626677034896,40.0298881530762,1.99240621924358,8.74000042676926,0.405824666946356,0.0702275900003334,2.5,-3.256383963465E-5,0.0365360822325366,-8.71586219175314E-6,297.9946899,297.9949646,22497.928,22499.072,52.7286599073133,18.4162427596409,33.257957,0,0,0,200,4417,297.9908,22498.5,,,,,,,,,,,,,0,,,,49.0420456,,,,,,297.99482725,,,,
,7641734.535,297.99412535,19998.241,0.0324494927430925,1.55486340024588E-6,1,4.99626677034896,40.0298881530762,1.99234372418691,8.74000042676926,0.360438628286078,0.0623349601305404,2.5,-3.23022274803512E-5,0.0324504033040497,-1.1116888101321E-5,297.9940796,297.9941711,19998.123,19998.359,52.4253880418517,18.417312719515,33.257957,0,0,0,200,4417,298.001,19998.241,,,,,,,,,,,,,0,,,,46.24419405,,,,,,297.99412535,,,,
,7641809.405,297.99479675,17499.641,0.0283845364964739,1.7404250982815E-6,1,4.99626677034896,40.0298881530762,1.99237385871666,8.74000042676926,0.315282525289666,0.0545754661426072,2.5,-2.38990726586379E-5,0.02838532912315,-5.36310450877654E-6,297.9943848,297.9952087,17499.225,17500.057,52.7442924776979,18.4196437613886,32.495537,0,0,0,200,4417,298.0007,17499.641,,,,,,,,,,,,,0,,,,45.83927155,,,,,,297.99479675,,,,
,7641884.37,297.99641415,14998.212,0.0243010152064611,1.29329396915837E-6,1,4.99626677034896,40.0298881530762,1.99238082598409,8.74000042676926,0.269927057539983,0.0467152954100547,2.5,-2.12624772628134E-5,0.0243016927770962,-5.38965857671912E-6,297.9960632,297.9967651,14998.081,14998.343,52.8013513596017,18.4203864081043,32.114323,0,0,0,200,4417,298.0025,14998.212,,,,,,,,,,,,,0,,,,41.37384225,,,,,,297.99641415,,,,
,7641969.29,297.99494935,12500.2695,0.020228384344969,1.38961936369943E-6,1,4.99626677034896,40.0298881530762,1.99230919379791,8.74000042676926,0.224679108837182,0.0389013872722006,2.5,-1.6216771220165E-5,0.0202289480015003,-3.00121270517512E-6,297.9946594,297.9952393,12500.258,12500.281,52.609070743871,18.4191375242171,33.257957,0,0,0,200,4417,298.0043,12500.2695,,,,,,,,,,,,,0,,,,43.3481121,,,,,,297.99494935,,,,
,7642054.24,297.99491885,10000.06,0.0161424433865865,9.24443560859215E-7,1,4.99626677034896,40.0298881530762,1.9923587539025,8.7500000372529,0.179301633247563,0.0310370082441869,2.5,-1.36102498037987E-5,0.0161428934456153,-3.06219242491293E-6,297.9947815,297.9950562,10000.021,10000.099,52.5824953742171,18.4204225637802,33.257957,0,0,0,200,4417,298.0119,10000.06,,,,,,,,,,,,,0,,,,43.30288695,,,,,,297.99491885,,,,
,7642129.155,297.99534605,7500.377,0.012050064803573,6.64880742376249E-7,1,4.99626677034896,40.0298881530762,1.99233781084783,8.7500000372529,0.133846124831058,0.0231580388845786,2.5,-1.10919387727281E-5,0.0120504010747072,-3.21659930488107E-6,297.9951477,297.9955444,7500.266,7500.488,52.6278298283325,18.4206755486804,32.114323,0,0,0,200,4417,298.01775,7500.377,,,,,,,,,,,,,0,,,,49.0420456,,,,,,297.99534605,,,,
,7642204.125,297.99876405,5000.271,0.00796901128408268,5.68468803339181E-7,1,4.99626677034896,40.0298881530762,1.99241916472886,8.74000042676926,0.0885208250719774,0.0153066448032266,2.5,-8.14208939699021E-6,0.00796923326077322,-2.93286250827653E-6,297.9984741,297.999054,5000.221,5000.321,52.7255333932363,18.4226225554463,33.257957,0,0,0,200,4417,298.01295,5000.271,,,,,,,,,,,,,0,,,,49.0420456,,,,,,297.99876405,,,,
,7642279.11,297.99568175,2500.336,0.00387983420364097,2.98712530668344E-7,1,4.99626677034896,40.0298881530762,1.99241196449039,8.74000042676926,0.0431077324770336,0.00747016994220823,0.25,-2.55200625283099E-6,0.00387994167457878,-1.53755006698324E-8,297.9944153,297.9969482,2500.296,2500.376,52.5402874341786,18.4226300993262,33.639168,0,0,0,200,4417,298.0162,2500.336,,,,,,,,,,,,,0,,,,49.2906704,,,,,,297.99568175,,,,
,7642364.01,297.99768065,0.1075,-0.000221391120386144,1.47904557855558E-7,1,4.99626677034896,40.0298881530762,1.99247017408447,8.74000042676926,-0.00245641827130023,-0.000446187273982649,0.25,-1.64670207057629E-6,-0.000221396065701606,-1.7915137144008E-6,297.9968872,297.9984741,0.107,0.108,52.6942682524671,18.4246505473076,32.495537,0,0,0,200,4417,298.0187,0.1075,,,,,,,,,,,,,0,,,,49.28575135,,,,,,297.99768065,,,,