File: 2023 VSM Calibration/Pd-2173_CALIBRATION_15_11_2023_10000GAUSS.DAT
[Header]
; VSM Data File (default extension .dat)
; Copyright (c) 2003-2013, Quantum Design, Inc. All rights reserved.
TITLE,Pd-2173_calibration_15_11_2023
FILEOPENTIME,7464868.80,11/15/2023,11:10 am
BYAPP,VSM,2.0,2.0
INFO,PPMS VSM Option Release 1.4.10 Build 1,APPNAME
INFO,Quantum Design Linear Motor Servo Controller,MOTOR_MODULE_NAME
INFO,3101-100 C1,MOTOR_HW_VERSION
INFO,074,MOTOR_SERIAL_NUMBER
INFO,SRV No X-over 01.01.11,MOTOR_SOFTWARE_VERSION
INFO,Quantum Design VSM Detection Module,VSM_MODULE_NAME
INFO,3101-150 E1,VSM_HW_VERSION
INFO,VSM061,VSM_SERIAL_NUMBER
INFO,VSM No X-over 01.02.05 May 20 2008 13:51:47,VSM_SOFTWARE_VERSION
INFO,113,PREAMP_SERIAL_NUMBER
INFO,Quantum Design VSM Oven,OVEN_MODULE_NAME
INFO,3101-200 B0,OVEN_HW_VERSION
INFO,OVN054,OVEN_SERIAL_NUMBER
INFO,01.01.00,OVEN_SOFTWARE_VERSION
INFO,818,COIL_SERIAL_NUMBER
INFO,0,MOMENT_UNITS
INFO,Palladium,SAMPLE_MATERIAL
INFO,Silindrical sample shape,SAMPLE_COMMENT
INFO,314.3,SAMPLE_MASS
INFO,,SAMPLE_VOLUME
INFO,,SAMPLE_MOLECULAR_WEIGHT
INFO,,SAMPLE_SIZE
INFO,,SAMPLE_SHAPE
DATATYPE,COMMENT,1
DATATYPE,TIME,2
STARTUPAXIS,X,2
STARTUPAXIS,Y1,5
[Data]
Comment,Time Stamp (sec),Temperature (K),Magnetic Field (Oe),Moment (emu),M. Std. Err. (emu),Transport Action,Averaging Time (sec),Frequency (Hz),Peak Amplitude (mm),Center Position (mm),Coil Signal' (mV),Coil Signal" (mV),Range (mV),M. Quad. Signal (emu),M. Raw' (emu),M. Raw" (emu),Min. Temperature (K),Max. Temperature (K),Min. Field (Oe),Max. Field (Oe),Mass (grams),Motor Lag (deg),Pressure (Torr),VSM Status (code),Motor Status (code),Measure Status (code),Measure Count,PPMS Status (code),System Temp. (K),System Field (Oe),Sample Position (deg),Bridge 1 Resistance (ohms),Bridge 1 Excitation (에),Bridge 2 Resistance (ohms),Bridge 2 Excitation (에),Bridge 3 Resistance (ohms),Bridge 3 Excitation (에),Bridge 4 Resistance (ohms),Bridge 4 Excitation (에),Signal 1 Vin (V),Signal 2 Vin (V),Digital Inputs (code),Drive 1 Iout (mA),Drive 1 Ipower (W),Drive 2 Iout (mA),Drive 2 Ipower (W),Pressure (),Map 20 (),Map 21 (),Map 22 (),Map 23 (),Map 24 (),Map 25 (),Map 26 (),Map 27 (),Map 28 (),Map 29 ()
,7466461.745,298.0059814,9999.8025,0.0164646411896592,2.36984695146805E-6,1,0.999253354069792,40.0298881530762,1.9922347287901,8.74000042676926,0.182854903525227,0.0317382445952676,2.5,-6.34919558142503E-6,0.0164650898274747,4.40927262620647E-6,298.0059814,298.0059814,9999.692,9999.913,52.0916326641401,18.4167322726335,32.495537,0,0,0,40,4417,298.0196,9999.8025,,,,,,,,,,,,,0,,,,10.2192116,,,,,,298.0059814,,,,
,7466517.115,298.0010986,9166.8525,0.0150792120551488,2.26771356125691E-6,1,0.999253354069792,40.0298881530762,1.99236134007407,8.74000042676926,0.167475139304762,0.0290897120635367,2.5,-3.98531751697377E-6,0.0150796238858877,5.86880496850989E-6,298.0010986,298.0010986,9166.852,9166.853,52.748200620294,18.4222297577531,32.495537,0,0,0,40,4417,298.0144,9166.8525,,,,,,,,,,,,,0,,,,10.37310935,,,,,,298.0010986,,,,
,7466564.93,298.0022583,8333.613,0.0136935003029566,2.01587412470506E-6,1,0.999253354069792,40.0298881530762,1.99222741246888,8.74000042676926,0.152076794521778,0.0264051541178306,2.5,-4.48763517947674E-6,0.0136938743286149,4.4613687983488E-6,298.0022583,298.0022583,8333.486,8333.74,51.7586589149478,18.4263855764428,32.495537,0,0,0,40,4417,298.01865,8333.613,,,,,,,,,,,,,0,,,,10.1689291,,,,,,298.0022583,,,,
,7466617.705,298.00102235,7500.1755,0.012311261991901,1.92731744100014E-6,1,0.999253354069792,40.0298881530762,1.992350493051,8.74000042676926,0.136735011997561,0.0237358719659896,2.5,-4.51423142558701E-6,0.0123115989955506,3.53184432159443E-6,297.9989014,298.0031433,7500.111,7500.24,52.0087800411017,18.4321713737749,31.733112,0,0,0,40,4417,298.0226,7500.1755,,,,,,,,,,,,,0,,,,9.6477375,,,,,,298.00102235,,,,
,7466672.3,298.0042267,6666.797,0.010923150639163,1.51227426273463E-6,1,0.999253354069792,40.0298881530762,1.99235606411153,8.74000042676926,0.121318901152261,0.0210560365493375,2.5,-4.3335249013201E-6,0.0109234487301176,2.8060195411171E-6,298.0039978,298.0044556,6666.722,6666.872,52.067402180044,18.4283906138421,32.495537,0,0,0,40,4417,298.01485,6666.797,,,,,,,,,,,,,0,,,,10.27102425,,,,,,298.0042267,,,,
,7466728.74,298.0016174,5833.5815,0.00953938807857343,1.31598467594591E-6,1,0.999253354069792,40.0298881530762,1.99245029725576,8.74000042676926,0.105954754976241,0.0183899374538884,2.5,-3.74186185784293E-6,0.00953964909155961,2.49363831349211E-6,298.0016174,298.0016174,5833.496,5833.667,52.2440502253901,18.431816489859,32.495537,0,0,0,40,4417,298.0145,5833.5815,,,,,,,,,,,,,0,,,,10.32335665,,,,,,298.0016174,,,,
,7466783.21,297.9978333,5000.091,0.00815781589214577,1.55994178780507E-6,1,0.999253354069792,40.0298881530762,1.99246603350493,8.7500000372529,0.0906087143234013,0.0157353164433727,2.5,-2.42237467992715E-6,0.00815803949881203,2.91037251651736E-6,297.9978333,297.9978333,4999.966,5000.216,52.1799566868132,18.4335319940664,32.495537,0,0,0,40,4417,298.01575,5000.091,,,,,,,,,,,,,0,,,,10.4772544,,,,,,297.9978333,,,,
,7466838.755,298.00009155,4166.7955,0.00677743466657515,1.19452769930341E-6,1,0.999253354069792,40.0298881530762,1.99231151544504,8.74000042676926,0.0752733958248016,0.0130593891045826,2.5,-3.12815151736831E-6,0.00677762067086218,1.30252510886173E-6,297.9994202,298.0007629,4166.77,4166.821,52.0955408067363,18.4314427939318,32.876747,0,0,0,40,4417,298.013,4166.7955,,,,,,,,,,,,,0,,,,9.9817014,,,,,,298.00009155,,,,
,7466888.505,298.0021973,3333.8095,0.00539533361779925,9.03887179489275E-7,1,0.999253354069792,40.0298881530762,1.99243261426293,8.74000042676926,0.0599246102702587,0.0104083671369274,2.5,-1.4519695966007E-6,0.00539548065100197,2.07536756486255E-6,298.0021973,298.0021973,3333.809,3333.81,52.4871366948709,18.4347466477012,32.876747,0,0,0,40,4417,298.0155,3333.8095,,,,,,,,,,,,,0,,,,10.424922,,,,,,298.0021973,,,,
,7466936,297.9981079,2500.42,0.00401240508027689,7.98070489044909E-7,1,0.999253354069792,40.0298881530762,1.99251406048015,8.74000042676926,0.0445685255798279,0.00772930021630385,2.5,-2.1157893259843E-6,0.00401251558896617,5.07505261976204E-7,297.9981079,297.9981079,2500.362,2500.478,52.3605128747555,18.4329271533546,33.639168,0,0,0,40,4417,298.0186,2500.42,,,,,,,,,,,,,0,,,,10.5295868,,,,,,297.9981079,,,,
,7466990.83,297.9981995,1666.7395,0.00263218149589155,5.42614533385518E-7,1,0.999253354069792,40.0298881530762,1.99253650897907,8.74000042676926,0.0292378029364115,0.00507028234881143,2.5,-1.41303752882788E-6,0.00263225399396757,3.07929666532081E-7,297.9981995,297.9981995,1666.725,1666.754,51.7617854290247,18.4331293408104,32.495537,0,0,0,40,4417,298.0229,1666.7395,,,,,,,,,,,,,0,,,,10.58244515,,,,,,297.9981995,,,,
,7467045.135,297.9984436,833.329,0.00125145696742819,3.81693108359385E-7,1,0.999253354069792,40.0298881530762,1.99249427141637,8.74000042676926,0.0139066484360459,0.00240091019744161,0.25,-1.60812132242362E-6,0.00125149203388884,-7.8986944469105E-7,297.9984436,297.9984436,833.329,833.329,52.3886515014479,18.4382225509294,33.639168,0,0,0,40,4417,298.0183,833.329,,,,,,,,,,,,,0,,,,10.4772544,,,,,,297.9984436,,,,
,7467100.795,297.9983368,0.2865,-0.000129343493298815,3.97618373433886E-7,1,0.999253354069792,40.0298881530762,1.99251262738415,8.74000042676926,-0.00143251664233746,-0.000275785913723546,0.25,-2.32157987966914E-6,-0.000129345491238848,-2.40621778674854E-6,297.9983215,297.9983521,0.243,0.33,52.5621730327171,18.4364024748467,32.114323,0,0,0,40,4417,298.02595,0.2865,,,,,,,,,,,,,0,,,,10.0698581,,,,,,297.9983368,,,,
,7467155.665,298.0024719,-833.1265,-0.00150874297270846,4.65584108592121E-7,1,0.999253354069792,40.0298881530762,1.9924598267202,8.74000042676926,-0.0167564920299594,-0.00294581006126905,0.25,-2.68306676098784E-6,-0.00150878203992099,-3.66969071613581E-6,298.0021057,298.0028381,-833.154,-833.099,52.2385788257555,18.4417110309961,32.495537,0,0,0,40,4417,298.0124,-833.1265,,,,,,,,,,,,,0,,,,10.5295868,,,,,,298.0024719,,,,
,7467211.305,297.9978333,-1666.5485,-0.00288178207732886,5.85093161370009E-7,1,0.999253354069792,40.0298881530762,1.9924961636205,8.7500000372529,-0.0320015656276377,-0.00559773224298602,2.5,-2.66310552279915E-6,-0.0028818587267395,-4.54740607822286E-6,297.9978333,297.9978333,-1666.633,-1666.464,51.5226071021401,18.4408567039546,32.114323,0,0,0,40,4417,298.0195,-1666.5485,,,,,,,,,,,,,0,,,,10.4772544,,,,,,297.9978333,,,,
,7467266.965,297.9992981,-2499.748,-0.00424961352437327,3.95411806576989E-7,1,0.999253354069792,40.0298881530762,1.99263148866338,8.7500000372529,-0.0471995863949268,-0.00822373716783799,2.5,-1.09284667237833E-6,-0.00424972824010618,-3.87125260949498E-6,297.9992981,297.9992981,-2499.777,-2499.719,52.1205529193517,18.4377453913431,32.114323,0,0,0,40,4417,298.0245,-2499.748,,,,,,,,,,,,,0,,,,10.6886921,,,,,,297.9992981,,,,
,7467322.59,297.99383545,-3333.1255,-0.0056124673124678,5.49808322693504E-7,1,0.999253354069792,40.0298881530762,1.99254001927527,8.74000042676926,-0.0623329844533685,-0.0108652518862644,2.5,-1.86065344248564E-6,-0.00561261949163228,-5.52992843879174E-6,297.9935303,297.9941406,-3333.136,-3333.115,53.0084829171979,18.4391877697602,32.876747,0,0,0,40,4417,298.02315,-3333.1255,,,,,,,,,,,,,0,,,,9.7601385,,,,,,297.99383545,,,,
,7467378.575,297.99784855,-4166.5365,-0.00697246641424361,5.34128227402212E-7,1,0.999253354069792,40.0298881530762,1.99254398831139,8.74000042676926,-0.077439729234169,-0.0134852851506853,2.5,-1.15657077090613E-6,-0.00697265541268566,-5.71459358052185E-6,297.9976807,297.9980164,-4166.56,-4166.513,52.9389179789864,18.4422717096054,32.876747,0,0,0,40,4417,298.02805,-4166.5365,,,,,,,,,,,,,0,,,,9.8581295,,,,,,297.99784855,,,,
,7467434.8,297.99554445,-4999.745,-0.00833441310619805,1.09298253533534E-6,1,0.999253354069792,40.0298881530762,1.99259139850724,8.74000042676926,-0.0925702514157702,-0.0161086341372152,2.5,-3.80829412407397E-7,-0.00833464029495548,-5.82879693427154E-6,297.9937134,297.9973755,-4999.844,-4999.646,52.5168385786017,18.4434882839128,32.114323,0,0,0,40,4417,298.02955,-4999.745,,,,,,,,,,,,,0,,,,10.6353035,,,,,,297.99554445,,,,
,7467483.755,297.99693295,-5832.813,-0.00969167442940858,1.06478025257985E-6,1,0.999253354069792,40.0298881530762,1.99247989505628,8.74000042676926,-0.107641389961529,-0.0187204047864558,2.5,5.03761136619023E-7,-0.00969193887468224,-5.83091915099249E-6,297.9969177,297.9969482,-5832.877,-5832.749,52.2393604542748,18.4402123000893,32.876747,0,0,0,40,4417,298.0325,-5832.813,,,,,,,,,,,,,0,,,,10.4783001,,,,,,297.99693295,,,,
,7467540.485,298.0002441,-6666.5775,-0.0110361931721388,1.28829306362109E-6,1,0.999253354069792,40.0298881530762,1.99255924227546,8.7500000372529,-0.122576243977382,-0.0213345219427603,2.5,-8.8868236010942E-7,-0.0110364922838985,-8.10179175502925E-6,298.0002441,298.0002441,-6666.621,-6666.534,52.2049687994286,18.4380061900638,32.876747,0,0,0,40,4417,298.03105,-6666.5775,,,,,,,,,,,,,0,,,,10.4296036,,,,,,298.0002441,,,,
,7467596.68,298.0003052,-7499.9005,-0.012396185826355,1.23290964769935E-6,1,0.999253354069792,40.0298881530762,1.99251409082589,8.74000042676926,-0.137678240392782,-0.023963696833159,2.5,-1.05594195994688E-6,-0.0123965217727841,-9.1575773099704E-6,298.0003052,298.0003052,-7499.986,-7499.815,52.4191350136979,18.4414273794952,32.495537,0,0,0,40,4417,298.02555,-7499.9005,,,,,,,,,,,,,0,,,,10.7420807,,,,,,298.0003052,,,,
,7467645.895,297.9999695,-8333.2045,-0.0137501815770339,1.52854378353986E-6,1,0.999253354069792,40.0298881530762,1.99256371326795,8.74000042676926,-0.152720605424937,-0.0265785842468064,2.5,-8.81625968117938E-7,-0.0137505546270491,-9.86738688482017E-6,297.9999695,297.9999695,-8333.222,-8333.187,52.5371609201017,18.4441241557359,32.114323,0,0,0,40,4417,298.03075,-8333.2045,,,,,,,,,,,,,0,,,,9.7256484,,,,,,297.9999695,,,,
,7467701.67,298.002655,-9166.4435,-0.0151096974812695,2.15296882045451E-6,1,0.999253354069792,40.0298881530762,1.99258230062237,8.7500000372529,-0.167824511459789,-0.0291921486704678,2.5,3.44058283006404E-7,-0.0151101070986744,-9.52958627096786E-6,298.002655,298.002655,-9166.483,-9166.404,52.6676928828133,18.4445782527465,32.495537,0,0,0,40,4417,298.0271,-9166.4435,,,,,,,,,,,,,0,,,,10.8499308,,,,,,298.002655,,,,
,7467753.025,298.0024414,-9999.653,-0.0164561249384112,1.8723260560947E-6,1,0.999253354069792,40.0298881530762,1.99265649688373,8.74000042676926,-0.182786401683779,-0.0317917642002021,2.5,6.29454713823722E-7,-0.0164565713986555,-1.01233519477817E-5,298.0024414,298.0024414,-9999.711,-9999.595,52.5418506912171,18.4458612645477,32.876747,0,0,0,40,4417,298.0255,-9999.653,,,,,,,,,,,,,0,,,,10.8499308,,,,,,298.0024414,,,,
,7467806.265,298.0014954,-9166.7505,-0.015069751647107,1.56260882408368E-6,1,0.999253354069792,40.0298881530762,1.99259363967247,8.74000042676926,-0.167382968554206,-0.029108124449544,2.5,9.74223852001244E-7,-0.0150701611119536,-8.87341017342172E-6,298.0014954,298.0014954,-9166.906,-9166.595,52.7575801625248,18.4431289409552,32.876747,0,0,0,40,4417,298.0243,-9166.7505,,,,,,,,,,,,,0,,,,10.5295868,,,,,,298.0014954,,,,
,7467861.135,298.0001831,-8333.43,-0.0136839501775366,1.13257826133333E-6,1,0.999253354069792,40.0298881530762,1.99252948574444,8.74000042676926,-0.151985181244782,-0.0264346051261541,2.5,5.20223812207906E-7,-0.013684322232928,-8.42243715560595E-6,297.9996033,298.0007629,-8333.457,-8333.403,52.8146390444287,18.4472619419625,32.876747,0,0,0,40,4417,298.02455,-8333.43,,,,,,,,,,,,,0,,,,10.6886921,,,,,,298.0001831,,,,
,7467909.895,297.9980469,-7500.2915,-0.0122982540797403,1.45956139369559E-6,1,0.999253354069792,40.0298881530762,1.99259183489163,8.74000042676926,-0.136598619674424,-0.0237583830214366,2.5,4.72889425730469E-7,-0.0122985892067419,-7.5647023545108E-6,297.9980469,297.9980469,-7500.348,-7500.235,52.4035024433132,18.4493216280729,32.114323,0,0,0,40,4417,298.0255,-7500.2915,,,,,,,,,,,,,0,,,,9.155283,,,,,,297.9980469,,,,
,7467957.795,297.9984741,-6667.0145,-0.0109164122316125,8.0167540033815E-7,1,0.999253354069792,40.0298881530762,1.99280234085479,8.74000042676926,-0.121264368707571,-0.021080664918076,2.5,1.35121106420881E-6,-0.0109167101359807,-5.78358750540529E-6,297.9984741,297.9984741,-6667.015,-6667.014,52.2112218275824,18.4408189454157,32.876747,0,0,0,40,4417,298.02975,-6667.0145,,,,,,,,,,,,,0,,,,10.7420807,,,,,,297.9984741,,,,
,7468012.285,298.001709,-5833.3885,-0.00953319806120121,9.69281654392943E-7,1,0.999253354069792,40.0298881530762,1.99296146226588,8.74000042676926,-0.105906802347451,-0.0184127031817771,2.5,1.02286117033996E-6,-0.00953345711340627,-5.20856117510924E-6,298.001709,298.001709,-5833.446,-5833.331,53.0264603731402,18.4411360189386,32.876747,0,0,0,40,4417,298.01875,-5833.3885,,,,,,,,,,,,,0,,,,9.9571047,,,,,,298.001709,,,,
,7468061.655,297.999176,-5000.2135,-0.00815103785645134,1.39648932007275E-6,1,0.999253354069792,40.0298881530762,1.99282448767576,8.74000042676926,-0.0905445394768767,-0.015750862489285,2.5,8.77305384565853E-8,-0.00815125945384715,-5.24032895018691E-6,297.999176,297.999176,-5000.257,-5000.17,52.7099008228517,18.4407240445051,32.495537,0,0,0,40,4417,298.03085,-5000.2135,,,,,,,,,,,,,0,,,,10.58878235,,,,,,297.999176,,,,
,7468109.675,298.0003967,-4166.982,-0.00676772174465695,8.65366770614351E-7,1,0.999253354069792,40.0298881530762,1.99287334091135,8.74000042676926,-0.0751799200639396,-0.0130782624786486,2.5,5.71526436393109E-8,-0.00676790543349468,-4.3670778115435E-6,298.0002441,298.0005493,-4166.985,-4166.979,52.6739459109671,18.4442966816474,30.208265,0,0,0,40,4417,298.0232,-4166.982,,,,,,,,,,,,,0,,,,10.5343161,,,,,,298.0003967,,,,
,7468165.195,298.0011292,-3333.587,-0.00538628001378072,7.41855496933994E-7,1,0.999253354069792,40.0298881530762,1.99277610386917,8.74000042676926,-0.0598298150480506,-0.010416368921059,2.5,-6.88623351942907E-7,-0.00538642559079853,-4.20996083195106E-6,298.0011292,298.0011292,-3333.6,-3333.574,52.1838648294094,18.4448298562429,32.495537,0,0,0,40,4417,298.0254,-3333.587,,,,,,,,,,,,,0,,,,10.2802501,,,,,,298.0011292,,,,
,7468219.885,298.0028076,-2499.986,-0.00400424848350717,5.67064103170042E-7,1,0.999253354069792,40.0298881530762,1.99271742830622,8.74000042676926,-0.0444764316810625,-0.00774791190406425,2.5,-9.10780632107588E-7,-0.00400435622500661,-3.5287919357041E-6,298.0028076,298.0028076,-2499.986,-2499.986,52.9561138064094,18.4448740449178,32.876747,0,0,0,40,4417,298.0217,-2499.986,,,,,,,,,,,,,0,,,,10.7970834,,,,,,298.0028076,,,,
,7468274.915,297.99723815,-1666.8655,-0.00262331447395902,3.37780227456547E-7,1,0.999253354069792,40.0298881530762,1.99278008365346,8.74000042676926,-0.0291352437397962,-0.00509680660873176,2.5,-2.46387681691568E-6,-0.00262338427476852,-4.17912946969238E-6,297.9964294,297.9980469,-1666.893,-1666.838,52.3988126721978,18.4416194419052,32.495537,0,0,0,40,4417,298.0262,-1666.8655,,,,,,,,,,,,,0,,,,10.850472,,,,,,297.99723815,,,,
,7468323.47,297.9972534,-833.5155,-0.00124236883551343,3.14846672301539E-7,1,0.999253354069792,40.0298881530762,1.99284899218311,8.74000042676926,-0.0138017492518475,-0.0024198998688899,0.25,-1.64502681219328E-6,-0.00124240157565274,-2.45739511426731E-6,297.9971313,297.9973755,-833.626,-833.405,52.5418506912171,18.4499099150183,32.495537,0,0,0,40,4417,298.02745,-833.5155,,,,,,,,,,,,,0,,,,10.79600575,,,,,,297.9972534,,,,
,7468385.305,297.9976196,-0.039,0.000140758555241095,3.15313603907173E-7,1,0.999253354069792,40.0298881530762,1.99278623018269,8.74000042676926,0.00156733675621107,0.000253088947162681,0.25,-1.71021214947667E-6,0.00014076350304897,-1.61822220647391E-6,297.9976196,297.9976196,-0.04,-0.038,52.5981279446017,18.4481724213329,32.495537,0,0,0,40,4417,298.03245,-0.039,,,,,,,,,,,,,0,,,,10.0410619,,,,,,297.9976196,,,,
,7468453.365,298.0001831,833.206,0.00151779878329983,4.63906180201182E-7,1,0.999253354069792,40.0298881530762,1.9927077739013,8.74000042676926,0.0168663516769852,0.00292205314148126,0.25,-1.06208613196172E-6,0.00151784065681922,-6.97125349373867E-8,298.0001831,298.0001831,833.178,833.234,53.1413597654671,18.4442042429479,33.639168,0,0,0,40,4417,298.03025,833.206,,,,,,,,,,,,,0,,,,10.90548515,,,,,,298.0001831,,,,
,7468502.475,298.0014648,1666.426,0.00289147329647451,7.04117388055166E-7,1,0.999253354069792,40.0298881530762,1.9929669898253,8.74000042676926,0.0321242965995711,0.00557276637146029,2.5,-1.38425387030129E-6,0.00289155254527132,5.06200449497813E-7,298.0014648,298.0014648,1666.412,1666.44,52.8888937537556,18.4423275945593,32.495537,0,0,0,40,4417,298.02915,1666.426,,,,,,,,,,,,,0,,,,9.8340397,,,,,,298.0014648,,,,
,7468557.925,298.00024415,2499.8985,0.00425610199934369,8.25731388413026E-7,1,0.999253354069792,40.0298881530762,1.99285156404043,8.74000042676926,0.0472819561464929,0.00820671007197049,2.5,-1.64714574208424E-6,0.00425621855943212,1.13544113372056E-6,298.0001221,298.0003662,2499.857,2499.94,52.5668628038325,18.4367523019745,33.257957,0,0,0,40,4417,298.0233,2499.8985,,,,,,,,,,,,,0,,,,11.0688896,,,,,,298.00024415,,,,
,7468614.675,297.9996338,3333.1285,0.0056202088686252,1.12083188467536E-6,1,0.999253354069792,40.0298881530762,1.9928517593789,8.74000042676926,0.0624360524951556,0.0108374077851375,2.5,-2.13916997050264E-6,0.00562036289831584,1.53495056565387E-6,297.9996338,297.9996338,3333.089,3333.168,52.6426807701979,18.4400308616588,30.208265,0,0,0,40,4417,298.0304,3333.1285,,,,,,,,,,,,,0,,,,10.8499308,,,,,,297.9996338,,,,
,7468669.96,297.9991455,4166.475,0.00698208543269017,1.27774486606141E-6,1,0.999253354069792,40.0298881530762,1.99279726582283,8.7500000372529,0.0775628445007175,0.0134662633490325,2.5,-2.37721686988118E-6,0.00698227672516608,2.18703319747436E-6,297.9991455,297.9991455,4166.475,4166.475,53.0069196601595,18.4392869368616,31.733112,0,0,0,40,4417,298.0261,4166.475,,,,,,,,,,,,,0,,,,11.0688896,,,,,,297.9991455,,,,
,7468724.805,297.9972229,4999.789,0.00833946586208228,1.43594948524755E-6,1,0.999253354069792,40.0298881530762,1.99283249726836,8.7500000372529,0.0926442827330428,0.0160790705163745,2.5,-3.32767988417917E-6,0.0083396951975232,2.12340563558259E-6,297.9969788,297.997467,4999.786,4999.792,52.0783449793132,18.4404070004565,32.495537,0,0,0,40,4417,298.0334,4999.789,,,,,,,,,,,,,0,,,,9.9571047,,,,,,297.9972229,,,,
,7468781.135,298.0012817,5833.2635,0.00969756463298855,1.17596513507127E-6,1,0.999253354069792,40.0298881530762,1.99286879560777,8.7500000372529,0.107732805725764,0.0187016600932924,2.5,-3.53111168900477E-6,0.00969782993819007,2.80735818009384E-6,298.0012817,298.0012817,5833.235,5833.292,52.4793204096786,18.4389643470315,32.876747,0,0,0,40,4417,298.0316,5833.2635,,,,,,,,,,,,,0,,,,10.59300805,,,,,,298.0012817,,,,
,7468831.135,298.0003357,6666.2885,0.0110522148345191,1.5761920905436E-6,1,0.999253354069792,40.0298881530762,1.99284956831659,8.74000042676926,0.122782262017898,0.0213057229932455,2.5,-4.75933028208053E-6,0.0110525180544404,2.46397669987879E-6,298.0003357,298.0003357,6666.161,6666.416,52.4066289573901,18.4382057099305,32.495537,0,0,0,40,4417,298.03525,6666.2885,,,,,,,,,,,,,0,,,,10.39485595,,,,,,298.0003357,,,,
,7468887.295,297.9984131,7499.8985,0.0124104610198729,2.12718606919942E-6,1,0.999253354069792,40.0298881530762,1.99286159441909,8.74000042676926,0.137873282847564,0.0239180871318899,2.5,-5.89394967237497E-6,0.0124108026366048,2.21653792498561E-6,297.9984131,297.9984131,7499.842,7499.955,52.4269512988902,18.4385275836561,32.114323,0,0,0,40,4417,298.0345,7499.8985,,,,,,,,,,,,,0,,,,8.9741783,,,,,,297.9984131,,,,
,7468944.105,298.0028076,8333.09,0.0137626160906361,2.3762555679203E-6,1,0.999253354069792,40.0298881530762,1.99281193475073,8.74000042676926,0.152894939572867,0.0265024508901059,2.5,-8.42098456540152E-6,0.0137629943740751,5.72658503267183E-7,298.0028076,298.0028076,8333.09,8333.09,52.8670081552171,18.4408010337442,32.876747,0,0,0,40,4417,298.0305,8333.09,,,,,,,,,,,,,0,,,,11.0688896,,,,,,298.0028076,,,,
,7469000.46,298.00318905,9166.627,0.015117018466134,1.84434324628616E-6,1,0.999253354069792,40.0298881530762,1.99272114167704,8.74000042676926,0.167929235117563,0.0291381619862114,2.5,-6.65341375442147E-6,0.0151174321697965,3.2247513153147E-6,298.0028381,298.00354,9166.603,9166.651,53.0827376265248,18.4410337953232,32.114323,0,0,0,40,4417,298.02945,9166.627,,,,,,,,,,,,,0,,,,11.0688896,,,,,,298.00318905,,,,
,7469055.485,298.00665285,9999.874,0.0164714212539163,2.61865088129121E-6,1,0.999253354069792,40.0298881530762,1.99270424535724,8.7500000372529,0.182974270498161,0.0317428093357192,2.5,-7.76311874073457E-6,0.0164718707006398,2.99937979668987E-6,298.0064392,298.0068665,9999.815,9999.933,53.0327134012941,18.44899131117,32.876747,0,0,0,40,4417,298.02805,9999.874,,,,,,,,,,,,,0,,,,10.08794835,,,,,,298.00665285,,,,