File: DataFailid_Testimiseks/1_CooFe2O4_700degC_Hys_at300K_2TSweep_19062023.DAT
[Header]
; VSM Data File (default extension .dat)
; Copyright (c) 2003-2013, Quantum Design, Inc. All rights reserved.
TITLE,1_CoFe2O4_700degC_Hys_at300K_2TSweep_19062023
FILEOPENTIME,26122407.64,06/19/2023,10:51 am
BYAPP,VSM,2.0,2.0
INFO,PPMS VSM Option Release 1.4.10 Build 1,APPNAME
INFO,Quantum Design Linear Motor Servo Controller,MOTOR_MODULE_NAME
INFO,3101-100 C1,MOTOR_HW_VERSION
INFO,074,MOTOR_SERIAL_NUMBER
INFO,SRV No X-over 01.01.11,MOTOR_SOFTWARE_VERSION
INFO,Quantum Design VSM Detection Module,VSM_MODULE_NAME
INFO,3101-150 E1,VSM_HW_VERSION
INFO,VSM061,VSM_SERIAL_NUMBER
INFO,VSM No X-over 01.02.05 May 20 2008 13:51:47,VSM_SOFTWARE_VERSION
INFO,113,PREAMP_SERIAL_NUMBER
INFO,Quantum Design VSM Oven,OVEN_MODULE_NAME
INFO,3101-200 B0,OVEN_HW_VERSION
INFO,OVN054,OVEN_SERIAL_NUMBER
INFO,01.01.00,OVEN_SOFTWARE_VERSION
INFO,818,COIL_SERIAL_NUMBER
INFO,0,MOMENT_UNITS
INFO,1_CooFe2O4_700degC_Hys_at300K_2TSweep_19062023,SAMPLE_MATERIAL
INFO,granular powder in plastic holder,SAMPLE_COMMENT
INFO,39.4,SAMPLE_MASS
INFO,,SAMPLE_VOLUME
INFO,,SAMPLE_MOLECULAR_WEIGHT
INFO,,SAMPLE_SIZE
INFO,,SAMPLE_SHAPE
DATATYPE,COMMENT,1
DATATYPE,TIME,2
STARTUPAXIS,X,2
STARTUPAXIS,Y1,5
[Data]
Comment,Time Stamp (sec),Temperature (K),Magnetic Field (Oe),Moment (emu),M. Std. Err. (emu),Transport Action,Averaging Time (sec),Frequency (Hz),Peak Amplitude (mm),Center Position (mm),Coil Signal' (mV),Coil Signal" (mV),Range (mV),M. Quad. Signal (emu),M. Raw' (emu),M. Raw" (emu),Min. Temperature (K),Max. Temperature (K),Min. Field (Oe),Max. Field (Oe),Mass (grams),Motor Lag (deg),Pressure (Torr),VSM Status (code),Motor Status (code),Measure Status (code),Measure Count,PPMS Status (code),System Temp. (K),System Field (Oe),Sample Position (deg),Bridge 1 Resistance (ohms),Bridge 1 Excitation (에),Bridge 2 Resistance (ohms),Bridge 2 Excitation (에),Bridge 3 Resistance (ohms),Bridge 3 Excitation (에),Bridge 4 Resistance (ohms),Bridge 4 Excitation (에),Signal 1 Vin (V),Signal 2 Vin (V),Digital Inputs (code),Drive 1 Iout (mA),Drive 1 Ipower (W),Drive 2 Iout (mA),Drive 2 Ipower (W),Pressure (),Map 20 (),Map 21 (),Map 22 (),Map 23 (),Map 24 (),Map 25 (),Map 26 (),Map 27 (),Map 28 (),Map 29 ()
,26123648.905,300.0174561,49998.195,0.556583716662856,7.11582485443118E-5,1,0.999253354069792,40.0298881530762,1.9913848720881,9.8099997267127,6.19397982354324,1.08021299017475,250,0.000236512736064916,0.556565173092644,0.000595580108968012,300.0174561,300.0174561,49997.777,49998.613,52.2206013698132,18.4007122545716,38.976128,0,0,0,40,4417,300.20845,49998.195,,,,,,,,,,,,,0,,,,9.7213078,,,,,,300.0174561,,,,
,26123738.155,300.0165405,41635.8595,0.550659847229883,6.69847204749483E-5,1,0.999253354069792,40.0298881530762,1.99154861402057,9.82000026851892,6.12847712940104,1.06915378277434,250,0.000265376597020701,0.550641457012265,0.000621005345230694,300.0165405,300.0165405,41627.668,41644.051,52.7786841325441,18.3979234870794,38.976128,0,0,0,40,4449,300.1709,41635.8595,,,,,,,,,,,,,0,,,,9.8184195,,,,,,300.0165405,,,,
,26123864.9,300.0097961,29014.4785,0.540418164358785,7.33018632979265E-5,1,0.999253354069792,40.0298881530762,1.99153629598645,9.8099997267127,6.0145784900799,1.04857599497107,250,0.000198292650338647,0.540400219569469,0.000547771860501724,300.0097961,300.0097961,28995.693,29033.264,53.0545989998325,18.4010087673745,38.594913,0,0,0,40,4449,300.17425,29014.4785,,,,,,,,,,,,,0,,,,9.8184195,,,,,,300.0097961,,,,
,26123989.025,300.0003052,16609.984,0.526367724626909,6.77142987843484E-5,1,0.999253354069792,40.0298881530762,1.99161943628898,9.82000026851892,5.85819988938141,1.02273546477567,250,0.000316763190344313,0.52635027667634,0.000657553273822256,300.0003052,300.0003052,16609.984,16609.984,52.2760969946786,18.4071001502489,38.594913,0,0,0,40,4449,300.18125,16609.984,,,,,,,,,,,,,0,,,,9.8184195,,,,,,300.0003052,,,,
,26124113.27,299.9945374,4031.572,0.481652563076076,7.92949224783896E-5,1,0.999253354069792,40.0298881530762,1.99150838469766,9.8099997267127,5.36052070459149,0.934289128456462,250,0.000153448075331845,0.481636736511702,0.000465618379402869,299.9945374,299.9945374,4020.272,4042.872,52.0228493544478,18.4057434487779,38.976128,0,0,0,40,4449,300.1786,4031.572,,,,,,,,,,,,,0,,,,9.86770725,,,,,,299.9945374,,,,
,26124240.89,299.9988708,-8467.2495,-0.506926805615768,5.87235995108451E-5,1,0.999253354069792,40.0298881530762,1.99166776271625,9.82000026851892,-5.62899150024068,-0.981206793997257,25,-0.000172604771394612,-0.506910087047511,-0.000501036404018514,299.9988708,299.9988708,-8467.673,-8466.826,51.8430747950247,18.4135029700947,38.976128,0,0,0,40,4449,300.1862,-8467.2495,,,,,,,,,,,,,0,,,,9.536139,,,,,,299.9988708,,,,
,26124371.315,300.01023865,-20895.1115,-0.531129691798276,6.02626935440165E-5,1,0.999253354069792,40.0298881530762,1.9918357840052,9.8099997267127,-5.89824087008266,-1.02801406290617,25,-0.000170149545638965,-0.531112035094104,-0.000513910352047097,300.0101929,300.0102844,-20956.266,-20833.957,52.6176686575825,18.4037768565981,38.594913,0,0,0,40,4449,300.1659,-20895.1115,,,,,,,,,,,,,0,,,,9.72276305,,,,,,300.01023865,,,,
,26124500.76,300.0185242,-33386.459,-0.543550996878494,6.86115133222968E-5,1,0.999253354069792,40.0298881530762,1.99181401216152,9.82000026851892,-6.03603327045715,-1.05252134691307,25,-0.000217476157055532,-0.543532805387589,-0.00056885766043215,300.0185242,300.0185242,-33395.922,-33376.996,51.5960801829478,18.4147732766027,38.976128,0,0,0,40,4449,300.1481,-33386.459,,,,,,,,,,,,,0,,,,9.96677825,,,,,,300.0185242,,,,
,26124630.405,300.0206909,-45936.0975,-0.553418567595027,5.40422825540168E-5,1,0.999253354069792,40.0298881530762,1.99190733128349,9.8099997267127,-6.14608078305997,-1.07056301762099,25,-0.000121546361281073,-0.553400116217849,-0.000478895368597264,300.0206909,300.0206909,-45944.574,-45927.621,52.5879667738517,18.4106233859113,38.594913,0,0,0,40,4449,300.09685,-45936.0975,,,,,,,,,,,,,0,,,,10.1171265,,,,,,300.0206909,,,,
,26124729.8,300.0168762,-45663.17,-0.553462273172199,7.78654759963508E-5,1,0.999253354069792,40.0298881530762,1.99185301409975,9.82000026851892,-6.14614628683018,-1.07211309394056,25,-0.000255986564701876,-0.553443793241146,-0.000613400323795469,300.0168762,300.0168762,-45680.965,-45645.375,52.4160084996209,18.411607868147,38.976128,0,0,0,40,4449,300.07545,-45663.17,,,,,,,,,,,,,0,,,,9.9174905,,,,,,300.0168762,,,,
,26124852.46,300.0014038,-33303.773,-0.544012430058866,4.48468779758986E-5,1,0.999253354069792,40.0298881530762,1.99175045517246,9.82000026851892,-6.04106205944696,-1.05288584568742,25,-0.000172784396799767,-0.543994524157099,-0.00052456161343777,300.000946,300.0018616,-33303.773,-33303.773,53.269546842621,18.4081191689074,38.213703,0,0,0,40,4449,300.08115,-33303.773,,,,,,,,,,,,,0,,,,9.6734753,,,,,,300.0014038,,,,
,26124976.82,299.99272155,-20767.1195,-0.53177020413949,5.93504177944333E-5,1,0.999253354069792,40.0298881530762,1.99170169791956,9.8099997267127,-5.90479821476498,-1.03020740954812,25,-0.000262065030231587,-0.531752738460732,-0.000606336855855469,299.9925842,299.9928589,-20825.729,-20708.51,53.0022298890441,18.4067390950295,38.594913,0,0,0,40,4449,300.09585,-20767.1195,,,,,,,,,,,,,0,,,,9.1352482,,,,,,299.99272155,,,,
,26125600.49,300.0075531,19559.342,0.529530816710675,2.73818740148782E-5,1,4.99626677034896,40.0298881530762,1.99135776702535,9.8099997267127,5.87896334017376,1.02565321174123,25,0.000256791772981131,0.529513181669091,0.000599692519678659,300.0074768,300.0076294,19266.004,19852.68,52.4246064133325,18.3781985640037,37.832493,0,0,0,200,4449,300.0666,19559.342,,,,,,,,,,,,,0,,,,9.3075376,,,,,,300.0075531,,,,
,26125615.43,300.00790405,17787.0235,0.527096866249708,2.96510238450258E-5,1,4.99626677034896,40.0298881530762,1.99124709395037,9.82000026851892,5.85185531201693,1.01958382344984,25,0.000138410497116754,0.527079376849036,0.000479795198619816,300.0071411,300.008667,17496.934,18077.113,51.9407783599286,18.3902485437262,38.594913,0,0,0,200,4449,300.0669,17787.0235,,,,,,,,,,,,,0,,,,9.33538915,,,,,,300.00790405,,,,
,26125630.395,300.00671385,16072.7545,0.52450376181154,3.58572077565858E-5,1,4.99626677034896,40.0298881530762,1.99152253319256,9.8099997267127,5.82379330106407,1.01496633072486,25,0.000161432153818817,0.524486356182884,0.000501193614979999,300.0066833,300.0067444,15803.851,16341.658,52.3980310436786,18.3922329363795,38.594913,0,0,0,200,4449,300.06425,16072.7545,,,,,,,,,,,,,0,,,,9.96976185,,,,,,300.00671385,,,,
,26125645.36,300.00697325,14418.9305,0.521679806624428,2.93788862186439E-5,1,4.99626677034896,40.0298881530762,1.9915282649076,9.8099997267127,5.79241949198068,1.00970046593901,25,0.000178165869596937,0.521662474320151,0.0005161454952471,300.0062866,300.0076599,14148.048,14689.813,52.0853796359863,18.3914462240872,38.976128,0,0,0,200,4449,300.0659,14418.9305,,,,,,,,,,,,,0,,,,10.2187014,,,,,,300.00697325,,,,
,26125660.35,300.00712585,12800.699,0.518593744240154,3.34402928371217E-5,1,4.99626677034896,40.0298881530762,1.99156243607587,9.82000026851892,5.75818835221921,1.00408901431526,25,0.000208135022651737,0.518576486767405,0.000544165356990773,300.0059204,300.0083313,12533.207,13068.191,52.7794657610633,18.3887286125254,38.594913,0,0,0,200,4449,300.0634,12800.699,,,,,,,,,,,,,0,,,,10.1171265,,,,,,300.00712585,,,,
,26125675.36,300.0061951,11226.953,0.515089089943033,3.38934585896566E-5,1,4.99626677034896,40.0298881530762,1.99147673390346,9.82000026851892,5.71924224208402,0.99609165401371,25,0.000101256033818466,0.515072026873506,0.000435068808401843,300.0056763,300.0067139,10972.877,11481.029,52.0103432981401,18.3975414666218,38.976128,0,0,0,200,4449,300.05975,11226.953,,,,,,,,,,,,,0,,,,7.92869305,,,,,,300.0061951,,,,
,26125690.385,300.0054932,9669.3055,0.510816454590334,4.07166580528774E-5,1,4.99626677034896,40.0298881530762,1.99158872592824,9.82000026851892,5.67199917629235,0.988504674252058,25,0.000156415352593804,0.510799503785697,0.000487494907612891,300.0044556,300.0065308,9407.743,9930.868,52.5488853478902,18.3938622042079,38.976128,0,0,0,200,4449,300.0639,9669.3055,,,,,,,,,,,,,0,,,,10.16791395,,,,,,300.0054932,,,,
,26125705.31,300.0032349,8120.41,0.50543570254639,0.000346612392176772,1,4.99626677034896,40.0298881530762,1.99130848944587,9.82000026851892,5.61214639485929,0.97421791001373,25,-0.000182334683111132,0.505419178523117,0.000145315902171579,300.0023804,300.0040894,7871.982,8368.838,52.036918667794,18.397604470456,38.976128,0,0,0,200,4449,300.05895,8120.41,,,,,,,,,,,,,0,,,,10.01706075,,,,,,300.0032349,,,,
,26125720.345,300.0015564,6575.75,0.498092547301673,0.000512698490896317,1,4.99626677034896,40.0298881530762,1.9915145081539,9.82000026851892,5.53080841541448,0.962180961617388,25,2.3338310878315E-6,0.498076166978378,0.000325254300248005,300.0014038,300.001709,6320.118,6831.382,52.6489337983517,18.3974727649861,38.976128,0,0,0,200,4449,300.06105,6575.75,,,,,,,,,,,,,0,,,,9.21061565,,,,,,300.0015564,,,,
,26125735.39,300.0006714,5009.194,0.488719054662615,9.12314604610446E-5,1,4.99626677034896,40.0298881530762,1.99145342430553,9.82000026851892,5.42609140949666,0.94677333181744,25,0.000247871257327762,0.488702833344126,0.00056473728935531,300.0001221,300.0012207,4743.11,5275.278,52.595783059044,18.3956554817386,38.213703,0,0,0,200,4449,300.066,5009.194,,,,,,,,,,,,,0,,,,10.066844,,,,,,300.0006714,,,,
,26125750.335,299.99993895,3460.707,0.473273504943298,0.000683328267181428,1,4.99626677034896,40.0298881530762,1.99149427665765,9.8099997267127,5.254407423495,0.918596473088057,25,0.000395538901814814,0.473257702388803,0.000702420314144139,299.9997253,300.0001526,3210.723,3710.691,52.0924142926594,18.3969507106916,38.976128,0,0,0,200,4449,300.0646,3460.707,,,,,,,,,,,,,0,,,,10.11763145,,,,,,299.99993895,,,,
,26125765.335,299.99954225,1928.171,0.439272896983591,0.000483432948275626,1,4.99626677034896,40.0298881530762,1.99155177375076,9.82000026851892,4.87841714858714,0.8448184078781,25,-0.000336103042845619,0.439258688405591,-5.12197252917782E-5,299.9990845,300,1660.813,2195.529,52.2972009646978,18.3982293830368,38.594913,0,0,0,200,4449,300.0665,1928.171,,,,,,,,,,,,,0,,,,9.77059555,,,,,,299.99954225,,,,
,26125780.28,299.99833675,404.9475,0.323218369932533,0.00216689517033911,1,4.99626677034896,40.0298881530762,1.9915259981608,9.82000026851892,3.58789477821012,0.63089796410699,25,0.000588916446175443,0.323207382972921,0.000798523801124191,299.9972839,299.9993896,161.457,648.438,52.3534782180825,18.4013241939271,38.976128,0,0,0,200,4449,300.06675,404.9475,,,,,,,,,,,,,0,,,,9.6869922,,,,,,299.99833675,,,,
,26125795.27,299.99827575,-1092.998,-0.391311447792082,0.0011918526930951,1,4.99626677034896,40.0298881530762,1.99162000956167,9.8099997267127,-4.34656932951076,-0.748849313646707,25,0.000637425106530986,-0.391299023716573,0.000383624886420329,299.9982605,299.998291,-1331.404,-854.592,52.0119065551786,18.3989154977746,38.976128,0,0,0,200,4449,300.06805,-1092.998,,,,,,,,,,,,,0,,,,8.97596935,,,,,,299.99827575,,,,
,26125810.345,299.99882505,-2575.5465,-0.459287991649745,0.00053922828572024,1,4.99626677034896,40.0298881530762,1.99164610869465,9.8099997267127,-5.09964806248961,-0.890720499685332,25,-0.000312150390784223,-0.459272717163907,-0.00060997421844994,299.9986572,299.9989929,-2786.128,-2364.965,52.4879183233902,18.3920880977832,38.976128,0,0,0,200,4449,300.0719,-2575.5465,,,,,,,,,,,,,0,,,,10.066844,,,,,,299.99882505,,,,
,26125825.225,299.9967804,-4008.514,-0.480582137224941,0.000497499872883436,1,4.99626677034896,40.0298881530762,1.99153590221124,9.82000026851892,-5.33421934125034,-0.941066604792816,25,-0.00114604066036414,-0.480565654903356,-0.00145762673102179,299.9961853,299.9973755,-4252.143,-3764.885,52.1862097149671,18.4009095254607,38.976128,0,0,0,200,4449,300.0634,-4008.514,,,,,,,,,,,,,0,,,,10.1171265,,,,,,299.9967804,,,,
,26125840.235,299.99749755,-5412.0965,-0.491552555989488,0.00116924701488061,1,4.99626677034896,40.0298881530762,1.99167619748379,9.8099997267127,-5.45926764138768,-0.94586501189632,25,0.000335990646652199,-0.491536668511266,1.72801507962853E-5,299.9952698,299.9997253,-5638.212,-5185.981,52.639554256121,18.4006782217968,38.976128,0,0,0,200,4449,300.06805,-5412.0965,,,,,,,,,,,,,0,,,,9.4342871,,,,,,299.99749755,,,,
,26125855.205,299.99339295,-6819.4875,-0.501627190091076,0.00101890866740055,1,4.99626677034896,40.0298881530762,1.99162792987992,9.82000026851892,-5.56896110622194,-0.97711871551022,25,-0.000727893968622381,-0.501610349494701,-0.00105305839229978,299.9925232,299.9942627,-7035.856,-6603.119,52.7521087628902,18.4053471948566,38.213703,0,0,0,200,4449,300.07505,-6819.4875,,,,,,,,,,,,,0,,,,10.0678482,,,,,,299.99339295,,,,
,26125870.195,299.995163,-8235.489,-0.507096513343841,0.000464249769294599,1,4.99626677034896,40.0298881530762,1.99172975551128,9.8099997267127,-5.6309650075968,-0.982021648901378,25,-0.000213657335160446,-0.507079803558559,-0.000542353965929025,299.9943848,299.9959412,-8473.043,-7997.935,52.5465404623325,18.39295581699,38.976128,0,0,0,200,4449,300.07025,-8235.489,,,,,,,,,,,,,0,,,,10.2187014,,,,,,299.995163,,,,
,26125885.215,299.99783325,-9662.6445,-0.511488892781668,3.62100739828015E-5,1,4.99626677034896,40.0298881530762,1.99156994536453,9.82000026851892,-5.67939812349794,-0.989898602640016,25,-0.000165768105939749,-0.511472033979913,-0.00049726636127692,299.9969177,299.9987488,-9904.575,-9420.714,53.3961706627364,18.4036360462875,38.976128,0,0,0,200,4449,300.077,-9662.6445,,,,,,,,,,,,,0,,,,8.8655305,,,,,,299.99783325,,,,
,26125900.22,299.99989315,-11080.3355,-0.515222860282121,3.64195255470573E-5,1,4.99626677034896,40.0298881530762,1.99176705967046,9.82000026851892,-5.72140379765548,-0.997206670193888,25,-0.000165844232660999,-0.515205850548716,-0.000499728025060853,299.9993896,300.0003967,-11331.869,-10828.802,52.1291508330632,18.4019518003029,38.976128,0,0,0,200,4449,300.07325,-11080.3355,,,,,,,,,,,,,0,,,,10.01856045,,,,,,299.99989315,,,,
,26125915.17,300.002243,-12498.7285,-0.518440272043111,3.7227947441309E-5,1,4.99626677034896,40.0298881530762,1.99178961683941,9.82000026851892,-5.75714324637271,-1.00373882825728,25,-0.000193394038197786,-0.518423105572966,-0.000529327390349702,300.0021667,300.0023193,-12743.907,-12253.55,52.4879183233902,18.398589993045,38.594913,0,0,0,200,4449,300.0686,-12498.7285,,,,,,,,,,,,,0,,,,10.01856045,,,,,,300.002243,,,,
,26125930.195,300.0032501,-13928.2785,-0.52132439218151,2.84749931339474E-5,1,4.99626677034896,40.0298881530762,1.99156833663977,9.82000026851892,-5.78858846467835,-1.00901518867635,25,-0.000176495863499956,-0.521307129243638,-0.000514266544350118,300.0031738,300.0033264,-14161.593,-13694.964,52.3339375051017,18.4029972386846,38.213703,0,0,0,200,4449,300.061,-13928.2785,,,,,,,,,,,,,0,,,,10.16791395,,,,,,300.0032501,,,,
,26125945.135,300.0052338,-15350.06,-0.523791860015412,3.36283805475727E-5,1,4.99626677034896,40.0298881530762,1.99176513667977,9.8099997267127,-5.81660644793563,-1.01348881747208,25,-0.000141532321218495,-0.523774512492252,-0.00048085019245684,300.0048218,300.0056458,-15594.532,-15105.588,52.3597312462363,18.403914555787,38.213703,0,0,0,200,4449,300.0682,-15350.06,,,,,,,,,,,,,0,,,,9.20399715,,,,,,300.0052338,,,,
,26125960.165,300.007843,-16795.2825,-0.526084340668892,2.89210058073466E-5,1,4.99626677034896,40.0298881530762,1.99161017061391,9.8099997267127,-5.84148943982317,-1.01864308110828,25,-0.00021374538208603,-0.526066833520276,-0.000554504698508848,300.0074463,300.0082397,-17036.225,-16554.34,51.7367733164093,18.4035184685206,38.976128,0,0,0,200,4449,300.0656,-16795.2825,,,,,,,,,,,,,0,,,,9.1776772,,,,,,300.007843,,,,
,26125975.145,300.01104735,-18220.453,-0.528123877936621,3.19798752467571E-5,1,4.99626677034896,40.0298881530762,1.99159759966921,9.8099997267127,-5.86419223766747,-1.02205479588296,25,-0.000166778908053967,-0.528106286039395,-0.00050882783892761,300.0102539,300.0118408,-18462.385,-17978.521,52.8498123277941,18.4006280666309,38.976128,0,0,0,200,4449,300.05665,-18220.453,,,,,,,,,,,,,0,,,,10.01706075,,,,,,300.01104735,,,,
,26125990.085,300.0120697,-19598.358,-0.530080472049274,2.990151858821E-5,1,4.99626677034896,40.0298881530762,1.99153941920214,9.82000026851892,-5.88576554049047,-1.02573964671404,25,-0.000160870105708396,-0.530062806666826,-0.000504148572580373,300.0119934,300.012146,-19787.732,-19408.984,52.3659842743902,18.4073728766097,38.976128,0,0,0,200,4449,300.05185,-19598.358,,,,,,,,,,,,,0,,,,10.16791395,,,,,,300.0120697,,,,
,26126020.305,300.01138305,-19577.9455,-0.530017759848995,3.18691521899026E-5,1,4.99626677034896,40.0298881530762,1.99170437389363,9.82000026851892,-5.88557058825693,-1.02550565714942,25,-0.00014336243411972,-0.530000118136154,-0.000486608302277561,300.0105896,300.0121765,-19848.121,-19307.77,52.1033570919286,18.4007898623343,38.976128,0,0,0,200,4449,300.04685,-19577.9455,,,,,,,,,,,,,0,,,,10.01706075,,,,,,300.01138305,,,,
,26126035.06,300.0107422,-17795.0385,-0.527568971633031,2.38428121841463E-5,1,4.99626677034896,40.0298881530762,1.99172096792545,9.82000026851892,-5.85835878013072,-1.02115605381245,25,-0.000176885859226542,-0.527551393677453,-0.000518602099907356,300.0105896,300.0108948,-18092.895,-17497.182,52.301109107294,18.4004431270997,38.976128,0,0,0,200,4449,300.0466,-17795.0385,,,,,,,,,,,,,0,,,,8.97596935,,,,,,300.0107422,,,,
,26126050.085,300.01057435,-16053.936,-0.524941435235012,3.12393525275829E-5,1,4.99626677034896,40.0298881530762,1.99171145437935,9.8099997267127,-5.82914963295783,-1.01609482794073,25,-0.000178587295406923,-0.524923940470116,-0.00051865407797661,300.0097656,300.0113831,-16340.494,-15767.378,52.9412628645441,18.402998992398,38.976128,0,0,0,200,4449,300.04795,-16053.936,,,,,,,,,,,,,0,,,,10.11763145,,,,,,300.01057435,,,,
,26126065.03,300.0091858,-14393.1925,-0.522147500877332,3.36511758549754E-5,1,4.99626677034896,40.0298881530762,1.99168702659171,9.82000026851892,-5.79791214611981,-1.01150586834784,25,-0.000252402662569722,-0.522130066608303,-0.000590716989749522,300.0086975,300.0096741,-14669.159,-14117.226,52.7693045903133,18.3959865115102,38.976128,0,0,0,200,4449,300.04085,-14393.1925,,,,,,,,,,,,,0,,,,10.11763145,,,,,,300.0091858,,,,
,26126080.065,300.00727845,-12764.6505,-0.519014528908214,3.64189381191985E-5,1,4.99626677034896,40.0298881530762,1.99178034381371,9.8099997267127,-5.76353860345842,-1.00458716371208,25,-0.000170276738637437,-0.518997276896634,-0.000506608288388229,300.006958,300.0075989,-13033.697,-12495.604,52.8560653559479,18.3977228422368,38.976128,0,0,0,200,4449,300.0436,-12764.6505,,,,,,,,,,,,,0,,,,10.0165615,,,,,,300.00727845,,,,
,26126095.04,300.0065918,-11175.2295,-0.515435028130311,3.01960795907683E-5,1,4.99626677034896,40.0298881530762,1.9917029775074,9.8099997267127,-5.72358216811232,-0.997585620985756,25,-0.000165810297564698,-0.515417903066724,-0.000499870237034198,300.006012,300.0071716,-11449.079,-10901.38,52.3761454451402,18.4047318022907,38.594913,0,0,0,200,4449,300.0418,-11175.2295,,,,,,,,,,,,,0,,,,10.11763145,,,,,,300.0065918,,,,
,26126110.055,300.00608825,-9582.6945,-0.511120148006689,4.19306613702201E-5,1,4.99626677034896,40.0298881530762,1.9916921893271,9.82000026851892,-5.67568683636613,-0.988952581297209,25,-0.000139452506739405,-0.511103185639352,-0.000470762251049915,300.0059204,300.0062561,-9843.269,-9322.12,52.5363792915825,18.4051025214044,38.976128,0,0,0,200,4449,300.0406,-9582.6945,,,,,,,,,,,,,0,,,,10.11763145,,,,,,300.00608825,,,,
,26126125.01,300.00460815,-8029.565,-0.505799506023367,4.71184556932686E-5,1,4.99626677034896,40.0298881530762,1.99175726927686,9.82000026851892,-5.61681441057858,-0.97849346117979,25,-0.000120400497115014,-0.5057827506414,-0.000448297784453831,300.0040588,300.0051575,-8293.104,-7766.026,52.5012060082171,18.4064167257912,38.213703,0,0,0,200,4449,300.04465,-8029.565,,,,,,,,,,,,,0,,,,10.0678482,,,,,,300.00460815,,,,
,26126139.965,300.0042877,-6476.57,-0.49859519791323,6.39628221853148E-5,1,4.99626677034896,40.0298881530762,1.99179958145219,9.8099997267127,-5.53691911389639,-0.964607873638346,25,-0.000121513422512114,-0.498578680197252,-0.000444779416585145,300.0036621,300.0049133,-6742.37,-6210.77,52.5723342034671,18.4100955966622,38.594913,0,0,0,200,4449,300.04445,-6476.57,,,,,,,,,,,,,0,,,,9.9174905,,,,,,300.0042877,,,,
,26126154.965,300.0035095,-4900.4105,-0.489272647136268,0.000947607420338886,1,4.99626677034896,40.0298881530762,1.99169620673029,9.8099997267127,-5.43347415668483,-0.944497488589303,25,6.33621257665227E-5,-0.489256564472607,-0.000253902068326768,300.0035095,300.0035095,-5162.54,-4638.281,53.1468311651018,18.4019956311542,38.976128,0,0,0,200,4449,300.0448,-4900.4105,,,,,,,,,,,,,0,,,,10.11763145,,,,,,300.0035095,,,,
,26126169.995,300.00242615,-3360.82,-0.472094666232338,0.00113384119330534,1,4.99626677034896,40.0298881530762,1.99178379166216,9.82000026851892,-5.24327864341001,-0.909373342778314,25,0.00024144295203423,-0.472079277570508,-6.47183253871739E-5,300.0021057,300.0027466,-3602.753,-3118.887,52.6927049954287,18.399498616242,38.976128,0,0,0,200,4449,300.04695,-3360.82,,,,,,,,,,,,,0,,,,10.11763145,,,,,,300.00242615,,,,
,26126184.945,299.99899295,-1802.862,-0.435255491489086,0.000518795455774582,1,4.99626677034896,40.0298881530762,1.99184475564481,9.8099997267127,-4.83281804082573,-0.846782275719916,25,-0.000528847189466761,-0.435240858150761,-0.000811126008508386,299.995636,300.0023499,-2067.537,-1538.187,52.7138089654479,18.3913300603988,38.976128,0,0,0,200,4449,300.04215,-1802.862,,,,,,,,,,,,,0,,,,9.7725463,,,,,,299.99899295,,,,
,26126199.93,299.99946595,-234.16,-0.260101952905711,0.00555306373665386,1,4.99626677034896,40.0298881530762,1.99160431228021,9.82000026851892,-2.88949486077274,-0.495549877786395,25,0.000621939589721452,-0.260093811665165,0.000453211159106118,299.9988098,300.0001221,-492.198,23.878,52.1705771445824,18.4075413304404,38.213703,0,0,0,200,4449,300.0443,-234.16,,,,,,,,,,,,,0,,,,10.2187014,,,,,,299.99946595,,,,
,26126214.93,299.99868775,1279.038,0.408320258668478,0.00104065041949485,1,4.99626677034896,40.0298881530762,1.9916687010707,9.82000026851892,4.53550728495559,0.781975087277463,25,-0.000614913970216597,0.408307255151057,-0.000350066101018493,299.9985962,299.9987793,1035.125,1522.951,52.1338406041786,18.3916406997034,38.976128,0,0,0,200,4449,300.0487,1279.038,,,,,,,,,,,,,0,,,,10.11763145,,,,,,299.99868775,,,,
,26126229.91,299.9992218,2760.173,0.462930363865956,0.000707382304291687,1,4.99626677034896,40.0298881530762,1.99184016569717,9.8099997267127,5.14150028095958,0.89252596103303,25,-0.000166432711476772,0.462915272347638,0.000133791450702915,299.9981995,300.0002441,2509.905,3010.441,52.6458072842748,18.3996042614775,38.976128,0,0,0,200,4449,300.0498,2760.173,,,,,,,,,,,,,0,,,,9.87361625,,,,,,299.9992218,,,,
,26126244.935,299.9983978,4203.025,0.482961173770586,0.000770452329715637,1,4.99626677034896,40.0298881530762,1.99167188464673,9.82000026851892,5.36411279268014,0.927756857510476,25,-0.000471938828417067,0.482945637473234,-0.000158741440981907,299.9979858,299.9988098,3965.47,4440.58,52.4660327248517,18.3946875699426,38.976128,0,0,0,200,4449,300.0473,4203.025,,,,,,,,,,,,,0,,,,10.16791395,,,,,,299.9983978,,,,
,26126259.91,299.998703,5616.4935,0.494076546570694,0.000873045195032387,1,4.99626677034896,40.0298881530762,1.99159579350753,9.8099997267127,5.48794607150367,0.945745768117185,25,-0.000782527943287282,0.494060845896766,-0.000462146393381739,299.9985962,299.9988098,5400.406,5832.581,52.7872820462556,18.4042849867286,39.357338,0,0,0,200,4449,300.04845,5616.4935,,,,,,,,,,,,,0,,,,10.066844,,,,,,299.998703,,,,
,26126274.895,299.9981537,7035.1815,0.501266294089984,0.000440758070485524,1,4.99626677034896,40.0298881530762,1.99164687691563,9.8099997267127,5.56696830825239,0.965135526378824,25,-0.000289254972962669,0.501250049267012,3.5740347309498E-5,299.9973145,299.9989929,6794.097,7276.266,52.9522056638133,18.3994137589586,38.976128,0,0,0,200,4449,300.04615,7035.1815,,,,,,,,,,,,,0,,,,10.2187014,,,,,,299.9981537,,,,
,26126289.885,300.00010685,8464.0355,0.50706442502311,0.000362961081454251,1,4.99626677034896,40.0298881530762,1.99171510459313,9.8099997267127,5.63057158949164,0.981932379444725,25,0.000211818034111812,0.507047639579757,0.000540514108226816,299.9995728,300.0006409,8224.788,8703.283,52.0408268103901,18.401424443863,38.213703,0,0,0,200,4449,300.05,8464.0355,,,,,,,,,,,,,0,,,,10.16791395,,,,,,300.00010685,,,,
,26126304.87,299.9998169,9881.87,0.511759381801205,3.67261942554289E-5,1,4.99626677034896,40.0298881530762,1.9914945058838,9.82000026851892,5.68229337167728,0.989818995129967,25,0.000114754724783539,0.511742513063623,0.000446463652389661,299.9992981,300.0003357,9624.687,10139.053,51.982986299967,18.4071938445454,38.594913,0,0,0,200,4449,300.04665,9881.87,,,,,,,,,,,,,0,,,,10.1171265,,,,,,299.9998169,,,,
,26126319.88,300.00190735,11331.4765,0.515487996796331,0.000291194938028856,1,4.99626677034896,40.0298881530762,1.99164057900935,9.82000026851892,5.72440258973229,0.995339372239082,25,-4.2988192988681E-5,0.515471079327796,0.000291103454745741,300.0010986,300.0027161,11096.606,11566.347,52.0900694071017,18.4042249453391,38.976128,0,0,0,200,4449,300.0457,11331.4765,,,,,,,,,,,,,0,,,,9.81890865,,,,,,300.00190735,,,,
,26126334.85,300.0030365,12775.715,0.518625284344473,0.000116470255106891,1,4.99626677034896,40.0298881530762,1.99168652202533,9.82000026851892,5.75907741344879,1.00309461471874,25,0.000107664438639903,0.518608152635559,0.000443742699044154,300.0029297,300.0031433,12528.984,13022.446,52.3253395913902,18.3999957345687,38.976128,0,0,0,200,4449,300.04575,12775.715,,,,,,,,,,,,,0,,,,8.75689675,,,,,,300.0030365,,,,
,26126349.82,300.0035858,14216.8465,0.52146147498156,2.75379242226064E-5,1,4.99626677034896,40.0298881530762,1.99154818046014,9.82000026851892,5.78993715303753,1.0099440909213,25,0.000237165707412834,0.521444160923468,0.000575042883888476,300.0033264,300.0038452,13976.33,14457.363,52.0517696096594,18.4014498317816,38.976128,0,0,0,200,4449,300.03975,14216.8465,,,,,,,,,,,,,0,,,,10.0678482,,,,,,300.0035858,,,,
,26126364.82,300.0052948,15663.4835,0.523838776363093,7.07260558348282E-5,1,4.99626677034896,40.0298881530762,1.99169866961949,9.82000026851892,5.8168779055488,1.01391118109925,25,0.000174301669475293,0.523821402636923,0.00051367303537288,300.0048828,300.0057068,15426.779,15900.188,52.514493693044,18.4053043260393,38.594913,0,0,0,200,4449,300.04295,15663.4835,,,,,,,,,,,,,0,,,,9.8262587,,,,,,300.0052948,,,,
,26126379.795,300.0069275,17101.648,0.526144803572258,2.76888869186036E-5,1,4.99626677034896,40.0298881530762,1.99155351665362,9.8099997267127,5.84206178944787,1.01838613377123,25,0.000182566092798047,0.526127326963521,0.000523387529007913,300.0067139,300.0071411,16860.566,17342.73,52.473849010044,18.4052788480668,38.976128,0,0,0,200,4449,300.04215,17101.648,,,,,,,,,,,,,0,,,,9.18078425,,,,,,300.0069275,,,,
,26126394.8,300.0092621,18558.7375,0.528170490520862,3.06092402830182E-5,1,4.99626677034896,40.0298881530762,1.99143000190663,9.8099997267127,5.86428217273221,1.02180166213113,25,0.000143282100039687,0.528152939328669,0.000485376704760418,300.0088501,300.0096741,18317.512,18799.963,52.4832285522748,18.4063203885791,38.976128,0,0,0,200,4449,300.03775,18558.7375,,,,,,,,,,,,,0,,,,10.11763145,,,,,,300.0092621,,,,
,26126419.79,300.0110626,19997.3665,0.530048518957332,2.44620514708606E-5,1,4.99626677034896,40.0298881530762,1.99158848615638,9.8099997267127,5.88547557428408,1.02612976523322,25,0.000199358287794555,0.530030844105453,0.000542631994769571,300.0107727,300.0113525,19994.59,20000.143,52.8677897837364,18.4039681975715,38.594913,0,0,0,200,4417,300.02955,19997.3665,,,,,,,,,,,,,0,,,,10.01856045,,,,,,300.0110626,,,,
,26127484.025,300.00245665,3838.6085,0.476919620558607,2.90961882553107E-5,1,4.99626677034896,40.0298881530762,1.99162633668118,9.82000026851892,5.29574433139138,0.922740251590815,25,0.000129111498522951,0.476903830168993,0.000438410231704601,300.0022888,300.0026245,3838.519,3838.698,52.1713587731017,18.3943119583768,38.976128,0,0,0,200,4417,300.02185,3838.6085,,,,,,,,,,,,,0,,,,10.16791395,,,,,,300.00245665,,,,
,26127608.9,299.99835205,322.664,0.300929113422674,1.81764798676124E-5,1,4.99626677034896,40.0298881530762,1.99161245586454,9.82000026851892,3.33970263482802,0.59263875213756,25,0.00101865032078996,0.300918575803178,0.00121381751846918,299.9978943,299.9988098,322.625,322.703,52.4675959818902,18.393882756931,38.213703,0,0,0,200,4417,300.02885,322.664,,,,,,,,,,,,,0,,,,10.4772544,,,,,,299.99835205,,,,
,26127713.82,299.9955139,27.227,0.0860829263145236,1.29866579126066E-5,1,4.99626677034896,40.0298881530762,1.99172231336326,9.8099997267127,0.956179347848285,0.165037225970548,25,-0.000113854195377893,0.0860801823159898,-5.80129756309193E-5,299.9953613,299.9956665,27.107,27.347,52.270625595044,18.4010048883789,38.213703,0,0,0,200,4417,300.0363,27.227,,,,,,,,,,,,,0,,,,10.4772544,,,,,,299.9955139,,,,
,26127803.76,299.99806215,2.414,0.0694898640425386,6.86341170622849E-6,1,4.99626677034896,40.0298881530762,1.99167493564142,9.8099997267127,0.771741797686641,0.13385382687356,25,-3.50243849190591E-5,0.0694876067115877,1.00512263706173E-5,299.9978333,299.998291,2.401,2.427,52.1119550056401,18.4015468541686,38.594913,0,0,0,200,4417,300.0363,2.414,,,,,,,,,,,,,0,,,,9.73828985,,,,,,299.99806215,,,,
,26127903.71,300.00242615,-5.1345,0.0638338678876314,6.44020904122701E-6,1,4.99626677034896,40.0298881530762,1.99172237811693,9.82000026851892,0.709057783096188,0.122304520067131,25,-9.13651732750691E-5,0.0638318241877485,-4.99557809085726E-5,300.0015564,300.0032959,-5.152,-5.117,52.4957346085825,18.3963494047704,38.594913,0,0,0,200,4417,300.03215,-5.1345,,,,,,,,,,,,,0,,,,10.58244515,,,,,,300.00242615,,,,
,26128013.03,300.00138855,-62,0.0300261098623828,9.70290686491226E-6,1,4.99626677034896,40.0298881530762,1.991784735559,9.82000026851892,0.333387627832655,0.057792767684823,2.5,-1.7866488883246E-5,0.0300251331832793,1.61099388600387E-6,300.0005493,300.0022278,-62.054,-61.946,52.8341797574094,18.3977223821163,38.976128,0,0,0,200,4417,300.02915,-62,,,,,,,,,,,,,0,,,,10.58244515,,,,,,300.00138855,,,,
,26128113.58,299.9957733,-736.6925,-0.3427353296938,2.15164551608648E-5,1,4.99626677034896,40.0298881530762,1.99181152082968,9.8099997267127,-3.80613980169779,-0.662917312966201,25,-6.90331934349942E-5,-0.342724064279306,-0.000291333666518219,299.994812,299.9967346,-736.705,-736.68,52.9311016937941,18.4020918806749,38.976128,0,0,0,200,4417,300.0422,-736.6925,,,,,,,,,,,,,0,,,,10.42544175,,,,,,299.9957733,,,,
,26128293.4,299.9992523,-8762.03,-0.50809930571905,2.55942566977903E-5,1,4.99626677034896,40.0298881530762,1.99171991405884,9.82000026851892,-5.64216280098698,-0.983441895113653,25,-0.000167502968207754,-0.508082527373693,-0.000496879083648724,299.9988708,299.9996338,-8762.081,-8761.979,52.3628577603132,18.3969403755041,38.213703,0,0,0,200,4417,300.038,-8762.03,,,,,,,,,,,,,0,,,,8.84610895,,,,,,299.9992523,,,,
,26128653.135,299.995224,-3838.649,-0.476702591127559,2.34123778046057E-5,1,4.99626677034896,40.0298881530762,1.99190649665884,9.8099997267127,-5.29407392599274,-0.922305688819026,25,-0.000116512466530237,-0.476686920471896,-0.000425669794787923,299.9946289,299.9958191,-3838.685,-3838.613,52.1275875760247,18.3994845349986,38.594913,0,0,0,200,4417,300.0228,-3838.649,,,,,,,,,,,,,0,,,,10.79600575,,,,,,299.995224,,,,
,26128788.045,299.9961853,-322.7075,-0.299745763589468,1.58480818165762E-5,1,4.99626677034896,40.0298881530762,1.99188378006362,9.82000026851892,-3.32869011250147,-0.580697164562828,25,-0.000142296507075785,-0.299735853299103,-0.000336721098784898,299.9959106,299.99646,-322.762,-322.653,52.3573863606786,18.3939669660009,38.976128,0,0,0,200,4417,300.0338,-322.7075,,,,,,,,,,,,,0,,,,10.1689291,,,,,,299.9961853,,,,
,26128887.97,299.9974518,-27.317,-0.0804298165549454,2.86463657597984E-5,1,4.99626677034896,40.0298881530762,1.99181995133307,9.8099997267127,-0.896926991769469,-0.134095902440187,25,0.00191721591812545,-0.0804284226342798,0.00186498239308383,299.9967041,299.9981995,-27.347,-27.287,52.575460717544,18.4009089578162,38.976128,0,0,0,200,4417,300.0361,-27.317,,,,,,,,,,,,,0,,,,10.79600575,,,,,,299.9974518,,,,
,26128977.89,300.0014343,-2.3275,-0.0642868685000855,1.09590243436303E-5,1,4.99626677034896,40.0298881530762,1.99179509329869,9.8099997267127,-0.716848798152465,-0.107460094337685,25,0.00150723071680944,-0.0642857302807641,0.00146548167924849,300.0009155,300.0019531,-2.352,-2.303,52.5355976630632,18.3948912160122,38.976128,0,0,0,200,4417,300.037,-2.3275,,,,,,,,,,,,,0,,,,10.2268615,,,,,,300.0014343,,,,
,26129067.83,299.9994049,5.18,-0.059752568577589,1.00868573695467E-5,1,4.99626677034896,40.0298881530762,1.99184151603265,9.8099997267127,-0.664525105266209,-0.110101421751285,25,0.000480813230822323,-0.0597509174153822,0.000442038441327791,299.9992981,299.9995117,5.169,5.191,52.3597312462363,18.3891585355792,38.213703,0,0,0,200,4417,300.0323,5.18,,,,,,,,,,,,,0,,,,10.9588633,,,,,,299.9994049,,,,
,26129168.555,300.00091555,61.7385,-0.0274559647291903,6.76939247966383E-6,1,4.99626677034896,40.0298881530762,1.99180032296163,9.8099997267127,-0.30484786913492,-0.0528754106567625,2.5,1.37129023065344E-5,-0.0274550703563864,-4.09713240594679E-6,300.0007019,300.0011292,61.727,61.75,52.4300778129671,18.3945394353872,38.594913,0,0,0,200,4417,300.03125,61.7385,,,,,,,,,,,,,0,,,,10.63583375,,,,,,300.00091555,,,,
,26129277.69,299.9997101,736.8875,0.343888859718324,1.78376989794885E-5,1,4.99626677034896,40.0298881530762,1.99172627074373,9.8099997267127,3.8188646433849,0.66470776160817,25,3.2034445476816E-5,0.343877538343472,0.00025509648744547,299.9993286,300.0000916,736.728,737.047,52.8521572133517,18.4001412040755,38.594913,0,0,0,200,4417,300.02835,736.8875,,,,,,,,,,,,,0,,,,9.8340397,,,,,,299.9997101,,,,
,26129457.605,300.00106815,8762.3395,0.507971208656763,2.12583789833055E-5,1,4.99626677034896,40.0298881530762,1.99181172806217,9.82000026851892,5.64117759093186,0.982155676429587,25,7.00556438283071E-5,0.507954469374056,0.000399355912665189,300.0010071,300.0011292,8762.276,8762.403,52.2886030509863,18.3960366638811,38.594913,0,0,0,200,4417,300.0349,8762.3395,,,,,,,,,,,,,0,,,,10.8499308,,,,,,300.00106815,,,,
,26129602.5,300.00730895,19998.707,0.529694269348421,2.28870713373256E-5,1,4.99626677034896,40.0298881530762,1.99188423376618,9.8099997267127,5.8826514854222,1.02403183890568,25,5.89099346498775E-5,0.529676756873074,0.000401963395026846,300.0068054,300.0078125,19998.008,19999.406,52.588748402371,18.404315993617,38.976128,0,0,0,200,4417,300.0262,19998.707,,,,,,,,,,,,,0,,,,11.01387645,,,,,,300.00730895,,,,