File: DataFailid_Testimiseks/1_NiFe2O4_200C_ACMS_DChys300K_3T_27012023 - Copy.dat
[Header]
; ACMS II Data File (default extension .dat)
; Copyright (c) 2014, Quantum Design, Inc. All rights reserved.
TITLE,
FILEOPENTIME,3883994288.145,01/27/2023,3:17 pm
BYAPP,ACMS II,1.0,1.2
INFO,PPMS ACMS II Option Release 1.0.8 Build 33,APPNAME
INFO,Quantum Design Linear Motor Servo Controller,MOTOR_MODULE_NAME
INFO,3101-100 C1,MOTOR_HW_VERSION
INFO,074,MOTOR_SERIAL_NUMBER
INFO,SRV No X-over 01.01.11,MOTOR_SOFTWARE_VERSION
INFO,ACMS,ACMS_MODULE_NAME
INFO,3101-430 D0,ACMS_HW_VERSION
INFO,ACMSII183,ACMS_SERIAL_NUMBER
INFO,00.14.14,ACMS_SOFTWARE_VERSION
INFO,WF181,COIL_SERIAL_NUMBER
INFO,0,MOMENT_UNITS
INFO,1_NiFe2O4,SAMPLE_MATERIAL
INFO,1_NiFe2O4 pressed pellet glued with GE varnish on quarz stick,SAMPLE_COMMENT
INFO,17.7mg,SAMPLE_MASS
INFO,,SAMPLE_VOLUME
INFO,,SAMPLE_MOLECULAR_WEIGHT
INFO,,SAMPLE_SIZE
INFO,,SAMPLE_SHAPE
DATATYPE,COMMENT,1
DATATYPE,TIME,2
STARTUPAXIS,X,2
STARTUPAXIS,Y1,5
STARTUPGROUP, AC
FIELDGROUP, AC, 2,3,4,5,6,7,8,9,10,11,12,13,14,15,16,20,21,22,23,24,25,35,43,44,45,46,47,48,49
FIELDGROUP, DC, 2,3,4,17,18,19,20,21,23,24,25,35,36,37,43,44,45,46,47,48,49,50,51
FIELDGROUP, Diagnostic, 26,27,28,29,30,31,32,33,34,38,39,40,41,42,52,53,54,55,56,57,58,59,60,61,62,63,64,65,66,67,68,69
[Data]
Comment,Time Stamp (sec),Temperature (K),Magnetic Field (Oe),AC Moment (emu),AC Std. Dev. (emu),AC Phase (deg),AC Phase Std. Dev. (deg),AC Suscept. (emu/Oe),AC Suscept. Std. Dev. (emu/Oe),AC X'  (emu/Oe),AC X" (emu/Oe),AC X' Std. Dev. (emu/Oe),AC X" Std. Dev. (emu/Oe),AC Drive (Oe),AC Frequency (Hz),DC Moment (emu),DC Std. Err. (emu),DC Quad. Moment (emu),Range (mV),"AC=1 DC=2 Locate=3",Measure Type,Measure Count,Measure Time (sec),Measure Number,AC X' Raw (emu/Oe),AC X" Raw (emu/Oe),DC M. Raw' (emu),DC M. Raw" (emu),Coil InPhase (V),Coil Quadrature (V),Null Status,Trim Ratio,Trim Phase (deg.),Max. Signal (mV),Motor Frequency (Hz),Motor Ampl. (mm),System Temp. (K),Min. Temperature (K),Max. Temperature (K),Min. Field (Oe),Max. Field (Oe),Pressure (Torr),Temp. Status (code),Field Status (code),Chamber Status (code),Measure Status (code),Center Position (mm),Transport Action,Motor Lag (deg),Motor Current (amps),Motor Heatsink Temp. (C),Motor Board Temp. (C),QMap 01,QMap 02,QMap 03,QMap 04,QMap 05,QMap 06,QMap 07,QMap 08,QMap 09,QMap 10,QMap 11,QMap 12,QMap 13,QMap 14,QMap 15,QMap 16
sample offset = 24.97 mm touchdown = 3.25000006705523 mm,3883994991.72142,299.972685977943,28810.6845,,,,,,,,,,,,,0.384842992999622,1.80797380908808E-5,-0.000544727795454819,10,2,,2400,60,1,,,0.384795321828929,0.000298212036845033,0.00249951193109155,-0.000770155107602477,,,,0.102216572982906,39.995735168457,1.99351932357875,300.1335,299.965698242188,299.980865478516,28045.635,29575.734,9.624196,1,6,3,0,18.4030000670552,1,18.5462374165282,1.02432250976562,44.4770278930664,42.5219955444336,,,,,,,,,,,,,,,,
,3883995666.81793,299.990733016324,14554.4765,,,,,,,,,,,,,0.344148574685083,3.39006152584804E-5,-0.000479028137394098,10,2,,2400,60,12,,,0.344105538044356,0.000275751981189773,0.00223531690426171,-0.000689159438479692,,,,0.0914171240069759,39.995735168457,1.99372441477421,300.2024,299.986145019531,299.997161865234,13946.758,15162.195,9.916995,1,6,3,0,18.4030000670552,1,18.5542931285866,1.02462768554688,52.2971649169922,50.8308906555176,,,,,,,,,,,,,,,,
,3883996327.43939,299.988561607988,1056.0095,,,,,,,,,,,,,0.0996138819459517,0.000701589419081754,0.00012250014857967,10,2,,2400,60,23,,,0.0996008279969658,0.000341164270932101,0.000646445841994137,-0.000201232178369537,,,,0.0264598298358577,39.995735168457,1.99365873640369,300.2662,299.984161376953,299.993011474609,442.342,1669.677,9.818419,1,6,3,0,18.4030000670552,1,18.5600059585589,1.02462768554688,53.7634429931641,53.2746849060059,,,,,,,,,,,,,,,,
,3883996988.17493,299.994273616274,-11467.8905,,,,,,,,,,,,,-0.32794033243923,0.000227219967132165,0.000354107211950891,10,2,,2400,60,34,,,-0.327899000472312,-0.00036528952425921,-0.00212966767139733,0.000657649477943778,,,,0.0871086569407344,39.995735168457,1.99365598513862,300.2639,299.988586425781,299.999176025391,-12020.108,-10915.673,7.648531,1,6,3,0,18.4030000670552,1,18.5624719196463,1.02348327636719,54.7409591674805,54.7409591674805,,,,,,,,,,,,,,,,
,3883997648.86706,299.998176363464,-23682.208,,,,,,,,,,,,,-0.374314691519661,1.67514138707633E-5,0.000474480870007974,10,2,,2400,60,45,,,-0.374267714133293,-0.000345719939565212,-0.00243090488947928,0.000750236213207245,,,,0.0994249700241419,39.995735168457,1.99361882018405,300.2481,299.992736816406,300.003601074219,-24242.898,-23121.518,9.340043,1,6,3,0,18.4030000670552,1,18.5639834830847,1.02386474609375,54.7409591674805,54.7409591674805,,,,,,,,,,,,,,,,
,3883998309.45803,299.998808982848,-24750.3255,,,,,,,,,,,,,-0.37665712807382,1.87661021727429E-5,0.000440394580737117,10,2,,2400,60,56,,,-0.37660979443874,-0.000384849343332827,-0.0024459408596158,0.000755253946408629,,,,0.100044296185702,39.995735168457,1.99356137426605,300.263,299.993011474609,300.003448486328,-25397.729,-24102.922,9.155283,1,6,3,0,18.4030000670552,1,18.5664281881454,1.02821350097656,54.7409591674805,54.7409591674805,,,,,,,,,,,,,,,,
,3883998970.11034,299.991898149703,-11054.2285,,,,,,,,,,,,,-0.324458749481898,5.0147162141353E-5,0.000469729837923018,10,2,,2400,60,67,,,-0.32441814531631,-0.000242075898900254,-0.00210710661485791,0.000649866065941751,,,,0.0861764445944101,39.995735168457,1.99348192349735,300.2807,299.987731933594,299.997589111328,-11674.237,-10434.22,9.720822,1,6,3,0,18.4030000670552,1,18.5632772463553,1.02607727050781,54.7409591674805,55.2297172546387,,,,,,,,,,,,,,,,
,3883999630.97077,299.996235038466,2489.392,,,,,,,,,,,,,0.193216668033726,0.000723198710538672,-0.00090214616324375,10,2,,2400,60,78,,,0.193193804558631,-0.000477912239039348,0.0012560662580654,-0.000383021775633097,,,,0.0513205276325128,39.995735168457,1.99354330638567,300.3128,299.991149902344,300.004455566406,1906.516,3072.268,9.624196,1,6,3,0,18.4030000670552,1,18.5655815814738,1.02607727050781,54.7409591674805,54.7409591674805,,,,,,,,,,,,,,,,
,3884000291.59039,300.002820216439,14922.9495,,,,,,,,,,,,,0.346360177468918,3.04022389697779E-5,-0.000461915482611551,10,2,,2400,60,89,,,0.346316668831852,0.00029764542288685,0.00224916078150272,-0.000694295973517001,,,,0.091993297782769,39.995735168457,1.99347876835558,300.2964,299.997314453125,300.008178710937,14347.431,15498.468,9.624196,1,6,3,0,18.4030000670552,1,18.571163583634,1.024169921875,54.7409591674805,55.2297172546387,,,,,,,,,,,,,,,,
,3884000952.26837,300.003650907468,27250.5355,,,,,,,,,,,,,0.382013375804466,1.37976011233241E-5,-0.0003365645078235,10,2,,2400,60,100,,,0.381965123618299,0.000500181970996119,0.002480253810063,-0.00076693925075233,,,,0.101460349020704,39.995735168457,1.99343085193727,300.2744,299.998016357422,300.008880615234,26735.188,27765.883,9.624196,1,6,3,0,18.4030000670552,1,18.5729383962012,1.02485656738281,54.7409591674805,55.2297172546387,,,,,,,,,,,,,,,,
sample offset = 24.97 mm,3884004224.66003,299.993779935446,20001.84,,,,,,,,,,,,,0.364383725941233,6.93409465953731E-6,-0.000208968775797122,10,2,,2400,60,1,,,0.364337476645994,0.000589736518561187,0.00236508483067155,-0.000732138752937317,,,,0.0967584810200812,39.995735168457,1.99302564352535,300.3087,299.989868164063,299.999603271484,20001.559,20002.121,9.528531,1,4,3,0,18.4030000670552,1,18.5731739856571,1.02577209472656,52.7859268188477,52.2971649169922,,,,,,,,,,,,,,,,
sample offset = 24.97 mm,3884006048.83544,299.999638258385,9000.234,,,,,,,,,,,,,0.308273775458881,5.4271764913788E-6,-0.000228138077661731,10,2,,2400,60,1,,,0.308234628586132,0.000448231401309049,0.00200075935572386,-0.000619071361143142,,,,0.0818501768555608,39.995735168457,1.99280887782169,300.2917,299.995452880859,300.005187988281,9000.224,9000.244,9.624196,1,4,3,0,18.4030000670552,1,18.5751144768854,1.02622985839844,54.7409591674805,54.2522010803223,,,,,,,,,,,,,,,,
sample offset = 24.97 mm,3884007943.81536,299.996345517124,-1999.7795,,,,,,,,,,,,,-0.174367170275808,3.0878417762938E-6,0.000313442766477447,10,2,,2400,60,1,,,-0.17434541977723,-6.93480023511023E-5,-0.00113179080653936,0.000348990201018751,,,,0.0462871438793011,39.995735168457,1.99240247918493,300.3035,299.991302490234,300.018341064453,-1999.797,-1999.762,9.720822,1,4,3,0,18.4030000670552,1,18.5798864118732,1.02935791015625,54.7409591674805,55.2297172546387,,,,,,,,,,,,,,,,
sample offset = 24.97 mm,3884009835.93584,300.001080638705,-12999.8295,,,,,,,,,,,,,-0.337033406026997,6.43209028872197E-6,3.8936698253107E-6,10,2,,2400,60,1,,,-0.336990076837441,-0.000735284656650154,-0.00218630814924836,0.00067864399170503,,,,0.0894658899155238,39.995735168457,1.99235410683351,300.2963,299.99658203125,300.005462646484,-12999.904,-12999.755,7.802884,1,4,3,0,18.4030000670552,1,18.5850757028497,1.0296630859375,54.7409591674805,54.7409591674805,,,,,,,,,,,,,,,,
sample offset = 24.97 mm,3884011807.52072,300.004628318954,-35000.9825,,,,,,,,,,,,,-0.394145176658658,1.15365476862237E-5,-0.00102293379944397,10,2,,2400,60,1,,,-0.394092475392403,-0.00188537527323045,-0.00255478150211275,0.000800237990915775,,,,0.104628151317289,39.995735168457,1.99238229421614,300.2729,300.000885009766,300.009765625,-35002.363,-34999.602,9.720822,1,4,3,0,18.4030000670552,1,18.5835065405461,1.02890014648438,53.2746849060059,53.2746849060059,,,,,,,,,,,,,,,,
sample offset = 24.97 mm,3884013938.81788,299.994415812415,-19999.424,,,,,,,,,,,,,-0.363860074594515,7.70980373970559E-6,-0.000593063392645054,10,2,,2400,60,1,,,-0.363812079611111,-0.00139050668645502,-0.0023590219207108,0.000736225745640695,,,,0.0965796209518469,39.995735168457,1.99219638667908,300.3067,299.990570068359,300.000305175781,-19999.842,-19999.006,9.624196,1,4,3,0,18.4030000670552,1,18.5790177978158,1.02996826171875,53.7634429931641,53.7634429931641,,,,,,,,,,,,,,,,
sample offset = 24.97 mm,3884015709.85736,300.000297543356,-9000.197,,,,,,,,,,,,,-0.307850789391561,5.69610168597275E-6,3.72845757426852E-5,10,2,,2400,60,1,,,-0.30781125902277,-0.000638123739089363,-0.00199717609211802,0.000619722879491746,,,,0.0817239481952427,39.995735168457,1.99246763566066,300.3098,299.995452880859,300.005462646484,-9000.242,-9000.152,9.818419,1,4,3,0,18.4030000670552,1,18.5857284095655,1.02813720703125,54.7409591674805,54.7409591674805,,,,,,,,,,,,,,,,
sample offset = 24.97 mm,3884017592.95929,299.998609872306,1999.822,,,,,,,,,,,,,0.174415572783954,2.89496287723556E-6,-0.000319730190399185,10,2,,2400,60,1,,,0.174393816927806,6.31649355186739E-5,0.00113200233317912,-0.000349122099578381,,,,0.0462965626107691,39.995735168457,1.99225380648397,300.3046,299.994445800781,300.003601074219,1999.792,1999.852,9.433816,1,4,3,0,18.4030000670552,1,18.5850057442721,1.01844787597656,54.7409591674805,55.2297172546387,,,,,,,,,,,,,,,,
sample offset = 24.97 mm,3884019476.73542,299.999859881454,13000.0365,,,,,,,,,,,,,0.336490488232611,6.69353867967171E-6,-0.000218280884680575,10,2,,2400,60,1,,,0.336447698809097,0.000519736314264108,0.00218301569111645,-0.000676217372529209,,,,0.0893149010007272,39.995735168457,1.99219930279523,300.3131,299.996032714844,300.005462646484,12999.946,13000.127,9.818419,1,4,3,0,18.4030000670552,1,18.587949062114,1.0284423828125,54.7409591674805,55.2297172546387,,,,,,,,,,,,,,,,
sample offset = 24.97 mm,3884021413.86178,300.005017889776,34999.7535,,,,,,,,,,,,,0.393085792226479,1.24589474154423E-5,0.000623012060861534,10,2,,2400,60,1,,,0.39303410214459,0.00148318348424069,0.0025348337367177,-0.000790814694482833,,,,0.103774190678338,39.995735168457,1.98137129964728,300.2719,300.000885009766,300.009887695313,34999.273,35000.234,9.720822,1,4,3,0,18.4030000670552,1,18.5760206120097,1.01524353027344,53.2746849060059,54.2522010803223,,,,,,,,,,,,,,,,
sample offset = 24.99 mm,3884080204.84612,5.00036506108292,20004.082,,,,,,,,,,,,,0.526150745135639,1.13932099281944E-5,-0.0011966337440576,10,2,,2400,60,1,,,0.51176950158577,0.00305058273101019,0.00329966330900788,-0.00103702011983842,,,,0.135174433662951,39.995735168457,1.98209016793692,4.9915,4.99909067153931,5.00134611129761,20003.26,20004.904,2.066468,1,4,3,0,20.0930000493228,1,18.5708074955307,1.01676940917969,52.2971649169922,52.2971649169922,,,,,,,,,,,,,,,,
sample offset = 24.99 mm,3884082013.39597,4.99982403177617,10000.2165,,,,,,,,,,,,,0.506556646908956,1.11494092791165E-5,-0.00144286982386405,10,2,,2400,60,1,,,0.492429553555149,0.00198651377218759,0.00317701022140682,-0.000992387998849154,,,,0.130078712537993,39.995735168457,1.98230229712395,4.9913,4.99910926818848,5.00114631652832,10000.198,10000.235,1.814796,1,4,3,0,20.0930000493228,1,18.5812753831538,1.02088928222656,54.7409591674805,54.7409591674805,,,,,,,,,,,,,,,,
sample offset = 24.99 mm,3884083898.2112,5.00006413367124,-999.843,,,,,,,,,,,,,-0.356541256153534,7.9947925214054E-6,0.00106489781440305,10,2,,2400,60,1,,,-0.346474973218965,-0.000998052499839461,-0.00223616417497396,0.0006956378929317,,,,0.0915236557315182,39.995735168457,1.98230735748834,4.9961,4.99872732162476,5.00165033340454,-999.889,-999.797,1.778896,1,4,3,0,20.0930000493228,1,18.580521013267,1.01753234863281,54.7409591674805,55.2297172546387,,,,,,,,,,,,,,,,
sample offset = 24.99 mm,3884085770.27966,5.00004774485993,-11999.755,,,,,,,,,,,,,-0.511704811450946,1.11276330423972E-5,0.00142021469869093,10,2,,2400,60,1,,,-0.497484277317915,-0.00217244044758519,-0.00320935482159257,0.00100416142959148,,,,0.131422497267678,39.995735168457,1.98242931869921,4.9933,4.99964666366577,5.00064086914063,-11999.791,-11999.719,1.692224,1,4,3,0,20.0930000493228,1,18.5893720606877,1.01722717285156,54.7409591674805,55.2297172546387,,,,,,,,,,,,,,,,
sample offset = 24.99 mm,3884087698.35976,4.99977527791615,-29998.753,,,,,,,,,,,,,-0.537499622387849,1.21428107283497E-5,0.00113135119946029,10,2,,2400,60,1,,,-0.523194754483463,-0.00394861142279446,-0.0033718862105161,0.00106678123120219,,,,0.138216136204657,39.995735168457,1.98241453341614,4.9944,4.99934673309326,5.00009202957153,-29998.871,-29998.635,1.625937,1,4,3,0,20.0930000493228,1,18.5890850313028,1.01951599121094,53.2746849060059,53.7634429931641,,,,,,,,,,,,,,,,
sample offset = 24.99 mm,3884089922.75904,5.00029385317654,-20000.2735,,,,,,,,,,,,,-0.525743942049479,1.14153908282964E-5,0.00124189095414006,10,2,,2400,60,1,,,-0.511374058979249,-0.00300303132256627,-0.00331530580297112,0.00104249792639166,,,,0.135821829124006,39.995735168457,1.99320486607907,4.9934,5.00011777877808,5.00048065185547,-20000.723,-19999.824,1.577932,1,4,3,0,20.0930000493228,1,18.5847049558964,1.02622985839844,53.2746849060059,53.7634429931641,,,,,,,,,,,,,,,,
sample offset = 24.99 mm,3884091661.58679,4.99980943736227,-9999.95,,,,,,,,,,,,,-0.506360882022348,1.06246972057909E-5,0.00139725238342135,10,2,,2400,60,1,,,-0.492238940385445,-0.00202953155310204,-0.00319321267306805,0.000997893861494958,,,,0.130747285474692,39.995735168457,1.99334185791137,4.9943,4.99953651428223,5.00017070770264,-10000.011,-9999.889,1.562247,1,4,3,0,20.0930000493228,1,18.5834496550577,1.01913452148438,54.7409591674805,55.2297172546387,,,,,,,,,,,,,,,,
sample offset = 24.99 mm,3884093544.28054,4.9999313066472,999.7445,,,,,,,,,,,,,0.357237063557777,9.21970054968337E-6,-0.00112448897161975,10,2,,2400,60,1,,,0.347151462753184,0.00094410919259566,0.00225304998457432,-0.000700980890542269,,,,0.0922158183832299,39.995735168457,1.99348888245616,4.9983,4.9997353553772,5.00011301040649,999.723,999.766,1.531343,1,4,3,0,20.0930000493228,1,18.5918340389716,1.02714538574219,54.7409591674805,55.2297172546387,,,,,,,,,,,,,,,,
sample offset = 24.99 mm,3884095430.18694,5.00010563405478,12000.1925,,,,,,,,,,,,,0.51162294106537,1.10061814964706E-5,-0.00147440422229985,10,2,,2400,60,1,,,0.497405071373188,0.00211921813744501,0.00322676217183471,-0.00100953876972198,,,,0.132134517879058,39.995735168457,1.993568947807,4.9937,4.99977922439575,5.00040197372437,12000.146,12000.239,1.516122,1,4,3,0,20.0930000493228,1,18.5943440174819,1.016845703125,54.7409591674805,54.7409591674805,,,,,,,,,,,,,,,,
sample offset = 24.99 mm,3884097322.36879,4.9997802509418,29999.4365,,,,,,,,,,,,,0.537419886410188,1.17087027612573E-5,-0.00106073207045186,10,2,,2400,60,1,,,0.52311650805925,0.00401665169564233,0.00338946375995874,-0.00107246078550816,,,,0.138938049552727,39.995735168457,1.99314281006464,4.9943,4.99942541122437,5.00014925003052,29999.404,29999.469,1.48613,1,4,3,0,20.0930000493228,1,18.5833886286464,1.02653503417969,53.7634429931641,54.2522010803223,,,,,,,,,,,,,,,,
,3884156073.56739,16.0863911481609,499.926,,,,,,,,,,,,,0.281212347389201,1.32127359700736E-5,-0.000769247209348428,10,2,,2400,60,7,,,0.27326302410744,0.000845118301277092,0.00176365638617426,-0.00054872123291716,,,,0.0721853037884362,39.995735168457,1.98233565096212,18.168,15.0729370117188,17.0649490356445,499.926,499.926,2.760876,6,1,3,0,20.0930000493228,1,18.5705482411764,1.01799011230469,50.3421325683594,47.8983383178711,,,,,,,,,,,,,,,,
,3884156777.17067,38.9383749877597,499.926,,,,,,,,,,,,,0.246937275584463,1.76826359210353E-5,-0.000118801956099459,10,2,,2400,60,17,,,0.24081283129463,0.00290850239018162,0.00155832944437861,-0.000500595720950514,,,,0.0639670560868179,39.995735168457,1.99330507105908,43.1419,37.9155349731445,39.9275970458984,499.926,499.926,4.32794,6,1,3,0,20.3829999292195,1,18.582465797384,1.02188110351562,52.7859268188477,52.2971649169922,,,,,,,,,,,,,,,,
,3884157486.92612,61.8377228814796,499.926,,,,,,,,,,,,,0.213203392879735,1.49663460822225E-5,-0.000590157656637922,10,2,,2400,60,27,,,0.211605417376264,0.00339334698520848,0.00136010313872248,-0.000443162396550178,,,,0.0559052917188133,39.995735168457,1.98235615688615,69.0701,60.8271369934082,62.8269844055176,499.926,499.926,5.782277,6,1,3,0,20.3729998530746,1,18.5938493298194,1.02203369140625,53.7634429931641,53.7634429931641,,,,,,,,,,,,,,,,
,3884158196.91227,85.1319236093619,499.926,,,,,,,,,,,,,0.183937072742391,1.35208499699215E-5,-0.000664052358694666,10,2,,2400,60,37,,,0.18443276833739,0.00172334081533045,0.00119425961747766,-0.000380263343686238,,,,0.048982314661647,39.995735168457,1.99301470379499,94.3878,84.0912017822266,86.1417007446289,499.926,499.926,6.326241,6,1,3,0,20.3129998618662,1,18.5920155022503,1.02798461914062,54.2522010803223,54.2522010803223,,,,,,,,,,,,,,,,
,3884158905.46303,108.569572240607,499.926,,,,,,,,,,,,,0.160477269263564,1.09424961711678E-5,-0.00050639815118875,10,2,,2400,60,47,,,0.16130279314193,0.000891560366432183,0.00103999546263367,-0.000326988199958578,,,,0.0426062037308921,39.995735168457,1.98214476016384,119.1955,107.557518005371,109.549430847168,499.926,499.926,6.518706,6,1,3,0,20.2629999468029,1,18.6025602915047,1.01570129394531,54.2522010803223,54.7409591674805,,,,,,,,,,,,,,,,
,3884159610.90294,132.033881509784,499.926,,,,,,,,,,,,,0.141341910621702,8.94164989559124E-6,-0.000409641692953221,10,2,,2400,60,57,,,0.142118060695995,0.000490139306380886,0.00091685465304181,-0.000286149006569758,,,,0.0375366181920618,39.995735168457,1.98204808544262,143.5794,131.016754150391,133.008728027344,499.926,499.926,6.990869,6,1,3,0,20.1429999643862,1,18.600879379555,1.02272033691406,54.7409591674805,54.7409591674805,,,,,,,,,,,,,,,,
,3884160306.03329,155.160309,499.926,,,,,,,,,,,,,,,,,3,,,,,,,,,,,,,,,,,,,,,,7.131949,6,1,3,,19.892999923408,2,,,51.808406829834,54.7409591674805,,,,,,,,,,,,,,,,
touchdown = 4.65000001713634 mm,3884161056.94107,180.147838232121,499.926,,,,,,,,,,,,,0.110936644199368,6.64889981791591E-6,-0.000281638985764003,10,2,,2400,60,76,,,0.111436006716035,0.000171729502417776,0.000728107814211398,-0.000225756710278802,,,,0.0297919661857648,39.995735168457,2.00642514033916,194.293,179.132736206055,181.179229736328,499.926,499.926,6.85258,6,1,3,0,19.7830000171363,1,18.6036618731978,1.02783203125,54.2522010803223,54.2522010803223,,,,,,,,,,,,,,,,
,3884161768.005,203.786720073497,499.926,,,,,,,,,,,,,0.0990523601674947,6.15901363701302E-6,-0.000230051702843941,10,2,,2400,60,86,,,0.0994203016492919,0.000116078490612674,0.000641711871139705,-0.00019860637257807,,,,0.026252714289899,39.995735168457,1.98156802825997,216.5954,202.692840576172,204.857330322266,499.926,499.926,7.881224,6,1,3,0,19.6529999585748,1,18.5955333554763,1.01570129394531,54.2522010803223,54.2522010803223,,,,,,,,,,,,,,,,
,3884162480.40346,227.530075071905,499.926,,,,,,,,,,,,,0.0884877453398787,5.71552948783366E-6,-0.00021973875664121,10,2,,2400,60,96,,,0.0887383062879294,5.05076632608126E-5,0.000580028689000756,-0.000179137277882546,,,,0.0237248591783218,39.995735168457,2.00651511344132,240.4005,226.460327148438,228.555130004883,499.926,499.926,8.040272,6,1,3,0,19.5030002133846,1,18.5956929162495,1.02668762207031,54.2522010803223,54.7409591674805,,,,,,,,,,,,,,,,
,3884163191.31454,251.122537976087,499.926,,,,,,,,,,,,,0.0790934426361713,4.53657082404476E-6,-0.000188806862684067,10,2,,2400,60,106,,,0.0792433890204725,2.5850357625444E-5,0.000514472834765911,-0.000158738112077117,,,,0.0210416732936475,39.995735168457,1.99271400116707,265.8411,250.114135742187,252.103805541992,499.926,499.926,8.120996,6,1,3,0,19.3730001548231,1,18.5940812723634,1.029052734375,54.2522010803223,54.7409591674805,,,,,,,,,,,,,,,,
,3884163903.34586,274.735285807884,499.926,,,,,,,,,,,,,0.0705578253596464,4.15749752335959E-6,-0.000162082076620409,10,2,,2400,60,116,,,0.0706232482063283,9.95153346302832E-6,0.000458648981293663,-0.000141300653922372,,,,0.0187560507342206,39.995735168457,1.99306761699882,289.7748,273.718475341797,275.741119384766,499.926,499.926,8.368062,6,1,3,0,19.1629999527633,1,18.5803679753616,1.02729797363281,54.7409591674805,54.7409591674805,,,,,,,,,,,,,,,,
,3884164615.02609,298.305174128625,499.926,,,,,,,,,,,,,0.0627111026576196,4.0904223554747E-6,-0.000147421120552136,10,2,,2400,60,126,,,0.0627079089274398,-8.78020095403456E-6,0.000405069644330069,-0.000124653422972187,,,,0.0165633545638742,39.995735168457,1.98215237920445,313.9379,297.283569335937,299.333587646484,499.926,499.926,8.368062,6,1,3,0,19.0329998942018,1,18.5783116370272,1.02294921875,54.7409591674805,54.7409591674805,,,,,,,,,,,,,,,,
,3884165323.67203,321.564808789506,499.926,,,,,,,,,,,,,0.0554314938741808,3.68130001881749E-6,-0.000177298264553176,1,2,,2400,60,136,,,0.0554257798559274,-6.5032778702595E-5,0.000358185468940064,-0.000109811291622464,,,,0.0146414998755224,39.995735168457,1.98237066233785,339.453,320.555450439453,322.551635742188,499.926,499.926,8.536935,6,1,3,0,18.8430000772625,1,18.5769562429499,1.00921630859375,54.7409591674805,55.2297172546387,,,,,,,,,,,,,,,,
,3884166034.74849,345.048089602504,499.926,,,,,,,,,,,,,0.193217066795484,0.00420920673021777,-0.000326814829316488,10,2,,2400,60,146,,,0.193199537951091,3.54933796765655E-5,0.00124809436965734,-0.000384411396225914,,,,0.0510385621609052,39.995735168457,1.98245748199204,359.2027,344.005523681641,346.069183349609,499.926,499.926,8.884974,6,1,3,0,18.6729999469519,1,18.5736504509443,1.01203918457031,54.7409591674805,54.7409591674805,,,,,,,,,,,,,,,,
sample offset = 24.99 mm touchdown = 4.97000012546778 mm,3884270415.2462,5.00712410613777,999.908,,,,,,,,,,,,,0.35173369785885,7.39386257568443E-6,-0.00103450126783322,10,2,,2400,60,1,,,0.341803048843558,0.00100018124195207,0.00223423354327679,-0.000693763664457947,,,,0.091429863965801,39.995735168457,2.00752948780865,5.5353,4.9823899269104,5.18297338485718,999.908,999.908,2.19412,6,1,3,4,20.1030001254678,1,18.5481236045343,1.02386474609375,44.4770278930664,42.0332374572754,,,,,,,,,,,,,,,,
,3884271076.91215,25.779072,999.908,,,,,,,,,,,,,,,,,3,,,,,,,,,,,,,,,,,,,,,,4.735088,6,1,3,,20.1530000405312,2,,,49.8533744812012,50.8308906555176,,,,,,,,,,,,,,,,
touchdown = 5.03000011667609 mm,3884271829.93702,50.0668761745042,999.908,,,,,,,,,,,,,0.317110598105891,1.22944733812963E-5,-9.03689276984135E-5,10,2,,2400,60,21,,,0.311610272943326,0.00550631467348346,0.00200241524726152,-0.000655489217024297,,,,0.0823436172296807,39.995735168457,1.98272435610119,56.1345,49.0351600646973,51.0906295776367,999.908,999.908,5.840331,6,1,3,4,20.1630001166761,1,18.5788961173915,1.01860046386719,53.7634429931641,52.7859268188477,,,,,,,,,,,,,,,,
,3884272541.67196,73.2609732850586,999.908,,,,,,,,,,,,,0.287006791446795,1.39778178301146E-5,-0.00103990663821322,10,2,,2400,60,31,,,0.286756788450236,0.00358163283275471,0.00185537419747561,-0.000596746627707034,,,,0.0761690060400476,39.995735168457,1.99323868296216,81.7182,72.2450714111328,74.2559585571289,999.908,999.908,6.584153,6,1,3,4,20.1130002016127,1,18.5792409974826,1.026611328125,54.2522010803223,54.2522010803223,,,,,,,,,,,,,,,,
,3884273250.4261,96.6238474101211,999.908,,,,,,,,,,,,,0.25952579268265,1.38271858534067E-5,-0.0008592477909082,10,2,,2400,60,41,,,0.26065574473194,0.00188111722891625,0.00168917211703956,-0.00053385115461424,,,,0.0692338170379705,39.995735168457,1.9932801012378,106.7589,95.609001159668,97.6290740966797,999.908,999.908,6.85258,6,1,3,4,20.0129999058247,1,18.5907056560211,1.02951049804688,54.2522010803223,54.7409591674805,,,,,,,,,,,,,,,,
,3884273962.48719,120.280123596174,999.908,,,,,,,,,,,,,0.235170171713455,1.23061845303334E-5,-0.000661355646022068,10,2,,2400,60,51,,,0.236451242684012,0.00107230484320693,0.00153352599591017,-0.00048013124614954,,,,0.0628012625687092,39.995735168457,1.99319985058493,131.5359,119.220802307129,121.294975280762,999.908,999.908,7.203554,6,1,3,4,19.9629999907613,1,18.5903825017606,1.02294921875,54.7409591674805,54.7409591674805,,,,,,,,,,,,,,,,
,3884274673.80956,143.981950090064,999.908,,,,,,,,,,,,,0.213451151974396,1.14141755215217E-5,-0.00056783425744799,10,2,,2400,60,61,,,0.214597926668881,0.000624258872620027,0.00139235809911042,-0.000433765846537426,,,,0.0569948776954377,39.995735168457,1.99313585745731,155.9616,142.948287963867,144.999237060547,999.908,999.908,6.650258,6,1,3,4,19.8630001606345,1,18.6022910791406,1.02745056152344,54.7409591674805,55.2297172546387,,,,,,,,,,,,,,,,
,3884275384.91066,167.731305507681,999.908,,,,,,,,,,,,,0.193771771512863,1.04014515263324E-5,-0.00047562093190007,10,2,,2400,60,71,,,0.194713698634954,0.000396018614069189,0.00126348133198917,-0.000392276066122577,,,,0.051703871032041,39.995735168457,1.99275303953864,180.3562,166.700775146484,168.742370605469,999.908,999.908,7.648531,6,1,3,4,19.7430001782179,1,18.597008964792,1.02653503417969,54.7409591674805,55.2297172546387,,,,,,,,,,,,,,,,
,3884276096.7142,191.375159328099,999.908,,,,,,,,,,,,,0.175828060664614,9.4226398564179E-6,-0.000431592254242699,10,2,,2400,60,81,,,0.176556468274155,0.000233184022554032,0.0011396910995245,-0.000352949573425576,,,,0.0466278209771244,39.995735168457,1.98185421038555,204.4718,190.328155517578,192.386383056641,999.908,999.908,7.802884,6,1,3,4,19.6230001958013,1,18.5969095213926,1.01181030273438,55.2297172546387,55.2297172546387,,,,,,,,,,,,,,,,
,3884276806.92093,214.966720166326,999.908,,,,,,,,,,,,,0.159287431571857,8.66728304943308E-6,-0.00038839379272617,10,2,,2400,60,91,,,0.159814400501233,0.000132753588307138,0.00103167630732059,-0.000318981270538643,,,,0.042202669352963,39.995735168457,1.98168302054467,228.3096,213.92333984375,215.967681884766,999.908,999.908,7.802884,6,1,3,4,19.5329999761581,1,18.5987676813279,1.02157592773438,54.7409591674805,55.2297172546387,,,,,,,,,,,,,,,,
,3884277517.5956,238.569484327193,999.908,,,,,,,,,,,,,0.143926210917928,7.76906092977272E-6,-0.000383658180703955,10,2,,2400,60,101,,,0.144271628728544,3.1531169720822E-5,0.000936615164391697,-0.000289032293949276,,,,0.0383075859494974,39.995735168457,1.99265220498835,252.3373,237.560485839844,239.559478759766,999.908,999.908,8.20253,6,1,3,4,19.4430002221763,1,18.602718660884,1.03012084960938,55.2297172546387,55.2297172546387,,,,,,,,,,,,,,,,
,3884278212.94861,261.588074,999.908,,,,,,,,,,,,,,,,,3,,,,,,,,,,,,,,,,,,,,,,8.120996,6,1,3,,19.102999961555,2,,,52.2971649169922,55.2297172546387,,,,,,,,,,,,,,,,
touchdown = 3.83000005967915 mm,3884278967.61035,286.635964940505,999.908,,,,,,,,,,,,,0.115455703560777,6.58464794657854E-6,-0.00025682022385429,10,2,,2400,60,120,,,0.11550565823402,1.07844274119806E-5,0.000750140228774399,-0.000231071215239353,,,,0.0306759620362409,39.995735168457,1.99307327671537,303.5158,285.623107910156,287.631256103516,999.908,999.908,7.422709,6,1,3,4,18.9630000596791,1,18.5808519783183,1.0162353515625,53.7634429931641,54.2522010803223,,,,,,,,,,,,,,,,
,3884279679.87866,310.090494789432,999.908,,,,,,,,,,,,,0.102836430458816,6.34468526262291E-6,-0.000246587799442301,10,2,,2400,60,130,,,0.102824695877022,-2.9403680683094E-5,0.000667914748191833,-0.000205410760827363,,,,0.0273096469802042,39.995735168457,1.99318286677097,327.386,309.072479248047,311.104553222656,999.908,999.908,8.796656,6,1,3,4,18.7929999293685,1,18.5765754792965,1.02752685546875,54.2522010803223,54.7409591674805,,,,,,,,,,,,,,,,
,3884280392.36553,333.549515454005,999.908,,,,,,,,,,,,,0.0908692943010414,6.19377586450768E-6,-0.000211635417314459,10,2,,2400,60,140,,,0.0908605365266143,-3.50054479723166E-5,0.000590298324823379,-0.000181400799192488,,,,0.024134467408868,39.995735168457,1.99338517230991,351.9932,332.535461425781,334.566345214844,999.908,999.908,7.648531,6,1,3,4,18.5930000362843,1,18.5698697380392,1.02691650390625,54.2522010803223,54.7409591674805,,,,,,,,,,,,,,,,
,3884281104.05136,349.435497319936,999.908,,,,,,,,,,,,,0.0829025397339089,1.56169190867034E-6,-0.000162920980319351,10,2,,2400,60,150,,,0.0828952572730405,-9.46995623664002E-6,0.000535510771442205,-0.000164695142302662,,,,0.0218959687371689,39.995735168457,1.98219146425805,350.9871,349.371337890625,349.511627197266,999.908,999.908,9.155283,6,1,3,4,18.5229999689311,1,18.5671229729863,1.01249694824219,54.7409591674805,54.7409591674805,,,,,,,,,,,,,,,,
,3884288458.93018,16.4735469454621,999.908,,,,,,,,,,,,,0.363264896000983,1.4453754734751E-5,-0.00102461565605797,10,2,,2400,60,7,,,0.352999767999972,0.00107423523509866,0.00229110545478761,-0.00071258150273934,,,,0.0937706239775878,39.995735168457,1.99351457287189,18.6519,15.4513912200928,17.4944705963135,999.908,999.908,4.28492,6,1,3,4,20.0829999731779,1,18.5678359859044,1.02630615234375,50.3421325683594,48.3870964050293,,,,,,,,,,,,,,,,
,3884289165.71218,39.4167731356894,999.908,,,,,,,,,,,,,0.333485707979303,1.47155618365975E-5,-5.80909987142602E-5,10,2,,2400,60,17,,,0.325294406173867,0.00412296669763371,0.00210507051087916,-0.000676976691465825,,,,0.0864188744737402,39.995735168457,1.99354580808431,43.6297,38.4140548706055,40.4039840698242,999.908,999.908,5.782277,6,1,3,4,20.1530000405312,1,18.5666995347946,1.01715087890625,53.2746849060059,52.7859268188477,,,,,,,,,,,,,,,,
,3884289875.55689,62.2607377161932,999.908,,,,,,,,,,,,,0.303861503610182,1.4050618988508E-5,-0.000971908559384241,10,2,,2400,60,27,,,0.301685357499717,0.00468825335319835,0.00193936238065362,-0.000630991242360324,,,,0.0797039735110598,39.995735168457,1.98236997287161,69.7001,61.2509727478027,63.2466888427734,999.908,999.908,6.018012,6,1,3,4,20.1429999643862,1,18.5979209843686,1.02256774902344,54.2522010803223,53.7634429931641,,,,,,,,,,,,,,,,
,3884290584.87054,85.5575376744194,999.908,,,,,,,,,,,,,0.274319913839271,1.41691892099461E-5,-0.00106347078137124,10,2,,2400,60,37,,,0.27508377094989,0.00246877397901069,0.00178149458952248,-0.000566835980862379,,,,0.0730627960098526,39.995735168457,1.99316065120612,94.9046,84.5346069335938,86.5293426513672,999.908,999.908,5.840331,6,1,3,4,20.1030001254678,1,18.6012503112383,1.02783203125,54.7409591674805,54.7409591674805,,,,,,,,,,,,,,,,
,3884291295.48698,109.082919757253,999.908,,,,,,,,,,,,,0.248293713792534,1.27107430505082E-5,-0.000820941469325718,10,2,,2400,60,47,,,0.249576690923687,0.00132478656517257,0.00161821383517236,-0.000508337805513293,,,,0.0662891995853018,39.995735168457,1.99324759327587,119.8285,108.066612243652,110.057304382324,999.908,999.908,7.131949,6,1,3,4,20.0530002104044,1,18.600618897636,1.02638244628906,54.7409591674805,55.2297172546387,,,,,,,,,,,,,,,,
,3884291989.61626,132.118713,999.908,,,,,,,,,,,,,,,,,3,,,,,,,,,,,,,,,,,,,,,,7.497232,6,1,3,,19.8729997711182,2,,,52.7859268188477,55.2297172546387,,,,,,,,,,,,,,,,
touchdown = 4.65000001713634 mm,3884292744.11629,157.282101363774,999.908,,,,,,,,,,,,,0.805797115164291,0.0175831327463969,-0.00192769365479605,100,2,,2400,60,66,,,0.809921761299478,0.00203368413226096,0.00525501975789666,-0.00163422140758485,,,,0.21507573336998,39.995735168457,1.99285159119135,170.2607,156.228408813477,158.350540161133,999.908,999.908,7.348926,6,1,3,4,19.7830000171363,1,18.5963484873177,1.02935791015625,54.2522010803223,54.2522010803223,,,,,,,,,,,,,,,,
,3884293456.96122,181.061932535174,999.908,,,,,,,,,,,,,0.184543101561752,1.00949022576168E-5,-0.000460144656783864,10,2,,2400,60,76,,,0.185368892751329,0.000289355126818831,0.00120284932199866,-0.000373026210581884,,,,0.0492177771576478,39.995735168457,1.99256333010745,193.3786,179.990997314453,182.126922607422,999.908,999.908,6.85258,6,1,3,4,19.7029998736382,1,18.6056241726871,1.02897644042969,54.7409591674805,54.7409591674805,,,,,,,,,,,,,,,,
,3884294168.24905,204.738646903516,999.908,,,,,,,,,,,,,0.167123123518314,9.52779062909352E-6,-0.000432332935964991,10,2,,2400,60,86,,,0.167738407352327,0.000148108845198967,0.00109639961738139,-0.000339093443471938,,,,0.04485145955055,39.995735168457,2.00675467674228,217.5327,203.68798828125,205.739059448242,999.908,999.908,6.784464,6,1,3,4,19.553000128448,1,18.6005666640079,1.026611328125,54.7409591674805,54.7409591674805,,,,,,,,,,,,,,,,
,3884294876.0831,228.242312045115,999.908,,,,,,,,,,,,,0.151043650041576,8.38074895118778E-6,-0.000395729177788391,10,2,,2400,60,96,,,0.15146728094783,6.3772550211165E-5,0.000990119762718678,-0.000305793131701648,,,,0.0404988044206897,39.995735168457,2.0066589504732,242.7784,227.217803955078,229.218612670898,999.908,999.908,8.284883,6,1,3,4,19.4330001460314,1,18.6043111783207,1.02592468261719,54.7409591674805,55.2297172546387,,,,,,,,,,,,,,,,
,3884295584.96892,251.751314295401,999.908,,,,,,,,,,,,,0.136131900390563,8.00965772284771E-6,-0.000327994532993297,10,2,,2400,60,106,,,0.136386544508391,4.03518557676383E-5,0.000880628998856991,-0.00027174357092008,,,,0.0360176140361748,39.995735168457,1.98177279375111,265.9061,250.716064453125,252.783325195313,999.908,999.908,8.368062,6,1,3,4,19.2430000962615,1,18.5975869993182,1.01860046386719,54.7409591674805,54.7409591674805,,,,,,,,,,,,,,,,
,3884296296.40547,275.373326203407,999.908,,,,,,,,,,,,,0.122077133245591,7.43865028746347E-6,-0.000285710819249283,10,2,,2400,60,116,,,0.122187154770953,1.11113589896378E-5,0.000793440500274301,-0.000244460330577567,,,,0.0324472545875149,39.995735168457,1.99287667835776,289.9093,274.31494140625,276.413177490234,999.908,999.908,8.536935,6,1,3,4,19.0630001226366,1,18.5843557028563,1.02996826171875,54.7409591674805,55.2297172546387,,,,,,,,,,,,,,,,
,3884297009.27376,299.042533802277,999.908,,,,,,,,,,,,,0.108854654576127,6.91766616323896E-6,-0.000257620237920391,10,2,,2400,60,126,,,0.108845804826122,-1.76683383285095E-5,0.000706992985215038,-0.000217501059523784,,,,0.0289083040753839,39.995735168457,1.99314716932803,314.3973,297.978973388672,300.05810546875,999.908,999.908,8.709216,6,1,3,4,18.9129999117851,1,18.5748344003534,1.01898193359375,54.7409591674805,55.2297172546387,,,,,,,,,,,,,,,,
,3884297719.49218,322.539958991381,999.908,,,,,,,,,,,,,0.096452335344721,6.23792210975784E-6,-0.000241162512605123,10,2,,2400,60,136,,,0.096442328335332,-4.65044076648179E-5,0.000626482884399593,-0.0001925448741531,,,,0.0256141609766847,39.995735168457,1.99315402959621,339.1288,321.543792724609,323.516662597656,999.908,999.908,8.120996,6,1,3,4,18.7730000099093,1,18.5774650462426,1.02371215820312,54.7409591674805,55.2297172546387,,,,,,,,,,,,,,,,
,3884298430.22111,346.09169691933,999.908,,,,,,,,,,,,,0.0847512712412346,5.96023797295978E-6,-0.000183136075996567,10,2,,2400,60,146,,,0.0847437057911792,-2.47085633237436E-5,0.000550604308955371,-0.000169219289091416,,,,0.0225117600949664,39.995735168457,1.99356824511996,356.5132,345.107452392578,347.042999267578,999.908,999.908,8.974178,6,1,3,4,18.5829999601394,1,18.5660799524415,1.02653503417969,55.2297172546387,55.2297172546387,,,,,,,,,,,,,,,,
,3884330149.61531,6.31572163690349,99.984,,,,,,,,,,,,,0.0611844031965387,8.62542029849839E-5,-0.00020311094605349,1,2,,2400,60,2,,,0.0594558284902406,0.000147608967224207,0.000383892329409719,-0.000119029915367719,,,,0.0157077166776296,39.995735168457,1.98257217690346,7.5003,5.17662382125854,7.16150283813477,99.984,99.984,2.706262,6,1,3,4,20.072999897033,1,18.5497759837259,1.01333618164062,46.4320640563965,43.49951171875,,,,,,,,,,,,,,,,
touchdown = 5.04000019282103 mm,3884330850.98886,29.1034456391988,99.984,,,,,,,,,,,,,0.0951332947661236,1.87386499048186E-5,-0.000151531968286193,10,2,,2400,60,12,,,0.0925117457348023,0.000588370513455557,0.000599932507611811,-0.000188762001926079,,,,0.0245794316051182,39.995735168457,1.99386511704351,32.3588,28.0547370910645,30.1472396850586,99.984,99.984,4.977609,6,1,3,4,20.173000192821,1,18.5666150639477,1.01943969726562,51.808406829834,50.8308906555176,,,,,,,,,,,,,,,,
,3884331557.74821,51.8492051938477,99.984,,,,,,,,,,,,,0.0694415055033253,9.608393333625E-6,-2.93193054798579E-5,10,2,,2400,60,22,,,0.0683398988020603,0.0012318637578635,0.000439072289736941,-0.000143936005770229,,,,0.018058102197992,39.995735168457,1.9826179067084,58.174,50.862964630127,52.81591796875,99.984,99.984,6.13946,6,1,3,4,20.1429999643862,1,18.5828377396878,1.01593017578125,53.7634429931641,53.2746849060059,,,,,,,,,,,,,,,,
,3884332265.36381,74.9607050785112,99.984,,,,,,,,,,,,,0.0528058530656619,6.6395583119082E-6,-0.000249250255558326,1,2,,2400,60,32,,,0.0527964367476077,0.000576622246305345,0.000339913327479735,-0.000108843625639565,,,,0.0139487519302139,39.995735168457,1.98251494239599,83.6134,73.9566192626953,75.963508605957,99.984,99.984,6.584153,6,1,3,4,20.1429999643862,1,18.5952589148085,1.02310180664062,53.7634429931641,54.2522010803223,,,,,,,,,,,,,,,,
,3884332978.68077,98.4919387555075,99.984,,,,,,,,,,,,,0.0420423263847429,4.50729041549371E-6,-0.000178757587955351,1,2,,2400,60,42,,,0.042232761287626,0.000251495027164633,0.000273792044026777,-8.61688531585969E-5,,,,0.01121762285262,39.995735168457,1.9932985537889,108.7885,97.4396438598633,99.5008163452148,99.984,99.984,7.061057,6,1,3,4,20.0530002104044,1,18.5942491546017,1.02394104003906,54.2522010803223,54.2522010803223,,,,,,,,,,,,,,,,
,3884333689.46094,122.1008152309,99.984,,,,,,,,,,,,,0.0347558310067702,3.22257901872053E-6,-0.000133088153635045,1,2,,2400,60,52,,,0.0349461108869022,0.00011690020629975,0.000226709642447531,-7.07042418071069E-5,,,,0.00928103879291541,39.995735168457,1.99307501995182,133.4548,121.063095092773,123.11905670166,99.984,99.984,7.131949,6,1,3,4,19.9830001430511,1,18.5949557150613,1.0284423828125,54.7409591674805,54.7409591674805,,,,,,,,,,,,,,,,
,3884334398.20135,145.748853927956,99.984,,,,,,,,,,,,,0.0294919477253497,2.41928818397509E-6,-0.000103419460768825,1,2,,2400,60,62,,,0.0296497323074535,5.82746779065699E-5,0.000192439809325151,-5.97117759753019E-5,,,,0.00787456342074099,39.995735168457,1.99311922683979,157.8559,144.72492980957,146.761123657227,99.984,99.984,7.572504,6,1,3,4,19.8630001606345,1,18.5912958293958,1.02714538574219,54.7409591674805,54.7409591674805,,,,,,,,,,,,,,,,
,3884335109.61033,169.480521104062,99.984,,,,,,,,,,,,,0.0254722710407732,1.88814851941174E-6,-9.22346541644345E-5,1,2,,2400,60,72,,,0.0255950001618228,2.05956367427479E-5,0.00016617109940853,-5.13638369739056E-5,,,,0.00679737938998378,39.995735168457,1.9930330694444,182.1115,168.434799194336,170.479995727539,99.984,99.984,6.921379,6,1,3,4,19.8030001694262,1,18.5957989714824,1.02645874023438,54.7409591674805,54.7409591674805,,,,,,,,,,,,,,,,
,3884335820.99502,193.105087969949,99.984,,,,,,,,,,,,,0.0223268909706992,1.51693066171902E-6,-7.73387401398925E-5,1,2,,2400,60,82,,,0.0224181853919692,6.03660245394183E-6,0.000144771562190726,-4.46480335085653E-5,,,,0.00592084559128646,39.995735168457,1.9819560413263,206.2538,192.085815429687,194.086120605469,99.984,99.984,8.040272,6,1,3,4,19.6230001958013,1,18.5899233138709,1.0247802734375,54.7409591674805,55.2297172546387,,,,,,,,,,,,,,,,
,3884336532.23333,216.730034365118,99.984,,,,,,,,,,,,,0.0197675684005493,1.23090186271921E-6,-7.08200000023602E-5,1,2,,2400,60,92,,,0.0198317257626356,-6.86128152791246E-6,0.000128780578961596,-3.96384821215179E-5,,,,0.00526595259230583,39.995735168457,1.99271031014082,230.254,215.749877929687,217.702743530273,99.984,99.984,7.131949,6,1,3,4,19.5329999761581,1,18.593529318776,1.02821350097656,54.7409591674805,55.2297172546387,,,,,,,,,,,,,,,,
,3884337231.88434,239.900589,99.984,,,,,,,,,,,,,,,,,3,,,,,,,,,,,,,,,,,,,,,,8.120996,6,1,3,,19.2530001724064,2,,,52.2971649169922,54.7409591674805,,,,,,,,,,,,,,,,
touchdown = 3.94000019878149 mm,3884337986.91298,264.983781337857,99.984,,,,,,,,,,,,,0.0158059297992197,7.37058710147565E-7,-3.37360128441209E-5,1,2,,2400,60,111,,,0.0158269308450682,6.50165228204946E-6,0.000102191675978247,-3.15378565574065E-5,,,,0.00417966868773345,39.995735168457,1.98178070652537,281.3122,263.951324462891,265.998046875,99.984,99.984,7.881224,6,1,3,4,19.0730001987815,1,18.592873707167,1.02371215820312,54.2522010803223,54.7409591674805,,,,,,,,,,,,,,,,
,3884338700.39286,288.610091203002,99.984,,,,,,,,,,,,,0.0142704639242511,7.73118512346491E-7,-4.41864237270305E-5,1,2,,2400,60,121,,,0.014275495700274,-1.13823535422787E-5,9.27259679883719E-5,-2.84722045762464E-5,,,,0.00379085824613997,39.995735168457,1.99284804968016,304.1581,287.565551757813,289.648681640625,99.984,99.984,8.536935,6,1,3,4,18.9829999791384,1,18.5805953435927,1.02485656738281,54.2522010803223,54.2522010803223,,,,,,,,,,,,,,,,
,3884339410.70221,312.052286323775,99.984,,,,,,,,,,,,,0.0128953244356637,7.73525312465264E-7,-4.02987812935715E-5,1,2,,2400,60,131,,,0.0128938943390859,-1.32603109444743E-5,8.3318431279622E-5,-2.55626619036775E-5,,,,0.00340601622765559,39.995735168457,1.98231971984235,328.6587,310.976989746094,313.089630126953,99.984,99.984,8.622645,6,1,3,4,18.7730000099093,1,18.5807080585498,1.02272033691406,54.2522010803223,54.7409591674805,,,,,,,,,,,,,,,,
,3884340119.85973,335.448983409153,99.984,,,,,,,,,,,,,0.0115709515229273,8.08956338341233E-7,-3.73248071092274E-5,1,2,,2400,60,141,,,0.0115698704167766,-1.49707271531975E-5,7.47742960811593E-5,-2.29083034355426E-5,,,,0.00305635863921967,39.995735168457,1.98237985157965,353.535,334.411956787109,336.485443115234,99.984,99.984,8.884974,6,1,3,4,18.6330001080334,1,18.5728359962455,1.01821899414062,54.2522010803223,54.7409591674805,,,,,,,,,,,,,,,,
,3884340831.03061,349.569952013968,99.984,,,,,,,,,,,,,0.0107043495295294,2.65854824528895E-7,-3.12190390554239E-5,1,2,,2400,60,151,,,0.0107034286502135,-1.14106295320657E-5,6.91778914188035E-5,-2.12035811273381E-5,,,,0.00282772115693644,39.995735168457,1.98255438473316,350.8856,349.495971679687,349.630981445313,99.984,99.984,9.340043,5,1,3,4,18.4929999733269,1,18.5672197068997,1.0211181640625,54.2522010803223,54.7409591674805,,,,,,,,,,,,,,,,
,3884348114.8563,16.3468238142095,99.984,,,,,,,,,,,,,0.120195488589619,1.87665241104462E-5,-0.000283364908182122,10,2,,2400,60,7,,,0.116796326965902,0.000401869680802053,0.000757898378651589,-0.000236114268773235,,,,0.0310239051783187,39.995735168457,1.99339589111045,18.4893,15.3211860656738,17.3327026367187,99.984,99.984,3.725659,6,1,3,4,20.0530002104044,1,18.5720777856907,1.02531433105469,50.3421325683594,48.3870964050293,,,,,,,,,,,,,,,,
,3884348821.47806,39.2992837894562,99.984,,,,,,,,,,,,,0.0855604360644874,1.39600043469696E-5,-6.34610029507194E-6,10,2,,2400,60,17,,,0.0834507483793437,0.00105692070658261,0.000537072424776852,-0.00017277967708651,,,,0.0220490119678993,39.995735168457,1.98260336340958,43.505,38.2974243164063,40.2852935791016,99.984,99.984,5.611556,6,1,3,4,20.072999897033,1,18.5731096941748,1.011962890625,53.2746849060059,52.7859268188477,,,,,,,,,,,,,,,,
,3884349532.60164,62.1574757964378,99.984,,,,,,,,,,,,,0.0642906349051291,8.27067649636795E-6,-0.000197532293905492,10,2,,2400,60,27,,,0.0638236423097747,0.00100119657251951,0.000412516266806051,-0.000134241869091056,,,,0.0169539144752758,39.995735168457,1.99325840973357,69.6381,61.1293334960937,63.1511878967285,99.984,99.984,6.584153,6,1,3,4,20.0930000493228,1,18.5927212297829,1.01737976074219,54.2522010803223,53.7634429931641,,,,,,,,,,,,,,,,
,3884350241.98136,85.478232210083,99.984,,,,,,,,,,,,,0.0506307558152227,5.44523332966448E-6,-0.000230992391469776,1,2,,2400,60,37,,,0.0507710467143573,0.000422200243040929,0.000327179674059153,-0.000103787278931122,,,,0.0134145938823879,39.995735168457,1.98270603322045,94.8813,84.4671096801758,86.4393997192383,99.984,99.984,5.898967,6,1,3,4,20.0530002104044,1,18.5889305560183,1.00845336914062,54.7409591674805,54.7409591674805,,,,,,,,,,,,,,,,
,3884350953.50346,109.007585232198,99.984,,,,,,,,,,,,,0.0416190873246795,3.77193061177181E-6,-0.000185930124407002,1,2,,2400,60,47,,,0.0418344167624384,0.000173903267896271,0.000269858748652041,-8.44140304252505E-5,,,,0.0110504225363888,39.995735168457,1.98222334925072,119.8004,108.015922546387,109.983123779297,99.984,99.984,7.275877,6,1,3,4,20.0330000581145,1,18.5973511731036,1.01493835449219,54.7409591674805,54.7409591674805,,,,,,,,,,,,,,,,
,3884351652.18118,132.20253,99.984,,,,,,,,,,,,,,,,,3,,,,,,,,,,,,,,,,,,,,,,5.958192,6,1,3,,19.8329999321997,2,,,52.2971649169922,54.7409591674805,,,,,,,,,,,,,,,,
touchdown = 4.56999987363815 mm,3884352405.93798,157.341516164248,99.984,,,,,,,,,,,,,0.030228451592281,2.22849846551404E-6,-8.5866424107809E-5,1,2,,2400,60,66,,,0.0303832015742879,6.26014274637439E-5,0.000197135464986786,-6.12226285738871E-5,,,,0.00806733174650962,39.995735168457,1.99261347312582,170.3784,156.295471191406,158.383697509766,99.984,99.984,7.648531,6,1,3,4,19.7029998736382,1,18.6001296420821,1.02241516113281,54.2522010803223,54.7409591674805,,,,,,,,,,,,,,,,
,3884353115.26643,181.010428212653,99.984,,,,,,,,,,,,,0.0264402123011026,1.87669311993803E-6,-9.38298847752804E-5,1,2,,2400,60,76,,,0.0265586665918191,1.34652377559536E-5,0.000172426385688595,-5.32517697138246E-5,,,,0.00705273158326092,39.995735168457,1.99287034626499,193.4987,179.935562133789,182.070648193359,99.984,99.984,7.960351,6,1,3,4,19.6130001196563,1,18.5990256188774,1.03096008300781,54.2522010803223,54.7409591674805,,,,,,,,,,,,,,,,
,3884353827.8122,204.72057514725,99.984,,,,,,,,,,,,,0.0232968491319016,1.58994234871795E-6,-8.59351309581496E-5,1,2,,2400,60,86,,,0.0233827397366865,-5.09165076529542E-6,0.000151858170283958,-4.67354147986043E-5,,,,0.00620954322986376,39.995735168457,1.99293143980872,217.6998,203.641662597656,205.731109619141,99.984,99.984,8.20253,6,1,3,4,19.5229999000132,1,18.5840053291891,1.02668762207031,54.2522010803223,54.7409591674805,,,,,,,,,,,,,,,,
,3884354539.39526,228.349086861777,99.984,,,,,,,,,,,,,0.0206343100383323,1.28928804594355E-6,-5.71986131665495E-5,1,2,,2400,60,96,,,0.0206921054389676,5.53385621654325E-6,0.000134335772600025,-4.14529313275125E-5,,,,0.00549431301332141,39.995735168457,1.99267466768411,243.0357,227.331268310547,229.319946289062,99.984,99.984,8.368062,6,1,3,4,19.3730001548231,1,18.5991143538802,1.02867126464844,54.7409591674805,54.7409591674805,,,,,,,,,,,,,,,,
,3884355250.65477,251.931199905889,99.984,,,,,,,,,,,,,0.0184095363720308,2.4451849065061E-6,-5.71316898206072E-5,1,2,,2400,60,106,,,0.0184438632633037,-7.38559739449363E-6,0.000119758064101916,-3.68569817510433E-5,,,,0.00489696353502602,39.995735168457,1.99251864087618,266.1459,250.920822143555,252.948150634766,99.984,99.984,7.497232,6,1,3,4,19.2229999439716,1,18.5947342708679,1.02836608886719,54.7409591674805,55.2297172546387,,,,,,,,,,,,,,,,
,3884355958.21377,275.395855057538,99.984,,,,,,,,,,,,,0.0162901710138471,1.07163191046478E-6,-5.33884866995673E-5,1,2,,2400,60,116,,,0.016304868257701,-1.37972488712711E-5,0.000105899103800766,-3.25189575960394E-5,,,,0.00432942852858582,39.995735168457,1.99269512313855,289.9832,274.361114501953,276.436492919922,99.984,99.984,7.061057,6,1,3,4,19.0730001987815,1,18.584306448607,1.02775573730469,54.7409591674805,54.7409591674805,,,,,,,,,,,,,,,,
,3884356669.27172,299.039351303658,99.984,,,,,,,,,,,,,0.0914773219598381,0.0013038888072423,-0.000161915148959162,10,2,,2400,60,126,,,0.0914698045882481,3.97434528889504E-5,0.00059397384757176,-0.000183215321158059,,,,0.024292619453262,39.995735168457,1.99308078603222,314.3597,298.001556396484,300.046936035156,99.984,99.984,8.368062,6,1,3,4,18.9129999117851,1,18.5832577854894,1.02622985839844,54.7409591674805,54.7409591674805,,,,,,,,,,,,,,,,
,3884357379.3606,322.546864642686,99.984,,,,,,,,,,,,,0.0126570045865872,8.95190370212591E-7,-4.14866825389598E-5,1,2,,2400,60,136,,,0.0126557110826427,-1.59397379845966E-5,8.17854670458473E-5,-2.50645753112622E-5,,,,0.00334303132298646,39.995735168457,1.98227914116767,339.0613,321.553466796875,323.514801025391,99.984,99.984,8.974178,6,1,3,4,18.75300009045,1,18.5761695666662,1.01974487304688,54.7409591674805,54.7409591674805,,,,,,,,,,,,,,,,
,3884358089.98521,346.103796446871,99.984,,,,,,,,,,,,,0.108896973138386,0.000208217024107429,-0.000130793233127475,10,2,,2400,60,146,,,0.108887057018516,7.27597327821947E-5,0.000703323865309358,-0.00021703154197894,,,,0.0287658635741438,39.995735168457,1.9824975708567,356.4922,345.096435546875,347.047302246094,99.984,99.984,9.064279,6,1,3,4,18.6129999557435,1,18.5762978191321,1.02218627929688,54.7409591674805,54.7409591674805,,,,,,,,,,,,,,,,
,3884358619.43526,349.776000704392,99.984,,,,,,,,,,,,,0.0107077133716371,2.57167012508919E-7,-3.33237997993324E-5,1,2,,2400,60,153,,,0.010706797240832,-1.3521088798857E-5,6.95717972121201E-5,-2.13127514143707E-5,,,,0.00284369006252008,39.995735168457,1.99319997713406,350.8608,349.734710693359,349.814910888672,99.984,99.984,9.433816,1,1,3,4,18.5030000494719,1,18.5697874559652,1.02378845214844,54.7409591674805,54.7409591674805,,,,,,,,,,,,,,,,