File: DataFailid_Testimiseks/6_BiFeO3_600C_MvsT_OVEN_300-750K_03052023.DAT
[Header]
; VSM Data File (default extension .dat)
; Copyright (c) 2003-2013, Quantum Design, Inc. All rights reserved.
TITLE,6_BiFeO3_600C_MvsT_OVEN_300-750K_03052023
FILEOPENTIME,22089952.48,05/03/2023,6:44 pm
BYAPP,VSM,2.0,2.0
INFO,PPMS VSM Option Release 1.4.10 Build 1,APPNAME
INFO,Quantum Design Linear Motor Servo Controller,MOTOR_MODULE_NAME
INFO,3101-100 C1,MOTOR_HW_VERSION
INFO,074,MOTOR_SERIAL_NUMBER
INFO,SRV No X-over 01.01.11,MOTOR_SOFTWARE_VERSION
INFO,Quantum Design VSM Detection Module,VSM_MODULE_NAME
INFO,3101-150 E1,VSM_HW_VERSION
INFO,VSM061,VSM_SERIAL_NUMBER
INFO,VSM No X-over 01.02.05 May 20 2008 13:51:47,VSM_SOFTWARE_VERSION
INFO,113,PREAMP_SERIAL_NUMBER
INFO,Quantum Design VSM Oven Module,OVEN_MODULE_NAME
INFO,unknown,OVEN_HW_VERSION
INFO,OVN054,OVEN_SERIAL_NUMBER
INFO,unknown,OVEN_SOFTWARE_VERSION
INFO,818,COIL_SERIAL_NUMBER
INFO,0,MOMENT_UNITS
INFO,6_BiFeO3_600C_MvsT_OVEN_300-750K_03052023,SAMPLE_MATERIAL
INFO,powder mixed with BUSTER cement,SAMPLE_COMMENT
INFO,,SAMPLE_MASS
INFO,,SAMPLE_VOLUME
INFO,,SAMPLE_MOLECULAR_WEIGHT
INFO,,SAMPLE_SIZE
INFO,,SAMPLE_SHAPE
DATATYPE,COMMENT,1
DATATYPE,TIME,2
STARTUPAXIS,X,2
STARTUPAXIS,Y1,5
[Data]
Comment,Time Stamp (sec),Temperature (K),Magnetic Field (Oe),Moment (emu),M. Std. Err. (emu),Transport Action,Averaging Time (sec),Frequency (Hz),Peak Amplitude (mm),Center Position (mm),Coil Signal' (mV),Coil Signal" (mV),Range (mV),M. Quad. Signal (emu),M. Raw' (emu),M. Raw" (emu),Min. Temperature (K),Max. Temperature (K),Min. Field (Oe),Max. Field (Oe),Mass (grams),Motor Lag (deg),Pressure (Torr),VSM Status (code),Motor Status (code),Measure Status (code),Measure Count,PPMS Status (code),System Temp. (K),System Field (Oe),Sample Position (deg),Bridge 1 Resistance (ohms),Bridge 1 Excitation (에),Bridge 2 Resistance (ohms),Bridge 2 Excitation (에),Bridge 3 Resistance (ohms),Bridge 3 Excitation (에),Bridge 4 Resistance (ohms),Bridge 4 Excitation (에),Signal 1 Vin (V),Signal 2 Vin (V),Digital Inputs (code),Drive 1 Iout (mA),Drive 1 Ipower (W),Drive 2 Iout (mA),Drive 2 Ipower (W),Pressure (),Map 20 (),Map 21 (),Map 22 (),Map 23 (),Map 24 (),Map 25 (),Map 26 (),Map 27 (),Map 28 (),Map 29 ()
sample offset = 35.76 mm touchdown = 5.65999979153276 mm,22104906.665,649.987365722656,999.823,0.00581326148122786,5.64328791689328E-7,1,60.005163911891,40.0298881530762,1.97406311443685,10.329999960959,0.0640008360937908,0.0110877669817953,2.5,-4.3245533146158E-6,0.00581351142812817,-2.86180444660761E-7,297.3508606,297.3508606,999.823,999.823,58.6487143119677,21.6254887089116,44.313087,0,0,0,2402,5905,283.2348,999.823,,,,,,,,,,,,,0,,,,9.2E-6,,,,,,297.3508606,,,,
,22105977.62,563.445617675781,999.823,0.00681126693337927,2.73689472466589E-7,1,60.005163911891,40.0298881530762,1.98472530334559,10.329999960959,0.0753785296197481,0.0130896717525332,2.5,-2.30859743312461E-6,0.00681215474386382,2.36566218264428E-6,294.4268188,294.5530701,999.823,999.823,59.0614141701216,21.6550651502431,38.213703,0,0,0,2402,5906,286.1646,999.823,,,,,,,,,,,,,0,,,,9.25E-6,,,,,,294.48994445,,,,
,22107057.68,473.701507568359,999.823,0.00736245996321228,2.16783564735973E-7,1,60.005163911891,40.0298881530762,1.98464346235924,10.329999960959,0.0814714905921201,0.0141654833764386,2.5,-8.41065573356892E-7,0.00736335284012051,4.1146111009634E-6,294.8281555,294.8321838,999.823,999.823,60.2377650915641,21.6660013757035,38.594913,0,0,0,2402,5906,290.85765,999.823,,,,,,,,,,,,,0,,,,9.2E-6,,,,,,294.83016965,,,,
,22108137.805,383.728149414063,999.823,0.00779579268034677,2.0079632369589E-7,1,60.005163911891,40.0298881530762,1.98471790038319,10.329999960959,0.0862678428492589,0.0150107090613361,2.5,1.47545308259578E-7,0.00779673568260053,5.34647500827884E-6,294.8583374,294.8597412,999.823,999.823,59.9626318527948,21.6669084760746,38.213703,0,0,0,2402,5906,293.1376,999.823,,,,,,,,,,,,,0,,,,9.2E-6,,,,,,294.8590393,,,,
sample offset = 35.76 mm,22109639.585,299.943115234375,999.823,0.00811658016221672,1.38961873868625E-7,1,60.005163911891,40.0298881530762,1.98483064568688,10.329999960959,0.0898253203021127,0.0156115061018136,2.5,-1.40503762340509E-6,0.00811753489101286,3.96926577127166E-6,294.9894714,294.9894714,999.823,999.823,59.2904313262563,21.7022795366612,38.213703,0,0,0,2402,5905,294.8956,999.823,,,,,,,,,,,,,0,,,,9.2E-6,,,,,,294.9894714,,,,
,22110718.025,386.936798095703,999.823,0.00782973588201441,1.47145391047642E-7,1,60.005163911891,40.0298881530762,1.98446443424735,10.329999960959,0.0866346395804779,0.0150596340762839,2.5,-1.15174542222108E-6,0.00783061928484179,4.06265688385192E-6,295.1330261,295.1351318,999.823,999.823,59.353743236314,21.7034778324273,38.594913,0,0,0,2402,5906,293.46705,999.823,,,,,,,,,,,,,0,,,,9.2E-6,,,,,,295.13407895,,,,
,22111858.28,481.890319824219,999.823,0.00737390677047094,2.10463865836122E-7,1,60.005163911891,40.0298881530762,1.98489479064117,10.329999960959,0.0816084211054716,0.014182082993113,2.5,-1.46967770450479E-6,0.00737472276597725,3.48865361401577E-6,295.1830444,295.1858215,999.823,999.823,60.2830995456794,21.7198320715272,38.976128,0,0,0,2402,5906,291.1008,999.823,,,,,,,,,,,,,0,,,,9.15E-6,,,,,,295.18443295,,,,
,22112938.275,572.141967773438,999.823,0.00679985666077935,2.58873137473471E-7,1,60.005163911891,40.0298881530762,1.9849765122219,10.329999960959,0.0752616149721517,0.0130581091933405,2.5,-3.25662208315256E-6,0.00680059168437567,1.37395528973745E-6,295.2431335,295.2475281,999.823,999.823,59.6773374432755,21.7168830804144,39.357338,0,0,0,2402,5906,288.01345,999.823,,,,,,,,,,,,,0,,,,9.3E-6,,,,,,295.2453308,,,,
sample offset = 35.76 mm,22114464.725,649.938110351562,999.823,0.00632541425902042,1.99334768753009E-7,1,60.005163911891,40.0298881530762,1.99900201780012,10.329999960959,0.0704879026724387,0.0122145162087845,2.5,-4.44430673842836E-6,0.0063261469784653,-5.84498518148592E-8,294.9507751,294.9515686,999.823,999.823,60.8458720795257,21.7240639908192,38.213703,0,0,0,2402,5905,283.6843,999.823,,,,,,,,,,,,,0,,,,9.15E-6,,,,,,294.95117185,,,,
,22115518.49,563.441223144531,999.823,0.00719578710854922,2.67033945723929E-7,1,60.005163911891,40.0298881530762,1.99849296549547,10.329999960959,0.0801679861158671,0.0138924009810414,2.5,-4.93153932700369E-6,0.00719667857867677,-2.56386552451199E-8,294.7226257,294.7298889,999.823,999.823,60.0947270725448,21.7309146485797,38.594913,0,0,0,2402,5906,287.72475,999.823,,,,,,,,,,,,,0,,,,9.25E-6,,,,,,294.7262573,,,,
,22116598.62,473.656280517578,999.823,0.00780345515386993,2.25965293519255E-7,1,60.005163911891,40.0298881530762,1.99852096715176,10.329999960959,0.0869397149257454,0.0150617787821526,2.5,-5.63634090348463E-6,0.00780440976768118,-3.85364463795925E-7,294.807373,294.8110352,999.823,999.823,60.2940423449487,21.7397485125406,38.213703,0,0,0,2402,5906,290.90225,999.823,,,,,,,,,,,,,0,,,,9.15E-6,,,,,,294.8092041,,,,
,22117678.78,383.726898193359,999.823,0.00831446190372603,2.05677235491281E-7,1,60.005163911891,40.0298881530762,1.99860493415613,10.329999960959,0.0926321268143648,0.0160743068275414,2.5,-3.6577644389741E-6,0.00831546967916951,1.88596166644741E-6,294.859375,294.8632813,999.823,999.823,61.1741560576026,21.7499534126079,38.213703,0,0,0,2402,5906,293.1659,999.823,,,,,,,,,,,,,0,,,,9.3E-6,,,,,,294.86132815,,,,
,22118758.8,304.924041748047,999.823,0.00867421847449555,1.666726727476E-7,1,60.005163911891,40.0298881530762,1.99781192668786,10.329999960959,0.09660454997335,0.0167564024021422,2.5,-4.40912348693989E-6,0.00867525931663995,1.33702739566294E-6,294.9110718,294.9241638,999.823,999.823,60.8716658206603,21.7481020458062,38.213703,0,0,0,2402,5905,294.76815,999.823,,,,,,,,,,,,,0,,,,9.2E-6,,,,,,294.9176178,,,,
,22120199.015,381.916381835937,999.823,0.00838382217490854,2.33128012057504E-7,1,60.005163911891,40.0298881530762,1.9983144531346,10.329999960959,0.0933925671608296,0.0161975505606404,2.5,-4.43782728880581E-6,0.00838476993910797,1.14217043243936E-6,295.1355896,295.1373291,999.823,999.823,59.3373290374101,21.7640315623955,38.594913,0,0,0,2402,5906,293.6019,999.823,,,,,,,,,,,,,0,,,,9.2E-6,,,,,,295.13645935,,,,
,22121279.205,471.865844726562,999.823,0.00788662024057948,2.56871967518302E-7,1,60.005163911891,40.0298881530762,1.9977711427205,10.329999960959,0.0878309936755812,0.0152322986630494,2.5,-4.28086200930319E-6,0.0078874980637031,1.01516977349658E-6,295.171051,295.1763916,999.823,999.823,59.3076271536794,21.7665694671378,38.976128,0,0,0,2402,5906,291.41265,999.823,,,,,,,,,,,,,0,,,,9.2E-6,,,,,,295.1737213,,,,
,22122359.18,561.969482421875,999.823,0.00724957481054152,3.02647022772232E-7,1,60.005163911891,40.0298881530762,1.99784161590798,10.3200003504753,0.0807388757566868,0.0140025749799934,2.5,-3.97315928826561E-6,0.00725036220158062,9.54412581023346E-7,295.2332458,295.2352295,999.823,999.823,59.5413340809294,21.7728103426165,39.357338,0,0,0,2402,5906,288.46455,999.823,,,,,,,,,,,,,0,,,,9.3E-6,,,,,,295.23423765,,,,
,22123499.27,649.977478027344,999.823,0.00644746783550899,1.99706070889422E-7,1,60.005163911891,40.0298881530762,1.99802895325151,10.329999960959,0.0718127092664609,0.0124499163370966,2.5,-4.01470672910748E-6,0.00644814229562558,4.48693355728492E-7,295.3032532,295.3439941,999.823,999.823,59.9899888509679,21.7804711645237,40.500973,0,0,0,2402,5905,284.06455,999.823,,,,,,,,,,,,,0,,,,9.2E-6,,,,,,295.32362365,,,,
,22124999.42,568.481140136719,999.823,0.00734964528658455,3.27235401530747E-7,1,60.005163911891,40.0298881530762,1.99715500713906,10.329999960959,0.0818307351538543,0.0141736803985228,2.5,-5.63700391893603E-6,0.00735055710511874,-6.2446024346794E-7,294.7184448,294.7244568,999.823,999.823,60.8247681095064,21.796338765703,37.832493,0,0,0,2402,5906,287.6371,999.823,,,,,,,,,,,,,0,,,,9.2E-6,,,,,,294.7214508,,,,
,22126079.53,478.770294189453,999.823,0.00802788893074481,3.05535503906398E-7,1,60.005163911891,40.0298881530762,1.99644821001725,10.329999960959,0.0893362900208123,0.0155655491389589,2.5,1.9255011168642E-6,0.00802886584719095,7.33103460365218E-6,294.8057556,294.8100281,999.823,999.823,59.4279979456409,21.7484858810702,37.451283,0,0,0,2402,5906,290.78505,999.823,,,,,,,,,,,,,0,,,,9.2E-6,,,,,,294.80789185,,,,
,22127159.695,389.115936279297,999.823,0.00858672400147695,2.717167631032E-7,1,60.005163911891,40.0298881530762,1.99738232661805,10.329999960959,0.09561239532121,0.0165733253321592,2.5,-5.36187976846677E-6,0.00858776630304291,3.65744653531473E-7,294.8557129,294.8612976,999.823,999.823,60.7630194564872,21.8143231284309,37.832493,0,0,0,2402,5906,293.0559,999.823,,,,,,,,,,,,,0,,,,9.2E-6,,,,,,294.85850525,,,,
,22128239.755,305.310852050781,999.823,0.00899706003634774,2.31054672158645E-7,1,60.005163911891,40.0298881530762,1.99446613795885,10.329999960959,0.100037653640625,0.0173609647693551,2.5,-3.78214970817243E-6,0.00899814269686826,2.17950240182123E-6,294.8991394,294.9085083,999.823,999.823,59.2529131573332,21.8227995176396,38.594913,0,0,0,2402,5909,294.704,999.823,,,,,,,,,,,,,0,,,,9.25E-6,,,,,,294.90382385,,,,
,22129679.895,376.787872314453,999.823,0.00872146311018334,2.41986497738591E-7,1,60.005163911891,40.0298881530762,1.99530341540426,10.3399995714426,0.097000830895518,0.0168979697890634,2.5,1.89829416739519E-6,0.0087224460301682,7.70128263498248E-6,295.1322632,295.1325989,999.823,999.823,61.1616500012949,21.8644049802224,38.976128,0,0,0,2402,5906,293.70685,999.823,,,,,,,,,,,,,0,,,,9.2E-6,,,,,,295.13243105,,,,
,22130760.02,466.913269042969,999.823,0.0081915789079641,2.90640873318222E-7,1,60.005163911891,40.0298881530762,1.99550341033006,10.329999960959,0.0911207675293983,0.0158454399324852,2.5,-7.25141437899282E-7,0.00819248897200342,4.7727661362524E-6,295.1707764,295.1730652,999.823,999.823,61.1225685753334,21.8675480475657,38.594913,0,0,0,2402,5906,291.5606,999.823,,,,,,,,,,,,,0,,,,9.2E-6,,,,,,295.1719208,,,,
,22131840.095,557.110168457031,999.823,0.00751702280487254,3.69680813534695E-7,1,60.005163911891,40.0298881530762,1.99533414412188,10.329999960959,0.0836195092443667,0.0144857907564849,2.5,-5.54420106994487E-6,0.00751784181680591,-4.39516418227532E-7,295.2271423,295.2314453,999.823,999.823,60.813043681718,21.8551308242117,38.976128,0,0,0,2402,5906,288.67875,999.823,,,,,,,,,,,,,0,,,,9.25E-6,,,,,,295.2292938,,,,
,22132920.175,647.347778320312,999.823,0.00668872725256862,3.639278067757E-7,1,60.005163911891,40.0298881530762,1.99543595089723,10.329999960959,0.0744043447876584,0.0129160951189318,2.5,-2.68125631478279E-6,0.00668942564223163,1.93842057362188E-6,295.3265991,295.335022,999.823,999.823,60.7497317716603,21.8803904057516,40.119759,0,0,0,2402,5906,284.62595,999.823,,,,,,,,,,,,,0,,,,9.25E-6,,,,,,295.33081055,,,,
,22134420.3,578.373291015625,999.823,0.00740059805844103,3.21188170193559E-7,1,60.005163911891,40.0298881530762,1.99714978161629,10.329999960959,0.0823932660836199,0.0142984596886383,2.5,-3.30018230343066E-6,0.0074015190328899,1.75595865883826E-6,294.6904907,294.7045898,999.823,999.823,59.7930184641217,21.8347726882599,38.213703,0,0,0,2402,5906,287.229,999.823,,,,,,,,,,,,,0,,,,9.25E-6,,,,,,294.69754025,,,,
,22135500.45,488.824371337891,999.823,0.00813613773602791,2.98285781870102E-7,1,60.005163911891,40.0298881530762,1.9972858184621,10.329999960959,0.0905846784312518,0.0157395630835207,2.5,-1.84759689325863E-6,0.00813713119680092,3.63718632495265E-6,294.8010559,294.8023071,999.823,999.823,60.291697459391,21.8410819697411,37.451283,0,0,0,2402,5906,290.4813,999.823,,,,,,,,,,,,,0,,,,9.1E-6,,,,,,294.8016815,,,,
,22136580.555,399.038299560547,999.823,0.00873914676352831,2.84333034482339E-7,1,60.005163911891,40.0298881530762,1.99700950481719,10.329999960959,0.0972882223055608,0.0168873242863774,2.5,-3.4119891704606E-6,0.00874020584049835,2.42293265709856E-6,294.8562927,294.8592224,999.823,999.823,60.2190060071025,21.8582715028558,38.213703,0,0,0,2402,5906,292.82885,999.823,,,,,,,,,,,,,0,,,,9.3E-6,,,,,,294.85775755,,,,
,22137660.765,310.848663330078,999.823,0.00917863154842235,2.59859411803381E-7,1,60.005163911891,40.0298881530762,1.99686771624061,10.329999960959,0.102173931100425,0.0177343080501826,2.5,-3.63481702292492E-6,0.00917973796782753,2.45064475204823E-6,294.8935852,294.896698,999.823,999.823,59.9790460516986,21.8692667059554,38.594913,0,0,0,2402,5910,294.5627,999.823,,,,,,,,,,,,,0,,,,9.2E-6,,,,,,294.8951416,,,,
,22139100.775,366.975799560547,999.823,0.0089809970990329,2.54068102310023E-7,1,60.005163911891,40.0298881530762,1.99713204622959,10.329999960959,0.0999747503449294,0.0174184554949047,2.5,2.17041172582968E-6,0.00898200995023312,8.14111677746019E-6,295.1311646,295.1314697,999.823,999.823,60.7043973175449,21.8733501693108,38.976128,0,0,0,2402,5906,293.9134,999.823,,,,,,,,,,,,,0,,,,9.3E-6,,,,,,295.13131715,,,,
,22140180.86,456.97900390625,999.823,0.00844985583689458,2.99518689244357E-7,1,60.005163911891,40.0298881530762,1.99506474367335,10.329999960959,0.0939740443213461,0.0163412463346248,2.5,-7.73497546934494E-7,0.00845079708874709,4.89147996077733E-6,295.1647949,295.164856,999.823,999.823,60.7059605745833,21.9186608838514,38.594913,0,0,0,2402,5906,291.83185,999.823,,,,,,,,,,,,,0,,,,9.15E-6,,,,,,295.16482545,,,,
,22141261.07,547.113220214844,999.823,0.00776285239528815,3.57223600711658E-7,1,60.005163911891,40.0298881530762,1.99534404986586,10.329999960959,0.0863474253885132,0.0150006321003564,2.5,-2.02831413239951E-6,0.00776369854501396,3.23583544111868E-6,295.2195435,295.2218018,999.823,999.823,60.9271614455257,21.9063205255488,38.213703,0,0,0,2402,5906,289.0411,999.823,,,,,,,,,,,,,0,,,,9.3E-6,,,,,,295.22067265,,,,
,22142341.17,637.386474609375,999.823,0.00692685632481457,3.84347456501046E-7,1,60.005163911891,40.0298881530762,1.99564543011893,10.329999960959,0.0770597035988339,0.0133851080846967,2.5,-2.06250238726615E-6,0.00692758402514314,2.71085195506146E-6,295.3084717,295.3172607,999.823,999.823,61.7392734770065,21.9058124469693,39.738548,0,0,0,2402,5906,285.169,999.823,,,,,,,,,,,,,0,,,,9.2E-6,,,,,,295.3128662,,,,
,22143841.28,588.311340332031,999.823,0.00743134685807544,3.30167662232731E-7,1,60.005163911891,40.0298881530762,1.9822255576677,10.329999960959,0.0821381180966913,0.0142803200400428,2.5,-1.02786720031324E-6,0.007432276274215,4.05913384379081E-6,294.6581726,294.6730042,999.823,999.823,60.9154370177372,21.9023115821215,37.451283,0,0,0,2402,5906,286.776,999.823,,,,,,,,,,,,,0,,,,9.2E-6,,,,,,294.6655884,,,,
,22144921.43,498.620910644531,999.823,0.00819575855378489,2.85134164431417E-7,1,60.005163911891,40.0298881530762,1.9809856397315,10.329999960959,0.0905247817301718,0.01578380139948,2.5,2.93400188117217E-6,0.00819675694216532,8.46635292389455E-6,294.7932434,294.7972412,999.823,999.823,60.7145584882949,21.9420920330354,38.213703,0,0,0,2402,5906,290.18195,999.823,,,,,,,,,,,,,0,,,,9.2E-6,,,,,,294.7952423,,,,
,22146001.45,409.004089355469,999.823,0.00883951451557121,2.977417268161E-7,1,60.005163911891,40.0298881530762,1.98128200882738,10.329999960959,0.0976518715954365,0.0170106494957934,2.5,1.83325184002824E-6,0.00884058371980968,7.74105810465013E-6,294.849884,294.8504028,999.823,999.823,61.1374195171988,21.9016391355536,38.213703,0,0,0,2402,5906,292.61095,999.823,,,,,,,,,,,,,0,,,,9.25E-6,,,,,,294.8501434,,,,
sample offset = 35.71 mm,22148830.68,300.0332947,999.894,0.00944799429587091,2.52210146826482E-7,1,60.005163911891,40.0298881530762,1.98234601845792,10.499999858439,0.104409871210391,0.0181974246456287,2.5,2.98097089699184E-6,0.0094476720591247,9.11157284895197E-6,300.0332947,300.0332947,999.894,999.894,61.5727866024104,21.8819871468761,38.594913,0,0,0,2402,5905,299.9308,999.894,,,,,,,,,,,,,0,,,,9.15E-6,,,,,,300.0332947,,,,
,22153114.945,361.900604248047,999.985,0.00910762916788473,3.0015951229269E-7,1,60.005163911891,40.0298881530762,1.99571718492605,10.5200000107288,0.101311898127673,0.0176728270596546,2.5,4.06943208744655E-6,0.00910865285888053,1.01233617119187E-5,295.1384888,295.1409607,999.985,999.985,62.6975500415836,21.8991283295328,38.594913,0,0,0,2402,5906,293.9612,999.985,,,,,,,,,,,,,0,,,,9.25E-6,,,,,,295.13972475,,,,
,22154195.055,451.958068847656,999.985,0.00860442047210954,2.78110647718084E-7,1,60.005163911891,40.0298881530762,1.9973557390496,10.5200000107288,0.0957924772342766,0.0166923619149256,2.5,2.25828552319307E-6,0.00860537788760829,8.02449345700296E-6,295.160614,295.1636658,999.985,999.985,61.8838747530642,21.8796953598987,38.976128,0,0,0,2402,5906,291.94805,999.985,,,,,,,,,,,,,0,,,,9.3E-6,,,,,,295.1621399,,,,
,22155275.265,542.004577636719,999.985,0.00793002686419154,3.19034426151294E-7,1,60.005163911891,40.0298881530762,1.99704831015595,10.5200000107288,0.0882744984901979,0.0153630799175891,2.5,3.44531488686901E-7,0.00793089074045567,5.7184207079663E-6,295.2145996,295.2206726,999.985,999.985,60.5902795537372,21.875986013469,39.357338,0,0,0,2402,5906,289.2166,999.985,,,,,,,,,,,,,0,,,,9.25E-6,,,,,,295.2176361,,,,
,22156355.285,632.224792480469,999.985,0.00709878537563133,3.80867574953955E-7,1,60.005163911891,40.0298881530762,1.9968216325038,10.5200000107288,0.0790144560850581,0.0137397932628978,2.5,-7.87492479788735E-7,0.00709953183948167,4.09936574580993E-6,295.3058472,295.3099976,999.985,999.985,60.4050335946795,21.8745392886444,40.500973,0,0,0,2402,5906,285.41915,999.985,,,,,,,,,,,,,0,,,,9.25E-6,,,,,,295.3079224,,,,
,22157435.36,722.531433105469,999.985,0.00646492435213781,2.81065725643123E-7,1,60.005163911891,40.0298881530762,1.9968170168819,10.5100004002452,0.0719458703272744,0.0125194148748268,2.5,8.83895811474857E-8,0.00646455895234247,4.49805053125117E-6,300.2269287,301.1057434,999.985,999.985,61.0006345263334,21.8579809911028,38.213703,0,0,0,2402,5906,287.59915,999.985,,,,,,,,,,,,,0,,,,9.2E-6,,,,,,300.66633605,,,,
,22158515.485,812.791259765625,999.985,0.00707048342398453,6.57566826593908E-7,1,60.005163911891,40.0298881530762,1.9971096752566,10.5200000107288,0.0786888184062921,0.0136763435312262,2.5,-1.42926811866688E-6,0.0070691922539971,3.48671870955228E-6,304.6317139,304.9664001,999.985,999.985,60.4253559361795,21.8715127203825,39.738548,0,0,0,2402,5906,282.99985,999.985,,,,,,,,,,,,,0,,,,9.2E-6,,,,,,304.799057,,,,
,22160075.635,808.276489257812,999.985,0.00845165349419823,2.09013631608453E-6,1,60.005163911891,40.0298881530762,1.98233684674138,10.5299996212125,0.0934025343075315,0.0162840881248393,0.25,2.72302682918317E-6,0.00844924429685153,8.59764729677784E-6,307.9961243,308.3787537,999.985,999.985,60.5480716136987,21.8799957651303,39.357338,0,0,0,2402,5906,282.99915,999.985,,,,,,,,,,,,,0,,,,9.25E-6,,,,,,308.187439,,,,
,22161155.735,718.634399414062,999.985,0.0123038661148816,8.95744987891579E-7,1,60.005163911891,40.0298881530762,1.9828722627192,10.5200000107288,0.136026197518679,0.0237692879658893,0.25,8.78244901086711E-6,0.0123026375384508,1.72633532142093E-5,301.9559937,302.1600037,999.985,999.985,61.9120133797566,21.8699727282401,48.887619,0,0,0,2402,5906,285.0442,999.985,,,,,,,,,,,,,0,,,,9.25E-6,,,,,,302.0579987,,,,
,22162295.86,624.046508789063,999.985,0.0145549362794172,6.70681261766372E-7,1,60.005163911891,40.0298881530762,1.98232426558383,10.5200000107288,0.160873312750958,0.0281780149852387,0.25,1.64316650147875E-5,0.014554767717722,2.62991041981328E-5,299.0882568,299.2527161,999.985,999.985,62.2582748137758,21.8793676383828,37.832493,0,0,0,2402,5906,289.08085,999.985,,,,,,,,,,,,,0,,,,9.25E-6,,,,,,299.17048645,,,,
,22163435.965,529.31884765625,999.985,0.0162323868230827,6.36073787727997E-7,1,60.005163911891,40.0298881530762,1.98292475563445,10.5200000107288,0.179468361131793,0.0312463512737515,2.5,1.77239059341182E-6,0.016234394069929,1.27689482514577E-5,294.7104492,294.7526855,999.985,999.985,61.6548575969296,21.9074630751555,38.213703,0,0,0,2402,5906,289.3014,999.985,,,,,,,,,,,,,0,,,,9.2E-6,,,,,,294.73156735,,,,
,22164516.125,439.684600830078,999.985,0.0178938908105389,7.24897811914521E-7,1,60.005163911891,40.0298881530762,1.98282015867427,10.5200000107288,0.197808956841152,0.0345512635784591,2.5,1.18872260425903E-5,0.0178960583417367,2.38852244204467E-5,294.8246155,294.8292847,999.985,999.985,61.3867590148334,21.9053481872721,38.594913,0,0,0,2402,5906,291.8365,999.985,,,,,,,,,,,,,0,,,,9.25E-6,,,,,,294.8269501,,,,
,22165716.25,339.892639160156,999.985,0.0198164461844206,6.71324207838532E-7,1,60.005163911891,40.0298881530762,1.98286575351093,10.5299996212125,0.219052397252117,0.0383457571261245,2.5,2.06468815146898E-5,0.0198188221155644,3.38175558095554E-5,294.8797302,294.880188,999.985,999.985,60.924816559968,21.8740996395824,37.451283,0,0,0,2402,5906,294.0195,999.985,,,,,,,,,,,,,0,,,,9.2E-6,,,,,,294.8799591,,,,
,22167156.405,337.064636230469,999.985,0.0200917026972179,5.45236576948612E-7,1,60.005163911891,40.0298881530762,1.98278773312696,10.5200000107288,0.222101392413931,0.0387839234345772,2.5,1.25724227555802E-5,0.0200939852703355,2.58971787192187E-5,295.0933838,295.1091003,999.985,999.985,60.6481200641603,21.9068220951741,38.594913,0,0,0,2402,5906,294.5332,999.985,,,,,,,,,,,,,0,,,,9.15E-6,,,,,,295.10124205,,,,
,22168236.385,427.060943603516,999.985,0.0185044253758546,7.62789410440102E-7,1,60.005163911891,40.0298881530762,1.98268018710218,10.5200000107288,0.204546682317528,0.0357023890676824,2.5,1.0070787047485E-5,0.0185064919449217,2.24389390687627E-5,295.1474609,295.1497803,999.985,999.985,60.9693693855641,21.8980116780624,38.213703,0,0,0,2402,5906,292.60415,999.985,,,,,,,,,,,,,0,,,,9.2E-6,,,,,,295.1486206,,,,
,22169736.57,522.055786132812,999.985,0.0166054825517419,6.17493918984859E-7,1,60.005163911891,40.0298881530762,1.98328421404915,10.5200000107288,0.183610278574183,0.0320407172726943,2.5,8.27266273186023E-6,0.0166072898052958,1.94911273707546E-5,295.2135925,295.223053,999.985,999.985,61.1827539713142,21.8969807795888,38.594913,0,0,0,2402,5906,289.98005,999.985,,,,,,,,,,,,,0,,,,9.15E-6,,,,,,295.21832275,,,,
,22170816.665,612.226013183594,999.985,0.0149812200123724,6.82599598053948E-7,1,60.005163911891,40.0298881530762,1.98273844272078,10.5200000107288,0.165608062532848,0.0288882298299583,2.5,6.33859108133517E-6,0.0149828041561805,1.66161471072818E-5,295.2825317,295.2876282,999.985,999.985,60.6387405219295,21.8870029911923,39.738548,0,0,0,2402,5906,286.26855,999.985,,,,,,,,,,,,,0,,,,9.25E-6,,,,,,295.28507995,,,,
,22171896.8,702.659545898438,999.985,0.0130243460253867,8.01289588982538E-7,1,60.005163911891,40.0298881530762,1.98304554815192,10.5200000107288,0.143985787536211,0.0250858436356177,2.5,2.92229346545847E-6,0.0130242026166388,1.17530033571274E-5,298.3728638,299.97052,999.985,999.985,62.3723925775835,21.8940655183091,42.025818,0,0,0,2402,5906,289.0589,999.985,,,,,,,,,,,,,0,,,,9.15E-6,,,,,,299.1716919,,,,
,22172976.92,792.935791015625,999.985,0.0099191259500025,1.40932418780373E-6,1,60.005163911891,40.0298881530762,1.98375319374174,10.5299996212125,0.109681929648442,0.0190956415712022,2.5,8.74322716919223E-7,0.00991765080079597,7.75335665527586E-6,303.5754395,303.7750854,999.985,999.985,60.8966779332757,21.9074040805822,40.119759,0,0,0,2402,5906,283.59635,999.985,,,,,,,,,,,,,0,,,,9.15E-6,,,,,,303.67526245,,,,
,22174116.985,888.249206542969,999.985,0.000215230718180906,2.00416658336033E-7,1,60.005163911891,40.0298881530762,1.98354006668097,10.5200000107288,0.00238109701651041,0.000406961796227777,0.25,-6.47436173406403E-7,0.000215145747505917,-4.9757384424962E-7,311.6164856,312.2174683,999.985,999.985,61.4281853263527,21.9223250794044,38.976128,0,0,0,2402,5906,283.00125,999.985,,,,,,,,,,,,,0,,,,9.25E-6,,,,,,311.91697695,,,,
,22175677.19,933.135192871094,999.985,0.000127202308916497,1.80240559904507E-7,1,60.005163911891,40.0298881530762,1.99809035843763,10.5200000107288,0.00141640078899217,0.000243551653016342,0.25,-2.54431305762846E-7,0.000127108111812269,-1.65854909754989E-7,323.3158875,323.6531067,999.985,999.985,61.5954538294681,21.9058465634158,40.882183,0,0,0,2402,5906,282.99935,999.985,,,,,,,,,,,,,0,,,,9.2E-6,,,,,,323.4844971,,,,
,22176757.24,843.536071777344,999.985,0.00282233527424463,4.01789160454959E-6,1,60.005163911891,40.0298881530762,1.99781328127184,10.5200000107288,0.031417685650926,0.00548831792728701,0.25,1.85616191931281E-6,0.00282110378768452,3.81707516766402E-6,312.9155579,313.5200806,999.985,999.985,61.7009736795642,21.9045592626517,40.882183,0,0,0,2402,5906,282.99965,999.985,,,,,,,,,,,,,0,,,,9.2E-6,,,,,,313.21781925,,,,
,22177503.91,756.294128417969,999.985,0.00963683046722852,2.49775984450187E-6,1,0.999253354069792,40.0298881530762,1.99685114594789,10.8099998906255,0.107233168101778,0.0188271675346439,0.25,1.45978837521072E-5,0.00963471966527324,2.12945878236772E-5,305.9674072,305.9674072,999.985,999.985,61.3281368758911,21.9584236420301,39.357338,0,0,0,40,5910,282.9944,999.985,,,,,,,,,,,,,,,,,9.2E-6,,,,,,305.9674072,,,,
,22177540.3,743.905090332031,999.985,0.0100795372559663,2.76552717774609E-6,1,0.999253354069792,40.0298881530762,1.99732357727403,10.8099998906255,0.112181485685203,0.0197281724967622,0.25,1.80767952872687E-5,0.010077518958262,2.50807851610242E-5,305.3241882,305.3507385,999.985,999.985,62.180893590372,21.9564531868219,39.738548,0,0,0,40,5910,283.0018,999.985,,,,,,,,,,,,,,,,,9.2E-6,,,,,,305.33746335,,,,
,22177568.825,734.622375488281,999.985,0.0103639361397968,2.29677499738685E-6,1,0.999253354069792,40.0298881530762,1.99656420376515,10.8099998906255,0.115307084119632,0.0202733346178114,0.25,1.81941450749769E-5,0.0103620071862065,2.53962161394447E-5,304.8702393,304.8702393,999.985,999.985,60.9779672992757,21.9557847827271,38.594913,0,0,0,40,5910,283.001,999.985,,,,,,,,,,,,,,,,,9.2E-6,,,,,,304.8702393,,,,
,22177597.78,724.830322265625,999.985,0.01065863505534,2.006683255013E-6,1,0.999253354069792,40.0298881530762,1.99663063216232,10.8099998906255,0.118592929374257,0.0208421676742091,0.25,1.79367873280835E-5,0.0106568136588269,2.53442308742033E-5,304.3521423,304.3814087,999.985,999.985,61.4070813563334,21.9489933827784,39.357338,0,0,0,40,5910,282.9993,999.985,,,,,,,,,,,,,,,,,9.15E-6,,,,,,304.3667755,,,,
,22177625.385,715.567138671875,999.985,0.0109154085211142,2.54368996876804E-6,1,0.999253354069792,40.0298881530762,1.99801324608736,10.8099998906255,0.121537105084125,0.0213308785586254,0.25,1.58686059376412E-5,0.0109137002312033,2.34538115343852E-5,303.8825073,303.9093323,999.985,999.985,61.852609612295,21.9271846022521,39.357338,0,0,0,40,5910,283.0445,999.985,,,,,,,,,,,,,,,,,9.25E-6,,,,,,303.8959198,,,,
,22177653.165,706.589538574219,999.985,0.0111472177280899,2.17854163700998E-6,1,0.999253354069792,40.0298881530762,1.99808904850561,10.8099998906255,0.124124305777223,0.0217856962878343,0.25,1.62910977869893E-5,0.0111456296498253,2.40167165112798E-5,303.4375305,303.4375305,999.985,999.985,62.4052209753912,21.932089499785,38.594913,0,0,0,40,5910,283.6889,999.985,,,,,,,,,,,,,,,,,9.1E-6,,,,,,303.4375305,,,,
,22177675.375,698.981140136719,999.985,0.0113347606346372,2.16346037451669E-6,1,0.999253354069792,40.0298881530762,1.99897581479582,10.8099998906255,0.126269418098486,0.0221512097595361,0.25,1.56242714395522E-5,0.011333261173173,2.3464411191288E-5,303.0973511,303.1176453,999.985,999.985,61.6876859947373,21.9117937249905,38.594913,0,0,0,40,5910,284.1687,999.985,,,,,,,,,,,,,,,,,9.25E-6,,,,,,303.1074982,,,,
,22177700.14,690.7080078125,999.985,0.0115263081068118,3.00029049495887E-6,1,0.999253354069792,40.0298881530762,1.99854524147918,10.8000002801418,0.128372584293181,0.0225520310066007,0.25,1.86782668334011E-5,0.0115248904077906,2.66365347043601E-5,302.7895203,302.8079834,999.985,999.985,61.0889585490065,21.94558967717,37.832493,0,0,0,40,5910,284.595,999.985,,,,,,,,,,,,,,,,,9.25E-6,,,,,,302.79875185,,,,
,22177725.865,682.378784179688,999.985,0.0117183571179517,2.89692587149877E-6,1,0.999253354069792,40.0298881530762,1.99715821309505,10.8000002801418,0.130419729429871,0.0229487009768601,0.25,2.22310452845897E-5,0.0117170307874099,3.03081161678728E-5,302.4718018,302.4718018,999.985,999.985,61.9729804042566,21.9554784877499,38.594913,0,0,0,40,5910,284.9996,999.985,,,,,,,,,,,,,,,,,9.3E-6,,,,,,302.4718018,,,,
,22177752.055,673.647888183594,999.985,0.0119041878941961,2.7362757304509E-6,1,0.999253354069792,40.0298881530762,1.99763324968663,10.8099998906255,0.13252438725623,0.0232891798735,0.25,1.99962799828269E-5,0.0119029501881558,2.81877440681987E-5,302.176178,302.176178,999.985,999.985,61.9268643216219,21.9372170913703,38.594913,0,0,0,40,5910,285.41475,999.985,,,,,,,,,,,,,,,,,9.2E-6,,,,,,302.176178,,,,
,22177778.265,664.751831054687,999.985,0.0120869051385759,2.64778216377057E-6,1,0.999253354069792,40.0298881530762,1.99449587164396,10.8099998906255,0.13434969716566,0.0236536939946361,0.25,2.41226115774892E-5,0.0120857527687827,3.24375978040728E-5,301.8768311,301.8910217,999.985,999.985,61.2288700539488,21.9315640493633,38.213703,0,0,0,40,5910,285.47525,999.985,,,,,,,,,,,,,,,,,9.2E-6,,,,,,301.8839264,,,,
,22177806.645,655.518798828125,999.985,0.012273596620485,2.00648392468793E-6,1,0.999253354069792,40.0298881530762,1.99431015982976,10.8099998906255,0.136413702423437,0.0240198191458899,0.25,2.47019541977583E-5,0.0122725624265782,3.31776509123742E-5,301.5074768,301.5074768,999.985,999.985,62.248895271545,21.9320305758323,50.412464,0,0,0,40,5910,284.5736,999.985,,,,,,,,,,,,,,,,,9.15E-6,,,,,,301.5074768,,,,
,22177833.67,646.323364257812,999.985,0.0124505972958442,2.94824629309073E-6,1,0.999253354069792,40.0298881530762,1.99593155152637,10.8099998906255,0.138488763277706,0.024397448476344,0.25,2.61376908697686E-5,0.0124497278895359,3.47248168842959E-5,301.031311,301.031311,999.985,999.985,62.1957445322374,21.926219928931,59.942749,0,0,0,40,5910,284.88505,999.985,,,,,,,,,,,,,,,,,9.2E-6,,,,,,301.031311,,,,
,22177862.875,636.837036132813,999.985,0.0126237685674328,3.13060453888048E-6,1,0.999253354069792,40.0298881530762,1.99715010734775,10.8099998906255,0.140508336320487,0.0246973025627036,0.25,2.17517048027376E-5,0.0126230480253382,3.03342553030664E-5,300.6538391,300.6538391,999.985,999.985,61.5290154053334,21.939757852302,42.025818,0,0,0,40,5910,288.3521,999.985,,,,,,,,,,,,,,,,,9.2E-6,,,,,,300.6538391,,,,
,22177887.635,628.37890625,999.985,0.0127708143316243,3.07222540798702E-6,1,0.999253354069792,40.0298881530762,1.99752321611757,10.8099998906255,0.142170767571985,0.0249877060903083,0.25,2.18327267506004E-5,0.0127700840580711,3.05304272979504E-5,300.6533508,300.6533508,999.985,999.985,61.6955022799296,21.9329589433562,42.025818,0,0,0,40,5910,287.93015,999.985,,,,,,,,,,,,,,,,,9.15E-6,,,,,,300.6533508,,,,
,22177916.775,618.893005371094,999.985,0.012934708525994,3.41792997277152E-6,1,0.999253354069792,40.0298881530762,1.9970623444111,10.8099998906255,0.143959451295779,0.0253298622176268,0.25,2.45207519490891E-5,0.0129340277333888,3.33434126096943E-5,300.4949951,300.4949951,999.985,999.985,60.6356140078526,21.9477852698962,40.119759,0,0,0,40,5910,287.5656,999.985,,,,,,,,,,,,,,,,,9.15E-6,,,,,,300.4949951,,,,
,22177945.975,609.068786621094,999.985,0.0130872961210497,2.69205125748024E-6,1,0.999253354069792,40.0298881530762,1.99745402417883,10.8099998906255,0.145687178759559,0.0256289178317662,0.25,2.43974947275684E-5,0.0130867202487044,3.3306585567629E-5,300.2088623,300.2216797,999.985,999.985,63.4275910785452,21.9368638475976,38.213703,0,0,0,40,5910,288.05165,999.985,,,,,,,,,,,,,,,,,9.25E-6,,,,,,300.215271,,,,
,22177972.32,600.059265136719,999.985,0.0132388196374883,2.98060168256392E-6,1,0.999253354069792,40.0298881530762,1.99767200304907,10.8099998906255,0.147388166193761,0.0259416334149142,0.25,2.58668513221141E-5,0.0132383345915299,3.48670579843729E-5,299.973114,299.973114,999.985,999.985,61.598580343545,21.9476986942268,38.213703,0,0,0,40,5910,288.38025,999.985,,,,,,,,,,,,,,,,,9.25E-6,,,,,,299.973114,,,,
,22178000.17,591.019287109375,999.985,0.0133687819943046,2.23462372869656E-6,1,0.999253354069792,40.0298881530762,1.99814216744297,10.8000002801418,0.148870360854229,0.0261982876375825,0.25,2.57278982224713E-5,0.0133683848909628,3.48415559122775E-5,299.7378845,299.7378845,999.985,999.985,61.1436725453526,21.9416451722104,38.594913,0,0,0,40,5910,287.7207,999.985,,,,,,,,,,,,,,,,,9.2E-6,,,,,,299.7378845,,,,
,22178031.37,580.645141601562,999.985,0.0135125046906792,3.19190765739829E-6,1,0.999253354069792,40.0298881530762,1.99749833056754,10.8099998906255,0.150393915514411,0.0263907044516873,2.5,1.93580258173951E-5,0.0135122706200253,2.86190021731583E-5,299.3134155,299.34021,999.985,999.985,60.6582812349103,21.9453264907932,55.368217,0,0,0,40,5910,286.44845,999.985,,,,,,,,,,,,,,,,,9.2E-6,,,,,,299.32681275,,,,
,22178059.845,571.049499511719,999.985,0.0136509931888149,2.94245200475999E-6,1,0.999253354069792,40.0298881530762,1.99738329006445,10.8000002801418,0.151928967809025,0.0266618028418996,2.5,1.96540354116376E-5,0.0136509685117886,2.90637116942644E-5,298.7999268,298.7999268,999.985,999.985,60.4613108480641,21.9443556098959,90.058441,0,0,0,40,5910,285.0865,999.985,,,,,,,,,,,,,,,,,9.15E-6,,,,,,298.7999268,,,,
,22178116.495,552.30615234375,999.985,0.0139167448172131,2.82505602251438E-6,1,0.999253354069792,40.0298881530762,1.98304622902233,10.7100000604987,0.153830898444384,0.0269675607969723,2.5,1.75467922409675E-5,0.0139172681817468,2.7172273400634E-5,297.4732666,297.5149231,999.985,999.985,61.2101109694872,21.9364719119471,62.611229,0,0,0,40,5910,284.30285,999.985,,,,,,,,,,,,,,,,,9.2E-6,,,,,,297.49409485,,,,
,22178145.33,542.591735839844,999.985,0.0140549685247822,2.59318702604408E-6,1,0.999253354069792,40.0298881530762,1.98314731772014,10.7100000604987,0.155371821579886,0.0272220438098799,2.5,1.63503511504874E-5,0.014055751559218,2.60689769824404E-5,296.8993835,296.8993835,999.985,999.985,62.7436661242182,21.9347164756611,53.080944,0,0,0,40,5910,284.37335,999.985,,,,,,,,,,,,,,,,,9.2E-6,,,,,,296.8993835,,,,
,22178176.195,532.471008300781,999.985,0.0141895364885058,2.33131404532535E-6,1,0.999253354069792,40.0298881530762,1.98372225716257,10.7100000604987,0.156908521674698,0.0274744907614747,2.5,1.50274911296391E-5,0.0141905657641439,2.48455863163206E-5,296.3449402,296.3449402,999.985,999.985,60.6692240341795,21.9320138934896,45.837933,0,0,0,40,5910,284.22555,999.985,,,,,,,,,,,,,,,,,9.15E-6,,,,,,296.3449402,,,,
,22178204.295,523.083618164063,999.985,0.0143172888739643,2.93114745300784E-6,1,0.999253354069792,40.0298881530762,1.98372084445257,10.7100000604987,0.158320936552347,0.0277362499537571,2.5,1.64371953120392E-5,0.0143185319366236,2.63373445109971E-5,295.8640137,295.8825989,999.985,999.985,61.4946237504873,21.9312211639702,40.500973,0,0,0,40,5910,284.3895,999.985,,,,,,,,,,,,,,,,,9.15E-6,,,,,,295.8733063,,,,
,22178230.315,514.307556152344,999.985,0.0144262155400061,2.24473028571123E-6,1,0.999253354069792,40.0298881530762,1.98420282244238,10.7100000604987,0.15956844384813,0.0279315398617292,2.5,1.45316445379672E-5,0.0144276385101291,2.44974295076408E-5,295.4891968,295.4891968,999.985,999.985,61.8361954133912,21.9320186970258,38.594913,0,0,0,40,5910,284.6238,999.985,,,,,,,,,,,,,,,,,9.3E-6,,,,,,295.4891968,,,,
,22178257.215,505.365783691406,999.985,0.0145470426696918,2.74305102608962E-6,1,0.999253354069792,40.0298881530762,1.98395868771944,10.7100000604987,0.160876920025393,0.028224896011416,2.5,2.03092331010982E-5,0.0145486424153925,3.03458256268957E-5,295.1004944,295.1193542,999.985,999.985,61.7806997885258,21.9387119009046,38.976128,0,0,0,40,5910,284.94655,999.985,,,,,,,,,,,,,,,,,9.2E-6,,,,,,295.1099243,,,,
,22178283.435,496.618804931641,999.985,0.0146598787861027,3.50015200071074E-6,1,0.999253354069792,40.0298881530762,1.9834226675795,10.7100000604987,0.162087754896463,0.0284171348249656,2.5,1.87116830281676E-5,0.0146616367500492,2.88092832151308E-5,294.7811584,294.7964478,999.985,999.985,61.4250588122757,21.9298539904338,38.976128,0,0,0,40,5910,285.34715,999.985,,,,,,,,,,,,,,,,,9.3E-6,,,,,,294.7888031,,,,
,22178309.86,487.901611328125,999.985,0.0147789005151263,2.83844569477934E-6,1,0.999253354069792,40.0298881530762,1.98391912071714,10.7100000604987,0.163441063429557,0.0286738322053486,2.5,2.05883946241074E-5,0.0147807953381137,3.07486827740155E-5,294.5128479,294.5220642,999.985,999.985,61.4789911801027,21.8865444934447,38.594913,0,0,0,40,5910,285.81245,999.985,,,,,,,,,,,,,,,,,9.25E-6,,,,,,294.51745605,,,,
,22178333.345,480.222625732422,999.985,0.0148788877319078,3.78827857788213E-6,1,0.999253354069792,40.0298881530762,1.98307919430588,10.7100000604987,0.164477111393505,0.0288790937052617,2.5,2.2809157002457E-5,0.0148808940702552,3.30194383929294E-5,294.2948914,294.3055725,999.985,999.985,61.2015130557757,21.9502004942236,38.594913,0,0,0,40,5910,286.26405,999.985,,,,,,,,,,,,,,,,,9.2E-6,,,,,,294.30023195,,,,
,22178356.565,472.235809326172,999.985,0.0149765002994618,3.12749800086531E-6,1,0.999253354069792,40.0298881530762,1.98403843435721,10.7100000604987,0.165646350850722,0.0290109253425357,2.5,1.65353985621238E-5,0.0149786086365125,2.6791342223425E-5,294.1138611,294.1247253,999.985,999.985,61.4805544371411,21.9388364737647,38.594913,0,0,0,40,5910,286.74625,999.985,,,,,,,,,,,,,,,,,9.2E-6,,,,,,294.1192932,,,,
,22178384.54,463.331726074219,999.985,0.0151076223049698,2.55686638384044E-6,1,0.999253354069792,40.0298881530762,1.98364476204472,10.7100000604987,0.167059645332903,0.0292945563513656,2.5,1.98733647393078E-5,0.0151098325175133,3.01947324608162E-5,293.9384155,293.9384155,999.985,999.985,62.3059541534489,21.9295336577054,38.594913,0,0,0,40,5910,287.3286,999.985,,,,,,,,,,,,,,,,,9.3E-6,,,,,,293.9384155,,,,
,22178410.075,454.725830078125,999.985,0.0152192021928601,2.82416714481683E-6,1,0.999253354069792,40.0298881530762,1.98387666657725,10.7000004500151,0.168312017029491,0.0295205206527695,2.5,2.06016531112607E-5,0.0152214931000815,3.09755388448811E-5,293.8037415,293.8037415,999.985,999.985,61.1780642001988,21.9362309309513,38.594913,0,0,0,40,5910,287.8846,999.985,,,,,,,,,,,,,,,,,9.3E-6,,,,,,293.8037415,,,,
,22178437.365,445.542266845703,999.985,0.0153581188256325,3.22821207396438E-6,1,0.999253354069792,40.0298881530762,1.98413000058324,10.7100000604987,0.169872759858143,0.0297763899458297,2.5,1.92477994042949E-5,0.01536048649505,2.96905397829085E-5,293.6920776,293.6920776,999.985,999.985,60.8998044473526,21.9257998393998,38.213703,0,0,0,40,5910,288.4792,999.985,,,,,,,,,,,,,,,,,9.3E-6,,,,,,293.6920776,,,,
,22178462.5,437.138366699219,999.985,0.0154739680287414,2.86919661525476E-6,1,0.999253354069792,40.0298881530762,1.98385156649182,10.7100000604987,0.171132599365737,0.0299907709597176,2.5,1.88503526104068E-5,0.0154763916836017,2.9348496599717E-5,293.6170044,293.6170044,999.985,999.985,61.7752283888911,21.9368086739771,37.832493,0,0,0,40,5910,289.01775,999.985,,,,,,,,,,,,,,,,,9.2E-6,,,,,,293.6170044,,,,
,22178490.195,428.043212890625,999.985,0.0156178537189239,2.83842761551388E-6,1,0.999253354069792,40.0298881530762,1.98383989731817,10.7100000604987,0.172718741915975,0.0302953235850993,2.5,2.13841964894108E-5,0.0156203271304199,3.19538852121909E-5,293.5621948,293.5621948,999.985,999.985,60.8896432766026,21.9272331963697,38.213703,0,0,0,40,5910,289.626,999.985,,,,,,,,,,,,,,,,,9.15E-6,,,,,,293.5621948,,,,
,22178515.79,419.460327148438,999.985,0.0157489320342385,2.72210370722353E-6,1,0.999253354069792,40.0298881530762,1.9836505397194,10.7100000604987,0.174151538491959,0.0305526184602792,2.5,2.21109501261498E-5,0.0157514401101644,3.27466993403606E-5,293.536438,293.5384216,999.985,999.985,60.5128983303333,21.9292474746854,38.976128,0,0,0,40,5910,290.14645,999.985,,,,,,,,,,,,,,,,,9.25E-6,,,,,,293.5374298,,,,
,22178542.01,410.769073486328,999.985,0.0158895686146474,3.27197434918382E-6,1,0.999253354069792,40.0298881530762,1.98346199227674,10.7100000604987,0.175688375635166,0.0308362040173343,2.5,2.35569209525436E-5,0.0158921041896262,3.42648459525163E-5,293.5302124,293.5302124,999.985,999.985,62.6021913622374,21.8981046895416,38.213703,0,0,0,40,5910,290.67005,999.985,,,,,,,,,,,,,,,,,9.3E-6,,,,,,293.5302124,,,,
,22178567.22,402.265899658203,999.985,0.0160322565314291,3.84505792796543E-6,1,0.999253354069792,40.0298881530762,1.98399558859522,10.7100000604987,0.177322008449648,0.0310624223690903,2.5,1.84819390431817E-5,0.0160348160391091,2.92638663674104E-5,293.5393066,293.5403137,999.985,999.985,61.0850504064103,21.9436791465819,38.594913,0,0,0,40,5910,291.1523,999.985,,,,,,,,,,,,,,,,,9.2E-6,,,,,,293.53981015,,,,
,22178594.42,393.359039306641,999.985,0.0161808872905266,2.83515856395038E-6,1,0.999253354069792,40.0298881530762,1.98394749650262,10.7100000604987,0.178962621253199,0.0313439725445377,2.5,1.81625856462164E-5,0.016183460410687,2.90223588985374E-5,293.5658569,293.5658569,999.985,999.985,62.228572930045,21.9311539112774,38.594913,0,0,0,40,5910,291.648,999.985,,,,,,,,,,,,,,,,,9.2E-6,,,,,,293.5658569,,,,
,22178619.9,385.091735839844,999.985,0.0163267144236928,4.44709054117828E-6,1,0.999253354069792,40.0298881530762,1.98303247866429,10.7000004500151,0.180493334998062,0.0316242422283122,2.5,1.94147855309412E-5,0.0163292948348043,3.03527107325032E-5,293.6000977,293.6013794,999.985,999.985,60.7669275990834,21.9525641067658,37.451283,0,0,0,40,5910,292.093,999.985,,,,,,,,,,,,,,,,,9.3E-6,,,,,,293.60073855,,,,
,22178645.195,376.958099365234,999.985,0.0164606670335634,2.97954779891952E-6,1,0.999253354069792,40.0298881530762,1.98393830656708,10.7100000604987,0.182051258546357,0.0319118610743155,2.5,2.08776172843808E-5,0.0164632465203248,3.18874947265813E-5,293.6452026,293.6488953,999.985,999.985,61.6767431954681,21.9273880594389,38.213703,0,0,0,40,5910,292.49325,999.985,,,,,,,,,,,,,,,,,9.2E-6,,,,,,293.64704895,,,,
,22178672.015,369.720581054687,999.985,0.0165909736784975,3.58509205128831E-6,1,0.999253354069792,40.0298881530762,1.98365314515796,10.7100000604987,0.183464530334933,0.0321730411885876,2.5,2.22412708713368E-5,0.0165935448654423,3.33198188311149E-5,293.7043152,293.7085571,999.985,999.985,61.9612559764681,21.9158497518538,37.451283,0,0,0,40,5910,292.9064,999.985,,,,,,,,,,,,,,,,,9.3E-6,,,,,,293.70643615,,,,
,22178697.75,363.322723388672,999.985,0.0167097233380717,3.85893148823786E-6,1,0.999253354069792,40.0298881530762,1.98258551494935,10.7100000604987,0.184678468212652,0.0324060406175279,2.5,2.41821960619474E-5,0.0167122788997499,3.53245083459015E-5,293.7745056,293.7745056,999.985,999.985,62.1527549636797,21.9380217190785,38.213703,0,0,0,40,5910,293.2542,999.985,,,,,,,,,,,,,,,,,9.25E-6,,,,,,293.7745056,,,,
,22178751.19,351.986297607422,999.985,0.0169135588365719,3.93919709500906E-6,1,0.999253354069792,40.0298881530762,1.99650183332542,10.5799995362759,0.188193955966599,0.0329929565292019,2.5,2.18937681045642E-5,0.016916072311114,3.31429399622172E-5,293.9265137,293.9265137,999.985,999.985,62.6819174711989,21.9400025703968,38.213703,0,0,0,40,5910,293.8792,999.985,,,,,,,,,,,,,,,,,9.3E-6,,,,,,293.9265137,,,,
,22178777.25,347.291564941406,999.985,0.0170017398294314,3.48077719468671E-6,1,0.999253354069792,40.0298881530762,1.9977107735495,10.5699999257922,0.189297935417787,0.0331069375247969,2.5,1.50871431957679E-5,0.0170042319467144,2.63814087078216E-5,294.0018005,294.007782,999.985,999.985,60.322180971641,21.9254745083237,38.213703,0,0,0,40,5910,294.15185,999.985,,,,,,,,,,,,,,,,,9.2E-6,,,,,,294.00479125,,,,
,22178803.39,342.890045166016,999.985,0.0170706659961934,2.92210342222179E-6,1,0.999253354069792,40.0298881530762,1.99746211897126,10.5699999257922,0.19003885114987,0.0332562793551077,2.5,1.68810130823607E-5,0.0170731224537846,2.82108727827129E-5,294.0930481,294.0930481,999.985,999.985,62.1840201044489,21.9231942028573,38.594913,0,0,0,40,5910,294.3784,999.985,,,,,,,,,,,,,,,,,9.3E-6,,,,,,294.0930481,,,,
,22178828.25,339.024749755859,999.985,0.0171387248534902,3.76228938479139E-6,1,0.999253354069792,40.0298881530762,1.99771621422853,10.5799995362759,0.190814686182371,0.0334195135254423,2.5,1.93503088854876E-5,0.0171411484447894,3.07171465083558E-5,294.1717224,294.1757813,999.985,999.985,60.1783613241025,21.9474973697267,38.594913,0,0,0,40,5910,294.56285,999.985,,,,,,,,,,,,,,,,,9.25E-6,,,,,,294.17375185,,,,
,22178853.15,335.656219482422,999.985,0.0171907694100747,3.52534910369124E-6,1,0.999253354069792,40.0298881530762,1.99772000720117,10.5799995362759,0.191401130807547,0.0334800755644448,2.5,1.57431686304611E-5,0.017193161477093,2.71367690985281E-5,294.2533264,294.2555237,999.985,999.985,60.7442603720257,21.9292636079258,37.451283,0,0,0,40,5910,294.71875,999.985,,,,,,,,,,,,,,,,,9.2E-6,,,,,,294.25442505,,,,
,22178878.655,332.434173583984,999.985,0.0172453332405348,3.39538047499994E-6,1,0.999253354069792,40.0298881530762,1.9980268252112,10.5799995362759,0.192033001804049,0.033610919048624,2.5,1.75701255373626E-5,0.0172476889049955,2.89933375031067E-5,294.3358154,294.339447,999.985,999.985,61.8705870682373,21.925561211601,37.832493,0,0,0,40,5910,294.8648,999.985,,,,,,,,,,,,,,,,,9.2E-6,,,,,,294.3376312,,,,
,22178904.18,329.333374023438,999.985,0.0172967648701893,2.74455360481355E-6,1,0.999253354069792,40.0298881530762,1.99808445721948,10.5699999257922,0.192602453737865,0.0337587464848907,2.5,2.18237276693266E-5,0.0172990841639225,3.32764425823099E-5,294.4150085,294.4171143,999.985,999.985,62.1003858528912,21.909750110766,38.213703,0,0,0,40,5910,294.9745,999.985,,,,,,,,,,,,,,,,,9.25E-6,,,,,,294.4160614,,,,
,22178929.265,326.542236328125,999.985,0.0173318854647961,4.61753155385105E-6,1,0.999253354069792,40.0298881530762,1.99784317446833,10.5799995362759,0.192981989277222,0.033758753673146,2.5,1.60759004234769E-5,0.017334174769096,2.75469646139048E-5,294.4901733,294.4901733,999.985,999.985,60.789594826141,21.9475690298832,38.213703,0,0,0,40,5910,295.0624,999.985,,,,,,,,,,,,,,,,,9.3E-6,,,,,,294.4901733,,,,
,22178954.295,324.239776611328,999.985,0.0173733856782497,3.10419143611692E-6,1,0.999253354069792,40.0298881530762,1.99788766297246,10.5799995362759,0.193446357819278,0.0338484444347701,2.5,1.68546475145171E-5,0.0173756425237143,2.83499933255516E-5,294.5618896,294.5618896,999.985,999.985,61.6908125088142,21.9230438345857,38.213703,0,0,0,40,5910,295.132,999.985,,,,,,,,,,,,,,,,,9.2E-6,,,,,,294.5618896,,,,
,22178977.305,322.138549804687,999.985,0.0174036277431679,2.89456837218959E-6,1,0.999253354069792,40.0298881530762,1.99812702452648,10.5799995362759,0.193803892424293,0.0339175332074758,2.5,1.74552454761923E-5,0.0174058565687213,2.89682360886334E-5,294.6201172,294.6242371,999.985,999.985,61.3320450184873,21.9285704279885,38.213703,0,0,0,40,5910,295.1835,999.985,,,,,,,,,,,,,,,,,9.25E-6,,,,,,294.62217715,,,,
,22179001.685,319.921020507812,999.985,0.0174356307239456,3.39770191622431E-6,1,0.999253354069792,40.0298881530762,1.99795764859036,10.5699999257922,0.194140049585556,0.034000602051753,2.5,1.96005907156027E-5,0.0174378304217879,3.11338021038442E-5,294.6811523,294.6840515,999.985,999.985,61.5673152027757,21.9420501232141,38.213703,0,0,0,40,5910,295.2086,999.985,,,,,,,,,,,,,,,,,9.25E-6,,,,,,294.6826019,,,,
,22179026.82,317.831787109375,999.985,0.0174647633269237,2.69303810783863E-6,1,0.999253354069792,40.0298881530762,1.99833665166247,10.5799995362759,0.1945066010891,0.0340225365124669,2.5,1.5953539034446E-5,0.0174669399883727,2.75034484353015E-5,294.7363892,294.7396851,999.985,999.985,60.6606261204679,21.9220187628184,38.976128,0,0,0,40,5910,295.2529,999.985,,,,,,,,,,,,,,,,,9.2E-6,,,,,,294.73803715,,,,
,22179052.305,316.154144287109,999.985,0.0174897115156727,2.79397570468254E-6,1,0.999253354069792,40.0298881530762,1.99790205295112,10.5799995362759,0.194737929487586,0.034096169951015,2.5,1.88671884266478E-5,0.0174918609779611,3.04335881734632E-5,294.7897949,294.7934875,999.985,999.985,60.5168064729295,21.9245452943878,38.594913,0,0,0,40,5910,295.2598,999.985,,,,,,,,,,,,,,,,,9.2E-6,,,,,,294.7916412,,,,
,22179077.86,314.420745849609,999.985,0.0175206352401399,2.81479646546903E-6,1,0.999253354069792,40.0298881530762,1.9980556006078,10.5799995362759,0.195090671624399,0.0341914581838783,2.5,2.1821742480118E-5,0.017522760827442,3.3409096080788E-5,294.8400574,294.8400574,999.985,999.985,62.2356075867181,21.8866105813343,38.594913,0,0,0,40,5910,295.2557,999.985,,,,,,,,,,,,,,,,,9.2E-6,,,,,,294.8400574,,,,
,22179104.165,312.677856445313,999.985,0.0175381196443779,3.14774059903962E-6,1,0.999253354069792,40.0298881530762,1.99848567787269,10.5799995362759,0.195332759682902,0.0341903539794558,2.5,1.80513182289111E-5,0.0175402283457,2.96496726508969E-5,294.8805237,294.8805237,999.985,999.985,60.894333047718,21.9428602210284,38.594913,0,0,0,40,5910,295.25705,999.985,,,,,,,,,,,,,,,,,9.1E-6,,,,,,294.8805237,,,,
,22179128,311.417144775391,999.985,0.017557567901439,3.69547647313234E-6,1,0.999253354069792,40.0298881530762,1.99801806352761,10.5799995362759,0.195509892747764,0.0341942559087957,2.5,1.57093846913893E-5,0.0175596632399581,2.73205943063247E-5,294.9117432,294.914032,999.985,999.985,61.6204659420834,21.9288001766819,39.357338,0,0,0,40,5910,295.2505,999.985,,,,,,,,,,,,,,,,,9.2E-6,,,,,,294.9128876,,,,
,22179154.125,310.009124755859,999.985,0.0175794844686232,3.81640284889236E-6,1,0.999253354069792,40.0298881530762,1.99790106619655,10.5799995362759,0.195743039896713,0.0342334109749306,2.5,1.55869457676692E-5,0.0175815656209932,2.72133196820829E-5,294.9437256,294.9451599,999.985,999.985,61.229651682468,21.93322640576,38.976128,0,0,0,40,5910,295.23525,999.985,,,,,,,,,,,,,,,,,9.2E-6,,,,,,294.94444275,,,,
,22179177.705,308.744354248047,999.985,0.0175962322992868,3.60061967477396E-6,1,0.999253354069792,40.0298881530762,1.99797013785041,10.5699999257922,0.19593698067303,0.0342607102381866,2.5,1.5024176068814E-5,0.0175983021240432,2.66623753505186E-5,294.9689026,294.9709778,999.985,999.985,61.811964929295,21.9285169317681,38.594913,0,0,0,40,5910,295.21735,999.985,,,,,,,,,,,,,,,,,9.15E-6,,,,,,294.9699402,,,,
,22179203.96,307.583221435547,999.985,0.0176175308013491,3.22661917416316E-6,1,0.999253354069792,40.0298881530762,1.99778603969182,10.5799995362759,0.196149875772839,0.0343382075364123,2.5,1.85508272539046E-5,0.0176195881380898,3.02046532590936E-5,294.9934387,294.9934387,999.985,999.985,61.8275974996796,21.918557989925,38.976128,0,0,0,40,5910,295.1929,999.985,,,,,,,,,,,,,,,,,9.1E-6,,,,,,294.9934387,,,,
,22179229.965,306.615234375,999.985,0.0176300845883854,3.07206729766029E-6,1,0.999253354069792,40.0298881530762,1.99759879781495,10.5799995362759,0.196268032267307,0.0343818360576428,2.5,2.05625912550476E-5,0.0176321325398851,3.22260468389602E-5,295.0110474,295.0110474,999.985,999.985,61.3679999303719,21.937664837858,38.594913,0,0,0,40,5910,295.1693,999.985,,,,,,,,,,,,,,,,,9.2E-6,,,,,,295.0110474,,,,
,22179238.275,306.175689697266,999.985,0.0176342984224077,2.88695335619021E-6,1,0.999253354069792,40.0298881530762,1.99806830858607,10.5699999257922,0.196363453551963,0.0343729784671682,2.5,1.83388785358444E-5,0.0176363451178542,3.00052150619921E-5,295.0163574,295.0176392,999.985,999.985,61.0076691830065,21.9228862030258,38.594913,0,0,0,40,5910,295.16165,999.985,,,,,,,,,,,,,,,,,9.25E-6,,,,,,295.0169983,,,,