File: DataFailid_Testimiseks/BaCu2PO4H2O__dc_zfcfc_AllCrystalsRandomlyOriented_2-100K_09052022.dat
[Header]
; ACMS II Data File (default extension .dat)
; Copyright (c) 2014, Quantum Design, Inc. All rights reserved.
TITLE,BaCu2PO4H2O__ACMSII_AllCrystalsRandomlyOriented_2-100K_04052022
FILEOPENTIME,3861252742.625,05/09/2022,11:11 am
BYAPP,ACMS II,1.0,1.2
INFO,PPMS ACMS II Option Release 1.0.8 Build 33,APPNAME
INFO,Quantum Design Linear Motor Servo Controller,MOTOR_MODULE_NAME
INFO,3101-100 C1,MOTOR_HW_VERSION
INFO,074,MOTOR_SERIAL_NUMBER
INFO,SRV No X-over 01.01.11,MOTOR_SOFTWARE_VERSION
INFO,ACMS,ACMS_MODULE_NAME
INFO,3101-430 D0,ACMS_HW_VERSION
INFO,ACMSII183,ACMS_SERIAL_NUMBER
INFO,00.14.14,ACMS_SOFTWARE_VERSION
INFO,WF181,COIL_SERIAL_NUMBER
INFO,0,MOMENT_UNITS
INFO,BaCu2PO4H2O__ACMSII_AllCrystalsRandomlyOriented_2-100K_04052022,SAMPLE_MATERIAL
INFO,all crystals randomly in powder capsule,SAMPLE_COMMENT
INFO,12.6,SAMPLE_MASS
INFO,,SAMPLE_VOLUME
INFO,,SAMPLE_MOLECULAR_WEIGHT
INFO,,SAMPLE_SIZE
INFO,,SAMPLE_SHAPE
DATATYPE,COMMENT,1
DATATYPE,TIME,2
STARTUPAXIS,X,2
STARTUPAXIS,Y1,5
STARTUPGROUP, AC
FIELDGROUP, AC, 2,3,4,5,6,7,8,9,10,11,12,13,14,15,16,20,21,22,23,24,25,35,43,44,45,46,47,48,49
FIELDGROUP, DC, 2,3,4,17,18,19,20,21,23,24,25,35,36,37,43,44,45,46,47,48,49,50,51
FIELDGROUP, Diagnostic, 26,27,28,29,30,31,32,33,34,38,39,40,41,42,52,53,54,55,56,57,58,59,60,61,62,63,64,65,66,67,68,69
[Data]
Comment,Time Stamp (sec),Temperature (K),Magnetic Field (Oe),AC Moment (emu),AC Std. Dev. (emu),AC Phase (deg),AC Phase Std. Dev. (deg),AC Suscept. (emu/Oe),AC Suscept. Std. Dev. (emu/Oe),AC X'  (emu/Oe),AC X" (emu/Oe),AC X' Std. Dev. (emu/Oe),AC X" Std. Dev. (emu/Oe),AC Drive (Oe),AC Frequency (Hz),DC Moment (emu),DC Std. Err. (emu),DC Quad. Moment (emu),Range (mV),"AC=1 DC=2 Locate=3",Measure Type,Measure Count,Measure Time (sec),Measure Number,AC X' Raw (emu/Oe),AC X" Raw (emu/Oe),DC M. Raw' (emu),DC M. Raw" (emu),Coil InPhase (V),Coil Quadrature (V),Null Status,Trim Ratio,Trim Phase (deg.),Max. Signal (mV),Motor Frequency (Hz),Motor Ampl. (mm),System Temp. (K),Min. Temperature (K),Max. Temperature (K),Min. Field (Oe),Max. Field (Oe),Pressure (Torr),Temp. Status (code),Field Status (code),Chamber Status (code),Measure Status (code),Center Position (mm),Transport Action,Motor Lag (deg),Motor Current (amps),Motor Heatsink Temp. (C),Motor Board Temp. (C),QMap 01,QMap 02,QMap 03,QMap 04,QMap 05,QMap 06,QMap 07,QMap 08,QMap 09,QMap 10,QMap 11,QMap 12,QMap 13,QMap 14,QMap 15,QMap 16
sample offset = 25.17 mm touchdown = 5.04000019282103 mm,3861266679.83009,2.00468342442758,10000.08,,,,,,,,,,,,,0.00169578566619434,4.2738698760519E-7,3.196407954779E-6,1,2,,800,20,1,,,0.00164843840793278,1.44528213732451E-5,1.0748455679277E-5,-3.41289910466003E-6,,,,0.00044073310948332,39.995735168457,2.00648636030236,1.9892,2.00216436386108,2.00941205024719,10000.08,10000.08,0.19364,1,1,3,0,19.993000192821,1,18.5790052394532,1.0284423828125,37.6344108581543,37.1456527709961,,,,,,,,,,,,,,,,
,3861274828.32725,40.7855457505279,9999.967,,,,,,,,,,,,,0.0020241056837099,9.19305049132928E-7,1.3653694033019E-5,1,2,,800,20,34,,,0.00197663520725033,4.12475852744258E-5,1.2758244338329E-5,-4.22599487137631E-6,,,,0.00052626816272163,39.995735168457,1.99377717447167,46.5641,40.3017044067383,41.2540168762207,9999.967,9999.967,0.439294,6,1,3,0,20.173000166446,1,18.596713388585,1.03195190429688,48.3870964050293,46.9208221435547,,,,,,,,,,,,,,,,
,3861275703.86189,83.1097414103054,9999.967,,,,,,,,,,,,,0.0015344468059078,2.23407651660462E-6,0.000101548257137994,1,2,,800,20,66,,,0.00153656660780004,0.000122373742860033,9.68353651842335E-6,-3.85132898372831E-6,,,,0.000408313110669674,39.995735168457,1.9828094326603,95.7021,82.5862884521484,83.5782775878906,9999.967,9999.967,0.547271,6,1,3,0,20.0829999468029,1,18.6005988926322,1.02455139160156,49.364616394043,49.364616394043,,,,,,,,,,,,,,,,
,3861276556.25957,125.215431,9999.967,,,,,,,,,,,,,,,,,3,,,,,,,,,,,,,,,,,,,,,,0.563921,6,1,3,,19.8730002104044,2,,,47.4095802307129,50.3421325683594,,,,,,,,,,,,,,,,
,3861277430.77951,168.885574,9999.967,,,,,,,,,,,,,,,,,3,,,,,,,,,,,,,,,,,,,,,,0.629423,6,1,3,,19.6730000844896,2,,,47.8983383178711,50.3421325683594,,,,,,,,,,,,,,,,
,3861278297.39563,211.50754237434,9999.967,,,,,,,,,,,,,0.00678827032894318,4.25777115994422E-5,0.000543637356572027,10,2,,800,20,163,,,0.00680972986052481,0.0005681898514692,4.28641869802959E-5,-1.72327618201962E-5,,,,0.00180976036800672,39.995735168457,1.98278277604789,230.3561,210.994171142578,211.991546630859,9999.967,9999.967,0.745929,6,1,3,0,19.4430001958013,1,18.5975106910626,1.01905822753906,50.3421325683594,50.3421325683594,,,,,,,,,,,,,,,,
,3861279173.7021,254.135157828996,9999.967,,,,,,,,,,,,,0.00254600262095855,8.69666739468233E-5,0.000175889337037958,1,2,,800,20,195,,,0.00255003380565087,0.000183018139634858,1.63083295774413E-5,-6.33844001640682E-6,,,,0.000683800324185835,39.995735168457,2.00733115496421,274.2059,253.600799560547,254.611694335938,9999.967,9999.967,0.688635,6,1,3,0,19.1930001548231,1,18.5995345533418,1.03752136230469,49.364616394043,49.8533744812012,,,,,,,,,,,,,,,,
,3861280018.63364,294.083178544922,9999.967,,,,,,,,,,,,,0.00417951103897639,3.73839267513272E-5,0.000331234659966795,10,2,,800,20,228,,,0.00417926670175659,0.000340666621343513,2.64626378339017E-5,-1.05765921034617E-5,,,,0.00111374387920955,39.995735168457,1.99331490018883,313.2296,293.644165039063,294.511047363281,9999.967,9999.967,0.675013,6,1,3,0,18.9330000376999,1,18.5909494498383,1.02508544921875,50.3421325683594,50.3421325683594,,,,,,,,,,,,,,,,
,3861341750.45556,24.8715773451687,9999.72,,,,,,,,,,,,,0.00209344157997162,3.81747352719444E-7,9.63991826407331E-7,1,2,,800,20,18,,,0.0020355850204696,1.66849155735318E-5,1.31163660626044E-5,-4.16200418840162E-6,,,,0.000538528802279139,39.995735168457,1.98255203029522,28.1124,24.3827648162842,25.3497905731201,9999.72,9999.72,0.393578,6,1,3,4,20.0829999468029,1,18.6007451424653,1.01287841796875,46.4320640563965,43.9882698059082,,,,,,,,,,,,,,,,
,3861342624.32391,66.7496425164342,9999.72,,,,,,,,,,,,,0.00171522921267661,2.10528343902439E-6,6.66151052512842E-5,1,2,,800,20,50,,,0.00170712531623017,9.66889618890462E-5,1.08941767393844E-5,-4.04782804253045E-6,,,,0.000454996349281003,39.995735168457,1.9934963626378,77.1742,66.2759857177734,67.2073593139648,9999.72,9999.72,0.541832,6,1,3,4,20.0129998794496,1,18.6067279871923,1.02455139160156,49.364616394043,48.8758583068848,,,,,,,,,,,,,,,,
touchdown = 4.91000013425946 mm,3861343499.26994,109.791065987195,9999.72,,,,,,,,,,,,,0.00125893111989909,2.62360394277408E-6,0.000103555130544429,1,2,,800,20,82,,,0.00126456878345429,0.000114842036526817,7.98373366706073E-6,-3.2782145353849E-6,,,,0.0003372954101712,39.995735168457,1.99348703677955,124.2075,109.225776672363,110.313491821289,9999.72,9999.72,0.68179,6,1,3,4,19.8630001342595,1,18.5999494518712,1.03080749511719,48.8758583068848,49.8533744812012,,,,,,,,,,,,,,,,
,3861344352.56357,152.259186,9999.72,,,,,,,,,,,,,,,,,3,,,,,,,,,,,,,,,,,,,,,,0.623166,6,1,3,,19.6830001606345,2,,,47.8983383178711,49.8533744812012,,,,,,,,,,,,,,,,
,3861345217.5307,195.193631071479,9999.72,,,,,,,,,,,,,0.000746401777624508,2.77920845947814E-6,6.66543331300153E-5,1,2,,800,20,147,,,0.000749146445562611,6.96782044444507E-5,4.72504689241759E-6,-1.95332086150302E-6,,,,0.000199922673201785,39.995735168457,1.99309406989393,213.6455,194.698455810547,195.672622680664,9999.72,9999.72,0.655083,6,1,3,4,19.5030001870096,1,18.6116755896384,1.02996826171875,49.8533744812012,50.3421325683594,,,,,,,,,,,,,,,,
,3861346093.75505,237.842328524568,9999.72,,,,,,,,,,,,,0.000581780729691957,2.54251270615337E-6,3.63699524900622E-5,1,2,,800,20,179,,,0.00058308450985004,3.81448991769783E-5,3.7099453038536E-6,-1.41557325150643E-6,,,,0.000155574457535804,39.995735168457,1.99307007959443,257.4777,237.317626953125,238.327713012695,9999.72,9999.72,0.675013,6,1,3,4,19.2229999175966,1,18.6074474636739,1.01913452148438,49.364616394043,49.8533744812012,,,,,,,,,,,,,,,,
,3861346938.83349,278.497851411054,9999.72,,,,,,,,,,,,,0.000476640712630706,2.66135824015552E-6,4.68297830391837E-5,1,2,,800,20,212,,,0.000476893814622844,4.80091934414941E-5,2.98431723422254E-6,-1.26001407352305E-6,,,,0.000126977965974769,39.995735168457,1.98215181341201,299.7285,277.9765625,278.962738037109,9999.72,9999.72,0.731174,6,1,3,4,19.0030001050532,1,18.6068274144563,1.01837158203125,50.3421325683594,50.3421325683594,,,,,,,,,,,,,,,,
sample offset = 25.17 mm,3861350546.515,300.018845009343,500.024,,,,,,,,,,,,,9.47297167109472E-6,3.3386484321095E-7,3.74535869405537E-6,1,2,,800,20,1,,,9.46353007827573E-6,3.76567024931786E-6,5.3929824161969E-8,-4.33712976644074E-8,,,,3.18957906019943E-6,39.995735168457,1.99284530875782,299.4613,300.010314941406,300.026214599609,500.024,500.024,0.71671,6,1,3,4,18.8529998942018,1,18.5739598051923,1.01654052734375,37.6344108581543,37.1456527709961,,,,,,,,,,,,,,,,
,3861351389.47176,245.800628224419,500.024,,,,,,,,,,,,,1.79573745644367E-5,2.80102007339508E-7,3.65394592116558E-6,1,2,,800,20,34,,,1.7984846083839E-5,3.71165422514687E-6,1.0932829752619E-7,-6.00977685394355E-8,,,,5.70215723502447E-6,39.995735168457,1.99251310562974,214.4946,244.966979980469,246.685760498047,500.024,500.024,0.702532,6,1,3,4,18.6829999967217,1,18.6022040861077,1.02638244628906,47.8983383178711,46.9208221435547,,,,,,,,,,,,,,,,
,3861352375.58855,158.934311,500.024,,,,,,,,,,,,,,,,,3,,,,,,,,,,,,,,,,,,,,,,0.738515,6,1,3,,18.9829999527633,2,,,46.4320640563965,49.364616394043,,,,,,,,,,,,,,,,
touchdown = 4.54000011086464 mm,3861353368.91849,68.7312021490259,500.024,,,,,,,,,,,,,8.5217373195947E-5,2.57147934123776E-7,9.80705191975406E-7,1,2,,800,20,91,,,8.4938374931157E-5,2.45005777894524E-6,5.43546093467739E-7,-1.85123440132884E-7,,,,2.29878292082734E-5,39.995735168457,1.98182428960773,53.0977,67.770751953125,69.7331390380859,500.024,500.024,0.648572,6,1,3,4,19.4930001108646,1,18.6212217761792,1.01875305175781,48.3870964050293,48.8758583068848,,,,,,,,,,,,,,,,
,3861354277.4942,10.0024444688968,500.024,,,,,,,,,,,,,8.43144854871757E-5,2.18995383914696E-7,-8.35046312124738E-7,1,2,,800,20,122,,,8.19358574397486E-5,-3.33929387496824E-7,5.29621161149407E-7,-1.61183535851706E-7,,,,2.24870685526187E-5,39.995735168457,1.98154406890237,9.9983,9.99974536895752,10.0045547485352,500.024,500.024,0.381958,1,1,3,4,19.8030001430511,1,18.6258888449727,1.01356506347656,50.3421325683594,49.364616394043,,,,,,,,,,,,,,,,
,3861355008.49242,10.0014654993574,500.024,,,,,,,,,,,,,8.41205187577238E-5,2.19793400590255E-7,-1.12067070304684E-6,1,2,,800,20,158,,,8.1748991414867E-5,-6.12578424215233E-7,5.29023168382992E-7,-1.59072769179147E-7,,,,2.23980056521588E-5,39.995735168457,1.98179011087754,9.9852,10.0010442733765,10.0018272399902,500.024,500.024,0.39753,1,1,3,4,19.8030001430511,1,18.6303325458108,1.02569580078125,50.8308906555176,51.3196487426758,,,,,,,,,,,,,,,,
,3861355730.55497,7.04878601001425,500.024,,,,,,,,,,,,,7.89482617293343E-5,2.29534431836458E-7,-1.13643134914709E-6,1,2,,800,20,194,,,7.67233474651598E-5,-6.57189179010108E-7,4.96589734666486E-7,-1.48817633771614E-7,,,,2.09732002000352E-5,39.995735168457,1.98157460517438,7.033,7.04429483413696,7.05232334136963,500.024,500.024,0.269257,7,1,3,4,19.8030001430511,1,18.6385625553118,1.0125732421875,51.3196487426758,51.3196487426758,,,,,,,,,,,,,,,,
,3861356496.80016,1.99988397004964,500.024,,,,,,,,,,,,,7.81678413700947E-5,2.20391450050116E-7,-1.39375207771952E-6,1,2,,800,20,229,,,7.59665105233208E-5,-9.11657862976143E-7,4.94917003379669E-7,-1.4646815316155E-7,,,,2.09366093031975E-5,39.995735168457,1.99254797264855,1.9933,1.99832737445831,2.00164794921875,500.024,500.024,0.165036,1,1,3,4,20.0229999555945,1,18.6388254680345,1.01669311523438,51.3196487426758,51.3196487426758,,,,,,,,,,,,,,,,
,3861357898.92634,39.3763183479004,47000.746,,,,,,,,,,,,,0.00922421571726188,4.41761685128121E-6,0.000139050859833636,1,2,,800,20,30,,,0.00903005123728806,0.000281848867549649,5.80491796426941E-5,-1.99344649445266E-5,,,,0.00239974638314314,39.995735168457,1.99250703754153,44.8965,38.8703804016113,39.8228607177734,47000.746,47000.746,0.439294,6,1,3,4,20.0930000229478,1,18.6304643087111,1.02920532226562,48.3870964050293,48.3870964050293,,,,,,,,,,,,,,,,
,3861358742.12816,80.0284214519671,47000.746,,,,,,,,,,,,,0.00719001102393279,1.01295571023382E-5,0.000394058797901898,1,2,,800,20,63,,,0.00719849185475215,0.000494084397715518,4.54901819466613E-5,-1.75483983184677E-5,,,,0.00190551927401369,39.995735168457,1.98180883072529,92.2221,79.5056991577148,80.4900436401367,47000.746,47000.746,0.569583,6,1,3,4,20.0330000317395,1,18.633685311166,1.01829528808594,50.3421325683594,49.8533744812012,,,,,,,,,,,,,,,,
,3861359616.56465,123.29040465464,47000.746,,,,,,,,,,,,,0.00528670610395487,1.37743937538681E-5,0.000611903500363988,1,2,,800,20,95,,,0.00531154159998298,0.00065220499605318,3.29899157804903E-5,-1.48008375617792E-5,,,,0.00141310753604446,39.995735168457,1.98159652892669,139.8582,122.801445007324,123.777572631836,47000.746,47000.746,0.610839,6,1,3,4,19.8730002104044,1,18.6283602326986,1.02523803710938,49.8533744812012,49.8533744812012,,,,,,,,,,,,,,,,
,3861360491.76429,167.038700649442,47000.746,,,,,,,,,,,,,0.00409939237076993,1.41300016645E-5,0.000491513008871506,1,2,,800,20,127,,,0.0041171919107003,0.000512320064011912,2.57041647273581E-5,-1.15780703708879E-5,,,,0.00110176236915618,39.995735168457,1.99286696753497,185.0282,166.563323974609,167.491821289062,47000.746,47000.746,0.629423,6,1,3,4,19.6830001606345,1,18.620807391998,1.02989196777344,49.8533744812012,49.8533744812012,,,,,,,,,,,,,,,,
touchdown = 4.44999989122152 mm,3861361367.93279,210.038184544446,47000.746,,,,,,,,,,,,,0.00321209611390597,1.45371418034717E-5,0.000339354860622255,1,2,,800,20,159,,,0.00322215245200511,0.000351295956639094,2.02158389583929E-5,-8.73825229064096E-6,,,,0.000860713481846068,39.995735168457,1.99284994467109,228.8826,209.503982543945,210.541412353516,47000.746,47000.746,0.655083,6,1,3,4,19.4029998912215,1,18.619612433388,1.02821350097656,49.364616394043,49.8533744812012,,,,,,,,,,,,,,,,
,3861362212.62536,251.143525008057,47000.746,,,,,,,,,,,,,0.00251234186753034,1.33321490854121E-5,0.00017847938253363,1,2,,800,20,192,,,0.00251661302637248,0.000185608914281332,1.58748425747035E-5,-6.21317258264753E-6,,,,0.000666238082242121,39.995735168457,1.98127479438632,271.1314,250.623428344727,251.609375,47000.746,47000.746,0.768623,6,1,3,4,19.1529998502433,1,18.6219106367344,1.01325988769531,50.3421325683594,50.3421325683594,,,,,,,,,,,,,,,,
,3861363089.47648,293.271363957084,47000.746,,,,,,,,,,,,,0.00201268373701076,1.53321564266023E-5,0.000191107020088565,1,2,,800,20,224,,,0.00201256495466882,0.000195657045801205,1.2605455594894E-5,-5.27289284946164E-6,,,,0.000534003741075333,39.995735168457,1.98181101004087,312.9424,292.806243896484,293.723297119141,47000.746,47000.746,0.688635,6,1,3,4,18.8529998942018,1,18.6123738659415,1.01799011230469,49.8533744812012,49.8533744812012,,,,,,,,,,,,,,,,
,3861439556.91861,2.00082819464463,2460.274,,,,,,,,,,,,,0.000379489920693765,7.84983940332651E-7,-1.48863625934421E-6,1,2,,400,10,16,,,0.000368793713453467,7.66838092893803E-7,2.38019970311143E-6,-7.3937980005212E-7,,,,9.82666021833339E-5,39.995735168457,1.98204913300988,1.9955,1.99673497676849,2.00373911857605,2310.424,2610.124,0.153889,1,6,3,4,20.1929998530745,1,18.6030435018856,1.02081298828125,43.49951171875,40.5669593811035,,,,,,,,,,,,,,,,
,3861439925.70284,2.00036185895597,11776.418,,,,,,,,,,,,,0.00182532257548391,8.03488618538955E-7,-1.35206819823624E-5,1,2,,400,10,52,,,0.00177463298484002,-5.22170526903883E-7,1.14622225737548E-5,-3.53142354470037E-6,,,,0.000469925678527322,39.995735168457,1.98213745306911,1.9947,1.99890804290771,2.00333404541016,11659.479,11893.357,0.146391,1,6,3,4,20.1929998530745,1,18.6059400217132,1.02294921875,47.4095802307129,45.9433059692383,,,,,,,,,,,,,,,,
,3861440287.68989,2.00250950085449,20421.616,,,,,,,,,,,,,0.00313736621232015,1.53001107282154E-6,-2.58803470900054E-5,1,2,,400,10,88,,,0.00305184727803805,1.36550410165443E-7,1.97092595044523E-5,-6.08283380643115E-6,,,,0.000807754176405033,39.995735168457,1.98219615492874,1.9839,2.00014662742615,2.00523829460144,20301.994,20541.238,0.139259,1,6,3,4,20.1929998530745,1,18.6145530217977,1.02371215820312,48.8758583068848,48.3870964050293,,,,,,,,,,,,,,,,
,3861440649.48735,2.00044901495043,29079.5785,,,,,,,,,,,,,0.0044529793644577,2.18825001287769E-6,-3.67323465707246E-5,1,2,,400,10,124,,,0.00433439661204456,5.51441312952048E-6,2.79802970908349E-5,-8.67492963152472E-6,,,,0.00114699210856159,39.995735168457,1.98214351800701,1.9786,1.99878859519958,2.00200796127319,28960.098,29199.059,0.140657,1,6,3,4,20.1929998530745,1,18.6178943978345,1.00975036621094,49.364616394043,49.8533744812012,,,,,,,,,,,,,,,,
,3861441011.44132,1.99973666823402,37751.871,,,,,,,,,,,,,0.00577893573734258,2.94776505494495E-6,-2.73298643474353E-5,1,2,,400,10,160,,,0.00562913423926246,3.38803779180883E-5,3.62802384188399E-5,-1.14311560537317E-5,,,,0.00148908655965347,39.995735168457,1.98177982980303,1.9741,1.99781262874603,2.00274515151978,37635.922,37867.82,0.131157,1,6,3,4,20.1929998530745,1,18.6091353491915,1.01600646972656,50.3421325683594,50.8308906555176,,,,,,,,,,,,,,,,
,3861441373.26517,1.99843816716194,46403.8145,,,,,,,,,,,,,0.00709266602542329,4.3553940807941E-6,-1.52347499597416E-5,1,2,,400,10,196,,,0.0069145998351309,6.76861406096185E-5,4.4512955355458E-5,-1.42170674735098E-5,,,,0.00182919821268844,39.995735168457,1.98186119017142,1.9715,1.99655067920685,2.00020551681519,46281.508,46526.121,0.136504,1,6,3,4,20.1929998530745,1,18.6176202093958,1.01898193359375,50.3421325683594,50.3421325683594,,,,,,,,,,,,,,,,
,3861441735.25577,2.00135079486143,55049.8185,,,,,,,,,,,,,0.0084577998186427,6.09702796820033E-6,3.26701617144633E-5,1,2,,400,10,232,,,0.0082527609494003,0.000139708642538964,5.30037832504604E-5,-1.7346048480249E-5,,,,0.00218207056486401,39.995735168457,1.98161834636393,1.9695,1.99713099002838,2.00962853431702,54927.938,55171.699,0.146391,1,6,3,4,20.1929998530745,1,18.6167940531565,1.02348327636719,50.8308906555176,50.8308906555176,,,,,,,,,,,,,,,,
,3861442097.22946,1.99944527733889,63675.7655,,,,,,,,,,,,,0.00984306044490367,7.07896939957627E-6,6.26902460649353E-5,1,2,,400,10,268,,,0.0096140929514828,0.000196925844231938,6.16846373304725E-5,-2.04230491362978E-5,,,,0.00254182100798404,39.995735168457,1.98173743720146,1.9693,1.99836361408234,2.00139093399048,63557.414,63794.117,0.133804,1,6,3,4,20.1929998530745,1,18.6110791062504,1.02210998535156,50.8308906555176,50.8308906555176,,,,,,,,,,,,,,,,
,3861442459.12971,2.00047509447303,72285.324,,,,,,,,,,,,,0.0113130113003966,7.26046184283454E-6,7.34811826700904E-5,1,2,,400,10,304,,,0.011062057825608,0.000238532384919676,7.09535815985873E-5,-2.35917705140309E-5,,,,0.00292412434350216,39.995735168457,1.98193312121067,1.9673,1.9977353811264,2.00471615791321,72161.75,72408.898,0.127285,1,6,3,4,20.1929998530745,1,18.6218817733731,1.02142333984375,50.8308906555176,51.3196487426758,,,,,,,,,,,,,,,,
,3861442820.99464,1.99954100859347,80869.887,,,,,,,,,,,,,0.0127433076401841,9.34817997368512E-6,0.000113004936089921,1,2,,400,10,340,,,0.012474587255475,0.0003092151875002,7.99228146206588E-5,-2.68631447397638E-5,,,,0.0032968913814012,39.995735168457,1.9816858406685,1.9691,1.9981107711792,2.00105738639832,80750.547,80989.227,0.11634,1,6,3,4,20.1929998530745,1,18.6236762424872,1.01661682128906,50.8308906555176,50.8308906555176,,,,,,,,,,,,,,,,
,3861443184.00336,2.00038733926098,89466.164,,,,,,,,,,,,,0.014261858951906,1.00411215141944E-5,0.000151639235077407,10,2,,400,10,376,,,0.0139774193389946,0.000381586051338247,8.94673357834108E-5,-3.03307078866055E-5,,,,0.00427425755949791,39.995735168457,1.98143895421349,1.9672,1.99853253364563,2.00161409378052,89341.883,89590.445,0.126019,1,6,3,4,20.1929998530745,1,18.6290122149473,1.01860046386719,50.8308906555176,50.8308906555176,,,,,,,,,,,,,,,,
,3861443547.73728,2.00093979146639,98060.039,,,,,,,,,,,,,0.0166117606275227,0.000496712288215739,0.000178776837800898,10,2,,400,10,412,,,0.0163002771770787,0.000457541946665725,0.000104326703876723,-3.54527510353364E-5,,,,0.00496238117280684,39.995735168457,1.98171840513226,1.9658,1.99590504169464,2.00658559799194,97939.992,98180.086,0.129853,1,6,3,4,20.1929998530745,1,18.6265777683915,1.01387023925781,51.3196487426758,51.3196487426758,,,,,,,,,,,,,,,,
,3861443911.42642,2.00040360379615,106621.0115,,,,,,,,,,,,,0.0252930372269049,0.00167876142415047,0.000231034680624411,10,2,,400,10,448,,,0.0248498989073062,0.000670278780120441,0.000159097879077308,-5.38781023351476E-5,,,,0.00705875663208146,39.995735168457,1.98170406610011,1.9627,1.9977639913559,2.00267434120178,106498,106744.023,0.129853,1,6,3,4,20.1929998530745,1,18.628887069964,1.0223388671875,51.3196487426758,51.3196487426758,,,,,,,,,,,,,,,,
,3861444275.16715,2.00059302009348,115162.07,,,,,,,,,,,,,0.0266398280724868,0.00173210439783654,0.000221775724558978,10,2,,400,10,484,,,0.0262054145057072,0.000696895310572552,0.000167783320648596,-5.67456518183462E-5,,,,0.00713939793043375,39.995735168457,1.98154060264878,1.9602,1.99877440929413,2.00208520889282,115041.32,115282.82,0.122299,1,6,3,4,20.1929998530745,1,18.6280196119273,1.0235595703125,51.3196487426758,51.3196487426758,,,,,,,,,,,,,,,,
,3861444638.94588,1.9995214620374,123682.367,,,,,,,,,,,,,0.0205871318587608,1.44557638880185E-5,0.000149459296438431,10,2,,400,10,520,,,0.0202761902379769,0.000524386247945845,0.000129856212879531,-4.38276401837356E-5,,,,0.00535623125938759,39.995735168457,1.98170099140134,1.9591,1.9975780248642,2.00094771385193,123568.25,123796.484,0.123527,1,6,3,4,20.1929998530745,1,18.6339528036598,1.01493835449219,50.8308906555176,51.808406829834,,,,,,,,,,,,,,,,
,3861445002.74386,2.00079195935186,132168.7735,,,,,,,,,,,,,0.0313463728221474,0.00204668168735234,0.000269647633033154,10,2,,400,10,556,,,0.0309084371427714,0.000848462612547816,0.000197863264475018,-6.71007510391064E-5,,,,0.00816535473798377,39.995735168457,1.98173164643682,1.9551,1.99764895439148,2.00573444366455,132054.516,132283.031,0.122299,1,6,3,4,20.1929998530745,1,18.6261704968124,1.01699829101562,51.3196487426758,50.8308906555176,,,,,,,,,,,,,,,,
,3861445366.53709,1.99868738917478,140003.1095,,,,,,,,,,,,,0.0238135594519512,1.6150486847865E-5,0.000150178487436247,1,2,,400,10,592,,,0.0235067244145133,0.000594928768919396,0.000150553081766702,-5.07283039041795E-5,,,,0.00620886534423159,39.995735168457,1.9814864083458,1.9543,1.99674105644226,2.00139164924622,140001.406,140004.813,0.117508,1,4,3,4,20.1929998530745,1,18.6366852957417,1.01646423339844,51.3196487426758,51.3196487426758,,,,,,,,,,,,,,,,
,3861445730.33561,2.00033321887334,130829.7145,,,,,,,,,,,,,0.223595934740645,0.0112962755741342,0.000891839158752532,100,2,,400,10,628,,,0.22045079825625,0.00502657101739536,0.00141309411264956,-0.000472145155072212,,,,0.0582269046532174,39.995735168457,1.98156951065396,1.9512,1.9967600107193,2.00470685958862,130699.359,130960.07,0.122299,1,6,3,4,20.1929998530745,1,18.634803672129,1.02005004882812,51.3196487426758,51.808406829834,,,,,,,,,,,,,,,,
,3861446094.06676,1.99938530372556,121525.4495,,,,,,,,,,,,,0.0202113082184433,1.46381912734562E-5,0.000167752994286088,10,2,,400,10,664,,,0.0198996358496421,0.00053384553542067,0.000127397404867224,-4.31468797614798E-5,,,,0.00526691973363673,39.995735168457,1.98161952527572,1.9618,1.99565279483795,2.00659704208374,121398.766,121652.133,0.126019,1,6,3,4,20.1929998530745,1,18.6388974658713,1.01699829101562,51.3196487426758,51.3196487426758,,,,,,,,,,,,,,,,
,3861446457.91105,2.00099367068736,112224.004,,,,,,,,,,,,,0.018531383381126,0.000104766694830987,0.000217633726912641,1,2,,400,10,700,,,0.0182204368488427,0.000544390981067846,0.000116510593215935,-3.9852769987192E-5,,,,0.00485702882746299,39.995735168457,1.9811623572703,1.9595,1.99861598014832,2.00406503677368,112095.906,112352.102,0.123527,1,6,3,4,20.1929998530745,1,18.6374318441317,1.01341247558594,51.3196487426758,51.808406829834,,,,,,,,,,,,,,,,
,3861446821.76981,1.99974588461656,102933.578,,,,,,,,,,,,,0.0212995601533385,0.00126929366522784,0.000219584902296411,10,2,,400,10,736,,,0.0209149078004417,0.000584201123713176,0.00013385149941314,-4.54913351859432E-5,,,,0.00591104465339096,39.995735168457,1.98159770506011,1.9625,1.99588668346405,2.00221991539001,102804.07,103063.086,0.124767,1,6,3,4,20.1929998530745,1,18.6364875779559,1.01921081542969,51.3196487426758,51.808406829834,,,,,,,,,,,,,,,,
,3861447185.56937,2.00040484878188,93643.8635,,,,,,,,,,,,,0.0158084823129589,0.000486991384044631,0.00012560212782485,10,2,,400,10,772,,,0.0155030560580847,0.000386578306044914,9.93151843431406E-5,-3.3417934901081E-5,,,,0.00463564960308102,39.995735168457,1.98168909572563,1.9657,1.997398853302,2.002765417099,93512.516,93775.211,0.103197,1,6,3,4,20.1929998530745,1,18.6342488251445,1.01806640625,51.3196487426758,51.3196487426758,,,,,,,,,,,,,,,,
,3861447549.21404,1.99955757105138,84371.801,,,,,,,,,,,,,0.0133982112095198,9.84421459912354E-6,0.000161450924286773,1,2,,400,10,808,,,0.0131213461664528,0.000371190161483107,8.39621425257064E-5,-2.85688729491085E-5,,,,0.00435909814097483,39.995735168457,1.98153216849241,1.9676,1.99798142910004,2.00223350524902,84243.563,84500.039,0.124767,1,6,3,4,20.1929998530745,1,18.6363372807963,1.02561950683594,51.3196487426758,51.3196487426758,,,,,,,,,,,,,,,,
,3861447912.85599,1.99982271433728,75102.137,,,,,,,,,,,,,0.0117777184995068,9.03352974521615E-6,0.000135144695957311,10,2,,400,10,844,,,0.0115198899705422,0.000309142063028156,7.37512091291137E-5,-2.49795411946252E-5,,,,0.00414587962759235,39.995735168457,1.98165623748663,1.9672,1.99737691879272,2.00327754020691,74976.016,75228.258,0.109572,1,6,3,4,20.1929998530745,1,18.6394670019858,1.02630615234375,50.8308906555176,51.808406829834,,,,,,,,,,,,,,,,
,3861448276.58385,1.99846104364483,65840.379,,,,,,,,,,,,,0.0131885929100941,0.000794693294573386,0.000125217266095956,10,2,,400,10,880,,,0.0128847288022461,0.000307411629126699,8.25698880362324E-5,-2.76939917966956E-5,,,,0.00495093554039447,39.995735168457,1.98176951014422,1.9697,1.99500107765198,2.00232291221619,65708.469,65972.289,0.123527,1,6,3,4,20.1929998530745,1,18.6401610155068,1.00624084472656,51.3196487426758,51.3196487426758,,,,,,,,,,,,,,,,
,3861448640.23525,1.99980185315005,56595.424,,,,,,,,,,,,,0.00932503097965409,0.000329731982157662,1.13286797890702E-5,10,2,,400,10,916,,,0.00910092995986333,0.000131727452133061,5.84794761380181E-5,-1.90014707186492E-5,,,,0.00393077767101082,39.995735168457,1.98128711279918,1.969,1.9964154958725,2.00384044647217,56467.75,56723.098,0.121083,1,6,3,4,20.1929998530745,1,18.6364679346247,1.01028442382812,51.3196487426758,51.808406829834,,,,,,,,,,,,,,,,
,3861449004.05531,1.99909791519419,47346.795,,,,,,,,,,,,,0.0114049424488447,0.000775970389547284,-3.63368400365581E-5,10,2,,400,10,952,,,0.0111198705035348,9.87111494195145E-5,7.15817732270807E-5,-2.28180360863917E-5,,,,0.00544209800477792,39.995735168457,1.98144160650924,1.9718,1.99499773979187,2.00522232055664,47222.512,47471.078,0.119879,1,6,3,4,20.1929998530745,1,18.6374714369434,1.01539611816406,51.3196487426758,51.3196487426758,,,,,,,,,,,,,,,,
,3861449366.14218,1.99699004928525,38151.545,,,,,,,,,,,,,0.00586269321526857,3.90768251059334E-6,-5.34023134642539E-5,1,2,,400,10,988,,,0.005711206531021,9.6815657690721E-6,3.68500077456702E-5,-1.14530012069736E-5,,,,0.00151101223732806,39.995735168457,1.98159033956743,1.9714,1.9944099187851,1.99973022937775,38024.719,38278.371,0.124767,1,6,3,4,20.1929998530745,1,18.6335584407636,1.01470947265625,50.8308906555176,51.3196487426758,,,,,,,,,,,,,,,,
,3861449728.11693,1.99852581825066,28965.1805,,,,,,,,,,,,,0.0372548292939472,0.000760749612266433,-0.000325640379975166,10,2,,400,10,1024,,,0.0362625657201389,2.77061071337348E-5,0.000234057559282519,-7.25125064491294E-5,,,,0.00959590646173393,39.995735168457,1.98174065598167,1.9728,1.99315750598907,2.00287079811096,28837.367,29092.994,0.123527,1,6,3,4,20.1929998530745,1,18.6349482632315,1.0162353515625,50.8308906555176,51.3196487426758,,,,,,,,,,,,,,,,
,3861450090.11009,1.99908705848058,19767.044,,,,,,,,,,,,,0.00306673350378492,1.60219124372677E-6,-2.98216935330224E-5,1,2,,400,10,1060,,,0.00298304522516185,-4.54029441094683E-6,1.92662118934095E-5,-5.91971456742613E-6,,,,0.000789433251965119,39.995735168457,1.98155822693945,1.9845,1.9932302236557,2.00515127182007,19640.076,19894.012,0.121083,1,6,3,4,20.1929998530745,1,18.632660225256,1.01951599121094,51.3196487426758,51.3196487426758,,,,,,,,,,,,,,,,
,3861450452.08441,1.99905403881391,10545.895,,,,,,,,,,,,,0.00925735431292279,0.000363035483468999,-6.25676111367277E-5,10,2,,400,10,1096,,,0.00899966419958444,1.74636048980723E-6,5.80987325520255E-5,-1.79547023435589E-5,,,,0.0023765381574643,39.995735168457,1.98165828103349,1.9912,1.99454391002655,2.00406670570374,10414.268,10677.522,0.121083,1,6,3,4,20.1929998530745,1,18.6274201187891,1.02432250976562,51.3196487426758,50.8308906555176,,,,,,,,,,,,,,,,
,3861450814.05385,2.00112552597809,1243.2805,,,,,,,,,,,,,0.000171021733937362,0.000118442536191011,-3.28205508205886E-5,1,2,,400,10,1132,,,0.000166379155733083,-3.09150089078393E-5,1.13571491056064E-6,-1.32389715190584E-7,,,,4.57030018782438E-5,39.995735168457,1.98158119205604,1.9929,1.99715197086334,2.00601267814636,1127.609,1358.952,0.123527,1,6,3,4,20.1929998530745,1,18.640464460916,1.0150146484375,50.8308906555176,51.3196487426758,,,,,,,,,,,,,,,,
,3861451175.95163,2.00009308666816,-7453.524,,,,,,,,,,,,,-0.0011409127517155,0.000162220759991527,-0.000192801393691133,1,2,,400,10,1168,,,-0.00110771183862181,-0.000194677559744233,-6.76271793054184E-6,3.46679371432401E-6,,,,0.000297001336558244,39.995735168457,1.98169302378812,1.9919,1.99633324146271,2.00748038291931,-7578.657,-7328.391,0.122299,1,6,3,4,20.1929998530745,1,18.6388027071402,1.01852416992188,50.8308906555176,51.3196487426758,,,,,,,,,,,,,,,,
,3861451537.88885,2.00299244150416,-15963.5935,,,,,,,,,,,,,-0.00253963199818624,1.09734324918014E-6,1.65595855292868E-5,1,2,,400,10,1204,,,-0.00246967117363056,-2.85198426699625E-6,-1.59363989951089E-5,4.94680716656148E-6,,,,0.000652133742693453,39.995735168457,1.98156072238581,1.986,1.99913501739502,2.0054292678833,-16086.466,-15840.721,0.121083,1,6,3,4,20.1929998530745,1,18.6440799479964,1.01715087890625,51.3196487426758,51.3196487426758,,,,,,,,,,,,,,,,
,3861451899.8572,1.99996721299934,-24526.505,,,,,,,,,,,,,-0.00387834131878079,2.1277245257221E-6,3.29457085366994E-5,1,2,,400,10,1240,,,-0.00377373080186076,-1.42925252645033E-6,-2.43561535171466E-5,7.53906306272256E-6,,,,0.000996923677317838,39.995735168457,1.98146652477893,1.98,1.99604845046997,2.0038902759552,-24645.422,-24407.588,0.118688,1,6,3,4,20.1929998530745,1,18.642799808547,1.01158142089844,51.3196487426758,51.3196487426758,,,,,,,,,,,,,,,,
,3861452261.84528,2.00055004062589,-33098.252,,,,,,,,,,,,,-0.00521104407125865,3.21153456340186E-6,4.48034114717825E-5,1,2,,400,10,1276,,,-0.00507401777866941,-7.58308881835005E-6,-3.27415218634997E-5,1.01719897429575E-5,,,,0.00134116605828567,39.995735168457,1.98169106732826,1.9708,1.99639201164246,2.00687408447266,-33218.441,-32978.063,0.119879,1,6,3,4,20.1929998530745,1,18.638527155526,1.0162353515625,50.8308906555176,50.8308906555176,,,,,,,,,,,,,,,,
,3861452623.78313,1.99856043066915,-41661.084,,,,,,,,,,,,,-0.00654657121133995,4.26818836973969E-6,3.636784205775E-5,1,2,,400,10,1312,,,-0.00637935068026225,-3.6590762541992E-5,-4.11119144700933E-5,1.29656173157855E-5,,,,0.001685578301837,39.995735168457,1.98178014925914,1.9709,1.99689197540283,2.0004563331604,-41777.316,-41544.852,0.122299,1,6,3,4,20.1929998530745,1,18.6406846927007,1.01112365722656,51.3196487426758,51.3196487426758,,,,,,,,,,,,,,,,
,3861452985.73309,2.00389043373489,-50215.4335,,,,,,,,,,,,,-0.00790836582223337,5.720832197377E-6,-1.04177454530388E-5,1,2,,400,10,1348,,,-0.00771267574179333,-0.000106130563907476,-4.95787862746511E-5,1.60769341164269E-5,,,,0.00203847066669356,39.995735168457,1.98171885181925,1.962,1.99880218505859,2.00805306434631,-50335.34,-50095.527,0.118688,1,6,3,4,20.1929998530745,1,18.6433886016435,1.01531982421875,50.8308906555176,51.3196487426758,,,,,,,,,,,,,,,,
,3861453347.64325,1.99866671997903,-58757.348,,,,,,,,,,,,,-0.00924013349255877,6.93544440635381E-6,-2.41296227498436E-5,1,2,,400,10,1384,,,-0.00902022569544299,-0.000145565157484776,-5.79441657464486E-5,1.8945729607367E-5,,,,0.00238499101593464,39.995735168457,1.98185957888773,1.9715,1.99430596828461,2.004319190979,-58871.887,-58642.809,0.11634,1,6,3,4,20.1929998530745,1,18.6468225996885,1.01478576660156,50.8308906555176,50.8308906555176,,,,,,,,,,,,,,,,
,3861453709.59881,2.00231419611041,-67275.25,,,,,,,,,,,,,-0.0106726117919441,8.4643686173699E-6,-0.000102123015665481,1,2,,400,10,1420,,,-0.0104286040688585,-0.000251273629348054,-6.68227512505837E-5,2.24371542572044E-5,,,,0.00275625966031348,39.995735168457,1.98175959710653,1.9668,1.99744832515717,2.00767350196838,-67396,-67154.5,0.096227,1,6,3,4,20.1929998530745,1,18.6457265004687,1.02546691894531,50.8308906555176,51.3196487426758,,,,,,,,,,,,,,,,
,3861454071.56168,2.00083833044624,-75783.965,,,,,,,,,,,,,-0.0121365522543895,9.29760655512896E-6,-0.00013714851731922,1,2,,400,10,1456,,,-0.0118719823041027,-0.000317337319219086,-7.60054244892672E-5,2.57462743320502E-5,,,,0.00313708022168066,39.995735168457,1.98169010838982,1.9668,1.99883198738098,2.00274181365967,-75901.188,-75666.742,0.117508,1,6,3,4,20.1929998530745,1,18.6476957716014,1.02363586425781,50.8308906555176,51.3196487426758,,,,,,,,,,,,,,,,
,3861454433.45201,2.00031267722849,-84262.7465,,,,,,,,,,,,,-0.0136670898152998,9.6933379490948E-6,-0.00015231702144343,1,2,,400,10,1492,,,-0.0133846629380168,-0.000366384517407919,-8.5668136307504E-5,2.9056696803309E-5,,,,0.00353540608967733,39.995735168457,1.98141617153905,1.9658,1.99559330940247,2.00378799438477,-84381.805,-84143.688,0.135147,1,6,3,4,20.1929998530745,1,18.6331976399148,1.01356506347656,50.8308906555176,51.3196487426758,,,,,,,,,,,,,,,,
,3861454795.43701,2.00030570966755,-92732.0585,,,,,,,,,,,,,-0.0448839864790538,0.00275678631062781,-0.00059128885673304,10,2,,400,10,1528,,,-0.0440072177195742,-0.00132456638849517,-0.00028144521638751,9.63608399615623E-5,,,,0.0116261231339631,39.995735168457,1.98163941374482,1.9622,1.99548017978668,2.0028235912323,-92845.469,-92618.648,0.115184,1,6,3,4,20.1929998530745,1,18.641508055046,1.01753234863281,51.3196487426758,51.3196487426758,,,,,,,,,,,,,,,,
,3861455157.37029,2.00076089851449,-101178.0665,,,,,,,,,,,,,-0.0167489626732913,1.26351253193771E-5,-0.000176035147219926,1,2,,400,10,1564,,,-0.0164423018854011,-0.000460769683067524,-0.000105231745692436,3.57924509444274E-5,,,,0.00434399474301985,39.995735168457,1.98183170286582,1.965,1.99852824211121,2.00215291976929,-101295.289,-101060.844,0.118688,1,6,3,4,20.1929998530745,1,18.6449085241233,1.02226257324219,51.3196487426758,51.3196487426758,,,,,,,,,,,,,,,,
,3861455519.48487,2.00077894027328,-109602.6095,,,,,,,,,,,,,-0.0183510033015273,1.23298244020491E-5,-0.000151575384531742,1,2,,400,10,1600,,,-0.0180374675119216,-0.000473653518213405,-0.000115490045573097,3.90474997402634E-5,,,,0.00476452184747381,39.995735168457,1.98154614144167,1.961,1.99605429172516,2.00540399551392,-109721.102,-109484.117,0.112905,1,6,3,4,20.1929998530745,1,18.6417412304336,1.01188659667969,51.3196487426758,51.3196487426758,,,,,,,,,,,,,,,,
,3861455881.55176,2.00020387588628,-118009.637,,,,,,,,,,,,,-0.019926471953853,1.37128436127719E-5,-0.000173038648232827,1,2,,400,10,1636,,,-0.0196093235904693,-0.000530916239020043,-0.000125509046483785,4.25539728894364E-5,,,,0.0051793457184496,39.995735168457,1.98135815827394,1.9601,1.99805188179016,2.00350522994995,-118123.188,-117896.086,0.11634,1,6,3,4,20.1929998530745,1,18.6438097226313,1.01287841796875,50.8308906555176,51.3196487426758,,,,,,,,,,,,,,,,
,3861456243.54667,2.00092164517447,-126388.844,,,,,,,,,,,,,-0.0215735852728416,1.53803452761534E-5,-0.00016034204949639,1,2,,400,10,1672,,,-0.0212557008244556,-0.000555245719460224,-0.00013611804752145,4.60237497463822E-5,,,,0.00561554985951171,39.995735168457,1.98188926218378,1.9556,1.99752223491669,2.00225281715393,-126506.063,-126271.625,0.123527,1,6,3,4,20.1929998530745,1,18.650303048784,1.014404296875,51.3196487426758,51.3196487426758,,,,,,,,,,,,,,,,
,3861456605.55658,2.0011974460907,-134739.2425,,,,,,,,,,,,,-0.02322436939339,1.61466797407263E-5,-0.000128881530785779,1,2,,400,10,1708,,,-0.0229092432694331,-0.000560230256897415,-0.000146784383105114,4.93461884616409E-5,,,,0.00605204325795924,39.995735168457,1.98185583068844,1.9519,1.99792432785034,2.00404381752014,-134853.922,-134624.563,0.102171,1,6,3,4,20.1929998530745,1,18.6462535578296,1.01844787597656,51.3196487426758,51.3196487426758,,,,,,,,,,,,,,,,
,3861456967.76273,1.99995887709109,-136896.5,,,,,,,,,,,,,-0.0236550783920004,1.64355518683589E-5,-0.000143123597984723,1,2,,400,10,1744,,,-0.023340690354345,-0.00058349287351729,-0.00014951458433643,5.03516421304084E-5,,,,0.00616570366416095,39.995735168457,1.98172634094452,1.9512,1.99493300914764,2.00384116172791,-137027.281,-136765.719,0.114039,1,6,3,4,20.1929998530745,1,18.6452270426089,1.01089477539062,51.3196487426758,51.3196487426758,,,,,,,,,,,,,,,,
,3861457329.67167,2.00096778564771,-127536.3005,,,,,,,,,,,,,-0.0218229867187316,1.53178185025085E-5,-0.000125870160299921,1,2,,400,10,1780,,,-0.021505523066134,-0.000526693784876604,-0.000137786293635145,4.63257674709894E-5,,,,0.00568110139412387,39.995735168457,1.98181382264016,1.9527,1.998419880867,2.00389266014099,-127666.234,-127406.367,0.115184,1,6,3,4,20.1929998530745,1,18.6458558765303,1.01463317871094,51.3196487426758,51.3196487426758,,,,,,,,,,,,,,,,
,3861457691.76538,2.00002314091937,-118184.0155,,,,,,,,,,,,,-0.0199984221444017,1.54173399424457E-5,-0.000151352935165265,1,2,,400,10,1816,,,-0.0196810181386839,-0.000511027298603715,-0.00012604433868546,4.2584040784277E-5,,,,0.00519953828257255,39.995735168457,1.9818990567192,1.9593,1.99497497081757,2.00692081451416,-118313.383,-118054.648,0.112905,1,6,3,4,20.1929998530745,1,18.6455590941047,1.01348876953125,51.3196487426758,51.808406829834,,,,,,,,,,,,,,,,
,3861458053.82331,2.00010255381139,-108837.664,,,,,,,,,,,,,-0.0182358888334024,1.35665114845953E-5,-0.000159639645754691,1,2,,400,10,1852,,,-0.0179221996420297,-0.000478770845103529,-0.000114722148282453,3.88502630812582E-5,,,,0.00473362392420249,39.995735168457,1.9813322628416,1.9631,1.99428927898407,2.00528407096863,-108964.773,-108710.555,0.114039,1,6,3,4,20.1929998530745,1,18.6436821818552,1.01219177246094,50.8308906555176,51.3196487426758,,,,,,,,,,,,,,,,
,3861458415.85287,1.99866402211126,-99495.2655,,,,,,,,,,,,,-0.0164784219883682,1.15065723601848E-5,-0.000156637907293631,1,2,,400,10,1888,,,-0.0161731062180844,-0.000435199102924674,-0.00010352522804169,3.50808877556119E-5,,,,0.00427190180759043,39.995735168457,1.98143847184073,1.9661,1.9963366985321,2.00098586082458,-99628.023,-99362.508,0.111783,1,6,3,4,20.1929998530745,1,18.6436519170343,1.02203369140625,51.3196487426758,51.3196487426758,,,,,,,,,,,,,,,,
,3861458777.8179,1.99770511800194,-90164.168,,,,,,,,,,,,,-0.0147754251405028,1.07864302208842E-5,-0.000150536209194034,1,2,,400,10,1924,,,-0.0144822741469761,-0.00038974161063102,-9.27159198909067E-5,3.14089920721017E-5,,,,0.00382574956358418,39.995735168457,1.9816770582538,1.969,1.99707818031311,1.9987827539444,-90296.078,-90032.258,0.110672,1,6,3,4,20.1929998530745,1,18.6384909917589,1.01203918457031,50.8308906555176,51.3196487426758,,,,,,,,,,,,,,,,
,3861459139.75471,1.99968116099167,-80837.164,,,,,,,,,,,,,-0.019129281644404,0.00127035355864506,-0.000228555106930589,10,2,,400,10,1960,,,-0.0187248970247564,-0.000521797258515337,-0.00011984151933575,4.07252118748147E-5,,,,0.00495804274430759,39.995735168457,1.98167245069087,1.9652,1.99524104595184,2.00310039520264,-80966.672,-80707.656,0.117508,1,6,3,4,20.1929998530745,1,18.6382685717677,1.01119995117188,50.8308906555176,51.3196487426758,,,,,,,,,,,,,,,,
,3861459501.67022,1.99991248339017,-71522.7305,,,,,,,,,,,,,-0.0114636023225684,8.97709112794318E-6,-0.000114849196033501,1,2,,400,10,1996,,,-0.0112075909783478,-0.000280274619814765,-7.17955917934887E-5,2.41729976551142E-5,,,,0.00296140268069564,39.995735168457,1.98175225470728,1.9639,1.99454867839813,2.00360083580017,-71652.805,-71392.656,0.111783,1,6,3,4,20.1929998530745,1,18.640849438561,1.02188110351562,50.8308906555176,51.3196487426758,,,,,,,,,,,,,,,,
,3861459863.59579,1.99942526185099,-62210.1325,,,,,,,,,,,,,-0.00985139169633947,7.90305991462122E-6,-5.36057269142819E-5,1,2,,400,10,2032,,,-0.00962060679958543,-0.00018647987767089,-6.1732396716252E-5,2.04035277420189E-5,,,,0.00254300058399309,39.995735168457,1.98163343748273,1.9659,1.99709248542786,2.00169491767883,-62341.195,-62079.07,0.112905,1,6,3,4,20.1929998530745,1,18.6445000850178,1.01150512695312,50.8308906555176,51.3196487426758,,,,,,,,,,,,,,,,
,3861460225.63454,1.99718755009206,-52906.424,,,,,,,,,,,,,-0.00832898976925618,6.32965390771919E-6,1.61853280487584E-5,1,2,,400,10,2068,,,-0.00812568039486966,-8.81527267705493E-5,-5.22863629157655E-5,1.67911839525914E-5,,,,0.0021488824153256,39.995735168457,1.9819760071252,1.9696,1.9950578212738,1.99912905693054,-53038.051,-52774.797,0.114039,1,6,3,4,20.1929998530745,1,18.6476999556925,1.01242065429688,50.8308906555176,51.3196487426758,,,,,,,,,,,,,,,,
,3861460587.57028,1.99990589559702,-43614.293,,,,,,,,,,,,,-0.00686434971240253,5.3460034004775E-6,4.15997478227487E-5,1,2,,400,10,2104,,,-0.00669037508622153,-3.67879972451581E-5,-4.31133885285817E-5,1.35865275296965E-5,,,,0.00176782688667997,39.995735168457,1.98151031972521,1.9683,1.99401819705963,2.00759387016296,-43742.813,-43485.773,0.112905,1,6,3,4,20.1929998530745,1,18.6418196360279,1.01806640625,50.8308906555176,51.3196487426758,,,,,,,,,,,,,,,,
,3861460949.62916,1.99661689473239,-34323.002,,,,,,,,,,,,,-0.0054252019677415,3.557531439074E-6,5.87480147525866E-5,1,2,,400,10,2140,,,-0.00528323948625736,2.97388491651254E-6,-3.41103877872229E-5,1.05229310065624E-5,,,,0.00139684313274565,39.995735168457,1.98156483631841,1.9734,1.9940425157547,2.0034191608429,-34451.238,-34194.766,0.128563,1,6,3,4,20.1929998530745,1,18.6424701257852,1.01524353027344,50.8308906555176,51.3196487426758,,,,,,,,,,,,,,,,
,3861461311.48156,1.99832680512746,-25037.9115,,,,,,,,,,,,,-0.0232875209826465,0.000871621740397959,0.000170363750685308,10,2,,400,10,2176,,,-0.0226600130387539,-3.69449793851152E-5,-0.000146183912875131,4.54412474937271E-5,,,,0.0059891235635461,39.995735168457,1.98129546269747,1.9777,1.99459159374237,2.0009183883667,-25167.563,-24908.26,0.11634,1,6,3,4,20.1929998530745,1,18.6398481852567,1.01234436035156,51.3196487426758,50.8308906555176,,,,,,,,,,,,,,,,
,3861461673.53187,1.99836245504467,-15740.335,,,,,,,,,,,,,-0.00252273185085254,1.21208923060807E-6,2.08309255190495E-5,1,2,,400,10,2212,,,-0.00245323650622338,1.50247059358928E-6,-1.58416405611206E-5,4.88495288664126E-6,,,,0.000647910204914321,39.995735168457,1.98183081639916,1.9838,1.9941520690918,2.00431656837463,-15869.139,-15611.531,0.114039,1,6,3,4,20.1929998530745,1,18.6382555942301,1.007080078125,50.8308906555176,51.3196487426758,,,,,,,,,,,,,,,,
,3861462035.56574,1.99989186266009,-6371.433,,,,,,,,,,,,,-0.00103637328869685,7.86355771782904E-7,6.8607035797026E-6,1,2,,400,10,2248,,,-0.00100732821923758,1.87682757506148E-7,-6.50283891445724E-6,2.00813974515768E-6,,,,0.000265982581977278,39.995735168457,1.98149151407913,1.9905,1.9971798658371,2.00218033790588,-6507.44,-6235.426,0.118688,1,6,3,4,20.1929998530745,1,18.6372848440209,1.01219177246094,50.8308906555176,51.3196487426758,,,,,,,,,,,,,,,,
,3861462397.6206,2.00342437565041,2879.594,,,,,,,,,,,,,0.000395410457086055,0.000114698191370195,0.000144492420846001,1,2,,400,10,2284,,,0.000383413020682048,0.000142741045867549,2.19017783820163E-6,-1.68632618624542E-6,,,,0.000108578845206206,39.995735168457,1.9814888374171,1.9843,1.99803900718689,2.0069317817688,2744.007,3015.181,0.119879,1,6,3,4,20.1929998530745,1,18.6400429275113,1.01768493652344,50.8308906555176,51.3196487426758,,,,,,,,,,,,,,,,
,3861462759.52304,2.00086860707474,11462.4625,,,,,,,,,,,,,0.00186446253407844,0.000192577674708471,1.51162412868499E-5,1,2,,400,10,2320,,,0.00181245734656374,2.75136659066466E-5,1.16430746857077E-5,-3.79378229808935E-6,,,,0.000479170685235232,39.995735168457,1.98126199771464,1.989,1.9979590177536,2.00531625747681,11350.467,11574.458,0.11634,1,6,3,4,20.1929998530745,1,18.6434072308936,1.009521484375,50.8308906555176,51.3196487426758,,,,,,,,,,,,,,,,
,3861463121.66713,2.00236314446259,20090.8535,,,,,,,,,,,,,0.00311919537715063,1.48033178233961E-6,-2.74734330676283E-5,1,2,,400,10,2356,,,0.00303411825538015,-1.70026109782315E-6,1.95844240806764E-5,-6.04043725616066E-6,,,,0.000802706899882057,39.995735168457,1.98103140516837,1.979,1.9988466501236,2.00620985031128,19970.666,20211.041,0.117508,1,6,3,4,20.1929998530745,1,18.6388893249243,1.02256774902344,50.8308906555176,50.8308906555176,,,,,,,,,,,,,,,,
,3861463483.46928,2.00376590470651,28749.099,,,,,,,,,,,,,0.00443957043342023,2.74719681248671E-6,-4.12726465051265E-5,1,2,,400,10,2392,,,0.00432127160262367,7.67783887090047E-7,2.78890402114484E-5,-8.62621891428717E-6,,,,0.00114203123811125,39.995735168457,1.98126493520726,1.9644,1.99724185466766,2.00928401947021,28628.768,28869.43,0.126019,1,6,3,4,20.1929998530745,1,18.6423325622291,1.01608276367188,50.3421325683594,51.3196487426758,,,,,,,,,,,,,,,,
,3861463845.35172,2.00006267848616,37408.4005,,,,,,,,,,,,,0.00575000413813476,4.12491115396488E-6,-5.81381608371797E-5,1,2,,400,10,2428,,,0.00560109430905888,3.29978562088715E-6,3.61464299203362E-5,-1.11973513412522E-5,,,,0.00148217674306365,39.995735168457,1.98139552967573,1.9678,1.99485456943512,2.00472378730774,37281.434,37535.367,0.112905,1,6,3,4,20.1929998530745,1,18.6434651285014,1.01936340332031,50.8308906555176,50.8308906555176,,,,,,,,,,,,,,,,
,3861464207.34629,2.00508059798559,46064.58,,,,,,,,,,,,,0.00705939503786226,4.92442215715297E-6,-2.6600117683055E-5,1,2,,400,10,2464,,,0.00688204984545316,5.59032432345292E-5,4.43033313786145E-5,-1.40869351525907E-5,,,,0.0018207086396913,39.995735168457,1.98106389948749,1.9578,1.99598503112793,2.012610912323,45947.359,46181.801,0.112905,1,6,3,4,20.1929998530745,1,18.6388816186749,1.02584838867188,50.8308906555176,50.8308906555176,,,,,,,,,,,,,,,,
,3861464569.27114,1.99835218545394,54706.631,,,,,,,,,,,,,0.00840152251655858,7.34631118160977E-6,-2.01527016846415E-5,1,2,,400,10,2500,,,0.00819819089891331,8.70871141094749E-5,5.27457414136734E-5,-1.69182876561536E-5,,,,0.00216897457584814,39.995735168457,1.98148335661175,1.9647,1.99332892894745,2.00698494911194,54582.207,54831.055,0.117508,1,6,3,4,20.1929998530745,1,18.640532925761,1.01463317871094,50.8308906555176,51.3196487426758,,,,,,,,,,,,,,,,
,3861464931.25021,1.99974860094628,63329.326,,,,,,,,,,,,,0.00974278592166314,7.91747723026105E-6,5.2394805343394E-5,1,2,,400,10,2536,,,0.00951587328173984,0.000185094564995439,6.1059974541422E-5,-2.01805614779005E-5,,,,0.0025175710446795,39.995735168457,1.98161136916845,1.9659,1.99662101268768,2.00649094581604,63203.207,63455.445,0.111783,1,6,3,4,20.1929998530745,1,18.6400100810258,1.01432800292969,50.8308906555176,50.8308906555176,,,,,,,,,,,,,,,,
,3861465293.22884,2.00037899462069,71937.191,,,,,,,,,,,,,0.0112099224756606,9.38581895612736E-6,0.00012142494583744,1,2,,400,10,2572,,,0.0109600383219403,0.000283483545606137,7.01782191754319E-5,-2.36901450989535E-5,,,,0.00289762367558283,39.995735168457,1.9813427599644,1.9631,1.99657320976257,2.0056095123291,71815.734,72058.648,0.114039,1,6,3,4,20.1929998530745,1,18.6369784484288,1.02096557617188,50.8308906555176,51.3196487426758,,,,,,,,,,,,,,,,
,3861465655.14297,2.00091845915095,80522.883,,,,,,,,,,,,,0.012698233819344,9.93656630726591E-6,0.000170136522725049,1,2,,400,10,2608,,,0.0124289779124357,0.000364027717267386,7.95003361417912E-5,-2.71480421361048E-5,,,,0.00328469370530214,39.995735168457,1.98143258625626,1.9638,1.99866604804993,2.00374436378479,80404.813,80640.953,0.11634,1,6,3,4,20.1929998530745,1,18.6419612859522,1.02340698242188,50.3421325683594,50.8308906555176,,,,,,,,,,,,,,,,
,3861466018.03063,1.99924534025104,89115.203,,,,,,,,,,,,,0.0216723038483718,0.0014556746818374,0.000279857560310973,10,2,,400,10,2644,,,0.0212382151990611,0.000627673089310308,0.000135850234073587,-4.64220320282038E-5,,,,0.00679357893933321,39.995735168457,1.98159885496247,1.9636,1.99633800983429,2.0027334690094,88996.711,89233.695,0.104233,1,6,3,4,20.1929998530745,1,18.6386461722398,1.02409362792969,50.8308906555176,50.8308906555176,,,,,,,,,,,,,,,,
,3861466381.85606,2.00111501980019,97708.0975,,,,,,,,,,,,,0.0162345464588917,0.000366431610667198,0.000233727480612729,10,2,,400,10,2680,,,0.0159283356275085,0.000504657366391445,0.000101804485893808,-3.50533555319998E-5,,,,0.00476013933439078,39.995735168457,1.9814754618427,1.9627,1.99749624729156,2.00457763671875,97588.898,97827.297,0.105279,1,6,3,4,20.1929998530745,1,18.6503469323257,1.01722717285156,50.8308906555176,51.3196487426758,,,,,,,,,,,,,,,,
,3861466745.47613,1.99996911329357,106276.414,,,,,,,,,,,,,0.0173754193969795,1.2598435954344E-5,0.000197368552307362,10,2,,400,10,2716,,,0.0170694802307319,0.000498086102502589,0.000109193315438461,-3.72759277524892E-5,,,,0.00463922843647194,39.995735168457,1.98156708325537,1.9588,1.99504947662354,2.00600862503052,106161.875,106390.953,0.115184,1,6,3,4,20.1929998530745,1,18.6426519206,1.02363586425781,51.3196487426758,50.8308906555176,,,,,,,,,,,,,,,,
,3861467109.33498,2.00064066011556,114823.824,,,,,,,,,,,,,0.0215956009636174,0.00102192096874848,0.000156141292871467,10,2,,400,10,2752,,,0.0212428458341248,0.00054133065537008,0.000136048736749217,-4.5900796976639E-5,,,,0.00578450214215636,39.995735168457,1.98167040892477,1.9552,1.99764633178711,2.00350022315979,114702.648,114945,0.114039,1,6,3,4,20.1929998530745,1,18.6492848454665,1.01486206054688,51.3196487426758,51.3196487426758,,,,,,,,,,,,,,,,
,3861467473.03136,2.00086687882423,123342.7105,,,,,,,,,,,,,0.020613393597955,1.53264983927157E-5,0.000196566842008312,10,2,,400,10,2788,,,0.0203002308114599,0.000571007088075251,0.000129909021779895,-4.41905176558066E-5,,,,0.0053627371000872,39.995735168457,1.9816367534934,1.9564,1.99761617183685,2.00354933738709,123222.523,123462.898,0.114039,1,6,3,4,20.1929998530745,1,18.6407300992275,1.01325988769531,50.8308906555176,51.3196487426758,,,,,,,,,,,,,,,,
,3861467836.84517,2.00094155231945,131835.75,,,,,,,,,,,,,0.0222746943505885,1.58446262115339E-5,0.000219727592495282,10,2,,400,10,2824,,,0.0219619750294495,0.000630438485598918,0.0001405078364769,-4.78948823001701E-5,,,,0.00580151111598804,39.995735168457,1.98153141907738,1.9504,1.998171210289,2.00330352783203,131720.359,131951.141,0.118688,1,6,3,4,20.1929998530745,1,18.6438328809849,1.01509094238281,49.8533744812012,51.3196487426758,,,,,,,,,,,,,,,,
,3861468200.53255,2.00110193934573,140000.2265,,,,,,,,,,,,,0.0314831088806922,0.00194823402960939,0.000262882625690397,10,2,,400,10,2860,,,0.0310762340152516,0.000850048976375431,0.0001988750154851,-6.74800830893219E-5,,,,0.00820756206356422,39.995735168457,1.98122127746548,1.9449,1.99526739120483,2.00747108459473,139998.25,140002.203,0.114039,1,4,3,4,20.1929998530745,1,18.6410921340334,1.01295471191406,51.3196487426758,51.3196487426758,,,,,,,,,,,,,,,,