File: DataFailid_Testimiseks/BaCu2PO4H2O__ACMSII_AllCrystalsRandomlyOriented__13042022.dat
[Header]
; ACMS II Data File (default extension .dat)
; Copyright (c) 2014, Quantum Design, Inc. All rights reserved.
TITLE,
FILEOPENTIME,3859003162.088,04/13/2022,10:19 am
BYAPP,ACMS II,1.0,1.2
INFO,PPMS ACMS II Option Release 1.0.8 Build 33,APPNAME
INFO,Quantum Design Linear Motor Servo Controller,MOTOR_MODULE_NAME
INFO,3101-100 C1,MOTOR_HW_VERSION
INFO,074,MOTOR_SERIAL_NUMBER
INFO,SRV No X-over 01.01.11,MOTOR_SOFTWARE_VERSION
INFO,ACMS,ACMS_MODULE_NAME
INFO,3101-430 D0,ACMS_HW_VERSION
INFO,ACMSII183,ACMS_SERIAL_NUMBER
INFO,00.14.14,ACMS_SOFTWARE_VERSION
INFO,WF181,COIL_SERIAL_NUMBER
INFO,0,MOMENT_UNITS
INFO,,SAMPLE_MATERIAL
INFO,,SAMPLE_COMMENT
INFO,,SAMPLE_MASS
INFO,,SAMPLE_VOLUME
INFO,,SAMPLE_MOLECULAR_WEIGHT
INFO,,SAMPLE_SIZE
INFO,,SAMPLE_SHAPE
DATATYPE,COMMENT,1
DATATYPE,TIME,2
STARTUPAXIS,X,2
STARTUPAXIS,Y1,5
STARTUPGROUP, AC
FIELDGROUP, AC, 2,3,4,5,6,7,8,9,10,11,12,13,14,15,16,20,21,22,23,24,25,35,43,44,45,46,47,48,49
FIELDGROUP, DC, 2,3,4,17,18,19,20,21,23,24,25,35,36,37,43,44,45,46,47,48,49,50,51
FIELDGROUP, Diagnostic, 26,27,28,29,30,31,32,33,34,38,39,40,41,42,52,53,54,55,56,57,58,59,60,61,62,63,64,65,66,67,68,69
[Data]
Comment,Time Stamp (sec),Temperature (K),Magnetic Field (Oe),AC Moment (emu),AC Std. Dev. (emu),AC Phase (deg),AC Phase Std. Dev. (deg),AC Suscept. (emu/Oe),AC Suscept. Std. Dev. (emu/Oe),AC X'  (emu/Oe),AC X" (emu/Oe),AC X' Std. Dev. (emu/Oe),AC X" Std. Dev. (emu/Oe),AC Drive (Oe),AC Frequency (Hz),DC Moment (emu),DC Std. Err. (emu),DC Quad. Moment (emu),Range (mV),"AC=1 DC=2 Locate=3",Measure Type,Measure Count,Measure Time (sec),Measure Number,AC X' Raw (emu/Oe),AC X" Raw (emu/Oe),DC M. Raw' (emu),DC M. Raw" (emu),Coil InPhase (V),Coil Quadrature (V),Null Status,Trim Ratio,Trim Phase (deg.),Max. Signal (mV),Motor Frequency (Hz),Motor Ampl. (mm),System Temp. (K),Min. Temperature (K),Max. Temperature (K),Min. Field (Oe),Max. Field (Oe),Pressure (Torr),Temp. Status (code),Field Status (code),Chamber Status (code),Measure Status (code),Center Position (mm),Transport Action,Motor Lag (deg),Motor Current (amps),Motor Heatsink Temp. (C),Motor Board Temp. (C),QMap 01,QMap 02,QMap 03,QMap 04,QMap 05,QMap 06,QMap 07,QMap 08,QMap 09,QMap 10,QMap 11,QMap 12,QMap 13,QMap 14,QMap 15,QMap 16
,3859009082.15879,299.967834,-0.042,,,,,,,,,,,,,,,,,3,,,,,,,,,,,,,,,,,,,,,,36.688858,1,1,3,,18.1930000626594,2,,,33.2355842590332,37.6344108581543,,,,,,,,,,,,,,,,
,3859009980.16241,299.999484819685,-0.042,5.73848486561448E-8,3.86037317588202E-8,-7.24452315185864,23.2206506099476,5.74340570653279E-9,3.86368350652307E-9,5.69755614693587E-9,-7.24267258922188E-10,2.02080633957281E-10,3.29339187504854E-10,9.99143218994141,499.200012207031,,,,1,1,5,14976,30,3,5.95624302435961E-9,-5.93010394610871E-10,,,-5.51283118291152E-10,5.71233676389123E-9,5,0.0870518982410431,29.9632167816162,0.331966485795422,,,299.9183,299.992584228516,300.017608642578,-0.042,-0.042,37.451283,1,1,3,0,18.1930000626594,1,,,32.7468223571777,37.6344108581543,,,,,,,,,,,,,,,,
,3859011143.60372,299.99561857284,-0.042,5.08989541407263E-8,7.66852410341712E-9,4.64083119746576,5.24568027399051,5.09511211974944E-9,7.67638368204666E-10,5.07840765446827E-9,4.12241686217773E-10,3.88336625949254E-10,6.40316964369458E-10,9.98976135253906,4992,,,,10,1,5,150016,30,6,5.10271386119671E-9,5.0122429063244E-10,,,5.35085871152061E-9,4.93655665563479E-8,5,0.361022591590881,20.3319110870361,2.40444584082356,,,299.9381,299.973693847656,300.008331298828,-0.042,-0.042,37.451283,1,1,3,0,18.1930000626594,1,,,32.7468223571777,37.1456527709961,,,,,,,,,,,,,,,,
sample offset = 25.21 mm touchdown = 3.23999999091029 mm,3859012896.17897,290.034112841407,-0.042,7.13053285255189E-7,2.01480924526972E-6,23.5222637441939,152.705923175577,7.13300082120455E-8,2.01550659652821E-7,6.54028455294011E-8,2.84681904621242E-8,3.01961897849837E-10,2.81391561839618E-10,9.99654006958008,10,,,,10,1,5,300,30,1,6.93075965275124E-8,3.02177783199327E-8,,,5.84211413941744E-10,1.33828219930696E-9,5,0.0599709302186966,0.391146242618561,0.117270403248388,,,289.9162,289.910949707031,290.076049804687,-0.042,-0.042,36.688858,1,1,3,0,18.1529999909103,1,,,32.2580642700195,37.6344108581543,,,,,,,,,,,,,,,,
,3859014026.3568,289.994336051502,-0.042,1.37505667718864E-7,1.41692481401304E-8,173.396510724669,4.15385440748807,1.37583698329326E-8,1.41772887911124E-9,-1.36670935627059E-8,1.58218014397697E-9,1.78978672070116E-10,2.12494644055962E-10,9.99432849884033,998.400024414062,,,,1,1,5,29952,30,4,-1.40015031574174E-8,1.196147410288E-9,,,2.16432288284348E-9,-2.68593216515211E-8,5,0.129750669002533,39.0901527404785,0.589746702111895,,,289.8345,289.985046386719,290.012420654297,-0.042,-0.042,36.688858,1,1,3,0,18.1529999909103,1,,,32.2580642700195,37.1456527709961,,,,,,,,,,,,,,,,
,3859015184.19912,290.002108755828,-0.042,1.79321614457024E-8,4.24351642499018E-9,-32.0961563045222,12.7899253256878,1.79299009200928E-9,4.24298148793964E-10,1.51894512655639E-9,-9.52690491478761E-10,5.54162385822755E-10,6.6262993400938E-10,10.0012607574463,9984,,,,10,1,5,299520,30,7,1.55709165963012E-9,-9.45545949731459E-10,,,-1.86431271034511E-8,3.13883539703743E-8,5,0.759891211986542,12.1135950088501,4.012150684907,,,289.8979,289.990844726562,290.007598876953,-0.042,-0.042,36.307648,1,1,3,0,18.1529999909103,1,,,32.7468223571777,37.6344108581543,,,,,,,,,,,,,,,,
,3859017098.03578,280.041104577035,-0.042,1.15074423637348E-7,1.12391913792078E-7,102.302797012856,46.5160555363309,1.15116558623462E-8,1.12433066565886E-8,-2.45288155796951E-9,1.1247292685605E-8,1.55733557448611E-10,1.6484495236293E-10,9.99633979797363,98.9429168701172,,,,10,1,5,2968,30,2,-2.68628861464205E-9,1.18825984891238E-8,,,2.26286005744532E-9,-5.1634630818599E-10,5,0.0661724507808685,10.0612049102783,0.173087898269634,,,279.6364,280.010772705078,280.07568359375,-0.042,-0.042,35.926437,1,1,3,0,18.1729999103695,1,,,32.2580642700195,37.6344108581543,,,,,,,,,,,,,,,,
sample offset = 25.21 mm touchdown = 2.24000005982816 mm,3859023781.01825,280.129402872721,-0.042,3.72457966310226E-6,8.18356316793073E-6,213.596073422324,124.557355982978,3.72586878777821E-7,8.18639560384865E-7,-3.10349654923535E-7,-2.06165161766583E-7,1.25153834441534E-9,1.12554344664787E-9,9.99654006958008,10,,,,100,1,5,300,30,1,-3.28825420390922E-7,-2.1874045793071E-7,,,-4.24071204659677E-9,-6.37678236442746E-9,5,0.0600514970719814,0.250294089317322,0.147594330447072,,,279.6507,279.930816650391,280.184814453125,-0.042,-0.042,30.97069,1,1,3,0,17.1530000598282,1,,,32.2580642700195,37.1456527709961,,,,,,,,,,,,,,,,
,3859025057.67788,279.991241848571,-0.042,4.12085108137288E-7,1.80247407200015E-8,177.722271513877,1.41346439932132,4.12318954880363E-8,1.80349692549058E-9,-4.1199318963426E-8,1.63869536102208E-9,1.97527371099999E-10,2.92575064281035E-10,9.99432849884033,998.400024414062,,,,1,1,5,29952,30,4,-4.20618141620823E-8,4.26217670776132E-10,,,4.34086494048335E-10,-8.06592673085132E-8,5,0.130738407373428,39.5225296020508,0.589424680579985,,,279.611,279.979278564453,280.002105712891,-0.042,-0.042,31.733112,1,1,3,0,17.1530000598282,1,,,32.2580642700195,37.1456527709961,,,,,,,,,,,,,,,,
,3859026217.32654,280.000276822257,-0.042,1.06193609054077E-7,4.14584453152241E-9,261.282075864336,1.64022333981121,1.06180222303485E-8,4.14532190697626E-10,-1.60937414449617E-9,-1.04953471094196E-8,5.39978045275924E-10,6.48445207890945E-10,10.0012607574463,9984,,,,10,1,5,299520,30,7,-1.48347746292364E-9,-1.06844849520578E-8,,,-2.14382093083229E-7,-2.77536537543585E-8,5,0.751752495765686,11.7806091308594,4.01389496820485,,,279.7169,279.981536865234,280.007965087891,-0.042,-0.042,31.351902,1,1,3,0,17.1530000598282,1,,,32.2580642700195,37.6344108581543,,,,,,,,,,,,,,,,
,3859028003.05597,270.034726615574,-0.042,1.85487943206486E-7,1.0776430879091E-7,112.74561243606,30.5342584773371,1.8555586040011E-8,1.07803767147606E-8,-7.17433810870078E-9,1.71125289186109E-8,1.48880750757546E-10,1.58449689400729E-10,9.99633979797363,98.9429168701172,,,,10,1,5,2968,30,2,-7.73445970618816E-9,1.80468577585487E-8,,,3.43545344873437E-9,-1.48068231214956E-9,5,0.0646853148937225,10.3031034469604,0.160609461995198,,,269.6066,270.017028808594,270.04638671875,-0.042,-0.042,31.351902,1,1,3,0,17.3529999529123,1,,,32.2580642700195,37.1456527709961,,,,,,,,,,,,,,,,
,3859029475.02066,269.994562939776,-0.042,1.23348475188664E-7,1.10785060432325E-8,244.969760368373,4.95415587195626,1.2349684910768E-8,1.10918322019545E-9,-5.22510889423049E-9,-1.11898594467796E-8,3.32054104120281E-10,2.71590872987502E-10,9.98798561096191,1996.80004882813,,,,10,1,5,59904,30,5,-5.01544136826858E-9,-1.13744944548838E-8,,,-4.37198625242375E-8,-1.908795996301E-8,5,0.217861995100975,35.5503921508789,1.19658742713145,,,269.703,269.986633300781,270.003631591797,-0.042,-0.042,30.589479,1,1,3,0,17.3529999529123,1,,,32.7468223571777,37.1456527709961,,,,,,,,,,,,,,,,
,3859031460.15738,260.048645,-0.042,,,,,,,,,,,,,,,,,3,,,,,,,,,,,,,,,,,,,,,,31.351902,1,1,3,,17.3730001052022,2,,,33.2355842590332,37.1456527709961,,,,,,,,,,,,,,,,
,3859032514.53357,260.003345722229,-0.042,1.50552048642777E-7,2.4351031815855E-8,139.311830376578,9.02358180938145,1.50681149389515E-8,2.43719132081682E-9,-1.14256839143936E-8,9.82353474579396E-9,1.49111014702043E-10,1.91350639012064E-10,9.99143218994141,499.200012207031,,,,10,1,5,14976,30,3,-1.21422312358547E-8,9.84750299920763E-9,,,9.41085961473625E-9,-1.16617641240539E-8,5,0.0930847227573395,32.8073768615723,0.376365548099656,,,259.6479,259.992858886719,260.018035888672,-0.042,-0.042,30.97069,1,1,3,0,17.3730001052022,1,,,32.7468223571777,37.1456527709961,,,,,,,,,,,,,,,,
,3859033678.3807,259.994870172031,-0.042,1.43483707982406E-7,5.26632199199083E-9,-56.9215516363884,1.96348558653053,1.43630766460639E-8,5.2717195197584E-10,7.83917788490814E-9,-1.20351676693544E-8,2.91635482820521E-10,4.2296762584611E-10,9.98976135253906,4992,,,,10,1,5,150016,30,6,8.05620357207266E-9,-1.1981201926886E-8,,,-1.15337055842433E-7,7.90631061487894E-8,5,0.366574645042419,17.5189113616943,2.40377496263208,,,259.7057,259.979217529297,260.005889892578,-0.042,-0.042,30.97069,1,1,3,0,17.3730001052022,1,,,32.2580642700195,37.1456527709961,,,,,,,,,,,,,,,,
sample offset = 25.21 mm touchdown = 2.60000000707805 mm,3859035430.58207,250.065570324025,-0.042,2.86260660641197E-7,1.92215359124063E-6,8.06355694400987,180,2.86359739118438E-8,1.92281887319177E-7,2.8352852267431E-8,4.0168109466386E-9,2.84605552049649E-10,2.72142506770007E-10,9.99654006958008,10,,,,10,1,5,300,30,1,3.00500582946278E-8,4.28019285851687E-9,,,8.35859338699008E-11,5.80251046198851E-10,5,0.0604100897908211,1.09323501586914,0.11753875452498,,,249.6818,250.032211303711,250.085754394531,-0.042,-0.042,31.351902,1,1,3,0,17.513000007078,1,,,32.2580642700195,37.6344108581543,,,,,,,,,,,,,,,,
,3859036561.20104,249.9981709565,-0.042,1.5964169946938E-7,1.24992129246346E-8,190.826583985618,3.58600447995732,1.59732291657117E-8,1.25063058774633E-9,-1.56889089479516E-8,-3.00036431175066E-9,1.58053230205172E-10,1.85750919414611E-10,9.99432849884033,998.400024414062,,,,1,1,5,29952,30,4,-1.5856333062449E-8,-3.49613506357876E-9,,,-6.83203929312385E-9,-3.03739131341309E-8,5,0.144227474927902,40.2355499267578,0.585681133682767,,,249.6601,249.989883422852,250.005859375,-0.042,-0.042,30.208265,1,1,3,0,17.513000007078,1,,,32.2580642700195,37.1456527709961,,,,,,,,,,,,,,,,
,3859037720.36305,250.003175809786,-0.042,1.29661308002144E-7,5.28090894978658E-9,-75.3693371310236,1.4496842797961,1.29644962916907E-8,5.28024323918838E-10,3.27466593601461E-9,-1.25441112520882E-8,4.12440076447757E-10,9.91841954866536E-10,10.0012607574463,9984,,,,10,1,5,299520,30,7,3.49419292430695E-9,-1.26916697423953E-8,,,-2.53774658964118E-7,7.19396674779766E-8,5,0.745163321495056,11.024561882019,4.01080892852404,,,249.6573,249.982864379883,250.011703491211,-0.042,-0.042,30.208265,1,1,3,0,17.513000007078,1,,,32.2580642700195,37.1456527709961,,,,,,,,,,,,,,,,
,3859039507.79767,240.035797340282,-0.042,2.08086655921208E-7,1.0220901364793E-7,104.525438999688,24.6359811399354,2.08162847728915E-8,1.02246437909852E-8,-5.22092887422692E-9,2.01509209078985E-8,1.48158012589282E-10,1.43224803860486E-10,9.99633979797363,98.9429168701172,,,,1,1,5,2968,30,2,-5.71301303133385E-9,2.12622394888434E-8,,,4.04858642536811E-9,-1.0940137003879E-9,5,0.0654438883066177,11.2318315505981,0.128313141266374,,,239.5943,240.015579223633,240.055633544922,-0.042,-0.042,30.208265,1,1,3,0,17.523000083223,1,,,32.2580642700195,37.1456527709961,,,,,,,,,,,,,,,,
,3859040989.13947,239.992349554391,-0.042,1.25308627942852E-7,2.55196480027596E-8,-58.0330532004951,11.627250928915,1.25459359698441E-8,2.55503451814663E-9,6.642194228251E-9,-1.06433906812452E-8,7.73645549057753E-10,6.12048898341939E-10,9.98798561096191,1996.80004882813,,,,1,1,5,59904,30,5,6.87873861035314E-9,-1.05660760927769E-8,,,-4.03310917650305E-8,2.67221101663753E-8,5,0.234645649790764,32.591911315918,1.0923858344219,,,239.6277,239.978378295898,240.00309753418,-0.042,-0.042,30.97069,1,1,3,0,17.523000083223,1,,,32.7468223571777,37.6344108581543,,,,,,,,,,,,,,,,
,3859043097.44597,229.995621,-0.042,,,,,,,,,,,,,,,,,3,,,,,,,,,,,,,,,,,,,,,,30.97069,1,1,3,,17.8330001154095,2,,,33.2355842590332,37.1456527709961,,,,,,,,,,,,,,,,
,3859044153.46165,229.999077071449,-0.042,2.41347675019587E-7,2.27379245366928E-8,146.425484773471,5.13849808247379,2.41554634442254E-8,2.27574226641738E-9,-2.01255423332087E-8,1.33584789553127E-8,1.46209150079972E-10,1.71696062837468E-10,9.99143218994141,499.200012207031,,,,1,1,5,14976,30,3,-2.1190452634004E-8,1.31818423456154E-8,,,1.25839154174076E-8,-2.03380019597401E-8,5,0.099123939871788,35.296516418457,0.337427480862827,,,229.6233,229.990692138672,230.012954711914,-0.042,-0.042,30.97069,1,1,3,0,17.8330001154095,1,,,32.7468223571777,37.1456527709961,,,,,,,,,,,,,,,,
,3859045351.12293,229.995889211666,-0.042,2.12667724557139E-7,4.91807489828299E-9,-46.1864595301685,1.32060375552284,2.12885690710805E-8,4.92311550268714E-10,1.47383685554406E-8,-1.53617598411824E-8,3.10355104180894E-10,3.65350183628268E-10,9.98976135253906,4992,,,,10,1,5,150016,30,6,1.50004411072869E-8,-1.52384861467909E-8,,,-1.46386209847087E-7,1.46468721743698E-7,5,0.36797297000885,15.5170373916626,2.41169132529154,,,229.6863,229.980270385742,230.007141113281,-0.042,-0.042,30.208265,1,1,3,0,17.8330001154095,1,,,32.7468223571777,37.1456527709961,,,,,,,,,,,,,,,,
sample offset = 25.21 mm touchdown = 2.85999989137054 mm,3859047223.81232,220.058404963067,-0.042,5.56317019024533E-7,1.9776063026768E-6,4.33739334013505,155.729184248829,5.56509567462677E-8,1.97829077752086E-7,5.54915716980709E-8,4.20885462481339E-9,2.88508491887816E-10,2.84293288647245E-10,9.99654006958008,10,,,,10,1,5,300,30,1,5.8814934226801E-8,4.51392137970775E-9,,,8.83581304071102E-11,1.13559292577667E-9,5,0.0604564473032951,0.533979177474976,0.128809602775259,,,219.6173,219.989013671875,220.082275390625,-0.042,-0.042,30.97069,1,1,3,0,17.7729998913705,1,,,32.2580642700195,37.1456527709961,,,,,,,,,,,,,,,,
,3859048352.72709,219.994754884569,-0.042,1.15452808786413E-7,1.4675067878043E-8,227.857082276727,7.16274432635955,1.15518325017843E-8,1.46833955675419E-9,-7.75107412431693E-9,-8.56537705350003E-9,1.80176149148852E-10,2.21183670225256E-10,9.99432849884033,998.400024414062,,,,1,1,5,29952,30,4,-7.62305367442207E-9,-8.87590763210537E-9,,,-1.70781369210695E-8,-1.4542856774531E-8,5,0.1598140001297,40.2346611022949,0.587774273640182,,,219.6552,219.984390258789,220.00212097168,-0.042,-0.042,30.208265,1,1,3,0,17.7729998913705,1,,,32.2580642700195,37.6344108581543,,,,,,,,,,,,,,,,
,3859049510.54151,220.005805043127,-0.042,1.65330564074883E-7,3.45660676626795E-9,-44.871438647048,1.13685270679152,1.65309722528521E-8,3.45617102693217E-10,1.17153614956719E-8,-1.16629048118508E-8,3.27637265453581E-10,6.21494914853417E-10,10.0012607574463,9984,,,,10,1,5,299520,30,7,1.20313468188861E-8,-1.16889804637998E-8,,,-2.32756111149569E-7,2.4243826618276E-7,5,0.740370512008667,10.291259765625,4.0122848605453,,,219.629,219.989013671875,220.013656616211,-0.042,-0.042,30.97069,1,1,3,0,17.7729998913705,1,,,32.2580642700195,37.1456527709961,,,,,,,,,,,,,,,,
,3859051395.33124,210.033434413794,-0.042,4.03432866376678E-7,1.01330832565195E-7,105.885425596087,12.5853373451431,4.03580585024189E-8,1.01367935277406E-8,-1.10465886456198E-8,3.88168232262653E-8,1.42857847584646E-10,1.45763431693029E-10,9.99633979797363,98.9429168701172,,,,1,1,5,2968,30,2,-1.21006254487767E-8,4.09034906856443E-8,,,7.78566282825873E-9,-2.31590509548111E-9,5,0.0659654662013054,12.5058937072754,0.131224775911776,,,209.5991,210.01008605957,210.055953979492,-0.042,-0.042,30.97069,1,1,3,0,17.7030000568479,1,,,32.2580642700195,37.6344108581543,,,,,,,,,,,,,,,,
,3859052740.75396,210.000946571087,-0.042,3.00358594551889E-7,1.34451457066043E-8,-74.3580694937698,2.3922931994438,3.00719891128239E-8,1.34613186585373E-9,8.10814849770545E-9,-2.89582882287776E-8,4.09539009604742E-10,3.18705615895975E-10,9.98798561096191,1996.80004882813,,,,10,1,5,59904,30,5,8.6174028565323E-9,-2.89184653141083E-8,,,-1.10871340581906E-7,3.33859034651979E-8,5,0.248222500085831,28.9118728637695,1.1980633591527,,,209.6481,209.991165161133,210.010696411133,-0.042,-0.042,30.97069,1,1,3,0,17.7030000568479,1,,,32.2580642700195,37.6344108581543,,,,,,,,,,,,,,,,
,3859054820.42987,199.996582,-0.042,,,,,,,,,,,,,,,,,3,,,,,,,,,,,,,,,,,,,,,,30.97069,1,1,3,,17.9929999367446,2,,,33.2355842590332,37.1456527709961,,,,,,,,,,,,,,,,
,3859055719.52672,200.004358302525,-0.042,3.49770122047818E-7,2.49427329572435E-8,160.372573938043,3.26551952935529,3.50070055422024E-8,2.49641217425805E-9,-3.29729855371568E-8,1.17589396545026E-8,1.42055974612095E-10,2.00901943900404E-10,9.99143218994141,499.200012207031,,,,1,1,5,14976,30,3,-3.42326231724366E-8,1.1075518514129E-8,,,1.05341254084852E-8,-3.28252337203586E-8,5,0.107295952737331,38.0560607910156,0.341976058295439,,,199.6192,199.993530273438,200.019943237305,-0.042,-0.042,30.589479,1,1,3,0,17.9929999367446,1,,,32.2580642700195,37.1456527709961,,,,,,,,,,,,,,,,
,3859056986.31372,200.001683826197,-0.042,3.11728748700197E-7,6.00430619748137E-9,-36.8118156016884,1.05725745290092,3.12048243896203E-8,6.01046009568114E-10,2.49828265087615E-8,-1.86975785817352E-8,3.56627449963016E-10,4.63526116846881E-10,9.98976135253906,4992,,,,10,1,5,150016,30,6,2.5280368481008E-8,-1.84924569133732E-8,,,-1.77279090947054E-7,2.46125596591731E-7,5,0.367514371871948,13.5080738067627,2.42094944433396,,,199.6063,199.991912841797,200.00993347168,-0.042,-0.042,30.589479,1,1,3,0,17.9929999367446,1,,,32.2580642700195,36.6568908691406,,,,,,,,,,,,,,,,
sample offset = 25.21 mm touchdown = 3.04000009782612 mm,3859058756.21872,190.063640695937,-0.042,9.32566515373613E-7,2.07119737672754E-6,32.0419318901257,123.937901667316,9.3288928857641E-8,2.07191424463979E-7,7.90772979049546E-8,4.94934864750612E-8,2.98387578408657E-10,3.01574123291269E-10,9.99654006958008,10,,,,10,1,5,300,30,1,8.37594209609443E-8,5.25531824650013E-8,,,1.01752154615159E-9,1.61582520998763E-9,5,0.0605288855731487,1.18068885803223,0.135115901452131,,,189.6411,190.006164550781,190.085266113281,-0.042,-0.042,30.589479,1,1,3,0,17.9530000978261,1,,,32.2580642700195,37.1456527709961,,,,,,,,,,,,,,,,
,3859060071.12987,190.003298556551,-0.042,2.83241172383816E-7,2.02313090259064E-8,238.152424433571,3.87808423814422,2.83401903806426E-8,2.02427897264473E-9,-1.49540223329227E-8,-2.40737119463849E-8,2.56979273190919E-10,2.95797787213295E-10,9.99432849884033,998.400024414062,,,,10,1,5,29952,30,4,-1.4521840061275E-8,-2.46381888997119E-8,,,-4.72945145181029E-8,-2.77336713981354E-8,5,0.180019333958626,38.8118209838867,0.649012512493243,,,189.5642,189.990386962891,190.012771606445,-0.042,-0.042,30.589479,1,1,3,0,17.9530000978261,1,,,32.2580642700195,37.1456527709961,,,,,,,,,,,,,,,,
,3859061221.0228,190.005144212706,-0.042,2.50191491521798E-7,5.39291036793502E-9,-29.3540278669572,1.03871490690876,2.5015995241952E-8,5.39223053845468E-10,2.18041269382613E-8,-1.22629550437712E-8,5.27492259739647E-10,9.60126760941044E-10,10.0012607574463,9984,,,,10,1,5,299520,30,7,2.22523422813011E-8,-1.2188920257854E-8,,,-2.42278240788173E-7,4.46832872271857E-7,5,0.738028943538666,9.49375247955322,4.02597077565147,,,189.5221,189.994110107422,190.015487670898,-0.042,-0.042,30.97069,1,1,3,0,17.9530000978261,1,,,32.2580642700195,37.1456527709961,,,,,,,,,,,,,,,,
,3859062928.75884,180.027401389414,-0.042,5.56287774775539E-7,1.03874530981288E-7,113.7248292943,10.0457519708288,5.56491461893187E-8,1.03912565079415E-8,-2.23901303461587E-8,5.09461434721234E-8,1.48632769362716E-10,1.46821900456398E-10,9.99633979797363,98.9429168701172,,,,1,1,5,2968,30,2,-2.43029423355144E-8,5.34907762010331E-8,,,1.0175200277851E-8,-4.6430273144318E-9,5,0.066475048661232,14.3777885437012,0.12513315534438,,,179.5568,180.010482788086,180.045684814453,-0.042,-0.042,29.827055,1,1,3,0,18.082999923557,1,,,32.2580642700195,37.1456527709961,,,,,,,,,,,,,,,,
,3859064384.35281,180.000857479358,-0.042,4.5064017849324E-7,1.67069748178235E-8,-68.5152193787354,2.05282421507025,4.51182246396769E-8,1.67270713721168E-9,1.65247333418063E-8,-4.19831797583096E-8,5.11446883818017E-10,3.91139623808685E-10,9.98798561096191,1996.80004882813,,,,10,1,5,59904,30,5,1.71624315169621E-8,-4.18263281772794E-8,,,-1.6024174334345E-7,6.64240035734674E-8,5,0.261212468147278,24.5293769836426,1.20316214987985,,,179.5486,179.989715576172,180.011093139648,-0.042,-0.042,30.97069,1,1,3,0,18.082999923557,1,,,32.2580642700195,37.1456527709961,,,,,,,,,,,,,,,,
,3859066322.26964,170.019623,-0.042,,,,,,,,,,,,,,,,,3,,,,,,,,,,,,,,,,,,,,,,30.208265,1,1,3,,18.1630000670552,2,,,33.2355842590332,37.1456527709961,,,,,,,,,,,,,,,,
,3859067222.05536,170.010086933999,-0.042,3.74077786826266E-7,3.14173221851474E-8,176.400195445149,2.4247957507041,3.74398564404869E-8,3.14442630324568E-9,-3.73659854550961E-8,2.35074057560894E-9,1.46626617495949E-10,2.70755091023174E-10,9.99143218994141,499.200012207031,,,,1,1,5,14976,30,3,-3.82127339668647E-8,1.29730714798704E-9,,,1.16388242095922E-9,-3.66119562126112E-8,5,0.121965706348419,40.6969566345215,0.337736084830907,,,169.5463,169.999267578125,170.018890380859,-0.042,-0.042,30.97069,1,1,3,0,18.1630000670552,1,,,32.2580642700195,37.6344108581543,,,,,,,,,,,,,,,,
,3859068651.7621,170.001824076717,-0.042,4.61975857439105E-7,8.07392081417873E-9,-24.3440497830115,0.840172776803055,4.62449343018276E-8,8.08219588962114E-10,4.21331413206366E-8,-1.90628526468525E-8,4.35597438052694E-10,6.54289340699331E-10,9.98976135253906,4992,,,,10,1,5,150016,30,6,4.24615256141418E-8,-1.86913217170532E-8,,,-1.78323778959705E-7,4.12387087802379E-7,5,0.370156198740006,11.5497217178345,2.42027856614248,,,169.5371,169.990768432617,170.011596679687,-0.042,-0.042,30.208265,1,1,3,0,18.1630000670552,1,,,32.2580642700195,37.1456527709961,,,,,,,,,,,,,,,,
sample offset = 25.21 mm touchdown = 3.28000006265938 mm,3859070306.98314,160.07197252233,-0.042,8.95282457516437E-7,2.05503886447771E-6,70.1854078280562,119.921668197066,8.95592326229774E-8,2.05575013972213E-7,3.03585678332198E-8,8.42568306259639E-8,3.0323005935482E-10,2.91847282667542E-10,9.99654006958008,10,,,,10,1,5,300,30,1,3.20484877693875E-8,8.93513224834928E-8,,,1.72596487848495E-9,6.16761564099767E-10,5,0.0603771544992924,1.31212902069092,0.144910795842672,,,159.61,160.000686645508,160.104110717773,-0.042,-0.042,29.827055,1,1,3,0,18.1930000626594,1,,,32.2580642700195,37.1456527709961,,,,,,,,,,,,,,,,
,3859071702.82879,160.00100545306,-0.042,4.804686137061E-7,1.92363963158517E-8,261.315795433639,1.85574250904266,4.80741266170959E-8,1.92473124313292E-9,-7.25863085433796E-9,-4.75229831567529E-8,2.69958906611801E-10,2.54872554701445E-10,9.99432849884033,998.400024414062,,,,1,1,5,29952,30,4,-6.34056304069974E-9,-4.79209344486994E-8,,,-9.19170869373991E-8,-1.18557677592889E-8,5,0.206677302718163,35.1957702636719,0.582420619083413,,,159.5527,159.989852905273,160.011520385742,-0.042,-0.042,30.589479,1,1,3,0,18.1930000626594,1,,,32.2580642700195,37.1456527709961,,,,,,,,,,,,,,,,
,3859072856.83899,160.0048981817,-0.042,3.68207993078619E-7,1.22749216228651E-8,-17.4522605084229,1.87732527765003,3.68161576833676E-8,1.22733742480676E-9,3.51214057973732E-8,-1.10415724144175E-8,2.2149550232189E-9,1.14394986377007E-9,10.0012607574463,9984,,,,10,1,5,299520,30,7,3.57293408858235E-8,-1.08148048967163E-8,,,-2.14803817328652E-7,7.16378467796854E-7,5,0.750412821769714,8.61069107055664,4.02328726288556,,,159.5323,159.964385986328,160.01579284668,-0.042,-0.042,29.827055,1,1,3,0,18.1930000626594,1,,,32.2580642700195,37.6344108581543,,,,,,,,,,,,,,,,
,3859074478.53449,150.038987483125,-0.042,8.17352681179915E-7,1.01349828187163E-7,118.909734627631,6.85658654789021,8.17651958315384E-8,1.01386937854702E-8,-3.95278401032874E-8,7.15758136952614E-8,1.43612347615994E-10,1.43978605799266E-10,9.99633979797363,98.9429168701172,,,,1,1,5,2968,30,2,-4.28060657476433E-8,7.47612356041175E-8,,,1.4213294225947E-8,-8.17002915764765E-9,5,0.0678711012005806,17.4015960693359,0.131815148720278,,,149.565,150.01481628418,150.072631835938,-0.042,-0.042,30.589479,1,1,3,0,18.3430000406802,1,,,31.7693061828613,36.6568908691406,,,,,,,,,,,,,,,,
,3859075971.19748,149.999403233542,-0.042,4.7479020116987E-7,1.20344118483683E-8,-43.9546154282766,1.4486549714779,4.75361318751584E-8,1.204888785098E-9,3.42207774474071E-8,-3.29942756330168E-8,3.60833302894492E-10,2.90683358282788E-10,9.98798561096191,1996.80004882813,,,,1,1,5,59904,30,5,3.46467281144412E-8,-3.25993393988819E-8,,,-1.24278780375347E-7,1.33763050511183E-7,5,0.273577660322189,19.5802478790283,1.10785647187246,,,149.5726,149.988143920898,150.009460449219,-0.042,-0.042,30.208265,1,1,3,0,18.3430000406802,1,,,32.2580642700195,37.1456527709961,,,,,,,,,,,,,,,,
,3859077901.37279,139.953995,-0.042,,,,,,,,,,,,,,,,,3,,,,,,,,,,,,,,,,,,,,,,30.589479,1,1,3,,18.3229998883903,2,,,33.2355842590332,37.1456527709961,,,,,,,,,,,,,,,,
,3859079135.64863,140.002566346427,-0.042,3.13537080368662E-7,3.30839742611756E-8,222.093291504942,5.84610319597382,3.13805943340442E-8,3.31123442888217E-9,-2.32861059979822E-8,-2.10356594431595E-8,1.68347785089818E-10,2.74096898109131E-10,9.99143218994141,499.200012207031,,,,10,1,5,14976,30,3,-2.3036452715906E-8,-2.19265658739582E-8,,,-2.1033951400096E-8,-2.20291632043136E-8,5,0.15337061882019,42.1028671264648,0.389514848006582,,,139.5923,139.9931640625,140.010192871094,-0.042,-0.042,30.208265,1,1,3,0,18.3229998883903,1,,,32.2580642700195,37.1456527709961,,,,,,,,,,,,,,,,
,3859080292.74509,140.000064695502,-0.042,6.34989271447151E-7,8.35516817764816E-9,-11.6077945275871,0.67415315681656,6.35640080917207E-8,8.36373150748447E-10,6.22639897430572E-8,-1.27897891288638E-8,6.46290036518026E-10,4.93018436385146E-10,9.98976135253906,4992,,,,10,1,5,150016,30,6,6.25517098807313E-8,-1.2243125758501E-8,,,-1.15081994730661E-7,6.06320554728588E-7,5,0.386232227087021,9.6427059173584,2.4098128663554,,,139.6026,139.988632202148,140.010528564453,-0.042,-0.042,30.589479,1,1,3,0,18.3229998883903,1,,,32.2580642700195,37.1456527709961,,,,,,,,,,,,,,,,
sample offset = 25.21 mm touchdown = 3.65000008605421 mm,3859081899.32732,130.074506397425,-0.042,8.01851202299102E-7,2.83221713697906E-6,43.0037048422066,180,8.02128733259592E-8,2.83319740356729E-7,5.8660444380691E-8,5.47088412623247E-8,4.33325618091835E-10,3.8570669133675E-10,9.99654006958008,10,,,,10,1,5,300,30,1,6.20519687673477E-8,5.8109900543613E-8,,,1.1246355120778E-9,1.19620019301372E-9,5,0.06209821626544,1.6226019859314,0.125455182699885,,,129.697,129.956695556641,130.119842529297,-0.042,-0.042,30.208265,1,1,3,0,18.5630000860542,1,,,32.2580642700195,37.1456527709961,,,,,,,,,,,,,,,,
,3859083383.19188,129.998634272228,-0.042,6.37532490361988E-7,1.56508227974053E-8,-47.7730283589095,1.39843236687211,6.37894272172425E-8,1.56597042004586E-9,4.28709121352405E-8,-4.72353248892856E-8,2.400280576704E-10,1.81693931319831E-10,9.99432849884033,998.400024414062,,,,1,1,5,29952,30,4,4.37011308552894E-8,-4.66477866792872E-8,,,-8.92156152641324E-8,8.40315741660198E-8,5,0.241934254765511,28.5849380493164,0.58958569134594,,,129.6162,129.989181518555,130.007339477539,-0.042,-0.042,30.208265,1,1,3,0,18.5630000860542,1,,,32.2580642700195,37.6344108581543,,,,,,,,,,,,,,,,
,3859084658.36464,130.003250475385,-0.042,5.64496352530121E-7,6.3101710252494E-9,-9.5092180434585,0.35941116950264,5.64425192203726E-8,6.30937556602677E-10,5.56669445423161E-8,-9.32465877471301E-9,5.46192146499641E-10,1.15900184291484E-9,10.0012607574463,9984,,,,10,1,5,299520,30,7,5.65269206500171E-8,-8.90830443925458E-9,,,-1.77420286121439E-7,1.13251755095388E-6,5,0.771504342556,7.63412475585938,4.04891480980007,,,129.6042,129.988433837891,130.012924194336,-0.042,-0.042,30.208265,1,1,3,0,18.5630000860542,1,,,32.2580642700195,37.1456527709961,,,,,,,,,,,,,,,,
,3859086530.36242,120.01540195181,-0.042,5.85526173942464E-7,1.07170693621401E-7,66.6587522910212,9.57671091070278,5.85740566823426E-8,1.07209934623396E-8,2.32074276827614E-8,5.37804371177446E-8,1.48345872256961E-10,1.54149305125932E-10,9.99633979797363,98.9429168701172,,,,10,1,5,2968,30,2,2.31885428228241E-8,5.68893426922485E-8,,,1.08294758060051E-8,4.38637210740613E-9,5,0.0742324143648148,23.1472187042236,0.174832196126469,,,119.6093,119.997032165527,120.048767089844,-0.042,-0.042,29.445843,1,1,3,0,18.493000018701,1,,,32.2580642700195,37.1456527709961,,,,,,,,,,,,,,,,
,3859087810.38001,119.997860935756,-0.042,8.55663659153003E-7,1.41878437873484E-8,-16.1671917697932,0.872830176273552,8.56692923359745E-8,1.42049101189904E-9,8.22813529727277E-8,-2.38538592752632E-8,4.26886459878883E-10,3.39642721585737E-10,9.98798561096191,1996.80004882813,,,,1,1,5,59904,30,5,8.24690593968423E-8,-2.30413430943942E-8,,,-8.64313187656056E-8,3.17033740349253E-7,5,0.298905164003372,14.6343307495117,1.11981161442215,,,119.6404,119.989250183105,120.006645202637,-0.042,-0.042,30.208265,1,1,3,0,18.493000018701,1,,,32.2580642700195,37.1456527709961,,,,,,,,,,,,,,,,
,3859089665.46218,109.939812,-0.042,,,,,,,,,,,,,,,,,3,,,,,,,,,,,,,,,,,,,,,,30.208265,1,1,3,,18.7329999835342,2,,,33.2355842590332,37.6344108581543,,,,,,,,,,,,,,,,
,3859090916.74046,109.997210561629,-0.042,5.84952844643262E-7,3.55413850406808E-8,-48.0685390722988,3.47272939812672,5.85454450896586E-8,3.55718623366739E-9,3.9122475778866E-8,-4.35545753013191E-8,2.33161971887199E-10,2.51430366956886E-10,9.99143218994141,499.200012207031,,,,1,1,5,14976,30,3,4.01996654562168E-8,-4.29891512449178E-8,,,-4.11400665976672E-8,3.85624789011681E-8,5,0.206298500299454,37.7051124572754,0.345451230621683,,,109.6839,109.988998413086,110.003684997559,-0.042,-0.042,30.589479,1,1,3,0,18.7329999835342,1,,,32.2580642700195,37.1456527709961,,,,,,,,,,,,,,,,
,3859092072.22851,109.998988094965,-0.042,9.02074018665671E-7,3.80897999347471E-9,-3.79249489748882,0.14260011457619,9.02998567064261E-8,3.81288387085103E-10,9.0102112740527E-8,-5.97272139769288E-9,2.0217729147067E-10,3.10405532635245E-10,9.98976135253906,4992,,,,10,1,5,150016,30,6,9.03495040853321E-8,-5.2403976784871E-9,,,-4.64622349139387E-8,8.75180493502557E-7,5,0.398291051387787,7.99977207183838,2.40632429975971,,,109.698,109.981178283691,110.007095336914,-0.042,-0.042,29.445843,1,1,3,0,18.7329999835342,1,,,32.7468223571777,37.1456527709961,,,,,,,,,,,,,,,,
sample offset = 25.21 mm touchdown = 3.77999991178513 mm,3859093632.92874,100.069595833382,-0.042,1.60787472471183E-6,2.0113056131178E-6,-21.2660755031585,66.0182094490303,1.60843123072619E-7,2.01200175172437E-7,1.49890694481823E-7,-5.83377231944339E-8,2.96695752763871E-10,2.85637786059265E-10,9.99654006958008,10,,,,10,1,5,300,30,1,1.59034930790487E-7,-6.12807721834885E-8,,,-1.17959175616406E-9,3.0725874652678E-9,5,0.0646474882960319,3.0543327331543,0.122503289539399,,,99.7612,99.9811706542969,100.103012084961,-0.042,-0.042,29.445843,1,1,3,0,18.6929999117851,1,,,32.2580642700195,37.1456527709961,,,,,,,,,,,,,,,,
,3859094840.24783,99.9997699367672,-0.042,1.00935445085795E-6,1.56605821895134E-8,-17.0138857931117,0.852043404597903,1.00992723120425E-7,1.5669469130748E-9,9.65726625496101E-8,-2.95508201469592E-8,2.52107906117978E-10,1.63174331671219E-10,9.99432849884033,998.400024414062,,,,10,1,5,29952,30,4,9.67795503733098E-8,-2.84880176853279E-8,,,-5.4424590223508E-8,1.85629909685154E-7,5,0.279852688312531,19.2424411773682,0.658539041048204,,,99.6904,99.9908065795898,100.00806427002,-0.042,-0.042,30.208265,1,1,3,0,18.6929999117851,1,,,32.2580642700195,37.1456527709961,,,,,,,,,,,,,,,,
,3859096019.86692,100.002456939873,-0.042,9.27217033708045E-7,7.28454196880157E-9,-3.90802569497568,0.211267710381892,9.27100148866431E-8,7.28362368052245E-10,9.24944401661137E-8,-6.31865481244152E-9,6.1344080799501E-10,1.3454466961601E-9,10.0012607574463,9984,,,,10,1,5,299520,30,7,9.37975776769439E-8,-5.63615775151197E-9,,,-1.14312662880645E-7,1.87892736551898E-6,5,0.808804094791412,6.19993495941162,4.19597270703525,,,99.6841,99.9892807006836,100.010353088379,-0.042,-0.042,29.445843,1,1,3,0,18.6929999117851,1,,,32.7468223571777,37.1456527709961,,,,,,,,,,,,,,,,
,3859097270.97874,100.01088,-0.042,,,,,,,,,,,,,,,,,3,,,,,,,,,,,,,,,,,,,,,,30.589479,1,1,3,,18.6929999117851,2,,,33.2355842590332,37.1456527709961,,,,,,,,,,,,,,,,
,3859098332.95038,99.9975129280996,-0.042,1.05272884787698E-6,1.08095824536854E-8,-6.66574624086947,0.501048890545383,1.05399515866503E-7,1.08225851284985E-9,1.04687038599474E-7,-1.2234455205094E-8,3.28638591976642E-10,2.53777457996862E-10,9.98798561096191,1996.80004882813,,,,10,1,5,59904,30,5,1.0463462221017E-7,-1.13827266804833E-8,,,-4.26949394431168E-8,4.0162610495135E-7,5,0.311317533254623,11.2875518798828,1.22919245665307,,,99.7049,99.990234375,100.00358581543,-0.042,-0.042,30.208265,1,1,3,0,18.6929999117851,1,,,32.2580642700195,37.6344108581543,,,,,,,,,,,,,,,,
sample offset = 25.21 mm,3859099930.13429,95.0538044805112,-0.042,8.92750749626136E-7,2.13789795005507E-6,-11.3858790392014,113.739782914268,8.9305974208298E-8,2.13863790388916E-7,8.75484200380422E-8,-1.76304049339688E-8,3.09257869052702E-10,3.09686539665361E-10,9.99654006958008,10,,,,10,1,5,300,30,1,9.28308817339731E-8,-1.83330003717826E-8,,,-3.49590783589446E-10,1.79320369894921E-9,5,0.0666632056236267,4.09441995620728,0.152558865461491,,,94.7927,94.9982757568359,95.0791244506836,-0.042,-0.042,30.589479,1,1,3,0,18.6929999117851,1,,,32.2580642700195,37.1456527709961,,,,,,,,,,,,,,,,
,3859100960.05434,94.997459,-0.042,,,,,,,,,,,,,,,,,3,,,,,,,,,,,,,,,,,,,,,,30.208265,1,1,3,,18.6029999249726,2,,,33.7243423461914,37.1456527709961,,,,,,,,,,,,,,,,
,3859102159.32199,95.0003939130372,-0.042,1.10575615761341E-6,1.20882909906578E-8,-2.40734183010755,0.159699406480002,1.1068894627121E-7,1.21006804507751E-9,1.10591258404409E-7,-4.64934308909436E-9,2.65633011628679E-10,1.14470790335092E-9,9.98976135253906,4992,,,,10,1,5,150016,30,6,1.10826409343205E-7,-3.79489190046275E-9,,,-3.1985312167289E-8,1.07334819563091E-6,5,0.416366338729858,7.16389322280884,2.4131672573128,,,94.7113,94.9922943115234,95.0077896118164,-0.042,-0.042,29.445843,1,1,3,0,18.6029999249726,1,,,31.2805480957031,36.1681327819824,,,,,,,,,,,,,,,,
,3859103906.72232,90.0155024666318,-0.042,5.85100740552587E-7,1.07548911349697E-7,100.964242333855,8.77411993984628,5.85314977659316E-8,1.0758829083771E-8,-1.11324763877685E-8,5.74630681411899E-8,1.46810393342523E-10,1.52981801630548E-10,9.99633979797363,98.9429168701172,,,,10,1,5,2968,30,2,-1.31312672764637E-8,5.92229079406693E-8,,,1.12532147141478E-8,-2.51528634204434E-9,5,0.0910304039716721,34.3146209716797,0.183016968298471,,,89.6942,90.000862121582,90.0333557128906,-0.042,-0.042,29.064632,1,1,3,0,18.6029999249726,1,,,32.2580642700195,37.1456527709961,,,,,,,,,,,,,,,,
,3859104936.00355,89.996445,-0.042,,,,,,,,,,,,,,,,,3,,,,,,,,,,,,,,,,,,,,,,30.208265,1,1,3,,18.713000064075,2,,,33.2355842590332,37.1456527709961,,,,,,,,,,,,,,,,
,3859105867.96023,90.0043776587617,-0.042,1.01272598740412E-6,8.40442081586689E-9,-3.26014584095552,0.308378017271762,1.0125983233165E-7,8.40336135582657E-10,1.01095955022971E-7,-5.75860415616445E-9,1.03977944420351E-9,1.35193966026775E-9,10.0012607574463,9984,,,,10,1,5,299520,30,7,1.024726839103E-7,-5.00174807621819E-9,,,-1.02864285694615E-7,2.05285107745912E-6,5,0.834964096546173,5.43865585327148,4.03777823182151,,,89.6963,89.9912109375,90.0115051269531,-0.042,-0.042,29.445843,1,1,3,0,18.713000064075,1,,,32.2580642700195,37.1456527709961,,,,,,,,,,,,,,,,
,3859107486.44953,85.0027734493387,-0.042,1.10564800649171E-6,3.15317397989598E-8,-19.5101184665043,1.58900203916621,1.10659611702594E-7,3.15587787611704E-9,1.04305816315536E-7,-3.69573584678138E-8,2.55880748190183E-10,1.61317726479825E-10,9.99143218994141,499.200012207031,,,,1,1,5,14976,30,3,1.04690010856991E-7,-3.56514046103373E-8,,,-3.40656043416453E-8,1.00350546903816E-7,5,0.270953506231308,25.9815692901611,0.342163904189053,,,84.713,84.9959869384766,85.0116729736328,-0.042,-0.042,29.827055,1,1,3,0,18.713000064075,1,,,32.2580642700195,37.1456527709961,,,,,,,,,,,,,,,,
,3859108675.76685,84.995705,-0.042,,,,,,,,,,,,,,,,,3,,,,,,,,,,,,,,,,,,,,,,29.064632,1,1,3,,18.6530000728667,2,,,33.2355842590332,37.1456527709961,,,,,,,,,,,,,,,,
,3859109226.39453,85.0049462222228,-0.042,1.14406013714758E-6,5.37375395781167E-9,-2.48592782120553,0.135547188714336,1.14391591709654E-7,5.37307654318554E-10,1.14283938311891E-7,-4.96162249590998E-9,5.13996472097223E-10,9.61358795437672E-10,10.0012607574463,9984,,,,10,1,5,299520,30,7,1.15790819364959E-7,-4.0891161092054E-9,,,-8.55054015205846E-8,2.31959867536417E-6,5,0.842835068702698,4.96878004074097,4.02999604480035,,,84.7047,84.9931488037109,85.0110702514648,-0.042,-0.042,29.064632,1,1,3,0,18.6530000728667,1,,,32.2580642700195,36.6568908691406,,,,,,,,,,,,,,,,