File: DataFailid_Testimiseks/BaCu2PO4H2O__ACMSII_AllCrystalsRandomlyOriented_2-100K_04052022.dat
[Header]
; ACMS II Data File (default extension .dat)
; Copyright (c) 2014, Quantum Design, Inc. All rights reserved.
TITLE,BaCu2PO4H2O__ACMSII_AllCrystalsRandomlyOriented_2-100K_04052022
FILEOPENTIME,3860816882.726,05/04/2022,10:07 am
BYAPP,ACMS II,1.0,1.2
INFO,PPMS ACMS II Option Release 1.0.8 Build 33,APPNAME
INFO,Quantum Design Linear Motor Servo Controller,MOTOR_MODULE_NAME
INFO,3101-100 C1,MOTOR_HW_VERSION
INFO,074,MOTOR_SERIAL_NUMBER
INFO,SRV No X-over 01.01.11,MOTOR_SOFTWARE_VERSION
INFO,ACMS,ACMS_MODULE_NAME
INFO,3101-430 D0,ACMS_HW_VERSION
INFO,ACMSII183,ACMS_SERIAL_NUMBER
INFO,00.14.14,ACMS_SOFTWARE_VERSION
INFO,WF181,COIL_SERIAL_NUMBER
INFO,0,MOMENT_UNITS
INFO,BaCu2PO4H2O__ACMSII_AllCrystalsRandomlyOriented_2-100K_04052022,SAMPLE_MATERIAL
INFO,all crystals randomly in powder capsule,SAMPLE_COMMENT
INFO,12.6,SAMPLE_MASS
INFO,,SAMPLE_VOLUME
INFO,,SAMPLE_MOLECULAR_WEIGHT
INFO,,SAMPLE_SIZE
INFO,,SAMPLE_SHAPE
DATATYPE,COMMENT,1
DATATYPE,TIME,2
STARTUPAXIS,X,2
STARTUPAXIS,Y1,5
STARTUPGROUP, AC
FIELDGROUP, AC, 2,3,4,5,6,7,8,9,10,11,12,13,14,15,16,20,21,22,23,24,25,35,43,44,45,46,47,48,49
FIELDGROUP, DC, 2,3,4,17,18,19,20,21,23,24,25,35,36,37,43,44,45,46,47,48,49,50,51
FIELDGROUP, Diagnostic, 26,27,28,29,30,31,32,33,34,38,39,40,41,42,52,53,54,55,56,57,58,59,60,61,62,63,64,65,66,67,68,69
[Data]
Comment,Time Stamp (sec),Temperature (K),Magnetic Field (Oe),AC Moment (emu),AC Std. Dev. (emu),AC Phase (deg),AC Phase Std. Dev. (deg),AC Suscept. (emu/Oe),AC Suscept. Std. Dev. (emu/Oe),AC X'  (emu/Oe),AC X" (emu/Oe),AC X' Std. Dev. (emu/Oe),AC X" Std. Dev. (emu/Oe),AC Drive (Oe),AC Frequency (Hz),DC Moment (emu),DC Std. Err. (emu),DC Quad. Moment (emu),Range (mV),"AC=1 DC=2 Locate=3",Measure Type,Measure Count,Measure Time (sec),Measure Number,AC X' Raw (emu/Oe),AC X" Raw (emu/Oe),DC M. Raw' (emu),DC M. Raw" (emu),Coil InPhase (V),Coil Quadrature (V),Null Status,Trim Ratio,Trim Phase (deg.),Max. Signal (mV),Motor Frequency (Hz),Motor Ampl. (mm),System Temp. (K),Min. Temperature (K),Max. Temperature (K),Min. Field (Oe),Max. Field (Oe),Pressure (Torr),Temp. Status (code),Field Status (code),Chamber Status (code),Measure Status (code),Center Position (mm),Transport Action,Motor Lag (deg),Motor Current (amps),Motor Heatsink Temp. (C),Motor Board Temp. (C),QMap 01,QMap 02,QMap 03,QMap 04,QMap 05,QMap 06,QMap 07,QMap 08,QMap 09,QMap 10,QMap 11,QMap 12,QMap 13,QMap 14,QMap 15,QMap 16
sample offset = 26.65 mm touchdown = 5.28000015765429 mm,3860817286.11087,2.00303957356166,-0.042,1.45625471722277E-6,9.49047610198784E-8,-0.784405669667074,2.6413019781808,1.45678793103649E-7,9.49395107988592E-9,1.45665141120636E-7,-1.99434762290082E-9,1.26195206771678E-10,1.28453263844755E-10,9.99633979797363,98.9429168701172,,,,10,1,5,5000,50.5050506591797,1,1.45133491551982E-7,-1.42451892064821E-9,,,-2.55076455802821E-10,2.76194472864282E-8,5,0.315165758132935,7.19538068771362,0.143837376177317,,,1.95,1.96274745464325,2.04749512672424,-0.042,-0.042,0.074215,1,1,3,0,18.7530001576543,1,,,30.7917900085449,35.6793746948242,,,,,,,,,,,,,,,,
sample offset = 26.65 mm,3860820080.4052,4.00294603096942,-0.042,1.41281654208774E-6,9.26317913527583E-8,-1.85495538478098,2.70804774820678,1.41333385083022E-7,9.26657088742979E-9,1.41259322559887E-7,-4.57488021126985E-9,1.23254418374858E-10,1.25298030179529E-10,9.99633979797363,98.9429168701172,,,,10,1,5,5000,50.5050506591797,1,1.40753950278869E-7,-4.01250845294246E-9,,,-7.47170376702903E-10,2.67864746429786E-8,5,0.315171509981155,7.16995859146118,0.152961392376379,,,3.984,3.99762749671936,4.01682615280151,-0.042,-0.042,0.115184,1,1,3,0,18.7530001576543,1,,,30.7917900085449,36.1681327819824,,,,,,,,,,,,,,,,
,3860822206.74711,4.09351534256037,-0.042,1.34613494186023E-6,3.20393414253185E-9,2.17090842250564,0.11071910316068,1.34596524828931E-7,3.2035302550695E-10,1.34499922046307E-7,5.0985748560101E-9,4.95863706486872E-10,3.97240705198964E-10,10.0012607574463,9984,,,,10,1,5,299520,30,6,1.33104470023252E-7,7.53444566516774E-9,,,1.38839883105505E-7,2.66618861913617E-6,5,0.735283136367798,340.425048828125,3.95552809965851,,,3.6865,3.86692142486572,4.25028991699219,-0.042,-0.042,0.111783,6,1,3,0,18.7530001576543,1,,,30.7917900085449,36.1681327819824,,,,,,,,,,,,,,,,
touchdown = 5.26000000536442 mm,3860824686.46457,6.01404146514187,-0.042,1.40569766930608E-6,2.02024810077479E-9,0.109454535702795,0.0630232870005559,1.40713838869514E-7,2.02231868157822E-10,1.40713582108581E-7,2.68811396989892E-10,1.45433403043702E-10,1.28076903118552E-10,9.98976135253906,4992,,,,10,1,5,150016,30,5,1.38957414756138E-7,2.81254931198596E-9,,,3.07479698218263E-8,1.34666799777763E-6,5,0.491263389587402,348.774597167969,2.35855730663874,,,5.9032,5.96170568466186,6.05508804321289,-0.042,-0.042,0.15236,5,1,3,0,18.7330000053644,1,,,29.8142719268799,34.7018585205078,,,,,,,,,,,,,,,,
,3860827707.2333,8.01420347794243,-0.042,1.42970694782113E-6,2.49266472277672E-9,0.10228398640034,0.0630530625841463,1.43117227465874E-7,2.49521949004634E-10,1.43116999414953E-7,2.55491641737967E-10,1.46684931380244E-10,1.88834265544597E-10,9.98976135253906,4992,,,,10,1,5,150016,30,5,1.41326421866554E-7,2.83607426650784E-9,,,3.10570435451281E-8,1.36971173377531E-6,5,0.491859287023544,348.744323730469,2.3598990630217,,,7.928,8.00113868713379,8.03628730773926,-0.042,-0.042,0.161771,1,1,3,0,18.7330000053644,1,,,29.3255138397217,34.2131004333496,,,,,,,,,,,,,,,,
,3860830181.46259,10.0028780392238,-0.042,1.52392289641227E-6,5.02868557683279E-9,0.124753208590602,0.134210215678525,1.52575599902722E-7,5.03473450273472E-10,1.52575238232209E-7,3.32210867229754E-10,1.34033723162108E-10,1.37461313194827E-10,9.98798561096191,1996.80004882813,,,,1,1,5,59904,30,4,1.51230703058202E-7,1.81518760897523E-9,,,9.6011988031615E-9,5.81043492427499E-7,5,0.395332604646683,0.251250326633453,1.06788517651402,,,9.9863,9.9929666519165,10.0099811553955,-0.042,-0.042,0.182374,1,1,3,0,18.7330000053644,1,,,29.8142719268799,34.7018585205078,,,,,,,,,,,,,,,,
,3860832998.67447,12.0012103134575,-0.042,1.62424209332482E-6,9.70361374591859E-9,0.232333253371117,0.247958249598557,1.62516380516538E-7,9.70912027460826E-10,1.62515044400942E-7,6.58998904590054E-10,1.32917772337294E-10,1.29318225824828E-10,9.99432849884033,998.400024414062,,,,1,1,5,29952,30,3,1.61553613712804E-7,1.39440229869772E-9,,,3.42096461043713E-9,3.10214929431539E-7,5,0.366329073905945,2.70205879211426,0.553505582675599,,,11.9876,11.9968194961548,12.0027074813843,-0.042,-0.042,0.222707,1,1,3,0,18.7129998530746,1,,,29.8142719268799,35.190616607666,,,,,,,,,,,,,,,,
,3860835803.16127,14.0010883680842,-0.042,1.73753988486541E-6,9.77401027143179E-9,0.200095237475643,0.223289139332772,1.73852589002555E-7,9.77955674817562E-10,1.73851528824123E-7,6.0714776316171E-10,1.28055730446205E-10,1.36039205618222E-10,9.99432849884033,998.400024414062,,,,1,1,5,29952,30,3,1.72825298064692E-7,1.35309750953861E-9,,,3.38068200073409E-9,3.31922357600526E-7,5,0.366189450025558,2.69733238220215,0.548031170044364,,,13.9946,13.9977216720581,14.0020971298218,-0.042,-0.042,0.277448,1,1,3,0,18.7129998530746,1,,,30.3030319213867,34.7018585205078,,,,,,,,,,,,,,,,
,3860838284.21427,16.0008400792661,-0.042,1.80153657410796E-6,1.90848612474228E-8,-0.0533085332669256,0.415653719046648,1.80308142002065E-7,1.91012268157471E-9,1.80308063959144E-7,-1.67760370503997E-10,1.24847797933381E-10,1.33424299452972E-10,9.99143218994141,499.200012207031,,,,1,1,5,14976,30,2,1.79531111257405E-7,1.83033713501714E-10,,,3.6616960534395E-10,1.72338636991402E-7,5,0.344894021749496,3.9311785697937,0.319152619160639,,,15.9952,15.9994316101074,16.0019187927246,-0.042,-0.042,0.26393,1,1,3,0,18.6429997857213,1,,,29.8142719268799,34.7018585205078,,,,,,,,,,,,,,,,
sample offset = 26.65 mm touchdown = 5.16000017523766 mm,3860840611.76183,18.0019796986979,-0.042,1.870955635662E-6,7.88394057952425E-8,0.00327909383203368,1.70313616572858,1.87164069396807E-7,7.88682731765722E-9,1.8716406909029E-7,1.0711583827256E-11,1.05151279595343E-10,1.06567795749622E-10,9.99633979797363,98.9429168701172,,,,10,1,5,5000,50.5050506591797,1,1.86474667557725E-7,7.19226685902321E-10,,,1.5292110879403E-10,3.55150019170976E-8,5,0.315344721078873,7.2721381187439,0.140885497575819,,,17.9951,17.9989452362061,18.0045337677002,-0.042,-0.042,0.27469,1,1,3,0,18.6330001752377,1,,,29.8142719268799,34.7018585205078,,,,,,,,,,,,,,,,
sample offset = 26.65 mm,3860843410.83193,20.0018296369965,-0.042,1.86526532183839E-6,9.54066670696679E-8,0.216189117182008,2.04026213257446,1.86594829661203E-7,9.54416006236681E-9,1.86593501375536E-7,7.04060161457871E-10,1.25080672463864E-10,1.3106490376085E-10,9.99633979797363,98.9429168701172,,,,10,1,5,5000,50.5050506591797,1,1.85917496735243E-7,1.42030121125618E-9,,,2.84345727427023E-10,3.54061943031233E-8,5,0.314724743366241,7.39321041107178,0.139007024080688,,,19.9981,19.9997806549072,20.004150390625,-0.042,-0.042,0.283047,1,1,3,0,18.6330001752377,1,,,31.2805480957031,35.6793746948242,,,,,,,,,,,,,,,,
,3860845541.56459,20.0210709406461,-0.042,1.76580147539184E-6,5.50863173041042E-9,0.369772867515835,0.118403609653925,1.76557887872E-7,5.5079373131123E-10,1.76554210983678E-7,1.13945326917003E-9,7.11196369305742E-10,8.36376139414424E-10,10.0012607574463,9984,,,,10,1,5,299520,30,6,1.75518713504198E-7,3.86247622011827E-9,,,6.81820003423008E-8,3.5190345064707E-6,5,0.750256538391113,340.720184326172,3.96706720455195,,,19.9098,19.9981307983398,20.0424270629883,-0.042,-0.042,0.303549,1,1,3,0,18.6230000990927,1,,,30.7917900085449,35.6793746948242,,,,,,,,,,,,,,,,
touchdown = 5.10000018402934 mm,3860848231.78094,22.0086026880782,-0.042,1.85676912791411E-6,3.31491927247732E-9,0.0960894115382646,0.0643207186862499,1.85867215681001E-7,3.31831678004478E-10,1.85866954297303E-7,3.11713413426827E-10,1.95427330707571E-10,2.51853809617285E-10,9.98976135253906,4992,,,,10,1,5,150016,30,5,1.83796481353033E-7,3.0532879139266E-9,,,3.58572711239011E-8,1.78339094443573E-6,5,0.49358919262886,350.193878173828,2.36003323866,,,21.9647,22.0002479553223,22.01682472229,-0.042,-0.042,0.300532,1,1,3,0,18.5730001840293,1,,,30.7917900085449,36.1681327819824,,,,,,,,,,,,,,,,
,3860851032.39063,24.0083244908063,-0.042,1.84408462608368E-6,3.62378405114467E-9,0.927526166447258,0.07543306925545,1.84597465445456E-7,3.62749811858481E-10,1.84573277814731E-7,2.98820441278666E-9,2.24358908615171E-10,2.66711859048566E-10,9.98976135253906,4992,,,,10,1,5,150016,30,5,1.825031207824E-7,5.71315187814254E-9,,,6.16604727312194E-8,1.77071567783911E-6,5,0.493936568498611,350.892944335937,2.35976488738341,,,23.9592,24.0029811859131,24.0149688720703,-0.042,-0.042,0.303549,1,1,3,0,18.5730001840293,1,,,30.7917900085449,35.6793746948242,,,,,,,,,,,,,,,,
,3860853507.22364,26.0019055938721,-0.042,1.88731305641713E-6,4.9476683404709E-9,0.592184205332605,0.1093975794325,1.88958327527603E-7,4.95361981202775E-10,1.88948234985978E-7,1.95295614715719E-9,1.34684202361055E-10,1.32678676783784E-10,9.98798561096191,1996.80004882813,,,,1,1,5,59904,30,4,1.87302148737213E-7,3.27639946020149E-9,,,1.65534879049404E-8,7.2012002873006E-7,5,0.385661005973816,0.788991093635559,1.07242040626594,,,25.9766,25.9981746673584,26.0034198760986,-0.042,-0.042,0.33544,1,1,3,0,18.5329998794496,1,,,30.7917900085449,35.6793746948242,,,,,,,,,,,,,,,,
touchdown = 5.04000019282103 mm,3860855995.34583,28.000706187599,-0.042,1.88495717201833E-6,9.88409761060386E-9,0.32796214455156,0.210309573261883,1.88602683235501E-7,9.88970655882557E-10,1.88599593517408E-7,1.07955949316321E-9,1.3071905881574E-10,1.36407124094636E-10,9.99432849884033,998.400024414062,,,,1,1,5,29952,30,3,1.87418523796797E-7,1.61699035466079E-9,,,4.06757574111097E-9,3.60072760904783E-7,5,0.358775228261948,2.99327087402344,0.550419496406031,,,27.991,27.9952487945557,28.0040950775146,-0.042,-0.042,0.325536,1,1,3,0,18.513000192821,1,,,30.7917900085449,35.6793746948242,,,,,,,,,,,,,,,,
,3860858801.17837,30.0010854217397,-0.042,1.86638929793251E-6,9.8607398587171E-9,0.386750661062808,0.215376900750231,1.86744842152134E-7,9.86633555206963E-10,1.86740587796064E-7,1.26053163613461E-9,1.32485271875334E-10,1.34086110771201E-10,9.99432849884033,998.400024414062,,,,1,1,5,29952,30,3,1.85545518303748E-7,1.7586383821409E-9,,,4.3588212051281E-9,3.56549852566227E-7,5,0.356773227453232,3.15388965606689,0.553438494856451,,,29.9881,29.9982490539551,30.0041999816895,-0.042,-0.042,0.325536,1,1,3,0,18.513000192821,1,,,30.7917900085449,35.190616607666,,,,,,,,,,,,,,,,
,3860861281.00199,32.0014329329781,-0.042,1.85528633071601E-6,1.90539742578316E-8,-0.186292681059183,0.420450627810579,1.85687726788935E-7,1.90703133400771E-9,1.8568674526896E-7,-6.03747846826658E-10,1.30268795994923E-10,1.27804709648138E-10,9.99143218994141,499.200012207031,,,,1,1,5,14976,30,2,1.84824944889498E-7,-3.89770368260117E-10,,,-1.77504159885162E-10,1.77542003926887E-7,5,0.333699256181717,5.04821491241455,0.331241914054242,,,31.9877,31.9991149902344,32.0035705566406,-0.042,-0.042,0.3223,1,1,3,0,18.5030001166761,1,,,30.3030319213867,35.190616607666,,,,,,,,,,,,,,,,
,3860863992.84578,33.99786,-0.042,,,,,,,,,,,,,,,,,3,,,,,,,,,,,,,,,,,,,,,,0.345645,1,1,3,,18.513000192821,2,,,31.2805480957031,35.190616607666,,,,,,,,,,,,,,,,
sample offset = 26.65 mm,3860866404.2457,36.006135377619,-0.042,1.84417826261657E-6,8.01851044575565E-8,-0.700177888960588,1.77973401803136,1.84485351627443E-7,8.02144645721336E-9,1.8447157642446E-7,-2.2544304327042E-9,1.09288115245641E-10,1.07742129955358E-10,9.99633979797363,98.9429168701172,,,,10,1,5,5000,50.5050506591797,1,1.84223702388997E-7,-8.57213417868344E-10,,,-1.1450693703923E-10,3.52828943397414E-8,5,0.305402964353561,12.4593667984009,0.150948743242952,,,35.9788,36.0008697509766,36.0149040222168,-0.042,-0.042,0.33544,1,1,3,0,18.513000192821,1,,,30.3030319213867,35.190616607666,,,,,,,,,,,,,,,,
,3860868534.02981,36.0136638652383,-0.042,1.71711295106784E-6,7.71672808282976E-9,-4.03724220166549,0.237891063634516,1.71689649206416E-7,7.71575531323327E-10,1.7126360097918E-7,-1.20877882288856E-8,1.39489708597519E-9,6.65573870341836E-10,10.0012607574463,9984,,,,10,1,5,299520,30,6,1.71216189108574E-7,-9.28313739135966E-9,,,-1.80609642000851E-7,3.43482071254704E-6,5,0.867642104625702,347.889251708984,3.96478621870092,,,35.9141,35.9948616027832,36.0218696594238,-0.042,-0.042,0.405552,1,1,3,0,18.513000192821,1,,,30.7917900085449,35.190616607666,,,,,,,,,,,,,,,,
,3860871349.32221,38.0128343886223,-0.042,1.68425551069329E-6,6.57175306862361E-9,-2.74278411135799,0.187183106133868,1.68404319369366E-7,6.57092463440742E-10,1.68211398913834E-7,-8.05853942786013E-9,1.08231239746084E-9,7.53322207718141E-10,10.0012607574463,9984,,,,10,1,5,299520,30,6,1.68398416536399E-7,-5.38841735416481E-9,,,-9.98649533523097E-8,3.37853531537054E-6,5,0.878106415271759,349.559997558594,3.9849125644453,,,37.9166,38.0016822814941,38.020450592041,-0.042,-0.042,0.342209,1,1,3,0,18.513000192821,1,,,30.7917900085449,35.190616607666,,,,,,,,,,,,,,,,
,3860873867.53774,40.0046893654531,-0.042,1.74361885555789E-6,3.76510653060674E-9,0.730430284819434,0.08939111315934,1.74540591514203E-7,3.76896544145148E-10,1.74526408359369E-7,2.22505534907413E-9,2.54786974196724E-10,2.60635439917135E-10,9.98976135253906,4992,,,,10,1,5,150016,30,5,1.73548854974451E-7,4.53454263645165E-9,,,5.62734861675443E-8,1.68524743063696E-6,5,0.477603793144226,358.429656982422,2.36942576628452,,,39.9373,39.9995613098145,40.008186340332,-0.042,-0.042,0.338807,1,1,3,0,18.513000192821,1,,,30.3030319213867,35.190616607666,,,,,,,,,,,,,,,,
,3860876350.97949,42.0014334554849,-0.042,1.77428207902696E-6,5.79926774866699E-9,0.772067446123969,0.136248394673872,1.77641633472085E-7,5.80624359560774E-10,1.77625505736002E-7,2.39366970575863E-9,1.57889426426263E-10,1.56619446384448E-10,9.98798561096191,1996.80004882813,,,,1,1,5,59904,30,4,1.76293925447754E-7,3.11374962161706E-9,,,1.71896340515812E-8,6.79375507926769E-7,5,0.364600390195847,2.89659643173218,1.07653959836163,,,41.9423,41.997730255127,42.0054512023926,-0.042,-0.042,0.332105,1,1,3,0,18.5030001166761,1,,,30.3030319213867,35.190616607666,,,,,,,,,,,,,,,,
,3860879266.714,44.0012855693272,-0.042,1.76747175717698E-6,6.21109200703112E-9,0.864543472976994,0.150807516068444,1.76959782084303E-7,6.21856323082242E-10,1.76939637201416E-7,2.67006785597103E-9,1.74152526600361E-10,1.61978931197421E-10,9.98798561096191,1996.80004882813,,,,1,1,5,59904,30,4,1.75665802242356E-7,3.3619444407061E-9,,,1.68712393600902E-8,6.75780917079608E-7,5,0.360978811979294,3.31277346611023,1.07362798701061,,,43.9373,43.9980735778809,44.0039901733398,-0.042,-0.042,0.342209,1,1,3,0,18.5030001166761,1,,,30.7917900085449,35.6793746948242,,,,,,,,,,,,,,,,
,3860881832.99772,46.0016685254646,-0.042,1.72871931862171E-6,1.04112795940988E-8,0.231210293757467,0.241439184564375,1.72970031835785E-7,1.04171877033127E-9,1.72968623489844E-7,6.97998066706475E-10,1.38069313602343E-10,1.43013331530749E-10,9.99432849884033,998.400024414062,,,,1,1,5,29952,30,3,1.71769408268424E-7,7.55364174812582E-10,,,2.3594176479021E-9,3.29874763441221E-7,5,0.333885967731476,5.62992858886719,0.569056632331618,,,45.9347,45.9992561340332,46.0052452087402,-0.042,-0.042,0.366996,1,1,3,0,18.4729998882413,1,,,30.3030319213867,34.7018585205078,,,,,,,,,,,,,,,,
,3860884470.47279,48.0026853205326,-0.042,1.72972778975112E-6,1.93094111883722E-8,0.465006798635595,0.464062950824359,1.73121105850318E-7,1.93259693117984E-9,1.73115404326035E-7,1.40501810326543E-9,1.32627838181234E-10,1.28362999820266E-10,9.99143218994141,499.200012207031,,,,1,1,5,14976,30,2,1.72207529630007E-7,1.55746156016053E-9,,,1.66600337756784E-9,1.65189573371561E-7,5,0.309885650873184,7.80558967590332,0.325848030100366,,,47.9321,48.0001029968262,48.0051612854004,-0.042,-0.042,0.434927,1,1,3,0,18.4930000405312,1,,,30.3030319213867,34.7018585205078,,,,,,,,,,,,,,,,
,3860887356.27061,50.0030867203422,-0.042,1.6953735792849E-6,1.99659656685293E-8,-0.0292313871316586,0.482540818062762,1.69682738876181E-7,1.9983086797736E-9,1.6968271679302E-7,-8.65694062743912E-11,1.362539197574E-10,1.33584542614989E-10,9.99143218994141,499.200012207031,,,,1,1,5,14976,30,2,1.68797075648594E-7,1.09110926530861E-10,,,2.46603593736828E-10,1.61887172243928E-7,5,0.307690024375916,8.28842926025391,0.331657881827341,,,49.9208,50.0006103515625,50.0063591003418,-0.042,-0.042,0.35616,1,1,3,0,18.4930000405312,1,,,30.3030319213867,35.6793746948242,,,,,,,,,,,,,,,,
sample offset = 26.65 mm,3860889750.91499,52.0163830816746,-0.042,1.84296535379433E-6,8.17224397062598E-8,5.91240553565772,1.96953427145553,1.8436401633405E-7,8.17523627226295E-9,1.83383298848877E-7,1.8990951058999E-8,1.08337877387892E-10,1.12614843752293E-10,9.99633979797363,98.9429168701172,,,,10,1,5,5000,50.5050506591797,1,1.8387584423925E-7,2.22755163134603E-8,,,4.25201654458624E-9,3.49700061991601E-8,5,0.250113248825073,34.366584777832,0.155108217148101,,,51.9168,52.0029602050781,52.034969329834,-0.042,-0.042,0.385793,1,1,3,0,18.4829999643862,1,,,30.3030319213867,35.190616607666,,,,,,,,,,,,,,,,
,3860891876.64815,52.0101815099302,-0.042,1.57499820843476E-6,4.32571061702373E-9,-0.0515449083191527,0.0941624326338967,1.57479966439443E-7,4.32516531858555E-10,1.57479902712723E-7,-1.41673425272826E-10,5.18009228647528E-10,7.04505157815293E-10,10.0012607574463,9984,,,,10,1,5,299520,30,6,1.58779717758198E-7,1.60783326936204E-9,,,2.37686884462928E-8,3.18419565609602E-6,5,0.880634725093842,358.538726806641,3.98370498370064,,,51.8741,52.0010604858398,52.0170097351074,-0.042,-0.042,0.366996,1,1,3,0,18.4430001254678,1,,,30.7917900085449,35.190616607666,,,,,,,,,,,,,,,,
,3860894763.92457,54.0096818013184,-0.042,1.5468077003735E-6,4.2480298884595E-9,0.178160672301343,0.0679589795733159,1.54661271002443E-7,4.24749438244242E-10,1.54660523298535E-7,4.80916951494819E-10,3.62495659873346E-10,7.78762941712791E-10,10.0012607574463,9984,,,,10,1,5,299520,30,6,1.56005681498295E-7,2.12875736870135E-9,,,3.42151809390868E-8,3.12801537373614E-6,5,0.877354800701141,359.284759521484,3.97699620178585,,,53.8592,53.9992561340332,54.0156211853027,-0.042,-0.042,0.370681,1,1,3,0,18.4430001254678,1,,,30.7917900085449,35.190616607666,,,,,,,,,,,,,,,,
,3860897361.75662,56.003236519445,-0.042,1.58216559174068E-6,4.08061500636998E-9,0.108027610214676,0.0817326762916877,1.58378717559509E-7,4.08479728630636E-10,1.5837843605136E-7,2.98612993406032E-10,2.14098760338037E-10,3.32850081605212E-10,9.98976135253906,4992,,,,10,1,5,150016,30,5,1.58191829617935E-7,1.74171510409539E-9,,,2.21860569057296E-8,1.53274490831406E-6,5,0.453399270772934,2.69166326522827,2.39210144915653,,,55.878,55.9975090026855,56.006721496582,-0.042,-0.042,0.315924,1,1,3,0,18.4829999643862,1,,,30.7917900085449,35.6793746948242,,,,,,,,,,,,,,,,
,3860899915.03989,58.0013793018886,-0.042,1.57761312282903E-6,6.17848588805057E-9,-0.000417516032941995,0.164562237398757,1.57951080856343E-7,6.18591789045993E-10,1.57951080852149E-7,-1.15099417859215E-12,1.71989886513817E-10,1.62505700816777E-10,9.98798561096191,1996.80004882813,,,,1,1,5,59904,30,4,1.5717021563148E-7,6.84888537972327E-10,,,5.75010638209293E-9,6.03429501662717E-7,5,0.342625707387924,5.6838870048523,1.08850815847514,,,57.8813,57.9978637695313,58.0044212341309,-0.042,-0.042,0.39753,1,1,3,0,18.412999897033,1,,,30.7917900085449,35.6793746948242,,,,,,,,,,,,,,,,
,3860902817.16043,60.0009410221464,-0.042,1.55036905679286E-6,5.75463595297712E-9,-0.118082294100864,0.154962617146745,1.55223397107353E-7,5.76155811304068E-10,1.55223067458678E-7,-3.19903525340027E-10,1.59491484929389E-10,1.52165757823881E-10,9.98798561096191,1996.80004882813,,,,1,1,5,59904,30,4,1.5449950562892E-7,3.7378763427846E-10,,,4.42232510418283E-9,5.93150971586228E-7,5,0.340257376432419,5.97858238220215,1.08599907403901,,,59.8604,59.9965972900391,60.0054092407227,-0.042,-0.042,0.33544,1,1,3,0,18.412999897033,1,,,30.7917900085449,35.6793746948242,,,,,,,,,,,,,,,,
,3860905389.56891,62.0007794826706,-0.042,1.53887038421376E-6,1.00215209494134E-8,-0.70959126849575,0.269613719219418,1.53974365000342E-7,1.00272078815262E-9,1.53962556788499E-7,-1.90687818351182E-9,1.37391332083223E-10,1.33326357600259E-10,9.99432849884033,998.400024414062,,,,1,1,5,29952,30,3,1.53148978519202E-7,-1.44322311559691E-9,,,-2.09165765555772E-9,2.93806641552785E-7,5,0.316194295883179,8.19675445556641,0.587452252108272,,,61.8519,61.9970092773437,62.0038681030273,-0.042,-0.042,0.385793,1,1,3,0,18.4229999731779,1,,,31.7693061828613,35.6793746948242,,,,,,,,,,,,,,,,
,3860908302.58217,63.9980216260609,-0.042,1.51957943820281E-6,2.14280962403735E-8,-5.27758889418783,0.647695412541706,1.52088250144219E-7,2.14464711695143E-9,1.5144351041682E-7,-1.39892453177745E-8,1.53082826180098E-10,1.36175148697486E-10,9.99143218994141,499.200012207031,,,,10,1,5,14976,30,2,1.5087459329322E-7,-1.31933025890179E-8,,,-1.25092857285422E-8,1.44630596788991E-7,5,0.298024356365204,13.5356540679932,0.391795862975589,,,63.8499,63.9937133789063,64.0024108886719,-0.042,-0.042,0.39753,1,1,3,0,18.412999897033,1,,,31.2805480957031,35.6793746948242,,,,,,,,,,,,,,,,
,3860911147.90016,66.000984,-0.042,,,,,,,,,,,,,,,,,3,,,,,,,,,,,,,,,,,,,,,,0.405552,1,1,3,,18.4530002016127,2,,,31.7693061828613,35.6793746948242,,,,,,,,,,,,,,,,
sample offset = 26.65 mm,3860913923.22402,68.0276374022166,-0.042,1.70559200532702E-6,8.31489089150966E-8,0.275915621724471,1.89628501290763,1.7062165150416E-7,8.31793542391904E-9,1.70619673120021E-7,8.21648601322199E-10,1.05455871296514E-10,1.21682967709626E-10,9.99633979797363,98.9429168701172,,,,10,1,5,5000,50.5050506591797,1,1.73586567789623E-7,5.41234047122691E-9,,,1.06205369663983E-9,3.30002086201214E-8,5,0.142233788967133,44.7412872314453,0.159804408165422,,,67.8031,68.0027542114258,68.0552749633789,-0.042,-0.042,0.405552,1,1,3,0,18.4530002016127,1,,,30.7917900085449,36.1681327819824,,,,,,,,,,,,,,,,
,3860916507.48308,68.0073093458407,-0.042,1.32452413497417E-6,5.65001940049312E-9,-1.00199578752651,0.137703988069767,1.32435716565836E-7,5.6493071598863E-10,1.32415465373979E-7,-2.3159343900387E-9,6.34051031924099E-10,9.52725994539706E-10,10.0012607574463,9984,,,,10,1,5,299520,30,6,1.33889919060537E-7,-1.18201716948485E-9,,,-3.03701431205654E-8,2.68302073674591E-6,5,0.85808664560318,2.70767331123352,4.0120165092687,,,67.7941,67.9975662231445,68.013557434082,-0.042,-0.042,0.385793,1,1,3,0,18.4229999731779,1,,,29.3255138397217,34.2131004333496,,,,,,,,,,,,,,,,
touchdown = 4.9200002104044 mm,3860919233.73753,70.0031196128785,-0.042,1.38580479937688E-6,3.37175256093299E-9,-1.14609267221733,0.0641329320334143,1.38722513028267E-7,3.37520831774025E-10,1.38694760875484E-7,-2.7746939597168E-9,1.48229370328752E-10,2.91941280347271E-10,9.98976135253906,4992,,,,10,1,5,150016,30,5,1.38769050501222E-7,-1.66089197312131E-9,,,-1.10680307859458E-8,1.34427310095588E-6,5,0.439350992441177,4.88624382019043,2.39330902990119,,,69.7956,69.9938125610352,70.0095672607422,-0.042,-0.042,0.385793,1,1,3,0,18.3930002104044,1,,,30.3030319213867,35.190616607666,,,,,,,,,,,,,,,,
,3860923069.77373,71.996017,-0.042,,,,,,,,,,,,,,,,,3,,,,,,,,,,,,,,,,,,,,,,0.39753,1,1,3,,18.3330002191961,2,,,31.7693061828613,35.6793746948242,,,,,,,,,,,,,,,,
,3860926528.7496,74.0009085915305,-0.042,1.40508105708575E-6,6.1016250390104E-9,-0.696285381642918,0.18498669069341,1.40677120674229E-7,6.10896458672688E-10,1.40666733021549E-7,-1.7095327536172E-9,1.73312888640089E-10,1.57283153012966E-10,9.98798561096191,1996.80004882813,,,,10,1,5,59904,30,4,1.40236626319506E-7,-9.21607667184316E-10,,,-2.38080555228105E-9,5.38297167528029E-7,5,0.328257262706757,7.58317136764526,1.21510389816009,,,73.7709,73.9933776855469,74.0065383911133,-0.042,-0.042,0.401521,1,1,3,0,18.3330002191961,1,,,30.7917900085449,35.6793746948242,,,,,,,,,,,,,,,,
,3860929616.30597,76.0002288919679,-0.042,1.36814364182789E-6,1.04117787688923E-8,-3.0980222340781,0.331184223150224,1.3689200249788E-7,1.0417687161374E-9,1.36691939826257E-7,-7.39823860216386E-9,1.45048626116596E-10,1.36535289702834E-10,9.99432849884033,998.400024414062,,,,10,1,5,29952,30,3,1.3624443123472E-7,-6.57032058559148E-9,,,-1.22887997730631E-8,2.6131958062365E-7,5,0.308089256286621,11.4388265609741,0.643645428725454,,,75.7613,75.9939117431641,76.0038375854492,-0.042,-0.042,0.405552,1,1,3,0,18.3629999819696,1,,,30.7917900085449,35.6793746948242,,,,,,,,,,,,,,,,
,3860932188.47897,78.0020851808436,-0.042,,,,,,,,,,,0,499.200012207031,,,,1,1,5,14976,30,2,,,,,-5.97728728735092E-7,-7.50838353269501E-6,5,0.283211827278137,21.2587814331055,0.329953827926602,,,77.7483,77.9997177124023,78.0093154907227,0,0,0.366996,1,1,3,1,18.3629999819696,1,,,30.7917900085449,35.6793746948242,,,,,,,,,,,,,,,,
sample offset = 26.65 mm touchdown = 4.84000006690621 mm,3860935316.50203,80.0380227346946,-0.042,1.27895001043481E-6,8.6340386393003E-8,0.620246527335411,2.65385012706079,1.27941830338147E-7,8.63720002900513E-9,1.27934333782993E-7,1.38498728409653E-9,1.10912703448337E-10,1.27495797687956E-10,9.99633979797363,98.9429168701172,,,,10,1,5,5000,50.5050506591797,1,1.31544713307426E-7,5.10455003010829E-9,,,1.00501841168529E-9,2.50025804617134E-8,5,0.10693733394146,39.1061897277832,0.177918250366262,,,79.7157,80.0017166137695,80.0746536254883,-0.042,-0.042,0.409624,1,1,3,3,18.3130000669062,1,,,30.7917900085449,35.6793746948242,,,,,,,,,,,,,,,,
sample offset = 26.65 mm,3860939077.35006,82.012886940294,-0.042,7.95884364103506E-7,1.3572078756043E-6,-5.51086775436591,44.1595733637263,7.96175780524028E-8,1.35770482299873E-7,7.92495856561165E-8,-7.64603873023853E-9,1.04290387191913E-9,2.45595568322007E-9,9.99633979797363,98.9429168701172,,,,100,1,5,5000,50.5050506591797,1,8.18595670792123E-8,-5.60113549176888E-9,,,-1.05340883008616E-9,1.56055147353752E-8,5,0.103402763605118,37.906494140625,0.198581455172954,,,81.7162,81.9950332641602,82.0510406494141,-0.042,-0.042,0.41789,1,1,3,3,18.3130000669062,1,,,30.7917900085449,35.6793746948242,,,,,,,,,,,,,,,,
,3860941429.36961,82.0060869480701,-0.042,1.15161176637683E-6,1.05580561082251E-8,-2.65386979406674,0.415951146535416,1.15146659436853E-7,1.05567251612396E-9,1.15023162081256E-7,-5.33154426933107E-9,1.64986750054513E-9,1.36350513849884E-9,10.0012607574463,9984,,,,100,1,5,299520,30,6,1.16514799707597E-7,-4.45990331555965E-9,,,-7.86356894643195E-8,2.33356818646853E-6,5,0.838605642318726,4.58882999420166,4.23327370918936,,,81.7083,81.9993286132813,82.0111770629883,-0.042,-0.042,0.405552,1,1,3,3,18.3330002191961,1,,,31.2805480957031,35.6793746948242,,,,,,,,,,,,,,,,
,3860944395.74699,84.0026407076444,-0.042,1.2141566881697E-6,3.37837730617538E-9,-1.18393333171784,0.0830259926486269,1.21540109450272E-7,3.38183985277758E-10,1.2151416267414E-7,-2.51126955675991E-9,1.68466921299456E-10,2.81826119091227E-10,9.98976135253906,4992,,,,10,1,5,150016,30,5,1.21695010769365E-7,-1.59476689441062E-9,,,-1.0599946720194E-8,1.17876640949238E-6,5,0.426368355751038,6.28861856460571,2.42537724039772,,,83.7192,83.9979476928711,84.007438659668,-0.042,-0.042,0.413736,1,1,3,3,18.3230001430511,1,,,30.7917900085449,35.6793746948242,,,,,,,,,,,,,,,,
,3860947368.87876,85.99511,-0.042,,,,,,,,,,,,,,,,,3,,,,,,,,,,,,,,,,,,,,,,0.448159,1,1,3,,18.2730002279878,2,,,31.2805480957031,35.190616607666,,,,,,,,,,,,,,,,
,3860950146.88843,87.9992438434524,-0.042,1.21675086353527E-6,6.05631741886602E-9,-3.32594760367909,0.21876100377525,1.21821447379727E-7,6.06360246676682E-10,1.21616256834442E-7,-7.06761029419613E-9,1.7072032131049E-10,1.57877407771327E-10,9.98798561096191,1996.80004882813,,,,10,1,5,59904,30,4,1.21409793696598E-7,-6.23276317670367E-9,,,-2.32339739607879E-8,4.66028948905872E-7,5,0.321001499891281,9.28379249572754,1.22999751048284,,,87.7114,87.9883804321289,88.0060043334961,-0.042,-0.042,0.405552,1,1,3,3,18.2730002279878,1,,,30.7917900085449,35.6793746948242,,,,,,,,,,,,,,,,
,3860952910.04682,89.9979624334787,-0.042,1.1791489064617E-6,1.0729766603573E-8,-9.30376508679838,0.434790557879283,1.17981804040013E-7,1.07358554452338E-9,1.16429764589961E-7,-1.90739613626067E-8,1.52236792089548E-10,1.38155227403925E-10,9.99432849884033,998.400024414062,,,,10,1,5,29952,30,3,1.16350309678071E-7,-1.80221092626273E-8,,,-3.42692072091458E-8,2.2317792103101E-7,5,0.299321800470352,15.6167993545532,0.655721352643991,,,89.7003,89.9915084838867,90.0031356811523,-0.042,-0.042,0.426324,1,1,3,3,18.3330002191961,1,,,30.7917900085449,35.6793746948242,,,,,,,,,,,,,,,,
touchdown = 4.82999999076128 mm,3860955874.40776,91.9986598868119,-0.042,1.00313185942844E-6,2.4827925758763E-8,-23.4515452624679,1.34518552272858,1.00399206075613E-7,2.48492160951238E-9,9.21059270809224E-8,-3.99562107459813E-8,1.80040158709909E-10,1.56506824365314E-10,9.99143218994141,499.200012207031,,,,1,1,5,14976,30,2,9.27679722126767E-8,-3.86343644043129E-8,,,-3.69271587820602E-8,8.89407458768968E-8,5,0.257182002067566,29.3311653137207,0.328115598387567,,,91.696,91.9927673339844,92.0057525634766,-0.042,-0.042,0.41789,1,1,3,3,18.3029999907613,1,,,30.7917900085449,35.190616607666,,,,,,,,,,,,,,,,
,3860958874.44728,93.9974944870193,-0.042,9.43239374851541E-7,2.59704388653411E-8,-26.7960165405706,1.53555352541559,9.44048217432852E-8,2.59927089246385E-9,8.42673641884703E-8,-4.25591553147989E-8,1.93692387565036E-10,1.57464460748026E-10,9.99143218994141,499.200012207031,,,,10,1,5,14976,30,2,8.502702336213E-8,-4.13175845700215E-8,,,-3.95127042686611E-8,8.15129394258174E-8,5,0.252484261989594,30.371826171875,0.377573128844318,,,93.6939,93.9918060302734,94.0024337768555,-0.042,-0.042,0.413736,1,1,3,3,18.3029999907613,1,,,30.3030319213867,35.6793746948242,,,,,,,,,,,,,,,,
sample offset = 26.65 mm,3860961792.11465,96.0548150293329,-0.042,9.88133254152953E-7,4.60043072641787E-7,-3.0473780603407,25.5651076645226,9.88495063316333E-8,4.60211519355357E-8,9.87097248833368E-8,-5.25500860737444E-9,8.65473057728531E-10,2.82257849544146E-10,9.99633979797363,98.9429168701172,,,,10,1,5,5000,50.5050506591797,1,1.02759907941725E-7,-2.83187613927238E-9,,,-5.03534188756838E-10,1.95396138510894E-8,5,0.0886738300323486,30.7606410980225,0.165708179927407,,,95.6803,96.0081481933594,96.0908203125,-0.042,-0.042,0.409624,1,1,3,3,18.242999999553,1,,,30.3030319213867,35.6793746948242,,,,,,,,,,,,,,,,
,3860964046.28087,96.0065121169736,-0.042,9.61624185168119E-7,5.28617153359212E-9,-4.1968934657687,0.165869169287625,9.615029629661E-8,5.28550515959339E-10,9.58924641502326E-8,-7.03667514684646E-9,5.03569076344E-10,9.4763417311136E-10,10.0012607574463,9984,,,,10,1,5,299520,30,6,9.72362000153611E-8,-6.3371155188505E-9,,,-1.29126638659288E-7,1.9481228433953E-6,5,0.82147890329361,5.8673734664917,4.05213502511917,,,95.6738,95.9958801269531,96.0121307373047,-0.042,-0.042,0.443704,1,1,3,3,18.2730002279878,1,,,30.7917900085449,35.190616607666,,,,,,,,,,,,,,,,
,3860967422.14028,97.999825,-0.042,,,,,,,,,,,,,,,,,3,,,,,,,,,,,,,,,,,,,,,,0.405552,1,1,3,,18.2630001518428,2,,,30.7917900085449,35.190616607666,,,,,,,,,,,,,,,,
,3860970288.17983,100.001764628239,-0.042,1.04052083349164E-6,3.69223669061732E-9,-2.10097569453608,0.103109087445925,1.04158727798555E-7,3.69602091613418E-10,1.0408870913791E-7,-3.81853461642792E-9,1.74536477742602E-10,3.13771518906633E-10,9.98976135253906,4992,,,,10,1,5,150016,30,5,1.04322131454492E-7,-3.00347250177773E-9,,,-2.4501581170368E-8,1.01051179179559E-6,5,0.413490980863571,7.32027721405029,2.42001021486589,,,99.6812,99.9961929321289,100.006874084473,-0.042,-0.042,0.413736,1,1,3,3,18.2630001518428,1,,,30.3030319213867,35.190616607666,,,,,,,,,,,,,,,,
,3860995465.11521,99.9983409914572,-0.042,1.0697539071506E-6,8.84988655580342E-9,-8.51278847370839,0.409673776239494,1.07104069711167E-7,8.86053194358889E-10,1.05924087844161E-7,-1.58546322277442E-8,2.67425141318535E-10,2.09959039811589E-10,9.98798561096191,1996.80004882813,,,,10,1,5,59904,30,4,1.058987534473E-7,-1.49878540202563E-8,,,-5.66902481548194E-8,4.06555201326253E-7,5,0.314876139163971,10.9865589141846,1.24032903463163,,,99.6342,99.9894180297852,100.005966186523,-0.042,-0.042,0.434927,1,1,3,3,18.1729999321997,1,,,31.2805480957031,36.1681327819824,,,,,,,,,,,,,,,,
,3860998696.96259,109.999814277,-0.042,9.12890102684409E-7,6.4704631896494E-8,-21.6749673435332,3.7334619239783,9.13408142218193E-8,6.4741349960632E-9,8.48824729909326E-8,-3.37358877406317E-8,8.92619624691451E-10,8.63702170626935E-10,9.99432849884033,998.400024414062,,,,10,1,5,29952,30,3,8.52915168818557E-8,-3.26732352788217E-8,,,-6.2437003910593E-8,1.63632358738149E-7,5,0.280432730913162,22.0297183990479,0.665784583752135,,,109.6852,109.993347167969,110.005729675293,-0.042,-0.042,0.422086,1,1,3,3,18.1629998560548,1,,,31.2805480957031,36.1681327819824,,,,,,,,,,,,,,,,
touchdown = 4.66000009328127 mm,3861002259.36448,119.994103356013,-0.042,4.18017054660773E-7,2.39528557664776E-8,-65.8223253783621,3.06966720187802,4.18375510851787E-8,2.39733957165735E-9,1.71353051321496E-8,-3.81675516483972E-8,1.60103105465928E-10,1.67535326375003E-10,9.99143218994141,499.200012207031,,,,10,1,5,14976,30,2,1.81310099998551E-8,-3.80748577658652E-8,,,-3.64629790899379E-8,1.74118412042807E-8,5,0.193620890378952,39.3829231262207,0.389246496729991,,,119.6461,119.981353759766,120.004013061523,-0.042,-0.042,0.439294,1,1,3,3,18.1330000932813,1,,,30.7917900085449,35.6793746948242,,,,,,,,,,,,,,,,
,3861005873.66139,130.038284,-0.042,,,,,,,,,,,,,,,,,3,,,,,,,,,,,,,,,,,,,,,,0.434927,1,1,3,,18.0830001782179,2,,,31.7693061828613,35.6793746948242,,,,,,,,,,,,,,,,
sample offset = 26.65 mm,3861008884.67618,140.071829772738,-0.042,6.22180589339587E-7,7.68901401955803E-8,5.74213471902883,5.47275184739538,6.22408403389519E-8,7.69182938450799E-9,6.19285321215037E-8,6.22728796305289E-9,1.0664753586256E-10,1.11257694314516E-10,9.99633979797363,98.9429168701172,,,,10,1,5,5000,50.5050506591797,1,6.50575425791392E-8,7.64879247998592E-9,,,1.48209205765206E-9,1.23778582682422E-8,5,0.0750756338238716,18.628475189209,0.166915760672069,,,139.6652,139.957534790039,140.110580444336,-0.042,-0.042,0.439294,1,1,3,3,18.0830001782179,1,,,30.7917900085449,36.1681327819824,,,,,,,,,,,,,,,,
,3861011395.41424,140.004969389064,-0.042,5.78537698968551E-7,4.41496042139975E-9,-7.08476322518847,0.279722791186947,5.78464768592109E-8,4.41440387214448E-10,5.7404805840821E-8,-7.13464444810465E-9,4.92868848222389E-10,7.4905254521018E-10,10.0012607574463,9984,,,,10,1,5,299520,30,6,5.82716054791497E-8,-6.64811838961255E-9,,,-1.31574918069155E-7,1.16774502158794E-6,5,0.778888523578644,7.87417840957642,4.01322409001337,,,139.591,139.994842529297,140.011795043945,-0.042,-0.042,0.448159,1,1,3,3,18.0230001870096,1,,,31.2805480957031,36.1681327819824,,,,,,,,,,,,,,,,
,3861014574.74035,150.001681054157,-0.042,6.07474835072254E-7,3.1115052264346E-9,-11.2091344756414,0.255595015093671,6.08097444607978E-8,3.11469425207416E-10,5.96497485233464E-8,-1.18208511744742E-8,2.33264999185282E-10,1.92783227898002E-10,9.98976135253906,4992,,,,100,1,5,150016,30,5,5.99339772914737E-8,-1.12783918480956E-8,,,-1.0391041635431E-7,5.80993318756578E-7,5,0.391363501548767,10.0038862228394,2.48897701707355,,,149.6014,149.994430541992,150.008804321289,-0.042,-0.042,0.461793,1,1,3,3,18.0030000347197,1,,,31.2805480957031,36.1681327819824,,,,,,,,,,,,,,,,
,3861017573.24982,159.998158046177,-0.042,5.36971657435445E-7,9.01031897386075E-9,-32.2566679229278,0.947357174087655,5.3761757210194E-8,9.02115734325031E-10,4.54644748727905E-8,-2.86933452714954E-8,2.6215544974041E-10,2.27491933782046E-10,9.98798561096191,1996.80004882813,,,,1,1,5,59904,30,4,4.58864800797403E-8,-2.81349575783467E-8,,,-1.06842862705743E-7,1.76835157879433E-7,5,0.286629289388657,20.8235607147217,1.11296856369154,,,159.5752,159.987640380859,160.007629394531,-0.042,-0.042,0.413736,1,1,3,3,17.9329999673665,1,,,31.2805480957031,35.6793746948242,,,,,,,,,,,,,,,,
,3861020696.93815,169.996576309204,-0.042,2.7997827824441E-7,1.50173600452844E-8,-52.8774900443778,3.06444498524583,2.80137158066093E-8,1.50258819759896E-9,1.69068739082527E-8,-2.23366489864509E-8,2.12960349214354E-10,1.97135730178773E-10,9.99432849884033,998.400024414062,,,,10,1,5,29952,30,3,1.74931248084889E-8,-2.21204575966074E-8,,,-4.23397813569225E-8,3.36333181034155E-8,5,0.211755827069283,36.047794342041,0.654647947537624,,,169.5676,169.984848022461,170.005187988281,-0.042,-0.042,0.448159,1,1,3,3,17.8430002133846,1,,,30.7917900085449,35.6793746948242,,,,,,,,,,,,,,,,
,3861023531.02087,180.010385654994,-0.042,3.65097382095175E-7,5.43327445114831E-8,172.260975437002,6.95025260806713,3.65410458835647E-8,5.43793356934165E-9,-3.62082194742232E-8,4.92065816444001E-9,4.00804948527854E-10,3.52655691345458E-10,9.99143218994141,499.200012207031,,,,1,1,5,14976,30,2,-3.71930442555758E-8,3.94784382857686E-9,,,3.71141284156488E-9,-3.56504141304027E-8,5,0.125332936644554,39.2335472106934,0.336380887589737,,,179.4898,179.999588012695,180.024139404297,-0.042,-0.042,0.48062,1,1,3,3,17.7830002221763,1,,,30.7917900085449,35.6793746948242,,,,,,,,,,,,,,,,
sample offset = 26.65 mm touchdown = 4.18000016361475 mm,3861026485.58026,190.043199627403,-0.042,3.29811074830782E-7,7.79272212056174E-8,52.5224653626101,13.3858746538007,3.29931836548452E-8,7.7955754586708E-9,2.00747129119117E-8,2.61831256573136E-8,1.10379074074769E-10,1.11452501211288E-10,9.99633979797363,98.9429168701172,,,,10,1,5,5000,50.5050506591797,1,2.08807928249016E-8,2.78999985769084E-8,,,5.32179698265507E-9,3.9648286391829E-9,5,0.071768082678318,13.4686498641968,0.160609461995198,,,189.619,190.014495849609,190.070587158203,-0.042,-0.042,0.490319,1,1,3,3,17.6530001636147,1,,,30.7917900085449,36.1681327819824,,,,,,,,,,,,,,,,
,3861030227.85114,200.079285,-0.042,,,,,,,,,,,,,,,,,3,,,,,,,,,,,,,,,,,,,,,,0.48062,1,1,3,,17.5830000962615,2,,,31.7693061828613,35.6793746948242,,,,,,,,,,,,,,,,
,3861032970.94874,200.005623513314,-0.042,2.4773815263143E-7,6.69148304692859E-9,-23.8812526088977,1.15996517954401,2.47706922796689E-8,6.69063951956911E-10,2.26499858759716E-8,-1.00282269535715E-8,5.87226723191534E-10,1.22646011954626E-9,10.0012607574463,9984,,,,10,1,5,299520,30,6,2.30887509310556E-8,-9.91250546729814E-9,,,-1.96451426706301E-7,4.63592281183271E-7,5,0.752697169780731,9.69856262207031,4.03509471905559,,,199.5339,199.993530273438,200.014602661133,-0.042,-0.042,0.569583,1,1,3,3,17.5830000962615,1,,,30.7917900085449,35.6793746948242,,,,,,,,,,,,,,,,
,3861035867.99121,210.003556155334,-0.042,2.88739803322722E-7,4.03016319551366E-9,-30.0493954187592,0.776803174723527,2.89035736824017E-8,4.03429376667674E-10,2.50187606997064E-8,-1.4473361208263E-8,2.88595321540847E-10,2.66341378547202E-10,9.98976135253906,4992,,,,10,1,5,150016,30,5,2.52845792735112E-8,-1.42388333506561E-8,,,-1.36067237668399E-7,2.45940614714341E-7,5,0.38219490647316,13.944522857666,2.40270155752572,,,209.5817,209.996963500977,210.009780883789,-0.042,-0.042,0.495242,1,1,3,3,17.5330001811981,1,,,30.3030319213867,35.190616607666,,,,,,,,,,,,,,,,
,3861038977.75177,220.000976805053,-0.042,2.31477849992633E-7,1.28814054145412E-8,-48.5888537974837,3.17870233079171,2.31756291016863E-8,1.28969002522427E-9,1.53297001262495E-8,-1.73813140555654E-8,3.91284580469755E-10,3.07193509857309E-10,9.98798561096191,1996.80004882813,,,,10,1,5,59904,30,4,1.56924055017043E-8,-1.71777253101699E-8,,,-6.5711947810474E-8,6.04487474839144E-8,5,0.256900578737259,29.5635013580322,1.20302797424156,,,219.6137,219.983978271484,220.011871337891,-0.042,-0.042,0.495242,1,1,3,3,17.4130001987815,1,,,30.3030319213867,35.190616607666,,,,,,,,,,,,,,,,
,3861042930.16503,230.001624928968,-0.042,6.30356346140587E-8,7.1684498539372E-8,-46.6628957895355,64.3766043248712,6.30714055690414E-9,7.17251774820987E-9,4.32852438913283E-9,-4.58736292626028E-9,1.12723833394769E-9,8.22472403409426E-10,9.99432849884033,998.400024414062,,,,10,1,5,29952,30,3,4.51206552642265E-9,-4.53303393999092E-9,,,-8.67049056275833E-9,8.67260611032153E-9,5,0.165356665849686,39.4023895263672,0.637204939851298,,,229.6334,229.994750976562,230.007797241211,-0.042,-0.042,0.598756,1,1,3,3,17.3729998942018,1,,,30.7917900085449,35.6793746948242,,,,,,,,,,,,,,,,
,3861045977.62483,240.005321482502,-0.042,6.44647001443538E-8,4.51197681669572E-8,69.4815215914599,28.8750644349146,6.45199796374055E-9,4.51584590769482E-9,2.26148624681672E-9,6.04267802216625E-9,2.0600295947487E-10,3.98113640096115E-10,9.99143218994141,499.200012207031,,,,10,1,5,14976,30,2,2.15582665865886E-9,6.31817843090363E-9,,,6.06118471601288E-9,2.05141185426532E-9,5,0.107098840177059,33.6304397583008,0.380659197643101,,,239.6537,239.978042602539,240.013977050781,-0.042,-0.042,0.510309,1,1,3,3,17.3129999029934,1,,,30.7917900085449,35.6793746948242,,,,,,,,,,,,,,,,
sample offset = 26.65 mm touchdown = 3.72999999672174 mm,3861049299.13295,250.050223569787,-0.042,1.47220117326512E-7,2.79987100360597E-7,88.7152063535972,27.725927940842,1.47274022594105E-8,2.80089618819634E-8,3.30217815685923E-10,1.47236997220363E-8,1.37344706624158E-10,5.4785944711702E-10,9.99633979797363,98.9429168701172,,,,10,1,5,5000,50.5050506591797,1,2.15502416435999E-10,1.55776661534951E-8,,,2.96855620045922E-9,3.45611059730421E-11,5,0.0740132927894592,10.6916723251343,0.180065075137985,,,249.5793,249.992752075195,250.105072021484,-0.042,-0.042,0.541832,1,1,3,3,17.2029999967217,1,,,30.7917900085449,35.6793746948242,,,,,,,,,,,,,,,,
,3861052648.8053,260.098389,-0.042,,,,,,,,,,,,,,,,,3,,,,,,,,,,,,,,,,,,,,,,0.547271,1,1,3,,17.1530000816584,2,,,31.2805480957031,35.6793746948242,,,,,,,,,,,,,,,,
,3861055574.72792,260.007383918256,-0.042,1.34611250921262E-7,1.90317554815819E-8,-20.3759356867359,6.17101106098038,1.34594281846955E-8,1.90293563413113E-9,1.26172489844564E-8,-4.68628158812623E-9,1.9839571637383E-9,3.3212644372637E-9,10.0012607574463,9984,,,,100,1,5,299520,30,6,1.28775215516333E-8,-4.58430159524775E-9,,,-8.80598272378122E-8,2.59112471127422E-7,5,0.785670638084412,11.180645942688,4.23595722195528,,,259.7152,259.999938964844,260.013305664062,-0.042,-0.042,0.558316,1,1,3,3,17.1530000816584,1,,,30.3030319213867,35.6793746948242,,,,,,,,,,,,,,,,
,3861059036.81112,270.003719660588,-0.042,1.46742752198144E-7,6.69217725301156E-9,-27.1078764825764,1.6206189538763,1.46893150916811E-8,6.69903615996856E-10,1.30756963581935E-8,-6.69344026723287E-9,1.44469364552016E-10,6.35971787429151E-10,9.98976135253906,4992,,,,100,1,5,150016,30,5,1.32482792579906E-8,-6.52925648183471E-9,,,-6.15791570125717E-8,1.28905971298825E-7,5,0.404840081930161,17.818920135498,2.50239487208291,,,269.7785,269.993988037109,270.010467529297,-0.042,-0.042,0.581078,1,1,3,3,17.0330000992417,1,,,30.7917900085449,35.6793746948242,,,,,,,,,,,,,,,,
,3861062522.79201,280.001482301212,-0.042,1.04519220552103E-7,1.0306288696324E-8,-28.6024028999878,5.49233290975583,1.04644945060185E-8,1.03186859670811E-9,9.18743793338277E-9,-5.00965362941705E-9,3.02748949770026E-10,2.59896022977513E-10,9.98798561096191,1996.80004882813,,,,10,1,5,59904,30,4,9.36383869979469E-9,-4.83769222481956E-9,,,-1.84034160177451E-8,3.59822362238569E-8,5,0.243578687310219,35.4978675842285,1.20879752668828,,,279.8406,279.986877441406,280.01171875,-0.042,-0.042,0.635742,1,1,3,3,16.9730001080334,1,,,30.7917900085449,35.6793746948242,,,,,,,,,,,,,,,,
,3861065574.25696,289.995726422079,-0.042,3.5949529385234E-7,1.13014154504033E-8,101.398126871825,1.52023859103125,3.59699297350545E-8,1.13078286867544E-9,-7.10856790305456E-9,3.52605176863929E-8,1.54641094560374E-10,1.58477412851347E-10,9.99432849884033,998.400024414062,,,,10,1,5,29952,30,3,-8.33860301315756E-9,3.57801056003658E-8,,,6.85156226390323E-8,-1.61564684175822E-8,5,0.148273974657059,38.4499588012695,0.655050474452511,,,289.9082,289.982849121094,290.006622314453,-0.042,-0.042,0.745929,1,1,3,3,16.8829998883903,1,,,30.3030319213867,35.190616607666,,,,,,,,,,,,,,,,
,3861069107.91444,299.983915983289,-0.042,1.30942108972975E-7,4.14398926676722E-8,-6.66822475646393,11.4361489345442,1.31054393888393E-8,4.14754280266153E-9,1.30167837172786E-8,-1.52180262587863E-9,2.32167988855388E-10,3.42927505206108E-10,9.99143218994141,499.200012207031,,,,100,1,5,14976,30,2,1.36039994946134E-8,-1.21636508922253E-9,,,-1.14009182222942E-9,1.30246069511767E-8,5,0.100716859102249,29.6562538146973,0.417289401680173,,,299.9192,299.975708007812,299.995727539063,-0.042,-0.042,0.77634,1,1,3,3,16.7329999103695,1,,,30.3030319213867,35.190616607666,,,,,,,,,,,,,,,,
,3861070844.43356,300.015263821216,-0.042,6.68102018591011E-8,1.55931720713216E-8,-14.1865129743644,9.08709956419084,6.68017797749735E-9,1.55912063983653E-9,6.47645303514229E-9,-1.63717253050397E-9,1.60464221705615E-9,2.73415619068369E-9,10.0012607574463,9984,,,,100,1,5,299520,30,6,6.6041283140634E-9,-1.56663900332849E-9,,,-2.91694360030114E-8,1.32680476196785E-7,5,0.812992811203003,12.1418447494507,4.25205829855078,,,299.8488,300.009887695313,300.020782470703,-0.042,-0.042,0.799958,1,1,3,3,16.7329999103695,1,,,30.7917900085449,35.6793746948242,,,,,,,,,,,,,,,,