File: DataFailid_Testimiseks/Cr2AlO3_powderl_LFZ774_VSM_2.5K_M(B)_26112023.DAT
[Header]
; VSM Data File (default extension .dat)
; Copyright (c) 2003-2013, Quantum Design, Inc. All rights reserved.
TITLE,Cr2AlO3_powderl_LFZ774_VSM_2.5K_M(B)_26112023
FILEOPENTIME,8672777.48,11/29/2023,10:42 am
BYAPP,VSM,2.0,2.0
INFO,PPMS VSM Option Release 1.4.10 Build 1,APPNAME
INFO,Quantum Design Linear Motor Servo Controller,MOTOR_MODULE_NAME
INFO,3101-100 C1,MOTOR_HW_VERSION
INFO,074,MOTOR_SERIAL_NUMBER
INFO,SRV No X-over 01.01.11,MOTOR_SOFTWARE_VERSION
INFO,Quantum Design VSM Detection Module,VSM_MODULE_NAME
INFO,3101-150 E1,VSM_HW_VERSION
INFO,VSM061,VSM_SERIAL_NUMBER
INFO,VSM No X-over 01.02.05 May 20 2008 13:51:47,VSM_SOFTWARE_VERSION
INFO,113,PREAMP_SERIAL_NUMBER
INFO,Quantum Design VSM Oven,OVEN_MODULE_NAME
INFO,3101-200 B0,OVEN_HW_VERSION
INFO,OVN054,OVEN_SERIAL_NUMBER
INFO,01.01.00,OVEN_SOFTWARE_VERSION
INFO,818,COIL_SERIAL_NUMBER
INFO,0,MOMENT_UNITS
INFO,Cr2O3:Al powder,SAMPLE_MATERIAL
INFO,LFZ774 (unoriented],SAMPLE_COMMENT
INFO,249.3,SAMPLE_MASS
INFO,,SAMPLE_VOLUME
INFO,,SAMPLE_MOLECULAR_WEIGHT
INFO,diam 4 length 6 mm,SAMPLE_SIZE
INFO,cylinder,SAMPLE_SHAPE
DATATYPE,COMMENT,1
DATATYPE,TIME,2
STARTUPAXIS,X,2
STARTUPAXIS,Y1,5
[Data]
Comment,Time Stamp (sec),Temperature (K),Magnetic Field (Oe),Moment (emu),M. Std. Err. (emu),Transport Action,Averaging Time (sec),Frequency (Hz),Peak Amplitude (mm),Center Position (mm),Coil Signal' (mV),Coil Signal" (mV),Range (mV),M. Quad. Signal (emu),M. Raw' (emu),M. Raw" (emu),Min. Temperature (K),Max. Temperature (K),Min. Field (Oe),Max. Field (Oe),Mass (grams),Motor Lag (deg),Pressure (Torr),VSM Status (code),Motor Status (code),Measure Status (code),Measure Count,PPMS Status (code),System Temp. (K),System Field (Oe),Sample Position (deg),Bridge 1 Resistance (ohms),Bridge 1 Excitation (에),Bridge 2 Resistance (ohms),Bridge 2 Excitation (에),Bridge 3 Resistance (ohms),Bridge 3 Excitation (에),Bridge 4 Resistance (ohms),Bridge 4 Excitation (에),Signal 1 Vin (V),Signal 2 Vin (V),Digital Inputs (code),Drive 1 Iout (mA),Drive 1 Ipower (W),Drive 2 Iout (mA),Drive 2 Ipower (W),Pressure (),Map 20 (),Map 21 (),Map 22 (),Map 23 (),Map 24 (),Map 25 (),Map 26 (),Map 27 (),Map 28 (),Map 29 ()
,8682217.92,4.3012705,-0.099,,,2,,,,14.9030001513958,,,,,,,4.3012705,4.3012705,-0.099,-0.099,,,92.345711,,,,-99999999,4881,4.3054,-0.099,,,,,,,,,,,,,,,,,,,,,,,4.3012705,,,,
,8683503.43,4.29867575,135492.9375,0.826335894024791,9.24671675286373E-5,1,9.99253354069792,40.0298881530762,1.99979977752012,14.8900002241135,9.18855483517671,1.71728287764246,25,0.00554830035553657,0.825979114832663,0.0108800162434971,4.2971339,4.3002176,134997.359,135988.516,52.8333981288902,18.387055360446,93.108131,0,0,0,400,4961,4.208,135492.9375,,,,,,,,,,,,,0,,,,4.4374449,,,,,,4.29867575,,,,
,8683573.36,4.30129675,128575.7345,0.782086018853937,0.000100590829191661,1,9.99253354069792,40.0298881530762,1.99961337115054,14.8900002241135,8.69271879851946,1.62544897413309,25,0.00533445456434095,0.781489748208166,0.0103665119572018,4.2984467,4.3041468,128078.742,129072.727,53.3187894393326,18.3901536464387,93.108131,0,0,0,400,4961,4.2111,128575.7345,,,,,,,,,,,,,0,,,,4.3288035,,,,,,4.30129675,,,,
,8683643.3,4.30001165,121684.8085,0.736960275473454,9.86393124491845E-5,1,9.99253354069792,40.0298881530762,1.9998054223859,14.8900002241135,8.18903578813374,1.53175949437354,25,0.00509315304930242,0.736147509636104,0.00980796413152568,4.2997794,4.3002439,121199.398,122170.219,52.8646632696594,18.3936584004828,93.870552,0,0,0,400,4961,4.2077,121684.8085,,,,,,,,,,,,,0,,,,4.3501,,,,,,4.30001165,,,,
,8683713.295,4.3012273,114768.617,0.690806748336144,0.000101341868826156,1,9.99253354069792,40.0298881530762,1.99974415100714,14.8900002241135,7.67322804053127,1.43543698344113,25,0.0048242129702046,0.689802001205606,0.00920432917069695,4.3007345,4.3017201,114273.461,115263.773,52.6200135431402,18.3912582639147,93.108131,0,0,0,400,4961,4.2041,114768.617,,,,,,,,,,,,,0,,,,4.37161015,,,,,,4.3012273,,,,
,8683783.195,4.3026128,107869.508,0.642838968536632,0.00010530798969116,1,9.99253354069792,40.0298881530762,1.99991550067097,14.8900002241135,7.13844117644914,1.33537085878761,25,0.00453504216964854,0.641673096493822,0.0085601164641201,4.2999554,4.3052702,107380.852,108358.164,52.125242690467,18.395879520074,93.108131,0,0,0,400,4961,4.2064,107869.508,,,,,,,,,,,,,0,,,,4.24317385,,,,,,4.3026128,,,,
,8683853.25,4.30081915,100936.6565,0.592871944061238,0.00010738388940044,1,9.99253354069792,40.0298881530762,1.99965080751173,14.8900002241135,6.58009586689256,1.23220981934286,25,0.00435321617981366,0.591578006468604,0.00800366602688299,4.3007984,4.3008399,100431.477,101441.836,52.3730189310632,18.3928926314251,92.726921,0,0,0,400,4961,4.20545,100936.6565,,,,,,,,,,,,,0,,,,4.3496659,,,,,,4.30081915,,,,
,8683923.175,4.3023851,94028.2305,0.539521082662871,0.000117788271774979,1,9.99253354069792,40.0298881530762,1.99982893731524,14.8900002241135,5.98643147896824,1.12003695338274,25,0.00394128112631174,0.538144052392292,0.00719375342912911,4.3016062,4.303164,93529.547,94526.914,52.7896269318133,18.393985058192,93.108131,0,0,0,400,4961,4.2053,94028.2305,,,,,,,,,,,,,0,,,,4.3713918,,,,,,4.3023851,,,,
,8683993.08,4.3026273,87107.0935,0.481922529554203,0.000126338328159438,1,9.99253354069792,40.0298881530762,1.99969300863476,14.8999998345971,5.34493610954385,1.00026161471216,25,0.00361491564642611,0.480512502217638,0.00644470828851764,4.3022518,4.3030028,86611.234,87602.953,52.5621730327171,18.3976109159209,93.108131,0,0,0,400,4961,4.2044,87107.0935,,,,,,,,,,,,,0,,,,4.32815575,,,,,,4.3026273,,,,
,8684063.065,4.3025224,80180.875,0.418886517217865,0.000138321816874363,1,9.99253354069792,40.0298881530762,1.99968905263035,14.8900002241135,4.64409199323657,0.868973528953932,25,0.00320592516349742,0.417505074372436,0.00558828223559506,4.3008647,4.3041801,79685.016,80676.734,52.7458557347364,18.3958956180042,91.9645,0,0,0,400,4961,4.20665,80180.875,,,,,,,,,,,,,0,,,,4.32815575,,,,,,4.3025224,,,,
,8684132.945,4.3020544,73253.5235,0.350586673844846,0.00014732465501881,1,9.99253354069792,40.0298881530762,1.9996473353004,14.8999998345971,3.88535764884167,0.72700198297193,25,0.00275603117693985,0.349301615275206,0.00467521699550654,4.3011384,4.3029704,72753.992,73753.055,52.7044294232171,18.3969230950567,92.726921,0,0,0,400,4961,4.20315,73253.5235,,,,,,,,,,,,,0,,,,4.04852535,,,,,,4.3020544,,,,
,8684202.975,4.301229,66322.781,0.279712137728414,0.000146310095032919,1,9.99253354069792,40.0298881530762,1.99971325645241,14.8900002241135,3.09897928939447,0.5792533040831,25,0.00221218578359333,0.278586629670315,0.00367601497756729,4.2999015,4.3025565,65824.664,66820.898,53.1147843958133,18.3991061562668,92.726921,0,0,0,400,4961,4.2023,66322.781,,,,,,,,,,,,,0,,,,4.30642985,,,,,,4.301229,,,,
,8684272.81,4.2983677,59389.924,0.212515901955219,0.000131370100728428,1,9.99253354069792,40.0298881530762,1.99980980480771,14.8900002241135,2.35376699318267,0.440084636358,25,0.00174783158103347,0.211586923984766,0.00280275521172259,4.2979712,4.2987642,58889.121,59890.727,52.1877729720055,18.3947936242683,93.108131,0,0,0,400,4961,4.2048,59389.924,,,,,,,,,,,,,0,,,,4.30685925,,,,,,4.2983677,,,,
,8684342.8,4.29696225,52441.668,0.155548494800125,0.000106200695988462,1,9.99253354069792,40.0298881530762,1.99984242185192,14.8900002241135,1.72217042337213,0.322540888629547,25,0.00137226816257799,0.154816701131046,0.00209819527758842,4.2968869,4.2970376,51953.012,52930.324,53.0420929435248,18.3967918003704,92.726921,0,0,0,400,4961,4.2069,52441.668,,,,,,,,,,,,,0,,,,4.18345395,,,,,,4.29696225,,,,
,8684412.775,4.29549145,45486.344,0.111750893265981,7.79520363047747E-5,1,9.99253354069792,40.0298881530762,1.99993667016122,14.8999998345971,1.23684703399539,0.232122363375201,25,0.00106268750449006,0.111190104608967,0.00154831932827907,4.2954783,4.2955046,44989.211,45983.477,51.8899725061786,18.3973892087089,93.108131,0,0,0,400,4961,4.21055,45486.344,,,,,,,,,,,,,0,,,,4.08611845,,,,,,4.29549145,,,,
,8684482.73,4.29709055,38548.955,0.0798130960539728,5.67962375642391E-5,1,9.99253354069792,40.0298881530762,1.99981361428923,14.8999998345971,0.883022678864834,0.165911182662719,25,0.000802412717879515,0.0793895722673911,0.00112217291171731,4.2959781,4.298203,38057.332,39040.578,52.4808836667171,18.3987580192353,93.489342,0,0,0,400,4961,4.21295,38548.955,,,,,,,,,,,,,0,,,,4.18345395,,,,,,4.29709055,,,,
,8684552.625,4.296963,31599.5575,0.0568670726431786,4.15351268858931E-5,1,9.99253354069792,40.0298881530762,2.00000917625506,14.8999998345971,0.628997407542058,0.11849068928195,25,0.000618541167880365,0.0565503747151058,0.000826118941484223,4.296896,4.29703,31099.742,32099.373,52.5731158319863,18.3967739228932,92.345711,0,0,0,400,4961,4.2137,31599.5575,,,,,,,,,,,,,0,,,,4.3713918,,,,,,4.296963,,,,
,8684632.61,4.2994072,23622.128,0.0377072717495477,3.02142674127437E-5,1,9.99253354069792,40.0298881530762,1.99970101284368,14.8900002241135,0.416909142734427,0.0784974024254683,25,0.000422175991487902,0.0374873884940871,0.000544158106669132,4.2988276,4.2999868,23122.17,24122.086,52.2151299701786,18.4098438439659,93.108131,0,0,0,400,4961,4.21285,23622.128,,,,,,,,,,,,,0,,,,4.28513335,,,,,,4.2994072,,,,
,8684712.54,4.3005388,15610.626,0.0230630688868191,2.39854676810275E-5,1,9.99253354069792,40.0298881530762,1.99984915191803,14.8999998345971,0.254886323882721,0.0479608803815161,2.5,0.000265087599623185,0.0229234921462852,0.000330129547504935,4.3000803,4.3009973,15107.278,16113.974,52.392559644044,18.4029113753299,93.108131,0,0,0,400,4961,4.21225,15610.626,,,,,,,,,,,,,0,,,,4.3713918,,,,,,4.3005388,,,,
,8684782.485,4.30025985,8539.153,0.0121838632434813,7.62818208088609E-5,1,9.99253354069792,40.0298881530762,1.99979626479341,14.8900002241135,0.134738103054044,0.0247055612680432,2.5,8.76583671298903E-5,0.0121083583357722,0.000118118242621353,4.2998028,4.3007169,8029.587,9048.719,52.788845303294,18.4018515312602,93.108131,0,0,0,400,4961,4.2121,8539.153,,,,,,,,,,,,,0,,,,4.24317385,,,,,,4.30025985,,,,
,8684869.585,4.3001275,-338.094,0.000415208622585644,3.82364936363834E-5,1,9.99253354069792,40.0298881530762,1.99980108420936,14.8900002241135,0.00453745339325444,0.00115539656303626,0.25,3.1415071647916E-5,0.00041251926395315,3.21365042005849E-5,4.3001275,4.3001275,-359.703,-316.485,51.8235340820439,18.4095896671676,92.726921,0,0,0,400,4961,4.21215,-338.094,,,,,,,,,,,,,0,,,,4.32815575,,,,,,4.3001275,,,,
,8684942.345,4.29948095,-7308.999,-0.0105862350972214,6.7367418624082E-5,1,9.99253354069792,40.0298881530762,1.9998025932391,14.8999998345971,-0.116919290437085,-0.022310684161881,2.5,-0.000153091174744352,-0.0105201905337112,-0.000178479480821218,4.2993088,4.2996531,-7759.25,-6858.748,52.0205044688901,18.4060962501609,92.345711,0,0,0,400,4961,4.2113,-7308.999,,,,,,,,,,,,,0,,,,4.32794,,,,,,4.29948095,,,,
,8685012.34,4.30333995,-13947.342,-0.0205148611926543,3.35367228366722E-5,1,9.99253354069792,40.0298881530762,1.99978875323021,14.8900002241135,-0.226658683728415,-0.0429416855012184,2.5,-0.000263064172631842,-0.0203898088079226,-0.000319034760188594,4.3025236,4.3041563,-14414.678,-13480.006,52.5129304360056,18.4098476455973,92.726921,0,0,0,400,4961,4.2092,-13947.342,,,,,,,,,,,,,0,,,,4.02679945,,,,,,4.30333995,,,,
,8685082.225,4.30292465,-20637.21,-0.0320021597579718,2.65378539791416E-5,1,9.99253354069792,40.0298881530762,1.99986260709229,14.8999998345971,-0.353632893999111,-0.0671001657003363,2.5,-0.000408400426971266,-0.0318126029175786,-0.00050667165100761,4.3023572,4.3034921,-21118.682,-20155.738,52.4363308411209,18.4030530737737,93.108131,0,0,0,400,4961,4.20715,-20637.21,,,,,,,,,,,,,0,,,,4.16172805,,,,,,4.30292465,,,,
,8685152.195,4.3028281,-27377.0735,-0.0461298087168595,3.36677419196503E-5,1,9.99253354069792,40.0298881530762,1.99979444022275,14.8999998345971,-0.509948444199338,-0.0961040698449624,2.5,-0.000515259659114365,-0.0458662497160307,-0.000673501815082036,4.3027511,4.3029051,-27864.463,-26889.684,52.8365246429671,18.4101965759857,92.345711,0,0,0,400,4961,4.20635,-27377.0735,,,,,,,,,,,,,0,,,,4.3713918,,,,,,4.3028281,,,,
,8685222.125,4.30199625,-34136.3945,-0.0645378087911497,4.47080463723843E-5,1,9.99253354069792,40.0298881530762,1.99991290196633,14.8999998345971,-0.713683566898976,-0.134315939648158,2.5,-0.000682468845821601,-0.064184363618428,-0.000926525089417987,4.3015161,4.3024764,-34620.676,-33652.113,52.2635909383709,18.4091029273493,93.108131,0,0,0,400,4961,4.20395,-34136.3945,,,,,,,,,,,,,0,,,,4.3496659,,,,,,4.30199625,,,,
,8685292.07,4.30235055,-40902.3455,-0.0895464891783439,6.11018212797267E-5,1,9.99253354069792,40.0298881530762,1.99990300650897,14.8900002241135,-0.990541794488407,-0.186158435177541,2.5,-0.000893913844520446,-0.0890797710759733,-0.0012630953228995,4.3017731,4.302928,-41390.156,-40414.535,52.9568954349287,18.4144363804356,93.108131,0,0,0,400,4961,4.2034,-40902.3455,,,,,,,,,,,,,0,,,,4.15923735,,,,,,4.30235055,,,,
,8685362.03,4.30090025,-47691.029,-0.124096473145563,8.48142772913033E-5,1,9.99253354069792,40.0298881530762,1.99981838838835,14.8900002241135,-1.37311006258481,-0.257816630720645,2.5,-0.00117799954375973,-0.123485652570357,-0.00173008465150448,4.3008466,4.3009539,-48176.863,-47205.195,52.5082406648902,18.4050439732708,93.108131,0,0,0,400,4961,4.20295,-47691.029,,,,,,,,,,,,,0,,,,4.28513335,,,,,,4.30090025,,,,
,8685442.03,4.30093575,-55434.8515,-0.178525578411632,0.000114009783985202,1,9.99253354069792,40.0298881530762,2.00003438398058,14.8900002241135,-1.97700113879842,-0.370403830637092,25,-0.00156392437019455,-0.177710741608362,-0.00242031601650959,4.3005209,4.3013506,-55911.223,-54958.48,52.7708678473517,18.4128000151563,93.108131,0,0,0,400,4961,4.2024,-55434.8515,,,,,,,,,,,,,0,,,,4.3496659,,,,,,4.30093575,,,,
,8685512.015,4.3023684,-62214.0645,-0.238990996657228,0.000135087935960369,1,9.99253354069792,40.0298881530762,1.99967501728481,14.8900002241135,-2.64707336998742,-0.495646852418389,25,-0.00200208020575563,-0.237979358914404,-0.00321513813400137,4.3020153,4.3027215,-62690.859,-61737.27,52.7317864213902,18.4156626820095,93.489342,0,0,0,400,4961,4.2008,-62214.0645,,,,,,,,,,,,,0,,,,4.3496659,,,,,,4.3023684,,,,
,8685581.91,4.3009548,-68987.7695,-0.306809899892298,0.000143404071427841,1,9.99253354069792,40.0298881530762,1.99983072276712,14.8900002241135,-3.39953094083752,-0.637326889076521,25,-0.0025628014145936,-0.305616490520717,-0.00419732271215108,4.3008895,4.3010201,-69466.258,-68509.281,51.4835256761785,18.4115567944638,93.489342,0,0,0,400,4961,4.1998,-68987.7695,,,,,,,,,,,,,0,,,,4.2225063,,,,,,4.3009548,,,,
,8685651.89,4.2994525,-75768.3905,-0.375615035304713,0.00013966558324223,1,9.99253354069792,40.0298881530762,1.99976038692537,14.8900002241135,-4.16321591864569,-0.780707359245533,25,-0.00307259012257098,-0.374287233653234,-0.00515856978015246,4.2991199,4.2997851,-76252.672,-75284.109,51.7555324008709,18.4137971319338,92.726921,0,0,0,400,4961,4.20145,-75768.3905,,,,,,,,,,,,,0,,,,4.0155734,,,,,,4.2994525,,,,
,8685721.765,4.2993295,-82525.8635,-0.440709142209529,0.000130293560789266,1,9.99253354069792,40.0298881530762,1.99980822000217,14.8900002241135,-4.88664230031618,-0.916012241240114,25,-0.00348887889765694,-0.439310281223081,-0.00602384472157808,4.2980032,4.3006558,-83004.641,-82047.086,51.5476192147555,18.4157185092095,92.345711,0,0,0,400,4961,4.20225,-82525.8635,,,,,,,,,,,,,0,,,,3.9839928,,,,,,4.2993295,,,,
,8685791.725,4.29885485,-88955.367,-0.497742500439451,0.000120313935196577,1,9.99253354069792,40.0298881530762,1.99972752979399,14.8999998345971,-5.5208793745004,-1.03409277863116,25,-0.00379091790866374,-0.496335333626085,-0.00673552928750239,4.2972918,4.3004179,-89439.648,-88471.086,52.7192803650825,18.4191756571691,93.108131,0,0,0,400,4961,4.20355,-88955.367,,,,,,,,,,,,,0,,,,4.2636232,,,,,,4.29885485,,,,
,8685861.67,4.2969725,-95711.551,-0.55282745911529,0.000112750811351238,1,9.99253354069792,40.0298881530762,1.99969718646543,14.8999998345971,-6.13401861350828,-1.14896263957329,25,-0.00413472149352745,-0.551465872299375,-0.0074858790024111,4.2966232,4.2973218,-96186.508,-95236.594,50.6135731342746,18.4188675861046,92.345711,0,0,0,400,4961,4.20685,-95711.551,,,,,,,,,,,,,0,,,,4.24253865,,,,,,4.2969725,,,,
,8685931.605,4.29570365,-102462.2305,-0.603966340217431,0.000103687307418226,1,9.99253354069792,40.0298881530762,1.99991208025646,14.8900002241135,-6.70469487423476,-1.25508407267672,25,-0.00438032333726981,-0.602697584730006,-0.00811427504212092,4.295517,4.2958903,-102937.047,-101987.414,52.6606582261402,18.4232805546162,93.108131,0,0,0,400,4961,4.20945,-102462.2305,,,,,,,,,,,,,0,,,,4.2636232,,,,,,4.29570365,,,,
,8686001.61,4.2958212,-109221.383,-0.652292741414212,0.000100009343456482,1,9.99253354069792,40.0298881530762,1.99986460648278,14.8900002241135,-7.24355107945549,-1.35623173177518,25,-0.00469528853382229,-0.651155365568258,-0.00879069983826291,4.2955313,4.2961111,-109703.688,-108739.078,51.7203591175055,18.4164729060019,92.345711,0,0,0,400,4961,4.2119,-109221.383,,,,,,,,,,,,,0,,,,4.30642985,,,,,,4.2958212,,,,
,8686071.535,4.2968221,-115968.5275,-0.698584527338785,9.74963650900125E-5,1,9.99253354069792,40.0298881530762,1.9999697704102,14.8900002241135,-7.76082271024578,-1.45249096418753,25,-0.00492916712771875,-0.697611161373886,-0.00936651822308352,4.296351,4.2972932,-116445.461,-115491.594,52.5051141508132,18.4194022001805,93.108131,0,0,0,400,4961,4.21285,-115968.5275,,,,,,,,,,,,,0,,,,4.32815575,,,,,,4.2968221,,,,
,8686141.485,4.29833985,-122696.184,-0.743459331094243,9.66255343995255E-5,1,9.99253354069792,40.0298881530762,1.99987825997664,14.8900002241135,-8.26192160573002,-1.54560979877057,25,-0.00515254673411382,-0.742676878062791,-0.00991380841185209,4.2983375,4.2983422,-123186.68,-122205.688,52.7880636747748,18.4175503456309,93.108131,0,0,0,400,4961,4.2135,-122696.184,,,,,,,,,,,,,0,,,,4.3496659,,,,,,4.29833985,,,,
,8686211.45,4.299829,-129175.1955,-0.785551151482034,9.30684845327676E-5,1,9.99253354069792,40.0298881530762,1.99979161349574,14.8900002241135,-8.73216092559425,-1.63323780519574,25,-0.00539255653489343,-0.784974840730295,-0.0104486687604714,4.2995291,4.3001289,-129625.375,-128725.016,52.4003759292363,18.4240180729302,93.489342,0,0,0,400,4961,4.21025,-129175.1955,,,,,,,,,,,,,0,,,,4.30685925,,,,,,4.299829,,,,
,8686281.385,4.3008199,-135864.383,-0.828439099848587,9.39451019548548E-5,1,9.99253354069792,40.0298881530762,1.99993336748541,14.8999998345971,-9.21244354883971,-1.72317290627422,25,-0.00568606903254736,-0.828095014720122,-0.0110317069429327,4.2998686,4.3017712,-136338.641,-135390.125,51.2255882648323,18.4181188964983,93.108131,0,0,0,400,4961,4.2117,-135864.383,,,,,,,,,,,,,0,,,,4.3713918,,,,,,4.3008199,,,,
,8686381.76,4.30132075,-139341.453,-0.851034447944787,0.000106236341042422,1,9.99253354069792,40.0298881530762,1.99975990000568,14.8900002241135,-9.46468961481155,-1.76896027939556,25,-0.00571988109265196,-0.850818778453742,-0.0112132534877832,4.3007197,4.3019218,-139837.328,-138845.578,51.3217285726977,18.4227709502057,93.108131,0,0,0,400,4961,4.21165,-139341.453,,,,,,,,,,,,,0,,,,4.3713918,,,,,,4.30132075,,,,
,8686451.23,4.2993481,-132380.4535,-0.80635252216902,9.79205405257652E-5,1,9.99253354069792,40.0298881530762,1.99973375020125,14.8999998345971,-8.96409830502533,-1.67904394031612,25,-0.00573985500798618,-0.805883720896597,-0.010937674276019,4.2992315,4.2994647,-132883.094,-131877.813,52.2073136849863,18.4088116873611,92.345711,0,0,0,400,4961,4.21045,-132380.4535,,,,,,,,,,,,,0,,,,4.32815575,,,,,,4.2993481,,,,
,8686521.175,4.3004091,-125405.7735,-0.761357135695241,9.7516922451513E-5,1,9.99253354069792,40.0298881530762,1.99971635064254,14.8900002241135,-8.46091717863918,-1.58502603911051,25,-0.00545644734092464,-0.760656944525627,-0.0103439772005778,4.3003807,4.3004375,-125895.844,-124915.703,52.0306656396401,18.4077896843641,93.108131,0,0,0,400,4961,4.2108,-125405.7735,,,,,,,,,,,,,0,,,,4.32794,,,,,,4.3004091,,,,
,8686591.155,4.3002102,-118423.762,-0.715314950889143,0.000101109386433694,1,9.99253354069792,40.0298881530762,1.99980900784409,14.8900002241135,-7.94696473504412,-1.48794277845916,25,-0.00508653121769462,-0.71440754864934,-0.00964537906573985,4.3001084,4.300312,-118922.727,-117924.797,52.2010606568324,18.4160457722178,93.108131,0,0,0,400,4961,4.21115,-118423.762,,,,,,,,,,,,,0,,,,4.3713918,,,,,,4.3002102,,,,
,8686661.125,4.30002855,-111447.9685,-0.667838576882635,0.000100531959578346,1,9.99253354069792,40.0298881530762,1.99995215390243,14.8900002241135,-7.41722009657752,-1.38954623815404,25,-0.00485987141675609,-0.666751320520962,-0.00907055812181256,4.2998843,4.3001728,-111932.953,-110962.984,51.495250103967,18.4123190561979,93.108131,0,0,0,400,4961,4.2107,-111447.9685,,,,,,,,,,,,,0,,,,4.10519865,,,,,,4.30002855,,,,
,8686731.05,4.29963275,-104458.621,-0.618610750769282,0.000106675240077666,1,9.99253354069792,40.0298881530762,1.99964177781114,14.8900002241135,-6.86694442732951,-1.28637800846332,25,-0.00454854405393654,-0.617376378797865,-0.00839196933834519,4.2992992,4.2999663,-104968.32,-103948.922,52.7388210780633,18.4148673774538,92.726921,0,0,0,400,4961,4.21075,-104458.621,,,,,,,,,,,,,0,,,,4.30642985,,,,,,4.29963275,,,,
,8686801.05,4.30012395,-97481.844,-0.566588334378833,0.000113748317155498,1,9.99253354069792,40.0298881530762,1.99975371707468,14.8999998345971,-6.28739634100777,-1.17814669956362,25,-0.00425873290538042,-0.565246519734152,-0.00771246025103222,4.299933,4.3003149,-97981.938,-96981.75,52.3597312462363,18.4167262405099,92.726921,0,0,0,400,4961,4.2113,-97481.844,,,,,,,,,,,,,0,,,,4.3496659,,,,,,4.30012395,,,,
,8686871.01,4.29955075,-90485.7145,-0.510740426611982,0.000123401877802957,1,9.99253354069792,40.0298881530762,1.99982643319813,14.8900002241135,-5.66558692851419,-1.06235433869702,25,-0.00397319953136419,-0.509338075404134,-0.00701248702431156,4.2992625,4.299839,-90980.023,-89991.406,51.1849435818323,18.4085488285353,93.108131,0,0,0,400,4961,4.2116,-90485.7145,,,,,,,,,,,,,0,,,,4.0812342,,,,,,4.29955075,,,,
,8686940.9,4.2996552,-83501.7305,-0.44984109743735,0.000135547540997878,1,9.99253354069792,40.0298881530762,1.99978564118653,14.8900002241135,-4.98805081521269,-0.935345070445975,25,-0.00357781654960444,-0.448436665151367,-0.00617709348320963,4.2991676,4.3001428,-84003.805,-82999.656,52.3534782180825,18.4099799143256,91.9645,0,0,0,400,4961,4.2119,-83501.7305,,,,,,,,,,,,,0,,,,4.3496659,,,,,,4.2996552,,,,
,8687010.89,4.3011751,-76497.832,-0.383100690860337,0.000144106405716121,1,9.99253354069792,40.0298881530762,1.99994179705404,14.8900002241135,-4.24675029502011,-0.796190357101333,25,-0.00310948284516751,-0.381761323628115,-0.00524579041771977,4.3003368,4.3020134,-77011.203,-75984.461,51.7234856315824,18.411611552601,92.726921,0,0,0,400,4961,4.2094,-76497.832,,,,,,,,,,,,,0,,,,4.02679945,,,,,,4.3011751,,,,
,8687080.8,4.3020215,-69506.086,-0.312118128628127,0.000150938792887819,1,9.99253354069792,40.0298881530762,1.99971192838551,14.8999998345971,-3.45820351184047,-0.648558582962097,25,-0.00262179564339504,-0.310912333501038,-0.00429021399251139,4.30164,4.302403,-70008.727,-69003.445,52.6645663687363,18.4097019474045,92.345711,0,0,0,400,4961,4.20835,-69506.086,,,,,,,,,,,,,0,,,,4.28513335,,,,,,4.3020215,,,,
,8687150.735,4.3022921,-62522.381,-0.241654572718031,0.000141403069529391,1,9.99253354069792,40.0298881530762,1.99977511902365,14.8900002241135,-2.67674548497874,-0.501200271050329,25,-0.00202131224528225,-0.240635383344956,-0.00325080537483741,4.3020763,4.3025079,-63026.574,-62018.188,51.7867975416401,18.4102854425525,92.345711,0,0,0,400,4961,4.20525,-62522.381,,,,,,,,,,,,,0,,,,4.2636232,,,,,,4.3022921,,,,
,8687220.685,4.29905485,-55496.59,-0.17894729400922,0.000117442107519671,1,9.99253354069792,40.0298881530762,1.99976351243239,14.8900002241135,-1.98142353193446,-0.371211176802426,25,-0.00156530145815962,-0.178131067182399,-0.00242419747799265,4.29881,4.2992997,-56001.207,-54991.973,50.8566596037554,18.4126279832408,93.489342,0,0,0,400,4961,4.20265,-55496.59,,,,,,,,,,,,,0,,,,3.88238665,,,,,,4.29905485,,,,
,8687290.695,4.30013035,-48491.9825,-0.128922826103875,8.89802339409536E-5,1,9.99253354069792,40.0298881530762,1.99969296149992,14.8900002241135,-1.42691812021174,-0.267844328695803,25,-0.00121251503029181,-0.128292869593866,-0.00179088947852544,4.2999544,4.3003063,-48984.879,-47999.086,51.9798597858901,18.4088262758205,93.108131,0,0,0,400,4961,4.2065,-48491.9825,,,,,,,,,,,,,0,,,,4.03885315,,,,,,4.30013035,,,,
,8687360.59,4.30166885,-41475.787,-0.0919848418496998,6.48679143361625E-5,1,9.99253354069792,40.0298881530762,1.99955066337689,14.8900002241135,-1.01769673528042,-0.191111786413141,25,-0.000902596491757613,-0.0915076323906413,-0.00128448721217602,4.301455,4.3018827,-41973.906,-40977.668,53.5634391658518,18.4082573167794,91.9645,0,0,0,400,4961,4.20525,-41475.787,,,,,,,,,,,,,0,,,,4.2423267,,,,,,4.30166885,,,,
,8687430.565,4.30020115,-34450.127,-0.0654256253666148,4.67563778467704E-5,1,9.99253354069792,40.0298881530762,1.99966572317348,14.8900002241135,-0.72357812806864,-0.136542367812698,25,-0.000722629788476887,-0.0650679565135339,-0.00097091984216133,4.2997794,4.3006229,-34944.574,-33955.68,51.7227040030632,18.4077900768783,92.345711,0,0,0,400,4961,4.2051,-34450.127,,,,,,,,,,,,,0,,,,4.1586151,,,,,,4.30020115,,,,
,8687500.49,4.29778005,-27427.141,-0.0461028882751589,3.52117638095799E-5,1,9.99253354069792,40.0298881530762,1.99975382296957,14.8900002241135,-0.509756485218521,-0.0962886313344311,25,-0.00053411956512888,-0.0458394913761917,-0.000692280509985676,4.297658,4.2979021,-27933.596,-26920.686,52.2659358239286,18.4066026444413,92.345711,0,0,0,400,4961,4.20745,-27427.141,,,,,,,,,,,,,0,,,,3.90284895,,,,,,4.29778005,,,,
,8687581.565,4.29809525,-19233.318,-0.029530222138936,2.6870021850917E-5,1,9.99253354069792,40.0298881530762,1.99962572238171,14.8900002241135,-0.326293161389029,-0.0617620593877044,2.5,-0.000365841495870514,-0.0293541975001885,-0.000454442158999529,4.2978802,4.2983103,-19618.74,-18847.896,52.1877729720055,18.4047786154531,93.108131,0,0,0,400,4961,4.20905,-19233.318,,,,,,,,,,,,,0,,,,4.2001576,,,,,,4.29809525,,,,
,8687650.345,4.2988372,-12258.746,-0.017734691387489,2.29209951369266E-5,1,9.99253354069792,40.0298881530762,1.99949582183308,14.8900002241135,-0.195928000258511,-0.0369952558824752,2.5,-0.000218033463912119,-0.0176259293602919,-0.000264987032679126,4.2983384,4.299336,-12771.558,-11745.934,52.2268543979671,18.4055797991059,93.108131,0,0,0,400,4961,4.21035,-12258.746,,,,,,,,,,,,,0,,,,4.1586151,,,,,,4.2988372,,,,
,8687720.315,4.2996407,-5071.1515,-0.00716580113314698,4.37796404553659E-5,1,9.99253354069792,40.0298881530762,1.99951433982078,14.8900002241135,-0.0791382540039386,-0.0150432585089284,2.5,-9.92684452842262E-5,-0.0071208280962162,-0.000115770210102006,4.2996407,4.2996407,-5586.794,-4555.509,51.4835256761785,18.4061574434397,92.726921,0,0,0,400,4961,4.20975,-5071.1515,,,,,,,,,,,,,0,,,,3.7782842,,,,,,4.2996407,,,,
,8687817.575,4.299305,4716.416,0.00593496224007403,7.65871096904767E-5,1,9.99253354069792,40.0298881530762,1.99962448420847,14.8999998345971,0.0655632499675273,0.0123736992449663,2.5,7.45186885125659E-5,0.00589769818423285,8.81445504929899E-5,4.299305,4.299305,4707.519,4725.313,52.1572894597555,18.406565165995,93.489342,0,0,0,400,4961,4.2098,4716.416,,,,,,,,,,,,,0,,,,4.076148,,,,,,4.299305,,,,
,8687880.2,4.3000064,10691.9795,0.0155390991013675,4.7039210345938E-5,1,9.99253354069792,40.0298881530762,1.99960249790073,14.8900002241135,0.171665848763814,0.0324653830103325,2.5,0.000196715493783882,0.0154432607980043,0.000236631835928116,4.2999401,4.3000727,10207.13,11176.829,52.1330589756594,18.4039254766916,93.108131,0,0,0,400,4961,4.2084,10691.9795,,,,,,,,,,,,,0,,,,3.84839585,,,,,,4.3000064,,,,
,8687950.125,4.30119445,17413.3445,0.0262542017837014,2.65068804295572E-5,1,9.99253354069792,40.0298881530762,1.99955402310005,14.8900002241135,0.290071981659381,0.0548988469629133,2.5,0.000327086087632684,0.0260964334482621,0.000403388697360803,4.3010869,4.301302,16935.701,17890.988,52.5840586312556,18.4068482554365,93.108131,0,0,0,400,4961,4.2072,17413.3445,,,,,,,,,,,,,0,,,,4.22124215,,,,,,4.30119445,,,,
,8688020.105,4.3012867,24201.5235,0.0390948365219033,2.99451444514714E-5,1,9.99253354069792,40.0298881530762,1.99937114179511,14.8900002241135,0.432014776820763,0.0816103598548373,2.5,0.000460029243983667,0.0388674747662833,0.00058754946255854,4.3009605,4.3016129,23722.467,24680.58,51.4671114772747,18.4043421187036,92.345711,0,0,0,400,4961,4.2069,24201.5235,,,,,,,,,,,,,0,,,,4.17969965,,,,,,4.3012867,,,,
,8688090.085,4.3022592,31029.6295,0.0554250681114594,3.96581758457626E-5,1,9.99253354069792,40.0298881530762,1.99952899566722,14.8900002241135,0.612690824313359,0.11553556794473,2.5,0.000614671142823927,0.0551152493399407,0.000815295248909951,4.3015938,4.3029246,30537.441,31521.818,52.1307140901017,18.4066405048786,92.345711,0,0,0,400,4961,4.2057,31029.6295,,,,,,,,,,,,,0,,,,4.15923735,,,,,,4.3022592,,,,
,8688160.02,4.3011408,37873.6855,0.0773481642752952,5.3382022220877E-5,1,9.99253354069792,40.0298881530762,1.99939759727382,14.8900002241135,0.85519288224372,0.161318512507024,2.5,0.00083580019328179,0.0769354407416412,0.00114277674732186,4.3002539,4.3020277,37371.043,38376.328,52.1025754634094,18.4069016910187,93.108131,0,0,0,400,4961,4.20455,37873.6855,,,,,,,,,,,,,0,,,,4.22124215,,,,,,4.3011408,,,,
,8688229.985,4.2999952,44713.0745,0.107627277049542,7.45145458773982E-5,1,9.99253354069792,40.0298881530762,1.99937153089722,14.8900002241135,1.19030088198395,0.224477947140878,2.5,0.00112267395900789,0.107083185972256,0.00158594688633883,4.2995367,4.3004537,44213.965,45212.184,51.8985704198901,18.3999604790785,92.345711,0,0,0,400,4961,4.204,44713.0745,,,,,,,,,,,,,0,,,,3.88451635,,,,,,4.2999952,,,,
,8688299.9,4.301774,51555.42,0.149261651877681,0.000100602720702071,1,9.99253354069792,40.0298881530762,1.99941614440232,14.8999998345971,1.65139499082622,0.310853009334334,2.5,0.0014594758958814,0.148552684277879,0.00214952866665814,4.301331,4.302217,51071.281,52039.559,53.300030354871,18.4058157465192,91.9645,0,0,0,400,4961,4.204,51555.42,,,,,,,,,,,,,0,,,,4.17969965,,,,,,4.301774,,,,
,8688379.815,4.30163,59364.35,0.212549973427343,0.000129137040311378,1,9.99253354069792,40.0298881530762,1.99944754499592,14.8900002241135,2.35343892239274,0.441724221768323,25,0.00189675088658408,0.211619838147464,0.00295097928702885,4.3013663,4.3018937,58879.93,59848.77,52.1721404016209,18.4028503878835,92.726921,0,0,0,400,4961,4.20165,59364.35,,,,,,,,,,,,,0,,,,4.03583205,,,,,,4.30163,,,,
,8688449.845,4.3006537,66222.6525,0.278738796141745,0.000144535607018402,1,9.99253354069792,40.0298881530762,1.99948205893174,14.8900002241135,3.08750836552448,0.579011692022592,25,0.00237145033799829,0.2776149066245,0.00382849424315959,4.3001862,4.3011212,65723.969,66721.336,51.6242188096401,18.4068504847403,92.345711,0,0,0,400,4961,4.20195,66222.6525,,,,,,,,,,,,,0,,,,4.15923735,,,,,,4.3006537,,,,
,8688519.725,4.29845735,73046.7695,0.348651734069553,0.000144277940806671,1,9.99253354069792,40.0298881530762,1.99939363628222,14.8900002241135,3.86312099705823,0.72446284860495,25,0.00288454301763713,0.347369204446987,0.00479025207680401,4.2982907,4.298624,72562.914,73530.625,52.4246064133325,18.4049268920418,92.345711,0,0,0,400,4961,4.2033,73046.7695,,,,,,,,,,,,,0,,,,4.17928265,,,,,,4.29845735,,,,
,8688589.655,4.2988539,79890.668,0.416212117076654,0.000135730434195626,1,9.99253354069792,40.0298881530762,1.9993259264213,14.8900002241135,4.61321829816044,0.865205772045461,25,0.00336398105362759,0.414832036651742,0.00572707736610296,4.2986093,4.2990985,79401.867,80379.469,52.5316895204671,18.4052305232879,92.726921,0,0,0,400,4961,4.20475,79890.668,,,,,,,,,,,,,0,,,,4.22124215,,,,,,4.2988539,,,,
,8688659.615,4.29854775,86403.9375,0.47573618762913,0.000126265178693269,1,9.99253354069792,40.0298881530762,1.99931429334853,14.8900002241135,5.27481924497812,0.989137871919892,25,0.00375067790293914,0.474325206458464,0.00653533480578528,4.2984047,4.2986908,85923.047,86884.828,52.4113187285055,18.4033954297784,93.108131,0,0,0,400,4961,4.2064,86403.9375,,,,,,,,,,,,,0,,,,4.1586151,,,,,,4.29854775,,,,
,8688729.575,4.29828,93223.8165,0.533122873318545,0.000115844519206918,1,9.99253354069792,40.0298881530762,1.99948888048246,14.8900002241135,5.91369717763895,1.10942137687822,25,0.00416383327764953,0.531737492163419,0.00736812947836112,4.2980132,4.2985468,92730.922,93716.711,52.6536235694671,18.39509072219,92.726921,0,0,0,400,4961,4.2068,93223.8165,,,,,,,,,,,,,0,,,,4.2003672,,,,,,4.29828,,,,
,8688809.48,4.30371715,101017.34,0.593340127428993,0.000107984184222593,1,9.99253354069792,40.0298881530762,1.99927491923127,14.8900002241135,6.58400791243079,1.23366834780315,25,0.00441909176185267,0.592047334570542,0.00807309306810021,4.3019023,4.305532,100534.758,101499.922,52.1189896623132,18.4043541498861,93.489342,0,0,0,400,4961,4.20485,101017.34,,,,,,,,,,,,,0,,,,3.9110229,,,,,,4.30371715,,,,
,8688879.515,4.29942655,107845.8355,0.642713562688354,0.000100067997932152,1,9.99253354069792,40.0298881530762,1.9993157895219,14.8900002241135,7.13470316324582,1.33631232515691,25,0.00467715265477767,0.641546222037969,0.00870098830644691,4.2985392,4.3003139,107367.773,108323.898,53.5689105654864,18.4040112343514,92.345711,0,0,0,400,4961,4.20675,107845.8355,,,,,,,,,,,,,0,,,,4.2003672,,,,,,4.29942655,,,,
,8688949.445,4.29930495,114644.254,0.689766583520541,9.93667880168766E-5,1,9.99253354069792,40.0298881530762,1.99944427125718,14.8900002241135,7.66033286740608,1.43412307876196,25,0.00491329785410755,0.688758325391189,0.00928583855715923,4.2992816,4.2993283,114154.469,115134.039,52.6950498809863,18.4066258022421,93.108131,0,0,0,400,4961,4.2072,114644.254,,,,,,,,,,,,,0,,,,4.1584077,,,,,,4.29930495,,,,
,8689019.36,4.29912425,121444.082,0.735332382590667,9.8745996646562E-5,1,9.99253354069792,40.0298881530762,1.99940335085937,14.8900002241135,8.16895362175136,1.52984147062367,25,0.0052428700756738,0.734511512626053,0.00994589659061566,4.2990141,4.2992344,120956.695,121931.469,53.5579677662172,18.3980802854645,93.108131,0,0,0,400,4961,4.20725,121444.082,,,,,,,,,,,,,0,,,,4.01958155,,,,,,4.29912425,,,,
,8689089.31,4.2994182,128236.0625,0.779725771237446,9.35529291202985E-5,1,9.99253354069792,40.0298881530762,1.99933131825175,14.8900002241135,8.66469341490478,1.62294843961128,25,0.00555746755570154,0.779116894899447,0.0105731118676904,4.299139,4.2996974,127754.414,128717.711,52.9193772660056,18.3977732296628,92.726921,0,0,0,400,4961,4.20855,128236.0625,,,,,,,,,,,,,0,,,,4.17928265,,,,,,4.2994182,,,,
,8689159.29,4.29986265,134765.2345,0.821449214954187,9.30058363334312E-5,1,9.99253354069792,40.0298881530762,1.99937307083895,14.8900002241135,9.13147499861635,1.70984128401657,25,0.00579643539428181,0.821064675078566,0.0110956159051483,4.2994676,4.3002577,134276.719,135253.75,52.5535751190056,18.3993463631132,93.108131,0,0,0,400,4961,4.2084,134765.2345,,,,,,,,,,,,,0,,,,4.17969965,,,,,,4.29986265,,,,
,8689229.22,4.298589,140001.5705,0.854913729622322,3.09006343037772E-5,1,9.99253354069792,40.0298881530762,1.99930173668289,14.8999998345971,9.50559097291038,1.77913864852095,25,0.00596651920308211,0.854721481594327,0.0114848660816398,4.2982159,4.2989621,140000.938,140002.203,52.3808352162555,18.4007446540105,92.726921,0,0,0,400,4929,4.20965,140001.5705,,,,,,,,,,,,,0,,,,4.1203599,,,,,,4.298589,,,,
,8696643.735,2.50322625,134486.172,0.818846699615892,0.00011466550123177,1,9.99253354069792,40.0298881530762,1.99909491780896,14.8999998345971,9.10170219919306,1.70143567740919,25,0.00553223874836759,0.818454036734533,0.0108143522386955,2.4988067,2.5076458,133902.469,135069.875,53.4868395709672,18.3916481582424,93.108131,0,0,0,400,4961,2.3084,134486.172,,,,,,,,,,,,,0,,,,3.6888095,,,,,,2.50322625,,,,
,8696713.665,2.5016204,126174.043,0.765452406113371,0.000114675921195277,1,9.99253354069792,40.0298881530762,1.99913356477247,14.8900002241135,8.50478899512161,1.59084709536534,25,0.00527473447925281,0.764778564135208,0.010191681239916,2.4989049,2.5043359,125578.898,126769.188,52.5731158319863,18.389976511191,92.345711,0,0,0,400,4961,2.3087,126174.043,,,,,,,,,,,,,0,,,,3.6888095,,,,,,2.5016204,,,,
,8696783.64,2.4966642,117880.984,0.710614317495756,0.000117562874534679,1,9.99253354069792,40.0298881530762,1.99929560734196,14.8999998345971,7.89281593973753,1.47644640128525,25,0.00493791095412785,0.709693870304488,0.00946375359729593,2.4933496,2.4999788,117291.773,118470.195,53.2453163585249,18.3927906308643,93.108131,0,0,0,400,4961,2.3142,117880.984,,,,,,,,,,,,,0,,,,3.7256589,,,,,,2.4966642,,,,
,8696853.58,2.5014763,109559.5465,0.653957156663526,0.000125123769575183,1,9.99253354069792,40.0298881530762,1.99905354442511,14.8900002241135,7.25943694771611,1.35864015729522,25,0.00465542030202607,0.652828632296863,0.00876410991226081,2.4977398,2.5052128,108963.695,110155.398,52.3456619328902,18.394633111408,91.9645,0,0,0,400,4961,2.3146,109559.5465,,,,,,,,,,,,,0,,,,3.72584485,,,,,,2.5014763,,,,
,8696923.51,2.50153505,101253.93,0.594087848913948,0.000129864002942013,1,9.99253354069792,40.0298881530762,1.99924549067681,14.8900002241135,6.59266546509421,1.23315397037264,25,0.00423639053171448,0.592801955232662,0.00789773737923183,2.5004444,2.5026257,100664.719,101843.141,52.8787325830056,18.4008236380299,92.726921,0,0,0,400,4961,2.3227,101253.93,,,,,,,,,,,,,0,,,,3.72584485,,,,,,2.50153505,,,,
,8696993.475,2.50017765,92918.5155,0.529774897515852,0.000140454540484342,1,9.99253354069792,40.0298881530762,1.99913904927003,14.8900002241135,5.87584669397802,1.10018580783946,25,0.00395503980887337,0.528390507159891,0.00713626235265942,2.4994493,2.500906,92321.961,93515.07,52.8662265266979,18.3935787319426,93.108131,0,0,0,400,4961,2.3155,92918.5155,,,,,,,,,,,,,0,,,,3.74436165,,,,,,2.50017765,,,,
,8697063.4,2.49796395,84585.6405,0.458978665397606,0.000157258447084807,1,9.99253354069792,40.0298881530762,1.99925380875485,14.8900002241135,5.08864883705204,0.952611390229147,25,0.00349849581044017,0.457573170956834,0.00616414141030254,2.4953485,2.5005794,83988.523,85182.758,53.8706191739095,18.4005445092777,92.345711,0,0,0,400,4961,2.31245,84585.6405,,,,,,,,,,,,,0,,,,3.7447352,,,,,,2.49796395,,,,
,8697133.375,2.49588475,76251.918,0.380293993702602,0.0001716168795447,1,9.99253354069792,40.0298881530762,1.99926910443122,14.8900002241135,4.21440987258517,0.789045353534613,25,0.00299522309911339,0.378959926943659,0.00511330668192755,2.4938507,2.4979188,75651.406,76852.43,51.7383365734478,18.3967100958751,92.345711,0,0,0,400,4961,2.3149,76251.918,,,,,,,,,,,,,0,,,,3.7630644,,,,,,2.49588475,,,,
,8697203.34,2.49635375,67901.1055,0.295886834841703,0.000175460810201471,1,9.99253354069792,40.0298881530762,1.99929649770409,14.8900002241135,3.27775520176338,0.612884178465074,25,0.00234213261175125,0.29472002033675,0.0039075407528542,2.4959242,2.4967833,67314.289,68487.922,52.3777087021786,18.3956497377199,92.345711,0,0,0,400,4961,2.3155,67901.1055,,,,,,,,,,,,,0,,,,3.6893617,,,,,,2.49635375,,,,
,8697273.275,2.50243165,59567.805,0.214681744569341,0.000156811091066251,1,9.99253354069792,40.0298881530762,1.99934368084291,14.8900002241135,2.37730763995151,0.444120001234409,25,0.00173217404043968,0.213745286531428,0.00279954015107545,2.4994805,2.5053828,58966.727,60168.883,52.720843622121,18.4063483600051,92.345711,0,0,0,400,4961,2.30625,59567.805,,,,,,,,,,,,,0,,,,3.50908195,,,,,,2.50243165,,,,
,8697343.275,2.50241445,51204.555,0.147396116573467,0.000121386926705778,1,9.99253354069792,40.0298881530762,1.99947796584144,14.8999998345971,1.63169437847527,0.304651685875292,25,0.00122595315117744,0.146694617509074,0.00190608758301236,2.4974222,2.5074067,50616.895,51792.215,52.3691107884671,18.4059354725599,93.108131,0,0,0,400,4961,2.30605,51204.555,,,,,,,,,,,,,0,,,,3.652689,,,,,,2.50241445,,,,
,8697413.195,2.50739385,42843.406,0.0988108086889134,8.38247646842951E-5,1,9.99253354069792,40.0298881530762,1.99947651986457,14.8999998345971,1.09330925359743,0.20491286969356,25,0.000928311752994342,0.0983039243736556,0.00134530354113114,2.5051968,2.5095909,42233.148,43453.664,52.280786765794,18.4035929714766,90.439651,0,0,0,400,4965,2.2923,42843.406,,,,,,,,,,,,,0,,,,3.74436165,,,,,,2.50739385,,,,
,8697483.2,2.50297085,34477.717,0.0659222786059502,5.57965669392449E-5,1,9.99253354069792,40.0298881530762,1.99942573030689,14.8900002241135,0.729152184845058,0.136634977449355,25,0.000644251998815665,0.0655622713777813,0.000894973879426082,2.5006378,2.5053039,33885.25,35070.184,51.7250488886209,18.4062733754763,92.345711,0,0,0,400,4965,2.31265,34477.717,,,,,,,,,,,,,0,,,,3.3514452,,,,,,2.50297085,,,,
,8697553.1,2.49998105,26107.7615,0.0435014291487428,3.90991516935643E-5,1,9.99253354069792,40.0298881530762,1.9992744552501,14.8900002241135,0.481005781539964,0.0900122776151311,25,0.000433080562694942,0.0432512819646962,0.000579739375718928,2.4972832,2.5026789,25507.107,26708.416,53.7486851249095,18.4020308720142,92.726921,0,0,0,400,4965,2.30375,26107.7615,,,,,,,,,,,,,0,,,,3.63380955,,,,,,2.49998105,,,,
,8697633.01,2.49645315,16465.741,0.0250700737956121,2.9311412357518E-5,1,9.99253354069792,40.0298881530762,1.99930206817009,14.8900002241135,0.277060612177496,0.0517807381686278,2.5,0.000256244000746591,0.0249189738148505,0.000328227106409301,2.4946067,2.4982996,15848.701,17082.781,53.6158082766403,18.4071466649595,92.345711,0,0,0,400,4965,2.3161,16465.741,,,,,,,,,,,,,0,,,,3.56192755,,,,,,2.49645315,,,,
,8697702.98,2.50389995,7955.2575,0.0117918192388296,7.67945142072247E-5,1,9.99253354069792,40.0298881530762,1.99924733284802,14.8999998345971,0.130422803358451,0.0235854637453042,2.5,5.63795452750978E-5,0.0117186796079913,8.57159644615557E-5,2.4986043,2.5091956,7335.531,8574.984,53.1710616491979,18.4039259073623,93.108131,0,0,0,400,4965,2.31705,7955.2575,,,,,,,,,,,,,0,,,,3.6519601,,,,,,2.50389995,,,,
,8697789.84,2.4993467,-2650.3,-0.0029276862099044,5.18913152171473E-5,1,9.99253354069792,40.0298881530762,1.9994804691061,14.8900002241135,-0.0323506987114852,-0.00609221297241817,0.25,-3.58402507039644E-5,-0.00290921462104878,-4.23239591581931E-5,2.4993467,2.4993467,-2685.326,-2615.274,52.9404812360248,18.4061402121794,92.345711,0,0,0,400,4965,2.30495,-2650.3,,,,,,,,,,,,,0,,,,3.615659,,,,,,2.4993467,,,,
,8697862.83,2.4996202,-10946.9135,-0.0164435742815501,3.02927891137142E-5,1,9.99253354069792,40.0298881530762,1.99964175414146,14.8999998345971,-0.181721490704718,-0.0340195228121097,2.5,-0.000177582127984016,-0.0163423238920692,-0.000220212434857979,2.4928889,2.5063515,-11522.575,-10371.252,52.1416568893709,18.4137515912744,93.108131,0,0,0,400,4965,2.3135,-10946.9135,,,,,,,,,,,,,0,,,,3.56406055,,,,,,2.4996202,,,,
,8697932.765,2.50828765,-18998.254,-0.029547464748275,3.01917673126769E-5,1,9.99253354069792,40.0298881530762,1.99928104576452,14.8900002241135,-0.326500171112512,-0.0613761382948118,2.5,-0.000329258465203318,-0.029371255978043,-0.000417770561209902,2.497066,2.5195093,-19579.563,-18416.945,51.4123974809285,18.4064074226471,93.108131,0,0,0,400,4965,2.3172,-18998.254,,,,,,,,,,,,,0,,,,3.39785465,,,,,,2.50828765,,,,
,8698002.75,2.50508105,-27127.698,-0.0460100165840313,3.95624388131191E-5,1,9.99253354069792,40.0298881530762,1.99957179905539,14.8999998345971,-0.508566819896689,-0.0958367821144338,2.5,-0.00051391154042571,-0.0457467593464734,-0.000671146916599384,2.504874,2.5052881,-27711.125,-26544.271,51.7524058867939,18.4115478244547,92.726921,0,0,0,400,4965,2.3076,-27127.698,,,,,,,,,,,,,0,,,,3.9166744,,,,,,2.50508105,,,,
,8698072.665,2.57215285,-35288.3165,-0.0686774748039337,5.55144604273574E-5,1,9.99253354069792,40.0298881530762,1.99939677689404,14.8999998345971,-0.759281776333405,-0.143041067037172,2.5,-0.000734788785597387,-0.0683042497453505,-0.000998466913357064,2.5124085,2.6318972,-35877.391,-34699.242,52.9912870897748,18.4086376793078,92.345711,0,0,0,400,4966,2.40975,-35288.3165,,,,,,,,,,,,,0,,,,4.5052826,,,,,,2.57215285,,,,
,8698142.635,4.0293381,-43462.4785,-0.101039097912176,8.08010414263647E-5,1,9.99253354069792,40.0298881530762,1.99947778643895,14.8900002241135,-1.11748723587444,-0.210450326963487,2.5,-0.00103411637555837,-0.100523057904915,-0.00146309155118361,3.9497523,4.1089239,-44047.598,-42877.359,51.7531875153132,18.4064934087117,92.726921,0,0,0,400,4966,3.9486,-43462.4785,,,,,,,,,,,,,0,,,,5.7082901,,,,,,4.0293381,,,,
,8698212.58,4.9811232,-51639.738,-0.148549074992579,0.00011648708660964,1,9.99253354069792,40.0298881530762,1.99966805246135,14.8900002241135,-1.64380302420008,-0.308918431926214,2.5,-0.00140783184150101,-0.147844258801029,-0.00209535815492733,4.9207568,5.0414896,-52229.66,-51049.816,52.5066774078517,18.4134089296988,92.345711,0,0,0,400,4966,4.9155,-51639.738,,,,,,,,,,,,,0,,,,7.3522265,,,,,,4.9811232,,,,
,8698292.53,5.8576207,-60994.863,-0.224869381063347,0.000158003658553728,1,9.99253354069792,40.0298881530762,1.99966559602939,14.8999998345971,-2.49055779297843,-0.465994109941771,25,-0.00186423131846675,-0.223903953463494,-0.00299489772145487,5.8081312,5.9071102,-61584.785,-60404.941,53.1687167636402,18.4154033603301,93.108131,0,0,0,400,4966,5.8141,-60994.863,,,,,,,,,,,,,0,,,,7.99254655,,,,,,5.8576207,,,,
,8698362.46,6.5515323,-69172.3985,-0.305383850067813,0.000172290354995643,1,9.99253354069792,40.0298881530762,1.99965039583675,14.8900002241135,-3.38361744514286,-0.633476856985492,25,-0.00247336810544319,-0.304199085583003,-0.00410256928384115,6.5031686,6.599896,-69757.234,-68587.563,52.2182564842555,18.4079956347404,91.9645,0,0,0,400,4966,6.5161,-69172.3985,,,,,,,,,,,,,0,,,,9.11068965,,,,,,6.5515323,,,,
,8698432.415,7.21996305,-77347.25,-0.387664756711576,0.000166497769641381,1,9.99253354069792,40.0298881530762,1.99951075075988,14.8900002241135,-4.29687062673897,-0.804289098721093,25,-0.003023532980566,-0.386327105332885,-0.00519576878075372,7.1730852,7.2668409,-77932.227,-76762.273,52.4089738429479,18.4141660841194,93.108131,0,0,0,400,4966,7.1876,-77347.25,,,,,,,,,,,,,0,,,,8.7092161,,,,,,7.21996305,,,,
,8698502.37,7.85802005,-85122.125,-0.460264765619504,0.00015128623042728,1,9.99253354069792,40.0298881530762,1.99963429643084,14.8999998345971,-5.10398879832599,-0.955426058007275,25,-0.00349710446490695,-0.458867987185904,-0.00617663052573222,7.8127999,7.9032402,-85710.352,-84533.898,51.7383365734478,18.4147425455389,92.726921,0,0,0,400,4966,7.8366,-85122.125,,,,,,,,,,,,,0,,,,10.38367655,,,,,,7.85802005,,,,
,8698572.335,8.4855218,-93305.164,-0.529178631504907,0.00013621768998508,1,9.99253354069792,40.0298881530762,1.99972130548619,14.8999998345971,-5.87101435666298,-1.09909753572546,25,-0.00393043292947282,-0.527805852825946,-0.0071124277396999,8.4414797,8.5295639,-93889.859,-92720.469,52.5309078919479,18.4068101024403,92.345711,0,0,0,400,4966,8.4692,-93305.164,,,,,,,,,,,,,0,,,,12.5412607,,,,,,8.4855218,,,,
,8698652.275,9.19262555,-102614.5195,-0.600466233796088,0.000124888970332124,1,9.99253354069792,40.0298881530762,1.99964410211074,14.8900002241135,-6.66523842631719,-1.2464300605278,25,-0.00424317324498891,-0.599208589756803,-0.00795714635128766,9.1498747,9.2353764,-103198.367,-102030.672,51.6359432374285,18.4159540216396,93.108131,0,0,0,400,4966,9.18295,-102614.5195,,,,,,,,,,,,,0,,,,12.1746249,,,,,,9.19262555,,,,
,8698722.25,9.79243135,-110763.379,-0.658370207403668,0.000117340290300452,1,9.99253354069792,40.0298881530762,1.99978966577191,14.8999998345971,-7.31154529364419,-1.36778525715464,25,-0.00462501906706668,-0.657273513317997,-0.00877103080919784,9.749897,9.8349657,-111351.039,-110175.719,52.5910932879286,18.409342188305,92.726921,0,0,0,400,4966,9.7887,-110763.379,,,,,,,,,,,,,0,,,,13.789608,,,,,,9.79243135,,,,
,8698792.16,10.3728266,-118899.5275,-0.71340006730964,0.000113766708219873,1,9.99253354069792,40.0298881530762,1.99990740559363,14.8999998345971,-7.92647893525523,-1.48262251790409,25,-0.00494131071842358,-0.712509937900008,-0.00949079908138548,10.3310528,10.4146004,-119481.961,-118317.094,51.8313503672362,18.4063801817265,92.345711,0,0,0,400,4966,10.38305,-118899.5275,,,,,,,,,,,,,0,,,,14.42383575,,,,,,10.3728266,,,,
,8698862.12,10.9545045,-127028.488,-0.766679865916619,0.000110025047421055,1,9.99253354069792,40.0298881530762,1.9998517976224,14.8900002241135,-8.52176617520023,-1.59349171256007,25,-0.00523438947427387,-0.766033424308606,-0.0101622750770975,10.9097166,10.9992924,-127610.078,-126446.898,51.7860159131209,18.4089152928204,92.345711,0,0,0,400,4966,10.9668,-127028.488,,,,,,,,,,,,,0,,,,15.16410545,,,,,,10.9545045,,,,
,8698932.07,11.5292001,-134826.9455,-0.816507236732526,0.000105938994849416,1,9.99253354069792,40.0298881530762,1.99982572922902,14.8999998345971,-9.07889180151878,-1.69761569185223,25,-0.00555473927343074,-0.816123612665512,-0.0108221395858966,11.4886389,11.5697613,-135411.641,-134242.25,51.9399967314093,18.4077960299966,93.108131,0,0,0,400,4966,11.5395,-134826.9455,,,,,,,,,,,,,0,,,,15.2573409,,,,,,11.5292001,,,,
,8699012.055,12.158361,-139998.3675,-0.849018575399965,1.51034884412822E-5,1,9.99253354069792,40.0298881530762,2.000007962397,14.8999998345971,-9.4434291107254,-1.76601191915411,25,-0.00579576145182802,-0.848822146078295,-0.0112759970335995,12.1218758,12.1948462,-139998.438,-139998.297,51.7242672601016,18.4023712476005,93.108131,0,0,0,400,4934,12.1731,-139998.3675,,,,,,,,,,,,,0,,,,16.1804361,,,,,,12.158361,,,,