File: DataFailid_Testimiseks/KNaCuInPO4_new_powderPellet_MvsT_FC_500Oe_300to2K_25032022.DAT
[Header]
; VSM Data File (default extension .dat)
; Copyright (c) 2003-2013, Quantum Design, Inc. All rights reserved.
TITLE,KNaCuInPO4_new_powderPellet_MvsT_FC_500Oe_300to2K_25032022
FILEOPENTIME,18698335.61,03/25/2022,11:41 am
BYAPP,VSM,2.0,2.0
INFO,PPMS VSM Option Release 1.4.10 Build 1,APPNAME
INFO,Quantum Design Linear Motor Servo Controller,MOTOR_MODULE_NAME
INFO,3101-100 C1,MOTOR_HW_VERSION
INFO,074,MOTOR_SERIAL_NUMBER
INFO,SRV No X-over 01.01.11,MOTOR_SOFTWARE_VERSION
INFO,Quantum Design VSM Detection Module,VSM_MODULE_NAME
INFO,3101-150 E1,VSM_HW_VERSION
INFO,VSM061,VSM_SERIAL_NUMBER
INFO,VSM No X-over 01.02.05 May 20 2008 13:51:47,VSM_SOFTWARE_VERSION
INFO,113,PREAMP_SERIAL_NUMBER
INFO,Quantum Design VSM Oven,OVEN_MODULE_NAME
INFO,3101-200 B0,OVEN_HW_VERSION
INFO,OVN054,OVEN_SERIAL_NUMBER
INFO,01.01.00,OVEN_SOFTWARE_VERSION
INFO,818,COIL_SERIAL_NUMBER
INFO,0,MOMENT_UNITS
INFO,KNaCuInPO4_new_powderPellet_MvsT_FC_500Oe_300to2K_25032022,SAMPLE_MATERIAL
INFO,,SAMPLE_COMMENT
INFO,67.0,SAMPLE_MASS
INFO,,SAMPLE_VOLUME
INFO,,SAMPLE_MOLECULAR_WEIGHT
INFO,disc,SAMPLE_SIZE
INFO,pressed pellet,SAMPLE_SHAPE
DATATYPE,COMMENT,1
DATATYPE,TIME,2
STARTUPAXIS,X,2
STARTUPAXIS,Y1,5
[Data]
Comment,Time Stamp (sec),Temperature (K),Magnetic Field (Oe),Moment (emu),M. Std. Err. (emu),Transport Action,Averaging Time (sec),Frequency (Hz),Peak Amplitude (mm),Center Position (mm),Coil Signal' (mV),Coil Signal" (mV),Range (mV),M. Quad. Signal (emu),M. Raw' (emu),M. Raw" (emu),Min. Temperature (K),Max. Temperature (K),Min. Field (Oe),Max. Field (Oe),Mass (grams),Motor Lag (deg),Pressure (Torr),VSM Status (code),Motor Status (code),Measure Status (code),Measure Count,PPMS Status (code),System Temp. (K),System Field (Oe),Sample Position (deg),Bridge 1 Resistance (ohms),Bridge 1 Excitation (에),Bridge 2 Resistance (ohms),Bridge 2 Excitation (에),Bridge 3 Resistance (ohms),Bridge 3 Excitation (에),Bridge 4 Resistance (ohms),Bridge 4 Excitation (에),Signal 1 Vin (V),Signal 2 Vin (V),Digital Inputs (code),Drive 1 Iout (mA),Drive 1 Ipower (W),Drive 2 Iout (mA),Drive 2 Ipower (W),Pressure (),Map 20 (),Map 21 (),Map 22 (),Map 23 (),Map 24 (),Map 25 (),Map 26 (),Map 27 (),Map 28 (),Map 29 ()
,18699025.56,299.9810486,500.145,,,2,,,,8.7829999923259,,,,,,,299.9810486,299.9810486,500.145,500.145,,,32.114323,,,,-99999999,4885,300.0261,500.145,,,,,,,,,,,,,,,,,,,,,,,299.9810486,,,,
,18699883.205,264.53907775,500.145,0.000133608989596196,1.01998381577194E-7,1,9.99253354069792,40.0298881530762,2.0060420432358,8.75999964773655,0.00149847938376902,0.00024335248162398,0.25,-1.51997018761138E-6,0.000133747739367376,-1.41731824146383E-6,264.2926025,264.785553,500.145,500.145,53.3664687790057,18.594291814952,32.114323,0,0,0,400,4886,257.25095,500.145,,,,,,,,,,,,,0,,,,18.79893875,,,,,,264.53907775,,,,
,18700722.575,222.5921631,500.145,0.000158320826454468,9.30354462714804E-8,1,9.99253354069792,40.0298881530762,1.99212988821556,8.84000025689602,0.00176484646232309,0.000293376701070681,0.25,-1.23943812617018E-6,0.000158679186552997,-1.08909861846737E-6,222.3414307,222.8428955,500.145,500.145,53.8096521494095,18.5882081003519,31.733112,0,0,0,400,4886,215.24335,500.145,,,,,,,,,,,,,0,,,,20.82659055,,,,,,222.5921631,,,,
,18701581.935,179.3953247,500.145,0.000195101850400899,8.25640146784615E-8,1,9.99253354069792,40.0298881530762,2.00609792240265,8.96000023931265,0.00219123268414554,0.000368684039467043,0.25,-1.20518812233141E-6,0.000195767653126177,-9.58834848489415E-7,179.1422272,179.6484222,500.145,500.145,53.279708013371,18.5886989258414,31.733112,0,0,0,400,4886,172.51605,500.145,,,,,,,,,,,,,0,,,,18.64181615,,,,,,179.3953247,,,,
,18702431.28,136.73371125,500.145,0.000252019344909486,7.46343133364E-8,1,9.99253354069792,40.0298881530762,1.99222840805082,9.15000028908253,0.00281252596667969,0.000483075357096464,0.25,-8.58841808402176E-7,0.000253100477915609,-3.77589082640727E-7,136.4870758,136.9803467,500.145,500.145,53.7010057852365,18.5966635106363,31.733112,0,0,0,400,4886,130.6918,500.145,,,,,,,,,,,,,0,,,,19.46422765,,,,,,136.73371125,,,,
,18703270.705,94.39667895,500.145,0.000352887151516549,8.77843098920681E-8,1,9.99253354069792,40.0298881530762,1.98134163626354,9.39000025391579,0.00391392614337609,0.000694109956180969,0.25,1.18354617128043E-7,0.000354405382316466,1.39215020109359E-6,94.1445694,94.6487885,500.145,500.145,54.1512238123134,18.5889815404611,30.97069,0,0,0,400,4886,89.8703,500.145,,,,,,,,,,,,,0,,,,19.67968465,,,,,,94.39667895,,,,
,18704120.095,50.544632,500.145,0.000595397652015875,1.122028522719E-7,1,9.99253354069792,40.0298881530762,1.98109783439278,9.87999979406595,0.00655021599395741,0.00121146948206004,0.25,3.04816836681048E-6,0.000593949770653509,6.70823484208244E-6,50.2880135,50.8012505,500.145,500.145,53.3797564638326,18.587008054135,30.208265,0,0,0,400,4886,48.6162,500.145,,,,,,,,,,,,,0,,,,19.8629732,,,,,,50.544632,,,,
,18704949.445,10.0616026,500.145,0.00145268141414918,1.39128888280367E-7,1,9.99253354069792,40.0298881530762,1.98122355963509,10.0299995392561,0.0159277854196227,0.0029002816164142,0.25,9.14063601007679E-6,0.00144349175689586,1.2306659131811E-5,10.0107145,10.1124907,500.145,500.145,53.0295868872172,18.5884859641345,28.68342,0,0,0,400,4885,10.02265,500.145,,,,,,,,,,,,,0,,,,18.89520355,,,,,,10.0616026,,,,
,18714632.29,3.8371066,500.145,0.00134550535864784,1.36817661544183E-7,1,9.99253354069792,40.0298881530762,1.981542543419,10.5900000780821,0.0147556869356405,0.0026828415903517,0.25,8.11201968214672E-6,0.00133699994211926,1.10467407415141E-5,3.79424,3.8799732,500.145,500.145,53.5501514810249,18.574502026298,27.158575,0,0,0,400,4882,3.8226,500.145,,,,,,,,,,,,,0,,,,20.467268,,,,,,3.8371066,,,,
,18715441.76,9.80188845,500.145,0.00145090577807591,1.24273098786389E-7,1,9.99253354069792,40.0298881530762,1.98129141943499,10.5699999257922,0.0159090010686162,0.00289594415857412,0.25,9.0485102231165E-6,0.00144172802033193,1.22111785680942E-5,9.73946,9.8643169,500.145,500.145,53.167935135121,18.5854528162948,27.920998,0,0,0,400,4886,9.82125,500.145,,,,,,,,,,,,,0,,,,19.3670158,,,,,,9.80188845,,,,
,18716231.12,17.025506,500.145,0.00136394707907805,1.3061583447197E-7,1,9.99253354069792,40.0298881530762,1.98117303717165,10.5200000107288,0.0149545361622057,0.00272163200457908,0.25,8.45395750262039E-6,0.00135530021603192,1.14292168972506E-5,16.9916172,17.0593948,500.145,500.145,53.4329072031403,18.581955680988,28.68342,0,0,0,400,4886,17.0458,500.145,,,,,,,,,,,,,0,,,,20.1575661,,,,,,17.025506,,,,
,18718359.545,2.00974305,500.145,0.00137549696293543,1.41621045445032E-7,1,9.99253354069792,40.0298881530762,1.98133011461324,10.5900000780821,0.0150831602522914,0.00274165166546299,0.25,8.22836810192413E-6,0.00136680154441015,1.12289068224976E-5,2.0095963,2.0098898,500.145,500.145,53.2828345274479,18.5692075245724,26.777365,0,0,0,400,4885,1.99355,500.145,,,,,,,,,,,,,0,,,,19.3978176,,,,,,2.00974305,,,,
,18783411.415,68.9738159,10000.009,0.00922709347956812,1.26592156130964E-6,1,9.99253354069792,40.0298881530762,1.98116000667762,10.2599998936057,0.101971214858052,0.0189726045792422,0.25,6.12774535401187E-5,0.00924781970033873,0.0001143488389161,68.7327499,69.2148819,10000.009,10000.009,53.4852763139287,18.5549802306541,29.827055,0,0,0,400,4886,66.0698,10000.009,,,,,,,,,,,,,0,,,,19.46422765,,,,,,68.9738159,,,,
,18784260.8,25.12689305,10000.009,0.0188672793587732,3.31296040337375E-6,1,9.99253354069792,40.0298881530762,1.98115024774357,10.4200001806021,0.206773444867773,0.0381169940065382,2.5,0.000146553320566597,0.018752681274417,0.000200748311575452,24.8706932,25.3830929,10000.009,10000.009,52.659876597621,18.5581261222051,29.445843,0,0,0,400,4886,24.65535,10000.009,,,,,,,,,,,,,0,,,,19.46422765,,,,,,25.12689305,,,,
,18785712.435,5.006938,10000.009,0.0211788422337761,1.58065288045415E-6,1,9.99253354069792,40.0298881530762,1.98114997668901,10.5600003153086,0.232104091171271,0.04266998138955,2.5,0.000160743520951361,0.0210481946151884,0.000215101453841261,5.0054636,5.0084124,10000.009,10000.009,52.9506424067748,18.5585360638927,27.539787,0,0,0,400,4885,4.99655,10000.009,,,,,,,,,,,,,0,,,,18.1767893,,,,,,5.006938,,,,
,18786499.145,15.25499395,10000.009,0.0228206525016849,2.12363178071537E-6,1,9.99253354069792,40.0298881530762,1.9811078460649,10.5100004002452,0.250078111263451,0.0460355464652659,2.5,0.000178608928710377,0.0226795512499681,0.000237144267593612,15.1934834,15.3165045,10000.009,10000.009,52.9694014912364,18.5634420866447,28.68342,0,0,0,400,4886,15.29765,10000.009,,,,,,,,,,,,,0,,,,18.8914328,,,,,,15.25499395,,,,
,18787298.585,23.21988585,10000.009,0.0197537324489465,1.75104670718432E-6,1,9.99253354069792,40.0298881530762,1.99197166628146,10.4700000956655,0.217614489091817,0.0401143776086493,2.5,0.000155247828064935,0.0196329791896792,0.000210078196252804,23.180172,23.2595997,10000.009,10000.009,52.8576286129864,18.5587657119751,28.68342,0,0,0,400,4886,23.2656,10000.009,,,,,,,,,,,,,0,,,,18.16773035,,,,,,23.21988585,,,,
,18788087.975,28.86238575,10000.009,0.0175737186150668,1.42096293783877E-6,1,9.99253354069792,40.0298881530762,2.00590878732105,10.4200001806021,0.194932836770573,0.0360047283310984,2.5,0.000135403518473291,0.0174706020509088,0.000193130717534298,28.830862,28.8939095,10000.009,10000.009,53.6009573347749,18.5663311457123,29.445843,0,0,0,400,4886,28.903,10000.009,,,,,,,,,,,,,0,,,,18.08769035,,,,,,28.86238575,,,,
,18788917.325,33.664093,10000.009,0.0160058895008599,1.20878682395992E-6,1,9.99253354069792,40.0298881530762,1.98128189459202,10.3599997237325,0.17550906343744,0.0325203695481217,2.5,0.000121800029879216,0.0159187779984383,0.000185034226236196,33.6370773,33.6911087,10000.009,10000.009,52.8756060689287,18.5698414459466,29.445843,0,0,0,400,4886,33.7024,10000.009,,,,,,,,,,,,,0,,,,19.80397275,,,,,,33.664093,,,,
,18789706.79,37.64930725,10000.009,0.0148720101799205,9.46306152975677E-7,1,9.99253354069792,40.0298881530762,1.98106464227078,10.3500001132488,0.163136426577227,0.0303174900969344,2.5,0.000111251882104893,0.0147994956255892,0.000179888890732681,37.6267776,37.6718369,10000.009,10000.009,52.4801020381979,18.5730180310365,29.445843,0,0,0,400,4886,37.6843,10000.009,,,,,,,,,,,,,0,,,,19.270751,,,,,,37.64930725,,,,
,18790496.18,41.27763555,10000.009,0.0139524067296911,1.20756721772586E-6,1,9.99253354069792,40.0298881530762,2.00618915757832,10.3200003504753,0.155010265680221,0.0288709430214014,2.5,0.000101326435090776,0.0138943458497598,0.000174400190412561,41.2542343,41.3010368,10000.009,10000.009,53.8909415154095,18.5788322506246,29.827055,0,0,0,400,4886,41.3128,10000.009,,,,,,,,,,,,,0,,,,17.0954094,,,,,,41.27763555,,,,
,18793693.88,5.0016303,10000.009,0.0211916393472776,1.8513051253025E-6,1,9.99253354069792,40.0298881530762,1.98135413449653,10.5799995362759,0.232272060420867,0.0426730027134323,2.5,0.000158381878470331,0.021060919237685,0.00021278777573119,5.000278,5.0029826,10000.009,10000.009,51.9181111328709,18.5709070195278,27.158575,0,0,0,400,4885,4.9933,10000.009,,,,,,,,,,,,,0,,,,20.4917793,,,,,,5.0016303,,,,
,18794763.025,8.6651211,10000.009,0.0228563281986286,1.84159904887468E-6,1,9.99253354069792,40.0298881530762,1.98131148029901,10.5499997735024,0.250503587919042,0.0460730829263362,2.5,0.000175288313948315,0.022715275263873,0.000233940018382641,8.5984116,8.7318306,10000.009,10000.009,53.353962722698,18.5749854251138,27.920998,0,0,0,400,4886,8.6765,10000.009,,,,,,,,,,,,,0,,,,18.45649625,,,,,,8.6651211,,,,
,18795552.47,17.2213993,10000.009,0.0222261294989047,1.72922560347438E-6,1,9.99253354069792,40.0298881530762,2.00605746414185,10.5100004002452,0.246503072522944,0.0453750175572446,2.5,0.000173680966252453,0.0220886179450217,0.000230755602451379,17.1851864,17.2576122,10000.009,10000.009,52.7067743087748,18.5688683177327,28.30221,0,0,0,400,4886,17.2496,10000.009,,,,,,,,,,,,,0,,,,20.5008402,,,,,,17.2213993,,,,
,18797700.87,2.1602422,10000.009,0.0211896769430632,2.272970780974E-6,1,9.99253354069792,40.0298881530762,2.00635855993521,10.5600003153086,0.235061525307809,0.0431777748921016,2.5,0.000157695012361334,0.0210589659858748,0.000212099957372977,2.1491551,2.1713293,10000.009,10000.009,52.4879183233902,18.5680268293694,27.158575,0,0,0,400,4886,2.1417,10000.009,,,,,,,,,,,,,0,,,,22.6546345,,,,,,2.1602422,,,,
,18798999.93,26.59713175,10000.009,0.0184475044995018,3.20534262984981E-6,1,9.99253354069792,40.0298881530762,1.99244546352348,10.6300003826618,0.203300421412773,0.0374785514327487,2.5,0.00013943219888316,0.0183374365203396,0.000196458471103015,26.3469582,26.8473053,10000.009,10000.009,53.1906023621787,18.5784854078632,28.30221,0,0,0,400,4886,27.12065,10000.009,,,,,,,,,,,,,0,,,,17.6155062,,,,,,26.59713175,,,,
,18799789.335,60.5286903,10000.009,0.0105625368369218,2.15613421972336E-6,1,9.99253354069792,40.0298881530762,1.98147866884346,10.610000230372,0.11666054756321,0.0217571584288102,2.5,7.23105115005964E-5,0.0105823194589038,0.000135363705431019,60.1745338,60.8828468,10000.009,10000.009,53.2969038407941,18.5626283022187,29.064632,0,0,0,400,4886,63.7225,10000.009,,,,,,,,,,,,,0,,,,17.1039305,,,,,,60.5286903,,,,
,18800638.75,99.61592485,10000.009,0.00679219998586605,5.08077449593118E-7,1,9.99253354069792,40.0298881530762,1.99247040581436,10.499999858439,0.075686031099093,0.0137297450616672,2.5,3.33620249207867E-5,0.00682332265810837,5.36449469196154E-5,99.5850449,99.6468048,10000.009,10000.009,53.1257271950825,18.5703100090578,29.827055,0,0,0,400,4885,100.48535,10000.009,,,,,,,,,,,,,0,,,,19.1744862,,,,,,99.61592485,,,,
,18886255.425,68.64330675,1000,0.000933515998417729,1.28008078925718E-7,1,9.99253354069792,40.0298881530762,1.98126412766889,10.1100001484156,0.0103196696717732,0.00189676127978022,0.25,4.09352596150541E-6,0.000935493978241272,9.52471597941327E-6,68.3957367,68.8908768,1000,1000,53.5689105654864,18.5583278083355,30.589479,0,0,0,400,4886,65.6729,1000,,,,,,,,,,,,,0,,,,18.1767893,,,,,,68.64330675,,,,
,18887094.77,25.2957077,1000,0.00189369294076587,3.4674177805863E-7,1,9.99253354069792,40.0298881530762,1.99230264244028,10.3099998086691,0.0208715907662182,0.00383011629478315,0.25,1.38368469512496E-5,0.00188189057855003,1.86288265152883E-5,25.0464554,25.54496,1000,1000,53.0444378290825,18.5638388935242,29.445843,0,0,0,400,4882,24.8016,1000,,,,,,,,,,,,,0,,,,17.8937359,,,,,,25.2957077,,,,
,18888593.665,5.00692845,1000,0.00241692861651324,2.11760275285679E-7,1,9.99253354069792,40.0298881530762,1.98133034972373,10.499999858439,0.0264994474612181,0.00483909132296829,0.25,1.63922936113348E-5,0.00240165883090122,2.16880676082152E-5,5.006773,5.0070839,1000,1000,52.7231885076786,18.5662614410328,27.539787,0,0,0,400,4885,4.99745,1000,,,,,,,,,,,,,0,,,,19.6655331,,,,,,5.00692845,,,,
,18889410.14,17.455986,1000,0.00246170120761182,2.35407249497972E-7,1,9.99253354069792,40.0298881530762,1.9814696229303,10.4499999433756,0.0269829486002529,0.00493127378899631,2.5,1.70252986980966E-5,0.00244610495327847,2.2430703552615E-5,17.455986,17.455986,1000,1000,53.4876211994864,18.561665280988,28.68342,0,0,0,400,4886,17.5081,1000,,,,,,,,,,,,,0,,,,18.63157845,,,,,,17.455986,,,,
,18890202.54,25.4698353,1000,0.00189553630683089,1.55179252504952E-7,1,9.99253354069792,40.0298881530762,1.98148489814285,10.4299997910857,0.020783612428174,0.00381396615781266,0.25,1.37310850288814E-5,0.00188377257731215,1.86469867478003E-5,25.4295864,25.5100842,1000,1000,52.934228207871,18.5670730905642,29.064632,0,0,0,400,4886,25.5186,1000,,,,,,,,,,,,,0,,,,19.9721365,,,,,,25.4698353,,,,
,18891033.07,31.3995781,1000,0.0016843270544164,1.46887857225368E-7,1,9.99253354069792,40.0298881530762,1.99233954760037,10.3599997237325,0.0185696228691737,0.00341759648321682,0.25,1.18520573804988E-5,0.00167445358986274,1.74399994117549E-5,31.3751869,31.4239693,1000,1000,53.5048170269095,18.5633486597555,29.064632,0,0,0,400,4886,31.4518,1000,,,,,,,,,,,,,0,,,,17.9961109,,,,,,31.3995781,,,,
,18891821.345,35.95926095,1000,0.00154517259034569,1.45272939580861E-7,1,9.99253354069792,40.0298881530762,1.98128212076513,10.3399995714426,0.016951262907563,0.0031326751548592,0.25,1.08310008607467E-5,0.0015369039091714,1.71408517487632E-5,35.9318581,35.9866638,1000,1000,53.3985155482941,18.5667971773556,29.445843,0,0,0,400,4886,35.99595,1000,,,,,,,,,,,,,0,,,,17.4404049,,,,,,35.95926095,,,,
,18892610.695,39.92821125,1000,0.00143855257827606,1.5792766861001E-7,1,9.99253354069792,40.0298881530762,1.98153203180366,10.3200003504753,0.015792581890916,0.00292912194075982,0.25,9.95577922575552E-6,0.00143183855095771,1.68963490698333E-5,39.9039574,39.9524651,1000,1000,52.8576286129864,18.5672225499993,29.445843,0,0,0,400,4886,39.96585,1000,,,,,,,,,,,,,0,,,,19.56243515,,,,,,39.92821125,,,,
,18893400.075,43.5356083,1000,0.00135323367275706,1.34253948423804E-7,1,9.99253354069792,40.0298881530762,1.9924491720203,10.3000001981854,0.0149456897118058,0.00277929443772291,0.25,9.14186427681761E-6,0.00134804034663796,1.65396527653881E-5,43.5134926,43.557724,1000,1000,53.2468796155633,18.5699564273926,29.827055,0,0,0,400,4886,43.57685,1000,,,,,,,,,,,,,0,,,,17.9871397,,,,,,43.5356083,,,,
,18896852.98,4.9979844,1000,,,2,,,,10.6229998003244,,,,,,,4.9979844,4.9979844,1000,1000,,,27.158575,,,,-99999999,4885,4.9996,1000,,,,,,,,,,,,,,,,,,,,,,,4.9979844,,,,
,18897696.92,8.6408472,1000,0.00257752371367184,2.49338766298442E-7,1,9.99253354069792,40.0298881530762,1.98142138666035,10.5600003153086,0.0282594611408025,0.00517194221839082,0.25,1.84923796059843E-5,0.0025612311947018,2.41336097766616E-5,8.578886,8.7028084,1000,1000,52.4058473288709,18.5706773040469,27.920998,0,0,0,400,4886,8.65755,1000,,,,,,,,,,,,,0,,,,17.8937359,,,,,,8.6408472,,,,
,18898486.365,16.7658234,1000,0.00248842029590022,1.97131318533254E-7,1,9.99253354069792,40.0298881530762,1.98172040538728,10.5100004002452,0.0272856714938721,0.00499612885961957,0.25,1.80656204538366E-5,0.00247265246684001,2.35099480506901E-5,16.7264767,16.8051701,1000,1000,53.6142450196018,18.5690944348611,28.30221,0,0,0,400,4886,16.7951,1000,,,,,,,,,,,,,0,,,,19.7146072,,,,,,16.7658234,,,,
,18900616.35,2.12369275,1000,0.00242825360795092,3.45334062633934E-7,1,9.99253354069792,40.0298881530762,1.98181438041131,10.5600003153086,0.0266306491795952,0.00485836784303701,0.25,1.60558993860846E-5,0.00241291262433726,2.13790870000473E-5,2.1133921,2.1339934,1000,1000,53.3367668952749,18.5692706254903,27.158575,0,0,0,400,4886,2.1091,1000,,,,,,,,,,,,,0,,,,20.68719865,,,,,,2.12369275,,,,
,18902023.75,22.66782475,1000,0.00204575500943488,8.59865643507413E-7,1,9.99253354069792,40.0298881530762,1.99240256719714,10.5600003153086,0.0225486349358645,0.00413223628256366,0.25,1.47191859882593E-5,0.00203291848470991,1.96325571975675E-5,22.4214287,22.9142208,1000,1000,52.8724795548518,18.5702837219708,27.539787,0,0,0,400,4882,23.05575,1000,,,,,,,,,,,,,0,,,,18.54360865,,,,,,22.66782475,,,,
,18902773.25,56.61148455,1000,0.0011108224516003,1.33433281693065E-7,1,9.99253354069792,40.0298881530762,1.99226684795923,10.5600003153086,0.0123183343045804,0.00228981989356361,0.25,6.44712434897208E-6,0.00111114758227278,1.3555283897168E-5,56.5044327,56.7185364,1000,1000,52.8310532433325,18.5720037185953,29.064632,0,0,0,400,4886,57.61175,1000,,,,,,,,,,,,,0,,,,18.58244705,,,,,,56.61148455,,,,
,18903522.67,91.17884065,1000,0.000746855652695947,1.04653095940054E-7,1,9.99253354069792,40.0298881530762,1.99264317376034,10.5600003153086,0.00832672228405749,0.00150245494216332,0.25,2.75971039229221E-6,0.000750270146801425,5.19664016414473E-6,90.9420166,91.4156647,1000,1000,53.1601188499287,18.5687043421749,29.445843,0,0,0,400,4886,95.53835,1000,,,,,,,,,,,,,0,,,,17.30150985,,,,,,91.17884065,,,,
,18904971.585,83.50228505,100.033,7.36770606058884E-5,7.31290680506986E-8,1,9.99253354069792,40.0298881530762,1.98122197338436,10.4000000283122,0.000818957363028562,0.000132226999325558,0.25,-1.1745960941965E-6,7.39626833670648E-5,-8.51671679585239E-7,83.1833878,83.8211823,100.033,100.033,52.0806898648709,18.5665449863166,30.208265,0,0,0,400,4886,79.45635,100.033,,,,,,,,,,,,,0,,,,18.63157845,,,,,,83.50228505,,,,
,18905800.955,40.6287174,100.033,0.000131331162111778,7.19439413708904E-8,1,9.99253354069792,40.0298881530762,1.98126876696727,10.5900000780821,0.00144428019832901,0.00025105730004819,0.25,-5.56619279886078E-7,0.000130706667510476,6.77392147406675E-8,40.3724632,40.8849716,100.033,100.033,52.6200135431402,18.5736148413061,29.445843,0,0,0,400,4886,39.3724,100.033,,,,,,,,,,,,,0,,,,18.0670786,,,,,,40.6287174,,,,
,18907299.81,5.9625025,100.033,0.000511496965537944,8.78123842387932E-8,1,9.99253354069792,40.0298881530762,2.00593640110391,10.5600003153086,0.00567952583395796,0.00100947583425294,0.25,1.06817917731788E-6,0.000508266054885232,2.19156461287303E-6,5.8752599,6.0497451,100.033,100.033,53.1741881632749,18.5758526945463,27.539787,0,0,0,400,4882,5.9386,100.033,,,,,,,,,,,,,0,,,,21.14257715,,,,,,5.9625025,,,,
,18917122.585,3.68896965,100.033,0.000507082379734155,7.93656185495429E-8,1,9.99253354069792,40.0298881530762,1.98133667747813,10.5699999257922,0.0055641868732659,0.000989534101010803,0.25,1.1083031196209E-6,0.000503879467760001,2.22168246258137E-6,3.6439784,3.7339609,100.033,100.033,52.4558715541017,18.5488692014604,27.158575,0,0,0,400,4886,3.6812,100.033,,,,,,,,,,,,,0,,,,18.51588535,,,,,,3.68896965,,,,
touchdown = 5.51000004634261 mm,18917960.855,13.9714384,100.033,0.000499941353228602,7.81201916131949E-8,1,9.99253354069792,40.0298881530762,1.9923634610969,10.5100004002452,0.00551495522763574,0.000981379610952863,0.25,1.14549368315186E-6,0.000496778011905,2.24283607738418E-6,13.9714384,13.9714384,100.033,100.033,52.6895784813517,18.5568236091307,27.920998,0,0,0,400,4886,13.9999,100.033,,,,,,,,,,,,,0,,,,20.15658,,,,,,13.9714384,,,,
,18918761.39,20.0446215,100.033,0.000395881922101897,8.14532464009846E-8,1,9.99253354069792,40.0298881530762,1.98105911154152,10.4700000956655,0.00434373738911909,0.00077044691323907,0.25,6.59112146691193E-7,0.000393380280154583,1.55514052855531E-6,20.0242825,20.0649605,100.033,100.033,52.0548961237363,18.560847665548,28.68342,0,0,0,400,4886,20.0636,100.033,,,,,,,,,,,,,0,,,,21.77205185,,,,,,20.0446215,,,,
,18920859.795,2.00446465,100.033,0.000513493912273354,1.08010514611035E-7,1,9.99253354069792,40.0298881530762,1.99210159308651,10.5600003153086,0.0056641725826179,0.00100575474413642,0.25,9.8515072545285E-7,0.000510250599484287,2.11347246961368E-6,2.0011349,2.0077944,100.033,100.033,53.2484428726018,18.5607932823619,26.777365,0,0,0,400,4885,1.97745,100.033,,,,,,,,,,,,,0,,,,19.56243515,,,,,,2.00446465,,,,
,18921978.98,22.6863804,100.033,0.000201075810098581,5.01084754321576E-7,1,9.99253354069792,40.0298881530762,2.00614325568328,10.5999996885657,0.00223389534966506,0.000391897875359636,0.25,-7.36854881837349E-8,0.00019981610397774,4.14546559902345E-7,22.440609,22.9321518,100.033,100.033,52.6411175131594,18.5628823743953,27.920998,0,0,0,400,4882,23.0939,100.033,,,,,,,,,,,,,0,,,,17.8172264,,,,,,22.6863804,,,,
,18922728.445,56.80609325,100.033,0.000103356276879733,6.44987353299499E-8,1,9.99253354069792,40.0298881530762,2.00626238057372,10.5999996885657,0.00115678154042474,0.000198550858269107,0.25,-8.26444245119242E-7,0.000103399222100824,-1.66086744485974E-7,56.7037354,56.9084511,100.033,100.033,52.9357914649095,18.5673980270872,29.445843,0,0,0,400,4886,57.76825,100.033,,,,,,,,,,,,,0,,,,19.36796285,,,,,,56.80609325,,,,
,18923477.91,90.52462005,100.033,7.04795483224482E-5,6.55261001156025E-8,1,9.99253354069792,40.0298881530762,2.00592588789521,10.5999996885657,0.000793816257914061,0.000125546067701998,0.25,-1.26928055209289E-6,7.08058172588861E-5,-1.04338432059419E-6,90.2606735,90.7885666,100.033,100.033,53.0569438853902,18.5710037037213,29.827055,0,0,0,400,4886,94.85475,100.033,,,,,,,,,,,,,0,,,,19.270751,,,,,,90.52462005,,,,
,18951607.07,83.7572746,250.161,0.000192086179157062,7.21092289222169E-8,1,9.99253354069792,40.0298881530762,1.981423395096,9.96000040322542,0.0021301847329748,0.00037429686579942,0.25,-3.90241501680344E-7,0.00019282730009432,4.52139509086839E-7,83.4837799,84.0307693,250.161,250.161,52.690360109871,18.5384490977416,30.208265,0,0,0,400,4886,80.01025,250.161,,,,,,,,,,,,,0,,,,17.8794594,,,,,,83.7572746,,,,
,18952436.48,40.98301315,250.161,0.000342102437912894,8.7748921462646E-8,1,9.99253354069792,40.0298881530762,1.99240521034605,10.2599998936057,0.00377722743321773,0.00068835425927194,0.25,1.31728282284475E-6,0.000340484871662577,2.95179360228637E-6,40.7283897,41.2376366,250.161,250.161,52.7997881025633,18.5458763190414,29.827055,0,0,0,400,4886,39.696,250.161,,,,,,,,,,,,,0,,,,18.72978595,,,,,,40.98301315,,,,
,18953945.4,6.1713238,250.161,0.000839177847341266,9.83866318015498E-8,1,9.99253354069792,40.0298881530762,1.99221642773388,10.4000000283122,0.00925289804949209,0.00166825041701758,0.25,3.82761655876851E-6,0.000833873445277713,5.66035204341661E-6,6.1202221,6.2224255,250.161,250.161,53.3266057245249,18.5489978539805,27.539787,0,0,0,400,4886,6.15465,250.161,,,,,,,,,,,,,0,,,,17.8403149,,,,,,6.1713238,,,,
,18954734.75,11.4399972,250.161,0.000864714590267795,1.06387348386638E-7,1,9.99253354069792,40.0298881530762,1.98132819996383,10.5200000107288,0.00948361514016756,0.00171454734452162,0.25,4.35910383926412E-6,0.000859243063979071,6.24495680915505E-6,11.3677645,11.5122299,250.161,250.161,53.401642062371,18.548658749283,27.920998,0,0,0,400,4886,11.47145,250.161,,,,,,,,,,,,,0,,,,18.9848366,,,,,,11.4399972,,,,
,18955574.145,21.26319505,250.161,0.000645656277757517,1.49436106205572E-7,1,9.99253354069792,40.0298881530762,1.98121561219477,10.4499999433756,0.00708114317594074,0.00127857826441228,0.25,3.03595731381555E-6,0.000641582385134908,4.52041785776588E-6,21.2167149,21.3096752,250.161,250.161,53.3187894393326,18.55909886813,28.68342,0,0,0,400,4886,21.31725,250.161,,,,,,,,,,,,,0,,,,18.7017832,,,,,,21.26319505,,,,
,18956363.555,27.5205107,250.161,0.000443675113820992,7.63492736098584E-8,1,9.99253354069792,40.0298881530762,1.98142985634548,10.4299997910857,0.00486726899368154,0.000879473875909348,0.25,1.91986363169927E-6,0.000440959646126409,3.16259257266898E-6,27.4878216,27.5531998,250.161,250.161,52.5809321171786,18.5693713624938,29.064632,0,0,0,400,4886,27.5665,250.161,,,,,,,,,,,,,0,,,,18.4270687,,,,,,27.5205107,,,,
,18957152.965,32.42710305,250.161,0.000402921017822721,7.0935582333067E-8,1,9.99253354069792,40.0298881530762,1.992452216529,10.3900004178286,0.00444515552245453,0.000804306744187671,0.25,1.56832521668075E-6,0.000400596470039694,2.96955406114519E-6,32.3988228,32.4553833,250.161,250.161,52.5387241771402,18.5682255484482,29.445843,0,0,0,400,4886,32.4689,250.161,,,,,,,,,,,,,0,,,,19.7617979,,,,,,32.42710305,,,,
,18957982.39,36.85684015,250.161,0.000370942722266579,7.16220733633367E-8,1,9.99253354069792,40.0298881530762,1.98152819732558,10.3399995714426,0.00407277872440884,0.000738846953760766,0.25,1.3261136809815E-6,0.000369008298996697,2.90366900749729E-6,36.8324738,36.8812065,250.161,250.161,52.5926565449671,18.5680615747579,29.445843,0,0,0,400,4886,36.8898,250.161,,,,,,,,,,,,,0,,,,19.36796285,,,,,,36.85684015,,,,
,18958771.79,40.62301445,250.161,0.000347163431596917,7.3280185679349E-8,1,9.99253354069792,40.0298881530762,1.98146360458126,10.329999960959,0.00381365250053258,0.000695334893263815,0.25,1.30505108801376E-6,0.000345594573574228,3.02614229162094E-6,40.6005707,40.6454582,250.161,250.161,52.6747275394863,18.5690180757727,29.827055,0,0,0,400,4886,40.6603,250.161,,,,,,,,,,,,,0,,,,17.0091791,,,,,,40.62301445,,,,
,18961859.52,71.6577034,749.973,0.000673568041575823,1.0967125649193E-7,1,9.99253354069792,40.0298881530762,1.99236269749263,10.329999960959,0.0074895165403117,0.00137535259313563,0.25,3.0196919039924E-6,0.000675288595757768,6.76859215721976E-6,71.4049377,71.9104691,749.973,749.973,52.4222615277748,18.5528043927003,30.208265,0,0,0,400,4886,68.24925,749.973,,,,,,,,,,,,,0,,,,17.91158675,,,,,,71.6577034,,,,
,18962688.885,28.7271566,749.973,0.00132113396203928,2.24989599695918E-7,1,9.99253354069792,40.0298881530762,1.98153000469772,10.4599995538592,0.0144857931345017,0.00266798759315937,0.25,1.0081491904437E-5,0.00131307394840243,1.38504766105972E-5,28.4612617,28.9930515,749.973,749.973,51.2451289778131,18.5520600095037,29.445843,0,0,0,400,4886,28.08585,749.973,,,,,,,,,,,,,0,,,,19.18311695,,,,,,28.7271566,,,,
,18964837.315,5.90448165,749.973,0.00191762656474612,1.8635746770517E-7,1,9.99253354069792,40.0298881530762,1.98150449403884,10.4400003328919,0.0210263048618031,0.00384230306932868,0.25,1.32560174640023E-5,0.00190550490187731,1.74415658834083E-5,5.8216815,5.9872818,749.973,749.973,52.659876597621,18.5497860790427,27.539787,0,0,0,400,4882,5.8825,749.973,,,,,,,,,,,,,0,,,,19.2726736,,,,,,5.90448165,,,,
,18965626.75,20.84877875,749.973,0.00172902387693405,2.30089638456123E-7,1,9.99253354069792,40.0298881530762,2.00607733622775,10.4400003328919,0.019182838664809,0.00351120918092486,0.25,1.22863652250451E-5,0.00171810395848376,1.62269736495371E-5,20.7826252,20.9149323,749.973,749.973,52.7825922751402,18.5635325855438,29.064632,0,0,0,400,4886,20.91675,749.973,,,,,,,,,,,,,0,,,,18.99906635,,,,,,20.84877875,,,,
,18966466.105,29.3406639,749.973,0.00131185828043419,1.22705481286784E-7,1,9.99253354069792,40.0298881530762,1.99231832628471,10.3900004178286,0.0144613090265803,0.00265814173790501,0.25,9.32709825819676E-6,0.00130396271205776,1.32888998914165E-5,29.2977333,29.3835945,749.973,749.973,52.6035993442363,18.5643419920666,29.445843,0,0,0,400,4886,29.3972,749.973,,,,,,,,,,,,,0,,,,22.4088068,,,,,,29.3406639,,,,
,18967255.51,34.6914635,749.973,0.00118316711557477,1.13315823733949E-7,1,9.99253354069792,40.0298881530762,1.98154462270893,10.3700002655387,0.0129800288338865,0.00239442050067266,0.25,8.18304670972455E-6,0.00117663194947092,1.27412966634517E-5,34.6609383,34.7219887,749.973,749.973,53.2077981896018,18.5611825160891,29.445843,0,0,0,400,4886,34.7345,749.973,,,,,,,,,,,,,0,,,,21.5310183,,,,,,34.6914635,,,,
,18968044.92,39.00486945,749.973,0.00109409866521533,1.10724137570036E-7,1,9.99253354069792,40.0298881530762,1.98142096978485,10.329999960959,0.0120088017973529,0.00222417974405417,0.25,7.48562518479518E-6,0.00108879180957914,1.25723261230605E-5,38.9792137,39.0305252,749.973,749.973,52.7450741062171,18.5618504352766,29.445843,0,0,0,400,4886,39.04835,749.973,,,,,,,,,,,,,0,,,,19.270751,,,,,,39.00486945,,,,
,18968834.38,42.775301,749.973,0.00102569395897704,1.13037473895784E-7,1,9.99253354069792,40.0298881530762,1.99241270124544,10.3000001981854,0.011326086181838,0.0021044434587663,0.25,6.90820076445658E-6,0.00102155826718236,1.23812352307729E-5,42.7524109,42.7981911,749.973,749.973,52.3980310436786,18.5643364050989,29.827055,0,0,0,400,4886,42.8159,749.973,,,,,,,,,,,,,0,,,,18.5269728,,,,,,42.775301,,,,
,18972111.945,5.0031517,749.973,0.00188755465581209,2.26150286520878E-7,1,9.99253354069792,40.0298881530762,1.98149151756278,10.5900000780821,0.0206974593103337,0.00377627750952753,0.25,1.25244973918165E-5,0.00187562480945068,1.66477156696188E-5,5.0018497,5.0044537,749.973,749.973,52.8998365530248,18.5637671089321,27.158575,0,0,0,400,4885,4.996,749.973,,,,,,,,,,,,,0,,,,19.1744862,,,,,,5.0031517,,,,
,18973181.14,7.88972185,749.973,0.00198518181061505,2.1851871177725E-7,1,9.99253354069792,40.0298881530762,2.00654625058208,10.5600003153086,0.0220311011149048,0.00402358911073957,0.25,1.35199728032442E-5,0.0019726310418046,1.78542295243335E-5,7.8283076,7.9511361,749.973,749.973,52.9991033749671,18.5617990905238,27.539787,0,0,0,400,4886,7.90025,749.973,,,,,,,,,,,,,0,,,,18.006876,,,,,,7.88972185,,,,
,18973970.57,16.53171345,749.973,0.00193599161312201,1.81964639636553E-7,1,9.99253354069792,40.0298881530762,1.98161983734196,10.5200000107288,0.0212290373750067,0.00387617060894765,0.25,1.31043587345435E-5,0.00192372161343203,1.73294804991352E-5,16.4923286,16.5710983,749.973,749.973,52.8318348718517,18.5689677217916,28.30221,0,0,0,400,4886,16.5566,749.973,,,,,,,,,,,,,0,,,,18.8914328,,,,,,16.53171345,,,,
,18976069.01,2.9935789,749.973,0.00186565722051567,1.85222710123326E-7,1,9.99253354069792,40.0298881530762,1.98142467629983,10.4700000956655,0.0204578075615917,0.00372596812522155,0.25,1.17980022490257E-5,0.00185386711444436,1.58770524244767E-5,2.8693149,3.1178429,749.973,749.973,52.9873789471787,18.5694125917265,27.158575,0,0,0,400,4886,2.9523,749.973,,,,,,,,,,,,,0,,,,17.09370325,,,,,,2.9935789,,,,
,18977378.06,21.1869526,749.973,0.00170679567058667,6.66551470094104E-7,1,9.99253354069792,40.0298881530762,1.98177513699377,10.5699999257922,0.0187172383599766,0.00342104841848508,0.25,1.16418932018144E-5,0.0016960344800602,1.55855573084908E-5,20.9361038,21.4378014,749.973,749.973,52.5973463160825,18.5738366224574,27.539787,0,0,0,400,4882,21.554,749.973,,,,,,,,,,,,,0,,,,18.350132,,,,,,21.1869526,,,,
,18978127.54,53.8338909,749.973,0.000865160201400995,1.13386495065629E-7,1,9.99253354069792,40.0298881530762,1.98154765783347,10.5600003153086,0.00953691020181469,0.00177207879641307,0.25,4.90461956407006E-6,0.000864708990805575,1.04866448164201E-5,53.72229,53.9454918,749.973,749.973,53.2124879607172,18.5693361209799,29.064632,0,0,0,400,4886,54.7793,749.973,,,,,,,,,,,,,0,,,,19.0787134,,,,,,53.8338909,,,,
,18978886.95,89.3360634,749.973,0.000569318525517507,9.09533493240573E-8,1,9.99253354069792,40.0298881530762,1.98129651350718,10.5600003153086,0.00631282922576348,0.00113668525629779,0.25,1.82877917844262E-6,0.000571899187685033,3.75169518380993E-6,89.0823975,89.5897293,749.973,749.973,53.6228429333134,18.5749744913549,29.827055,0,0,0,400,4886,93.6076,749.973,,,,,,,,,,,,,0,,,,17.1790924,,,,,,89.3360634,,,,
,18998392.55,285.8704529,10000.072,0.00244322475280561,3.38143841299791E-7,1,9.99253354069792,40.0298881530762,1.9817519716863,9.17000044137239,0.0270073098434172,0.00473396559863063,0.25,2.99558202730077E-6,0.0024441750949524,4.72005114781316E-6,285.6261597,286.1147461,10000.072,10000.072,53.1147843958133,18.5539798198214,31.733112,0,0,0,400,4886,279.56955,10000.072,,,,,,,,,,,,,0,,,,18.9839077,,,,,,285.8704529,,,,
,18999241.885,243.84127045,10000.072,0.00286227365167083,2.96540623644483E-7,1,9.99253354069792,40.0298881530762,2.00619154003225,9.22000035643578,0.0320500920855135,0.00563868955025298,0.25,4.86644464854491E-6,0.00286697254261277,7.34166168420545E-6,243.5874329,244.095108,10000.072,10000.072,53.3688136645633,18.562079906874,31.733112,0,0,0,400,4886,236.52115,10000.072,,,,,,,,,,,,,0,,,,20.16561315,,,,,,243.84127045,,,,
,19000081.335,201.78492735,10000.072,0.00344483170007041,3.38691292637892E-7,1,9.99253354069792,40.0298881530762,2.00640159836673,9.30000003427267,0.0386161043801567,0.00683355418476396,0.25,8.49134563239426E-6,0.00345457162587169,1.22891548889813E-5,201.529953,202.0399017,10000.072,10000.072,53.5696921940057,18.5597424234093,31.351902,0,0,0,400,4886,194.57525,10000.072,,,,,,,,,,,,,0,,,,17.9517555,,,,,,201.78492735,,,,
,19000930.62,159.0443649,10000.072,0.00432927317350701,4.23500783418192E-7,1,9.99253354069792,40.0298881530762,1.9815557923628,9.4200000166893,0.0479925146848144,0.00856023992678082,0.25,1.47335235072333E-5,0.00434601065640412,2.13792932742448E-5,158.7894287,159.2993011,10000.072,10000.072,52.8693530407748,18.5647428428426,31.733112,0,0,0,400,4886,152.5054,10000.072,,,,,,,,,,,,,0,,,,20.6290579,,,,,,159.0443649,,,,
,19001789.985,115.9624977,10000.072,0.00581508346923248,5.94212164598771E-7,1,9.99253354069792,40.0298881530762,2.00619448784219,9.56999976187944,0.0652503452255443,0.0117703471758136,0.25,2.54084013515046E-5,0.0058411938245962,4.01740306267146E-5,115.7060547,116.2189407,10000.072,10000.072,52.1846464579286,18.5683294758391,31.351902,0,0,0,400,4886,110.55265,10000.072,,,,,,,,,,,,,0,,,,20.1817112,,,,,,115.9624977,,,,
,19002629.365,73.1825371,10000.072,0.00875029453725448,9.81113279261489E-7,1,9.99253354069792,40.0298881530762,1.98137944515299,9.80000011622906,0.0967789395668898,0.0179279246125114,0.25,5.43604139556215E-5,0.00877479985434366,0.000101608715399252,72.9237137,73.4413605,10000.072,10000.072,53.0334950298133,18.5699465399124,30.97069,0,0,0,400,4886,69.608,10000.072,,,,,,,,,,,,,0,,,,19.6655331,,,,,,73.1825371,,,,
,19003478.74,29.1690712,10000.072,0.0173598420185687,2.85430347912983E-6,1,9.99253354069792,40.0298881530762,1.98132705043289,10.0199999287724,0.19028631281902,0.0351775486761963,2.5,0.00013729195494504,0.0172574735363918,0.000193497875863394,28.9156876,29.4224548,10000.072,10000.072,52.9217221515633,18.5650570677027,29.827055,0,0,0,400,4886,28.5064,10000.072,,,,,,,,,,,,,0,,,,20.08642195,,,,,,29.1690712,,,,
,19005657.19,9.3392539,10000.072,0.0230255646602,3.06021230708317E-6,1,9.99253354069792,40.0298881530762,1.98135075479849,10.2500002831221,0.252349689844258,0.0464908172494973,2.5,0.00018348767901572,0.0228834323257144,0.000242531098442654,8.9972954,9.6812124,10000.072,10000.072,52.0853796359863,18.5560086447436,28.68342,0,0,0,400,4886,9.43475,10000.072,,,,,,,,,,,,,0,,,,19.85702805,,,,,,9.3392539,,,,
,19006446.58,29.70360755,10000.072,0.0172789170562256,1.65547771270472E-6,1,9.99253354069792,40.0298881530762,1.98153667236774,10.2500002831221,0.189437387475699,0.0350133771939712,2.5,0.000133281663698815,0.0171786279711313,0.000191979451882264,29.6351089,29.7721062,10000.072,10000.072,52.097885692294,18.5684446901112,29.445843,0,0,0,400,4886,29.82315,10000.072,,,,,,,,,,,,,0,,,,18.4243288,,,,,,29.70360755,,,,
,19007275.975,38.67321395,10000.072,0.0146039054585781,1.28971951788644E-6,1,9.99253354069792,40.0298881530762,1.98115185690315,10.1899998262525,0.160224282042207,0.0298310312607533,2.5,0.000111334456097719,0.0145355296111874,0.000181480843134839,38.6303749,38.716053,10000.072,10000.072,52.9686198627171,18.5634310555052,29.827055,0,0,0,400,4886,38.7744,10000.072,,,,,,,,,,,,,0,,,,21.31305695,,,,,,38.67321395,,,,
,19008065.34,44.79829215,10000.072,0.0131578203130817,1.15285667214684E-6,1,9.99253354069792,40.0298881530762,1.98116537536907,10.1800002157688,0.144540222573374,0.0270451370085607,2.5,9.94239454149803E-5,0.0131146315365752,0.000175509859867281,44.7636604,44.8329239,10000.072,10000.072,52.179175058294,18.5639671108637,29.827055,0,0,0,400,4886,44.88685,10000.072,,,,,,,,,,,,,0,,,,17.9692049,,,,,,44.79829215,,,,
,19011562.76,4.25382255,10000.072,0.020923315217916,2.73233491238689E-6,1,9.99253354069792,40.0298881530762,1.98103122887314,10.499999858439,0.229291177140038,0.0421491289002306,2.5,0.000158475074687132,0.0207942471526677,0.000212179278659605,4.2119069,4.2957382,10000.072,10000.072,53.300030354871,18.5708021616246,27.920998,0,0,0,400,4882,4.2405,10000.072,,,,,,,,,,,,,0,,,,16.92378995,,,,,,4.25382255,,,,
,19012362.225,12.90375995,10000.072,0.023278861227896,1.94650601838472E-6,1,9.99253354069792,40.0298881530762,1.98148388523633,10.4799997061491,0.255157534924945,0.0469096202634503,2.5,0.000176814347493914,0.0231350597740558,0.000236559444098204,12.8344564,12.9730635,10000.072,10000.072,53.0444378290825,18.5685447152216,28.30221,0,0,0,400,4886,12.9356,10000.072,,,,,,,,,,,,,0,,,,18.2848768,,,,,,12.90375995,,,,
,19013151.61,20.8350811,10000.072,0.0208524729129198,1.67245768552841E-6,1,9.99253354069792,40.0298881530762,1.98139762862057,10.4499999433756,0.228544579659644,0.0420876579286119,2.5,0.000162768857572852,0.0207240135923897,0.000218109174308107,20.7972927,20.8728695,10000.072,10000.072,53.3352036382364,18.5730809447014,28.68342,0,0,0,400,4886,20.8717,10000.072,,,,,,,,,,,,,0,,,,17.3732109,,,,,,20.8350811,,,,
,19015320.06,1.9911998,10000.072,0.0213694873511506,2.28170148306964E-6,1,9.99253354069792,40.0298881530762,1.98165692194247,10.5499997735024,0.234247934021526,0.0430813328717317,2.5,0.000163710722948189,0.0212376535445823,0.000218548621185565,1.9901854,1.9922142,10000.072,10000.072,52.9123426093325,18.5563746920659,26.777365,0,0,0,400,4885,1.9802,10000.072,,,,,,,,,,,,,0,,,,19.007576,,,,,,1.9911998,,,,
,19016579.125,32.5117435,10000.072,0.0164458542242809,2.91798845236232E-6,1,9.99253354069792,40.0298881530762,1.99243419991272,10.5400001630187,0.18129310801462,0.0336273088656571,2.5,0.000129323985864685,0.0163556113739948,0.000193182691142046,32.242588,32.780899,10000.072,10000.072,52.4206982707363,18.5666185632419,28.30221,0,0,0,400,4886,33.27605,10000.072,,,,,,,,,,,,,0,,,,23.3056326,,,,,,32.5117435,,,,
,19017338.525,69.21679685,10000.072,0.00939759209486682,1.13879909243554E-6,1,9.99253354069792,40.0298881530762,1.99255176985348,10.5400001630187,0.104517545053494,0.0193459406929684,2.5,5.96518437597014E-5,0.009428048264779,0.000107818386866366,68.9769821,69.4566116,10000.072,10000.072,53.1366699943518,18.5624401526215,29.445843,0,0,0,400,4886,72.3365,10000.072,,,,,,,,,,,,,0,,,,18.9178305,,,,,,69.21679685,,,,
,19018087.96,105.73217775,10000.072,0.00647966509788143,1.85789632044896E-6,1,9.99253354069792,40.0298881530762,1.99258000685378,10.5400001630187,0.0722193162885488,0.013074006634775,2.5,3.24213628753864E-5,0.00651003762276803,4.88372842667115E-5,105.4909821,105.9733734,10000.072,10000.072,52.6692561398517,18.5636735319813,30.97069,0,0,0,400,4886,110.81745,10000.072,,,,,,,,,,,,,0,,,,19.36796285,,,,,,105.73217775,,,,
,19018847.435,143.65258785,10000.072,0.00486046578367815,5.46901748122926E-7,1,9.99253354069792,40.0298881530762,1.99234516786149,10.5400001630187,0.0541626312976345,0.00967815962030754,2.5,1.78579331576596E-5,0.00488098889327835,2.55288873155892E-5,143.4098663,143.8953094,10000.072,10000.072,52.7013029091402,18.5731745795636,30.589479,0,0,0,400,4886,149.77645,10000.072,,,,,,,,,,,,,0,,,,18.34281255,,,,,,143.65258785,,,,
,19019596.875,180.9895859,10000.072,0.00387079211559342,5.02601035645875E-7,1,9.99253354069792,40.0298881530762,1.992398882519,10.5400001630187,0.0431048205781021,0.00766954917939018,2.5,1.29652044165391E-5,0.00388389299102029,1.7456128331366E-5,180.7449646,181.2342072,10000.072,10000.072,52.6418991416786,18.5676214944694,30.97069,0,0,0,400,4886,187.52445,10000.072,,,,,,,,,,,,,0,,,,20.50403885,,,,,,180.9895859,,,,
,19020356.305,218.8147583,10000.072,0.00319057782370258,4.22728000185694E-7,1,9.99253354069792,40.0298881530762,1.99245989309621,10.5499997735024,0.035505206263632,0.0063206959208382,0.25,1.17264434219731E-5,0.00319814077684387,1.46647653882845E-5,218.5655823,219.0639343,10000.072,10000.072,53.3211343248902,18.5578670584561,30.97069,0,0,0,400,4886,225.74305,10000.072,,,,,,,,,,,,,0,,,,20.90531635,,,,,,218.8147583,,,,
,19021105.73,256.0532074,10000.072,0.00270706103473769,3.13230613992937E-7,1,9.99253354069792,40.0298881530762,1.9923095845712,10.5400001630187,0.0300908787906804,0.00535046530980374,0.25,9.81000648093867E-6,0.00271054355242171,1.18733388907152E-5,255.8041992,256.3022156,10000.072,10000.072,53.2054533040441,18.5670067827582,31.351902,0,0,0,400,4886,263.5185,10000.072,,,,,,,,,,,,,0,,,,18.9839077,,,,,,256.0532074,,,,
,19021865.2,293.813385,10000.072,0.00232202759402956,3.49839218464826E-7,1,9.99253354069792,40.0298881530762,1.99248021142934,10.5400001630187,0.025783749596288,0.00458522618152898,0.25,8.73005215620811E-6,0.0023223820164824,1.02264951347184E-5,293.5665588,294.0602112,10000.072,10000.072,53.4782416572557,18.5680491476074,31.351902,0,0,0,400,4886,301.789,10000.072,,,,,,,,,,,,,0,,,,17.5266352,,,,,,293.813385,,,,
,19023683.835,287.543396,46998.77,0.0113059720083107,1.41829236850004E-6,1,9.99253354069792,40.0298881530762,1.98202468106628,9.25000011920929,0.12496688191167,0.0220180899090394,0.25,2.38860440027523E-5,0.011309796522538,3.17893283440879E-5,287.2921143,287.7946777,46998.77,46998.77,52.1721404016209,18.5556340202477,31.733112,0,0,0,400,4886,280.9497,46998.77,,,,,,,,,,,,,0,,,,17.90175055,,,,,,287.543396,,,,
,19024553.29,244.3913879,46998.77,0.0132862843496206,1.75903651155577E-6,1,9.99253354069792,40.0298881530762,1.98164445781879,9.25000011920929,0.147005898820543,0.0259702687252514,0.25,3.20557541212634E-5,0.0133078812989168,4.34715225114536E-5,244.1452789,244.6374969,46998.77,46998.77,52.8349613859287,18.5760534838533,31.351902,0,0,0,400,4886,237.03305,46998.77,,,,,,,,,,,,,0,,,,20.2058649,,,,,,244.3913879,,,,
,19025392.6,202.4047699,46998.77,0.0159915778381711,1.56855787542426E-6,1,9.99253354069792,40.0298881530762,2.00636078297473,9.30999964475632,0.179211351745377,0.0316674442981298,2.5,3.56138772603492E-5,0.0160365498684452,5.30544674102585E-5,202.1568909,202.6526489,46998.77,46998.77,52.3526965895632,18.5703110720384,29.445843,0,0,0,400,4886,195.0881,46998.77,,,,,,,,,,,,,0,,,,18.3336649,,,,,,202.4047699,,,,
,19026241.955,159.69293215,46998.77,0.0200783380675659,2.15841537147232E-6,1,9.99253354069792,40.0298881530762,1.9815703563047,9.37999971210957,0.222531317196863,0.0395817087798253,2.5,5.90931609391007E-5,0.0201557575157269,8.94646936104447E-5,159.4355164,159.9503479,46998.77,46998.77,53.1351067373133,18.5700883130216,31.733112,0,0,0,400,4886,152.87615,46998.77,,,,,,,,,,,,,0,,,,19.85652545,,,,,,159.69293215,,,,
,19027081.32,117.58472825,46998.77,0.0267190260518879,3.06090528629682E-6,1,9.99253354069792,40.0298881530762,1.98109323414664,9.53000038862228,0.296153419538511,0.0532650283543793,2.5,0.000105529642570926,0.0268392325134088,0.00017078000333738,117.330719,117.8387375,46998.77,46998.77,53.5313923965634,18.5725455922647,31.351902,0,0,0,400,4886,111.9347,46998.77,,,,,,,,,,,,,0,,,,18.9848366,,,,,,117.58472825,,,,
,19027920.715,74.8257332,46998.77,0.0399829604575385,4.85439867288371E-6,1,9.99253354069792,40.0298881530762,2.00613341732898,9.73999965935945,0.44764703217024,0.0824882853813884,2.5,0.000224041930700308,0.0401125672474383,0.00042665194107946,74.5627365,75.0887299,46998.77,46998.77,53.1960737618133,18.5692422278863,30.97069,0,0,0,400,4886,71.09415,46998.77,,,,,,,,,,,,,0,,,,20.19279955,,,,,,74.8257332,,,,
,19028760.1,31.2554903,46998.77,0.0775348882963648,1.32980208676836E-5,1,9.99253354069792,40.0298881530762,2.00624538404791,9.97000001370907,0.861140930771166,0.160568420936842,2.5,0.000600303563401949,0.0771889979164015,0.000984407269867951,30.9985161,31.5124645,46998.77,46998.77,52.6348644850056,18.5724849550127,29.827055,0,0,0,400,4886,30.51115,46998.77,,,,,,,,,,,,,0,,,,19.07919695,,,,,,31.2554903,,,,
,19030948.515,13.8223276,46998.77,0.106947101260847,1.11947110050455E-5,1,9.99253354069792,40.0298881530762,1.98136707914293,10.1699996739626,1.17347733730504,0.218624654791256,25,0.000868141079514555,0.106416973037761,0.00134120078976113,13.6410818,14.0035734,46998.77,46998.77,52.7059926802556,18.5542084273263,29.064632,0,0,0,400,4886,13.9287,46998.77,,,,,,,,,,,,,0,,,,19.6655331,,,,,,13.8223276,,,,
,19031737.88,28.6857262,46998.77,0.0821046413051893,7.75672588939083E-6,1,9.99253354069792,40.0298881530762,1.98114189710546,10.1899998262525,0.90108621200775,0.168092979539662,25,0.0006526931554402,0.0817273481736965,0.00104897962732986,28.6241856,28.7472668,46998.77,46998.77,52.7950983314479,18.5688103531059,29.445843,0,0,0,400,4886,28.77465,46998.77,,,,,,,,,,,,,0,,,,17.62429615,,,,,,28.6857262,,,,
,19032587.23,36.83435245,46998.77,0.0702837641176577,5.65192207249705E-6,1,9.99253354069792,40.0298881530762,1.9812981562124,10.1500004529953,0.772050880185711,0.14442639805869,25,0.000545463545331752,0.0700248652765624,0.000934215859566506,36.7993011,36.8694038,46998.77,46998.77,53.5220128543326,18.5636194295362,29.827055,0,0,0,400,4886,36.88815,46998.77,,,,,,,,,,,,,0,,,,17.92317585,,,,,,36.83435245,,,,
,19033376.67,42.1074181,46998.77,0.0640549814465794,5.35919807009422E-6,1,9.99253354069792,40.0298881530762,1.98132220078086,10.1500004529953,0.704299691798732,0.131955246648775,25,0.000483869888555967,0.0638821913960227,0.000870054323845109,42.0766106,42.1382256,46998.77,46998.77,53.0170808309095,18.5640223066699,30.97069,0,0,0,400,4886,42.15805,46998.77,,,,,,,,,,,,,0,,,,19.36796285,,,,,,42.1074181,,,,
,19036044.7,10.03584385,46998.77,0.107672397324413,8.47548365898174E-6,1,9.99253354069792,40.0298881530762,2.00584740457023,10.4099996387959,1.19548592995659,0.222440275230456,25,0.000849245331625244,0.107139485460482,0.00132564387231669,9.9261274,10.1455603,46998.77,46998.77,53.0108278027556,18.5675917946094,28.30221,0,0,0,400,4886,10.0821,46998.77,,,,,,,,,,,,,0,,,,18.51588535,,,,,,10.03584385,,,,
,19036834.235,22.5925417,46998.77,0.0928903412629825,7.41644285760887E-6,1,9.99253354069792,40.0298881530762,1.98131071517374,10.3799998760223,1.01926176442603,0.190007949689476,25,0.000755068621194407,0.0924361760376824,0.00117502732383196,22.5373573,22.6477261,46998.77,46998.77,53.1874758481018,18.5627192505905,28.68342,0,0,0,400,4886,22.66205,46998.77,,,,,,,,,,,,,0,,,,20.0684013,,,,,,22.5925417,,,,
,19037663.505,30.32448005,46998.77,0.0795438990017961,7.30401991172188E-6,1,9.99253354069792,40.0298881530762,2.00615123609926,10.329999960959,0.88367225679555,0.164772269938558,25,0.000616867880278552,0.0791885135070299,0.00101013753944678,30.2863579,30.3626022,46998.77,46998.77,53.3148812967364,18.5718260463371,29.445843,0,0,0,400,4886,30.3831,46998.77,,,,,,,,,,,,,0,,,,18.7129831,,,,,,30.32448005,,,,
,19038452.99,35.7272797,46998.77,0.0717219139086014,6.21551142727008E-6,1,9.99253354069792,40.0298881530762,1.98118610669605,10.3000001981854,0.787682378675804,0.14729298405379,25,0.000559261534271623,0.0714456410721441,0.000948124072727706,35.6967812,35.7577782,46998.77,46998.77,52.9787810334671,18.5656223288402,29.827055,0,0,0,400,4886,35.7721,46998.77,,,,,,,,,,,,,0,,,,18.1604824,,,,,,35.7272797,,,,
,19039242.355,40.20070455,46998.77,0.0661971113936152,5.90543156907638E-6,1,9.99253354069792,40.0298881530762,1.99202776840615,10.2800000458956,0.73133480303747,0.137033662285057,25,0.000512218723806424,0.0659924823433729,0.000899947340346001,40.1734123,40.2279968,46998.77,46998.77,52.7880636747748,18.560620125505,29.827055,0,0,0,400,4886,40.2457,46998.77,,,,,,,,,,,,,0,,,,19.3670158,,,,,,40.20070455,,,,
,19040031.76,44.14058115,46998.77,0.0619328395720131,5.89908611173063E-6,1,9.99253354069792,40.0298881530762,1.98131986632512,10.2500002831221,0.681260194457662,0.127732662378925,25,0.000466622451022427,0.0617939379581425,0.000849853186985,44.1161385,44.1650238,46998.77,46998.77,53.2210858744287,18.5669287518437,29.827055,0,0,0,400,4886,44.1881,46998.77,,,,,,,,,,,,,0,,,,19.17546175,,,,,,44.14058115,,,,
,19043559.19,3.74524595,46998.77,0.0957971928226842,7.77680100897012E-6,1,9.99253354069792,40.0298881530762,1.98136321401752,10.5799995362759,1.05119817762942,0.195529425110983,25,0.000749971972111272,0.0953234666146663,0.00117386076579451,3.692591,3.7979009,46998.77,46998.77,52.0634940374478,18.5687550668142,27.158575,0,0,0,400,4886,3.7404,46998.77,,,,,,,,,,,,,0,,,,18.79614355,,,,,,3.74524595,,,,
,19044348.575,13.0341444,46998.77,0.10756746140745,9.00469358966028E-6,1,9.99253354069792,40.0298881530762,1.98141893840121,10.5600003153086,1.1803366084812,0.219781724835965,25,0.000862532323671782,0.107034478304713,0.0013383906141137,12.9818535,13.0864353,46998.77,46998.77,53.3805380923518,18.5621519718868,27.920998,0,0,0,400,4886,13.0668,46998.77,,,,,,,,,,,,,0,,,,18.8289595,,,,,,13.0341444,,,,
,19045177.965,19.46863745,46998.77,0.0986767616692577,8.56217904290595E-6,1,9.99253354069792,40.0298881530762,2.00617817583761,10.4900002479553,1.09578317462155,0.203877304952612,25,0.000774973898455326,0.0981884374805245,0.00121388761749386,19.4468403,19.4904346,46998.77,46998.77,53.3930441486595,18.5680011131362,28.68342,0,0,0,400,4886,19.48645,46998.77,,,,,,,,,,,,,0,,,,19.3670158,,,,,,19.46863745,,,,
,19047796.095,5.3698137,46998.77,0.0989489367026222,1.96982575139707E-5,1,9.99253354069792,40.0298881530762,1.98129193426801,10.5799995362759,1.0857592516303,0.201875493300114,25,0.000767377908678315,0.0984596355548202,0.0012052481381004,5.1185408,5.6210866,46998.77,46998.77,51.5898271547939,18.5640798759544,27.158575,0,0,0,400,4882,5.4208,46998.77,,,,,,,,,,,,,0,,,,19.87684725,,,,,,5.3698137,,,,
,19048555.485,42.68585015,46998.77,0.0638554628179212,9.10548796208252E-6,1,9.99253354069792,40.0298881530762,1.98123388969052,10.5799995362759,0.702384522134705,0.13149713946497,25,0.000464849463740522,0.0637096936912852,0.000859002701764548,42.4465752,42.9251251,46998.77,46998.77,52.5910932879286,18.5689458610275,28.30221,0,0,0,400,4886,43.96585,46998.77,,,,,,,,,,,,,0,,,,19.270751,,,,,,42.68585015,,,,
,19049324.94,77.42892455,46998.77,0.0397629083005006,4.67227755033806E-6,1,9.99253354069792,40.0298881530762,1.98133774225829,10.5799995362759,0.440452512680838,0.0810376482744434,25,0.000248117946679637,0.0399275303548615,0.000413731816900267,77.1796112,77.6782379,46998.77,46998.77,52.4597796966979,18.5674933347714,29.445843,0,0,0,400,4886,81.12795,46998.77,,,,,,,,,,,,,0,,,,21.19946385,,,,,,77.42892455,,,,
,19049944.465,100.0852661,46998.77,0.0313655828860281,3.48954295089769E-6,1,9.99253354069792,40.0298881530762,1.98151289761227,10.5799995362759,0.347633705490505,0.0632789922365025,2.5,0.000174536393995048,0.0315097811425007,0.000266759536490287,100.077774,100.0927582,46998.77,46998.77,53.340675037871,18.5621323148424,29.827055,0,0,0,400,4881,100.1856,46998.77,,,,,,,,,,,,,0,,,,17.0954094,,,,,,100.0852661,,,,