File: DataFailid_Testimiseks/PFO#1_HIGHTEMPSWEEP_300-600K_0p1_0p5_5T__2019-12-05.DAT
[Header]
; VSM Data File (default extension .dat)
; Copyright (c) 2003, Quantum Design, Inc. All rights reserved.
TITLE,PFO#1_HIGHTEMPSWEEP_300-600K_0p1_0p5_5T__2019-12-0
FILEOPENTIME,9564875.73,12/09/2019,6:44 pm
BYAPP,VSM,1.0,1.0
INFO,PPMS VSM Option Release 1.3.6 Build 0,APPNAME
INFO,221,COIL_SERIAL_NUMBER
INFO,0,MOMENT_UNITS
INFO,PFO#1_HIGHTEMPSWEEP_300-600K_0p1_0p5_5T__2019-12-0,SAMPLE_MATERIAL
INFO,,SAMPLE_COMMENT
INFO,unknown,SAMPLE_MASS
INFO,,SAMPLE_VOLUME
INFO,,SAMPLE_MOLECULAR_WEIGHT
INFO,,SAMPLE_SIZE
INFO,rectangular thin film,SAMPLE_SHAPE
INFO,35.86,SAMPLE_OFFSET
DATATYPE,COMMENT,1
DATATYPE,TIME,2
STARTUPAXIS,X,2
STARTUPAXIS,Y1,5
[Data]
Comment,Time Stamp (sec),Temperature (K),Magnetic Field (Oe),Moment (emu),M. Std. Err. (emu),Transport Action,Averaging Time (sec),Frequency (Hz),Peak Amplitude (mm),Center Position (mm),Coil Signal' (mV),Coil Signal" (mV),Range (mV),M. Quad. Signal (emu),M. Raw' (emu),M. Raw" (emu),Min. Temperature (K),Max. Temperature (K),Min. Field (Oe),Max. Field (Oe),Mass (grams),Motor Lag (deg),Pressure (Torr),VSM Status (code),Motor Status (code),Measure Status (code),PPMS Status (code),System Temp. (K),System Field (Oe),Sample Position (deg),Bridge 1 Resistance (ohms),Bridge 1 Excitation (에),Bridge 2 Resistance (ohms),Bridge 2 Excitation (에),Bridge 3 Resistance (ohms),Bridge 3 Excitation (에),Bridge 4 Resistance (ohms),Bridge 4 Excitation (에),Signal 1 Vin (V),Signal 2 Vin (V),Digital Inputs (code),Drive 1 Iout (mA),Drive 1 Ipower (W),Drive 2 Iout (mA),Drive 2 Ipower (W),Pressure (),Map 20 (),Map 21 (),Map 22 (),Map 23 (),Map 24 (),Map 25 (),Map 26 (),Map 27 (),Map 28 (),Map 29 ()
,9726454.425,299.994323730469,1000.176,7.80409943034112E-5,1.37928205642386E-7,1,9.99253354069792,40.0298881530762,1.9890944540211,11.4900009334087,0.000834517243538837,0.000135482026731523,0.25,-7.7977653539201E-7,7.80516400696695E-5,-7.26996016947466E-7,295.0030212,295.0055542,1000.176,1000.176,57.5849178972945,21.6333300937009,9.3E-6,0,0,0,5905,294.95015,1000.176,,,,,,,,,,,,,,,,,29.827055,,,,,,295.0042877,,,,
,9726644.265,323.825775146484,1000.176,7.54879567124735E-5,1.81353964021651E-7,1,9.99253354069792,40.0298881530762,1.98911719446063,11.4900009334087,0.000806946687688709,0.000132653160561364,0.25,-6.04205675778364E-7,7.54979292437383E-5,-5.53098114728985E-7,295.0893555,295.1005859,1000.176,1000.176,58.0077789261985,21.6511718860616,9.3E-6,0,0,0,5910,294.7922,1000.176,,,,,,,,,,,,,,,,,29.827055,,,,,,295.0949707,,,,
,9726824.07,353.84228515625,1000.176,7.19784268750974E-5,1.77935567856155E-7,1,9.99253354069792,40.0298881530762,1.98909269669621,11.4800013229251,0.000769904097566018,0.000123667321100161,0.25,-8.40081281789658E-7,7.19877666213181E-5,-7.91260809688695E-7,295.2381897,295.2437744,1000.176,1000.176,58.3032345064677,21.6595930299017,9.3E-6,0,0,0,5906,294.19185,1000.176,,,,,,,,,,,,,,,,,29.827055,,,,,,295.24098205,,,,
,9727003.92,383.839385986328,1000.176,6.79966064417456E-5,1.78116702294759E-7,1,9.99253354069792,40.0298881530762,1.98924407771116,11.4900009334087,0.00072732704155551,0.000117055387553695,0.25,-7.73040922925367E-7,6.80053014755126E-5,-7.2678700331992E-7,295.2879639,295.2884827,1000.176,1000.176,57.9389956165061,21.6620694137054,9.3E-6,0,0,0,5906,293.4963,1000.176,,,,,,,,,,,,,,,,,29.827055,,,,,,295.2882233,,,,
,9727183.78,413.734344482422,1000.176,6.29248520978978E-5,1.82209718076271E-7,1,9.99253354069792,40.0298881530762,1.98949957706262,11.4900009334087,0.000672949989654887,0.00010955218023595,0.25,-6.01759409236716E-7,6.2932797461203E-5,-5.58817627491519E-7,295.2941284,295.2955017,1000.176,1000.176,57.6834030907176,21.6704747876199,9.3E-6,0,0,0,5910,292.7858,1000.176,,,,,,,,,,,,,,,,,29.827055,,,,,,295.29481505,,,,
,9727363.635,443.736511230469,1000.176,5.65317716658185E-5,1.9077422298938E-7,1,9.99253354069792,40.0298881530762,1.98956126801821,11.4800013229251,0.000604974100906769,9.62375020984463E-5,0.25,-7.45578689467687E-7,5.65389915154945E-5,-7.06909756936935E-7,295.321228,295.3225403,1000.176,1000.176,58.8722600684678,21.6716454654428,0.00014545,0,0,0,5910,292.0643,1000.176,,,,,,,,,,,,,,,,,29.827055,,,,,,295.32188415,,,,
,9727543.515,473.701934814453,1000.176,4.96196242313378E-5,1.80151632501302E-7,1,9.99253354069792,40.0298881530762,1.98948825348098,11.4900009334087,0.000530880092319465,8.5077549857828E-5,0.25,-5.97387022686026E-7,4.96259458490505E-5,-5.63340344928198E-7,295.3019104,295.3021851,1000.176,1000.176,58.3602933883716,21.6798882914274,9.3E-6,0,0,0,5906,291.351,1000.176,,,,,,,,,,,,,,,,,29.827055,,,,,,295.30204775,,,,
,9727723.445,503.698455810547,1000.176,4.20030273667392E-5,1.72331787280715E-7,1,9.99253354069792,40.0298881530762,1.98954424075631,11.4900009334087,0.000449586425609123,7.09516596060836E-5,0.25,-6.05843538376402E-7,4.20084181212499E-5,-5.76944764958828E-7,295.3176575,295.3193359,1000.176,1000.176,58.4095359850831,21.6841202572612,9.3E-6,0,0,0,5906,290.59365,1000.176,,,,,,,,,,,,,,,,,30.208265,,,,,,295.3184967,,,,
,9727903.335,533.676086425781,1000.176,3.19698387907812E-5,1.67987510833791E-7,1,9.99253354069792,40.0298881530762,1.98953307184702,11.4900009334087,0.000342642632142599,5.1395522020228E-5,0.25,-7.05434987072076E-7,3.19740902991641E-5,-6.83395852967872E-7,295.3320618,295.3338928,1000.176,1000.176,58.0961029488715,21.6833577805342,9.3E-6,0,0,0,5906,289.80235,1000.176,,,,,,,,,,,,,,,,,30.208265,,,,,,295.3329773,,,,
,9728083.115,563.623352050781,1000.176,1.98086030045794E-5,1.61769982857234E-7,1,9.99253354069792,40.0298881530762,1.98979395343978,11.4900009334087,0.000213244802836588,2.65431781061455E-5,0.25,-9.33994983201934E-7,1.98115630488196E-5,-9.20348733517414E-7,295.3570862,295.3583069,1000.176,1000.176,58.5463209759485,21.6890482192519,9.25E-6,0,0,0,5910,288.94925,1000.176,,,,,,,,,,,,,,,,,30.589479,,,,,,295.35769655,,,,
,9728262.99,580.033508300781,1000.176,1.8821657550426E-5,1.70845152513495E-7,1,9.99253354069792,40.0298881530762,1.98969669035026,11.4800013229251,0.000202676791036788,2.48373816105761E-5,0.25,-9.23293781642259E-7,1.88245177590093E-5,-9.10287933717914E-7,295.3088379,295.3247681,1000.176,1000.176,58.9816880611601,21.6912667976293,9.3E-6,0,0,0,5905,288.1239,1000.176,,,,,,,,,,,,,,,,,30.97069,,,,,,295.316803,,,,
,9728542.825,557.838928222656,1000.176,1.97044851569489E-5,1.55101910742318E-7,1,9.99253354069792,40.0298881530762,1.98953003187311,11.4800013229251,0.000211550169759771,2.95909298284762E-5,0.25,-6.30329345696298E-7,1.97075900089135E-5,-6.16707109388678E-7,294.7640686,294.7877197,1000.176,1000.176,58.9723085189293,21.6941642780718,9.3E-6,0,0,0,5906,288.5192,1000.176,,,,,,,,,,,,,,,,,29.827055,,,,,,294.77589415,,,,
,9728722.65,528.007690429687,1000.176,3.28697386258177E-5,1.60480431395208E-7,1,9.99253354069792,40.0298881530762,1.98951206847938,11.4800013229251,0.000352412294951375,5.21499006262095E-5,0.25,-7.90218142284448E-7,3.28749700446718E-5,-7.67573086670615E-7,294.561554,294.5630493,1000.176,1000.176,58.4720662666216,21.697442349165,9.3E-6,0,0,0,5906,289.6718,1000.176,,,,,,,,,,,,,,,,,29.827055,,,,,,294.56230165,,,,
,9728902.54,498.099090576172,1000.176,4.21902091510032E-5,1.54771989521026E-7,1,9.99253354069792,40.0298881530762,1.98969836674032,11.4900009334087,0.000451638371180201,7.12510407444601E-5,0.25,-6.10761049779697E-7,4.21966282775452E-5,-5.8175871304517E-7,294.5787964,294.5840149,1000.176,1000.176,57.1644017539484,21.7059279576445,9.3E-6,0,0,0,5906,290.6869,1000.176,,,,,,,,,,,,,,,,,29.445843,,,,,,294.58140565,,,,
,9729082.41,468.220031738281,1000.176,4.94679084883995E-5,1.46045350496061E-7,1,9.99253354069792,40.0298881530762,1.98928687373958,11.4800013229251,0.000528998946971882,8.60728327952138E-5,0.25,-4.77340584231899E-7,4.94751863032546E-5,-4.43419005969871E-7,294.6395874,294.6410217,1000.176,1000.176,58.7245322783331,21.7020925894864,9.3E-6,0,0,0,5906,291.53515,1000.176,,,,,,,,,,,,,,,,,29.445843,,,,,,294.64030455,,,,
,9729272.24,436.725219726562,1000.176,5.69298859296548E-5,1.41433311969902E-7,1,9.99253354069792,40.0298881530762,1.98963397309403,11.4800013229251,0.000608610139793985,0.000100733331489258,0.25,-3.93719274308794E-7,5.69380743641091E-5,-3.54782393044028E-7,294.6885681,294.6912231,1000.176,1000.176,58.2047493130446,21.7028844443414,9.25E-6,0,0,0,5910,292.3126,1000.176,,,,,,,,,,,,,,,,,29.445843,,,,,,294.6898956,,,,
,9729452.11,406.734527587891,1000.176,6.38487335851042E-5,1.45588944039368E-7,1,9.99253354069792,40.0298881530762,1.98969558421156,11.4900009334087,0.000682480606619088,0.000113647553337191,0.25,-3.78842963130022E-7,6.38578280643177E-5,-3.35282147160503E-7,294.7171021,294.7174683,1000.176,1000.176,58.568206574487,21.7089193876844,9.3E-6,0,0,0,5910,292.97145,1000.176,,,,,,,,,,,,,,,,,29.445843,,,,,,294.7172852,,,,
,9729631.97,376.802398681641,1000.176,7.01457472680903E-5,1.31837564451768E-7,1,9.99253354069792,40.0298881530762,1.98946584861993,11.4900009334087,0.000749165877987908,0.000127970974508578,0.25,-1.23028312519917E-7,7.01554975959629E-5,-7.52495415597053E-8,294.7398987,294.7403564,1000.176,1000.176,58.8472479558524,21.7101400884784,9.25E-6,0,0,0,5906,293.58275,1000.176,,,,,,,,,,,,,,,,,29.445843,,,,,,294.74012755,,,,
,9729811.855,347.651885986328,1000.176,7.53774556996445E-5,1.10603924408502E-7,1,9.99253354069792,40.0298881530762,1.98990043819998,11.4800013229251,0.000805254274675578,0.000137284854525616,0.25,-1.56376239137157E-7,7.53879049506189E-5,-1.05153334913917E-7,294.7615662,294.7641907,1000.176,1000.176,58.6213573137947,21.7125154836613,9.3E-6,0,0,0,5910,294.1413,1000.176,,,,,,,,,,,,,,,,,29.064632,,,,,,294.76287845,,,,
,9729991.79,328.262145996094,1000.176,7.87828688546544E-5,1.22243613853767E-7,1,9.99253354069792,40.0298881530762,1.98958188370938,11.4800013229251,0.000841137718039118,0.000145582051051917,0.25,3.4942797501998E-8,7.87934995163511E-5,8.84143283208274E-8,294.8254395,294.829834,1000.176,1000.176,58.6510591975254,21.7122590050404,9.3E-6,0,0,0,5910,294.5691,1000.176,,,,,,,,,,,,,,,,,29.445843,,,,,,294.82763675,,,,
,9730171.7,315.982421875,1000.176,8.08891976409978E-5,1.14126186774618E-7,1,9.99253354069792,40.0298881530762,1.98967073811539,11.4900009334087,0.000863258003852573,0.000151816382657923,0.25,2.54697490423851E-7,8.08997734952011E-5,3.09577808311031E-7,294.9006348,294.90448,1000.176,1000.176,58.6752896816216,21.716494446601,9.25E-6,0,0,0,5910,294.7933,1000.176,,,,,,,,,,,,,,,,,29.445843,,,,,,294.9025574,,,,
,9730351.485,308.063507080078,1000.176,8.19794767920717E-5,1.25654494321039E-7,1,9.99253354069792,40.0298881530762,1.98983498801873,11.4900009334087,0.000875304826416815,0.00015188603997093,0.25,7.19343804893098E-8,8.1990196881755E-5,1.27506800087905E-7,294.9497375,294.9512939,1000.176,1000.176,59.2349357013909,21.719639412711,9.3E-6,0,0,0,5910,294.8944,1000.176,,,,,,,,,,,,,,,,,29.445843,,,,,,294.9505157,,,,
,9730531.335,303.065185546875,1000.176,8.3074263270635E-5,1.1951217828866E-7,1,9.99253354069792,40.0298881530762,1.98969757101489,11.4800013229251,0.000887209037860123,0.000152314943835045,0.25,-7.59153042860824E-8,8.30851812165972E-5,-1.96349248753729E-8,294.9675293,294.9689941,1000.176,1000.176,58.974653404487,21.7255113858892,9.3E-6,0,0,0,5910,294.95885,1000.176,,,,,,,,,,,,,,,,,29.445843,,,,,,294.9682617,,,,
,9730711.195,299.838653564453,1000.176,8.33803722833468E-5,1.29366707365576E-7,1,9.99253354069792,40.0298881530762,1.98979596593629,11.4900009334087,0.000890506722844371,0.000152960621754421,0.25,-6.89542568754922E-8,8.33912885199772E-5,-1.24725298932496E-8,294.9821167,294.9824524,1000.176,1000.176,58.2790040223716,21.7186552262949,9.3E-6,0,0,0,5905,294.9895,1000.176,,,,,,,,,,,,,,,,,29.445843,,,,,,294.98228455,,,,
,9731070.92,322.230743408203,5000.104,8.91473756702714E-5,2.9757911328063E-7,1,9.99253354069792,40.0298881530762,1.98980153747176,11.4800013229251,0.000945498899521769,0.00020176950363138,0.25,3.50630878480726E-6,8.91563287393287E-5,3.56715271146441E-6,295.0793457,295.0889893,5000.104,5000.104,58.8558458695639,21.724279716649,9.3E-6,0,0,0,5906,294.85015,5000.104,,,,,,,,,,,,,,,,,29.445843,,,,,,295.0841675,,,,
,9731250.86,352.179931640625,5000.104,8.27606530519502E-5,2.96201091132503E-7,1,9.99253354069792,40.0298881530762,1.98983104621065,11.4800013229251,0.000877906105960778,0.000186525464062284,0.25,3.18094566006025E-6,8.27686330682013E-5,3.23753258301168E-6,295.2203674,295.2220764,5000.104,5000.104,58.619012428237,21.7333193136029,9.3E-6,0,0,0,5910,294.2935,5000.104,,,,,,,,,,,,,,,,,29.827055,,,,,,295.2212219,,,,
,9731430.665,382.188323974609,5000.104,7.63226152913317E-5,2.96549524411605E-7,1,9.99253354069792,40.0298881530762,1.98980694649567,11.4800013229251,0.000809440039770989,0.000172953030727219,0.25,3.02137534974068E-6,7.63298027940824E-5,3.07369931193932E-6,295.2591858,295.2601929,5000.104,5000.104,58.9324454644486,21.7310406820761,9.3E-6,0,0,0,5910,293.66245,5000.104,,,,,,,,,,,,,,,,,29.445843,,,,,,295.25968935,,,,
,9731610.565,412.202850341797,5000.104,6.87632015963863E-5,3.06866509837382E-7,1,9.99253354069792,40.0298881530762,1.98985936761182,11.4900009334087,0.000729009505606277,0.000157431648685593,0.25,2.87229843951283E-6,6.87695282774259E-5,2.91957874053023E-6,295.2728271,295.2738647,5000.104,5000.104,59.4897465986601,21.7341877833085,9.3E-6,0,0,0,5906,293.019,5000.104,,,,,,,,,,,,,,,,,29.827055,,,,,,295.2733459,,,,
,9731790.435,442.137298583984,5000.104,5.97373847590226E-5,2.92719086824148E-7,1,9.99253354069792,40.0298881530762,1.9897228843354,11.4900009334087,0.000632667442322184,0.000140295745830908,0.25,2.826464662615E-6,5.97426215320165E-5,2.86768819671202E-6,295.2815857,295.2837219,5000.104,5000.104,58.9324454644486,21.7323103643742,9.3E-6,0,0,0,5910,292.3527,5000.104,,,,,,,,,,,,,,,,,29.827055,,,,,,295.2826538,,,,
,9731970.275,472.12646484375,5000.104,5.0533231450664E-5,3.13888355920074E-7,1,9.99253354069792,40.0298881530762,1.98961548752152,11.4900009334087,0.000534292170644517,0.000123699508650515,0.25,2.86161462461324E-6,5.05373006957892E-5,2.89664055393779E-6,295.2967529,295.2976379,5000.104,5000.104,59.9493441679679,21.7416922156046,9.3E-6,0,0,0,5906,291.64915,5000.104,,,,,,,,,,,,,,,,,28.68342,,,,,,295.2971954,,,,
,9732150.135,502.105773925781,5000.104,4.09537970896085E-5,2.96146017685419E-7,1,9.99253354069792,40.0298881530762,1.98967053765473,11.4900009334087,0.000432698023040778,0.000102112446167358,0.25,2.49322814318733E-6,4.09569350841891E-5,2.52171951412325E-6,295.3175659,295.3177795,5000.104,5000.104,59.0215511156409,21.7337574927922,9.3E-6,0,0,0,5906,290.8972,5000.104,,,,,,,,,,,,,,,,,29.827055,,,,,,295.3176727,,,,
,9732330,531.995666503906,5000.104,2.96697384001416E-5,2.93650503753435E-7,1,9.99253354069792,40.0298881530762,1.98970760077721,11.4900009334087,0.000312342884716309,8.05736572712766E-5,0.25,2.42384193820127E-6,2.96715575737678E-5,2.44462129465713E-6,295.3353882,295.3360901,5000.104,5000.104,58.7229690212947,21.7416156179425,9.3E-6,0,0,0,5906,290.09905,5000.104,,,,,,,,,,,,,,,,,30.208265,,,,,,295.33573915,,,,
,9732509.86,562.005920410156,5000.104,1.54345837227072E-5,2.92704027750046E-7,1,9.99253354069792,40.0298881530762,1.98987857081033,11.4800013229251,0.000160503018019181,5.34751965299214E-5,0.25,2.34305279060103E-6,1.54347631570945E-5,2.35402504128571E-6,295.3561707,295.35672,5000.104,5000.104,59.2443152436217,21.7484826110103,9.25E-6,0,0,0,5906,289.25145,5000.104,,,,,,,,,,,,,,,,,30.589479,,,,,,295.35644535,,,,
,9732689.79,580.021057128906,5000.104,1.25204872349197E-5,3.21137154445737E-7,1,9.99253354069792,40.0298881530762,1.98968114336756,11.4800013229251,0.000129498075081936,4.73663434813531E-5,0.25,2.27446521897618E-6,1.25203735302063E-5,2.28344125319503E-6,295.3282166,295.3434753,5000.104,5000.104,59.1622442491024,21.749591951678,9.3E-6,0,0,0,5905,288.39565,5000.104,,,,,,,,,,,,,,,,,30.589479,,,,,,295.33584595,,,,
,9732969.615,559.558715820313,5000.104,1.45026375845455E-5,2.83159368997248E-7,1,9.99253354069792,40.0298881530762,1.98972945603404,11.4800013229251,0.000150629719844211,5.12502940123594E-5,0.25,2.29582983200512E-6,1.4502988465544E-5,2.30621529317907E-6,294.8016052,294.8245239,5000.104,5000.104,59.3803186059678,21.7471964322745,9.3E-6,0,0,0,5906,288.65645,5000.104,,,,,,,,,,,,,,,,,29.827055,,,,,,294.81306455,,,,
,9733149.385,529.687255859375,5000.104,2.87100954614758E-5,2.74752091835041E-7,1,9.99253354069792,40.0298881530762,1.98967891705437,11.4800013229251,0.000302349448220218,7.73547137576167E-5,0.25,2.28794693782203E-6,2.87125868623649E-5,2.3081319400096E-6,294.5807495,294.585022,5000.104,5000.104,59.7187637547948,21.7499963601799,9.25E-6,0,0,0,5906,289.7467,5000.104,,,,,,,,,,,,,,,,,29.827055,,,,,,294.58288575,,,,
,9733329.265,499.806671142578,5000.104,3.94434020839207E-5,2.45948890938052E-7,1,9.99253354069792,40.0298881530762,1.98986606957389,11.4800013229251,0.000416358639162545,0.000100850946028664,0.25,2.63469803978377E-6,3.94471878364109E-5,2.66224464666502E-6,294.587616,294.5891418,5000.104,5000.104,59.5405524524102,21.7533510359352,9.25E-6,0,0,0,5906,290.75435,5000.104,,,,,,,,,,,,,,,,,29.445843,,,,,,294.5883789,,,,
,9733509.135,469.873413085937,5000.104,4.87741809582129E-5,2.61128159627576E-7,1,9.99253354069792,40.0298881530762,1.98957670476238,11.4800013229251,0.000515310892181563,0.00012161728545507,0.25,2.97023358022067E-6,4.87789865170555E-5,3.0041353289709E-6,294.6452942,294.6482849,5000.104,5000.104,59.6726476721602,21.7547171991777,9.3E-6,0,0,0,5910,291.59575,5000.104,,,,,,,,,,,,,,,,,29.445843,,,,,,294.64678955,,,,
,9733688.99,439.958190917969,5000.104,5.79443619370516E-5,2.47553607654386E-7,1,9.99253354069792,40.0298881530762,1.98971099241171,11.4900009334087,0.000613948420184301,0.000134566788897967,0.25,2.59929654848869E-6,5.7950644798125E-5,2.6393212946736E-6,294.6896057,294.690155,5000.104,5000.104,59.0903344253332,21.7630352047996,9.3E-6,0,0,0,5906,292.3202,5000.104,,,,,,,,,,,,,,,,,27.920998,,,,,,294.68988035,,,,
,9733868.905,410.09716796875,5000.104,6.67674198604914E-5,2.46613772572399E-7,1,9.99253354069792,40.0298881530762,1.98955968113984,11.4900009334087,0.000707596134501159,0.000153797548331179,0.25,2.87832786812249E-6,6.6774679144015E-5,2.92430637081178E-6,294.7252502,294.7258301,5000.104,5000.104,59.4514468012178,21.7555264185313,9.3E-6,0,0,0,5910,292.97515,5000.104,,,,,,,,,,,,,,,,,29.445843,,,,,,294.72554015,,,,
,9734048.8,380.139129638672,5000.104,7.52451855584558E-5,2.33620102265807E-7,1,9.99253354069792,40.0298881530762,1.98952640111857,11.4900009334087,0.000797338195801678,0.00017385357910775,0.25,3.29361250923978E-6,7.52533053632032E-5,3.34530946682478E-6,294.7435303,294.7440796,5000.104,5000.104,59.4530100582563,21.7542640269535,9.3E-6,0,0,0,5906,293.57585,5000.104,,,,,,,,,,,,,,,,,29.445843,,,,,,294.74380495,,,,
,9734228.645,350.844085693359,5000.104,8.23295965284313E-5,2.36343941338419E-7,1,9.99253354069792,40.0298881530762,1.98970665391064,11.4900009334087,0.000872871395997284,0.000187992862393759,0.25,3.39353043050892E-6,8.23385763439208E-5,3.44994038984687E-6,294.7673035,294.7686157,5000.104,5000.104,58.9285373218524,21.7620834112224,9.3E-6,0,0,0,5910,294.11895,5000.104,,,,,,,,,,,,,,,,,29.445843,,,,,,294.7679596,,,,
,9734408.505,330.979309082031,5000.104,8.67989414095346E-5,2.31169131835764E-7,1,9.99253354069792,40.0298881530762,1.98956056019577,11.4800013229251,0.000920373037807176,0.000197120374439885,0.25,3.47824819138818E-6,8.68083064632827E-5,3.53759855481855E-6,294.830719,294.8362427,5000.104,5000.104,59.7156372407179,21.762683593617,9.3E-6,0,0,0,5910,294.5436,5000.104,,,,,,,,,,,,,,,,,29.445843,,,,,,294.83348085,,,,
,9734588.32,318.119140625,5000.104,8.98888429054879E-5,2.45864823018038E-7,1,9.99253354069792,40.0298881530762,1.98979758114589,11.4800013229251,0.000952959752974469,0.000205805684581241,0.25,3.75619083293874E-6,8.98982447021342E-5,3.81761367027419E-6,294.9007263,294.9037781,5000.104,5000.104,58.2024044274869,21.76442931627,9.2E-6,0,0,0,5910,294.7585,5000.104,,,,,,,,,,,,,,,,,29.445843,,,,,,294.9022522,,,,
,9734768.21,309.767517089844,5000.104,9.16966194796934E-5,2.36973651014313E-7,1,9.99253354069792,40.0298881530762,1.98966500756332,11.4800013229251,0.000972323615655507,0.000208412285765162,0.25,3.68953514813573E-6,9.17061798532997E-5,3.75213835550783E-6,294.9446106,294.9485474,5000.104,5000.104,59.8125591771025,21.7663379613624,9.3E-6,0,0,0,5910,294.8813,5000.104,,,,,,,,,,,,,,,,,29.445843,,,,,,294.946579,,,,
,9734948.07,304.389434814453,5000.104,9.29436111595768E-5,2.42747322480676E-7,1,9.99253354069792,40.0298881530762,1.98986593260169,11.4900009334087,0.000985588703729074,0.000211570269545709,0.25,3.76814037455306E-6,9.29532100359705E-5,3.83158128529263E-6,294.9705811,294.9721069,5000.104,5000.104,59.3005924970063,21.7712739990447,9.3E-6,0,0,0,5910,294.93795,5000.104,,,,,,,,,,,,,,,,,29.445843,,,,,,294.971344,,,,
,9735127.93,300.721405029297,5000.104,9.37617439291443E-5,2.47276662746481E-7,1,9.99253354069792,40.0298881530762,1.98988860482089,11.4900009334087,0.000994904277295766,0.000209788356721298,0.25,3.4598525991862E-6,9.37716241993778E-5,3.52379758080759E-6,294.9829407,294.9832153,5000.104,5000.104,59.1622442491024,21.7763043029582,9.25E-6,0,0,0,5909,294.97085,5000.104,,,,,,,,,,,,,,,,,29.445843,,,,,,294.983078,,,,
,9735917.35,312.050201416016,50000.188,-3.75266657130698E-5,1.29801903344171E-6,1,9.99253354069792,40.0298881530762,1.98936068771246,11.4800013229251,-0.000445750750067159,0.000192152247059678,0.25,2.44756276071924E-5,-3.75479453095233E-5,2.4453612077851E-5,295.0275269,295.0345459,50000.188,50000.188,58.5361598051985,21.7431346950554,9.3E-6,0,0,0,5910,294.8649,50000.188,,,,,,,,,,,,,,,,,29.445843,,,,,,295.0310364,,,,
,9736097.225,342.119049072266,50000.188,-4.6405972925229E-5,1.38986547757993E-6,1,9.99253354069792,40.0298881530762,1.9897573905593,11.4800013229251,-0.000540196756523399,0.000173195765741129,0.25,2.42297696436279E-5,-4.64280488453948E-5,2.42016002689153E-5,295.1672974,295.175354,50000.188,50000.188,59.1786584480063,21.7486199413888,9.3E-6,0,0,0,5910,294.44875,50000.188,,,,,,,,,,,,,,,,,29.827055,,,,,,295.1713257,,,,
,9758584.9,313.892547607422,50001.527,-9.54956049849223E-6,2.20874130824699E-6,1,9.99253354069792,40.0298881530762,2.00361018928684,11.8300007283688,-9.19347471701705E-5,-7.98210297229791E-5,0.25,-5.77708624605485E-6,-9.54691699040825E-6,-5.78424144024779E-6,295.0325012,295.0416565,50001.527,50001.527,58.3329363901985,21.719722714404,9.25E-6,0,0,0,5906,294.83785,50001.527,,,,,,,,,,,,,,,,,29.827055,,,,,,295.03707885,,,,
,9758764.775,343.956634521484,50001.527,-2.27900954241332E-5,1.46399077920362E-6,1,9.99253354069792,40.0298881530762,2.00375744093276,11.8300007283688,-0.00024267110755803,-5.57891688216583E-5,0.25,-1.25563231297332E-6,-2.27920769434782E-5,-1.27111179922805E-6,295.1912231,295.1978149,50001.527,50001.527,58.4314215836216,21.7360253812971,9.3E-6,0,0,0,5906,294.36375,50001.527,,,,,,,,,,,,,,,,,29.445843,,,,,,295.194519,,,,
,9758944.635,373.859344482422,50001.527,-3.37954396019261E-5,1.37278978519051E-6,1,9.99253354069792,40.0298881530762,2.00379102304861,11.8300007283688,-0.000363424906543295,-6.20895932011898E-5,0.25,5.81182311608666E-8,-3.37995824573838E-5,3.53412722924834E-8,295.2686462,295.2695007,50001.527,50001.527,57.9616628435638,21.7354517423603,9.25E-6,0,0,0,5906,293.70005,50001.527,,,,,,,,,,,,,,,,,29.827055,,,,,,295.26907345,,,,
,9759124.49,403.760925292969,50001.527,-5.13049726931008E-5,1.48603684113015E-6,1,9.99253354069792,40.0298881530762,2.00383216431781,11.8300007283688,-0.000545300100098073,-0.000131491672739609,0.25,-3.37485033851606E-6,-5.13088713047122E-5,-3.4099423208604E-6,295.2932434,295.2941284,50001.527,50001.527,58.2883835646023,21.7492594207137,9.3E-6,0,0,0,5910,293.0019,50001.527,,,,,,,,,,,,,,,,,29.827055,,,,,,295.2936859,,,,
,9759304.375,433.685119628906,50001.527,-6.13083789454037E-5,1.50435041176609E-6,1,9.99253354069792,40.0298881530762,2.00366964170412,11.8300007283688,-0.000650480001460096,-0.00016343875902164,0.25,-4.62078998947283E-6,-6.13125958452665E-5,-4.66291226178032E-6,295.3058167,295.3061829,50001.527,50001.527,58.2321063112177,21.7505262666344,9.3E-6,0,0,0,5910,292.28335,50001.527,,,,,,,,,,,,,,,,,30.208265,,,,,,295.3059998,,,,
,9759484.28,463.758850097656,50001.527,-7.45685792998068E-5,1.54313610302487E-6,1,9.99253354069792,40.0298881530762,2.00397856497514,11.8300007283688,-0.000797891191454359,-0.000160556934273351,0.25,-2.0613768859891E-6,-7.457605867066E-5,-2.11234075577323E-6,295.3238525,295.3243103,50001.527,50001.527,59.1341056224101,21.7596846990021,9.3E-6,0,0,0,5906,291.5029,50001.527,,,,,,,,,,,,,,,,,29.827055,,,,,,295.3240814,,,,
,9759664.125,493.631195068359,50001.527,-8.37520899697998E-5,1.40458288262143E-6,1,9.99253354069792,40.0298881530762,2.00379089030255,11.840001270175,-0.000896048185162926,-0.000180465358398857,0.25,-2.32913667848662E-6,-8.37603991604285E-5,-2.3865660790422E-6,295.3448486,295.3470764,50001.527,50001.527,58.3978115572946,21.7707235423546,9.3E-6,0,0,0,5910,290.68155,50001.527,,,,,,,,,,,,,,,,,29.827055,,,,,,295.3459625,,,,
,9759843.975,523.710815429687,50001.527,-9.39785438301613E-5,1.38419919366228E-6,1,9.99253354069792,40.0298881530762,2.00373858923501,11.8300007283688,-0.00100564574122137,-0.000201262879200858,0.25,-2.49863541107799E-6,-9.39878501998973E-5,-2.56328854747033E-6,295.3674927,295.3697815,50001.527,50001.527,58.6729447960639,21.7836837211327,9.3E-6,0,0,0,5910,289.80935,50001.527,,,,,,,,,,,,,,,,,30.589479,,,,,,295.3686371,,,,
,9760023.845,553.61279296875,50001.527,-0.000107735200089266,1.42609367663549E-6,1,9.99253354069792,40.0298881530762,2.00393379469327,11.8300007283688,-0.00115436506812131,-0.000222602525512625,0.25,-2.10672949446745E-6,-0.00010774626924061,-2.18103497164226E-6,295.3922729,295.39505,50001.527,50001.527,58.2969814783139,21.7908058233629,9.25E-6,0,0,0,5910,288.8809,50001.527,,,,,,,,,,,,,,,,,30.97069,,,,,,295.39366145,,,,
,9760203.67,580.054016113281,50001.527,-0.000119074175185851,1.3633629534899E-6,1,9.99253354069792,40.0298881530762,2.00368014706158,11.8300007283688,-0.00127712281238993,-0.000237782649003213,0.25,-1.56361337457838E-6,-0.000119086804611634,-1.64598492924817E-6,295.4182739,295.418396,50001.527,50001.527,58.4439276399293,21.7970427194777,9.2E-6,0,0,0,5909,287.8781,50001.527,,,,,,,,,,,,,,,,,30.97069,,,,,,295.41833495,,,,
,9760483.48,567.924438476562,50001.527,-0.000118578984698628,1.33355679609592E-6,1,9.99253354069792,40.0298881530762,2.0037508374669,11.8300007283688,-0.00126859682615845,-0.000255796027626603,0.25,-3.32355655976132E-6,-0.000118592252741565,-3.40589144186049E-6,294.903717,294.9296875,50001.527,50001.527,58.5916554300639,21.8081899685694,9.3E-6,0,0,0,5910,287.7361,50001.527,,,,,,,,,,,,,,,,,30.208265,,,,,,294.91670225,,,,
,9760663.36,538.064697265625,50001.527,-0.000108233033593857,1.41190023619301E-6,1,9.99253354069792,40.0298881530762,2.00378116745661,11.8300007283688,-0.00115863011450107,-0.000229505922927446,0.25,-2.66388575719778E-6,-0.000108246715343748,-2.73866418633164E-6,294.5470886,294.5558167,50001.527,50001.527,58.4204787843523,21.8088434079427,9.3E-6,0,0,0,5910,288.90835,50001.527,,,,,,,,,,,,,,,,,29.827055,,,,,,294.55145265,,,,
,9760843.265,508.088897705078,50001.527,-9.86860741025679E-5,1.04448768603321E-6,1,9.99253354069792,40.0298881530762,2.00383479238541,11.840001270175,-0.0010545922310328,-0.000220079088637584,0.25,-3.43488740837825E-6,-9.86979724620971E-5,-3.50289335458064E-6,294.5261841,294.5305481,50001.527,50001.527,58.0296645247369,21.8166832879527,9.3E-6,0,0,0,5906,290.086,50001.527,,,,,,,,,,,,,,,,,29.445843,,,,,,294.5283661,,,,
,9761023.095,478.168426513672,50001.527,-9.05561978142221E-5,1.1867125452687E-6,1,9.99253354069792,40.0298881530762,2.00391702323908,11.8300007283688,-0.000967513786358407,-0.000203325820334447,0.25,-3.27954289859391E-6,-9.05668836388304E-5,-3.34171209567683E-6,294.5865784,294.5914001,50001.527,50001.527,58.4791009232947,21.8253705416953,9.3E-6,0,0,0,5906,291.072,50001.527,,,,,,,,,,,,,,,,,29.064632,,,,,,294.58898925,,,,
,9761203.025,448.229553222656,50001.527,-8.20069025598704E-5,1.222518278387E-6,1,9.99253354069792,40.0298881530762,2.00392209614321,11.8300007283688,-0.000874493579459165,-0.000193857838698816,0.25,-3.87489167868482E-6,-8.20158340316623E-5,-3.93112707840926E-6,294.6457214,294.6495972,50001.527,50001.527,58.9566759485447,21.8270711532137,9.25E-6,0,0,0,5906,291.9019,50001.527,,,,,,,,,,,,,,,,,29.445843,,,,,,294.6476593,,,,
,9761382.835,418.393249511719,50001.527,-7.09455736440675E-5,1.33183357626407E-6,1,9.99253354069792,40.0298881530762,2.00381399445299,11.840001270175,-0.00075460630451539,-0.000178667975603801,0.25,-4.37249711179345E-6,-7.09525365933636E-5,-4.42114443228104E-6,294.6866455,294.6898499,50001.527,50001.527,59.177876819487,21.8292546677594,9.3E-6,0,0,0,5910,292.63365,50001.527,,,,,,,,,,,,,,,,,29.445843,,,,,,294.6882477,,,,
,9761562.68,388.492065429687,50001.527,-6.23096179810901E-5,1.16989241286206E-6,1,9.99253354069792,40.0298881530762,2.00400761673705,11.8300007283688,-0.000663520202411037,-0.000152828998980244,0.25,-3.45858448011769E-6,-6.23159452778135E-5,-3.50114168643876E-6,294.7185669,294.7207031,50001.527,50001.527,59.5335177957371,21.8301506940245,9.25E-6,0,0,0,5910,293.29605,50001.527,,,,,,,,,,,,,,,,,29.445843,,,,,,294.719635,,,,
,9761742.565,358.869384765625,50001.527,-5.67896590698816E-5,1.0796545157819E-6,1,9.99253354069792,40.0298881530762,2.00404383738512,11.840001270175,-0.00060390889613615,-0.000144162872770203,0.25,-3.6052740097868E-6,-5.67950891182485E-5,-3.64402973291712E-6,294.742981,294.7455139,50001.527,50001.527,58.5603902892947,21.8410095766237,9.3E-6,0,0,0,5910,293.8956,50001.527,,,,,,,,,,,,,,,,,29.064632,,,,,,294.74424745,,,,
,9761922.425,337.131103515625,50001.527,-5.03201682922518E-5,1.24831760241208E-6,1,9.99253354069792,40.0298881530762,2.0038976493166,11.8300007283688,-0.000536594308012023,-0.000118917438710172,0.25,-2.37488368849678E-6,-5.0325436585868E-5,-2.40904196861647E-6,294.8063965,294.8106995,50001.527,50001.527,59.7531554096409,21.8428850002475,9.3E-6,0,0,0,5910,294.37,50001.527,,,,,,,,,,,,,,,,,29.445843,,,,,,294.808548,,,,
,9762102.32,322.999237060547,50001.527,-4.70856900184755E-5,1.32632630911929E-6,1,9.99253354069792,40.0298881530762,2.00380544089901,11.8300007283688,-0.000501536143048469,-0.000114418074073977,0.25,-2.51522999804469E-6,-4.7090314261487E-5,-2.54719247540007E-6,294.880249,294.8862915,50001.527,50001.527,59.4436305160255,21.8490500693907,9.3E-6,0,0,0,5910,294.6406,50001.527,,,,,,,,,,,,,,,,,29.445843,,,,,,294.88327025,,,,
,9762282.275,313.528778076172,50001.527,-4.62932383158405E-5,1.29972453422614E-6,1,9.99253354069792,40.0298881530762,2.00355058633504,11.8300007283688,-0.000495911279505562,-9.58113133409773E-5,0.25,-9.22385548164617E-7,-4.62987454080365E-5,-9.53585225474713E-7,294.9382324,294.9388428,50001.527,50001.527,59.0606325416024,21.8521431661657,9.3E-6,0,0,0,5910,294.76395,50001.527,,,,,,,,,,,,,,,,,29.445843,,,,,,294.9385376,,,,
,9762462.065,307.304870605469,50001.527,-4.59610627372236E-5,1.30321646345023E-6,1,9.99253354069792,40.0298881530762,2.003882280321,11.8300007283688,-0.000487561369210137,-0.000123347730497059,0.25,-3.53960094991898E-6,-4.59647269440345E-5,-3.57091167953264E-6,294.9672241,294.9685364,50001.527,50001.527,60.5168064729295,21.8562317812248,9.3E-6,0,0,0,5910,294.83705,50001.527,,,,,,,,,,,,,,,,,29.064632,,,,,,294.96788025,,,,
,9762641.885,302.886993408203,50001.527,-4.34405721778501E-5,1.34089538184466E-6,1,9.99253354069792,40.0298881530762,2.00376394642021,11.8300007283688,-0.000461540458745984,-0.000112271792815222,0.25,-2.94505249466212E-6,-4.34442864337602E-5,-2.97458748801922E-6,294.980957,294.9812622,50001.527,50001.527,58.974653404487,21.8590580926757,9.3E-6,0,0,0,5910,294.8784,50001.527,,,,,,,,,,,,,,,,,29.445843,,,,,,294.9811096,,,,
,9762821.77,299.933349609375,50001.527,-4.39206760517937E-5,1.34359013659695E-6,1,9.99253354069792,40.0298881530762,2.00374862018455,11.8300007283688,-0.000460373947051661,-0.000149800624601726,0.25,-6.35319863985135E-6,-4.3922157379354E-5,-6.38349725064498E-6,294.9870911,294.9889221,50001.527,50001.527,59.2935578403332,21.8631013838078,9.3E-6,0,0,0,5905,294.90915,50001.527,,,,,,,,,,,,,,,,,29.445843,,,,,,294.9880066,,,,
,9764700.53,579.985229492188,42287.1565,-0.000100744478984838,2.11517137872332E-6,1,4.99626677034896,40.0298881530762,1.98929893507298,11.8300007283688,-0.00106650132512393,-0.000238047543590298,0.25,-4.90561679005369E-6,-0.000100754250968969,-4.97594570271573E-6,294.9306946,294.9318848,42056.809,42517.504,57.9944912413715,21.8221122992007,9.25E-6,0,0,0,5985,287.82735,42287.1565,,,,,,,,,,,,,,,,,30.208265,,,,,,294.9312897,,,,
,9764790.41,579.977661132813,33328.7385,-7.18131847505366E-5,1.68638262746926E-6,1,4.99626677034896,40.0298881530762,1.98929177504955,11.840001270175,-0.000766641741201869,-0.000132521328016428,0.25,-1.56183464839667E-8,-7.18225319863145E-5,-6.53883878621634E-8,294.9385681,294.9393921,33089.211,33568.266,58.3407526753908,21.8230658759024,9.25E-6,0,0,0,5985,287.8926,33328.7385,,,,,,,,,,,,,,,,,29.827055,,,,,,294.9389801,,,,
,9764880.345,580.010070800781,24366.2255,-4.60933368993951E-5,1.26215221741103E-6,1,4.99626677034896,40.0298881530762,1.98941459872075,11.840001270175,-0.000491688262303528,-8.7440013632558E-5,0.25,-2.32522497797956E-7,-4.60991664866425E-5,-2.64552668220088E-7,294.9456787,294.9459534,24106.078,24626.373,59.495999626814,21.8308454143946,9.25E-6,0,0,0,5985,287.95665,24366.2255,,,,,,,,,,,,,,,,,29.827055,,,,,,294.94581605,,,,
,9764970.325,580.032104492188,15356.6375,-1.95043196543245E-5,1.03525492502156E-6,1,4.99626677034896,40.0298881530762,1.98934143532711,11.8300007283688,-0.000208089799100866,-3.6766060315395E-5,0.25,-7.65704917079344E-8,-1.95067911064595E-5,-9.01447791671347E-8,294.9583435,294.9592285,15102.844,15610.431,58.6620019967947,21.8384453156117,9.3E-6,0,0,0,5985,287.99205,15356.6375,,,,,,,,,,,,,,,,,29.827055,,,,,,294.958786,,,,
,9765095.82,580.000854492188,2583.019,1.09071786966021E-5,1.78551819355543E-5,1,4.99626677034896,40.0298881530762,1.98943828400066,11.8300007283688,0.000426383926484908,-0.00177515101605015,0.25,-0.000168148017456823,1.10257596952162E-5,-0.00016816211908824,294.9664001,294.9664001,2577.51,2588.528,59.3748472063332,21.8394616544633,9.25E-6,1,0,0,5985,288.05505,2583.019,,,,,,,,,,,,,,,,,29.827055,,,,,,294.9664001,,,,
,9765310.03,579.998413085938,-18041.554,3.34607504754876E-5,1.00643806737064E-6,1,4.99626677034896,40.0298881530762,1.98929898004916,11.840001270175,0.000358092402920536,5.66410260532758E-5,0.25,-4.71081996375014E-7,3.3465376687114E-5,-4.47892899261979E-7,294.9899292,294.9913635,-18274.729,-17808.379,59.5045975405255,21.8504357733845,9.3E-6,0,0,0,5985,288.07655,-18041.554,,,,,,,,,,,,,,,,,29.827055,,,,,,294.99064635,,,,
,9765399.94,580.032592773437,-26694.693,6.01803237808285E-5,1.36314889725359E-6,1,4.99626677034896,40.0298881530762,1.98935079302995,11.8300007283688,0.000644240669462746,0.00010081294911337,0.25,-9.46508587022433E-7,6.01886998533542E-5,-9.04890279914413E-7,295.0000305,295.0010986,-26929.984,-26459.402,59.7117290981217,21.8445717940593,9.3E-6,0,0,0,5985,288.064,-26694.693,,,,,,,,,,,,,,,,,29.827055,,,,,,295.00056455,,,,
,9765489.935,579.954223632813,-35406.252,8.71031420329383E-5,1.53059751196127E-6,1,4.99626677034896,40.0298881530762,1.98906012501412,11.840001270175,0.000932144056609898,0.000146931391845924,0.25,-1.27256172820317E-6,8.71151984428647E-5,-1.21243009834468E-6,295.0036011,295.0037231,-35659.195,-35153.309,59.2255561591601,21.8457048383629,9.3E-6,0,0,0,5985,288.05355,-35406.252,,,,,,,,,,,,,,,,,29.827055,,,,,,295.0036621,,,,
,9765579.93,580.023559570312,-44136.0175,0.000112933905734237,1.75316656499336E-6,1,4.99626677034896,40.0298881530762,1.98932090337444,11.840001270175,0.00120757271395379,0.000197212962987299,0.25,-1.02365503548165E-6,0.00011294908234137,-9.45770261393554E-7,295.0131531,295.0135193,-44380.488,-43891.547,58.7057731938716,21.8521671966927,9.3E-6,0,0,0,5985,288.0404,-44136.0175,,,,,,,,,,,,,,,,,29.827055,,,,,,295.0133362,,,,
,9765689.85,580.003845214844,-47892.8635,0.000125939252107372,1.66853581060764E-6,1,4.99626677034896,40.0298881530762,1.9894170858042,11.8300007283688,0.00134688471710113,0.000218853164687055,0.25,-1.24269731443479E-6,0.000125956261392752,-1.15593429353141E-6,295.0102844,295.0121765,-48176.313,-47609.414,60.0564272751025,21.8535494815851,9.3E-6,0,0,0,5985,288.03205,-47892.8635,,,,,,,,,,,,,,,,,29.445843,,,,,,295.01123045,,,,
,9765779.79,580.033630371094,-38675.287,9.67328264424717E-5,1.52772647811196E-6,1,4.99626677034896,40.0298881530762,1.98927445047651,11.8300007283688,0.00104131057039064,0.000128400098681091,0.25,-4.67218103554555E-6,9.67484700641453E-5,-4.60586488807956E-6,295.0047913,295.0048828,-38917.5,-38433.074,59.0676671982755,21.8566713376796,9.3E-6,0,0,0,5985,288.0291,-38675.287,,,,,,,,,,,,,,,,,29.827055,,,,,,295.00483705,,,,
,9765869.65,580.0126953125,-29637.498,6.87316053347914E-5,1.3029516326682E-6,1,4.99626677034896,40.0298881530762,1.98913406591808,11.8300007283688,0.000739800662049129,9.14124306505235E-5,0.25,-3.3023614054948E-6,6.8742729791598E-5,-3.25514236423878E-6,294.993103,294.9933472,-29900.754,-29374.242,59.5585299083524,21.8568467607452,9.3E-6,0,0,0,5985,288.0416,-29637.498,,,,,,,,,,,,,,,,,29.827055,,,,,,294.9932251,,,,
,9765959.575,580.024353027344,-20576.8115,4.05633014689457E-5,1.05451465303015E-6,1,4.99626677034896,40.0298881530762,1.98918761326795,11.840001270175,0.000441401272477291,2.62499827707516E-5,0.25,-4.54379443388372E-6,4.0571675265239E-5,-4.51620771697025E-6,294.9863892,294.9865417,-20839.65,-20313.973,59.0739202264293,21.8547982070743,9.3E-6,0,0,0,5985,288.064,-20576.8115,,,,,,,,,,,,,,,,,29.827055,,,,,,294.98646545,,,,
,9766049.505,579.998718261719,-11437.0065,1.60651918908685E-5,8.6628779437269E-6,1,4.99626677034896,40.0298881530762,1.98905846544738,11.8300007283688,0.000187512370118404,-6.31987467573722E-5,0.25,-8.6939044707963E-6,1.60733061561691E-5,-8.68384536120141E-6,294.984314,294.9851685,-11704.498,-11169.515,59.0520346278909,21.8553930993953,9.25E-6,0,0,0,5985,288.0817,-11437.0065,,,,,,,,,,,,,,,,,29.827055,,,,,,294.98474125,,,,
,9766232.665,580.024658203125,7001.7595,0.000373566353650588,0.000424667707482166,1,4.99626677034896,40.0298881530762,1.9890781880822,11.8300007283688,0.00487842875558509,-0.00447795650330031,2.5,-0.000484107136410502,0.00037395137025041,-0.000483909215132568,294.9885864,294.9885864,6968.852,7034.667,60.0017132787564,21.861752800101,9.3E-6,0,0,0,5985,288.10245,7001.7595,,,,,,,,,,,,,,,,,29.827055,,,,,,294.9885864,,,,
,9766374.225,579.990661621094,20627.6785,-4.26244204960769E-5,1.1409786632232E-6,1,4.99626677034896,40.0298881530762,1.98875018118746,11.8300007283688,-0.000452939399107426,-9.00932997441048E-5,0.25,-1.08261464252731E-6,-4.26291349208391E-5,-1.11235160274971E-6,294.9990845,294.9993591,20374.873,20880.484,59.5554033942755,21.8633147289474,9.3E-6,0,0,0,5985,288.09865,20627.6785,,,,,,,,,,,,,,,,,29.827055,,,,,,294.9992218,,,,
,9766464.145,579.995727539063,29390.9705,-7.02506571977685E-5,1.39011096328199E-6,1,4.99626677034896,40.0298881530762,1.98898784152149,11.8300007283688,-0.000749107406503813,-0.000133916895935055,0.25,-4.1795123753832E-7,-7.02593747722679E-5,-4.66691894424284E-7,295.0029602,295.0049133,29148.195,29633.746,59.7304881825832,21.8571470380148,9.25E-6,0,0,0,5985,288.10235,29390.9705,,,,,,,,,,,,,,,,,29.827055,,,,,,295.00393675,,,,
,9766554.12,579.97802734375,38185.711,-9.9209472792689E-5,1.51865829121747E-6,1,4.99626677034896,40.0298881530762,1.98911659036014,11.8300007283688,-0.00106071732396951,-0.00017322443789833,0.25,8.99800697459745E-7,-9.92228139522234E-5,8.31294850666815E-7,295.0077209,295.0090332,37947.453,38423.969,59.6445090454678,21.8645833825567,9.3E-6,0,0,0,5985,288.08475,38185.711,,,,,,,,,,,,,,,,,29.827055,,,,,,295.00837705,,,,
,9766644.08,580.006469726563,46998.9455,-0.000125633892530976,1.81939165339671E-6,1,4.99626677034896,40.0298881530762,1.98874536737498,11.8300007283688,-0.00134876062784661,-0.000185946183631196,0.25,4.26652177587828E-6,-0.000125652952079478,4.18035212694717E-6,295.0100708,295.0110474,46760.262,47237.629,59.6796823288332,21.8636331192208,9.3E-6,0,0,0,5985,288.0715,46998.9455,,,,,,,,,,,,,,,,,29.827055,,,,,,295.0105591,,,,
,9768746.82,308.787506103516,1000.07,7.87245407459891E-5,1.81267516533439E-7,1,9.99253354069792,40.0298881530762,1.9888762989267,11.8300007283688,0.000843066074970559,0.000128958418194492,0.25,-1.50760308523191E-6,7.87357315912546E-5,-1.45445898421029E-6,295.0163879,295.0214844,1000.07,1000.07,57.4864327038715,21.8084881119241,9.25E-6,0,0,0,5910,294.97765,1000.07,,,,,,,,,,,,,,,,,29.445843,,,,,,295.01893615,,,,
,9768926.695,338.876220703125,1000.07,7.51265174912087E-5,1.96004294564139E-7,1,9.99253354069792,40.0298881530762,1.98925214048463,11.8300007283688,0.000804987670697114,0.000121282528503342,0.25,-1.60773222631185E-6,7.51369194208325E-5,-1.55694842382423E-6,295.1744995,295.1824646,1000.07,1000.07,58.5048946644293,21.818431958578,9.25E-6,0,0,0,5910,294.5776,1000.07,,,,,,,,,,,,,,,,,29.827055,,,,,,295.17848205,,,,
,9769106.585,368.825622558594,1000.07,7.06916293244855E-5,2.06463757871292E-7,1,9.99253354069792,40.0298881530762,1.98923566711129,11.840001270175,0.000757903995826485,0.000111545976144863,0.25,-1.75422726968181E-6,7.07013903496581E-5,-1.70633988611409E-6,295.2573547,295.259552,1000.07,1000.07,58.5455393474293,21.8307683622932,9.3E-6,0,0,0,5910,293.9256,1000.07,,,,,,,,,,,,,,,,,29.827055,,,,,,295.25845335,,,,
,9769286.41,398.816711425781,1000.07,6.59374371010492E-5,2.09684708091016E-7,1,9.99253354069792,40.0298881530762,1.98913598112843,11.840001270175,0.00070680586134406,0.000104574763841637,0.25,-1.58619724304462E-6,6.59464425185248E-5,-1.54139911902281E-6,295.2843628,295.2858582,1000.07,1000.07,59.221648016564,21.8317262798898,9.3E-6,0,0,0,5906,293.24715,1000.07,,,,,,,,,,,,,,,,,29.827055,,,,,,295.2851105,,,,
,9769466.25,428.733673095703,1000.07,5.8413344952433E-5,2.03642941214664E-7,1,9.99253354069792,40.0298881530762,1.98940807299632,11.840001270175,0.0006266555086349,9.02134906061626E-5,0.25,-1.63389304634715E-6,5.84214311022934E-5,-1.59411372822798E-6,295.3058777,295.3068237,1000.07,1000.07,59.2052338176601,21.8406407318433,9.3E-6,0,0,0,5906,292.51305,1000.07,,,,,,,,,,,,,,,,,29.827055,,,,,,295.3063507,,,,
,9769646.12,458.749145507812,1000.07,5.03082151407121E-5,2.05402453430888E-7,1,9.99253354069792,40.0298881530762,1.98911713477807,11.8300007283688,0.000539907117143722,7.60680586357835E-5,0.25,-1.55875902784914E-6,5.03152517985787E-5,-1.52441014697519E-6,295.321106,295.321991,1000.07,1000.07,58.8175460721216,21.8588867149211,9.3E-6,0,0,0,5910,291.7582,1000.07,,,,,,,,,,,,,,,,,29.827055,,,,,,295.3215485,,,,
,9769826,488.674346923828,1000.07,4.24835118458723E-5,2.07326945407357E-7,1,9.99253354069792,40.0298881530762,1.98903459318505,11.8300007283688,0.000456544482504574,6.05822305417594E-5,0.25,-1.65853391475431E-6,4.24896613058631E-5,-1.62947143695641E-6,295.3373108,295.338623,1000.07,1000.07,59.2912129547755,21.8551176389887,9.3E-6,0,0,0,5906,290.95955,1000.07,,,,,,,,,,,,,,,,,30.208265,,,,,,295.3379669,,,,
,9770005.915,518.687805175781,1000.07,3.44674771993831E-5,2.02441787138775E-7,1,9.99253354069792,40.0298881530762,1.98919352187536,11.8300007283688,0.000370598285587183,4.81745674542012E-5,0.25,-1.43751425251461E-6,3.44724932795826E-5,-1.41385882767145E-6,295.366272,295.3671265,1000.07,1000.07,59.729706554064,21.8618073241366,9.3E-6,0,0,0,5910,290.0803,1000.07,,,,,,,,,,,,,,,,,30.208265,,,,,,295.36669925,,,,
,9770185.805,548.677978515625,1000.07,2.08203943388213E-5,1.98362121712987E-7,1,9.99253354069792,40.0298881530762,1.98893291166097,11.8300007283688,0.000225094294971939,2.18017261183623E-5,0.25,-1.55182978232367E-6,2.08238801129191E-5,-1.5375641247087E-6,295.3891907,295.3906555,1000.07,1000.07,59.2654192136409,21.8568826580616,9.2E-6,0,0,0,5906,289.1605,1000.07,,,,,,,,,,,,,,,,,30.589479,,,,,,295.3899231,,,,
,9770365.59,578.097717285156,1000.07,1.68235707939366E-5,1.84391748313341E-7,1,9.99253354069792,40.0298881530762,1.98894454528959,11.8300007283688,0.000182599395767093,1.3475964060545E-5,0.25,-1.64189801656741E-6,1.68266450658933E-5,-1.63036707180714E-6,295.4109497,295.4119568,1000.07,1000.07,58.446272525487,21.867982009155,9.25E-6,0,0,0,5906,288.1852,1000.07,,,,,,,,,,,,,,,,,30.97069,,,,,,295.41145325,,,,
,9770645.425,573.012756347656,1000.07,1.63983231618086E-5,1.72108751576906E-7,1,9.99253354069792,40.0298881530762,1.98884320510247,11.8300007283688,0.000177701755966092,1.47321236812735E-5,0.25,-1.45076981076001E-6,1.64014328308184E-5,-1.43951210190069E-6,294.9884338,295.0112305,1000.07,1000.07,59.1849114761601,21.8707024289915,9.25E-6,0,0,0,5910,287.7635,1000.07,,,,,,,,,,,,,,,,,30.208265,,,,,,294.99983215,,,,
,9770825.265,543.060852050781,1000.07,2.29416555724533E-5,1.68036243088689E-7,1,9.99253354069792,40.0298881530762,1.98908236897964,11.8300007283688,0.000247417779870851,2.76992489787602E-5,0.25,-1.36579724632058E-6,2.29458484607396E-5,-1.3500481088106E-6,294.5836487,294.595459,1000.07,1000.07,59.2990292399678,21.8727750629626,9.25E-6,0,0,0,5906,288.78205,1000.07,,,,,,,,,,,,,,,,,29.445843,,,,,,294.58955385,,,,
,9771005.155,513.184265136719,1000.07,3.43189048779379E-5,1.66797733751001E-7,1,9.99253354069792,40.0298881530762,1.98903898327604,11.8300007283688,0.000368970224855748,4.80405981125161E-5,0.25,-1.42421162226379E-6,3.43248275401167E-5,-1.40068578149828E-6,294.5220947,294.5226135,1000.07,1000.07,59.3803186059678,21.8768050516912,9.3E-6,0,0,0,5910,289.98175,1000.07,,,,,,,,,,,,,,,,,29.445843,,,,,,294.5223541,,,,
,9771185.065,483.199615478516,1000.07,4.20128526515872E-5,1.67937159488482E-7,1,9.99253354069792,40.0298881530762,1.98876435642679,11.8300007283688,0.00045076347252434,6.38166802471083E-5,0.25,-1.27363775144118E-6,4.20197122032576E-5,-1.24488888167456E-6,294.5744934,294.5790405,1000.07,1000.07,60.2166611215448,21.8833128652101,9.3E-6,0,0,0,5906,290.9958,1000.07,,,,,,,,,,,,,,,,,29.064632,,,,,,294.57676695,,,,
,9771364.87,453.393432617188,1000.07,4.94421807114794E-5,1.63192566379741E-7,1,9.99253354069792,40.0298881530762,1.98881988199374,11.8300007283688,0.000530350782412883,7.58946015201046E-5,0.25,-1.42462942645754E-6,4.94501140583893E-5,-1.3909031924479E-6,294.6350403,294.6387634,1000.07,1000.07,58.8972721810832,21.8843376471763,9.3E-6,0,0,0,5910,291.8546,1000.07,,,,,,,,,,,,,,,,,29.445843,,,,,,294.63690185,,,,
,9771544.76,423.442993164063,1000.07,5.72719140562992E-5,1.61157223523752E-7,1,9.99253354069792,40.0298881530762,1.98885262273975,11.8300007283688,0.000613894237263123,9.05360365806931E-5,0.25,-1.40452402483743E-6,5.72808586359578E-5,-1.3655401765142E-6,294.6820374,294.6835632,1000.07,1000.07,59.3162250673909,21.8927376361538,9.25E-6,0,0,0,5906,292.60235,1000.07,,,,,,,,,,,,,,,,,29.064632,,,,,,294.6828003,,,,
,9771724.71,393.530944824219,1000.07,6.49741304790759E-5,1.46179850714512E-7,1,9.99253354069792,40.0298881530762,1.98892860969051,11.8300007283688,0.000695960397608892,0.000105718082263691,0.25,-1.31199016540505E-6,6.49840256042761E-5,-1.26784487628426E-6,294.7146301,294.7165833,1000.07,1000.07,60.2557425475064,21.8929905015796,9.3E-6,0,0,0,5906,293.27635,1000.07,,,,,,,,,,,,,,,,,29.064632,,,,,,294.7156067,,,,
,9771904.5,363.790161132812,1000.07,7.11712980382648E-5,1.27407561613113E-7,1,9.99253354069792,40.0298881530762,1.98893967040144,11.840001270175,0.000762243031364334,0.000116386010405949,0.25,-1.3822848504951E-6,7.11820428187092E-5,-1.33403956631885E-6,294.7432556,294.7450256,1000.07,1000.07,59.7148556121986,21.8952200100574,9.3E-6,0,0,0,5910,293.8821,1000.07,,,,,,,,,,,,,,,,,29.445843,,,,,,294.7441406,,,,
,9772084.32,340.318328857422,1000.07,7.55188200706906E-5,1.1615840445434E-7,1,9.99253354069792,40.0298881530762,1.98876612289472,11.8300007283688,0.000808699480297212,0.000123696370604793,0.25,-1.44681157749827E-6,7.55300962659351E-5,-1.3957179574375E-6,294.7913208,294.7947388,1000.07,1000.07,59.9798276802179,21.9034905700284,9.25E-6,0,0,0,5910,294.3802,1000.07,,,,,,,,,,,,,,,,,29.445843,,,,,,294.7930298,,,,
,9772264.195,325.320526123047,1000.07,7.8111253079557E-5,1.23462690907868E-7,1,9.99253354069792,40.0298881530762,1.98875679400557,11.8300007283688,0.000836230628495966,0.000129240256151065,0.25,-1.3747542342893E-6,7.8122626708614E-5,-1.32194942392966E-6,294.8753662,294.8789063,1000.07,1000.07,59.7523737811217,21.9000599360491,9.3E-6,0,0,0,5910,294.6735,1000.07,,,,,,,,,,,,,,,,,29.064632,,,,,,294.87713625,,,,
,9772444.095,315.177856445313,1000.07,7.99470095801533E-5,1.29146381473686E-7,1,9.99253354069792,40.0298881530762,1.98882785770871,11.8300007283688,0.000855773296877084,0.000133082046977871,0.25,-1.33207039515732E-6,7.99584587886495E-5,-1.27804378808896E-6,294.9316406,294.9338379,1000.07,1000.07,60.301858630141,21.8975195193219,9.25E-6,0,0,0,5910,294.8173,1000.07,,,,,,,,,,,,,,,,,29.445843,,,,,,294.93273925,,,,
,9772623.96,308.387237548828,1000.07,8.09456488534784E-5,1.31030877222245E-7,1,9.99253354069792,40.0298881530762,1.98866634131686,11.840001270175,0.000866326465825114,0.000135128653829975,0.25,-1.31169277348561E-6,8.09571387017641E-5,-1.25700360739683E-6,294.9628601,294.9629517,1000.07,1000.07,59.7179821262755,21.9033008494561,9.3E-6,0,0,0,5910,294.9003,1000.07,,,,,,,,,,,,,,,,,29.064632,,,,,,294.9629059,,,,
,9772803.835,303.733459472656,1000.07,8.18405104810342E-5,1.23448893380363E-7,1,9.99253354069792,40.0298881530762,1.98881626743313,11.8300007283688,0.000875834447365259,0.000137398604427266,0.25,-1.25439078684789E-6,8.18520378538616E-5,-1.19909757873396E-6,294.9779358,294.9794617,1000.07,1000.07,59.9751379091025,21.9042848452156,9.3E-6,0,0,0,5910,294.94745,1000.07,,,,,,,,,,,,,,,,,29.064632,,,,,,294.97869875,,,,
,9772983.73,300.489349365234,1000.07,8.22970752272672E-5,1.33555041724025E-7,1,9.99253354069792,40.0298881530762,1.98880248120138,11.8300007283688,0.000880491483118728,0.000139455577932969,0.25,-1.14038834350344E-6,8.23085652645221E-5,-1.08477698125155E-6,294.9860229,294.9865723,1000.07,1000.07,59.8492957175063,21.9057734027901,9.25E-6,0,0,0,5909,294.9757,1000.07,,,,,,,,,,,,,,,,,29.445843,,,,,,294.9862976,,,,
,9773033.72,299.853942871094,1000.07,8.24385292267918E-5,1.27153924482798E-7,1,9.99253354069792,40.0298881530762,1.98882969866259,11.8300007283688,0.000882030267250311,0.000139616779836393,0.25,-1.14987303613542E-6,8.24500373116594E-5,-1.0941676085355E-6,294.9885559,294.9891968,1000.07,1000.07,59.6476355595448,21.9034796540984,9.25E-6,0,0,0,5905,294.9785,1000.07,,,,,,,,,,,,,,,,,29.445843,,,,,,294.98887635,,,,