File: DataFailid_Testimiseks/PFO#2_HIGHTEMPSWEEP_300-600K_0p1_0p5_5T__2019-12-30.DAT
[Header]
; VSM Data File (default extension .dat)
; Copyright (c) 2003, Quantum Design, Inc. All rights reserved.
TITLE,PFO#2_HIGHTEMPSWEEP_300-600K_0p1_0p5_5T__2019-12-30
FILEOPENTIME,11380959.11,12/30/2019,7:12 pm
BYAPP,VSM,1.0,1.0
INFO,PPMS VSM Option Release 1.3.6 Build 0,APPNAME
INFO,221,COIL_SERIAL_NUMBER
INFO,0,MOMENT_UNITS
INFO,PFO#2_HIGHTEMPSWEEP_300-600K_0p1_0p5_5T__2019-12-30,SAMPLE_MATERIAL
INFO,,SAMPLE_COMMENT
INFO,x,SAMPLE_MASS
INFO,,SAMPLE_VOLUME
INFO,,SAMPLE_MOLECULAR_WEIGHT
INFO,,SAMPLE_SIZE
INFO,rectangular thin film with contacts,SAMPLE_SHAPE
INFO,35.62,SAMPLE_OFFSET
DATATYPE,COMMENT,1
DATATYPE,TIME,2
STARTUPAXIS,X,2
STARTUPAXIS,Y1,5
[Data]
Comment,Time Stamp (sec),Temperature (K),Magnetic Field (Oe),Moment (emu),M. Std. Err. (emu),Transport Action,Averaging Time (sec),Frequency (Hz),Peak Amplitude (mm),Center Position (mm),Coil Signal' (mV),Coil Signal" (mV),Range (mV),M. Quad. Signal (emu),M. Raw' (emu),M. Raw" (emu),Min. Temperature (K),Max. Temperature (K),Min. Field (Oe),Max. Field (Oe),Mass (grams),Motor Lag (deg),Pressure (Torr),VSM Status (code),Motor Status (code),Measure Status (code),PPMS Status (code),System Temp. (K),System Field (Oe),Sample Position (deg),Bridge 1 Resistance (ohms),Bridge 1 Excitation (에),Bridge 2 Resistance (ohms),Bridge 2 Excitation (에),Bridge 3 Resistance (ohms),Bridge 3 Excitation (에),Bridge 4 Resistance (ohms),Bridge 4 Excitation (에),Signal 1 Vin (V),Signal 2 Vin (V),Digital Inputs (code),Drive 1 Iout (mA),Drive 1 Ipower (W),Drive 2 Iout (mA),Drive 2 Ipower (W),Pressure (),Map 20 (),Map 21 (),Map 22 (),Map 23 (),Map 24 (),Map 25 (),Map 26 (),Map 27 (),Map 28 (),Map 29 ()
,11445776.32,300.037231445313,0.0635,-3.81483958398401E-5,1.97971534635888E-7,1,4.99626677034896,40.0298881530762,1.99073249551173,11.0600018501282,-0.000403463774582906,-9.40374584723651E-5,0.25,-2.21706835578122E-6,-3.81518420397998E-5,-2.24322298325779E-6,294.9998474,294.9998474,0.035,0.092,61.8354137848719,21.4514411294172,9.25E-6,0,0,0,5953,294.8093,0.0635,,,,,,,,,,,,,,,,,29.064632,,,,,,294.9998474,,,,
,11445884.28,300.022491455078,10540.347,0.000310980764172655,6.38297189216291E-7,1,4.99626677034896,40.0298881530762,1.99296208666743,11.0400026291609,0.00332760606970161,0.000564143835930814,0.25,-9.31978456808853E-7,0.000311021776887573,-7.21568163590487E-7,294.9992371,294.9997864,10276.243,10804.451,62.3755190916605,21.4708644126002,9.25E-6,0,0,0,5985,294.8099,10540.347,,,,,,,,,,,,,,,,,29.445843,,,,,,294.99951175,,,,
,11445984.165,299.993011474609,20436.589,0.000326978589550504,1.21155985415439E-6,1,4.99626677034896,40.0298881530762,1.992520413302,11.0300020873547,0.00349640785958884,0.000602518979356632,0.25,-9.2906531734628E-8,0.000327021085249463,1.28025234722551E-7,295.0055542,295.0057373,20185.621,20687.557,61.9753252898142,21.4596710980793,9.3E-6,0,0,0,5985,294.8045,20436.589,,,,,,,,,,,,,,,,,29.445843,,,,,,295.00564575,,,,
,11446084.2,300.094818115234,30207.427,0.000323458478860011,1.91336297908693E-6,1,4.99626677034896,40.0298881530762,2.0003821368018,11.0300020873547,0.00347504919008591,0.00057979955715484,0.25,-1.81407487037803E-6,0.000323501696977941,-1.59618646355594E-6,295.0073547,295.0081177,29982.305,30432.549,58.4540888106793,21.616257588037,9.3E-6,0,0,0,5985,294.78945,30207.427,,,,,,,,,,,,,,,,,29.445843,,,,,,295.0077362,,,,
,11446184.03,300.050262451172,39967.3355,0.000312098270876073,2.13756296250029E-6,1,4.99626677034896,40.0298881530762,2.00067286740974,11.0300020873547,0.00335849800755604,0.000530383201196798,0.25,-4.46369700403262E-6,0.000312141835089352,-4.25426706185094E-6,295.0078125,295.0078125,39712.273,40222.398,58.4525255536408,21.6291845666222,9.3E-6,0,0,0,5985,294.77435,39967.3355,,,,,,,,,,,,,,,,,29.445843,,,,,,295.0078125,,,,
,11446283.905,300.125762939453,49666.0175,0.000300301489148187,2.46277554308739E-6,1,4.99626677034896,40.0298881530762,2.0008272939261,11.0300020873547,0.00323132033326157,0.000513101793622461,0.25,-4.04036433885349E-6,0.000300343195079637,-3.83927200885069E-6,295.0154724,295.0158081,49495.93,49836.105,58.8370867851024,21.6308720096227,9.25E-6,0,0,0,5985,294.76095,49666.0175,,,,,,,,,,,,,,,,,29.445843,,,,,,295.01564025,,,,
,11446398.86,300.032318115234,41250.2385,0.000310073558875083,1.86330184883149E-6,1,4.99626677034896,40.0298881530762,1.99506973579775,11.0300020873547,0.00332231832033789,0.000556967263314592,0.25,-1.49788647659454E-6,0.000310114840766596,-1.28947358960171E-6,295.010498,295.0105286,41001.813,41498.664,59.6366927602755,21.5095562694649,9.2E-6,0,0,0,5985,294.74755,41250.2385,,,,,,,,,,,,,,,,,29.445843,,,,,,295.0105133,,,,
,11446498.8,299.903167724609,31300.383,0.000318730051839877,1.69368482771076E-6,1,4.99626677034896,40.0298881530762,1.994661800705,11.0300020873547,0.00341633683170927,0.000561185394321162,0.25,-2.58832951141854E-6,0.000318773277120154,-2.37375055146297E-6,294.9980774,294.9984436,31048.428,31552.338,61.7846079311219,21.5100354830513,9.3E-6,0,0,0,5985,294.7518,31300.383,,,,,,,,,,,,,,,,,29.445843,,,,,,294.9982605,,,,
,11446598.685,300.043640136719,21325.0925,0.00032163758899294,1.15702941740331E-6,1,4.99626677034896,40.0298881530762,1.99633942240497,11.020002476871,0.0034462462851501,0.000590152508199879,0.25,-4.28828185101917E-7,0.000321679806932158,-2.11560169342024E-7,294.9874878,294.9876404,21072.148,21578.037,61.7283306777373,21.5535115312042,9.2E-6,0,0,0,5985,294.77175,21325.0925,,,,,,,,,,,,,,,,,29.445843,,,,,,294.9875641,,,,
,11446698.63,299.971923828125,11271.232,0.000311906770612429,6.32833602733959E-7,1,4.99626677034896,40.0298881530762,1.9951100907354,11.020002476871,0.00334162031202862,0.00056262686751483,0.25,-1.28801653837418E-6,0.000311948297012562,-1.07704344334732E-6,294.9840393,294.9849548,11027.75,11514.714,62.4169454031797,21.551514537035,9.25E-6,0,0,0,5985,294.7975,11271.232,,,,,,,,,,,,,,,,,29.445843,,,,,,294.98449705,,,,
,11446909.71,299.935577392578,-9628.0895,-0.000344743672695857,0.000148799645944229,1,4.99626677034896,40.0298881530762,1.99542071951033,11.0300020873547,-0.00394432315647921,0.000834958409773375,2.5,0.000137511636393801,-0.000344881632884157,0.000137296095399053,294.9916687,294.9916687,-9662.692,-9593.487,60.9068391040257,21.5570821344708,9.3E-6,0,0,0,5985,294.8056,-9628.0895,,,,,,,,,,,,,,,,,29.445843,,,,,,294.9916687,,,,
,11447028.425,299.929809570313,-20964.505,-0.000322898753404019,1.1216142330446E-6,1,4.99626677034896,40.0298881530762,1.99588904886779,11.0300020873547,-0.00345488093832726,-0.000616252116064655,0.25,-1.80239571228837E-6,-0.00032293948179995,-2.02079438585427E-6,295.0017395,295.0017395,-21215.477,-20713.533,61.026428267468,21.5663272194969,9.3E-6,0,0,0,5985,294.80325,-20964.505,,,,,,,,,,,,,,,,,29.445843,,,,,,295.0017395,,,,
,11447128.335,299.987609863281,-30615.13,-0.000321777661241808,1.83114729480617E-6,1,4.99626677034896,40.0298881530762,1.99518447001836,11.020002476871,-0.00343979000405609,-0.000625081319794249,0.25,-2.84052837424632E-6,-0.000321817504967282,-3.05786800445564E-6,295.0090637,295.0101318,-30858.471,-30371.789,61.8361954133912,21.5895363452812,9.3E-6,0,0,0,5985,294.78935,-30615.13,,,,,,,,,,,,,,,,,29.445843,,,,,,295.00959775,,,,
,11447228.29,299.952270507812,-40288.6075,-0.000315248638787243,2.42316205123182E-6,1,4.99626677034896,40.0298881530762,1.99553588098714,11.0300020873547,-0.00337033817615192,-0.000613814608042181,0.25,-2.90596250525063E-6,-0.00031528762506681,-3.11845108062642E-6,295.0105896,295.0109863,-40530.535,-40046.68,61.4422546396988,21.5801955204117,9.3E-6,0,0,0,5985,294.7777,-40288.6075,,,,,,,,,,,,,,,,,29.445843,,,,,,295.01078795,,,,
,11447328.26,300.040924072266,-49781.988,-0.000310825230987872,2.66962114952119E-6,1,4.99626677034896,40.0298881530762,1.99797877666769,11.0100019350648,-0.00332493475646539,-0.000617588138796112,0.25,-3.95470966295273E-6,-0.00031086298661902,-4.16389955383595E-6,295.0103149,295.0109253,-49852.941,-49711.035,62.1191449373527,21.6614330789871,9.25E-6,0,0,0,5969,294.76195,-49781.988,,,,,,,,,,,,,,,,,29.445843,,,,,,295.0106201,,,,
,11447448.095,300.000640869141,-40758.1605,-0.000316743216393852,2.21018780131288E-6,1,4.99626677034896,40.0298881530762,1.99893723544556,11.0300020873547,-0.00338587921008004,-0.000652343774437318,0.25,-6.14667123361484E-6,-0.000316780234311489,-6.36058433479417E-6,295.0083313,295.0097656,-41017.602,-40498.719,62.3661395494297,21.6922778518741,9.25E-6,0,0,0,5985,294.753,-40758.1605,,,,,,,,,,,,,,,,,29.445843,,,,,,295.00904845,,,,
,11447547.975,300.174194335937,-30718.4835,-0.000321589145303524,1.78966112165532E-6,1,4.99626677034896,40.0298881530762,1.99836652930177,11.0400026291609,-0.00343671928236748,-0.000662261043867692,0.25,-6.25124091915126E-6,-0.000321626771796795,-6.46892091962679E-6,294.9988098,294.9992371,-30971.852,-30465.115,60.088474044391,21.7020646518148,9.3E-6,0,0,0,5985,294.75755,-30718.4835,,,,,,,,,,,,,,,,,29.445843,,,,,,294.99902345,,,,
,11447647.91,300.035736083984,-20629.4965,-0.000322852606620589,1.22605761806824E-6,1,4.99626677034896,40.0298881530762,1.99596637799894,11.0500022396445,-0.00344825743610202,-0.000652446502862859,0.25,-5.18756129729665E-6,-0.000322891122960991,-5.40641696828272E-6,294.9927979,294.9941101,-20874.68,-20384.313,60.3596991405641,21.6779928574921,9.25E-6,0,0,0,5985,294.7667,-20629.4965,,,,,,,,,,,,,,,,,29.445843,,,,,,294.993454,,,,
,11447747.87,300.022247314453,-10461.9445,-0.000309584764879242,6.45071708533799E-7,1,4.99626677034896,40.0298881530762,1.99071078917631,11.020002476871,-0.00330034697504705,-0.000611586589091472,0.25,-3.80705373147469E-6,-0.000309622488919868,-4.01716062725821E-6,294.9888916,294.9893799,-10719.552,-10204.337,68.6348002736611,21.6478414654559,9.25E-6,0,0,0,5985,294.7838,-10461.9445,,,,,,,,,,,,,,,,,29.445843,,,,,,294.98913575,,,,
,11447987.29,300.013977050781,13302.5575,0.000511974235223064,0.000302409936331075,1,4.99626677034896,40.0298881530762,1.99555213879363,11.0700023919344,0.00551953711752102,0.000720870609878332,2.5,-2.10364562414996E-5,0.000512055097416424,-2.06927723591989E-5,294.9915466,294.9916992,13285.044,13320.071,60.5003922740256,21.6846065283419,9.25E-6,0,0,0,5985,294.8133,13302.5575,,,,,,,,,,,,,,,,,29.445843,,,,,,294.9916229,,,,
,11448092.63,300.01953125,23513.204,0.000322231264900886,1.32151696028806E-6,1,4.99626677034896,40.0298881530762,1.99579732356137,11.0300020873547,0.00345334784455778,0.00058158002076105,0.25,-1.31725886884685E-6,0.000322274043405208,-1.0998400032086E-6,294.9996643,295.0003052,23267.32,23759.088,61.4234955552373,21.7167989638884,9.3E-6,0,0,0,5985,294.81255,23513.204,,,,,,,,,,,,,,,,,29.445843,,,,,,294.99998475,,,,
,11448192.575,299.969848632812,33263.949,0.000320398971831306,1.72995222189987E-6,1,4.99626677034896,40.0298881530762,1.9928870983753,11.0100019350648,0.00342852131712781,0.000579697547444452,0.25,-1.10046266965735E-6,0.000320441325553041,-8.84698792974082E-7,295.0076294,295.0077515,33018.207,33509.691,66.3704224534493,21.6596148363612,9.3E-6,0,0,0,5985,294.7974,33263.949,,,,,,,,,,,,,,,,,29.445843,,,,,,295.00769045,,,,
,11448292.455,299.948944091797,43027.3885,0.000313254358741117,2.36402437895522E-6,1,4.99626677034896,40.0298881530762,1.9969094271171,11.020002476871,0.00335721473053756,0.000575652844074938,0.25,-3.48955145693182E-7,0.000313295242292534,-1.38365469686991E-7,295.0144348,295.0162354,42792.242,43262.535,62.0706839691604,21.673579049367,9.25E-6,0,0,0,5985,294.7764,43027.3885,,,,,,,,,,,,,,,,,29.445843,,,,,,295.0153351,,,,
,11449588.95,300.516174316406,999.908,0.000107174212506109,1.43136751105854E-7,1,9.99253354069792,40.0298881530762,1.99772858006472,11.020002476871,0.00115167653923956,0.000181875637104834,0.25,-1.53339971316282E-6,0.000107189158536081,-1.46093558018211E-6,294.9992065,295.0001831,999.908,999.908,59.4115837467371,21.6807965128591,9.3E-6,0,0,0,5906,294.81225,999.908,,,,,,,,,,,,,,,,,29.827055,,,,,,294.9996948,,,,
,11449788.875,332.193267822266,999.908,0.000105342966655415,1.77773636673836E-7,1,9.99253354069792,40.0298881530762,1.9974573465145,11.0300020873547,0.0011318295674118,0.000178790836189801,0.25,-1.50291721937438E-6,0.000105356447845882,-1.43146182990801E-6,295.3404846,295.360199,999.908,999.908,59.7304881825832,21.6937666571722,9.3E-6,0,0,0,5910,294.07755,999.908,,,,,,,,,,,,,,,,,29.827055,,,,,,295.3503418,,,,
,11449988.68,365.597229003906,999.908,0.000104914313480747,2.1351419142103E-7,1,9.99253354069792,40.0298881530762,1.99719827751459,11.0300020873547,0.00112718614483689,0.000177388151881367,0.25,-1.55807511366543E-6,0.000104926842940422,-1.48641783133916E-6,295.6138916,295.619812,999.908,999.908,59.8016163778333,21.681964747195,9.3E-6,0,0,0,5910,292.40425,999.908,,,,,,,,,,,,,,,,,30.208265,,,,,,295.6168518,,,,
,11450188.485,398.927093505859,999.908,0.000104053066594952,2.12055257917326E-7,1,9.99253354069792,40.0298881530762,1.99727385859256,11.020002476871,0.00111810328476524,0.000175161460478346,0.25,-1.61827415789712E-6,0.000104065141586123,-1.54664746016469E-6,295.722229,295.7251282,999.908,999.908,60.8661944210257,21.6855851512774,9.25E-6,0,0,0,5910,290.4913,999.908,,,,,,,,,,,,,,,,,34.782803,,,,,,295.7236786,,,,
,11450388.34,432.287780761719,999.908,0.000101592552497434,2.14254164234204E-7,1,9.99253354069792,40.0298881530762,1.9971910568408,11.0300020873547,0.00109176741928228,0.000170140181879711,0.25,-1.66198444897759E-6,0.000101604072624711,-1.59144326492981E-6,295.8058777,295.8115845,999.908,999.908,60.2033734367179,21.6841743256168,9.25E-6,0,0,0,5910,288.38355,999.908,,,,,,,,,,,,,,,,,36.307648,,,,,,295.8087311,,,,
,11450588.205,465.584777832031,999.908,9.71142498973073E-5,2.24272160772024E-7,1,9.99253354069792,40.0298881530762,1.99707164478953,11.0300020873547,0.00104377761307692,0.00016146743301166,0.25,-1.69791550769366E-6,9.71249212839841E-5,-1.6298069387832E-6,295.9214478,295.928833,999.908,999.908,60.9568633292564,21.6909876362612,9.3E-6,0,0,0,5910,285.97235,999.908,,,,,,,,,,,,,,,,,37.070068,,,,,,295.9251404,,,,
,11450788.105,499.017211914063,999.908,9.04241703272177E-5,2.00713960710576E-7,1,9.99253354069792,40.0298881530762,1.99653443376232,11.0300020873547,0.000971803091468615,0.000149228274976944,0.25,-1.68215230094061E-6,9.04337106853648E-5,-1.61800160025671E-6,296.0621643,296.0697327,999.908,999.908,60.2557425475064,21.6808838255842,9.25E-6,0,0,0,5906,283.23185,999.908,,,,,,,,,,,,,,,,,36.307648,,,,,,296.0659485,,,,
,11450987.93,532.44384765625,999.908,8.01487973980739E-5,1.95817691720155E-7,1,9.99253354069792,40.0298881530762,1.99664736005799,11.0300020873547,0.000861605133855436,0.000130435960830064,0.25,-1.66080886168649E-6,8.01454431704823E-5,-1.60402980688169E-6,300.6901855,300.7150879,999.908,999.908,60.9404491303526,21.6783954453643,9.3E-6,0,0,0,5906,284.50635,999.908,,,,,,,,,,,,,,,,,75.953629,,,,,,300.7026367,,,,
,11451187.87,565.812866210937,999.908,6.68355666016438E-5,2.019626124953E-7,1,9.99253354069792,40.0298881530762,1.99590480094289,11.020002476871,0.000718865321252096,0.000104841415017488,0.25,-1.74773123348899E-6,6.68296851157623E-5,-1.70022963786573E-6,302.2314148,302.283844,999.908,999.908,60.1431880407371,21.6848749997823,9.3E-6,0,0,0,5910,284.2628,999.908,,,,,,,,,,,,,,,,,45.075508,,,,,,302.2576294,,,,
,11451487.555,579.35400390625,999.908,6.74325839362544E-5,1.77968807325091E-7,1,9.99253354069792,40.0298881530762,1.99598335539262,11.0300020873547,0.000725145327792356,0.000106600280044106,0.25,-1.68661822408408E-6,6.74241069252669E-5,-1.63857066751751E-6,303.4046631,303.406311,999.908,999.908,60.9381042447949,21.6803952530135,9.25E-6,0,0,0,5906,283.9178,999.908,,,,,,,,,,,,,,,,,32.114323,,,,,,303.40548705,,,,
,11451687.385,547.962341308594,999.908,7.69426832953535E-5,1.86203526205168E-7,1,9.99253354069792,40.0298881530762,1.99567742233638,11.0300020873547,0.000826636461997838,0.00012560087644678,0.25,-1.552685624023E-6,7.69357042645908E-5,-1.49804005282682E-6,302.16745,302.2522888,999.908,999.908,60.914655389218,21.6697869785798,9.3E-6,0,0,0,5910,284.2112,999.908,,,,,,,,,,,,,,,,,37.832493,,,,,,302.2098694,,,,
,11451887.25,514.710266113281,999.908,9.74657360381927E-5,1.88623061311245E-7,1,9.99253354069792,40.0298881530762,1.9964373037246,11.0300020873547,0.00104655286624557,0.000164989068029487,0.25,-1.42302201947186E-6,9.74610471799055E-5,-1.35426321772778E-6,300.7129822,300.8256836,999.908,999.908,60.065025188814,21.6905577122014,9.3E-6,0,0,0,5910,285.3968,999.908,,,,,,,,,,,,,,,,,45.837933,,,,,,300.7693329,,,,
,11452087.145,481.338928222656,999.908,0.000111830091413296,1.81467315463418E-7,1,9.99253354069792,40.0298881530762,1.99608977227492,11.020002476871,0.00120036670216384,0.000190855687240244,0.25,-1.48464294556385E-6,0.00011182897372016,-1.40684745845755E-6,299.5452576,299.6105652,999.908,999.908,61.4141160130065,21.6916697608123,9.3E-6,0,0,0,5910,288.5697,999.908,,,,,,,,,,,,,,,,,29.445843,,,,,,299.5779114,,,,
,11452286.985,448.107727050781,999.908,0.000125144255880309,1.8046848053625E-7,1,9.99253354069792,40.0298881530762,1.99614924257937,11.0300020873547,0.00134309729758206,0.000215796494947151,0.25,-1.45853033733362E-6,0.000125157544279915,-1.37032899214087E-6,295.8213501,295.9890442,999.908,999.908,61.1757193146411,21.6863233495313,9.25E-6,0,0,0,5910,284.9854,999.908,,,,,,,,,,,,,,,,,32.114323,,,,,,295.90519715,,,,
,11452486.88,414.669616699219,999.908,0.000136976271669725,1.84751046891019E-7,1,9.99253354069792,40.0298881530762,1.99718946544716,11.020002476871,0.00147062570517841,0.000237958099328246,0.25,-1.4434944928787E-6,0.000136998950094973,-1.34819462200268E-6,294.0444641,294.0760193,999.908,999.908,62.2074689600258,21.6905191249649,9.3E-6,0,0,0,5910,287.91725,999.908,,,,,,,,,,,,,,,,,29.827055,,,,,,294.0602417,,,,
,11452686.645,381.517028808594,999.908,0.000148578357491645,1.705083482197E-7,1,9.99253354069792,40.0298881530762,1.99710014344855,11.0100019350648,0.00159512451577594,0.000258125164553867,0.25,-1.56248289153598E-6,0.000148603596806922,-1.46037585398325E-6,293.9428406,293.9533997,999.908,999.908,63.0891459297182,21.7037919716161,9.25E-6,0,0,0,5910,290.88285,999.908,,,,,,,,,,,,,,,,,29.445843,,,,,,293.94812015,,,,
,11452886.49,348.283050537109,999.908,0.000160101627356777,1.47123234224421E-7,1,9.99253354069792,40.0298881530762,1.99625796505937,11.0400026291609,0.00171767849161986,0.000280633346662641,0.25,-1.43966097906022E-6,0.000160127345609143,-1.33053366776145E-6,294.2110291,294.2241211,999.908,999.908,60.6629710060257,21.6933636560648,9.3E-6,0,0,0,5910,293.0004,999.908,,,,,,,,,,,,,,,,,29.064632,,,,,,294.2175751,,,,
,11453086.345,315.109710693359,999.908,0.000171521472701026,1.24858807678591E-7,1,9.99253354069792,40.0298881530762,1.993750562825,11.0500022396445,0.00183752937245806,0.000302827073412763,0.25,-1.30417255138099E-6,0.000171547670770539,-1.18790639229253E-6,294.4390869,294.4485474,999.908,999.908,62.8382431750451,21.6629823528443,9.3E-6,0,0,0,5910,294.4578,999.908,,,,,,,,,,,,,,,,,29.445843,,,,,,294.44381715,,,,
,11453286.195,300.056579589844,999.908,0.000178021142398526,1.30677760702723E-7,1,9.99253354069792,40.0298881530762,1.99597383091749,11.0300020873547,0.00190917961404151,0.000314665210739291,0.25,-1.35045141864282E-6,0.000178046773461984,-1.23017825113188E-6,294.7116699,294.7311096,999.908,999.908,61.4172425270834,21.6706370555409,9.3E-6,0,0,0,5909,295.2998,999.908,,,,,,,,,,,,,,,,,29.445843,,,,,,294.72138975,,,,
,11453695.995,322.114776611328,5000.012,0.000274351048533961,2.54652687657857E-7,1,9.99253354069792,40.0298881530762,1.97979936656875,11.0400026291609,0.0029171241872103,0.000493898439290439,0.25,-8.82396105070508E-7,0.000274384690111741,-6.96422567555954E-7,295.2772522,295.2988281,5000.012,5000.012,59.3936062907948,21.6681185881816,9.3E-6,0,0,0,5910,294.57685,5000.012,,,,,,,,,,,,,,,,,29.827055,,,,,,295.28804015,,,,
,11453895.805,355.410919189453,5000.012,0.000256175727526645,2.62206931921873E-7,1,9.99253354069792,40.0298881530762,1.98109933899358,11.0300020873547,0.0027250175883181,0.000464601874597465,0.25,-5.30032032454631E-7,0.000256204339883277,-3.55205579859375E-7,295.5868225,295.5948486,5000.012,5000.012,60.5902795537372,21.6775791787278,9.2E-6,0,0,0,5910,292.97025,5000.012,,,,,,,,,,,,,,,,,30.208265,,,,,,295.59083555,,,,
,11454095.625,388.76318359375,5000.012,0.000237465610018643,2.7464748800582E-7,1,9.99253354069792,40.0298881530762,1.98129530191302,11.0300020873547,0.00252659794386047,0.000428532105679235,0.25,-6.97184293048283E-7,0.000237491320235963,-5.33916157069942E-7,295.6987915,295.7030334,5000.012,5000.012,65.39416843293,21.6860385980473,9.3E-6,0,0,0,5910,291.11525,5000.012,,,,,,,,,,,,,,,,,31.351902,,,,,,295.70091245,,,,
,11454295.46,422.038543701172,5000.012,0.000218864452077186,2.6856082321381E-7,1,9.99253354069792,40.0298881530762,1.98175587864987,11.020002476871,0.00232960545838782,0.000392685292616891,0.25,-8.66279883213948E-7,0.000218887623420265,-7.1454722949075E-7,295.7788696,295.78302,5000.012,5000.012,61.8518279837758,21.6942555746609,9.3E-6,0,0,0,5906,289.06225,5000.012,,,,,,,,,,,,,,,,,34.020382,,,,,,295.7809448,,,,
,11454495.31,455.271728515625,5000.012,0.000200180019987334,2.99468442270007E-7,1,9.99253354069792,40.0298881530762,1.97970204904325,11.0300020873547,0.00212859047626603,0.000358850422384901,0.25,-7.89193909337226E-7,0.000200200442823922,-6.49079166847969E-7,295.8783569,295.8843079,5000.012,5000.012,64.7024271934107,21.6767165664903,9.3E-6,0,0,0,5910,286.7565,5000.012,,,,,,,,,,,,,,,,,35.164013,,,,,,295.8813324,,,,
,11454695.205,488.682952880859,5000.012,0.000180040933740834,2.71066842449699E-7,1,9.99253354069792,40.0298881530762,1.98070498821115,11.020002476871,0.00191573087646417,0.000320788910302279,0.25,-9.10126404416963E-7,0.000180058549346586,-7.82719491558405E-7,296.0103149,296.0164185,5000.012,5000.012,62.1480651925643,21.6891979401347,9.25E-6,0,0,0,5910,284.10715,5000.012,,,,,,,,,,,,,,,,,35.164013,,,,,,296.0133667,,,,
,11454895.065,521.940063476562,5000.012,0.000157697052074718,2.62257021127121E-7,1,9.99253354069792,40.0298881530762,1.98034076748784,11.0300020873547,0.00167686612737627,0.000284266729925837,0.25,-4.77219058535892E-7,0.00015769021223554,-3.67652990917465E-7,300.2834473,300.5100403,5000.012,5000.012,60.5371288144295,21.6807785781061,9.3E-6,0,0,0,5910,288.6876,5000.012,,,,,,,,,,,,,,,,,83.57785,,,,,,300.3967438,,,,
,11455094.95,555.265380859375,5000.012,0.00013049791871664,2.65424326546492E-7,1,9.99253354069792,40.0298881530762,1.98058734592316,11.0300020873547,0.00138853937358003,0.000230656573985496,0.25,-8.28453316420941E-7,0.000130486413104303,-7.36761175095622E-7,301.8019714,301.8833313,5000.012,5000.012,61.4195874126411,21.6906350210248,9.3E-6,0,0,0,5910,286.12495,5000.012,,,,,,,,,,,,,,,,,31.351902,,,,,,301.84265135,,,,
,11455294.75,580.010437011719,5000.012,0.000115595122718939,2.7818374342229E-7,1,9.99253354069792,40.0298881530762,1.98053395829413,11.0400026291609,0.00123034729734852,0.000201577773299546,0.25,-9.90747596371529E-7,0.000115579490055644,-9.08741478906968E-7,303.3222351,303.3598938,5000.012,5000.012,60.853688364718,21.686005134707,9.3E-6,0,0,0,5909,284.02335,5000.012,,,,,,,,,,,,,,,,,36.307648,,,,,,303.34106445,,,,
,11455594.52,559.5048828125,5000.012,0.000123705485553486,2.50316979097977E-7,1,9.99253354069792,40.0298881530762,1.97934086801765,11.020002476871,0.00131545779008442,0.000218356693392595,0.25,-8.00495545995588E-7,0.000123690897633508,-7.1303025718437E-7,302.7236023,302.797699,5000.012,5000.012,63.9911452409106,21.6781874891618,9.3E-6,0,0,0,5910,284.6889,5000.012,,,,,,,,,,,,,,,,,30.208265,,,,,,302.76065065,,,,
,11455794.34,526.25732421875,5000.012,0.00015070849157956,2.57731974825443E-7,1,9.99253354069792,40.0298881530762,1.98011179792419,11.020002476871,0.00160288154957901,0.000268418938878959,0.25,-7.59220087258664E-7,0.000150697603820689,-6.53567450465194E-7,301.288269,301.3558655,5000.012,5000.012,62.8538757454297,21.6894429584146,9.3E-6,0,0,0,5906,286.60365,5000.012,,,,,,,,,,,,,,,,,29.827055,,,,,,301.32206725,,,,
,11455994.225,493.080169677734,5000.012,0.000173183017257221,2.60447278673486E-7,1,9.99253354069792,40.0298881530762,1.98019093246906,11.0300020873547,0.00184147809422818,0.000311865760322542,0.25,-5.52225910741707E-7,0.000173177866794221,-4.31774888992804E-7,299.9575806,299.9902344,5000.012,5000.012,62.3856802624104,21.6821977932183,9.25E-6,0,0,0,5910,288.42615,5000.012,,,,,,,,,,,,,,,,,29.445843,,,,,,299.9739075,,,,
,11456194.155,459.766326904297,5000.012,0.000193729880633725,2.74641058451374E-7,1,9.99253354069792,40.0298881530762,1.97851877644106,11.020002476871,0.00205804540809009,0.000351139456468093,0.25,-3.82432146639161E-7,0.000193742393553198,-2.45463059926339E-7,296.8615417,297.1009521,5000.012,5000.012,65.1284147363915,21.6791177428207,9.3E-6,0,0,0,5906,284.4351,5000.012,,,,,,,,,,,,,,,,,45.075508,,,,,,296.9812469,,,,
,11456393.975,426.570831298828,5000.012,0.000212938638054548,2.75949820383553E-7,1,9.99253354069792,40.0298881530762,1.97994038551022,11.0300020873547,0.00226473097477926,0.000381241671932123,0.25,-8.906712587308E-7,0.000212971448662529,-7.41704750310519E-7,294.2435303,294.2984924,5000.012,5000.012,60.9529551866603,21.7035695561698,9.3E-6,0,0,0,5910,286.8129,5000.012,,,,,,,,,,,,,,,,,29.827055,,,,,,294.27101135,,,,
,11456593.86,393.364624023438,5000.012,0.000231160713954331,2.26519016890898E-7,1,9.99253354069792,40.0298881530762,1.97859109288744,11.020002476871,0.00245586349771698,0.000419932235951615,0.25,-3.68639960331128E-7,0.000231198917765049,-2.08957653312954E-7,293.8925171,293.895874,5000.012,5000.012,63.792611597026,21.6788722106412,9.3E-6,0,0,0,5910,290.00105,5000.012,,,,,,,,,,,,,,,,,29.445843,,,,,,293.89419555,,,,
,11456793.625,360.033752441406,5000.012,0.000249883646353417,2.4782069544438E-7,1,9.99253354069792,40.0298881530762,1.97805229969057,11.0300020873547,0.00265481235902425,0.000449485972859066,0.25,-8.0526695949116E-7,0.000249923446775987,-6.34376958813812E-7,294.1269531,294.1404419,5000.012,5000.012,62.0159699728143,21.6930008056629,9.3E-6,0,0,0,5910,292.36715,5000.012,,,,,,,,,,,,,,,,,29.445843,,,,,,294.1336975,,,,
,11456993.48,326.855316162109,5000.012,0.000268780804181865,2.42909897114291E-7,1,9.99253354069792,40.0298881530762,1.97930351875367,11.0300020873547,0.00285685869260427,0.000486279687556874,0.25,-6.28532939165312E-7,0.000268821392266869,-4.45892581570975E-7,294.3798218,294.3884277,5000.012,5000.012,60.2627772041795,21.7005394548088,9.25E-6,0,0,0,5910,293.9978,5000.012,,,,,,,,,,,,,,,,,29.445843,,,,,,294.38412475,,,,
,11457193.34,301.914367675781,5000.012,0.000283733490177284,2.0724785531786E-7,1,9.99253354069792,40.0298881530762,1.97942249518898,11.0300020873547,0.00301557571944775,0.000515493503210296,0.25,-4.61671835972924E-7,0.000283774326362656,-2.69720694285142E-7,294.59021,294.6051331,5000.012,5000.012,65.4223070596223,21.6963892228655,9.25E-6,0,0,0,5910,295.1324,5000.012,,,,,,,,,,,,,,,,,29.445843,,,,,,294.59767155,,,,
,11458002.76,310.520721435547,50002.164,0.000310902027633408,1.79731920803007E-6,1,9.99253354069792,40.0298881530762,1.98075337732687,11.0300020873547,0.00329392326044671,0.000637563493120814,0.25,6.30103277111752E-6,0.000310937560517207,6.510614901182E-6,295.0674438,295.0839844,50002.164,50002.164,61.9088868656796,21.6831713291893,9.25E-6,0,0,0,5910,294.68925,50002.164,,,,,,,,,,,,,,,,,29.827055,,,,,,295.0757141,,,,
,11458202.615,343.887451171875,50002.164,0.000288771034631221,1.92411372999031E-6,1,9.99253354069792,40.0298881530762,1.98053674540916,11.020002476871,0.00305451539369764,0.000618606858413466,0.25,8.34407596314512E-6,0.000288798506740956,8.53990384515359E-6,295.4715881,295.4845581,50002.164,50002.164,61.5759131164873,21.6680391733534,9.3E-6,0,0,0,5906,293.4557,50002.164,,,,,,,,,,,,,,,,,29.827055,,,,,,295.4780731,,,,
,11458402.45,377.190124511719,50002.164,0.000260131772509051,2.09336509515506E-6,1,9.99253354069792,40.0298881530762,1.97999540009672,11.020002476871,0.00274966447049785,0.000563914214659123,0.25,8.15591936815775E-6,0.00026015441327436,8.33358781207985E-6,295.6564941,295.6629944,50002.164,50002.164,62.187928247045,21.6941814394993,9.25E-6,0,0,0,5910,291.7042,50002.164,,,,,,,,,,,,,,,,,30.97069,,,,,,295.65974425,,,,
,11458602.32,410.527374267578,50002.164,0.000230201270602282,2.08157917799771E-6,1,9.99253354069792,40.0298881530762,1.97965020142816,11.0100019350648,0.00243211424752876,0.000503349371514432,0.25,7.63068751367134E-6,0.000230220176819764,7.78920121244477E-6,295.7512817,295.7540283,50002.164,50002.164,63.1399517834682,21.6945208858733,9.3E-6,0,0,0,5910,289.7083,50002.164,,,,,,,,,,,,,,,,,34.020382,,,,,,295.752655,,,,
,11458802.25,443.910430908203,50002.164,0.000205371759353151,2.25692005104521E-6,1,9.99253354069792,40.0298881530762,1.97985712229257,11.020002476871,0.00216655174988132,0.000469052812279127,0.25,8.68378760576171E-6,0.000205386556475466,8.826642429038E-6,295.8429565,295.84729,50002.164,50002.164,62.5529487655258,21.6947152745184,9.3E-6,0,0,0,5910,287.5023,50002.164,,,,,,,,,,,,,,,,,35.545227,,,,,,295.84512325,,,,
,11459002.135,477.295989990234,50002.164,0.000175900172359309,2.44639881548584E-6,1,9.99253354069792,40.0298881530762,1.9802206379845,11.020002476871,0.00185193054851302,0.000425161418326554,0.25,9.63327016968544E-6,0.000175910444588846,9.75707326123811E-6,295.9637146,295.9715271,50002.164,50002.164,63.1274457271605,21.6931979747025,9.3E-6,0,0,0,5910,284.97745,50002.164,,,,,,,,,,,,,,,,,35.545227,,,,,,295.96762085,,,,
,11459201.93,510.705139160156,50002.164,0.000147516818776175,2.37521649187066E-6,1,9.99253354069792,40.0298881530762,1.9798298444151,11.020002476871,0.00154736197155117,0.000387515407979276,0.25,1.10042792868356E-5,0.000147515231134745,1.11039423971435E-5,297.5339966,298.1068726,50002.164,50002.164,61.2155823691219,21.6861966402369,9.3E-6,0,0,0,5910,294.23975,50002.164,,,,,,,,,,,,,,,,,30.97069,,,,,,297.8204346,,,,
,11459401.71,544.098876953125,50002.164,0.000114614597973929,2.6653903474506E-6,1,9.99253354069792,40.0298881530762,1.97966266510918,11.0300020873547,0.00119351356658885,0.000350295500489641,0.25,1.3185296189635E-5,0.000114598575585336,1.32633344080378E-5,300.7819519,300.9966125,50002.164,50002.164,61.1804090857565,21.6987125873158,9.3E-6,0,0,0,5910,288.6875,50002.164,,,,,,,,,,,,,,,,,29.827055,,,,,,300.8892822,,,,
,11459601.585,577.197082519531,50002.164,8.34188216872674E-5,3.176309337186E-6,1,9.99253354069792,40.0298881530762,1.97981444168408,11.0300020873547,0.000861991556402323,0.000293645345225152,0.25,1.32373187782305E-5,8.33992343730324E-5,1.3293962724576E-5,302.76651,302.8894653,50002.164,50002.164,63.5495251275452,21.7037132404982,9.25E-6,0,0,0,5906,284.8672,50002.164,,,,,,,,,,,,,,,,,35.545227,,,,,,302.82798765,,,,
,11459901.355,569.547607421875,50002.164,8.75925920959649E-5,2.95501058984683E-6,1,9.99253354069792,40.0298881530762,1.97970433030594,11.0300020873547,0.000908996833875998,0.000285514223676837,0.25,1.1753021491053E-5,8.75723721711818E-5,1.18128019650128E-5,303.1919861,303.2534485,50002.164,50002.164,60.0533007610256,21.7064447464987,9.3E-6,0,0,0,5910,284.12565,50002.164,,,,,,,,,,,,,,,,,31.351902,,,,,,303.2227173,,,,
,11460101.2,536.262878417969,50002.164,0.000117317484375943,2.67745634807348E-6,1,9.99253354069792,40.0298881530762,1.98005360749708,11.0400026291609,0.00122753316943777,0.000325733660677513,0.25,1.04010148375637E-5,0.000117299931885533,1.04816515399085E-5,301.6970825,301.7402344,50002.164,50002.164,61.0225201248718,21.7044411831149,9.3E-6,0,0,0,5910,286.1124,50002.164,,,,,,,,,,,,,,,,,29.445843,,,,,,301.71865845,,,,
,11460301.07,503.156005859375,50002.164,0.000148915443811767,2.27041775937774E-6,1,9.99253354069792,40.0298881530762,1.97964107843684,11.0400026291609,0.00155885503612666,0.000408083768143993,0.25,1.27027686169073E-5,0.000148902508257891,1.28044307134E-5,299.8779602,299.9101563,50002.164,50002.164,60.9881284700257,21.7065756164477,9.3E-6,0,0,0,5910,289.67705,50002.164,,,,,,,,,,,,,,,,,29.445843,,,,,,299.89405825,,,,
,11460500.995,469.933288574219,50002.164,0.000179066576049508,2.43408178121424E-6,1,9.99253354069792,40.0298881530762,1.98029086065957,11.0400026291609,0.00188292435991792,0.000445818249827969,0.25,1.10317028188226E-5,0.000179061114583204,1.1157407532472E-5,298.4674683,298.668457,50002.164,50002.164,60.1080147573718,21.7092262955307,9.25E-6,0,0,0,5910,284.0317,50002.164,,,,,,,,,,,,,,,,,88.15239,,,,,,298.56796265,,,,
,11460700.795,436.708465576172,50002.164,0.000204344450315171,2.48500672579386E-6,1,9.99253354069792,40.0298881530762,1.98049876839463,11.0100019350648,0.00215062620769093,0.000500665623279895,0.25,1.1818557837697E-5,0.000204364145414079,1.19624750141406E-5,294.6876221,294.7766724,50002.164,50002.164,62.0167516013335,21.719324707741,9.3E-6,0,0,0,5910,285.73285,50002.164,,,,,,,,,,,,,,,,,30.208265,,,,,,294.73214725,,,,
,11460900.61,403.429290771484,50002.164,0.000228873013052755,1.77374840440049E-6,1,9.99253354069792,40.0298881530762,1.97872987733427,11.0300020873547,0.00240872552086799,0.000549027949464575,0.25,1.21783072601E-5,0.000228902329286369,1.23375596936023E-5,293.888031,293.8937988,50002.164,50002.164,62.3692660635066,21.6989708865515,9.25E-6,0,0,0,5910,289.02915,50002.164,,,,,,,,,,,,,,,,,29.445843,,,,,,293.8909149,,,,
,11461100.445,370.282989501953,50002.164,0.000256034896437175,1.82809822920989E-6,1,9.99253354069792,40.0298881530762,1.97981008663165,11.020002476871,0.00270513626539608,0.00056150410536726,0.25,8.6383348484579E-6,0.000256070090842288,8.81374970674084E-6,294.0370483,294.0511169,50002.164,50002.164,62.4028760898335,21.718215723427,9.25E-6,0,0,0,5910,291.67615,50002.164,,,,,,,,,,,,,,,,,29.445843,,,,,,294.0440826,,,,
,11461300.33,337.018646240234,50002.164,0.000285490403555268,1.71107248010587E-6,1,9.99253354069792,40.0298881530762,1.9803289787248,11.0300020873547,0.00301138704972963,0.000659251891942192,0.25,1.27377024466142E-5,0.000285525220157498,1.29322742271433E-5,294.31073,294.3228455,50002.164,50002.164,61.9714171472181,21.7080614587233,9.3E-6,0,0,0,5910,293.4943,50002.164,,,,,,,,,,,,,,,,,29.445843,,,,,,294.31678775,,,,
,11461500.185,306.491729736328,50002.164,0.000310226178797315,1.42073014415736E-6,1,9.99253354069792,40.0298881530762,1.97959445723255,11.0300020873547,0.0032736052683109,0.000701706116523611,0.25,1.24867051822254E-5,0.00031026313636947,1.26967636839782E-5,294.5048828,294.5154724,50002.164,50002.164,60.7473868861026,21.6995092895392,9.3E-6,0,0,0,5910,294.8007,50002.164,,,,,,,,,,,,,,,,,29.445843,,,,,,294.5101776,,,,
,11463452.29,580.004699707031,48658.0855,7.2215155905014E-5,4.62907376506499E-6,1,4.99626677034896,40.0298881530762,1.99606399248873,11.0300020873547,0.00073830681507902,0.00033599232094763,0.25,1.89106926630381E-5,7.21914172710518E-5,1.89586244195055E-5,303.4736328,303.4758606,48375.48,48940.691,60.2236957782179,21.6844665057674,9.25E-6,0,0,0,5985,283.91145,48658.0855,,,,,,,,,,,,,,,,,31.351902,,,,,,303.4747467,,,,
,11463552.21,580.072875976563,38454.0095,8.90164295234713E-5,3.30044402436993E-6,1,4.99626677034896,40.0298881530762,1.99558174941854,11.0300020873547,0.000931074789081282,0.000291219156135493,0.25,1.18348203421329E-5,8.899508853105E-5,1.18957597587962E-5,303.5039673,303.5048218,38206.855,38701.164,62.0878797965835,21.6822518762566,9.25E-6,0,0,0,5985,283.73105,38454.0095,,,,,,,,,,,,,,,,,31.351902,,,,,,303.50439455,,,,
,11463652.155,579.978820800781,28493.1355,0.000103574858698702,2.04113117892098E-6,1,4.99626677034896,40.0298881530762,1.99607294970424,11.0300020873547,0.00109216873601438,0.000289326882487626,0.25,9.13805895093975E-6,0.000103553256284439,9.20979795724949E-6,303.5046082,303.5061951,28233.412,28752.859,59.5632196794678,21.6896780776665,9.2E-6,0,0,0,5985,283.78,28493.1355,,,,,,,,,,,,,,,,,30.97069,,,,,,303.50540165,,,,
,11463752.085,579.990051269531,18497.7645,0.000115897147165367,1.16109919400534E-6,1,4.99626677034896,40.0298881530762,1.9955232077027,11.0300020873547,0.0012309310502086,0.000270665466651143,0.25,5.27436957894858E-6,0.000115876481829632,5.35552681491972E-6,303.4941101,303.4970703,18244.961,18750.568,61.3891039003911,21.6880659464167,9.3E-6,0,0,0,5985,283.8477,18497.7645,,,,,,,,,,,,,,,,,30.97069,,,,,,303.4955902,,,,
,11463852.015,579.972412109375,8405.636,0.000119867288869947,5.13795590356474E-7,1,4.99626677034896,40.0298881530762,1.99523305601892,11.0300020873547,0.00127927921075511,0.000243058472208067,0.25,2.01302507791385E-6,0.000119848249888341,2.0976620933603E-6,303.5151978,303.5157776,8151.136,8660.136,60.1408431551794,21.6920889143424,9.2E-6,0,0,0,5985,283.7669,8405.636,,,,,,,,,,,,,,,,,30.97069,,,,,,303.5154877,,,,
,11464108.585,579.995788574219,-16644.0685,-0.000118121131956812,4.12629799262166E-5,1,4.99626677034896,40.0298881530762,1.99578296724181,11.020002476871,-0.00125728933686016,-0.000260938366862976,0.25,-3.97866344841087E-6,-0.000118100954428435,-4.06164143741694E-6,303.5206604,303.5206604,-16652.824,-16635.313,61.9464050346027,21.7016081265813,9.25E-6,0,0,0,5985,283.76125,-16644.0685,,,,,,,,,,,,,,,,,30.97069,,,,,,303.5206604,,,,
,11464206.805,579.976745605469,-26115.784,-0.000107058809046303,1.66127916994666E-6,1,4.99626677034896,40.0298881530762,1.99549123620374,11.0300020873547,-0.00112712713921966,-0.000307443732538935,0.25,-1.02364505245788E-5,-0.000107035809776617,-1.03105699280671E-5,303.5314331,303.5343018,-26356.584,-25874.984,61.933898978295,21.7067193399171,9.3E-6,0,0,0,5985,283.6158,-26115.784,,,,,,,,,,,,,,,,,32.114323,,,,,,303.53286745,,,,
,11464306.72,579.957824707031,-35760.7405,-9.23280504777499E-5,2.78031702510717E-6,1,4.99626677034896,40.0298881530762,1.99545311749022,11.0300020873547,-0.000957641157857153,-0.000348433380345542,0.25,-1.66095639394634E-5,-9.23027314301465E-5,-1.66721593689943E-5,303.5449219,303.5450745,-36005.211,-35516.27,60.5175881014487,21.7022018179366,9.3E-6,0,0,0,5985,283.72215,-35760.7405,,,,,,,,,,,,,,,,,31.733112,,,,,,303.5449982,,,,
,11464406.675,580.025756835938,-45440.287,-7.93569695006168E-5,4.52003923068748E-6,1,4.99626677034896,40.0298881530762,1.99596825095621,11.0300020873547,-0.000806731555806371,-0.000395567632385116,0.25,-2.32431293012714E-5,-7.93289584714257E-5,-2.32954717718375E-5,303.5390625,303.5412903,-45684.617,-45195.957,60.7755255127949,21.7023402143835,9.3E-6,0,0,0,5985,283.76885,-45440.287,,,,,,,,,,,,,,,,,31.351902,,,,,,303.5401764,,,,
,11464521.58,579.999633789063,-45833.297,-7.97399132585081E-5,4.20307118765387E-6,1,4.99626677034896,40.0298881530762,1.9953700531619,11.020002476871,-0.000805952277497315,-0.000423071141815212,0.25,-2.57570416177163E-5,-7.97100231015679E-5,-2.5809302329114E-5,303.5553894,303.5579224,-46082.711,-45583.883,62.4036577183527,21.711582587402,9.3E-6,0,0,0,5985,283.6002,-45833.297,,,,,,,,,,,,,,,,,32.495537,,,,,,303.5566559,,,,
,11464621.46,580.032897949219,-35752.8025,-9.2291513425843E-5,2.64614807409774E-6,1,4.99626677034896,40.0298881530762,1.99582287424691,11.0300020873547,-0.000953416623671872,-0.00037161496042698,0.25,-1.87752762424725E-5,-9.22646400878614E-5,-1.88375234125532E-5,303.5560303,303.5561523,-36005.605,-35500,63.0649154456221,21.7104822719483,9.3E-6,0,0,0,5985,283.70905,-35752.8025,,,,,,,,,,,,,,,,,31.733112,,,,,,303.5560913,,,,
,11464721.39,580.015991210937,-25685.4355,-0.000106399556908848,1.70953967832756E-6,1,4.99626677034896,40.0298881530762,1.9961412546839,11.020002476871,-0.00111260005632133,-0.000351615545715958,0.25,-1.44663952245594E-5,-0.000106373681403898,-1.45393826921583E-5,303.5308533,303.5322876,-25948.832,-25422.039,60.5879346681795,21.7114841767,9.3E-6,0,0,0,5985,283.78025,-25685.4355,,,,,,,,,,,,,,,,,30.97069,,,,,,303.53157045,,,,
,11464821.275,579.955444335938,-15586.254,-0.000117305907329164,1.03334573614188E-6,1,4.99626677034896,40.0298881530762,1.99569473787067,11.0300020873547,-0.00123726119104183,-0.000324558300559268,0.25,-1.00628951679343E-5,-0.000117281450714125,-1.01444946819146E-5,303.5404663,303.5415344,-15841.742,-15330.766,59.9907704794871,21.7102543139956,9.3E-6,0,0,0,5985,283.52625,-15586.254,,,,,,,,,,,,,,,,,32.114323,,,,,,303.54100035,,,,
,11464967.155,579.988342285156,-600.3325,0.000166199698095691,0.000239138270155927,1,4.99626677034896,40.0298881530762,1.99625856911685,11.0300020873547,7.75076171645837E-5,0.0101637017089093,2.5,0.000920690398276328,0.000165521871453353,0.000920672365822856,303.5354919,303.5354919,-634.935,-565.73,61.954221319795,21.7171002941533,9.3E-6,0,0,0,5985,283.72025,-600.3325,,,,,,,,,,,,,,,,,30.97069,,,,,,303.5354919,,,,
,11465176.08,579.995544433594,19603.1805,0.000113955036565286,1.0061016111532E-6,1,4.99626677034896,40.0298881530762,1.99597886755356,11.020002476871,0.00121089806536197,0.000264277896882033,0.25,5.00761059807583E-6,0.000113934755637357,5.08741666241878E-6,303.52005,303.5202942,19369.865,19836.496,61.8127465578142,21.7097490841898,9.25E-6,0,0,0,5985,283.831,19603.1805,,,,,,,,,,,,,,,,,31.351902,,,,,,303.5201721,,,,
,11465275.95,580.028137207031,29330.379,0.000104376997939155,2.17319287489186E-6,1,4.99626677034896,40.0298881530762,1.99555940868309,11.020002476871,0.00110377057547276,0.000271706856427432,0.25,7.36033567274601E-6,0.000104356409635416,7.4328943149852E-6,303.5415039,303.5424194,29093.957,29566.801,64.2373582244683,21.7187865012066,9.3E-6,0,0,0,5985,283.72625,29330.379,,,,,,,,,,,,,,,,,30.97069,,,,,,303.54196165,,,,
,11465375.93,579.991882324219,39106.1095,9.17716484480392E-5,2.81536352430711E-6,1,4.99626677034896,40.0298881530762,1.9955680314067,11.0300020873547,0.000960539288113191,0.000296444838066279,0.25,1.18475034517569E-5,9.17497805355505E-5,1.19103588924424E-5,303.5431519,303.5450439,38860.367,39351.852,63.0492828752374,21.7216923948468,9.3E-6,0,0,0,5985,283.7179,39106.1095,,,,,,,,,,,,,,,,,31.351902,,,,,,303.5440979,,,,
,11465475.9,579.979919433594,48882.83,8.09021234114548E-5,3.97464068668352E-6,1,4.99626677034896,40.0298881530762,1.99613921334418,11.0300020873547,0.000830338512017949,0.000357940173691287,0.25,1.94594766187311E-5,8.08765342286687E-5,1.95134143158927E-5,303.5481567,303.5505371,48639.203,49126.457,59.6734293006794,21.7191885597912,9.25E-6,0,0,0,5985,283.7391,48882.83,,,,,,,,,,,,,,,,,32.114323,,,,,,303.5493469,,,,
,11466742.45,318.874450683594,999.774,0.000204143199143698,1.58489445554434E-7,1,9.99253354069792,40.0298881530762,1.99581852730487,11.0300020873547,0.00218851675550126,0.000364299135622076,0.25,-1.22248367011303E-6,0.000204168551790717,-1.08427695177467E-6,295.2859497,295.3123169,999.774,999.774,61.2163639976411,21.6930748643703,9.3E-6,0,0,0,5910,294.9058,999.774,,,,,,,,,,,,,,,,,30.208265,,,,,,295.2991333,,,,
,11466942.305,352.101348876953,999.774,0.000191631475244005,1.66761376880876E-7,1,9.99253354069792,40.0298881530762,1.99581836057069,11.0300020873547,0.00205415291477125,0.000343180757786279,0.25,-1.03520688404937E-6,0.000191653107953704,-9.04543438442828E-7,295.6217346,295.6282043,999.774,999.774,61.0037610404103,21.694608945008,9.3E-6,0,0,0,5910,293.19275,999.774,,,,,,,,,,,,,,,,,30.589479,,,,,,295.62496945,,,,
,11467142.165,385.580841064453,999.774,0.000178844068353743,1.84555894936682E-7,1,9.99253354069792,40.0298881530762,1.9956703051077,11.0300020873547,0.00191671511046291,0.000321549751115874,0.25,-8.46331812070789E-7,0.00017886358955347,-7.23423501833502E-7,295.7116394,295.712738,999.774,999.774,61.2695147369488,21.6842832791361,9.2E-6,0,0,0,5910,291.2942,999.774,,,,,,,,,,,,,,,,,32.114323,,,,,,295.7121887,,,,
,11467342.085,418.763061523438,999.774,0.000165452608053456,1.9238530975105E-7,1,9.99253354069792,40.0298881530762,1.99605085080004,11.020002476871,0.00177393046651473,0.000295123358629576,0.25,-1.00828347439209E-6,0.000165470416091067,-8.93649044176578E-7,295.7704163,295.775177,999.774,999.774,60.8935514191987,21.7094438920309,9.3E-6,0,0,0,5910,289.26855,999.774,,,,,,,,,,,,,,,,,33.639168,,,,,,295.77279665,,,,
,11467541.89,452.098419189453,999.774,0.000151234958379451,1.63881366113781E-7,1,9.99253354069792,40.0298881530762,1.99541623571587,11.020002476871,0.001621209924646,0.000268421270901208,0.25,-1.04015275379583E-6,0.000151250751978544,-9.34384937792361E-7,295.8685608,295.8737793,999.774,999.774,63.2665756035836,21.709083483105,9.3E-6,0,0,0,5906,286.99365,999.774,,,,,,,,,,,,,,,,,34.782803,,,,,,295.87117005,,,,
,11467741.715,485.332122802734,999.774,0.000136167845899534,1.70595373851157E-7,1,9.99253354069792,40.0298881530762,1.99581582009267,11.0300020873547,0.00146006669632368,0.000241145060944951,0.25,-9.91676162491833E-7,0.000136181441135278,-8.95400084631746E-7,295.9982605,296.0044861,999.774,999.774,62.3778639772181,21.7148579858191,9.3E-6,0,0,0,5910,284.3809,999.774,,,,,,,,,,,,,,,,,34.401592,,,,,,296.0013733,,,,
,11467941.56,518.634155273438,999.774,0.000119273116857545,1.76635871700518E-7,1,9.99253354069792,40.0298881530762,1.99641562087585,11.0400026291609,0.00127924985479779,0.000210532680331124,0.25,-9.34601728573302E-7,0.000119270469335462,-8.52162762227E-7,299.6835938,300.0198975,999.774,999.774,59.2513499002947,21.7086103374807,9.3E-6,0,0,0,5910,290.1216,999.774,,,,,,,,,,,,,,,,,56.511848,,,,,,299.85174565,,,,
,11468141.455,552.023498535156,999.774,9.57975461403018E-5,1.63663923489858E-7,1,9.99253354069792,40.0298881530762,1.99639532173707,11.020002476871,0.00102823613241495,0.000164209443856554,0.25,-1.20680071588318E-6,9.57900788865042E-5,-1.13945424044433E-6,301.6083374,301.7144165,999.774,999.774,61.618902685045,21.7293641118373,9.3E-6,0,0,0,5910,286.3087,999.774,,,,,,,,,,,,,,,,,30.589479,,,,,,301.66137695,,,,
,11468341.345,580.02880859375,999.774,8.46892734408747E-5,1.64249472494352E-7,1,9.99253354069792,40.0298881530762,1.99647079773045,11.0400026291609,0.000909225184799615,0.000143819816668028,0.25,-1.19311086847169E-6,8.46784268775897E-5,-1.13297743948117E-6,303.2072144,303.2726135,999.774,999.774,59.6030827339486,21.7237464362182,9.3E-6,0,0,0,5909,284.1999,999.774,,,,,,,,,,,,,,,,,35.926437,,,,,,303.23991395,,,,
,11468641.13,562.923278808594,999.774,8.85184039930547E-5,1.54316578889389E-7,1,9.99253354069792,40.0298881530762,1.99673530312195,11.0300020873547,0.000950345666077116,0.000151035529057725,0.25,-1.18234353592166E-6,8.85079200312135E-5,-1.11958012237596E-6,302.8888855,302.9619446,999.774,999.774,60.6746954338141,21.7360831853589,9.3E-6,0,0,0,5910,284.46045,999.774,,,,,,,,,,,,,,,,,30.589479,,,,,,302.92541505,,,,
,11468841,529.779113769531,999.774,0.000110032262069949,1.7737375609509E-7,1,9.99253354069792,40.0298881530762,1.99634581288116,11.0300020873547,0.00118055909576675,0.000191175830035683,0.25,-1.14616809390317E-6,0.000110024203400045,-1.06887394607802E-6,301.4372864,301.4983826,999.774,999.774,60.9107472466218,21.7281183520081,9.3E-6,0,0,0,5910,286.40795,999.774,,,,,,,,,,,,,,,,,29.827055,,,,,,301.4678345,,,,
,11469040.74,496.560943603516,999.774,0.000127875490479179,1.57231596299569E-7,1,9.99253354069792,40.0298881530762,1.99681904645095,11.0300020873547,0.00137180239500239,0.00022557756909936,0.25,-1.01963798345786E-6,0.000127871875183721,-9.30586662883943E-7,300.0289001,300.0307922,999.774,999.774,62.198089417795,21.7425158294245,9.3E-6,0,0,0,5910,288.31655,999.774,,,,,,,,,,,,,,,,,29.064632,,,,,,300.02984615,,,,
,11469240.61,463.360168457031,999.774,0.000143514585900595,1.73267291318415E-7,1,9.99253354069792,40.0298881530762,1.99618220469201,11.0300020873547,0.00153893068508174,0.000254836455264969,0.25,-9.84753069244658E-7,0.000143522252656932,-8.83187914928535E-7,297.2990723,297.5671082,999.774,999.774,62.9437630251413,21.732647373397,9.3E-6,0,0,0,5910,284.268,999.774,,,,,,,,,,,,,,,,,47.743988,,,,,,297.43309025,,,,
,11469440.465,430.076812744141,999.774,0.000157439449264068,1.63273501405173E-7,1,9.99253354069792,40.0298881530762,1.99631162566266,11.0300020873547,0.0016882436685345,0.000281220102749244,0.25,-9.28757868951116E-7,0.000157463395525572,-8.18441505540984E-7,294.3323059,294.4000549,999.774,999.774,59.3803186059678,21.7324024605799,9.3E-6,0,0,0,5910,286.48515,999.774,,,,,,,,,,,,,,,,,29.827055,,,,,,294.3661804,,,,
,11469640.36,396.874847412109,999.774,0.000171213475521878,1.6044555266741E-7,1,9.99253354069792,40.0298881530762,1.99649104918311,11.0300020873547,0.00183610584939729,0.000306010643504536,0.25,-9.9385954798293E-7,0.000171242315444566,-8.75511296778178E-7,293.8813782,293.8843079,999.774,999.774,59.3021557540447,21.7360437467642,9.3E-6,0,0,0,5910,289.73775,999.774,,,,,,,,,,,,,,,,,29.445843,,,,,,293.88284305,,,,
,11469840.29,363.482421875,999.774,0.000184324598643905,1.72039084849626E-7,1,9.99253354069792,40.0298881530762,1.99561644993883,11.0300020873547,0.00197589981616881,0.000329111790506232,0.25,-1.08660318807882E-6,0.000184354439735842,-9.60462693005618E-7,294.0999451,294.113678,999.774,999.774,60.6020039815256,21.7372541248521,9.25E-6,0,0,0,5910,292.18725,999.774,,,,,,,,,,,,,,,,,29.445843,,,,,,294.10681155,,,,
,11470040.025,330.418243408203,999.774,0.000197507791334683,1.33866001773968E-7,1,9.99253354069792,40.0298881530762,1.99543172748084,11.020002476871,0.00211644699431289,0.000355903425902657,0.25,-8.56410824211284E-7,0.000197537979561167,-7.22113222657521E-7,294.3622131,294.3721924,999.774,999.774,62.2379524722758,21.7337475119434,9.3E-6,0,0,0,5910,293.86335,999.774,,,,,,,,,,,,,,,,,29.445843,,,,,,294.36720275,,,,
,11470239.91,303.200500488281,999.774,0.000208581920607427,1.27220163841723E-7,1,9.99253354069792,40.0298881530762,1.99631793778863,11.0300020873547,0.00223621289768958,0.000375092277151285,0.25,-9.90022979190999E-7,0.000208612583579274,-8.48889097647922E-7,294.5569458,294.5750427,999.774,999.774,62.0808451399104,21.7401461689284,9.3E-6,0,0,0,5910,295.0618,999.774,,,,,,,,,,,,,,,,,29.445843,,,,,,294.56599425,,,,
,11470359.81,299.813903808594,999.774,0.000210807572075551,1.31603574528112E-7,1,9.99253354069792,40.0298881530762,1.99610475720433,11.0300020873547,0.00225969851751104,0.000379798230151436,0.25,-9.30873965684098E-7,0.000210837066684058,-7.88376628869866E-7,294.7721252,294.7903748,999.774,999.774,60.108796385891,21.7433322186125,9.3E-6,0,0,0,5905,295.3364,999.774,,,,,,,,,,,,,,,,,29.445843,,,,,,294.78125,,,,