File: DataFailid_Testimiseks/Tb5MnGa13Ge2_2021_09_14_Hys300Kand50K_wHystereesi_tootabHasti.DAT
[Header]
; VSM Data File (default extension .dat)
; Copyright (c) 2003-2013, Quantum Design, Inc. All rights reserved.
TITLE,Tb5MnGa13Ge2_2021_09_14_Hys300Kand50K
FILEOPENTIME,33640711.14,09/14/2021,11:22 am
BYAPP,VSM,2.0,2.0
INFO,PPMS VSM Option Release 1.4.10 Build 1,APPNAME
INFO,Quantum Design Linear Motor Servo Controller,MOTOR_MODULE_NAME
INFO,3101-100 C1,MOTOR_HW_VERSION
INFO,074,MOTOR_SERIAL_NUMBER
INFO,SRV No X-over 01.01.11,MOTOR_SOFTWARE_VERSION
INFO,Quantum Design VSM Detection Module,VSM_MODULE_NAME
INFO,3101-150 E1,VSM_HW_VERSION
INFO,VSM061,VSM_SERIAL_NUMBER
INFO,VSM No X-over 01.02.05 May 20 2008 13:51:47,VSM_SOFTWARE_VERSION
INFO,113,PREAMP_SERIAL_NUMBER
INFO,Quantum Design VSM Oven,OVEN_MODULE_NAME
INFO,3101-200 B0,OVEN_HW_VERSION
INFO,OVN054,OVEN_SERIAL_NUMBER
INFO,01.01.00,OVEN_SOFTWARE_VERSION
INFO,221,COIL_SERIAL_NUMBER
INFO,0,MOMENT_UNITS
INFO,Tb5MnGa13Ge2,SAMPLE_MATERIAL
INFO,,SAMPLE_COMMENT
INFO,14.8,SAMPLE_MASS
INFO,,SAMPLE_VOLUME
INFO,,SAMPLE_MOLECULAR_WEIGHT
INFO,,SAMPLE_SIZE
INFO,,SAMPLE_SHAPE
DATATYPE,COMMENT,1
DATATYPE,TIME,2
STARTUPAXIS,X,2
STARTUPAXIS,Y1,5
[Data]
Comment,Time Stamp (sec),Temperature (K),Magnetic Field (Oe),Moment (emu),M. Std. Err. (emu),Transport Action,Averaging Time (sec),Frequency (Hz),Peak Amplitude (mm),Center Position (mm),Coil Signal' (mV),Coil Signal" (mV),Range (mV),M. Quad. Signal (emu),M. Raw' (emu),M. Raw" (emu),Min. Temperature (K),Max. Temperature (K),Min. Field (Oe),Max. Field (Oe),Mass (grams),Motor Lag (deg),Pressure (Torr),VSM Status (code),Motor Status (code),Measure Status (code),Measure Count,PPMS Status (code),System Temp. (K),System Field (Oe),Sample Position (deg),Bridge 1 Resistance (ohms),Bridge 1 Excitation (에),Bridge 2 Resistance (ohms),Bridge 2 Excitation (에),Bridge 3 Resistance (ohms),Bridge 3 Excitation (에),Bridge 4 Resistance (ohms),Bridge 4 Excitation (에),Signal 1 Vin (V),Signal 2 Vin (V),Digital Inputs (code),Drive 1 Iout (mA),Drive 1 Ipower (W),Drive 2 Iout (mA),Drive 2 Ipower (W),Pressure (),Map 20 (),Map 21 (),Map 22 (),Map 23 (),Map 24 (),Map 25 (),Map 26 (),Map 27 (),Map 28 (),Map 29 ()
,33642086.33,299.9910583,0.239,,,2,,,,7.180000064075,,,,,,,299.9910583,299.9910583,0.239,0.239,,,31.733112,,,,-99999999,4929,300.0592,0.239,,,,,,,,,,,,,,,,,,,,,,,299.9910583,,,,
,33642205.455,299.99685665,5171.736,0.00707532303363987,5.15516574884017E-6,1,1.99850670813958,40.0298881530762,2.00759092554399,7.17000011354685,0.0761713116938281,0.0132591003552494,0.25,1.00580444489041E-5,0.00707510592215997,1.47517756875077E-5,299.9967651,299.9969482,5113.972,5229.5,53.1014967109864,18.5111958883088,31.733112,0,0,0,80,4961,300.064,5171.736,,,,,,,,,,,,,0,,,,6.0784326,,,,,,299.99685665,,,,
,33642299.35,299.99990845,10302.577,0.0142808222274571,4.79293072677096E-6,1,1.99850670813958,40.0298881530762,2.00753022543003,7.17000011354685,0.153735946382195,0.0267825764244767,0.25,2.22781035462641E-5,0.0142803820166449,3.17440195262943E-5,299.9992676,300.0005493,10249.474,10355.68,52.9271935511979,18.515751393515,31.733112,0,0,0,80,4961,300.0605,10302.577,,,,,,,,,,,,,0,,,,6.1394596,,,,,,299.99990845,,,,
,33642393.29,300.0027313,14981.728,0.0207705721662366,4.85694387947898E-6,1,1.99850670813958,40.0298881530762,2.00763616524064,7.17000011354685,0.2235626339162,0.0388348741817414,2.5,2.22850228706267E-5,0.0207699377746908,3.60414322559658E-5,300.0022888,300.0031738,14936.393,15027.063,52.5027692652556,18.5132517162047,31.733112,0,0,0,80,4961,300.0569,14981.728,,,,,,,,,,,,,0,,,,6.1394596,,,,,,300.0027313,,,,
,33642487.56,300.0050201,19543.6415,0.0270348789852529,4.67472172145521E-6,1,1.99850670813958,40.0298881530762,2.00757751912826,7.17000011354685,0.29098390680555,0.0505227560349361,2.5,2.68742950334634E-5,0.027034054105181,4.47640460053882E-5,300.0047607,300.0052795,19488.844,19598.439,52.8162023014671,18.5234441314628,31.733112,0,0,0,80,4961,300.05465,19543.6415,,,,,,,,,,,,,0,,,,6.2633576,,,,,,300.0050201,,,,
,33642585.97,300.00613405,24279.7415,0.0335332959402449,4.88799447241513E-6,1,1.99850670813958,40.0298881530762,2.00774415905683,7.17000011354685,0.360955720772967,0.0626788144701309,2.5,3.3988938687406E-5,0.0335322729619477,5.6158906207756E-5,300.0058899,300.0063782,24226.639,24332.844,52.6231400572171,18.5230742474336,31.733112,0,0,0,80,4961,300.03995,24279.7415,,,,,,,,,,,,,0,,,,6.2633576,,,,,,300.00613405,,,,
,33642704.72,300.0062561,30010.625,,,2,,,,7.16999998793006,,,,,,,300.0062561,300.0062561,30010.625,30010.625,,,31.733112,,,,-99999999,4961,300.0305,30010.625,,,,,,,,,,,,,,,,,,,,,,,300.0062561,,,,
,33642821,300.0062561,35615.0975,0.0491891576227562,5.59260600561383E-6,1,1.99850670813958,40.0298881530762,1.98272312954258,7.16000003740191,0.523124894684666,0.0909593081927963,2.5,6.09180725274262E-5,0.0491876565772312,9.33609167425647E-5,300.0054016,300.0071106,35566.09,35664.105,52.7130273369287,18.5115078422486,31.733112,0,0,0,80,4961,300.0271,35615.0975,,,,,,,,,,,,,0,,,,6.3579991,,,,,,300.0062561,,,,
,33642913.56,300.00080875,40085.6195,0.0553104238923602,5.1932043380238E-6,1,1.99850670813958,40.0298881530762,1.98275647739004,7.16000003740191,0.588231160522122,0.102296569634271,2.5,7.00670570787803E-5,0.0553087479542043,0.0001065113667031,300.0003052,300.0013123,40047.063,40124.176,52.7364761925056,18.5171084896918,31.733112,0,0,0,80,4961,300.02125,40085.6195,,,,,,,,,,,,,0,,,,6.3579991,,,,,,300.00080875,,,,
,33643003.175,300.0095825,44406.8615,0.0612903840216471,6.96527301017244E-6,1,1.99850670813958,40.0298881530762,1.98276049063738,7.16000003740191,0.651836136753722,0.113319262907149,2.5,7.41627443133735E-5,0.0612885154455595,0.000114508224138639,300.0095825,300.0095825,44362.516,44451.207,52.5309078919479,18.5178343676274,31.733112,0,0,0,80,4961,300.01545,44406.8615,,,,,,,,,,,,,0,,,,6.3897567,,,,,,300.0095825,,,,
,33643093.445,300.01008605,48765.807,0.0672818677362206,6.45928003063156E-6,1,1.99850670813958,40.0298881530762,1.98275098480176,7.16000003740191,0.71554314833015,0.124456648263893,2.5,8.71304429761268E-5,0.0672798156775537,0.000131375273747537,300.0092468,300.0109253,48717.223,48814.391,53.3758483212364,18.51463863008,31.733112,0,0,0,80,4961,300.0117,48765.807,,,,,,,,,,,,,0,,,,6.3897567,,,,,,300.01008605,,,,
,33643194.01,300.00743105,53619.342,0.0739267966715354,7.75245286048575E-6,1,1.99850670813958,40.0298881530762,1.98286064067549,7.17000011354685,0.786277050360265,0.13662133921285,2.5,8.31693331872078E-5,0.0739245613357629,0.0001317310202288,300.0067749,300.0080872,53569.629,53669.055,52.6833254531979,18.5183508588527,31.733112,0,0,0,80,4961,299.9965,53619.342,,,,,,,,,,,,,0,,,,6.4539089,,,,,,300.00743105,,,,
,33643295.36,300.0109711,58511.998,0.0806920867531128,8.03948412397117E-6,1,1.99850670813958,40.0298881530762,1.9828499851737,7.16000003740191,0.858218526579249,0.149174888150635,2.5,9.56936761405407E-5,0.0806896397104222,0.000148641006393086,300.0105591,300.0113831,58463.273,58560.723,53.6056471058903,18.5155659937816,31.733112,0,0,0,80,4961,299.97455,58511.998,,,,,,,,,,,,,0,,,,6.48630735,,,,,,300.0109711,,,,
,33643435.52,300.0100708,65276.9475,0.0900544057380566,7.97585014293559E-6,1,1.99850670813958,40.0298881530762,2.00763491077677,7.17000011354685,0.969284207322948,0.168433517488724,2.5,0.00010267863268084,0.0900516887183409,0.000161673635874058,300.0100708,300.0100708,65272.004,65281.891,53.1671535066018,18.5191118756291,31.733112,0,0,0,80,4961,299.96215,65276.9475,,,,,,,,,,,,,0,,,,6.5187058,,,,,,300.0100708,,,,
,33643537.335,300.00634765,70187.25,0.0968180593976829,7.70601779461726E-6,1,1.99850670813958,40.0298881530762,2.00773545488012,7.17000011354685,1.04214334854804,0.181037312477265,2.5,0.00010532626492353,0.0968151601768162,0.000168675039578895,300.006134,300.0065613,70172.422,70202.078,52.9381363504671,18.5231467072922,31.733112,0,0,0,80,4961,299.959,70187.25,,,,,,,,,,,,,0,,,,6.5187058,,,,,,300.00634765,,,,
,33643648.33,300.0081787,75528.0235,0.104239163211962,9.2416188111443E-6,1,1.99850670813958,40.0298881530762,2.00752900363426,7.17000011354685,1.12191570670172,0.194879164210467,2.5,0.00011205466729612,0.104236044602935,0.000180169173496553,300.0081177,300.0082397,75478.734,75577.313,52.8537204703902,18.5275465206543,31.351902,0,0,0,80,4961,299.94935,75528.0235,,,,,,,,,,,,,0,,,,6.5514295,,,,,,300.0081787,,,,
,33643766.195,300.00733945,81200.4105,0.111940703413783,9.97363620250215E-6,1,1.99850670813958,40.0298881530762,2.00762984839777,7.17000011354685,1.2052183859239,0.209390410210526,25,0.000124170557719472,0.111937364338902,0.000197212461314076,300.0073242,300.0073547,81195.469,81205.352,53.2812712704095,18.5224934676753,31.733112,0,0,0,80,4961,299.9431,81200.4105,,,,,,,,,,,,,0,,,,6.5841532,,,,,,300.00733945,,,,
,33643875.68,300.0124054,86467.1835,0.119338621616707,1.03177954742446E-5,1,1.99850670813958,40.0298881530762,2.00766268781601,7.17000011354685,1.28489458219585,0.223197890051974,25,0.000129301554984481,0.119335053127145,0.000207073898660039,300.012085,300.0127258,86409.422,86524.945,53.2304654166595,18.5232881477863,31.351902,0,0,0,80,4961,299.90965,86467.1835,,,,,,,,,,,,,0,,,,6.5841532,,,,,,300.0124054,,,,
,33644024.47,300.0062256,93616.555,0.129018106854893,1.26036380687038E-5,1,1.99850670813958,40.0298881530762,1.9827080502379,7.18000018969178,1.37250284565023,0.238656632837523,25,0.000161882694258337,0.129014274413969,0.000245803585572342,300.0062256,300.0062256,93605.68,93627.43,53.0741397128133,18.5185163251877,31.733112,0,0,0,80,4961,299.9107,93616.555,,,,,,,,,,,,,0,,,,6.6172054,,,,,,300.0062256,,,,
,33644143.25,300.01194765,99315.0625,0.136793553989761,1.45777917854935E-5,1,1.99850670813958,40.0298881530762,1.982576237241,7.18000018969178,1.45512212118532,0.253043093461061,25,0.000173617881971513,0.136789475738912,0.000262466767231514,300.0117798,300.0121155,99258.57,99371.555,52.700521280621,18.5097557036083,31.733112,0,0,0,80,4961,299.8934,99315.0625,,,,,,,,,,,,,0,,,,6.6172054,,,,,,300.01194765,,,,
,33644254.2,300.0072021,104633.5195,0.144032953442087,1.55550752553629E-5,1,1.99850670813958,40.0298881530762,1.98264224008704,7.18999980017543,1.53219941674972,0.266328063889254,25,0.000172110741110458,0.144028699831423,0.000265532792501809,300.0072021,300.0072021,104628.719,104638.32,52.9232854086018,18.5194440027973,31.351902,0,0,0,80,4961,299.87965,104633.5195,,,,,,,,,,,,,0,,,,6.6502576,,,,,,300.0072021,,,,
,33644357.195,300.00979615,109565.4375,0.150865238465766,1.49219558677857E-5,1,1.99850670813958,40.0298881530762,1.98272995902754,7.18000018969178,1.60492132766104,0.27912976251154,25,0.000195103290517268,0.150860772247485,0.000292829289123926,300.0091858,300.0104065,109516.148,109614.727,53.0037931460825,18.514440667791,31.733112,0,0,0,80,4961,299.8686,109565.4375,,,,,,,,,,,,,0,,,,6.6836417,,,,,,300.00979615,,,,
,33644468.115,300.00975035,114880.6445,0.158208555253624,1.38035991263448E-5,1,1.99850670813958,40.0298881530762,1.98291328163334,7.18000018969178,1.683213351183,0.292606425816118,25,0.000191974443164229,0.158203892986649,0.000294312566740834,300.0094604,300.0100403,114871.32,114889.969,53.4430683738903,18.5219480873088,31.733112,0,0,0,80,4961,299.85755,114880.6445,,,,,,,,,,,,,0,,,,6.6502576,,,,,,300.00975035,,,,
,33644614.095,300.0079498,121847.8285,0.167882122546141,1.77808733152817E-5,1,1.99850670813958,40.0298881530762,2.00766919818876,7.19999987632036,1.80756020697714,0.313984831442755,25,0.000182477832572346,0.167877216823493,0.000290869658092101,300.007843,300.0080566,121798.68,121896.977,53.5603126517749,18.5227289709351,31.733112,0,0,0,80,4961,299.8456,121847.8285,,,,,,,,,,,,,0,,,,6.6836417,,,,,,300.0079498,,,,
,33644725.42,300.0098572,127157.535,0.174959255949171,1.79126449587061E-5,1,1.99850670813958,40.0298881530762,1.99356560467065,7.2099999524653,1.87097351441082,0.325547075450951,25,0.000239975734752037,0.174954114765675,0.000352775641920956,300.0098572,300.0098572,127152.734,127162.336,52.7552352769671,18.508824371552,31.351902,0,0,0,80,4961,299.828,127157.535,,,,,,,,,,,,,0,,,,6.7170258,,,,,,300.0098572,,,,
,33644831.39,300.0106201,132204.4065,0.181880247864572,1.66122876233808E-5,1,1.99850670813958,40.0298881530762,1.99360278910456,7.19999987632036,1.94505448605685,0.338230666665895,25,0.000230896947769551,0.181874925238405,0.000347997156326395,300.0106201,300.0106201,132198.047,132210.766,53.0467827146402,18.511217880441,31.733112,0,0,0,80,4961,299.8192,132204.4065,,,,,,,,,,,,,0,,,,6.7170258,,,,,,300.0106201,,,,
,33644932.25,300.0063324,136996.797,0.188470799243452,1.53040586038042E-5,1,1.99850670813958,40.0298881530762,1.99359483231508,7.2099999524653,2.01557474437996,0.35021188581154,25,0.000213854936619613,0.18846534050858,0.000335036197909066,300.0059509,300.0067139,136939.453,137054.141,52.3472251899286,18.5166634462088,31.733112,0,0,0,80,4961,299.81605,136996.797,,,,,,,,,,,,,0,,,,6.7170258,,,,,,300.0063324,,,,
,33645044.48,300.00608825,138432.719,0.19064597753931,1.97450577169576E-5,1,1.99850670813958,40.0298881530762,1.99348702587806,7.19999987632036,2.03870500191407,0.354386955596602,25,0.000230539238996719,0.19064045212142,0.000353073933562707,300.0057068,300.0064697,138380.891,138484.547,52.9498607782556,18.5179523274765,31.733112,0,0,0,80,4977,299.80485,138432.719,,,,,,,,,,,,,0,,,,6.7507451,,,,,,300.00608825,,,,
,33645152.42,300.0016479,133065.5315,0.183289881548746,1.85788457771756E-5,1,1.99850670813958,40.0298881530762,1.99361243062714,7.19999987632036,1.96012054178392,0.34096073242344,25,0.00024271470584722,0.18328456646378,0.00036069533584764,300.0016479,300.0016479,133061.016,133070.047,52.697394766544,18.5114304014299,31.733112,0,0,0,80,4977,299.8154,133065.5315,,,,,,,,,,,,,0,,,,6.7844644,,,,,,300.0016479,,,,
,33645295.595,299.99523925,125946.8045,0.173631859698108,1.46593113221025E-5,1,1.99850670813958,40.0298881530762,2.00764203189609,7.2099999524653,1.86944217451217,0.324741074193117,25,0.00018947057414704,0.173626866779869,0.000301458013197297,299.9951782,299.9953003,125900.336,125993.273,53.4891844565249,18.5284138124003,31.351902,0,0,0,80,4977,299.819,125946.8045,,,,,,,,,,,,,0,,,,6.7844644,,,,,,299.99523925,,,,
,33645407.23,299.9901581,120398.711,0.166004983999149,1.61934830526754E-5,1,1.99850670813958,40.0298881530762,2.00783718338632,7.2099999524653,1.78751470277415,0.31037748203235,25,0.00016909241817277,0.166000231142343,0.000276320535834778,299.989502,299.9908142,120347.445,120449.977,53.005356403121,18.5343562258729,31.733112,0,0,0,80,4977,299.8344,120398.711,,,,,,,,,,,,,0,,,,6.7844644,,,,,,299.9901581,,,,
,33645521.5,299.9867249,114723.926,0.1582203347969,1.71108562973533E-5,1,1.99850670813958,40.0298881530762,2.00772747326413,7.2099999524653,1.70358903511234,0.295880249918196,25,0.00016779351382374,0.15821580383643,0.000270152410073394,299.9867249,299.9867249,114718.844,114729.008,52.8904570107941,18.5307001973737,31.733112,0,0,0,80,4977,299.83755,114723.926,,,,,,,,,,,,,0,,,,6.818522,,,,,,299.9867249,,,,
,33645629.04,299.99028015,109381.039,0.150853148132344,1.55831659483945E-5,1,1.99850670813958,40.0298881530762,2.00781329975501,7.2099999524653,1.62433217137719,0.282110031949385,25,0.00015940910323519,0.15084879928012,0.000257136643312452,299.9901123,299.990448,109329.492,109432.586,53.0366215438902,18.5295509720425,31.351902,0,0,0,80,4977,299.8599,109381.039,,,,,,,,,,,,,0,,,,6.7844644,,,,,,299.99028015,,,,
,33645734.32,299.9894714,104147.75,0.143778911302888,1.55143547405848E-5,1,1.99850670813958,40.0298881530762,2.00750365242305,7.2099999524653,1.54791626026888,0.268922479840201,25,0.000159396029698616,0.143774753935933,0.000252667768767699,299.9894714,299.9894714,104147.75,104147.75,53.0686683131787,18.5282142178032,31.733112,0,0,0,80,4977,299.87495,104147.75,,,,,,,,,,,,,0,,,,6.818522,,,,,,299.9894714,,,,
,33645871.57,299.99368285,97315.441,0.134245751954663,1.40590032824077E-5,1,1.99850670813958,40.0298881530762,1.99366242974955,7.18999980017543,1.43569109124264,0.249621578292332,25,0.000166475913154771,0.134241826405072,0.000253721663006759,299.9932556,299.9941101,97258.523,97372.359,53.3586524938133,18.522290469681,31.351902,0,0,0,80,4977,299.87955,97315.441,,,,,,,,,,,,,0,,,,6.818522,,,,,,299.99368285,,,,
,33645976.905,299.9873047,92078.0545,0.127008223894955,1.28444912154327E-5,1,1.99850670813958,40.0298881530762,1.9937641261208,7.18999980017543,1.35837410724422,0.236070547937224,25,0.000147587267922844,0.127004532757939,0.000230238092424684,299.9872437,299.9873657,92036.109,92120,53.3352036382364,18.5282735619497,31.733112,0,0,0,80,4977,299.90115,92078.0545,,,,,,,,,,,,,0,,,,6.818522,,,,,,299.9873047,,,,
,33646072.645,299.9951477,87324.9415,0.120433845109982,1.37988796968563E-5,1,1.99850670813958,40.0298881530762,1.99374600328227,7.18999980017543,1.28804194323948,0.223885991343866,25,0.00014333351422288,0.120430303543468,0.000221805512224884,299.9950867,299.9952087,87273.531,87376.352,53.5196679687749,18.5233230199556,31.733112,0,0,0,80,4977,299.89705,87324.9415,,,,,,,,,,,,,0,,,,6.8525796,,,,,,299.9951477,,,,
,33646170.945,299.98706055,82435.121,0.113737761144126,9.80204788366846E-6,1,1.99850670813958,40.0298881530762,1.99387482833197,7.18999980017543,1.21649716417207,0.211484147066156,25,0.000138361484490245,0.113734436260607,0.000212557705264168,299.9866028,299.9875183,82384.422,82485.82,53.3086282685826,18.5228666711507,31.351902,0,0,0,80,4977,299.92315,82435.121,,,,,,,,,,,,,0,,,,6.8525796,,,,,,299.98706055,,,,
,33646268.31,299.9941101,77587.668,0.107030949951247,1.1631396846E-5,1,1.99850670813958,40.0298881530762,1.99376463041597,7.18999980017543,1.1447022482585,0.199004563093337,25,0.000130272691996829,0.107027788985847,0.000200180955342178,299.9938354,299.9943848,77528.633,77646.703,53.0452194576018,18.524802018312,31.733112,0,0,0,80,4977,299.92435,77587.668,,,,,,,,,,,,,0,,,,6.8525796,,,,,,299.9941101,,,,
,33646366.335,299.9925537,72711.406,0.10032515551205,1.03650261831181E-5,1,1.99850670813958,40.0298881530762,1.99388687264392,7.18999980017543,1.07306079939518,0.186464374025054,25,0.000114276752936049,0.100322195555306,0.000179885017368375,299.9919128,299.9931946,72655.906,72766.906,53.1038415965441,18.5286756642147,31.733112,0,0,0,80,4977,299.9323,72711.406,,,,,,,,,,,,,0,,,,6.8525796,,,,,,299.9925537,,,,
,33646498.34,299.99655155,66139.664,0.0913434674555273,9.31570234307814E-6,1,1.99850670813958,40.0298881530762,2.00796330118729,7.18000018969178,0.983641752695297,0.170724932132199,25,8.58117226761431E-5,0.0913407640184615,0.000145643225406561,299.9963074,299.9967957,66088.68,66190.648,53.0397480579671,18.5395142571401,31.351902,0,0,0,80,4977,299.94365,66139.664,,,,,,,,,,,,,0,,,,6.8525796,,,,,,299.99655155,,,,
,33646594.685,299.99235535,61345.457,0.0847557605112015,8.71434143908898E-6,1,1.99850670813958,40.0298881530762,2.00789861430836,7.18000018969178,0.912650846701149,0.158536897466581,25,9.15871102658617E-5,0.0847532497371017,0.000147168717277789,299.9920349,299.9926758,61288.258,61402.656,53.3531810941787,18.5368558032013,31.733112,0,0,0,80,4977,299.9463,61345.457,,,,,,,,,,,,,0,,,,6.88697935,,,,,,299.99235535,,,,
,33646692.32,299.9851685,56486.9845,0.0781111746628567,8.61269079516021E-6,1,1.99850670813958,40.0298881530762,1.99376376127564,7.18000018969178,0.835408500229337,0.145202777342315,25,9.19457119515593E-5,0.0781088688008768,0.000143225319840939,299.9851685,299.9851685,56477.383,56496.586,53.310191525621,18.5240697284355,31.733112,0,0,0,80,4977,299.97265,56486.9845,,,,,,,,,,,,,0,,,,6.88697935,,,,,,299.9851685,,,,
,33646788.065,299.9880981,51723.9825,0.071542684613501,9.02288376011903E-6,1,1.99850670813958,40.0298881530762,1.99377372367724,7.18000018969178,0.765175156046649,0.132912486315996,25,7.66294733054312E-5,0.0715405662338838,0.000123648737511114,299.9880981,299.9880981,51719.887,51728.078,53.2656387000249,18.5259808040755,31.733112,0,0,0,80,4977,299.98475,51723.9825,,,,,,,,,,,,,0,,,,6.9213791,,,,,,299.9880981,,,,
,33646879.14,299.9976654,47188.6405,0.0652245575784149,7.81225852141172E-6,1,1.99850670813958,40.0298881530762,1.9938157486375,7.18000018969178,0.697609547401263,0.121204723950801,25,7.24040856449274E-5,0.0652226003343711,0.000115317453100506,299.9975586,299.9977722,47138.363,47238.918,53.2625121859479,18.5291962828858,31.733112,0,0,0,80,4977,299.9812,47188.6405,,,,,,,,,,,,,0,,,,6.88697935,,,,,,299.9976654,,,,
,33646968.185,299.9923248,42756.258,0.0590302956143394,7.23676409768999E-6,1,1.99850670813958,40.0298881530762,1.99398160189415,7.18000018969178,0.631405410901637,0.109725144472493,25,6.75710057252406E-5,0.0590285296767391,0.000106445990092508,299.9915466,299.993103,42709.934,42802.582,53.1530841932556,18.5331318654658,31.733112,0,0,0,80,4977,300.0006,42756.258,,,,,,,,,,,,,0,,,,6.9213791,,,,,,299.9923248,,,,
,33647093.92,299.9949036,36485.332,0.0503633452893329,7.3580180003647E-6,1,1.99850670813958,40.0298881530762,1.98313839959645,7.16000003740191,0.535875766638521,0.0932049445208521,25,6.49810460620152E-5,0.0503618254227906,9.81943888545702E-5,299.994751,299.9950562,36437.879,36532.785,53.8323193764672,18.5372573900116,31.733112,0,0,0,80,4977,300.0076,36485.332,,,,,,,,,,,,,0,,,,6.9213791,,,,,,299.9949036,,,,
,33647183.77,299.98725895,32008.3135,0.0441737889144822,6.04051700500673E-6,1,1.99850670813958,40.0298881530762,1.9830374850088,7.16000003740191,0.469999861210525,0.0817170086357323,25,5.42185080959019E-5,0.0441724660023311,8.33778141328837E-5,299.9872437,299.9872742,31961.143,32055.484,53.5829798788326,18.5296764089033,31.733112,0,0,0,80,4977,300.01685,32008.3135,,,,,,,,,,,,,0,,,,6.9213791,,,,,,299.98725895,,,,
,33647278.09,299.9951477,27310.9715,0.0377195068750983,5.10849082030696E-6,1,1.99850670813958,40.0298881530762,1.98309278797713,7.16000003740191,0.401220873095213,0.0697427760755685,2.5,4.48197843487756E-5,0.0377183663411852,6.97441820311162E-5,299.9948425,299.9954529,27263.236,27358.707,53.0381848009287,18.5394048374377,31.733112,0,0,0,80,4977,300.01205,27310.9715,,,,,,,,,,,,,0,,,,6.9213791,,,,,,299.9951477,,,,
,33647367.86,299.99409485,22827.0235,0.0315123091318003,4.83996177385928E-6,1,1.99850670813958,40.0298881530762,1.98302257360343,7.16000003740191,0.335186606894961,0.0582472884137754,2.5,3.58746433659884E-5,0.0315113566543299,5.67165574161117E-5,299.993927,299.9942627,22789.881,22864.166,53.4516662876018,18.5344597771077,31.733112,0,0,0,80,4977,300.01585,22827.0235,,,,,,,,,,,,,0,,,,6.9213791,,,,,,299.99409485,,,,
,33647458.415,299.98872375,18297.705,0.02529097205608,4.98774079589017E-6,1,1.99850670813958,40.0298881530762,1.98289625692132,7.16000003740191,0.268994901636577,0.0467499353786399,2.5,2.92491984760341E-5,0.0252902104537004,4.5989907004306E-5,299.988678,299.9887695,18245.873,18349.537,52.8904570107941,18.5385699209547,31.733112,0,0,0,80,4977,300.0402,18297.705,,,,,,,,,,,,,0,,,,6.9213791,,,,,,299.98872375,,,,
,33647549.78,299.99240115,13701.3455,0.0188921571302213,7.08287637301301E-5,1,1.99850670813958,40.0298881530762,1.98304416191088,7.17000011354685,0.200947902722773,0.0349447672856806,2.5,2.37592561889943E-5,0.0188915837385302,3.62751475009806E-5,299.9914551,299.9933472,13653.34,13749.351,53.0874273976402,18.538259399372,31.351902,0,0,0,80,4977,300.04325,13701.3455,,,,,,,,,,,,,0,,,,6.9213791,,,,,,299.99240115,,,,
,33647687.405,299.9980469,6740.597,0.00918092600822941,0.000467150538842399,1,1.99850670813958,40.0298881530762,1.9938901317831,7.14999996125698,0.0983718079479779,0.0158795433613099,2.5,-9.98725728034049E-5,0.00918071893074237,-9.37796354231353E-5,299.9973755,299.9987183,6715.472,6765.722,53.1546474502941,18.5362837776513,31.733112,0,0,0,80,4977,300.04355,6740.597,,,,,,,,,,,,,0,,,,6.95612405,,,,,,299.9980469,,,,
,33647790.885,299.9967957,1419.9615,0.00195997473943285,5.07139704602354E-6,1,1.99850670813958,40.0298881530762,1.99385504229074,7.14999996125698,0.0209649349633709,0.00363278815970365,0.25,1.28200972958007E-6,0.00195991553036672,2.58303539260496E-6,299.9967957,299.9967957,1410.031,1429.892,53.6963160141211,18.5394075677094,31.351902,0,0,0,80,4977,300.0498,1419.9615,,,,,,,,,,,,,0,,,,6.95612405,,,,,,299.9967957,,,,
,33648033.23,300.0003204,-5081.474,-0.00671335115186873,0.000704175654244892,1,1.99850670813958,40.0298881530762,1.99402547484264,7.14999996125698,-0.0717981747023402,-0.0124160930115198,2.5,-2.12022662594742E-6,-0.00671314930452521,-6.57427664035607E-6,300.0002441,300.0003967,-5106.755,-5056.193,53.4680804865057,18.5449494229337,31.733112,0,0,0,80,4961,300.05445,-5081.474,,,,,,,,,,,,,0,,,,6.990869,,,,,,300.0003204,,,,
,33648149.04,300.0013733,-10500.2905,-0.0146036685051216,4.47357359134692E-6,1,1.99850670813958,40.0298881530762,1.99383308170176,7.14999996125698,-0.156142574221286,-0.0271615813251322,2.5,-1.91272461664987E-5,-0.0146032200730707,-2.88073131456271E-5,300.0011902,300.0015564,-10545.06,-10455.521,53.4305623175826,18.5378812796565,31.733112,0,0,0,80,4961,300.0505,-10500.2905,,,,,,,,,,,,,0,,,,6.990869,,,,,,300.0013733,,,,
,33648239.055,300.0055542,-14726.653,-0.0203667347991639,0.000353748499065025,1,1.99850670813958,40.0298881530762,1.99386192571149,7.14999996125698,-0.217969933095605,-0.0366897994455386,2.5,8.46904347417303E-5,-0.0203661813421145,7.11969217520863E-5,300.0054321,300.0056763,-14772.411,-14680.895,53.1632453640056,18.5391678035026,31.733112,0,0,0,80,4961,300.04305,-14726.653,,,,,,,,,,,,,0,,,,6.990869,,,,,,300.0055542,,,,
,33648361.015,300.00793455,-20523.211,-0.0283803419196625,4.74584358299006E-6,1,1.99850670813958,40.0298881530762,1.98314099797672,7.16000003740191,-0.301887146705929,-0.0524777681677057,2.5,-3.38643036073884E-5,-0.0283794698376295,-5.26414741435062E-5,300.0072937,300.0085754,-20566.57,-20479.852,52.4269512988902,18.5445756677194,31.733112,0,0,0,80,4961,300.04225,-20523.211,,,,,,,,,,,,,0,,,,7.02596305,,,,,,300.00793455,,,,
,33648451.305,300.004364,-24817.119,-0.0342738579819807,5.18459858370505E-6,1,1.99850670813958,40.0298881530762,1.98328573964035,7.16000003740191,-0.364602461974308,-0.0633842134948297,2.5,-4.13248997550625E-5,-0.0342728101318832,-6.39829208215666E-5,300.0042419,300.0044861,-24862.314,-24771.924,53.2742366137364,18.5474247926264,31.733112,0,0,0,80,4961,300.027,-24817.119,,,,,,,,,,,,,0,,,,6.990869,,,,,,300.004364,,,,
,33648541.41,300.0070648,-29119.59,-0.0401848391030966,4.85554312604127E-6,1,1.99850670813958,40.0298881530762,1.98329212968865,7.14999996125698,-0.427492383904633,-0.0742690330255696,2.5,-4.40710363216477E-5,-0.0401836120132562,-7.06141088005373E-5,300.007019,300.0071106,-29172.41,-29066.77,52.802132988121,18.547152168325,31.733112,0,0,0,80,4961,300.0145,-29119.59,,,,,,,,,,,,,0,,,,7.02596305,,,,,,300.0070648,,,,
,33648634.835,300.00428775,-33576.5625,-0.046373483904719,5.57385844972282E-6,1,1.99850670813958,40.0298881530762,1.98312180166342,7.14999996125698,-0.493272232791749,-0.085788302256093,2.5,-5.92119184748433E-5,-0.0463720691748549,-8.98126517513466E-5,300.0040894,300.0044861,-33629.949,-33523.176,53.2703284711402,18.547816923775,31.733112,0,0,0,80,4961,300.01675,-33576.5625,,,,,,,,,,,,,0,,,,7.02596305,,,,,,300.00428775,,,,
,33648727.38,300.0098114,-37996.1015,-0.0524229771638446,4.99308325765429E-6,1,1.99850670813958,40.0298881530762,1.98318407717521,7.14999996125698,-0.557646836184621,-0.0969260776305372,2.5,-6.16732727141585E-5,-0.0524213751102099,-9.62323199292507E-5,300.0097351,300.0098877,-38045.109,-37947.094,52.8568469844671,18.5444415044442,31.733112,0,0,0,80,4961,300.01495,-37996.1015,,,,,,,,,,,,,0,,,,7.02596305,,,,,,300.0098114,,,,
,33648817.065,300.00549315,-42278.9275,-0.0583433984457638,6.42627229509102E-6,1,1.99850670813958,40.0298881530762,1.98331427500368,7.14999996125698,-0.620657043568727,-0.107921132225729,2.5,-7.26051045946412E-5,-0.0583416241773045,-0.000111031402126749,300.0054321,300.0055542,-42326.945,-42230.91,53.0030115175633,18.5496001563692,31.351902,0,0,0,80,4961,300.00275,-42278.9275,,,,,,,,,,,,,0,,,,7.02596305,,,,,,300.00549315,,,,
,33648943.525,300.00543215,-48321.0725,-0.0666349391039196,6.00281998945014E-6,1,1.99850670813958,40.0298881530762,1.98326129687372,7.16000003740191,-0.708842246617406,-0.123267384959958,2.5,-8.41172895938378E-5,-0.0666329174604871,-0.000127944654130202,300.0052185,300.0056458,-48365.418,-48276.727,52.8537204703902,18.5458072843934,31.351902,0,0,0,80,4961,299.99255,-48321.0725,,,,,,,,,,,,,0,,,,7.0610571,,,,,,300.00543215,,,,
,33654022.305,50.0008392,610.016,0.265526896526479,0.000292075552337541,1,1.99850670813958,40.0298881530762,1.98117267073325,8.34999978542328,2.81295123861463,0.524287359406907,25,0.00174443152325251,0.265164245383334,0.0037155671544817,50.0008392,50.0008392,604.931,615.101,52.0361370392747,18.5071829263378,31.733112,0,0,0,80,4961,49.8943,610.016,,,,,,,,,,,,,0,,,,4.1170726,,,,,,50.0008392,,,,
,33654143.31,50.00070385,6433.7965,0.308788977529306,0.000602128661851229,1,1.99850670813958,40.0298881530762,1.98120021164438,8.34999978542328,3.27426480790408,0.598012344319807,25,0.000910153906834728,0.308453620013664,0.00320539855269096,50.0006638,50.0007439,6429.419,6438.174,52.5535751190056,18.5184758124515,32.114323,0,0,0,80,4961,49.89465,6433.7965,,,,,,,,,,,,,0,,,,4.1170726,,,,,,50.00070385,,,,
,33654264.805,50.00060655,12182.941,0.336479253249911,2.83288289261646E-5,1,1.99850670813958,40.0298881530762,1.9812996312545,8.34999978542328,3.56708081767017,0.663212637370899,25,0.00206391451740824,0.336206329968048,0.00456234061650591,50.0005608,50.0006523,12134.073,12231.809,52.6145421435056,18.5172037861317,31.733112,0,0,0,80,4961,49.89665,12182.941,,,,,,,,,,,,,0,,,,4.0966103,,,,,,50.00060655,,,,
,33654383.015,50.00025175,17832.7665,0.363586791159829,9.210813160664E-5,1,1.99850670813958,40.0298881530762,1.98109719645654,8.34000017493963,3.85513466208727,0.717510614859232,25,0.00230555096363442,0.363403421688289,0.00499896190843153,50.0002441,50.0002594,17775.992,17889.541,52.5395058056594,18.5194483007226,31.733112,0,0,0,80,4961,49.8948,17832.7665,,,,,,,,,,,,,0,,,,4.076148,,,,,,50.00025175,,,,
,33654504.845,50.00156785,23686.9955,0.391536494842208,3.81358958211113E-5,1,1.99850670813958,40.0298881530762,1.98122759370224,8.34000017493963,4.15311619379406,0.772885282529194,25,0.00248936595032886,0.391466507152952,0.00537724124695337,50.0013428,50.0017929,23628.102,23745.889,52.731004792871,18.5145440086801,31.733112,0,0,0,80,4961,49.8974,23686.9955,,,,,,,,,,,,,0,,,,4.076148,,,,,,50.00156785,,,,
,33654644.76,50.00315665,30432.201,0.423500965399252,4.55469401601359E-5,1,1.99850670813958,40.0298881530762,1.99198641413696,8.39000009000301,4.51733651070639,0.840189508467884,25,0.0026745719264997,0.423582291404737,0.00577520997806016,50.0030937,50.0032196,30386.867,30477.535,52.5051141508132,18.5210042531092,31.733112,0,0,0,80,4961,49.8911,30432.201,,,,,,,,,,,,,0,,,,4.076148,,,,,,50.00315665,,,,
,33654752.265,50.00280955,35615.9455,0.448028363338578,4.18297254781007E-5,1,1.99850670813958,40.0298881530762,1.99188723674157,8.39999970048666,4.77999516630482,0.889456127299527,25,0.00289275775851623,0.448239191408463,0.00614893159850078,50.002697,50.0029221,35564.395,35667.496,51.9001336769286,18.521804448926,32.495537,0,0,0,80,4961,49.88805,35615.9455,,,,,,,,,,,,,0,,,,4.076148,,,,,,50.00280955,,,,
,33654869.115,50.0032024,41259.393,0.474251137840655,3.42608622472149E-5,1,1.99850670813958,40.0298881530762,1.99202801796882,8.39000009000301,5.06166374637128,0.941533461223512,25,0.0030664516828464,0.474614952177201,0.00648036522262122,50.0030746,50.0033302,41205.723,41313.063,52.6231400572171,18.5280290736905,31.733112,0,0,0,80,4961,49.8868,41259.393,,,,,,,,,,,,,0,,,,4.05588935,,,,,,50.0032024,,,,
,33654984.155,50.0012131,46818.3785,0.499696424567122,4.62289763470032E-5,1,1.99850670813958,40.0298881530762,1.99199295749675,8.39999970048666,5.33465076761697,0.992315926576727,25,0.00327212787219506,0.500220515777503,0.00683029281312689,50.0012131,50.0012131,46809.48,46827.277,52.118208033794,18.5259694764825,31.733112,0,0,0,80,4961,49.88605,46818.3785,,,,,,,,,,,,,0,,,,4.076148,,,,,,50.0012131,,,,
,33655094.205,50.00080105,52128.09,0.524597429377005,5.5069826514538E-5,1,1.99850670813958,40.0298881530762,1.99188854693429,8.39000009000301,5.60169502370586,1.04174204641831,25,0.00345768119714099,0.525283320753977,0.00715006317415231,50.0007095,50.0008926,52078.801,52177.379,52.9459526356594,18.5261694300398,31.733112,0,0,0,80,4961,49.88365,52128.09,,,,,,,,,,,,,0,,,,4.05588935,,,,,,50.00080105,,,,
,33655238.03,50.0022087,59072.6855,0.556220346475344,3.72359359957227E-5,1,1.99850670813958,40.0298881530762,1.98089459711706,8.41000024229288,5.90981230662639,1.09897611472697,25,0.00372781092181352,0.557126991115375,0.00757747862596064,50.00214,50.0022774,59019.441,59125.93,52.7403843351017,18.5224494494641,31.733112,0,0,0,80,4961,49.8856,59072.6855,,,,,,,,,,,,,0,,,,4.0356307,,,,,,50.0022087,,,,
,33655348.405,50.0013466,64388.6035,0.580199563370102,3.95751031112019E-5,1,1.99850670813958,40.0298881530762,1.98097886131038,8.41000024229288,6.1663234137995,1.14644160059255,25,0.00392470668832881,0.581281252398394,0.00788460471795896,50.0012398,50.0014534,64338.75,64438.457,52.5848402597748,18.5268255373161,31.733112,0,0,0,80,4961,49.8879,64388.6035,,,,,,,,,,,,,0,,,,4.0356307,,,,,,50.0013466,,,,
,33655467.68,50.0008583,70140.078,0.605591972496843,6.25104125947912E-5,1,1.99850670813958,40.0298881530762,1.98090487555939,8.41999985277653,6.43749629517583,1.1968742057431,25,0.00416531800600321,0.606865944344544,0.00823311637768507,50.0008583,50.0008583,70130.898,70149.258,54.0488304762942,18.5232716715173,31.733112,0,0,0,80,4961,49.88185,70140.078,,,,,,,,,,,,,0,,,,4.0155734,,,,,,50.0008583,,,,
,33655564.895,50.0014801,74825.4065,0.626614096070594,5.01536274612712E-5,1,1.99850670813958,40.0298881530762,1.98084001420695,8.41000024229288,6.66200064834604,1.23856245079526,25,0.00436391486711644,0.628049008438013,0.00851574826932662,50.0013504,50.0016098,74771.172,74879.641,51.9493762736401,18.5249657662649,31.733112,0,0,0,80,4961,49.8827,74825.4065,,,,,,,,,,,,,0,,,,4.0155734,,,,,,50.0014801,,,,
,33655675.505,50.0036964,80144.1485,0.649876422915837,3.86554185931692E-5,1,1.99850670813958,40.0298881530762,1.98094336232743,8.41999985277653,6.91116828509709,1.28420569497032,25,0.00453457457728938,0.651495542802788,0.00877163119842745,50.0036964,50.0036964,80135.672,80152.625,53.7479034963903,18.5239350617842,31.733112,0,0,0,80,4961,49.8818,80144.1485,,,,,,,,,,,,,0,,,,3.9955161,,,,,,50.0036964,,,,
,33655785.635,50.001791,85449.473,0.673388823335909,4.47447188846298E-5,1,1.99850670813958,40.0298881530762,1.98094677679908,8.41000024229288,7.16261705279266,1.33071148023522,25,0.00475281354550532,0.675194347775156,0.00907089296976936,50.0017281,50.0018539,85395.102,85503.844,53.249224501121,18.5264110620958,31.733112,0,0,0,80,4961,49.8793,85449.473,,,,,,,,,,,,,0,,,,3.9955161,,,,,,50.001791,,,,
,33655928.64,50.0026665,92313.2775,0.702590708111974,6.84860058414193E-5,1,1.99850670813958,40.0298881530762,1.98095364529924,8.48000030964613,7.47508604133317,1.38810307784151,25,0.00499989667253468,0.704636962640105,0.00940622895670671,50.002636,50.002697,92250.711,92375.844,52.9092160952556,18.5227172436882,31.733112,0,0,0,80,4961,49.88,92313.2775,,,,,,,,,,,,,0,,,,3.9955161,,,,,,50.0026665,,,,
,33656035.38,50.0024872,97435.1445,0.724667048860924,5.30204130063539E-5,1,1.99850670813958,40.0298881530762,1.98093427930267,8.48000030964613,7.71127106934065,1.43114102691405,25,0.00516026458132599,0.726894810909968,0.00962852740532015,50.0024529,50.0025215,97390.375,97479.914,53.2132695892364,18.5243230867883,31.733112,0,0,0,80,4961,49.87645,97435.1445,,,,,,,,,,,,,0,,,,3.9756581,,,,,,50.0024872,,,,
,33656141.665,50.0014534,102531.7305,0.746077679939172,6.65340981762704E-5,1,1.99850670813958,40.0298881530762,1.98121547995381,8.48999992012978,7.94147675233305,1.47336447634433,25,0.00534710672690876,0.74848502012464,0.00986889373792248,50.0013275,50.0015793,102487.102,102576.359,52.8044778736787,18.5263485088137,31.733112,0,0,0,80,4961,49.87675,102531.7305,,,,,,,,,,,,,0,,,,3.9756581,,,,,,50.0014534,,,,
,33656249.34,50.00035855,107696.8165,0.767547625462476,6.5800243130466E-5,1,1.99850670813958,40.0298881530762,1.98103873655462,8.48000030964613,8.17040822846041,1.51634479035209,25,0.00562983019487991,0.770135770607647,0.0102005843400239,50.0003471,50.00037,107637.5,107756.133,52.7966615884864,18.516994926266,31.733112,0,0,0,80,4961,49.87515,107696.8165,,,,,,,,,,,,,0,,,,3.9955161,,,,,,50.00035855,,,,
,33656356.045,50.00232125,112799.332,0.788515010941603,5.86520127979599E-5,1,1.99850670813958,40.0298881530762,1.98100907480257,8.48000030964613,8.39479427249842,1.55696807821952,25,0.00577425757254248,0.791281560106322,0.0103876593425142,50.0023079,50.0023346,112747.5,112851.164,53.310191525621,18.5250927364499,31.733112,0,0,0,80,4961,49.8714,112799.332,,,,,,,,,,,,,0,,,,3.9955161,,,,,,50.00232125,,,,
,33656499.96,50.0012627,119678.672,0.816360473077186,5.60407271055665E-5,1,1.99850670813958,40.0298881530762,1.98103391052442,8.53999983519316,8.69286128951282,1.61212345932027,25,0.00608170283901749,0.819365088095673,0.0107447919274152,50.0012627,50.0012627,119669.492,119687.852,53.6165899051595,18.523568473585,31.733112,0,0,0,80,4961,49.86895,119678.672,,,,,,,,,,,,,0,,,,3.9756581,,,,,,50.0012627,,,,
,33656611.75,50.0027733,125013.375,0.837925919871403,6.26826279066743E-5,1,1.99850670813958,40.0298881530762,1.98100161014369,8.53000022470951,8.92364468515492,1.65388990409145,25,0.00623890451462989,0.841115036700427,0.0109358454790112,50.0027733,50.0027733,125004.055,125022.695,53.1061864821018,18.5281486590932,31.733112,0,0,0,80,4961,49.8705,125013.375,,,,,,,,,,,,,0,,,,3.9558001,,,,,,50.0027733,,,,
,33656724.54,50.0011711,130388.324,0.858939828443143,6.77518208528946E-5,1,1.99850670813958,40.0298881530762,1.98115933618706,8.53000022470951,9.14922902546483,1.69562438120505,25,0.00648039907317373,0.862310814649369,0.0112046022979962,50.0011711,50.0011711,130383.242,130393.406,52.5293446349094,18.5219149967789,31.733112,0,0,0,80,4961,49.8711,130388.324,,,,,,,,,,,,,0,,,,3.9558001,,,,,,50.0011711,,,,
,33656832.735,50.00200655,135540.0005,0.879494798854784,3.3315348229233E-5,1,1.99850670813958,40.0298881530762,1.98081919067872,8.53999983519316,9.36762317085471,1.73613731755133,25,0.00672730219609969,0.88304054456965,0.0114774220089328,50.0019455,50.0020676,135491.563,135588.438,52.8341797574094,18.5196836934405,31.733112,0,0,0,80,4961,49.86615,135540.0005,,,,,,,,,,,,,0,,,,3.9558001,,,,,,50.00200655,,,,
,33656960.19,50.0008259,139699,0.896004293924464,7.70739308223473E-5,1,1.99850670813958,40.0298881530762,1.98111972407073,8.53999983519316,9.54579439997351,1.76826832531668,25,0.00684452542111316,0.899690830102047,0.0116127109081606,50.0006523,50.0009995,139645.75,139752.25,53.2945589552364,18.5209807637648,31.733112,0,0,0,80,4977,49.8669,139699,,,,,,,,,,,,,0,,,,3.9558001,,,,,,50.0008259,,,,
,33657099.595,49.9988823,132689.9925,0.86869333930984,6.22199158532308E-5,1,1.99850670813958,40.0298881530762,1.98109328922475,8.55999998748302,9.25323585407447,1.71511383104505,25,0.00661257965809139,0.872144689949313,0.01135187417045,49.9987869,49.9989777,132628.844,132751.141,52.9662749771594,18.5215314005253,31.733112,0,0,0,80,4977,49.8688,132689.9925,,,,,,,,,,,,,0,,,,3.9558001,,,,,,49.9988823,,,,
,33657213.47,49.9968109,127041.1955,0.84639940834113,7.74139681845553E-5,1,1.99850670813958,40.0298881530762,1.98109689309106,8.55999998748302,9.0144878929995,1.67201829301041,25,0.00645351841384617,0.849658678891056,0.0111646489778669,49.9968109,49.9968109,127031.875,127050.516,53.5274842539672,18.5226781897769,31.733112,0,0,0,80,4977,49.86965,127041.1955,,,,,,,,,,,,,0,,,,3.9558001,,,,,,49.9968109,,,,
,33657329.22,49.9972782,121288.3165,0.823488690189562,7.03793207522864E-5,1,1.99850670813958,40.0298881530762,1.98083624605409,8.55000037699938,8.76832133432494,1.62577285809305,25,0.00613050379783222,0.826551519254774,0.0108075904906926,49.9971466,49.9974098,121281.25,121295.383,52.5309078919479,18.5336029741097,31.351902,0,0,0,80,4977,49.87155,121288.3165,,,,,,,,,,,,,0,,,,3.9558001,,,,,,49.9972782,,,,
,33657443.955,49.99690435,115583.035,0.800227176662747,7.02698965079779E-5,1,1.99850670813958,40.0298881530762,1.98081779843382,8.55999998748302,8.51922872076654,1.58048011937623,25,0.00594547163331362,0.803091842891311,0.0105822039140707,49.996788,49.9970207,115518.211,115647.859,52.9146874948902,18.526466631078,31.733112,0,0,0,80,4977,49.8761,115583.035,,,,,,,,,,,,,0,,,,3.9361396,,,,,,49.99690435,,,,
,33657563.05,49.997015,109663.5,0.776174215838519,6.49091887370097E-5,1,1.99850670813958,40.0298881530762,1.98105756319384,8.55999998748302,8.26287422078418,1.53281469672604,25,0.00566234726338498,0.778833580538374,0.0102528278728232,49.9969406,49.9970894,109654.039,109672.961,53.2562591577941,18.5329007180821,31.733112,0,0,0,80,4977,49.88015,109663.5,,,,,,,,,,,,,0,,,,3.9558001,,,,,,49.997015,,,,
,33657710.005,49.99765205,102359.348,0.745620433135692,7.11263576843386E-5,1,1.99850670813958,40.0298881530762,1.980903140301,8.55000037699938,7.93512959743172,1.4736004932628,25,0.00546984645506747,0.748022233792459,0.00999163147740555,49.9975433,49.9977608,102299.891,102418.805,53.3359852667556,18.5280704246315,31.733112,0,0,0,80,4977,49.88335,102359.348,,,,,,,,,,,,,0,,,,3.9558001,,,,,,49.99765205,,,,
,33657819.075,49.9970856,96935.25,0.72298152695368,6.40470725575677E-5,1,1.99850670813958,40.0298881530762,1.9809962140105,8.55999998748302,7.69339461813393,1.4281795374556,25,0.00517350049273342,0.725193528631536,0.00963845698159277,49.9969597,49.9972115,96920.984,96949.516,52.1611976023517,18.5329555412354,31.733112,0,0,0,80,4977,49.88685,96935.25,,,,,,,,,,,,,0,,,,3.9164791,,,,,,49.9970856,,,,
,33657929.885,49.99723245,91427.121,0.69921795480775,6.13840130536953E-5,1,1.99850670813958,40.0298881530762,1.98089493218111,8.55999998748302,7.43880647465424,1.38121820037785,25,0.00494968592957972,0.701234714372947,0.00934733595474179,49.9971466,49.9973183,91367.242,91487,52.3394089047363,18.5289136625765,30.589479,0,0,0,80,4977,49.88525,91427.121,,,,,,,,,,,,,0,,,,3.9164791,,,,,,49.99723245,,,,
,33658041.22,49.99552725,85890.6055,0.675694331016648,5.77186717584225E-5,1,1.99850670813958,40.0298881530762,1.98101573207988,8.55000037699938,7.18752628674944,1.33518412957908,25,0.00476171240605248,0.677517370052035,0.00908796397099368,49.9950943,49.9959602,85834.961,85946.25,52.8568469844671,18.5315153815343,31.733112,0,0,0,80,4977,49.8907,85890.6055,,,,,,,,,,,,,0,,,,3.9164791,,,,,,49.99552725,,,,
,33658148.29,49.99701115,80568.762,0.652310662049093,5.72567074775582E-5,1,1.99850670813958,40.0298881530762,1.98101553799444,8.55000037699938,6.93745430546642,1.28887693971964,25,0.00453848242234315,0.65394722268609,0.00878521782716793,49.9969482,49.9970741,80518.766,80618.758,53.6142450196018,18.5333427315513,31.351902,0,0,0,80,4977,49.8952,80568.762,,,,,,,,,,,,,0,,,,3.9164791,,,,,,49.99701115,,,,
,33658258.9,49.9973736,75057.945,0.628229083749747,4.78540447430825E-5,1,1.99850670813958,40.0298881530762,1.9810435812288,8.55000037699938,6.67998575026626,1.24142643804557,25,0.00433512434554107,0.629674852604701,0.00849407705808567,49.997303,49.9974442,74997.781,75118.109,52.6458072842748,18.5367163107004,31.733112,0,0,0,80,4977,49.8972,75057.945,,,,,,,,,,,,,0,,,,3.9164791,,,,,,49.9973736,,,,
,33658403.77,49.99728585,67857.172,0.596671776604326,5.24329166325002E-5,1,1.99850670813958,40.0298881530762,2.00615113657809,8.58000013977289,6.41981256548974,1.19251853816386,25,0.00398194167448881,0.597873084639949,0.00801496635344103,49.9972,49.9973717,67845.875,67868.469,52.5778056031017,18.5338099384992,31.733112,0,0,0,80,4977,49.8981,67857.172,,,,,,,,,,,,,0,,,,3.9164791,,,,,,49.99728585,,,,
,33658518.465,49.9960251,62144.68,0.570810531314488,5.09050883436756E-5,1,1.99850670813958,40.0298881530762,2.00597515058985,8.58000013977289,6.13949256275923,1.14081788858499,25,0.00378047700706971,0.571820902825526,0.00769907530688487,49.9960251,49.9960251,62130.555,62158.805,52.6379909990825,18.5363408577057,31.733112,0,0,0,80,4977,49.90225,62144.68,,,,,,,,,,,,,0,,,,3.9164791,,,,,,49.9960251,,,,
,33658635.51,49.9964695,56325.414,0.544569590255102,5.46532563449011E-5,1,1.99850670813958,40.0298881530762,2.0059974152905,8.58000013977289,5.85589656748441,1.08749537031658,25,0.00349280711386205,0.545391786323391,0.0072868839232834,49.9964371,49.9965019,56316.375,56334.453,52.4902632089479,18.5405825503579,31.733112,0,0,0,80,4977,49.90455,56325.414,,,,,,,,,,,,,0,,,,3.9164791,,,,,,49.9964695,,,,
,33658754.06,49.9970512,50419.295,0.517280356794558,4.22664041650112E-5,1,1.99850670813958,40.0298881530762,2.00607302865301,8.58000013977289,5.56099007085471,1.03338461877761,25,0.00332474641773281,0.517916989694685,0.00697888205892826,49.9970512,49.9970512,50401.922,50436.668,52.473849010044,18.5407578360386,31.733112,0,0,0,80,4977,49.90725,50419.295,,,,,,,,,,,,,0,,,,3.8970139,,,,,,49.9970512,,,,
,33658879.665,49.9964066,44169.414,0.488300638689433,5.75144330558882E-5,1,1.99850670813958,40.0298881530762,2.00601520651585,8.58000013977289,5.24772847763259,0.974905000650358,25,0.00306690519669042,0.488751063079451,0.00656183093243504,49.9964066,49.9964066,44158.117,44180.711,52.8162023014671,18.5393778503475,31.733112,0,0,0,80,4977,49.9101,44169.414,,,,,,,,,,,,,0,,,,3.8970139,,,,,,49.9964066,,,,
,33659041.025,49.9978409,36128.8655,0.451105153698936,4.28901996699168E-5,1,1.99850670813958,40.0298881530762,2.00592091815923,8.58000013977289,4.84559761734806,0.901097985723851,25,0.00286512303477536,0.451332605276761,0.00614045841563866,49.9978409,49.9978409,36110.504,36147.227,52.8568469844671,18.5371727054914,32.495537,0,0,0,80,4977,49.91215,36128.8655,,,,,,,,,,,,,0,,,,3.8775487,,,,,,49.9978409,,,,
,33659169.105,49.9975395,29747.7705,0.420914159797363,3.92224783933988E-5,1,1.99850670813958,40.0298881530762,2.00626148861735,8.58000013977289,4.5204580256016,0.840742073225862,25,0.00265319382559204,0.42098133100082,0.00573722592010705,49.9975395,49.9975395,29738.166,29757.375,52.5269997493517,18.5370729942932,31.733112,0,0,0,80,4977,49.9109,29747.7705,,,,,,,,,,,,,0,,,,3.8775487,,,,,,49.9975395,,,,
,33659289.305,49.99779895,23748.6975,0.392067766563115,4.58843496059123E-5,1,1.99850670813958,40.0298881530762,2.00604562920228,8.58999975025654,4.20902351580855,0.7817450665835,25,0.0023540999837062,0.392001817239037,0.00524553510163135,49.9976578,49.9979401,23693.758,23803.637,52.7747759899479,18.5468076155613,31.733112,0,0,0,80,4977,49.9144,23748.6975,,,,,,,,,,,,,0,,,,3.8775487,,,,,,49.99779895,,,,
,33659402.835,49.9975777,18071.1695,0.365284585854826,3.88138497963197E-5,1,1.99850670813958,40.0298881530762,2.00606750862797,8.58000013977289,3.92037184499261,0.727729067541496,25,0.00214371330850939,0.36510853257006,0.00484924180312249,49.9975777,49.9975777,18062.273,18080.066,53.0139543168325,18.5461975311034,31.733112,0,0,0,80,4977,49.915,18071.1695,,,,,,,,,,,,,0,,,,3.8775487,,,,,,49.9975777,,,,
touchdown = 5.21000009030104 mm,33659543.15,49.9989433,10997.485,0.330899252245238,2.99105375552071E-5,1,1.99850670813958,40.0298881530762,1.98130009465041,8.58999975025654,3.50769368113813,0.652376393345211,25,0.0020475780471147,0.330612093503047,0.00450513902184713,49.9989433,49.9989433,10992.895,11002.075,53.0225522305441,18.5373577655378,31.733112,0,0,0,80,4977,49.92,10997.485,,,,,,,,,,,,,0,,,,3.8775487,,,,,,49.9989433,,,,
,33659648.445,49.9974518,5645.4015,0.304118920400732,3.19077624913431E-5,1,1.99850670813958,40.0298881530762,1.98137250347198,8.58999975025654,3.22305502257249,0.599370894536048,25,0.0018738575260986,0.303772214905685,0.00413328343089976,49.9971924,49.9977112,5580.519,5710.284,52.0814714933901,18.5366192940154,31.351902,0,0,0,80,4977,49.9212,5645.4015,,,,,,,,,,,,,0,,,,3.8775487,,,,,,49.9974518,,,,
,33659776.515,49.99876215,-0.0715,-0.0764211552742575,7.22801637093137E-6,1,1.99850670813958,40.0298881530762,1.98144276338659,8.58999975025654,-0.809518306582636,-0.150493158400042,2.5,-0.000466714059431992,-0.0763164020304124,-0.00103404659702121,49.9986725,49.9988518,-0.1,-0.043,52.7333496784287,18.5436204391021,32.114323,0,0,0,80,4929,49.91815,-0.0715,,,,,,,,,,,,,0,,,,3.8582771,,,,,,49.99876215,,,,
,33659998.58,49.9994926,-5990.877,-0.306220344697652,0.00010153396505084,1,1.99850670813958,40.0298881530762,1.98132079409103,8.58000013977289,-3.24530341008397,-0.603489907426763,25,-0.00188515858166574,-0.305876496931319,-0.00416024088830367,49.9994926,49.9994926,-5999.916,-5981.838,52.5598281471594,18.5398258421016,31.733112,0,0,0,80,4961,49.9225,-5990.877,,,,,,,,,,,,,0,,,,3.8582771,,,,,,49.9994926,,,,
,33660120.32,49.99939725,-11694.8325,-0.334231862352248,3.18179234810545E-5,1,1.99850670813958,40.0298881530762,1.98125637859046,8.58999975025654,-3.54310375211955,-0.65883818554479,25,-0.00205746058957587,-0.333954742816594,-0.0045393955899951,49.9993362,49.9994583,-11743.558,-11646.107,51.9579741873517,18.5414486941044,31.351902,0,0,0,80,4961,49.9245,-11694.8325,,,,,,,,,,,,,0,,,,3.8582771,,,,,,49.99939725,,,,
,33660284.375,49.999733,-19450.2765,-0.370970986554348,3.05299268219378E-5,1,1.99850670813958,40.0298881530762,1.99218049668337,8.60000029206276,-3.95496789092279,-0.735887339388835,25,-0.00233735629416182,-0.370819951573933,-0.00508248809996794,49.999733,49.999733,-19453.949,-19446.604,52.7708678473517,18.5305405184112,31.733112,0,0,0,80,4961,49.9211,-19450.2765,,,,,,,,,,,,,0,,,,3.8390055,,,,,,49.999733,,,,
,33660413.47,50.00086595,-25588.242,-0.400430829062534,2.7079104521615E-5,1,1.99850670813958,40.0298881530762,1.99235070050437,8.60000029206276,-4.27098827600313,-0.79387432054834,25,-0.00246650299515466,-0.400404659331257,-0.00541421703630566,50.0006638,50.0010681,-25641.629,-25534.855,52.585621888294,18.5418931330876,31.733112,0,0,0,80,4961,49.92265,-25588.242,,,,,,,,,,,,,0,,,,3.8582771,,,,,,50.00086595,,,,
,33660542.385,50.0010414,-31741.6865,-0.429364460267605,4.18042380759543E-5,1,1.99850670813958,40.0298881530762,1.99221158707677,8.60000029206276,-4.58071009403808,-0.852127137958385,25,-0.00273170564917306,-0.42948048497036,-0.00586928074387481,50.0010414,50.0010414,-31745.641,-31737.732,52.8083860162748,18.5402716330848,31.733112,0,0,0,80,4961,49.9209,-31741.6865,,,,,,,,,,,,,0,,,,3.8390055,,,,,,50.0010414,,,,
,33660665.435,50.0002136,-37618.59,-0.457593852038301,4.33141641593593E-5,1,1.99850670813958,40.0298881530762,1.99224251335318,8.60000029206276,-4.88347891974192,-0.90849047108,25,-0.00294663185569351,-0.457861450622744,-0.00626082641509389,50.0001907,50.0002365,-37672.539,-37564.641,52.5637362897556,18.5347500248752,31.733112,0,0,0,80,4961,49.9224,-37618.59,,,,,,,,,,,,,0,,,,3.8582771,,,,,,50.0002136,,,,
,33660818.87,50.0018196,-44952.0035,-0.491346838381005,4.3313202625727E-5,1,1.99850670813958,40.0298881530762,1.99215350174097,8.60000029206276,-5.24545855073435,-0.975785120386575,25,-0.00321005961912835,-0.491820028988001,-0.00672103825927252,50.0016022,50.002037,-44960.902,-44943.105,52.9318833223133,18.537684000659,31.351902,0,0,0,80,4961,49.9245,-44952.0035,,,,,,,,,,,,,0,,,,3.8390055,,,,,,50.0018196,,,,
,33660950.61,50.0007305,-49720.916,-0.513648497164858,5.35585859887424E-5,1,1.99850670813958,40.0298881530762,1.99235766570059,8.60000029206276,-5.4854090265957,-1.0201894133548,25,-0.00337285121591174,-0.514263851611315,-0.00700668134145342,50.0005302,50.0009308,-49839.41,-49602.422,51.881374592467,18.5417572477011,31.733112,0,0,0,80,4961,49.919,-49720.916,,,,,,,,,,,,,0,,,,3.8390055,,,,,,50.0007305,,,,
,33660957.27,50.0005951,-49313.461,-0.51250394332029,5.51323124250792E-5,1,1.99850670813958,40.0298881530762,1.99241751232444,8.60000029206276,-5.47323427849673,-1.01791937859073,25,-0.00336136844743389,-0.513107575488743,-0.00699040666622497,50.0005264,50.0006638,-49319.109,-49307.813,52.3237763343517,18.5417892714075,31.733112,0,0,0,80,4961,49.91695,-49313.461,,,,,,,,,,,,,0,,,,3.8390055,,,,,,50.0005951,,,,