File: DataToTest/3_CuFe2O4_derivative__MvsT_305-950K_26062023.DAT
[Header]
; VSM Data File (default extension .dat)
; Copyright (c) 2003-2013, Quantum Design, Inc. All rights reserved.
TITLE,3_CuFe2O4_derivative__MvsT_305-950K_26062023
FILEOPENTIME,26756222.00,06/26/2023,6:54 pm
BYAPP,VSM,2.0,2.0
INFO,PPMS VSM Option Release 1.4.10 Build 1,APPNAME
INFO,Quantum Design Linear Motor Servo Controller,MOTOR_MODULE_NAME
INFO,3101-100 C1,MOTOR_HW_VERSION
INFO,074,MOTOR_SERIAL_NUMBER
INFO,SRV No X-over 01.01.11,MOTOR_SOFTWARE_VERSION
INFO,Quantum Design VSM Detection Module,VSM_MODULE_NAME
INFO,3101-150 E1,VSM_HW_VERSION
INFO,VSM061,VSM_SERIAL_NUMBER
INFO,VSM No X-over 01.02.05 May 20 2008 13:51:47,VSM_SOFTWARE_VERSION
INFO,113,PREAMP_SERIAL_NUMBER
INFO,Quantum Design VSM Oven Module,OVEN_MODULE_NAME
INFO,unknown,OVEN_HW_VERSION
INFO,OVN054,OVEN_SERIAL_NUMBER
INFO,unknown,OVEN_SOFTWARE_VERSION
INFO,818,COIL_SERIAL_NUMBER
INFO,0,MOMENT_UNITS
INFO,3_CuFe2O4_derivative__MvsT_305-950K_26062023,SAMPLE_MATERIAL
INFO,unknown mass of pwd+Buster cement,SAMPLE_COMMENT
INFO,,SAMPLE_MASS
INFO,,SAMPLE_VOLUME
INFO,,SAMPLE_MOLECULAR_WEIGHT
INFO,,SAMPLE_SIZE
INFO,,SAMPLE_SHAPE
DATATYPE,COMMENT,1
DATATYPE,TIME,2
STARTUPAXIS,X,2
STARTUPAXIS,Y1,5
[Data]
Comment,Time Stamp (sec),Temperature (K),Magnetic Field (Oe),Moment (emu),M. Std. Err. (emu),Transport Action,Averaging Time (sec),Frequency (Hz),Peak Amplitude (mm),Center Position (mm),Coil Signal' (mV),Coil Signal" (mV),Range (mV),M. Quad. Signal (emu),M. Raw' (emu),M. Raw" (emu),Min. Temperature (K),Max. Temperature (K),Min. Field (Oe),Max. Field (Oe),Mass (grams),Motor Lag (deg),Pressure (Torr),VSM Status (code),Motor Status (code),Measure Status (code),Measure Count,PPMS Status (code),System Temp. (K),System Field (Oe),Sample Position (deg),Bridge 1 Resistance (ohms),Bridge 1 Excitation (에),Bridge 2 Resistance (ohms),Bridge 2 Excitation (에),Bridge 3 Resistance (ohms),Bridge 3 Excitation (에),Bridge 4 Resistance (ohms),Bridge 4 Excitation (에),Signal 1 Vin (V),Signal 2 Vin (V),Digital Inputs (code),Drive 1 Iout (mA),Drive 1 Ipower (W),Drive 2 Iout (mA),Drive 2 Ipower (W),Pressure (),Map 20 (),Map 21 (),Map 22 (),Map 23 (),Map 24 (),Map 25 (),Map 26 (),Map 27 (),Map 28 (),Map 29 ()
,26756778.33,305.054107666016,99.998,0.000203137818449029,4.15067338568828E-7,1,11.9910402488375,40.0298881530762,2.00183815098356,10.5499997735024,0.00215378575870128,0.00104830798905504,0.25,5.85682931444639E-5,0.000203154273642995,5.87222378565081E-5,289.6959839,289.6959839,99.998,99.998,59.7164188692371,21.9303140130432,41.263397,0,0,0,480,5649,289.1064,99.998,,,,,,,,,,,,,0,,,,9.2E-6,,,,,,289.6959839,,,,
,26757197.54,336.816864013672,99.998,0.000224916664441588,3.29181868155419E-7,1,11.9910402488375,40.0298881530762,2.00184711766448,10.5499997735024,0.00236505872639114,0.00127348211532424,0.25,7.49521784297814E-5,0.000224925706069656,7.512434949996E-5,290.0485229,290.0586548,99.998,99.998,59.7875470644871,21.9652929786601,38.213703,0,0,0,480,5906,289.53035,99.998,,,,,,,,,,,,,0,,,,9.25E-6,,,,,,290.05358885,,,,
,26757617.225,371.925109863281,99.998,0.000261216641231748,3.87730681431184E-7,1,11.9910402488375,40.0298881530762,2.00149789557623,10.5499997735024,0.00274379829201632,0.00149309120286131,0.25,8.83323344250281E-5,0.000261225165051839,8.85329776046767E-5,290.1565857,290.1577148,99.998,99.998,61.1116257760642,21.9777353479694,38.594913,0,0,0,480,5906,288.6465,99.998,,,,,,,,,,,,,0,,,,9.2E-6,,,,,,290.15715025,,,,
,26758037.01,406.847290039063,99.998,0.000303718440618724,4.53440026916939E-7,1,11.9910402488375,40.0298881530762,2.00109515781588,10.5499997735024,0.00318255312495946,0.00177629649096666,0.25,0.000106342759649998,0.000303725821145111,0.000106577705534209,290.1314087,290.1318359,99.998,99.998,60.677821947891,22.0032407170124,37.832493,0,0,0,480,5906,287.89345,99.998,,,,,,,,,,,,,0,,,,9.2E-6,,,,,,290.1316223,,,,
,26758468.635,442.812774658203,99.998,0.000342014556144084,4.82415346441151E-7,1,11.9910402488375,40.0298881530762,2.00108171589839,10.5600003153086,0.00357963490281821,0.00202427941005244,0.25,0.000121903764206757,0.000342020844356841,0.000122169583110074,290.1492615,290.1513367,99.998,99.998,60.3808031105833,22.0078268702083,38.213703,0,0,0,480,5906,287.08605,99.998,,,,,,,,,,,,,0,,,,9.15E-6,,,,,,290.1502991,,,,
,26758888.32,477.798492431641,99.998,0.000367233310920904,5.26204279063499E-7,1,11.9910402488375,40.0298881530762,2.00077658419497,10.5499997735024,0.00384160378540128,0.00218132672096089,0.25,0.000131617995526433,0.000367238937188373,0.000131904442260146,290.1663818,290.1684265,99.998,99.998,60.9388858733141,22.0189735972426,38.594913,0,0,0,480,5906,286.186,99.998,,,,,,,,,,,,,0,,,,9.25E-6,,,,,,290.16740415,,,,
,26759308,512.677917480469,99.998,0.000385760203654965,5.70123570137726E-7,1,11.9910402488375,40.0298881530762,2.00020593969887,10.5499997735024,0.00403595874489832,0.00228122730387224,0.25,0.000137403623508253,0.000385766063209652,0.000137705287165553,290.1782227,290.1798706,99.998,99.998,61.9792334324104,22.0097384014574,38.213703,0,0,0,480,5906,285.2117,99.998,,,,,,,,,,,,,0,,,,9.25E-6,,,,,,290.17904665,,,,
,26759727.73,547.768920898438,99.998,0.000401057120667598,5.28982294571883E-7,1,11.9910402488375,40.0298881530762,1.99486650565729,10.5499997735024,0.00417188826815928,0.00244242585763995,0.25,0.000149755311605952,0.000401057613677599,0.000150071826450881,290.1983643,290.20047,99.998,99.998,62.3489437220066,22.0427592127223,38.594913,0,0,0,480,5906,284.15005,99.998,,,,,,,,,,,,,0,,,,9.25E-6,,,,,,290.19941715,,,,
,26760147.4,582.831604003906,99.998,0.000426535292352492,6.2063940270484E-7,1,11.9910402488375,40.0298881530762,1.99592195070454,10.5499997735024,0.0044420038146425,0.00258253320022041,0.25,0.000157796967430747,0.000426535642732549,0.000158134497522712,290.2344666,290.2359619,99.998,99.998,61.5821661446411,22.0516892393683,38.594913,0,0,0,480,5906,282.92715,99.998,,,,,,,,,,,,,0,,,,9.25E-6,,,,,,290.23521425,,,,
,26760567.07,617.934509277344,99.998,0.000570325361600674,7.61801435638015E-7,1,11.9910402488375,40.0298881530762,1.99260504319555,10.5499997735024,0.00591272359802855,0.00354675674704692,0.25,0.000219910067158153,0.000570317982012226,0.000220365741208508,290.2628479,290.2634888,99.998,99.998,61.8150914433719,22.043290285449,39.357338,0,0,0,480,5906,281.5357,99.998,,,,,,,,,,,,,0,,,,9.15E-6,,,,,,290.26316835,,,,
,26760998.815,654.014831542969,99.998,0.000601994001243165,1.84062671386245E-6,1,11.9910402488375,40.0298881530762,1.99306899000524,10.5600003153086,0.00628299950754175,0.00351128696685747,0.25,0.000211134699832867,0.000601998802089419,0.000211612890278318,290.3012085,290.3046265,99.998,99.998,62.993787250372,22.0122271243087,38.976128,0,0,0,480,5906,279.87995,99.998,,,,,,,,,,,,,0,,,,9.15E-6,,,,,,290.3029175,,,,
,26761418.51,689.1142578125,99.998,0.000917556159211199,3.53181980919343E-7,1,11.9910402488375,40.0298881530762,1.99198432451255,10.5600003153086,0.0101966022812712,0.00175697190432613,0.25,-1.52930590903935E-6,0.000917789752862096,-8.780384600002E-7,290.3390503,290.3450623,99.998,99.998,60.9873468415065,22.1107777938316,40.500973,0,0,0,480,5906,278.1082,99.998,,,,,,,,,,,,,0,,,,9.3E-6,,,,,,290.3420563,,,,
,26761838.12,724.181274414062,99.998,0.00132239853779596,2.38680737482544E-6,1,11.9910402488375,40.0298881530762,1.99051791453654,10.5499997735024,0.0136723818889815,0.00833824004473499,0.25,0.000521070393590276,0.00132218417834809,0.000522046888573546,295.0635986,295.0822144,99.998,99.998,62.4708777710066,22.1054579494063,40.500973,0,0,0,480,5906,283.344,99.998,,,,,,,,,,,,,0,,,,9.2E-6,,,,,,295.0729065,,,,
,26762257.865,759.275756835938,99.998,0.00129110733461399,2.07418482708047E-6,1,11.9910402488375,40.0298881530762,1.99123666697036,10.5499997735024,0.0135132573113496,0.00722176108809314,0.25,0.000425729299841356,0.00129089784046062,0.000426662165957575,296.4414063,296.5026855,99.998,99.998,64.2311051963145,22.1128685537521,37.451283,0,0,0,480,5906,281.48085,99.998,,,,,,,,,,,,,0,,,,9.2E-6,,,,,,296.4720459,,,,
,26762677.49,794.347229003906,99.998,0.00119182593253758,2.07580921419639E-6,1,11.9910402488375,40.0298881530762,1.99056763911097,10.5600003153086,0.012478588097311,0.00661264945062563,0.25,0.000388356806666323,0.00119159074376279,0.000389208946375861,297.6379089,297.6702576,99.998,99.998,63.7003794317567,22.1149430829249,40.119759,0,0,0,480,5906,279.9469,99.998,,,,,,,,,,,,,0,,,,9.25E-6,,,,,,297.65408325,,,,
,26763097.19,829.367370605469,99.998,0.000898245538644283,1.19877227147061E-6,1,11.9910402488375,40.0298881530762,1.98934519123789,10.5600003153086,0.00938812757846454,0.0050421007031144,0.25,0.000298230629842737,0.000898026797262319,0.000298865728859301,298.9410095,298.9794617,99.998,99.998,64.6602192533722,22.051260017473,39.357338,0,0,0,480,5906,278.2246,99.998,,,,,,,,,,,,,0,,,,9.2E-6,,,,,,298.9602356,,,,
,26763516.885,864.434265136719,99.998,0.000106827474882068,3.92291942143851E-7,1,11.9910402488375,40.0298881530762,1.99301156027508,10.5499997735024,0.00113167363654367,0.000524509868129382,0.25,2.86138103357204E-5,0.000106799165564161,2.86875505030934E-5,301.1265869,301.2087097,99.998,99.998,62.6514339589489,22.0961357906512,37.451283,0,0,0,480,5906,278.0031,99.998,,,,,,,,,,,,,0,,,,9.2E-6,,,,,,301.1676483,,,,
,26763936.68,899.615295410156,99.998,3.72201008347907E-5,2.9847570277028E-7,1,11.9910402488375,40.0298881530762,1.99106711403649,10.5400001630187,0.000400062770216614,0.000147041003092151,0.25,6.76975776732366E-6,3.72088206069608E-5,6.79501546851573E-6,304.3977966,304.5030212,99.998,99.998,65.6106795327569,22.0638648959148,37.832493,0,0,0,480,5906,278.00075,99.998,,,,,,,,,,,,,0,,,,9.25E-6,,,,,,304.4504089,,,,
,26764356.265,934.650817871094,99.998,3.08477716143091E-5,3.24181719306109E-7,1,11.9910402488375,40.0298881530762,1.9919767419857,10.5400001630187,0.000331248624612832,0.00012436130825677,0.25,5.83187964067723E-6,3.08346692272506E-5,5.85209188192468E-6,308.2607117,308.3804932,99.998,99.998,64.3733615868145,22.0507688520359,38.213703,0,0,0,480,5910,278.0025,99.998,,,,,,,,,,,,,0,,,,9.2E-6,,,,,,308.32060245,,,,
,26764931.895,939.755310058594,99.998,2.94194946557076E-5,3.33206689569619E-7,1,11.9910402488375,40.0298881530762,2.00252443717388,10.5400001630187,0.000316890611448606,0.000122564495848695,0.25,5.86416154053874E-6,2.94033343087062E-5,5.88265997732835E-6,312.2182312,312.2319641,99.998,99.998,62.9976953929682,21.9756251398326,40.882183,0,0,0,480,5906,278.0017,99.998,,,,,,,,,,,,,0,,,,9.25E-6,,,,,,312.22509765,,,,
,26765351.535,904.494506835938,99.998,3.35099496521638E-5,3.28988549996873E-7,1,11.9910402488375,40.0298881530762,1.98894660880567,10.5400001630187,0.000359706140228172,0.000132505841039085,0.25,6.12017741184629E-6,3.34940806536354E-5,6.14186867037315E-6,310.0552063,310.1369934,99.998,99.998,65.4183989170262,22.0368952613287,39.357338,0,0,0,480,5906,278.00055,99.998,,,,,,,,,,,,,0,,,,9.2E-6,,,,,,310.09609985,,,,
,26765771.245,869.582702636719,99.998,3.7304341287432E-5,3.10665739874027E-7,1,11.9910402488375,40.0298881530762,1.98803051472628,10.5400001630187,0.000402639441021771,0.000134001904007235,0.25,5.59898284946854E-6,3.72910998721751E-5,5.62408475106887E-6,306.8818359,306.9607239,99.998,99.998,64.6461499400261,22.0359124918487,38.213703,0,0,0,480,5906,278.0028,99.998,,,,,,,,,,,,,0,,,,9.2E-6,,,,,,306.9212799,,,,
,26766191,834.754272460937,99.998,0.000228270509383908,4.1083845785259E-7,1,11.9910402488375,40.0298881530762,1.98800061720209,10.5499997735024,0.00240146900718983,0.00117949961346378,0.25,6.66912471195521E-5,0.000228189723247587,6.68436135035081E-5,303.4911194,303.5878296,99.998,99.998,64.0825957776606,22.0345711140728,38.213703,0,0,0,480,5906,277.99995,99.998,,,,,,,,,,,,,0,,,,9.3E-6,,,,,,303.5394745,,,,
,26766610.695,799.950561523437,99.998,0.000589194216770827,1.07235469420327E-6,1,11.9910402488375,40.0298881530762,1.98851208921571,10.5400001630187,0.0061969463552852,0.00306658124291798,0.25,0.000174041387999875,0.000589041548966197,0.000174451325630347,300.2836609,300.3678894,99.998,99.998,65.0815170252377,22.049170855103,37.070068,0,0,0,480,5906,278.00065,99.998,,,,,,,,,,,,,0,,,,9.25E-6,,,,,,300.32577515,,,,
,26767030.33,764.993041992188,99.998,0.000829614259468292,1.07682418808131E-6,1,11.9910402488375,40.0298881530762,1.98755895718083,10.5400001630187,0.00870646702794188,0.00440682520613189,0.25,0.000253236912669977,0.000829454562328369,0.000253828404474447,297.931427,297.9754333,99.998,99.998,65.4207438025838,21.9840240949165,37.832493,0,0,0,480,5906,279.45755,99.998,,,,,,,,,,,,,0,,,,9.2E-6,,,,,,297.95343015,,,,
,26767450.015,730.160339355469,99.998,0.00100255063802606,1.09575711847053E-6,1,11.9910402488375,40.0298881530762,1.98844274803679,10.5400001630187,0.0105152063119726,0.00539169119408189,0.25,0.000311780048167213,0.00100239616317602,0.000312502326364826,296.6120911,296.6400146,99.998,99.998,64.7235311634299,22.0357701104848,37.832493,0,0,0,480,5906,281.25475,99.998,,,,,,,,,,,,,0,,,,9.2E-6,,,,,,296.62605285,,,,
,26767869.68,695.3828125,99.998,0.0011246740249883,1.25480898129345E-6,1,11.9910402488375,40.0298881530762,1.98883031999128,10.5499997735024,0.0117872467282255,0.00611566832223526,0.25,0.000355702235278893,0.001124535642726,0.000356519959007342,295.522583,295.5568848,99.998,99.998,65.0525967700261,22.0273627913096,36.688858,0,0,0,480,5906,282.70475,99.998,,,,,,,,,,,,,0,,,,9.2E-6,,,,,,295.5397339,,,,
,26768289.385,660.657043457031,99.998,0.00120357051520363,2.48462630958222E-6,1,11.9910402488375,40.0298881530762,1.99311701283827,10.5299996212125,0.0127148723947076,0.00613243763908584,0.25,0.000342333076630685,0.00120349960408115,0.000343207263996821,294.1447754,294.397644,99.998,99.998,63.6261247224298,22.0294050869367,36.688858,0,0,0,480,5906,285.76785,99.998,,,,,,,,,,,,,0,,,,9.2E-6,,,,,,294.2712097,,,,
,26768709.095,625.716369628906,99.998,0.00117305411446892,2.0510632052025E-7,1,11.9910402488375,40.0298881530762,1.99155947892729,10.5499997735024,0.0130250926958827,0.00228533998968199,0.25,1.65382595956213E-6,0.00117324123760059,2.4616015591122E-6,293.4735718,293.4888916,99.998,99.998,63.2439083765259,22.0053209644307,36.688858,0,0,0,480,5906,285.4556,99.998,,,,,,,,,,,,,0,,,,9.2E-6,,,,,,293.4812317,,,,
,26769140.8,589.820678710937,99.998,0.00128689270376299,3.5682551415506E-6,1,11.9910402488375,40.0298881530762,1.9904148437632,10.5299996212125,0.0138947614448259,0.00473562022731705,0.25,0.000202636741538352,0.00128709426552632,0.000203596525189802,289.8740234,289.9334717,99.998,99.998,65.7654419795647,22.0039802580487,38.213703,0,0,0,480,5906,280.263,99.998,,,,,,,,,,,,,0,,,,9.2E-6,,,,,,289.90374755,,,,
,26769560.57,554.992004394531,99.998,0.00138339950240378,2.5979687114647E-6,1,11.9910402488375,40.0298881530762,1.99007278839132,10.5400001630187,0.0145764721174314,0.00714764882983438,0.25,0.000403226895325316,0.0013835085648745,0.000404299974609348,289.4848022,289.4978333,99.998,99.998,66.057771045757,21.9981410830657,36.307648,0,0,0,480,5906,283.6274,99.998,,,,,,,,,,,,,0,,,,9.25E-6,,,,,,289.49131775,,,,
,26769980.15,520.258239746094,99.998,0.00129539530573793,1.78616003647628E-7,1,11.9910402488375,40.0298881530762,1.98964747171685,10.5400001630187,0.014375908850523,0.00249840201933433,0.25,-2.69633977698605E-7,0.001295747027007,6.24015280623377E-7,289.822113,289.8251038,99.998,99.998,66.7479490282378,21.9975539540591,37.070068,0,0,0,480,5906,284.9479,99.998,,,,,,,,,,,,,0,,,,9.25E-6,,,,,,289.8236084,,,,
,26770399.86,485.354125976562,99.998,0.00132408894425212,1.7360978281492E-7,1,11.9910402488375,40.0298881530762,1.99299954197253,10.5600003153086,0.014717740578055,0.00255983983637232,0.25,-9.50303590065652E-8,0.00132444821450499,8.15207437645125E-7,289.8350525,289.8354492,99.998,99.998,62.3059541534489,21.9924033359327,36.307648,0,0,0,480,5906,285.8019,99.998,,,,,,,,,,,,,0,,,,9.25E-6,,,,,,289.83525085,,,,
,26770819.595,450.419982910156,99.998,0.00135261952977296,1.72441976439366E-7,1,11.9910402488375,40.0298881530762,1.98949433490167,10.5299996212125,0.0150090027934107,0.00261350548739982,0.25,1.69514766385826E-7,0.00135298670492098,1.09584883416083E-6,289.835968,289.8364563,99.998,99.998,65.6059897616415,21.9790312656164,36.688858,0,0,0,480,5906,286.73025,99.998,,,,,,,,,,,,,0,,,,9.3E-6,,,,,,289.83621215,,,,
,26771239.215,415.643310546875,99.998,0.00138325736664865,1.43707905013697E-7,1,11.9910402488375,40.0298881530762,1.99687402674366,10.5499997735024,0.0154050569801602,0.00267357165878468,0.25,-5.9897876809989E-7,0.00138363287212332,3.44887102518949E-7,289.8566895,289.85672,99.998,99.998,61.7681937322181,22.0076380909458,35.926437,0,0,0,480,5906,287.55545,99.998,,,,,,,,,,,,,0,,,,9.2E-6,,,,,,289.85670475,,,,
,26771658.915,380.833953857422,99.998,0.00141677617712125,1.62778297761309E-7,1,11.9910402488375,40.0298881530762,1.98860233143412,10.5400001630187,0.0157147684247716,0.00273261513079586,0.25,-1.47475402258942E-7,0.00141716007990046,8.16546938287326E-7,289.8724365,289.8728943,99.998,99.998,66.5376909565647,22.0140167633567,36.307648,0,0,0,480,5906,288.26615,99.998,,,,,,,,,,,,,0,,,,9.15E-6,,,,,,289.8726654,,,,
,26772078.7,345.948120117188,99.998,0.00144767751436189,1.43755231731648E-7,1,11.9910402488375,40.0298881530762,1.99058988236755,10.5499997735024,0.0160754157205699,0.00278051066534024,0.25,-1.4433945286018E-6,0.00144807026550857,-4.61368387324284E-7,289.8881836,289.8883667,99.998,99.998,64.567987088103,22.0239303794902,36.688858,0,0,0,480,5906,288.9239,99.998,,,,,,,,,,,,,0,,,,9.2E-6,,,,,,289.88827515,,,,
,26772498.29,311.34912109375,99.998,0.00147750209576941,1.48350217583159E-7,1,11.9910402488375,40.0298881530762,1.99062363224068,10.5299996212125,0.0164044068123083,0.00285194057834034,0.25,-2.00701364355541E-7,0.0014779018327587,7.99545906554841E-7,289.898407,289.9000549,99.998,99.998,66.6135089229301,21.9903206450081,37.070068,0,0,0,480,5906,289.49445,99.998,,,,,,,,,,,,,0,,,,9.25E-6,,,,,,289.89923095,,,,
,26773073.9,324.119567871094,99.998,0.0014775443107341,1.50159294059957E-7,1,11.9910402488375,40.0298881530762,1.9945441442623,10.5499997735024,0.0164356130413938,0.00285838445729059,0.25,-1.11053347459506E-7,0.00147793742145001,8.88473393663413E-7,290.0454712,290.0497131,99.998,99.998,61.3406429321988,22.0014474416924,35.926437,0,0,0,480,5906,289.68145,99.998,,,,,,,,,,,,,0,,,,9.25E-6,,,,,,290.04759215,,,,
,26773493.555,358.769195556641,99.998,0.00158711128782289,2.39801824107722E-6,1,11.9910402488375,40.0298881530762,1.99722591019795,10.5499997735024,0.0167815186380377,0.00822152693293278,0.25,0.000462020078691159,0.00158721591211326,0.0004632183391823,290.1271667,290.1278076,99.998,99.998,62.8624736591413,22.0054908431461,37.070068,0,0,0,480,5906,289.02745,99.998,,,,,,,,,,,,,0,,,,9.2E-6,,,,,,290.12748715,,,,
,26773913.295,393.724334716797,99.998,0.00141138515778116,2.0401097837155E-7,1,11.9910402488375,40.0298881530762,1.98976281739018,10.5400001630187,0.0156635421465018,0.00272413954091334,0.25,-1.08858867303075E-7,0.00141175676100191,8.51232419070351E-7,290.1245422,290.1265564,99.998,99.998,66.3227431137763,21.9939076187709,36.688858,0,0,0,480,5906,288.3333,99.998,,,,,,,,,,,,,0,,,,9.25E-6,,,,,,290.1255493,,,,
,26774332.94,428.888305664063,99.998,0.00136964181863862,1.64705877727713E-7,1,11.9910402488375,40.0298881530762,2.00013135103013,10.5600003153086,0.01527664042418,0.00265426324098567,0.25,-3.33641758772783E-7,0.00137000196786638,6.00779157424075E-7,290.1331482,290.1334229,99.998,99.998,61.2421577387757,21.9507256009135,37.070068,0,0,0,480,5906,287.61215,99.998,,,,,,,,,,,,,0,,,,9.25E-6,,,,,,290.13328555,,,,
,26774752.61,463.740020751953,99.998,0.00122107332923063,1.86565408013537E-7,1,11.9910402488375,40.0298881530762,2.00193703490091,10.5499997735024,0.0136319820583082,0.00236455493700127,0.25,-6.44181991055513E-7,0.00122139346985401,1.91651895729027E-7,290.1563721,290.1573181,99.998,99.998,61.1553969731411,21.9892197994003,37.070068,0,0,0,480,5906,286.7858,99.998,,,,,,,,,,,,,0,,,,9.15E-6,,,,,,290.1568451,,,,
,26775172.36,498.773315429687,99.998,0.00135252353808143,3.51064749168561E-6,1,11.9910402488375,40.0298881530762,2.00071645649928,10.5499997735024,0.0148309897113427,0.00410984135514824,0.25,0.000133042405997153,0.00135278507884522,0.000134006731366642,290.1744995,290.1755066,99.998,99.998,59.6398192743525,21.9732303189055,37.451283,0,0,0,480,5906,285.8529,99.998,,,,,,,,,,,,,0,,,,9.2E-6,,,,,,290.17500305,,,,
,26775592.04,533.802978515625,99.998,0.0012805981118348,1.79417325645836E-7,1,11.9910402488375,40.0298881530762,2.00109141223708,10.5499997735024,0.0142909761778362,0.00247718062593726,0.25,-8.29291058157724E-7,0.00128093093399654,5.47135870084678E-8,290.2134094,290.2149658,99.998,99.998,59.3357657803716,21.9956859001886,36.688858,0,0,0,480,5906,284.75425,99.998,,,,,,,,,,,,,0,,,,9.3E-6,,,,,,290.2141876,,,,
,26776011.795,568.931396484375,99.998,0.00136442088035912,2.78020007591498E-6,1,11.9910402488375,40.0298881530762,2.00208676419918,10.5600003153086,0.0145107477791852,0.00679494291587693,0.25,0.00037124411664498,0.00136451572586349,0.000372287211122244,290.2346191,290.2366028,99.998,99.998,59.9485625394487,21.9907290274502,37.832493,0,0,0,480,5906,283.476,99.998,,,,,,,,,,,,,0,,,,9.2E-6,,,,,,290.23561095,,,,
,26776431.44,604.083679199219,99.998,0.00122666842436633,2.15542296222561E-7,1,11.9910402488375,40.0298881530762,2.00184133845636,10.5499997735024,0.0136938142633429,0.00237492496028049,0.25,-6.94883995986989E-7,0.00122698433781664,1.61634819863627E-7,290.2614441,290.2620544,99.998,99.998,60.7262829160834,21.9909568868033,37.832493,0,0,0,480,5906,282.04505,99.998,,,,,,,,,,,,,0,,,,9.15E-6,,,,,,290.26174925,,,,
,26776851.1,639.127319335938,99.998,0.00118766974340277,2.1766352375921E-7,1,11.9910402488375,40.0298881530762,2.00227605455974,10.5499997735024,0.0132618514958134,0.00229614150211598,0.25,-1.0144227231391E-6,0.00118797438545061,-1.79887111143223E-7,290.2860413,290.2865295,99.998,99.998,59.2364989584293,22.0002591199051,37.832493,0,0,0,480,5906,280.53395,99.998,,,,,,,,,,,,,0,,,,9.2E-6,,,,,,290.2862854,,,,
,26777270.775,674.203979492188,99.998,0.0012537353750022,1.47881386469368E-6,1,11.9910402488375,40.0298881530762,2.00107937920247,10.5499997735024,0.013229017548636,0.00680403421911028,0.25,0.000391599034845782,0.00125377651316916,0.000392586271465369,290.3289795,290.3318481,99.998,99.998,60.1447512977756,21.9974392880141,38.976128,0,0,0,480,5906,278.79995,99.998,,,,,,,,,,,,,0,,,,9.2E-6,,,,,,290.3304138,,,,
,26777690.5,709.267456054687,99.998,0.00119319929788276,1.40085664324552E-6,1,11.9910402488375,40.0298881530762,2.00205811255241,10.5499997735024,0.012586637318392,0.00652511130055611,0.25,0.000376925982141316,0.00119311208525752,0.000377824700078355,293.7247925,293.8108521,99.998,99.998,59.8688364304871,22.0144880707491,62.611229,0,0,0,480,5906,279.52065,99.998,,,,,,,,,,,,,0,,,,9.15E-6,,,,,,293.7678223,,,,
,26778110.145,744.422668457031,99.998,0.00107379087573828,3.13149753134924E-6,1,11.9910402488375,40.0298881530762,2.00192360926389,10.5499997735024,0.0115543873675509,0.0045563542557669,0.25,0.000221391294120194,0.00107372345808516,0.000222159434650358,296.037262,296.0774231,99.998,99.998,59.4592630864101,22.0052565001835,36.688858,0,0,0,480,5906,281.9331,99.998,,,,,,,,,,,,,0,,,,9.2E-6,,,,,,296.05734255,,,,
,26778529.885,779.486694335938,99.998,0.000881096657572233,2.54192347192693E-7,1,11.9910402488375,40.0298881530762,2.00224360642895,10.5499997735024,0.00983667973108698,0.00170076319711898,0.25,-9.59563027151666E-7,0.000881131544950306,-3.37640659046123E-7,297.4193726,297.4424744,99.998,99.998,60.9982896407757,22.0097423960169,46.600353,0,0,0,480,5906,279.48135,99.998,,,,,,,,,,,,,0,,,,9.25E-6,,,,,,297.4309235,,,,
,26778949.535,814.574523925781,99.998,0.000627355541889136,2.95977199134641E-7,1,11.9910402488375,40.0298881530762,2.00091061876443,10.5499997735024,0.00699966674530215,0.00120706668595703,0.25,-9.61581317196512E-7,0.000627355296934355,-5.16860524017602E-7,298.7309265,298.7709045,99.998,99.998,60.3042035156987,22.0069279266779,37.451283,0,0,0,480,5906,278.4851,99.998,,,,,,,,,,,,,0,,,,9.2E-6,,,,,,298.7509155,,,,
,26779369.235,849.682983398438,99.998,0.000158555573330862,3.42528114709847E-7,1,11.9910402488375,40.0298881530762,2.00039228267626,10.5499997735024,0.00176995054952288,0.000296799963867325,0.25,-9.76475828092049E-7,0.000158546743133115,-8.63794089961488E-7,300.6437988,300.7203064,99.998,99.998,61.0952115771603,21.9553486015445,37.832493,0,0,0,480,5906,278.00255,99.998,,,,,,,,,,,,,0,,,,9.2E-6,,,,,,300.6820526,,,,
,26779956.82,863.168273925781,99.998,5.94733339101754E-5,2.68109627476895E-7,1,11.9910402488375,40.0298881530762,2.00192995314222,10.5499997735024,0.00066595512239545,0.000102047477540933,0.25,-1.20444013495734E-6,5.94652179144198E-5,-1.16201718621222E-6,303.6863403,303.6874084,99.998,99.998,60.1119228999679,22.0116690644495,37.451283,0,0,0,480,5906,277.9982,99.998,,,,,,,,,,,,,0,,,,9.2E-6,,,,,,303.68687435,,,,
,26780376.48,828.299987792969,99.998,0.000389927314374163,3.11901459641455E-7,1,11.9910402488375,40.0298881530762,2.00024761159122,10.5499997735024,0.00434980297457503,0.000743809218323643,0.25,-1.14666370589744E-6,0.000389886231034534,-8.69578326048492E-7,302.2181702,302.28125,99.998,99.998,59.7422126103717,22.0173552248517,37.451283,0,0,0,480,5906,277.9964,99.998,,,,,,,,,,,,,0,,,,9.2E-6,,,,,,302.2497101,,,,
,26780796.255,793.4775390625,99.998,0.00074483368322689,2.61862423334959E-7,1,11.9910402488375,40.0298881530762,2.00132056724569,10.5499997735024,0.00831186247626441,0.00143292578705591,0.25,-1.17965891167014E-6,0.000744810116249027,-6.50543305560715E-7,299.742157,299.8167114,99.998,99.998,59.9899888509679,22.0042440301229,37.451283,0,0,0,480,5906,278.0016,99.998,,,,,,,,,,,,,0,,,,9.2E-6,,,,,,299.7794342,,,,
,26781215.935,758.614318847656,99.998,0.000953326804849179,2.51848302645478E-7,1,11.9910402488375,40.0298881530762,2.00229982640031,10.5499997735024,0.0106436653893071,0.00183793822448013,0.25,-1.24210291230655E-6,0.000953357073009528,-5.69956896574045E-7,297.6818237,297.7137756,99.998,99.998,60.4026887091218,22.0109004979121,37.832493,0,0,0,480,5906,279.7449,99.998,,,,,,,,,,,,,0,,,,9.2E-6,,,,,,297.69779965,,,,
,26781635.585,723.907104492188,99.998,0.00108973913281058,2.24275507366483E-7,1,11.9910402488375,40.0298881530762,2.00192611819617,10.5499997735024,0.0121641486717531,0.00210550410609676,0.25,-9.83878114766777E-7,0.00108981773873509,-2.1568519915579E-7,296.2908325,296.4211121,99.998,99.998,60.4495864202756,22.0033489094289,56.130638,0,0,0,480,5906,279.7863,99.998,,,,,,,,,,,,,0,,,,9.25E-6,,,,,,296.3559723,,,,
,26782055.25,689.014526367187,99.998,0.00118877229063404,2.24252459638564E-7,1,11.9910402488375,40.0298881530762,2.00090677532373,10.5499997735024,0.0132633647641033,0.00229676838440723,0.25,-9.85567820643975E-7,0.00118889454261441,-1.48271869705102E-7,295.278717,295.4080811,99.998,99.998,60.7747438842757,22.0003508272427,75.953629,0,0,0,480,5906,279.98515,99.998,,,,,,,,,,,,,0,,,,9.15E-6,,,,,,295.34339905,,,,
,26782474.97,654.217834472656,99.998,0.00126581407428788,2.13453025705954E-7,1,11.9910402488375,40.0298881530762,2.00204255982845,10.5499997735024,0.0141277551636274,0.00246534833923713,0.25,6.07949517739736E-7,0.00126597269547893,1.4857536810784E-6,294.5997314,294.6240234,99.998,99.998,60.8106987961603,21.9322562167924,36.688858,0,0,0,480,5906,283.71165,99.998,,,,,,,,,,,,,0,,,,9.2E-6,,,,,,294.6118774,,,,
,26782894.64,619.445495605469,99.998,0.00132943292696332,2.01041453207129E-7,1,11.9910402488375,40.0298881530762,2.00169924300721,10.5499997735024,0.0148386053450353,0.00257471212136473,0.25,-6.50578990279409E-7,0.0013296683876658,2.83507137325187E-7,292.81604,292.970459,99.998,99.998,60.1760164385448,22.0055296340249,54.987003,0,0,0,480,5906,280.57505,99.998,,,,,,,,,,,,,0,,,,9.2E-6,,,,,,292.8932495,,,,
,26783314.36,584.574035644531,99.998,0.00136485604081233,2.00598006100576E-7,1,11.9910402488375,40.0298881530762,2.00202792058584,10.5499997735024,0.0152393703897382,0.00263598996573199,0.25,-1.38516979310875E-6,0.00136524109041748,-4.27388615521577E-7,289.4387207,289.4611206,99.998,99.998,60.3847112531795,22.0190583965039,37.451283,0,0,0,480,5906,280.8259,99.998,,,,,,,,,,,,,0,,,,9.25E-6,,,,,,289.44992065,,,,
,26783734.075,549.654235839844,99.998,0.00139954382587088,1.86425003644738E-7,1,11.9910402488375,40.0298881530762,2.00203467501881,10.5499997735024,0.0156264896947927,0.00270403694723742,0.25,-1.31344277320856E-6,0.00139993357881871,-3.43781437508284E-7,289.5929871,289.6061096,99.998,99.998,59.6781190717948,22.0136755327532,36.688858,0,0,0,480,5906,283.8535,99.998,,,,,,,,,,,,,0,,,,9.3E-6,,,,,,289.59954835,,,,
,26784153.725,514.953979492188,99.998,0.00142589496088946,1.63124553325556E-7,1,11.9910402488375,40.0298881530762,2.00116353857385,10.5499997735024,0.0159132869159798,0.00275770093722023,0.25,-9.82511775346068E-7,0.00142628248014636,9.62001873101362E-10,289.8255005,289.8267822,99.998,99.998,59.7172004977563,22.0203322324887,37.451283,0,0,0,480,5906,284.95195,99.998,,,,,,,,,,,,,0,,,,9.2E-6,,,,,,289.82614135,,,,
,26784585.38,479.100799560547,99.998,0.00145259388309575,1.6931874987871E-7,1,11.9910402488375,40.0298881530762,2.00106978480441,10.5499997735024,0.0162105339981807,0.00280920357519054,0.25,-9.97556941331503E-7,0.00145298935875503,2.01859485564997E-10,289.8202209,289.820282,99.998,99.998,61.3140675625449,22.0221156366674,35.926437,0,0,0,480,5906,285.94035,99.998,,,,,,,,,,,,,0,,,,9.25E-6,,,,,,289.82025145,,,,
,26785005.09,444.320037841797,99.998,0.00148068594490374,1.581553308459E-7,1,11.9910402488375,40.0298881530762,2.00201882296244,10.5499997735024,0.0165319905947597,0.00286223547733828,0.25,-1.2454908998312E-6,0.00148108885781925,-2.32456038737282E-7,289.8370667,289.838562,99.998,99.998,59.8868138864294,22.0208896602629,36.688858,0,0,0,480,5906,286.87645,99.998,,,,,,,,,,,,,0,,,,9.15E-6,,,,,,289.83781435,,,,
,26785424.75,409.573791503906,99.998,0.00151108336300487,1.45982689398113E-7,1,11.9910402488375,40.0298881530762,2.00182446258219,10.5499997735024,0.0168697292400353,0.00292115417778586,0.25,-1.22895246485264E-6,0.00151149392936288,-1.98522078535278E-7,289.85849,289.8586121,99.998,99.998,60.5191513584872,22.0228690918621,36.688858,0,0,0,480,5906,287.67285,99.998,,,,,,,,,,,,,0,,,,9.2E-6,,,,,,289.85855105,,,,
,26785844.445,374.415069580078,99.998,0.00154409468459412,1.52903640163989E-7,1,11.9910402488375,40.0298881530762,2.00076173449009,10.5499997735024,0.01722894805153,0.00298657490008782,0.25,-9.72701024068831E-7,0.00154451347626876,7.72656297797706E-8,289.8766174,289.8777771,99.998,99.998,59.4006409474678,22.0211635394772,36.688858,0,0,0,480,5906,288.3738,99.998,,,,,,,,,,,,,0,,,,9.2E-6,,,,,,289.87719725,,,,
,26786264.18,339.620544433594,99.998,0.00157554490501902,1.32814176969061E-7,1,11.9910402488375,40.0298881530762,2.00095514614087,10.5499997735024,0.017581081620854,0.00305005424958412,0.25,-7.77534990403082E-7,0.00157597176877776,2.91026873439596E-7,289.8891296,289.8908997,99.998,99.998,60.3948724239295,22.0170126414748,36.688858,0,0,0,480,5906,289.01855,99.998,,,,,,,,,,,,,0,,,,9.3E-6,,,,,,289.89001465,,,,
,26786683.885,306.418029785156,99.998,0.00160241861071629,1.14699626008555E-7,1,11.9910402488375,40.0298881530762,2.00218735968681,10.5499997735024,0.0178924420109521,0.00309852734647632,0.25,-1.27025818428995E-6,0.00160285274901306,-1.86105914737801E-7,289.9021606,289.9023438,99.998,99.998,61.270296365468,22.0266722699715,36.688858,0,0,0,480,5910,289.5789,99.998,,,,,,,,,,,,,0,,,,9.15E-6,,,,,,289.9022522,,,,
,26787259.46,329.765441894531,99.998,0.00159019450127321,1.3863603313433E-7,1,11.9910402488375,40.0298881530762,2.00235541384686,10.5499997735024,0.0177574421921647,0.00307420831303734,0.25,-1.34234759002101E-6,0.00159061700429673,-2.66470360666886E-7,290.073822,290.0775452,99.998,99.998,60.586371411141,22.024669790412,36.688858,0,0,0,480,5906,289.57525,99.998,,,,,,,,,,,,,0,,,,9.3E-6,,,,,,290.0756836,,,,
,26787691.085,365.813873291016,99.998,0.00155846607229686,1.54528440996325E-7,1,11.9910402488375,40.0298881530762,2.00193704624035,10.5499997735024,0.0173985664000988,0.00301832320123073,0.25,-7.75640533645945E-7,0.00155887702436833,2.82008290066664E-7,290.126709,290.1272583,99.998,99.998,60.0048397928333,22.0220184399356,36.688858,0,0,0,480,5906,288.86405,99.998,,,,,,,,,,,,,0,,,,9.2E-6,,,,,,290.12698365,,,,
,26788110.79,400.826477050781,99.998,0.00152415235462322,1.64879381401467E-7,1,11.9910402488375,40.0298881530762,2.00183153753651,10.5499997735024,0.017014557667077,0.00295212393786028,0.25,-7.25096479394449E-7,0.00152455391217792,3.1224660364671E-7,290.1266479,290.1276855,99.998,99.998,60.5418185855449,22.0203304579987,36.307648,0,0,0,480,5906,288.1696,99.998,,,,,,,,,,,,,0,,,,9.15E-6,,,,,,290.1271667,,,,
,26788530.525,435.675262451172,99.998,0.00149047181614661,1.7371184085576E-7,1,11.9910402488375,40.0298881530762,2.0016618975518,10.5600003153086,0.0166375672125892,0.00288460134724894,0.25,-8.95973657116883E-7,0.00149086368648892,1.2157094919842E-7,290.1401978,290.1408081,99.998,99.998,60.2690302323333,22.0240685096117,37.070068,0,0,0,480,5906,287.41565,99.998,,,,,,,,,,,,,0,,,,9.2E-6,,,,,,290.14050295,,,,
,26788962.17,471.779174804687,99.998,0.00145777595264506,1.80826451988578E-7,1,11.9910402488375,40.0298881530762,2.00210357869583,10.5400001630187,0.0162757177176473,0.00282366113776692,0.25,-7.23730801882157E-7,0.00145815775680149,2.75182106916954E-7,290.1614685,290.1636353,99.998,99.998,61.2468475098911,22.0316610523776,37.070068,0,0,0,480,5906,286.53485,99.998,,,,,,,,,,,,,0,,,,9.3E-6,,,,,,290.1625519,,,,
,26789393.9,507.694946289063,99.998,0.00142758903591756,1.7620916428681E-7,1,11.9910402488375,40.0298881530762,2.00039014204937,10.5499997735024,0.0159241301708898,0.00277137551366577,0.25,4.5205347703211E-8,0.00142796107851387,1.02773049682943E-6,290.1826172,290.1838684,99.998,99.998,60.4636557336218,21.9691922087608,36.307648,0,0,0,480,5906,285.53175,99.998,,,,,,,,,,,,,0,,,,9.15E-6,,,,,,290.1832428,,,,
,26789813.57,542.919555664063,99.998,0.00139988460385572,1.87206844671636E-7,1,11.9910402488375,40.0298881530762,2.0020109691738,10.5499997735024,0.0156288145300935,0.00271046164306503,0.25,-7.87737890836275E-7,0.00140024851726714,1.79991646612224E-7,290.2065735,290.2069092,99.998,99.998,60.7755255127949,22.0224084707044,37.451283,0,0,0,480,5906,284.42135,99.998,,,,,,,,,,,,,0,,,,9.1E-6,,,,,,290.20674135,,,,
,26790233.24,577.956481933594,99.998,0.00136749846929432,2.02767006124229E-7,1,11.9910402488375,40.0298881530762,2.00232902586994,10.5499997735024,0.0152701084495176,0.00264492801969246,0.25,-1.06354809798648E-6,0.00136785226227337,-1.13263505376268E-7,290.2387085,290.2404175,99.998,99.998,60.0493926184294,22.0348352397097,37.451283,0,0,0,480,5906,283.16205,99.998,,,,,,,,,,,,,0,,,,9.25E-6,,,,,,290.239563,,,,
,26790652.985,613.016723632813,99.998,0.00132789980860412,2.06923853507569E-7,1,11.9910402488375,40.0298881530762,2.0019282625039,10.5499997735024,0.0148247045619989,0.00256995620385301,0.25,-8.4904306777102E-7,0.00132824180155744,7.9327454965852E-8,290.2595215,290.2604675,99.998,99.998,60.6457751786026,22.0335958392272,37.451283,0,0,0,480,5906,281.74165,99.998,,,,,,,,,,,,,0,,,,9.25E-6,,,,,,290.2599945,,,,
,26791072.675,648.065185546875,99.998,0.00127635625967341,2.20056703230075E-7,1,11.9910402488375,40.0298881530762,2.00188097715394,10.5499997735024,0.0142485313003116,0.00247237690420052,0.25,-6.22000620630055E-7,0.00127668231255002,2.76658188114184E-7,290.3067932,290.3082581,99.998,99.998,59.8274101189679,22.0233557620073,38.213703,0,0,0,480,5906,280.09285,99.998,,,,,,,,,,,,,0,,,,9.25E-6,,,,,,290.30752565,,,,
,26791504.285,684.201293945313,99.998,0.00121601373857446,2.40340064316329E-7,1,11.9910402488375,40.0298881530762,1.99976607949333,10.5499997735024,0.0135612338853948,0.00235251697508499,0.25,-6.5194610519286E-7,0.00121632217106714,2.1121020427366E-7,290.3470764,290.3478699,99.998,99.998,61.7580325614681,22.0440452556995,38.213703,0,0,0,480,5906,278.1892,99.998,,,,,,,,,,,,,0,,,,9.2E-6,,,,,,290.34747315,,,,
,26791924,719.296264648438,99.998,0.00114161477533832,2.45532862121656E-7,1,11.9910402488375,40.0298881530762,2.001270672402,10.5499997735024,0.0127392280284381,0.00220809964525051,0.25,-7.53034494549999E-7,0.00114174484756538,3.98218109871814E-8,294.9661865,295.0514832,99.998,99.998,59.9196422842371,22.0225818012393,37.070068,0,0,0,480,5906,283.3084,99.998,,,,,,,,,,,,,0,,,,9.3E-6,,,,,,295.00883485,,,,
,26792343.685,754.428466796875,99.998,0.00104225625924496,2.60335161732853E-7,1,11.9910402488375,40.0298881530762,2.0015064767023,10.5600003153086,0.0116314398010044,0.00201522296482463,0.25,-7.6673891364563E-7,0.00104232936333912,-3.87219626069334E-8,296.3738708,296.5082703,99.998,99.998,60.5379104429487,22.0362993178233,37.451283,0,0,0,480,5906,281.94715,99.998,,,,,,,,,,,,,0,,,,9.15E-6,,,,,,296.44107055,,,,
,26792763.415,789.459411621094,99.998,0.00086249114698655,2.73142189568503E-7,1,11.9910402488375,40.0298881530762,2.00033088847663,10.5499997735024,0.00961891793205854,0.00166981250982635,0.25,-3.55247049718949E-7,0.00086251585665206,2.52796996467096E-7,297.7628174,297.7967529,99.998,99.998,59.7023495558909,22.0233169253402,40.119759,0,0,0,480,5906,279.77615,99.998,,,,,,,,,,,,,0,,,,9.2E-6,,,,,,297.77978515,,,,
,26793183.08,824.568176269531,99.998,0.000519542484316027,3.18147337826849E-7,1,11.9910402488375,40.0298881530762,2.00101137420259,10.5499997735024,0.00579747436973579,0.000996748869523169,0.25,-1.05853599779664E-6,0.00051953668293247,-6.89497565102438E-7,299.0927124,299.1345825,99.998,99.998,60.4574027054679,22.0380567931989,38.594913,0,0,0,480,5906,278.01955,99.998,,,,,,,,,,,,,0,,,,9.2E-6,,,,,,299.11364745,,,,
,26793602.735,859.672546386719,99.998,6.93024383255513E-5,2.82158936270568E-7,1,11.9910402488375,40.0298881530762,2.00027130943426,10.5499997735024,0.00077511146650679,0.000120795215497383,0.25,-1.22693357264E-6,6.92976171442168E-5,-1.17760790099222E-6,301.3723145,301.45224,99.998,99.998,60.078312873641,22.0234142092746,37.832493,0,0,0,480,5906,278.0026,99.998,,,,,,,,,,,,,0,,,,9.15E-6,,,,,,301.41227725,,,,
,26794178.35,854.152282714844,99.998,7.41252608366977E-5,2.82143205425538E-7,1,11.9910402488375,40.0298881530762,2.0007327528424,10.5600003153086,0.000828676018553887,0.000132140710756558,0.25,-1.05059404602518E-6,7.41153111648022E-5,-9.97794946010394E-7,303.4551697,303.4844055,99.998,99.998,59.4397223734294,22.0410546878819,37.451283,0,0,0,480,5906,278.00135,99.998,,,,,,,,,,,,,0,,,,9.25E-6,,,,,,303.4697876,,,,
,26794598.135,819.332946777344,99.998,0.000518104216691584,3.06593642482104E-7,1,11.9910402488375,40.0298881530762,2.00138370794491,10.5499997735024,0.00578214071354526,0.000993412753379063,0.25,-1.11654554126322E-6,0.000518059639619592,-7.48440728384821E-7,301.5579224,301.6257019,99.998,99.998,60.0353233050833,22.0392314382463,37.451283,0,0,0,480,5906,277.99985,99.998,,,,,,,,,,,,,0,,,,9.3E-6,,,,,,301.59181215,,,,
,26795017.74,784.552917480469,99.998,0.000836303684821248,2.57563506406078E-7,1,11.9910402488375,40.0298881530762,2.00112278198058,10.5499997735024,0.00933133579128833,0.00161224025422383,0.25,-1.01445400182103E-6,0.000836296082616081,-4.20441455587457E-7,298.9877625,299.0637817,99.998,99.998,59.5851052780063,22.0216344295036,37.070068,0,0,0,480,5906,278.02585,99.998,,,,,,,,,,,,,0,,,,9.2E-6,,,,,,299.0257721,,,,
,26795437.46,749.677490234375,99.998,0.00102386436298329,2.37202000624518E-7,1,11.9910402488375,40.0298881530762,2.00178136237201,10.5499997735024,0.0114282747782754,0.00197455235980185,0.25,-1.23451147053911E-6,0.00102390588185663,-5.13954649804447E-7,297.3929443,297.4262695,99.998,99.998,59.8868138864294,22.0388496494196,43.169453,0,0,0,480,5906,280.1743,99.998,,,,,,,,,,,,,0,,,,9.2E-6,,,,,,297.4096069,,,,
,26795869.105,713.909851074219,99.998,0.00115213710942701,2.29256147834281E-7,1,11.9910402488375,40.0298881530762,2.00119609571163,10.5499997735024,0.0128564068158045,0.00222419058884121,0.25,-1.13248239410715E-6,0.00115222443683825,-3.26986445792399E-7,296.2434692,296.2721558,99.998,99.998,61.5970170865065,22.0426984026739,36.688858,0,0,0,480,5906,281.72755,99.998,,,,,,,,,,,,,0,,,,9.25E-6,,,,,,296.2578125,,,,
,26796288.81,679.111633300781,99.998,0.00124288057618362,2.16891655189137E-7,1,11.9910402488375,40.0298881530762,2.00143156213445,10.5499997735024,0.0138707738405078,0.0024008243203051,0.25,-1.11726374873085E-6,0.00124301175721667,-2.5306570769096E-7,295.263855,295.3122864,99.998,99.998,59.5225749964678,22.0396506604932,36.688858,0,0,0,480,5906,283.02165,99.998,,,,,,,,,,,,,0,,,,9.2E-6,,,,,,295.2880707,,,,
,26796708.475,644.22265625,99.998,0.00144250856282886,1.38079029531997E-6,1,11.9910402488375,40.0298881530762,2.00087845543504,10.5600003153086,0.015171177849941,0.00809746188812795,0.25,0.000474790284933345,0.00144242439265454,0.000475896931543594,292.8276672,293.0140076,99.998,99.998,59.6601416158525,22.0413449926512,56.130638,0,0,0,480,5906,278.31915,99.998,,,,,,,,,,,,,0,,,,9.3E-6,,,,,,292.9208374,,,,
,26797128.175,609.337890625,99.998,0.00136341849626527,1.9759438750155E-7,1,11.9910402488375,40.0298881530762,1.99934866563824,10.5499997735024,0.0151996415214952,0.00264890260550209,0.25,3.31640702127513E-7,0.00136372915609746,1.29624044242177E-6,291.1280212,291.2473145,99.998,99.998,60.1345901270256,21.9824280166105,43.550663,0,0,0,480,5906,279.0164,99.998,,,,,,,,,,,,,0,,,,9.25E-6,,,,,,291.18766785,,,,
,26797547.885,574.4970703125,99.998,0.00140698054218301,1.88550129609466E-7,1,11.9910402488375,40.0298881530762,2.00110216047056,10.5499997735024,0.0157024042198921,0.00271849168587599,0.25,-1.21321981639816E-6,0.00140738259174752,-2.30886125601946E-7,289.3391113,289.3401184,99.998,99.998,59.7766042652179,22.049905846071,36.307648,0,0,0,480,5906,282.03885,99.998,,,,,,,,,,,,,0,,,,9.2E-6,,,,,,289.33961485,,,,
,26797967.515,539.727661132812,99.998,0.00143532814861779,1.83017405130606E-7,1,11.9910402488375,40.0298881530762,1.99907866861712,10.5499997735024,0.0160026393509405,0.00277305120927467,0.25,-1.00340767290181E-6,0.00143572250757826,-1.07122448175215E-8,289.717865,289.7253113,99.998,99.998,61.2233986543142,22.0668209886403,36.688858,0,0,0,480,5906,284.2977,99.998,,,,,,,,,,,,,0,,,,9.15E-6,,,,,,289.72158815,,,,
,26798387.305,504.976684570313,99.998,0.00146008107852571,1.69681494182429E-7,1,11.9910402488375,40.0298881530762,2.00049044206852,10.5600003153086,0.0162894273949889,0.00282365063480057,0.25,-9.38199636396152E-7,0.00146047766302504,6.7681714023689E-8,289.8326111,289.8334961,99.998,99.998,59.7078209555255,22.0480674166942,37.070068,0,0,0,480,5906,285.2344,99.998,,,,,,,,,,,,,0,,,,9.25E-6,,,,,,289.8330536,,,,
,26798806.945,469.984252929687,99.998,0.00148512742203091,1.59836888747616E-7,1,11.9910402488375,40.0298881530762,2.00130724981856,10.5600003153086,0.0165757212564232,0.00287107995757399,0.25,-1.14130744851733E-6,0.00148553180096517,-1.22365531947906E-7,289.8233948,289.8241272,99.998,99.998,59.8399161752756,22.0482383114566,36.688858,0,0,0,480,5906,286.20625,99.998,,,,,,,,,,,,,0,,,,9.2E-6,,,,,,289.823761,,,,
,26799238.61,434.354736328125,99.998,0.00151504446690182,1.50567968284902E-7,1,11.9910402488375,40.0298881530762,1.9999575243054,10.5499997735024,0.0168960316505998,0.00294231556836686,0.25,2.10987454396279E-7,0.00151545534905761,1.24687689663115E-6,289.8477783,289.8485718,99.998,99.998,60.4910127317949,22.0046438708797,36.688858,0,0,0,480,5906,287.12155,99.998,,,,,,,,,,,,,0,,,,9.2E-6,,,,,,289.84817505,,,,
,26799658.34,399.387908935547,99.998,0.00154569415877659,1.51303498392286E-7,1,11.9910402488375,40.0298881530762,2.00062011940922,10.5499997735024,0.0172460992376765,0.00298676509179687,0.25,-1.2179828745576E-6,0.00154611392009308,-1.64870222233976E-7,289.8641357,289.8649292,99.998,99.998,60.3339053994295,22.0527349304274,36.688858,0,0,0,480,5906,287.88585,99.998,,,,,,,,,,,,,0,,,,9.15E-6,,,,,,289.86453245,,,,
,26800078.015,364.725677490234,99.998,0.0015782358937668,1.45266439482428E-7,1,11.9910402488375,40.0298881530762,2.00121162821581,10.5600003153086,0.017613860112742,0.00305228706418604,0.25,-1.08122967829537E-6,0.0015786640423999,-8.98936882365741E-9,289.8779297,289.8789368,99.998,99.998,59.2568212999293,22.0488886479727,36.688858,0,0,0,480,5906,288.58095,99.998,,,,,,,,,,,,,0,,,,9.2E-6,,,,,,289.87843325,,,,
,26800497.66,329.681854248047,99.998,0.00160961027925671,1.21614962237045E-7,1,11.9910402488375,40.0298881530762,2.00095428204704,10.5499997735024,0.0179618615928347,0.00311219442550036,0.25,-1.13455989493893E-6,0.00161004652167069,-4.37553053558408E-8,289.89328,289.8934021,99.998,99.998,60.0501742469487,22.0458978652041,35.926437,0,0,0,480,5906,289.18945,99.998,,,,,,,,,,,,,0,,,,9.2E-6,,,,,,289.89334105,,,,
,26801073.27,305.299133300781,99.998,0.00163351433005272,1.19778395928787E-7,1,11.9910402488375,40.0298881530762,2.00047600968451,10.5499997735024,0.0182239336674611,0.00316035833607238,0.25,-9.08962803209345E-7,0.00163395369283125,1.95447175977012E-7,289.9614868,289.9652405,99.998,99.998,60.8052273965257,22.0482200934781,36.688858,0,0,0,480,5906,289.77355,99.998,,,,,,,,,,,,,0,,,,9.25E-6,,,,,,289.96336365,,,,
,26801492.985,339.85986328125,99.998,0.0016105211687952,1.54611783575623E-7,1,11.9910402488375,40.0298881530762,1.99948376208223,10.5499997735024,0.0179559103194447,0.00313096954268407,0.25,5.90160133609577E-7,0.00161094637942292,1.68106350880289E-6,290.100647,290.1035767,99.998,99.998,61.6587657395258,21.9915965048872,37.070068,0,0,0,480,5906,289.4063,99.998,,,,,,,,,,,,,0,,,,9.2E-6,,,,,,290.10211185,,,,
,26801912.62,374.957611083984,99.998,0.00174273469908,2.20947675521606E-6,1,11.9910402488375,40.0298881530762,1.99978434891527,10.5499997735024,0.0183562773694867,0.00957535030615871,0.25,0.000555439526007788,0.0017428162585412,0.000556769474621228,290.1270752,290.1284485,99.998,99.998,59.8688364304871,22.0254011165645,37.451283,0,0,0,480,5906,288.70405,99.998,,,,,,,,,,,,,0,,,,9.2E-6,,,,,,290.12776185,,,,
,26802332.355,409.758392333984,99.998,0.00154243289389012,1.50403995431918E-7,1,11.9910402488375,40.0298881530762,2.00020234960491,10.5499997735024,0.0172057650912094,0.00298193771094418,0.25,-1.02713581789966E-6,0.00154283926533997,2.33379360721E-8,290.1283569,290.131134,99.998,99.998,60.8372741658141,22.0515515449828,37.451283,0,0,0,480,5906,287.99335,99.998,,,,,,,,,,,,,0,,,,9.2E-6,,,,,,290.12974545,,,,
,26802751.99,444.776153564453,99.998,0.00166465594682797,1.61834580791469E-6,1,11.9910402488375,40.0298881530762,2.00067312366067,10.5600003153086,0.0175248421841573,0.00924479172169714,0.25,0.00053902344077581,0.00166472399049765,0.000540302441067998,290.1486511,290.1501465,99.998,99.998,59.8860322579102,22.0491530557227,37.070068,0,0,0,480,5906,287.2123,99.998,,,,,,,,,,,,,0,,,,9.2E-6,,,,,,290.1493988,,,,
,26803195.685,481.704681396484,99.998,0.00160537637867924,3.88954904418832E-6,1,11.9910402488375,40.0298881530762,1.999258675782,10.5600003153086,0.0170498411222843,0.00798682229488016,0.25,0.00043705983597909,0.00160549605404487,0.00043827555186019,290.1665039,290.1679993,99.998,99.998,60.1533492114871,22.0586934696376,37.070068,0,0,0,480,5906,286.26615,99.998,,,,,,,,,,,,,0,,,,9.3E-6,,,,,,290.1672516,,,,
,26803615.385,516.601806640625,99.998,0.00144704955648706,1.79211000195946E-7,1,11.9910402488375,40.0298881530762,2.00012830773847,10.5499997735024,0.0161414182351715,0.00279590551140461,0.25,-1.11150616204208E-6,0.00144742705316633,-1.14772706349914E-7,290.1897278,290.190155,99.998,99.998,61.5829477731604,22.067084695125,37.070068,0,0,0,480,5906,285.2637,99.998,,,,,,,,,,,,,0,,,,9.25E-6,,,,,,290.1899414,,,,
,26804047.125,552.818420410156,99.998,0.00142010849976361,1.95096910155249E-7,1,11.9910402488375,40.0298881530762,2.00091538871481,10.5499997735024,0.0158467415772035,0.00274553934844375,0.25,-1.03686043501866E-6,0.00142047743092938,-5.38315824540993E-8,290.212616,290.2127075,99.998,99.998,59.6320029891602,22.0629851360537,37.070068,0,0,0,480,5906,284.08665,99.998,,,,,,,,,,,,,0,,,,9.25E-6,,,,,,290.21266175,,,,
,26804466.745,587.944885253906,99.998,0.00138798594525927,2.06159952628968E-7,1,11.9910402488375,40.0298881530762,2.00009727837272,10.5499997735024,0.0154813986709261,0.0026869940019017,0.25,-6.05028275170374E-7,0.00138834433183925,3.61132929741993E-7,290.2434082,290.2457886,99.998,99.998,60.1009801006987,22.0566635083091,37.451283,0,0,0,480,5906,282.7894,99.998,,,,,,,,,,,,,0,,,,9.25E-6,,,,,,290.2445984,,,,
,26804898.445,623.941955566406,99.998,0.00134227404193631,2.18002648572649E-7,1,11.9910402488375,40.0298881530762,2.00041255009851,10.5600003153086,0.0149740611526207,0.00259724446687228,0.25,-7.38521105959911E-7,0.00134261881687004,2.01732651628852E-7,290.2746582,290.2767029,99.998,99.998,60.037668190641,22.0640919867147,37.832493,0,0,0,480,5906,281.28895,99.998,,,,,,,,,,,,,0,,,,9.25E-6,,,,,,290.27568055,,,,
,26805318.125,658.973083496094,99.998,0.00128931437790583,2.25320685019956E-7,1,11.9910402488375,40.0298881530762,2.00033301711074,10.5400001630187,0.0143833160124908,0.00249104399228851,0.25,-1.04096432827065E-6,0.00128964363430733,-1.31435426671285E-7,290.3121338,290.3128357,99.998,99.998,59.2716722417947,22.0627347459102,38.213703,0,0,0,480,5906,279.61515,99.998,,,,,,,,,,,,,0,,,,9.25E-6,,,,,,290.31248475,,,,
,26805737.955,694.086364746094,99.998,0.00122511020221944,2.17306779315221E-7,1,11.9910402488375,40.0298881530762,2.00021429473084,10.5499997735024,0.0136658144472824,0.00236497101470122,0.25,-1.11066046848664E-6,0.00122535308028768,-2.82368681208146E-7,291.9906006,292.6091003,99.998,99.998,60.5707388407564,22.0566704520019,39.357338,0,0,0,480,5906,289.74515,99.998,,,,,,,,,,,,,0,,,,9.25E-6,,,,,,292.29985045,,,,
,26806169.525,730.192016601562,99.998,0.00113629516836489,2.46753059235935E-7,1,11.9910402488375,40.0298881530762,2.00051524113847,10.5499997735024,0.01267468946511,0.00219971982030843,0.25,-5.1432548881678E-7,0.00113641402770856,2.8393512181791E-7,295.2672424,295.2992249,99.998,99.998,59.6460723025063,22.0632498508624,62.992439,0,0,0,480,5906,280.6074,99.998,,,,,,,,,,,,,0,,,,9.2E-6,,,,,,295.28323365,,,,
,26806589.195,765.271484375,99.998,0.00100846705460971,2.60565724067688E-7,1,11.9910402488375,40.0298881530762,1.99963378640257,10.5499997735024,0.0112428054757142,0.001955740546708,0.25,-6.47537204378498E-8,0.00100852531909999,6.46197286691509E-7,296.8099365,296.8106384,99.998,99.998,60.3589175120449,22.0704442676266,53.080944,0,0,0,480,5906,279.787,99.998,,,,,,,,,,,,,0,,,,9.25E-6,,,,,,296.81028745,,,,
,26807020.875,801.307312011719,99.998,0.0008525759812673,1.09592426163737E-6,1,11.9910402488375,40.0298881530762,1.99974014952762,10.5499997735024,0.00894838471877884,0.0048517468465409,0.25,0.0002868294383065,0.000852387671590735,0.000287436539638965,298.1392212,298.1738586,99.998,99.998,59.7390860962948,22.0713610466088,38.594913,0,0,0,480,5906,279.29805,99.998,,,,,,,,,,,,,0,,,,9.25E-6,,,,,,298.1565399,,,,
,26807440.55,836.430908203125,99.998,0.000386344282924225,6.45503992015454E-7,1,11.9910402488375,40.0298881530762,1.9992235154293,10.5499997735024,0.00406436471173063,0.00213708683902446,0.25,0.000124515978352769,0.000386246235549285,0.000124787320538557,299.4898987,299.5453491,99.998,99.998,59.7062576984871,22.0017735225753,38.594913,0,0,0,480,5906,277.99985,99.998,,,,,,,,,,,,,0,,,,9.2E-6,,,,,,299.5176239,,,,
,26807860.335,869.962036132813,99.998,5.64986151718484E-5,2.71971361342982E-7,1,11.9910402488375,40.0298881530762,2.00114698772741,10.5499997735024,0.000632977131165684,9.37940362687574E-5,0.25,-1.42363070797313E-6,5.6493445399058E-5,-1.38334509843636E-6,302.2653198,302.3632507,99.998,99.998,60.2737200034487,22.0660427868657,37.832493,0,0,0,480,5909,277.99965,99.998,,,,,,,,,,,,,0,,,,9.15E-6,,,,,,302.31428525,,,,
,26808435.915,842.196594238281,99.998,0.000219502868678288,3.24329849114673E-7,1,11.9910402488375,40.0298881530762,2.001496972953,10.5499997735024,0.00245167275115891,0.000409649805250181,0.25,-1.47959476744505E-6,0.000219475051844604,-1.32349351563784E-6,303.0231323,303.0697632,99.998,99.998,60.1846143522564,22.0737612358319,36.688858,0,0,0,480,5906,277.9974,99.998,,,,,,,,,,,,,0,,,,9.3E-6,,,,,,303.04644775,,,,
,26808459.845,840.173950195313,99.998,0.000248885893484879,3.15583026474553E-7,1,11.9910402488375,40.0298881530762,2.00101097854716,10.5499997735024,0.00277870730612431,0.000467318625428898,0.25,-1.41413422700446E-6,0.000248854866461502,-1.23717745284976E-6,302.9300232,302.9765015,99.998,99.998,60.2776281460448,22.0649401212378,37.451283,0,0,0,480,5906,278.00045,99.998,,,,,,,,,,,,,0,,,,9.2E-6,,,,,,302.95326235,,,,