File: DataToTest/7_TbMn0p2Ga3_VSM_DC_Hys_300K_50K_30K_2K_01112022.DAT
[Header]
; VSM Data File (default extension .dat)
; Copyright (c) 2003-2013, Quantum Design, Inc. All rights reserved.
TITLE,7_TbMn0p2Ga3_VSM_DC_Hys_300K_50K_30K_2K_01112022
FILEOPENTIME,6256081.44,11/01/2022,11:28 am
BYAPP,VSM,2.0,2.0
INFO,PPMS VSM Option Release 1.4.10 Build 1,APPNAME
INFO,Quantum Design Linear Motor Servo Controller,MOTOR_MODULE_NAME
INFO,3101-100 C1,MOTOR_HW_VERSION
INFO,074,MOTOR_SERIAL_NUMBER
INFO,SRV No X-over 01.01.11,MOTOR_SOFTWARE_VERSION
INFO,Quantum Design VSM Detection Module,VSM_MODULE_NAME
INFO,3101-150 E1,VSM_HW_VERSION
INFO,VSM061,VSM_SERIAL_NUMBER
INFO,VSM No X-over 01.02.05 May 20 2008 13:51:47,VSM_SOFTWARE_VERSION
INFO,113,PREAMP_SERIAL_NUMBER
INFO,Quantum Design VSM Oven,OVEN_MODULE_NAME
INFO,3101-200 B0,OVEN_HW_VERSION
INFO,OVN054,OVEN_SERIAL_NUMBER
INFO,01.01.00,OVEN_SOFTWARE_VERSION
INFO,221,COIL_SERIAL_NUMBER
INFO,0,MOMENT_UNITS
INFO,7_TbMn0p2Ga3_VSM_DC_Hys_300K_50K_30K_2K_01112022,SAMPLE_MATERIAL
INFO,Ibelieve its the same cristal that was used in ACMSII,SAMPLE_COMMENT
INFO,6.5,SAMPLE_MASS
INFO,,SAMPLE_VOLUME
INFO,,SAMPLE_MOLECULAR_WEIGHT
INFO,,SAMPLE_SIZE
INFO,,SAMPLE_SHAPE
DATATYPE,COMMENT,1
DATATYPE,TIME,2
STARTUPAXIS,X,2
STARTUPAXIS,Y1,5
[Data]
Comment,Time Stamp (sec),Temperature (K),Magnetic Field (Oe),Moment (emu),M. Std. Err. (emu),Transport Action,Averaging Time (sec),Frequency (Hz),Peak Amplitude (mm),Center Position (mm),Coil Signal' (mV),Coil Signal" (mV),Range (mV),M. Quad. Signal (emu),M. Raw' (emu),M. Raw" (emu),Min. Temperature (K),Max. Temperature (K),Min. Field (Oe),Max. Field (Oe),Mass (grams),Motor Lag (deg),Pressure (Torr),VSM Status (code),Motor Status (code),Measure Status (code),Measure Count,PPMS Status (code),System Temp. (K),System Field (Oe),Sample Position (deg),Bridge 1 Resistance (ohms),Bridge 1 Excitation (에),Bridge 2 Resistance (ohms),Bridge 2 Excitation (에),Bridge 3 Resistance (ohms),Bridge 3 Excitation (에),Bridge 4 Resistance (ohms),Bridge 4 Excitation (에),Signal 1 Vin (V),Signal 2 Vin (V),Digital Inputs (code),Drive 1 Iout (mA),Drive 1 Ipower (W),Drive 2 Iout (mA),Drive 2 Ipower (W),Pressure (),Map 20 (),Map 21 (),Map 22 (),Map 23 (),Map 24 (),Map 25 (),Map 26 (),Map 27 (),Map 28 (),Map 29 ()
,6257938.58,299.9841919,-0.078,,,2,,,,8.97999977409839,,,,,,,299.9841919,299.9841919,-0.078,-0.078,,,31.351902,,,,-99999999,4881,300.0444,-0.078,,,,,,,,,,,,,,,,,,,,,,,299.9841919,,,,
,6258766.415,299.99917605,42203.16,0.0255816585051089,1.67811335280561E-6,1,4.99626677034896,40.0298881530762,1.99163828240975,8.96000023931265,0.273222362209749,0.0475770852658917,2.5,3.80691297845022E-5,0.02558088150625,5.4919033191031E-5,299.9985962,299.9997559,42153.73,42252.59,52.8865488681979,18.5350763669626,31.733112,0,0,0,200,4961,299.9858,42203.16,,,,,,,,,,,,,0,,,,5.1035521,,,,,,299.99917605,,,,
,6259136.165,300.00297545,34692.219,0.021027303913244,1.68537502256098E-6,1,4.99626677034896,40.0298881530762,1.99151526127728,8.9699998497963,0.224563194674119,0.0391246484917335,2.5,3.31536068792825E-5,0.0210266593693311,4.70264585361146E-5,300.002655,300.0032959,34643.918,34740.52,52.2800051372748,18.5431939059131,31.733112,0,0,0,200,4961,299.9976,34692.219,,,,,,,,,,,,,0,,,,5.12929985,,,,,,300.00297545,,,,
,6259505.915,299.99362185,27192.149,0.0164775568590462,1.57710171728609E-6,1,4.99626677034896,40.0298881530762,1.99128189222197,8.9699998497963,0.175965179155772,0.0305907085876546,2.5,1.9880324861904E-5,0.0164770591944159,3.07688183770176E-5,299.9933777,299.993866,27140.318,27243.98,52.6958315095056,18.5506344664507,31.733112,0,0,0,200,4961,300.0087,27192.149,,,,,,,,,,,,,0,,,,5.3381476,,,,,,299.99362185,,,,
,6259880.6,299.99684145,19595.4285,0.0118613361738009,1.27855110047124E-6,1,4.99626677034896,40.0298881530762,1.99163334102269,8.96000023931265,0.12669068835046,0.0220181248577655,2.5,1.37128961582823E-5,0.0118609760138196,2.15628888825511E-5,299.9963074,299.9973755,19544.867,19645.99,52.5778056031017,18.55191706303,31.733112,0,0,0,200,4961,300.01775,19595.4285,,,,,,,,,,,,,0,,,,5.3654802,,,,,,299.99684145,,,,
,6260250.32,299.99752805,12090.3855,0.00730053057891758,1.30411053054894E-6,1,4.99626677034896,40.0298881530762,1.99176240268552,8.9699998497963,0.0779811817682978,0.0135555291058418,2.5,8.69165749728038E-6,0.00730030796992606,1.35298919572598E-5,299.997406,299.9976501,12040.389,12140.382,52.4441471263132,18.5431566175001,31.733112,0,0,0,200,4961,300.0294,12090.3855,,,,,,,,,,,,,0,,,,5.5557761,,,,,,299.99752805,,,,
,6260635.15,299.99935915,4201.7055,0.00249905010529995,1.43155899720843E-6,1,4.99626677034896,40.0298881530762,1.99167950968335,8.9699998497963,0.0266947666117708,0.00462820223887053,2.5,1.86716148846264E-6,0.00249897429646883,3.52551649493544E-6,299.9984436,300.0002747,4143.8,4259.611,52.7661780762363,18.5533523477415,31.733112,0,0,0,200,4961,300.03205,4201.7055,,,,,,,,,,,,,0,,,,5.2777231,,,,,,299.99935915,,,,
,6261254.635,300.00027465,-7784.433,-0.00478501496593272,1.30699848752354E-6,1,4.99626677034896,40.0298881530762,1.99167768381422,8.9699998497963,-0.0511102368620084,-0.0088796243721484,2.5,-5.24850368487777E-6,-0.00478486872419096,-8.42197240219766E-6,299.9997253,300.000824,-7837.961,-7730.905,52.6606582261402,18.5536485145952,31.733112,0,0,0,200,4961,300.03315,-7784.433,,,,,,,,,,,,,0,,,,5.9581923,,,,,,300.00027465,,,,
,6261624.32,299.99664305,-14662.002,-0.00893510136727255,1.22656769397309E-6,1,4.99626677034896,40.0298881530762,1.99160425870613,8.9699998497963,-0.0954377163919419,-0.0165661036367999,2.5,-8.46758274719723E-6,-0.00893483085326146,-1.43864674522786E-5,299.996582,299.9967041,-14706.066,-14617.938,52.8083860162748,18.5500599336894,31.733112,0,0,0,200,4961,300.0247,-14662.002,,,,,,,,,,,,,0,,,,6.1089461,,,,,,299.99664305,,,,
,6261999.06,299.99839785,-21667.2685,-0.0131691863051168,1.14405150371396E-6,1,4.99626677034896,40.0298881530762,1.99154416333611,8.9699998497963,-0.140663705621044,-0.0243872166170104,2.5,-9.83548736030431E-6,-0.0131687896651951,-1.85476214758715E-5,299.9980469,299.9987488,-21714.016,-21620.521,52.6082891153517,18.5557734858083,31.733112,0,0,0,200,4961,300.01665,-21667.2685,,,,,,,,,,,,,0,,,,5.7533903,,,,,,299.99839785,,,,
,6262373.81,300.0010376,-28664.4405,-0.0174022398684501,1.32298275674744E-6,1,4.99626677034896,40.0298881530762,1.99160979294399,8.9699998497963,-0.185884539355013,-0.0322240113121672,2.5,-1.27175382458142E-5,-0.0174017159178892,-2.42137832997179E-5,299.9998169,300.0022583,-28711.188,-28617.693,52.6528419409479,18.5560097209511,31.733112,0,0,0,200,4961,300.00725,-28664.4405,,,,,,,,,,,,,0,,,,6.48630735,,,,,,300.0010376,,,,
,6262753.48,300.00057985,-35755.229,-0.0216902323194803,1.26376419206371E-6,1,4.99626677034896,40.0298881530762,1.99163397504788,8.9699998497963,-0.231691200695297,-0.0401580968527232,2.5,-1.52608848307071E-5,-0.021689581883561,-2.95687563576687E-5,300,300.0011597,-35801.27,-35709.188,52.717717108044,18.5590410178905,31.733112,0,0,0,200,4961,299.9894,-35755.229,,,,,,,,,,,,,0,,,,6.6502576,,,,,,300.00057985,,,,
,6263123.22,300.0003052,-42655.633,-0.0258604495147958,1.36397573614817E-6,1,4.99626677034896,40.0298881530762,1.99160073423199,8.96000023931265,-0.276235312879933,-0.0478608974347094,2.5,-1.65982969023283E-5,-0.0258596776202182,-3.36314295351385E-5,299.9996338,300.0009766,-42704.922,-42606.344,52.626266571294,18.5606427336631,31.733112,0,0,0,200,4961,299.9749,-42655.633,,,,,,,,,,,,,0,,,,6.4655061,,,,,,300.0003052,,,,
,6263497.95,300.00698855,-49617.0505,-0.0300733871180588,6.94468544850808E-7,1,4.99626677034896,40.0298881530762,1.99160266912488,8.9699998497963,-0.321235748687314,-0.0556663531766911,2.5,-2.01166692977017E-5,-0.0300724852551855,-3.98938149391295E-5,300.0065308,300.0074463,-49657.984,-49576.117,52.710682451371,18.5634910609318,31.733112,0,0,0,200,4961,299.9576,-49617.0505,,,,,,,,,,,,,0,,,,6.990869,,,,,,300.00698855,,,,
,6263912.665,299.9923096,-42328.75,-0.0256427374248149,1.68618042378191E-6,1,4.99626677034896,40.0298881530762,1.99140500640013,8.96000023931265,-0.273886285947355,-0.0474402697950408,2.5,-1.52177777584318E-5,-0.0256419792865024,-3.21092138780732E-5,299.992157,299.9924622,-42382.418,-42275.082,52.6434623987171,18.5652164215067,31.733112,0,0,0,200,4961,299.96905,-42328.75,,,,,,,,,,,,,0,,,,6.605191,,,,,,299.9923096,,,,
,6264282.345,300.00265505,-34737.879,-0.0210392290047202,1.29222096407814E-6,1,4.99626677034896,40.0298881530762,1.99131624432172,8.96000023931265,-0.224708448600288,-0.038914562485972,2.5,-1.17775788136833E-5,-0.0210385983645198,-2.56596384181682E-5,300.002533,300.0027771,-34786.746,-34689.012,52.677072425044,18.5644532042228,31.733112,0,0,0,200,4961,299.98205,-34737.879,,,,,,,,,,,,,0,,,,6.8972914,,,,,,300.00265505,,,,
,6264652.095,299.99850465,-27154.4815,-0.0164409003615552,1.5182762142342E-6,1,4.99626677034896,40.0298881530762,1.99139516553793,8.96000023931265,-0.175602920319405,-0.0304105085168519,2.5,-9.18101761987366E-6,-0.016440408195652,-2.00463678840632E-5,299.9981079,299.9989014,-27205.467,-27103.496,52.6035993442363,18.5625418575669,31.733112,0,0,0,200,4961,299.9927,-27154.4815,,,,,,,,,,,,,0,,,,7.34929275,,,,,,299.99850465,,,,
,6265021.84,300.001297,-19572.0255,-0.0118416149787582,1.45180924078484E-6,1,4.99626677034896,40.0298881530762,1.99125014589171,8.9699998497963,-0.12647110135173,-0.0218938841504232,2.5,-5.86520119396821E-6,-0.0118412588332375,-1.3703117803711E-5,300.0006409,300.0019531,-19625.553,-19518.498,52.6372093705633,18.5666442501972,31.733112,0,0,0,200,4961,299.99475,-19572.0255,,,,,,,,,,,,,0,,,,7.38802865,,,,,,300.001297,,,,
,6265391.535,300.00076295,-11986.1945,-0.00723314477890718,1.40501290659229E-6,1,4.99626677034896,40.0298881530762,1.99088321333573,8.9699998497963,-0.0772364130358076,-0.0133798052925301,2.5,-4.40522644532434E-6,-0.00723292620459391,-9.19954112993758E-6,300.0005188,300.0010071,-12036.895,-11935.494,52.5176202071209,18.5716769452973,31.733112,0,0,0,200,4961,300.00165,-11986.1945,,,,,,,,,,,,,0,,,,7.7253218,,,,,,300.00076295,,,,
,6265820.455,299.9992676,-3103.5075,-0.00188491441056193,1.39836723144032E-6,1,4.99626677034896,40.0298881530762,1.99060502216856,8.96000023931265,-0.0201280240801244,-0.00350261927096677,0.25,-2.58297629083817E-6,-0.00188485643074302,-3.83405263027098E-6,299.9992676,299.9992676,-3105.344,-3101.671,52.6067258583133,18.5774278191069,31.733112,0,0,0,200,4961,300.0121,-3103.5075,,,,,,,,,,,,,0,,,,6.7875111,,,,,,299.9992676,,,,
,6266405.845,300.00439455,8291.5615,0.00509148928130426,1.27380710634785E-6,1,4.99626677034896,40.0298881530762,1.99059807305896,8.9699998497963,0.0543657980639726,0.00938371307680691,2.5,-8.69915607459658E-9,0.00509133670643151,3.36821587388384E-6,300.0042725,300.0045166,8243.685,8339.438,52.8928018963518,18.5777158552418,31.733112,0,0,0,200,4961,300.0101,8291.5615,,,,,,,,,,,,,0,,,,8.08063365,,,,,,300.00439455,,,,
,6266775.505,300.0014343,15231.129,0.00927520931426722,1.2972174112086E-6,1,4.99626677034896,40.0298881530762,1.99069202027974,8.9699998497963,0.0990401900780343,0.0171122493253952,2.5,1.59143735136172E-6,0.00927493186517258,7.73559396019443E-6,300.0012512,300.0016174,15185.512,15276.746,52.8154206729479,18.5760251966162,31.351902,0,0,0,200,4961,300.00745,15231.129,,,,,,,,,,,,,0,,,,8.08063365,,,,,,300.0014343,,,,
,6267145.26,300.0009155,22221.8495,0.0134981780999234,1.20168345991364E-6,1,4.99626677034896,40.0298881530762,1.99118793852617,8.96000023931265,0.144165212947869,0.024921408244111,2.5,3.45716785918869E-6,0.0134977748919208,1.23865806192986E-5,300.0003662,300.0014648,22172.842,22270.857,52.8513755848325,18.5660875591736,31.733112,0,0,0,200,4961,300.00415,22221.8495,,,,,,,,,,,,,0,,,,8.2025299,,,,,,300.0009155,,,,
,6267515.03,300.00190735,29207.8605,0.017721193362105,1.29622995920308E-6,1,4.99626677034896,40.0298881530762,1.99092820213441,8.96000023931265,0.189244534222593,0.032715700195986,2.5,4.69802020811932E-6,0.0177206648655779,1.64040991986401E-5,300.0016174,300.0021973,29163.514,29252.207,53.1147843958133,18.5693473484663,31.351902,0,0,0,200,4961,300.002,29207.8605,,,,,,,,,,,,,0,,,,8.1209955,,,,,,300.00190735,,,,
,6267884.71,300.0032501,36191.596,0.0219423654561951,1.38404019166683E-6,1,4.99626677034896,40.0298881530762,1.9910350829124,8.9699998497963,0.23433473100155,0.0405092438524099,2.5,5.70723417928675E-6,0.021941712063504,2.01809532825015E-5,300.0028381,300.0036621,36142.305,36240.887,52.8928018963518,18.5689908239135,31.733112,0,0,0,200,4961,299.97795,36191.596,,,,,,,,,,,,,0,,,,8.08063365,,,,,,300.0032501,,,,
,6268264.445,300.00247195,43355.1095,0.0262730311257377,1.48627401808787E-6,1,4.99626677034896,40.0298881530762,1.99106823524134,8.96000023931265,0.280586526668434,0.0485185339263734,2.5,8.11479338514886E-6,0.0262722511150852,2.54169660662065E-5,300.0020447,300.0028992,43307.797,43402.422,53.0874273976402,18.5691914487534,31.733112,0,0,0,200,4961,299.9775,43355.1095,,,,,,,,,,,,,0,,,,8.0402718,,,,,,300.00247195,,,,
,6274053.83,50.0034828,49962.2465,0.151090486527096,6.98104860026744E-6,1,4.99626677034896,40.0298881530762,1.99061416169413,9.92999970912933,1.61202527001804,0.300753301077549,25,0.00107782116459501,0.151271139643035,0.00214674270833429,50.0034828,50.0034828,49960.973,49963.52,52.5184018356402,18.5485064433441,31.733112,0,0,0,200,4961,49.8656,49962.2465,,,,,,,,,,,,,0,,,,3.8008451,,,,,,50.0034828,,,,
,6274419.9,49.99862485,42015.1795,0.132340759557506,7.76752395013084E-6,1,4.99626677034896,40.0298881530762,1.9906081538545,9.92000009864569,1.41141800734555,0.263306535860953,25,0.000926271560795331,0.1324463922303,0.0018778027740194,49.9986115,49.9986382,41965.043,42065.316,52.8591918700248,18.5477537647539,31.351902,0,0,0,200,4961,49.8669,42015.1795,,,,,,,,,,,,,0,,,,3.6902821,,,,,,49.99862485,,,,
,6274789.675,49.9980068,34504.9455,0.114287974794591,7.84539167905305E-6,1,4.99626677034896,40.0298881530762,1.99072942888041,9.92999970912933,1.21847897708271,0.227291041295876,25,0.000786875578684933,0.114334114916193,0.00161903013000168,49.997818,49.9981956,34455.797,34554.094,53.1773146773518,18.5560301661525,31.733112,0,0,0,200,4961,49.86965,34504.9455,,,,,,,,,,,,,0,,,,3.7630644,,,,,,49.9980068,,,,
,6275159.335,49.9973755,27007.2765,0.0957043475829652,7.31121223323239E-6,1,4.99626677034896,40.0298881530762,1.99060468629005,9.92000009864569,1.01988517789746,0.190183052273319,25,0.000645905131483748,0.0957041395581062,0.0013495096392977,49.9973526,49.9973984,26954.174,27060.379,52.8396511570441,18.5577873926734,31.733112,0,0,0,200,4961,49.87975,27007.2765,,,,,,,,,,,,,0,,,,3.7256589,,,,,,49.9973755,,,,
,6275534.115,49.9965725,19409.1425,0.0760042183994483,7.14381410792432E-6,1,4.99626677034896,40.0298881530762,1.99053658636673,9.92000009864569,0.809577631344788,0.150992978636547,25,0.000511238979849158,0.075972184627886,0.00107372306425313,49.99646,49.996685,19356.463,19461.822,53.7252362693326,18.5622659415915,31.733112,0,0,0,200,4961,49.8887,19409.1425,,,,,,,,,,,,,0,,,,3.7071421,,,,,,49.9965725,,,,
,6275903.805,49.9994469,11905.793,0.0550062482785817,7.34307978666361E-6,1,4.99626677034896,40.0298881530762,1.9905746600933,9.92000009864569,0.585671901149862,0.109298244150393,25,0.000374275290603886,0.0549604941799574,0.000782708308235237,49.9993706,49.9995232,11853.677,11957.909,53.4493214020441,18.5639556636719,31.733112,0,0,0,200,4961,49.8938,11905.793,,,,,,,,,,,,,0,,,,3.46193775,,,,,,49.9994469,,,,
,6276278.515,49.999012,4265.5415,0.0299090512622933,0.000736645427521556,1,4.99626677034896,40.0298881530762,1.9905876485585,9.92999970912933,0.317390945987904,0.0640954287393085,2.5,0.000645030065084023,0.0298693115666326,0.000866667053878395,49.9987602,49.9992638,4233.623,4297.46,52.8537204703902,18.5651765960495,31.733112,0,0,0,200,4961,49.8926,4265.5415,,,,,,,,,,,,,0,,,,3.6702927,,,,,,49.999012,,,,
,6276663.235,49.9999466,-3418.4865,-0.0265765347539302,9.92201067167257E-6,1,4.99626677034896,40.0298881530762,1.99064242320328,9.92000009864569,-0.282778280086693,-0.0527503356794869,2.5,-0.000178648618334767,-0.0265431500152582,-0.000376028923180684,49.9999466,49.9999466,-3468.2,-3368.773,52.8177655585056,18.5666052485441,32.114323,0,0,0,200,4961,49.89385,-3418.4865,,,,,,,,,,,,,0,,,,3.6702927,,,,,,49.9999466,,,,
,6277032.965,49.9988022,-10276.8995,-0.0506006584749587,5.94137682813926E-6,1,4.99626677034896,40.0298881530762,1.99052701156631,9.92999970912933,-0.538558537594036,-0.100423836920453,2.5,-0.000336667464364115,-0.0505542934400253,-0.000712509396647078,49.9987717,49.9988327,-10325.625,-10228.174,52.7435108491787,18.5710042421045,31.733112,0,0,0,200,4961,49.89695,-10276.8995,,,,,,,,,,,,,0,,,,3.6158396,,,,,,49.9988022,,,,
,6277407.73,49.9979153,-17247.9515,-0.0704522098168688,5.79788802543714E-6,1,4.99626677034896,40.0298881530762,1.99045969685582,9.92000009864569,-0.75009184001916,-0.139940538290666,2.5,-0.000476947122035598,-0.070414266851473,-0.000998997448163128,49.9977837,49.9980469,-17295.688,-17200.215,53.0913355402364,18.5704733331604,31.733112,0,0,0,200,4961,49.89925,-17247.9515,,,,,,,,,,,,,0,,,,3.615659,,,,,,49.9979153,,,,
,6277782.485,49.9996567,-24264.8035,-0.088909396227331,5.70271036415194E-6,1,4.99626677034896,40.0298881530762,1.99036125078846,9.92000009864569,-0.946924708213497,-0.176669536024192,2.5,-0.000606429661933787,-0.0888961217564528,-0.00126183940933248,49.9996376,49.9996758,-24309.857,-24219.75,52.9787810334671,18.575215765208,31.733112,0,0,0,200,4961,49.90035,-24264.8035,,,,,,,,,,,,,0,,,,3.42752565,,,,,,49.9996567,,,,
,6278162.125,49.9998493,-31350.657,-0.106711901393416,5.25582635673261E-6,1,4.99626677034896,40.0298881530762,1.99056443014912,9.92000009864569,-1.13709918007504,-0.212061578406904,2.5,-0.000726687445588855,-0.106737615902019,-0.00150700085950062,49.9996948,50.0000038,-31397.406,-31303.908,53.3797564638326,18.5755454151824,31.733112,0,0,0,200,4961,49.90115,-31350.657,,,,,,,,,,,,,0,,,,3.37297165,,,,,,49.9998493,,,,
,6278536.83,49.99961665,-38348.5135,-0.123728194468081,6.91120621070659E-6,1,4.99626677034896,40.0298881530762,1.99061218639614,9.92999970912933,-1.319309708259,-0.246210769722897,25,-0.00086798830380322,-0.123804146008628,-0.00176320733946432,49.9995003,49.999733,-38393.707,-38303.32,52.4621245822556,18.5736898719915,31.733112,0,0,0,200,4961,49.8987,-38348.5135,,,,,,,,,,,,,0,,,,3.1125,,,,,,49.99961665,,,,
,6278906.61,49.9997234,-45240.301,-0.140062595733689,8.30884479953021E-6,1,4.99626677034896,40.0298881530762,1.99058404732514,9.92999970912933,-1.4940244264084,-0.278626766312499,25,-0.000978982975024351,-0.14019833224424,-0.00197951098515764,49.999649,49.9997978,-45287.473,-45193.129,52.616105400544,18.5737140769673,31.733112,0,0,0,200,4961,49.89855,-45240.301,,,,,,,,,,,,,0,,,,3.5797191,,,,,,49.9997234,,,,
,6279321.27,49.9985447,-47310.244,-0.144889688528158,8.04853870391079E-6,1,4.99626677034896,40.0298881530762,1.99045205227179,9.92999970912933,-1.54558162063714,-0.288211846714821,25,-0.00101463635820765,-0.145045187590411,-0.00204522121910485,49.9983635,49.9987259,-47366.453,-47254.035,52.4238247848132,18.5757437936234,31.733112,0,0,0,200,4961,49.90215,-47310.244,,,,,,,,,,,,,0,,,,3.5797191,,,,,,49.9985447,,,,
,6279691,49.99809265,-39588.5915,-0.126604566528941,7.17763733114149E-6,1,4.99626677034896,40.0298881530762,1.99052353328356,9.92999970912933,-1.35004534520924,-0.251756641676019,25,-0.000873064586952077,-0.126690824756532,-0.00178708170267961,49.9979668,49.9982185,-39640.281,-39536.902,53.0420929435248,18.5671719345156,31.733112,0,0,0,200,4961,49.9059,-39588.5915,,,,,,,,,,,,,0,,,,3.52652155,,,,,,49.99809265,,,,
,6280060.74,49.9990082,-32002.5185,-0.108192972679631,6.53591115237565E-6,1,4.99626677034896,40.0298881530762,1.99046119288497,9.92000009864569,-1.15324401338273,-0.214886587122094,25,-0.000720709301051051,-0.108223200166005,-0.00151111291291172,49.9989319,49.9990845,-32053.361,-31951.676,52.6450256557556,18.5698688160381,32.495537,0,0,0,200,4961,49.90905,-32002.5185,,,,,,,,,,,,,0,,,,3.52652155,,,,,,49.9990082,,,,
,6280435.51,49.9985466,-24316.583,-0.0888588198110464,7.2747316708526E-6,1,4.99626677034896,40.0298881530762,1.99036387651102,9.92000009864569,-0.946694578270238,-0.176520461763466,25,-0.000596531309530695,-0.0888461582230694,-0.00125150217942265,49.9984703,49.9986229,-24367.85,-24265.316,52.3511333325248,18.5732752794259,31.733112,0,0,0,200,4961,49.91235,-24316.583,,,,,,,,,,,,,0,,,,3.1451613,,,,,,49.9985466,,,,
,6280805.195,49.99941065,-16742.7315,-0.0687715021330325,6.27369158605516E-6,1,4.99626677034896,40.0298881530762,1.99057998796988,9.92999970912933,-0.732442081408994,-0.136646262811264,25,-0.000465298971063248,-0.0687328319536615,-0.00097501010970284,49.9991379,49.9996834,-16794.705,-16690.758,52.8443409281594,18.569767991436,31.733112,0,0,0,200,4961,49.9138,-16742.7315,,,,,,,,,,,,,0,,,,3.5089071,,,,,,49.99941065,,,,
,6281174.9,49.99811935,-9132.181,-0.0465267249006381,6.93062214213914E-6,1,4.99626677034896,40.0298881530762,1.99051231553017,9.92000009864569,-0.495306656893815,-0.0924143695513466,25,-0.000314532050622184,-0.046481544828832,-0.000660153114616901,49.9980545,49.9981842,-9184.861,-9079.501,52.4605613252171,18.5650035685844,32.114323,0,0,0,200,4961,49.9162,-9132.181,,,,,,,,,,,,,0,,,,3.4740279,,,,,,49.99811935,,,,
,6281549.68,49.99987985,-1394.707,-0.014647082888029,0.000210355919486924,1,4.99626677034896,40.0298881530762,1.9904925322346,9.92999970912933,-0.155491432387461,-0.0309191737407042,2.5,-0.000272283705323841,-0.0146262687131997,-0.000380808908497116,49.9994774,50.0002823,-1442.162,-1347.252,52.6676928828133,18.5729847528261,31.733112,0,0,0,200,4961,49.915,-1394.707,,,,,,,,,,,,,0,,,,3.24974275,,,,,,49.99987985,,,,
,6281949.395,49.9983082,6362.1805,0.0379195262880044,2.8518015469782E-5,1,4.99626677034896,40.0298881530762,1.99038338344092,9.92999970912933,0.403486423149579,0.0752211019352301,2.5,0.00025066846865709,0.0378774937857996,0.000532379461735671,49.9981499,49.9984665,6308.794,6415.567,52.5332527775056,18.5649143280719,31.733112,0,0,0,200,4961,49.9213,6362.1805,,,,,,,,,,,,,0,,,,3.2242572,,,,,,49.9983082,,,,
,6282319.055,50.0006943,13308.261,0.0594888093836397,6.11169415943651E-6,1,4.99626677034896,40.0298881530762,1.99042256176463,9.92999970912933,0.633231738748164,0.118085417957286,2.5,0.000397003898829335,0.0594443518451177,0.000838538141697231,50.0004616,50.000927,13261.653,13354.869,52.8240185866594,18.5706641346737,31.733112,0,0,0,200,4961,49.9208,13308.261,,,,,,,,,,,,,0,,,,3.4740279,,,,,,50.0006943,,,,
,6282688.815,49.99979785,20296.669,0.0785827891399947,5.76195988584401E-6,1,4.99626677034896,40.0298881530762,1.9903596081263,9.92999970912933,0.836789511792153,0.155962245989671,2.5,0.000519453015580428,0.0785543388473355,0.00110060071614875,49.9997292,49.9998665,20250.627,20342.711,52.7622699336402,18.5695262737059,31.733112,0,0,0,200,4961,49.92275,20296.669,,,,,,,,,,,,,0,,,,3.4740279,,,,,,49.99979785,,,,
,6283058.58,49.99921415,27286.6915,0.0965420640368451,5.56966187997963E-6,1,4.99626677034896,40.0298881530762,1.99043918908989,9.92999970912933,1.02844847716187,0.191786747995889,2.5,0.000652591482509911,0.0965443929393565,0.00136197991051564,49.9989891,49.9994392,27240.227,27333.156,52.2034055423901,18.5629178285508,32.114323,0,0,0,200,4961,49.92315,27286.6915,,,,,,,,,,,,,0,,,,3.4059863,,,,,,49.99921415,,,,
,6283433.22,50.0003815,34360.1135,0.114054773931264,7.18136784932738E-6,1,4.99626677034896,40.0298881530762,1.99055538362222,9.92000009864569,1.21589733849485,0.226798661036176,25,0.000784387736300743,0.114101274509714,0.00161475248534348,50.0002251,50.0005379,34312.516,34407.711,52.4965162371017,18.5620878721705,31.733112,0,0,0,200,4961,49.92035,34360.1135,,,,,,,,,,,,,0,,,,3.2473158,,,,,,50.0003815,,,,
,6283802.98,49.9991913,41337.7695,0.130816431487523,7.82609946121858E-6,1,4.99626677034896,40.0298881530762,1.99040701122659,9.92000009864569,1.39504242016738,0.259966768898655,25,0.000888953220749744,0.130917961729535,0.00183029633353067,49.9988098,49.9995728,41291.023,41384.516,53.1515209362172,18.5715729277482,31.733112,0,0,0,200,4961,49.92115,41337.7695,,,,,,,,,,,,,0,,,,3.2150371,,,,,,49.9991913,,,,
,6284172.735,49.9994469,48304.412,0.147145330136065,8.27450858064896E-6,1,4.99626677034896,40.0298881530762,1.99034374431246,9.92999970912933,1.56966124025864,0.292598694542174,25,0.00102352677138207,0.14731101649314,0.00206779162488681,49.9993935,49.9995003,48255.121,48353.703,52.8943651533902,18.5651491470823,31.733112,0,0,0,200,4961,49.91935,48304.412,,,,,,,,,,,,,0,,,,3.45676185,,,,,,49.9994469,,,,
,6286610.905,25.0008907,44067.828,0.195653885912551,1.14940401474862E-5,1,4.99626677034896,40.0298881530762,2.00445281387021,10.499999858439,2.09422711929188,0.388677356049335,25,0.00116177914653399,0.195187242695801,0.00258619707942047,25.0007915,25.0009899,44014.867,44120.789,52.1768301727363,18.5496938247951,30.208265,0,0,0,200,4961,24.971,44067.828,,,,,,,,,,,,,0,,,,2.816592,,,,,,25.0008907,,,,
,6286980.655,24.99633215,36540.082,0.173385105595635,1.2671370999826E-5,1,4.99626677034896,40.0298881530762,2.00457657993457,10.499999858439,1.85464725782781,0.343567035919952,25,0.00100471231383702,0.172837538493378,0.00223189459040121,24.9962177,24.9964466,36488.391,36591.773,52.5527934904863,18.5552869654361,31.733112,0,0,0,200,4961,24.96625,36540.082,,,,,,,,,,,,,0,,,,2.7610135,,,,,,24.99633215,,,,
,6287350.32,24.99794865,29038.884,0.150607447121099,9.72073945446441E-6,1,4.99626677034896,40.0298881530762,2.00446437252899,10.499999858439,1.60975271777349,0.297674593376176,25,0.000868391353929742,0.150015301082525,0.0018897310448842,24.997694,24.9982033,28986.205,29091.563,52.8888937537556,18.5565468864939,31.733112,0,0,0,200,4961,24.97085,29038.884,,,,,,,,,,,,,0,,,,2.80259335,,,,,,24.99794865,,,,
,6287725.095,24.99869535,21439.3785,0.126727184452334,9.64332521371128E-6,1,4.99626677034896,40.0298881530762,2.00448420913028,10.499999858439,1.35361601922643,0.249553471438713,25,0.000711346595046345,0.126132589781022,0.00152070715648129,24.9985485,24.9988422,21390.23,21488.527,52.8842039826402,18.5527856277459,31.733112,0,0,0,200,4961,24.97075,21439.3785,,,,,,,,,,,,,0,,,,2.80259335,,,,,,24.99869535,,,,
,6288094.845,24.9986925,13942.636,0.101912461748017,9.70609409729217E-6,1,4.99626677034896,40.0298881530762,2.00448436359221,10.499999858439,1.08787874114287,0.200083289777711,25,0.000575986094919117,0.1013632295324,0.00117893160461704,24.9983387,24.9990463,13893.345,13991.927,52.6168870290633,18.559458787469,31.733112,0,0,0,200,4961,24.97425,13942.636,,,,,,,,,,,,,0,,,,2.7339779,,,,,,24.9986925,,,,
,6288464.54,24.99879075,6395.338,0.0740339386423898,9.93055832088772E-6,1,4.99626677034896,40.0298881530762,2.00454865317911,10.499999858439,0.789875157225788,0.144974929143104,25,0.000429242794767226,0.0735897988693718,0.000828921612299903,24.9984741,24.9991074,6341.387,6449.289,52.924067037121,18.5601573240081,31.733112,0,0,0,200,4961,24.9767,6395.338,,,,,,,,,,,,,0,,,,2.7747353,,,,,,24.99879075,,,,
,6288839.25,24.9993639,-1185.5615,-0.0476074920748065,2.66903071765261E-5,1,4.99626677034896,40.0298881530762,2.00461008817281,10.499999858439,-0.507646488178329,-0.0930402741848103,2.5,-0.00027950759812321,-0.0473062612273661,-0.000520782950732323,24.9991112,24.9996166,-1237.536,-1133.587,53.0944620543133,18.5655575215622,31.733112,0,0,0,200,4961,24.9767,-1185.5615,,,,,,,,,,,,,0,,,,2.7747353,,,,,,24.9993639,,,,
,6289214.055,25.00033285,-8210.5305,-0.0818580749775027,9.34900213416269E-6,1,4.99626677034896,40.0298881530762,2.00458971436112,10.499999858439,-0.873224260915881,-0.160288410024418,2.5,-0.000465857760811016,-0.0813781189586594,-0.00091804344679046,25.0001831,25.0004826,-8264.48,-8156.581,53.1812228199479,18.5660496401956,32.114323,0,0,0,200,4961,24.9769,-8210.5305,,,,,,,,,,,,,0,,,,2.7747353,,,,,,25.00033285,,,,
,6289583.67,25.00002385,-15106.175,-0.106255402298831,7.44703219174509E-6,1,4.99626677034896,40.0298881530762,2.00449633686874,10.5100004002452,-1.13401056882986,-0.208644041454267,2.5,-0.00059931379207108,-0.105693764414858,-0.00123616592041977,24.9998169,25.0002308,-15152.358,-15059.992,52.7356945639863,18.5669748788901,32.495537,0,0,0,200,4961,24.97655,-15106.175,,,,,,,,,,,,,0,,,,2.7608759,,,,,,25.00002385,,,,
,6289963.49,25.00045965,-22207.0575,-0.12945578733865,9.53859918006693E-6,1,4.99626677034896,40.0298881530762,2.00460369429158,10.499999858439,-1.38292240543852,-0.255087693258658,25,-0.000732920903681041,-0.128858089517581,-0.00156539865339164,25.0001297,25.0007896,-22249.568,-22164.547,52.619231914621,18.5631190840982,31.733112,0,0,0,200,4961,24.97525,-22207.0575,,,,,,,,,,,,,0,,,,2.57761835,,,,,,25.00045965,,,,
,6290333.15,25.00057605,-29108.8945,-0.151048858779346,1.01735713949076E-5,1,4.99626677034896,40.0298881530762,2.00450829013355,10.499999858439,-1.61451731365205,-0.298551088258709,25,-0.000870039072665749,-0.150456089119849,-0.00189487161432464,25.0004883,25.0006638,-29152.959,-29064.83,52.6035993442363,18.5637005808564,32.114323,0,0,0,200,4961,24.9739,-29108.8945,,,,,,,,,,,,,0,,,,2.6159147,,,,,,25.00057605,,,,
,6290707.875,25.0003319,-36108.7285,-0.172260092555921,1.11066819631071E-5,1,4.99626677034896,40.0298881530762,2.00448856113316,10.499999858439,-1.84246581271506,-0.341239671786641,25,-0.000994177983321056,-0.171708460404529,-0.00221093473724519,25.0001526,25.0005112,-36155.195,-36062.262,52.4402389837171,18.5670836830392,31.733112,0,0,0,200,4961,24.97175,-36108.7285,,,,,,,,,,,,,0,,,,2.6034975,,,,,,25.0003319,,,,
,6291077.625,24.9999981,-43000.8005,-0.192684739782585,1.14988999515658E-5,1,4.99626677034896,40.0298881530762,2.00451495802731,10.499999858439,-2.06230779103447,-0.382607715288531,25,-0.00113519523199478,-0.192204306408569,-0.00253355479328079,24.9998951,25.0001011,-43045.57,-42956.031,53.0209889735056,18.5624378402841,31.733112,0,0,0,200,4961,24.97185,-43000.8005,,,,,,,,,,,,,0,,,,2.7747353,,,,,,24.9999981,,,,
,6291482.305,24.99970915,-50001.277,-0.213042206803393,1.05604009789024E-5,1,4.99626677034896,40.0298881530762,2.00452858072241,10.5100004002452,-2.28171216466757,-0.423924705811546,25,-0.0012866814826497,-0.212660618525984,-0.00285836811025863,24.9996777,24.9997406,-50002.57,-49999.984,51.9923658421978,18.5647746332431,31.733112,0,0,0,200,4929,24.9705,-50001.277,,,,,,,,,,,,,0,,,,2.7608759,,,,,,24.99970915,,,,
,6291867.01,25.0003567,-41946.16,-0.189470673482506,1.205337311528E-5,1,4.99626677034896,40.0298881530762,2.00447880299812,10.499999858439,-2.02766579275543,-0.376106754276178,25,-0.00111398775197384,-0.188977837616306,-0.00248435305173698,25.0001755,25.0005379,-41998.84,-41893.48,52.4918264659863,18.5650332336259,31.733112,0,0,0,200,4961,24.9721,-41946.16,,,,,,,,,,,,,0,,,,2.7747353,,,,,,25.0003567,,,,
,6292236.795,24.998991,-34351.752,-0.166844332726692,8.92669612228036E-6,1,4.99626677034896,40.0298881530762,2.00447570457234,10.499999858439,-1.78420391344908,-0.330440291078641,25,-0.000972137202579404,-0.166279633114591,-0.00214023935074545,24.9988098,24.9991722,-34403.441,-34300.063,52.8560653559479,18.5601026160695,31.733112,0,0,0,200,4961,24.9718,-34351.752,,,,,,,,,,,,,0,,,,2.7608759,,,,,,24.998991,,,,
,6292606.49,24.99950885,-26766.52,-0.143608422138057,1.19471549458323E-5,1,4.99626677034896,40.0298881530762,2.0043811734216,10.499999858439,-1.53460732727149,-0.283309431530561,25,-0.000800778058620234,-0.143010792260439,-0.00175919713387942,24.9994259,24.9995918,-26820.188,-26712.852,52.2776602517171,18.5648795476912,31.733112,0,0,0,200,4961,24.97595,-26766.52,,,,,,,,,,,,,0,,,,2.54894365,,,,,,24.99950885,,,,
,6292976.19,24.999691,-19193.2405,-0.119476751212861,9.30999991384097E-6,1,4.99626677034896,40.0298881530762,2.00448872064841,10.499999858439,-1.27595595578788,-0.234893082164895,25,-0.000655296731804581,-0.118890491485746,-0.00140248423614833,24.999649,24.999733,-19244.225,-19142.256,53.2883059270826,18.5612213590939,31.733112,0,0,0,200,4961,24.97575,-19193.2405,,,,,,,,,,,,,0,,,,2.7608759,,,,,,24.999691,,,,
,6293345.955,24.99959945,-11603.457,-0.0937324969626299,1.01733530872229E-5,1,4.99626677034896,40.0298881530762,2.00443378691618,10.499999858439,-1.000351867363,-0.183877913029193,25,-0.000534712768301746,-0.0932084904469472,-0.00107440615788764,24.9994202,24.9997787,-11655.29,-11551.624,52.4511817829863,18.5663820296683,31.733112,0,0,0,200,4961,24.97595,-11603.457,,,,,,,,,,,,,0,,,,2.627539,,,,,,24.99959945,,,,
,6293715.68,24.9994669,-3994.5535,-0.0634948080395361,1.22487701658452E-5,1,4.99626677034896,40.0298881530762,2.00447506406651,10.499999858439,-0.677302718735721,-0.124272467152269,25,-0.000374567850888118,-0.0631034224788206,-0.0007071297453064,24.999382,24.9995518,-4053.872,-3935.235,52.9944136038518,18.5591167076391,31.733112,0,0,0,200,4961,24.9799,-3994.5535,,,,,,,,,,,,,0,,,,2.7608759,,,,,,24.9994669,,,,
,6294095.445,25.00007725,3670.8355,0.0629041473025064,2.1869536984955E-5,1,4.99626677034896,40.0298881530762,2.00450917470261,10.499999858439,0.670855619922735,0.122755889154378,2.5,0.000342118435468619,0.0625152556955277,0.000670452757131111,24.9999828,25.0001717,3621.122,3720.549,52.6841070817171,18.5629624221017,31.733112,0,0,0,200,4961,24.9808,3670.8355,,,,,,,,,,,,,0,,,,2.73356875,,,,,,25.00007725,,,,
,6294465.1,25.00032715,10597.3165,0.0906607694145706,2.28875715544142E-5,1,4.99626677034896,40.0298881530762,2.00446198456297,10.499999858439,0.967219270631964,0.177741954636805,2.5,0.000519235899090047,0.0901463792735168,0.00103498440128368,25.0002728,25.0003815,10560.737,10633.896,52.7247517647171,18.5558617120039,31.733112,0,0,0,200,4961,24.97915,10597.3165,,,,,,,,,,,,,0,,,,2.7471541,,,,,,25.00032715,,,,
,6294839.86,25.00113105,17654.799,0.114787061068674,9.65140561500899E-6,1,4.99626677034896,40.0298881530762,2.00444631724157,10.499999858439,1.22564993999365,0.225738975268201,25,0.000650049905211125,0.11420707383471,0.00135686512042235,25.0009727,25.0012894,17607.629,17701.969,52.6856703387556,18.5603199619086,31.733112,0,0,0,200,4961,24.97685,17654.799,,,,,,,,,,,,,0,,,,2.6936177,,,,,,25.00113105,,,,
,6295209.595,25.000802,24648.208,0.137207887739238,9.77945234737443E-6,1,4.99626677034896,40.0298881530762,2.00436710864389,10.499999858439,1.46590564226807,0.270513944597856,25,0.000769548680442883,0.136607625858309,0.00167031612748314,25.0006599,25.0009441,24601.742,24694.674,52.4652510963325,18.5636396059166,31.733112,0,0,0,200,4961,24.9772,24648.208,,,,,,,,,,,,,0,,,,2.7201185,,,,,,25.000802,,,,
,6295579.275,25.0009413,31630.821,0.158803951534374,1.12144791634818E-5,1,4.99626677034896,40.0298881530762,2.00443975652037,10.499999858439,1.69777120877067,0.314091879062609,25,0.000910875731113163,0.158221929857571,0.0020058128995773,25.0008507,25.0010319,31583.367,31678.275,53.2773631278133,18.5555322425267,32.114323,0,0,0,200,4961,24.974,31630.821,,,,,,,,,,,,,0,,,,2.7608759,,,,,,25.0009413,,,,
,6295949.025,24.9996271,38613.8495,0.179776326355229,1.26712920436661E-5,1,4.99626677034896,40.0298881530762,2.00450918222131,10.499999858439,1.92336894723157,0.356277258724572,25,0.00102865022295562,0.179247287016525,0.00231284182841619,24.999527,24.9997272,38567.527,38660.172,52.8638816411402,18.5530276793463,31.733112,0,0,0,200,4961,24.97415,38613.8495,,,,,,,,,,,,,0,,,,2.60232935,,,,,,24.9996271,,,,
,6296318.75,25.00064465,45585.711,0.200253978027863,1.18104583229645E-5,1,4.99626677034896,40.0298881530762,2.00442361400256,10.499999858439,2.14381725897002,0.39758880816447,25,0.00115710893034804,0.199807422115361,0.002621080588851,25.0006027,25.0006866,45539.246,45632.176,53.1397965084287,18.559950160125,32.114323,0,0,0,200,4961,24.9735,45585.711,,,,,,,,,,,,,0,,,,2.69308005,,,,,,25.00064465,,,,
,6341280.635,2.10907785,47401.582,0.208062190419225,1.54332677679937E-5,1,4.99626677034896,40.0298881530762,1.99078822683696,10.7000004500151,2.21302288858506,0.410535776818622,25,0.00121147086982721,0.207614192977391,0.0027336683785419,2.1080201,2.1101356,47345.371,47457.793,53.0045747746017,18.5606826416945,31.733112,0,0,0,200,4961,1.91415,47401.582,,,,,,,,,,,,,0,,,,0.3857926,,,,,,2.10907785,,,,
,6341650.33,2.10318875,39758.1715,0.182891067972959,1.13905896677638E-5,1,4.99626677034896,40.0298881530762,1.99070425644465,10.7000004500151,1.94377932904983,0.359880608948775,25,0.00103329448842269,0.182351488961625,0.00233680343315529,2.1018391,2.1045384,39706.48,39809.863,52.3487884469671,18.5633798136842,32.114323,0,0,0,200,4961,1.9084,39758.1715,,,,,,,,,,,,,0,,,,0.38581185,,,,,,2.10318875,,,,
,6342020.065,2.09706665,32256.2705,0.158211817179978,1.11296855483589E-5,1,4.99626677034896,40.0298881530762,1.99078089181901,10.7000004500151,1.68030491079405,0.310535997477979,25,0.000886141571428239,0.157619567695603,0.00196873220467174,2.0965228,2.0976105,32205.709,32306.832,53.0178624594287,18.5666818023617,31.733112,0,0,0,200,4961,1.90965,32256.2705,,,,,,,,,,,,,0,,,,0.3839135,,,,,,2.09706665,,,,
,6342399.795,2.09759165,24552.115,0.132973509226024,1.04371353512382E-5,1,4.99626677034896,40.0298881530762,1.99075100270072,10.6899999082088,1.41123171368378,0.260061864589556,25,0.000728412685239226,0.132369618888382,0.00158559017407088,2.0965235,2.0986598,24500.99,24603.24,52.148691546044,18.570693279843,31.733112,0,0,0,200,4961,1.9148,24552.115,,,,,,,,,,,,,0,,,,0.3744208,,,,,,2.09759165,,,,
,6342769.565,2.10076975,17053.965,0.108133211355703,8.64192037505706E-6,1,4.99626677034896,40.0298881530762,1.99093304710331,10.7000004500151,1.14695465221221,0.210806688494133,25,0.00059290823797543,0.107563062952837,0.00123816829525041,2.0997462,2.1017933,17000.721,17107.209,52.2612460528132,18.5711950956974,32.114323,0,0,0,200,4961,1.9202,17053.965,,,,,,,,,,,,,0,,,,0.3801732,,,,,,2.10076975,,,,
,6343139.215,2.09647715,9529.712,0.0816233130681457,9.4929684797434E-6,1,4.99626677034896,40.0298881530762,1.99082922828603,10.7000004500151,0.865226065109197,0.158608648476155,25,0.0004535668030981,0.0811396889152012,0.000896152022796708,2.0958467,2.0971076,9479.857,9579.567,52.9529872923325,18.5700472974934,32.114323,0,0,0,200,4961,1.93265,9529.712,,,,,,,,,,,,,0,,,,0.3896659,,,,,,2.09647715,,,,
,6343509,2.09781705,1969.217,0.0442219330223084,1.84062046381943E-5,1,4.99626677034896,40.0298881530762,1.9909157548488,10.7000004500151,0.468568222763044,0.0857072053896052,25,0.000252268768237998,0.0439368973141461,0.000468183891421004,2.0971844,2.0984497,1913.43,2025.004,52.5699893179094,18.5726869020941,32.114323,0,0,0,200,4961,1.9434,1969.217,,,,,,,,,,,,,0,,,,0.391622,,,,,,2.09781705,,,,
,6343893.735,2.1013954,-5487.1375,-0.0618248989662047,1.26816542376899E-5,1,4.99626677034896,40.0298881530762,1.99085551439523,10.7000004500151,-0.654994957137378,-0.119933221749338,2.5,-0.000349384479387818,-0.0614399710035046,-0.000666144453496924,2.0997782,2.1030126,-5538.969,-5435.306,52.639554256121,18.572686730215,31.733112,0,0,0,200,4961,1.9474,-5487.1375,,,,,,,,,,,,,0,,,,0.38968535,,,,,,2.1013954,,,,
,6344268.385,2.10243015,-12436.756,-0.0910831386497441,9.49742251006588E-6,1,4.99626677034896,40.0298881530762,1.99097658042965,10.7000004500151,-0.965471673367565,-0.177242474655757,2.5,-0.000510166995326268,-0.0905652666223359,-0.00102360933265876,2.1022952,2.1025651,-12482.233,-12391.279,52.3526965895632,18.5697319149059,31.733112,0,0,0,200,4961,1.9386,-12436.756,,,,,,,,,,,,,0,,,,0.3858696,,,,,,2.10243015,,,,
,6344643.12,2.10443925,-19433.782,-0.115159148440752,9.10011023292312E-6,1,4.99626677034896,40.0298881530762,1.99084949400394,10.6899999082088,-1.22167536617274,-0.224718761895354,25,-0.000629422344896368,-0.114577885531493,-0.00133512495633451,2.1032612,2.1056173,-19479.117,-19388.447,52.2690623380055,18.5779115536276,31.733112,0,0,0,200,4961,1.9305,-19433.782,,,,,,,,,,,,,0,,,,0.3783309,,,,,,2.10443925,,,,
,6345012.865,2.10352385,-26342.738,-0.138073644339622,7.18784069617794E-6,1,4.99626677034896,40.0298881530762,1.99074898826694,10.7000004500151,-1.46562152007899,-0.270117687449499,25,-0.000745581650241982,-0.137471879012603,-0.00164968955286667,2.1013908,2.1056569,-26389.908,-26295.568,52.4699408674479,18.5836164900272,31.733112,0,0,0,200,4961,1.9214,-26342.738,,,,,,,,,,,,,0,,,,0.37631915,,,,,,2.10352385,,,,
,6345387.64,2.1014324,-33343.426,-0.161229170220811,1.1496136877345E-5,1,4.99626677034896,40.0298881530762,1.9907665817538,10.7000004500151,-1.71253907254029,-0.316480634144874,25,-0.000894441656007502,-0.160644177850665,-0.00200537347410208,2.1007957,2.1020691,-33389.891,-33296.961,52.8505939563133,18.5783824131906,31.733112,0,0,0,200,4961,1.91565,-33343.426,,,,,,,,,,,,,0,,,,0.3896659,,,,,,2.1014324,,,,
,6345767.285,2.1010796,-40426.7265,-0.184780967319622,1.19293792657607E-5,1,4.99626677034896,40.0298881530762,1.9908306458769,10.6899999082088,-1.96415481244508,-0.363476840945298,25,-0.00102431230272698,-0.184248992039111,-0.00234513756266303,2.1002181,2.1019411,-40474.039,-40379.414,52.7450741062171,18.5842976923846,31.733112,0,0,0,200,4961,1.912,-40426.7265,,,,,,,,,,,,,0,,,,0.3896659,,,,,,2.1010796,,,,
,6346137.05,2.10063805,-47314.42,-0.207683623074181,1.1536599898756E-5,1,4.99626677034896,40.0298881530762,1.99073487422993,10.6899999082088,-2.20897951740074,-0.40944088960122,25,-0.001178237018024,-0.207234805151103,-0.00269739508058206,2.0987802,2.1024959,-47358.766,-47270.074,52.5199650926786,18.5823974867923,32.114323,0,0,0,200,4961,1.9065,-47314.42,,,,,,,,,,,,,0,,,,0.38772925,,,,,,2.10063805,,,,
,6346551.78,2.0963007,-44912.432,-0.199856350319325,1.2678111752848E-5,1,4.99626677034896,40.0298881530762,1.99087119770047,10.7000004500151,-2.12534083430545,-0.393909890819118,25,-0.00114048323730544,-0.199374721122142,-0.00259251822793351,2.0957725,2.0968289,-44964.969,-44859.895,52.4347675840825,18.5751608509971,31.733112,0,0,0,200,4961,1.9055,-44912.432,,,,,,,,,,,,,0,,,,0.3896659,,,,,,2.0963007,,,,
,6346921.445,2.09955505,-37293.875,-0.174793436400391,1.1968980674737E-5,1,4.99626677034896,40.0298881530762,1.99079974389702,10.7000004500151,-1.8573734283055,-0.343551234761448,25,-0.00097122089330235,-0.174232299093376,-0.00220266088640273,2.0979977,2.1011124,-37345.566,-37242.184,52.5738974605056,18.5760636728857,32.114323,0,0,0,200,4961,1.9086,-37293.875,,,,,,,,,,,,,0,,,,0.382034,,,,,,2.09955505,,,,
,6347296.18,2.09749855,-29611.195,-0.149576638564164,1.07695485661058E-5,1,4.99626677034896,40.0298881530762,1.99056619254676,10.6899999082088,-1.58807478117409,-0.292977127569367,25,-0.000809147470848362,-0.148975384439255,-0.00181413842853677,2.0970006,2.0979965,-29659.779,-29562.611,52.1948076286786,18.5780659064726,32.114323,0,0,0,200,4961,1.9154,-29611.195,,,,,,,,,,,,,0,,,,0.38772925,,,,,,2.09749855,,,,
,6347665.885,2.0994766,-22029.343,-0.124671593644075,1.00978500801745E-5,1,4.99626677034896,40.0298881530762,1.99069435043175,10.7000004500151,-1.32278589955045,-0.243561844264532,25,-0.000683232449546949,-0.124073889961093,-0.00146796259898658,2.0990248,2.0999284,-22079.338,-21979.348,52.8201104440633,18.5741675127264,31.733112,0,0,0,200,4961,1.9206,-22029.343,,,,,,,,,,,,,0,,,,0.38772925,,,,,,2.0994766,,,,
,6348040.625,2.0936029,-14345.046,-0.0989046202360805,8.87261193450012E-6,1,4.99626677034896,40.0298881530762,1.99070229833865,10.6899999082088,-1.04870841551268,-0.192646555465643,25,-0.000551638012299739,-0.098358721841372,-0.00112289002422069,2.0930817,2.0941241,-14398.573,-14291.519,53.096806939871,18.5747620766022,32.114323,0,0,0,200,4961,1.93665,-14345.046,,,,,,,,,,,,,0,,,,0.3896659,,,,,,2.0936029,,,,
,6348410.33,2.0948521,-6727.559,-0.070265135877857,3.11224442268148E-5,1,4.99626677034896,40.0298881530762,1.99083015732185,10.7000004500151,-0.744676170670071,-0.13645507713021,25,-0.000399948992975044,-0.0698337976093607,-0.000766292277835252,2.0927651,2.0969391,-6766.963,-6688.155,52.727878278794,18.573520079718,31.733112,0,0,0,200,4961,1.94605,-6727.559,,,,,,,,,,,,,0,,,,0.391622,,,,,,2.0948521,,,,
,6348790.07,2.0978334,1086.66,-0.000364187904225358,5.31595535685319E-5,1,4.99626677034896,40.0298881530762,1.99067374526614,10.6899999082088,-0.00386326635234549,-0.000670628839785671,2.5,1.1937562493277E-6,-0.000361839930049476,-5.86442888754684E-7,2.096344,2.0993228,1032.284,1141.036,53.1788779343902,18.5725533732391,31.733112,0,0,0,200,4961,1.9588,1086.66,,,,,,,,,,,,,0,,,,0.3955539,,,,,,2.0978334,,,,
,6349169.77,2.1007985,8268.68,0.0754680139595597,9.76216434395545E-6,1,4.99626677034896,40.0298881530762,1.99079418378126,10.7000004500151,0.799660743672587,0.146505042001022,2.5,0.000418681184117066,0.0750134513457731,0.000820818614032338,2.1003809,2.1012161,8216.564,8320.796,52.9920687182941,18.5729486479102,32.114323,0,0,0,200,4961,1.9575,8268.68,,,,,,,,,,,,,0,,,,0.3975297,,,,,,2.1007985,,,,
,6349539.55,2.1016767,15239.4605,0.101150778944584,7.87323066889788E-6,1,4.99626677034896,40.0298881530762,1.99073943016558,10.7000004500151,1.07230522703751,0.19700880109285,2.5,0.000560274146549198,0.100600600573495,0.00115098343091527,2.1011376,2.1022158,15194.267,15284.654,52.4574348111402,18.5774035522269,32.114323,0,0,0,200,4961,1.95015,15239.4605,,,,,,,,,,,,,0,,,,0.3935781,,,,,,2.1016767,,,,
,6349919.22,2.10334255,22411.0965,0.125242397928976,8.81397523312891E-6,1,4.99626677034896,40.0298881530762,1.99069435803881,10.7000004500151,1.32888913932645,0.244707935209235,25,0.000685478599085478,0.124646706371554,0.00147676443883169,2.1030872,2.1035979,22363.502,22458.691,52.670037768371,18.5744805344733,32.114323,0,0,0,200,4961,1.94125,22411.0965,,,,,,,,,,,,,0,,,,0.391622,,,,,,2.10334255,,,,
,6350288.955,2.10087215,29397.251,0.148285938859588,9.32000073039296E-6,1,4.99626677034896,40.0298881530762,1.99061645978625,10.6899999082088,1.57434023671554,0.290638185787394,25,0.000821457091761675,0.14768643096143,0.00181612470962501,2.1007547,2.1009896,29349.373,29445.129,53.4923109706018,18.5738512453546,31.733112,0,0,0,200,4961,1.93005,29397.251,,,,,,,,,,,,,0,,,,0.391622,,,,,,2.10087215,,,,
,6350658.695,2.10173305,36380.279,0.171366543475954,1.0533664607303E-5,1,4.99626677034896,40.0298881530762,1.99062549110802,10.7000004500151,1.82060737793993,0.336874263273236,25,0.000968933823750376,0.170799708715467,0.00217047060097243,2.1010532,2.1024129,36334.941,36425.617,52.832616500371,18.5727612382931,32.114323,0,0,0,200,4961,1.91995,36380.279,,,,,,,,,,,,,0,,,,0.3857926,,,,,,2.10173305,,,,
,6351028.42,2.10090125,43353.697,0.194486397466491,1.28735524296217E-5,1,4.99626677034896,40.0298881530762,1.99062603168896,10.6899999082088,2.06764787574575,0.383245650198678,25,0.00111925019197888,0.193986009363276,0.00252503762564489,2.1008232,2.1009793,43306.949,43400.445,52.6583133405825,18.5726890459475,31.733112,0,0,0,200,4961,1.9191,43353.697,,,,,,,,,,,,,0,,,,0.3857926,,,,,,2.10090125,,,,
,6353419.365,2.1117916,1000.113,0.0176536794832624,6.36735346967148E-7,1,9.99253354069792,40.0298881530762,1.99081194663618,10.6800002977252,0.186986224336182,0.0341704315253326,2.5,9.88124652433155E-5,0.0175390285819017,0.000184008528547598,2.1103127,2.1132705,1000.113,1000.113,52.8076043877556,18.570538318382,32.114323,0,0,0,400,4881,1.9653,1000.113,,,,,,,,,,,,,0,,,,0.3975297,,,,,,2.1117916,,,,
,6354308.72,44.7175102,1000.113,0.0174747566617357,6.63137935153517E-6,1,9.99253354069792,40.0298881530762,1.99057543124119,10.6499996036291,0.185710190406714,0.0345293133991812,2.5,0.000109471818700444,0.017430582548263,0.000236623272916286,44.4807205,44.9542999,1000.113,1000.113,52.3409721617748,18.5793955310204,31.733112,0,0,0,400,4886,46.06615,1000.113,,,,,,,,,,,,,0,,,,2.510939,,,,,,44.7175102,,,,
,6355328.045,94.22698595,1000.113,0.00227296014729735,3.60908672072501E-7,1,9.99253354069792,40.0298881530762,1.97961213362656,10.5299996212125,0.024236629052959,0.00438566497423997,0.25,1.26686003654421E-5,0.00228433845247949,2.00049623713418E-5,93.9826889,94.471283,1000.113,1000.113,52.7122457084094,18.5740369298772,32.114323,0,0,0,400,4886,98.3487,1000.113,,,,,,,,,,,,,0,,,,3.30493005,,,,,,94.22698595,,,,
,6356247.31,139.8558197,1000.113,0.00127576310603468,1.13471978467233E-7,1,9.99253354069792,40.0298881530762,1.98005612180046,10.3700002655387,0.0136106283037823,0.00240404557711372,0.25,3.69949923005446E-6,0.00128162156954552,5.85600655166353E-6,139.6230621,140.0885773,1000.113,1000.113,52.2307625405632,18.5750163947851,32.114323,0,0,0,400,4886,145.5156,1000.113,,,,,,,,,,,,,0,,,,3.74436165,,,,,,139.8558197,,,,
,6357146.64,184.6382065,1000.113,0.000972046026277194,1.00222256744342E-7,1,9.99253354069792,40.0298881530762,1.99086520667413,10.1899998262525,0.0104172955668155,0.0018175370894373,0.25,1.29188010946255E-6,0.000975462787244672,2.41591211708693E-6,184.394928,184.881485,1000.113,1000.113,52.3581679891978,18.5655555157006,32.114323,0,0,0,400,4886,190.95605,1000.113,,,,,,,,,,,,,0,,,,3.9756581,,,,,,184.6382065,,,,
,6358045.98,229.4563675,1000.113,0.000801500663887891,1.05248029452357E-7,1,9.99253354069792,40.0298881530762,1.99114170579245,9.94000025093555,0.00858114417816492,0.00148753273515785,0.25,4.02305823018809E-7,0.000803270013580731,1.11304885404947E-6,229.2093811,229.7033539,1000.113,1000.113,52.7904085603325,18.5651756132063,32.114323,0,0,0,400,4886,236.131,1000.113,,,,,,,,,,,,,0,,,,4.22124215,,,,,,229.4563675,,,,
,6358945.38,274.17730715,1000.113,0.000687266758717606,1.09822103049935E-7,1,9.99253354069792,40.0298881530762,1.99112631503677,9.65999998152256,0.00734924474588532,0.00126485050616764,0.25,-3.69471832154384E-7,0.000687815834807833,1.23011378260033E-7,273.9039307,274.4506836,1000.113,1000.113,52.5363792915825,18.5623914898251,32.114323,0,0,0,400,4886,281.4616,1000.113,,,,,,,,,,,,,0,,,,4.4596095,,,,,,274.17730715,,,,
,6382832.98,2.1004591,0.12,,,2,,,,10.6800001458824,,,,,,,2.1004591,2.1004591,0.12,0.12,,,31.733112,,,,-99999999,4881,2.0995,0.12,,,,,,,,,,,,,,,,,,,,,,,2.1004591,,,,
,6388283.64,41.80278395,100.238,0.00578666635905163,3.38277808679161E-6,1,9.99253354069792,40.0298881530762,1.99068592493277,10.6300003826618,0.0614492837535892,0.0113840022856988,2.5,3.39685335503693E-5,0.00576661805666676,7.45323483137017E-5,41.5656204,42.0399475,100.238,100.238,52.4504001544671,18.5565264886265,32.114323,0,0,0,400,4886,42.97555,100.238,,,,,,,,,,,,,0,,,,2.510939,,,,,,41.80278395,,,,
,6389222.95,87.3503456,100.238,0.000251961111021515,9.02838991087806E-8,1,9.99253354069792,40.0298881530762,1.99057880499988,10.5400001630187,0.00270232113713375,0.000479009001215244,0.25,3.86663164773003E-7,0.000253194634155055,1.31116570004469E-6,87.1064529,87.5942383,100.238,100.238,52.8193288155441,18.5554604479285,32.114323,0,0,0,400,4886,91.20695,100.238,,,,,,,,,,,,,0,,,,3.101668,,,,,,87.3503456,,,,
,6390142.305,132.819397,100.238,0.000125888037722793,7.09537251254934E-8,1,9.99253354069792,40.0298881530762,2.00448913687583,10.3799998760223,0.00136150397590742,0.000226404454238749,0.25,-9.16118276721137E-7,0.000126485262259262,-6.92575718008371E-7,132.5428925,133.0959015,100.238,100.238,52.5355976630632,18.5587731808289,32.114323,0,0,0,400,4886,138.3836,100.238,,,,,,,,,,,,,0,,,,3.74436165,,,,,,132.819397,,,,
,6391084.05,179.681015,100.238,,,2,,,,10.1400002250075,,,,,,,179.681015,179.681015,100.238,100.238,,,32.114323,,,,-99999999,4886,186.0573,100.238,,,,,,,,,,,,,,,,,,,,,,,179.681015,,,,
,6392020.89,226.46237945,100.238,7.5528290805397E-5,9.13480738985748E-8,1,9.99253354069792,40.0298881530762,1.9911062326265,9.89000033587217,0.000811373061214236,0.000124676125335837,0.25,-1.41157882374839E-6,7.57032511315541E-5,-1.34686536921322E-6,226.2181244,226.7066345,100.238,100.238,51.8250973390824,18.5513139779364,32.114323,0,0,0,400,4886,233.07695,100.238,,,,,,,,,,,,,0,,,,4.2636232,,,,,,226.46237945,,,,
,6392920.265,271.0986023,100.238,6.45544502152968E-5,1.01976345411889E-7,1,9.99253354069792,40.0298881530762,1.97968614587272,9.60000045597553,0.000688930522373876,0.000104485867795208,0.25,-1.32138336632499E-6,6.46133208269443E-5,-1.27568596439151E-6,270.8425293,271.3546753,100.238,100.238,52.7880636747748,18.5698503484414,32.114323,0,0,0,400,4886,278.5067,100.238,,,,,,,,,,,,,0,,,,4.4152803,,,,,,271.0986023,,,,
,6393799.585,301.8629761,100.238,5.87804417943473E-5,1.05270922737675E-7,1,9.99253354069792,40.0298881530762,1.99152660705353,9.4200000166893,0.000630810438079137,9.25672375295039E-5,0.25,-1.48218335882735E-6,5.87761810351107E-5,-1.44349100338922E-6,301.8508301,301.8751221,100.238,100.238,52.5488853478902,18.5479517288059,32.114323,0,0,0,400,4885,303.0824,100.238,,,,,,,,,,,,,0,,,,4.43877365,,,,,,301.8629761,,,,
,6393829.585,301.9254608,100.238,5.86063776874703E-5,1.03410479300538E-7,1,9.99253354069792,40.0298881530762,1.99159978611004,9.41000040620565,0.000629059685914215,9.17380692375185E-5,0.25,-1.53003118933498E-6,5.86020459063364E-5,-1.49144049193798E-6,301.9151611,301.9357605,100.238,100.238,52.8896753822748,18.5526516168893,31.733112,0,0,0,400,4881,303.0473,100.238,,,,,,,,,,,,,0,,,,4.3522706,,,,,,301.9254608,,,,