File: DataToTest/8_DyMn0p2Ga3_VSM_DC_HYS_300K_50K_2K_26102022.DAT
[Header]
; VSM Data File (default extension .dat)
; Copyright (c) 2003-2013, Quantum Design, Inc. All rights reserved.
TITLE,8_DyMn0p2Ga3_VSM_DC_HYS_300K_50K_2K_26102022
FILEOPENTIME,5743717.84,10/26/2022,2:08 pm
BYAPP,VSM,2.0,2.0
INFO,PPMS VSM Option Release 1.4.10 Build 1,APPNAME
INFO,Quantum Design Linear Motor Servo Controller,MOTOR_MODULE_NAME
INFO,3101-100 C1,MOTOR_HW_VERSION
INFO,074,MOTOR_SERIAL_NUMBER
INFO,SRV No X-over 01.01.11,MOTOR_SOFTWARE_VERSION
INFO,Quantum Design VSM Detection Module,VSM_MODULE_NAME
INFO,3101-150 E1,VSM_HW_VERSION
INFO,VSM061,VSM_SERIAL_NUMBER
INFO,VSM No X-over 01.02.05 May 20 2008 13:51:47,VSM_SOFTWARE_VERSION
INFO,113,PREAMP_SERIAL_NUMBER
INFO,Quantum Design VSM Oven,OVEN_MODULE_NAME
INFO,3101-200 B0,OVEN_HW_VERSION
INFO,OVN054,OVEN_SERIAL_NUMBER
INFO,01.01.00,OVEN_SOFTWARE_VERSION
INFO,221,COIL_SERIAL_NUMBER
INFO,0,MOMENT_UNITS
INFO,8_DyMn0p2Ga3_VSM_DC_HYS_300K_50K_2K_26102022,SAMPLE_MATERIAL
INFO,,SAMPLE_COMMENT
INFO,3.3,SAMPLE_MASS
INFO,,SAMPLE_VOLUME
INFO,,SAMPLE_MOLECULAR_WEIGHT
INFO,,SAMPLE_SIZE
INFO,,SAMPLE_SHAPE
DATATYPE,COMMENT,1
DATATYPE,TIME,2
STARTUPAXIS,X,2
STARTUPAXIS,Y1,5
[Data]
Comment,Time Stamp (sec),Temperature (K),Magnetic Field (Oe),Moment (emu),M. Std. Err. (emu),Transport Action,Averaging Time (sec),Frequency (Hz),Peak Amplitude (mm),Center Position (mm),Coil Signal' (mV),Coil Signal" (mV),Range (mV),M. Quad. Signal (emu),M. Raw' (emu),M. Raw" (emu),Min. Temperature (K),Max. Temperature (K),Min. Field (Oe),Max. Field (Oe),Mass (grams),Motor Lag (deg),Pressure (Torr),VSM Status (code),Motor Status (code),Measure Status (code),Measure Count,PPMS Status (code),System Temp. (K),System Field (Oe),Sample Position (deg),Bridge 1 Resistance (ohms),Bridge 1 Excitation (에),Bridge 2 Resistance (ohms),Bridge 2 Excitation (에),Bridge 3 Resistance (ohms),Bridge 3 Excitation (에),Bridge 4 Resistance (ohms),Bridge 4 Excitation (에),Signal 1 Vin (V),Signal 2 Vin (V),Digital Inputs (code),Drive 1 Iout (mA),Drive 1 Ipower (W),Drive 2 Iout (mA),Drive 2 Ipower (W),Pressure (),Map 20 (),Map 21 (),Map 22 (),Map 23 (),Map 24 (),Map 25 (),Map 26 (),Map 27 (),Map 28 (),Map 29 ()
,5748351.97,300.0236511,27850.648,,,2,,,,9.41999980926514,,,,,,,300.0236511,300.0236511,27850.648,27850.648,,,31.733112,,,,-99999999,4961,300.0549,27850.648,,,,,,,,,,,,,,,,,,,,,,,300.0236511,,,,
,5748870.925,299.9919586,43031.4805,0.0158003906009233,2.36894235777306E-6,1,4.99626677034896,40.0298881530762,1.99383308947714,9.41000040620565,0.168892809912173,0.0296495560279721,2.5,4.52765031828326E-5,0.0157999002852854,5.56802760931141E-5,299.9918518,299.9920654,42981.063,43081.898,52.9092160952556,18.5063396872657,32.876747,0,0,0,200,4961,300.00745,43031.4805,,,,,,,,,,,,,0,,,,5.2850857,,,,,,299.9919586,,,,
,5749235.61,300.00167845,35614.3205,0.0130737353278424,1.97346011394263E-6,1,4.99626677034896,40.0298881530762,1.99375603209459,9.41000040620565,0.139746046421793,0.0245082067115138,2.5,3.52193387378968E-5,0.0130733256711897,4.38424008561739E-5,300.0015564,300.0018005,35563.336,35665.305,52.5840586312556,18.5108832273813,31.733112,0,0,0,200,4961,300.0034,35614.3205,,,,,,,,,,,,,0,,,,5.41880845,,,,,,300.00167845,,,,
,5749565.44,299.9941101,28920.115,0.0106149881566426,1.619275383665E-6,1,4.99626677034896,40.0298881530762,1.99388430201705,9.41000040620565,0.113467120390464,0.0199247552114265,2.5,3.0878592195452E-5,0.0106146557175595,3.78896130192467E-5,299.993103,299.9951172,28868.707,28971.523,52.7200619936017,18.5126023525116,31.351902,0,0,0,200,4961,300.02105,28920.115,,,,,,,,,,,,,0,,,,5.3665509,,,,,,299.9941101,,,,
,5749930.15,300.00331115,21522.004,0.00789294914434595,1.41376389684342E-6,1,4.99626677034896,40.0298881530762,1.9937866937139,9.37000010162592,0.0843651816943478,0.0148214424909114,2.5,2.35848282232075E-5,0.00789269846537709,2.88059502326226E-5,300.0027771,300.0038452,21471.303,21572.705,53.3602157508518,18.5181857643277,31.733112,0,0,0,200,4961,300.0224,21522.004,,,,,,,,,,,,,0,,,,5.55605315,,,,,,300.00331115,,,,
,5750294.86,299.99845885,14124.124,0.00517131385631289,1.20837221357133E-6,1,4.99626677034896,40.0298881530762,1.99378721674417,9.34999994933605,0.0552737123298338,0.00971541576203246,2.5,1.58850946428417E-5,0.00517114969691671,1.93105888476741E-5,299.9981384,299.9987793,14073.563,14174.685,52.5160569500825,18.5154368331375,31.351902,0,0,0,200,4961,300.03645,14124.124,,,,,,,,,,,,,0,,,,5.20641065,,,,,,299.99845885,,,,
,5750629.615,300.0019989,7289.4885,0.0026507137165677,9.06913466838256E-7,1,4.99626677034896,40.0298881530762,1.99367733149286,9.3599995598197,0.0283310430927056,0.00497775868672666,2.5,7.96188726380883E-6,0.00265062919636335,9.71980874822484E-6,300.0013123,300.0026855,7237.09,7341.887,52.1111733771209,18.5228569630826,31.733112,0,0,0,200,4961,300.0402,7289.4885,,,,,,,,,,,,,0,,,,5.188781,,,,,,300.0019989,,,,
,5751262.205,300.0013733,-5278.398,-0.00195712356162626,8.11500920005445E-7,1,4.99626677034896,40.0298881530762,1.98275357966523,9.34999994933605,-0.0208080533896726,-0.00369213703903499,0.25,-9.17705360395689E-6,-0.00195705897421731,-1.04752590753481E-5,300.0013733,300.0013733,-5281.081,-5275.715,53.1874758481018,18.5227149111933,31.733112,0,0,0,200,4961,300.04975,-5278.398,,,,,,,,,,,,,0,,,,5.8406222,,,,,,300.0013733,,,,
,5751688.8,300.00271605,-13162.128,-0.00486608095541309,1.11151745948802E-6,1,4.99626677034896,40.0298881530762,1.99363178270839,9.32999979704618,-0.0519993421652209,-0.009187535760982,2.5,-1.92720522255487E-5,-0.00486592290201284,-2.24957867317121E-5,300.0025024,300.0029297,-13212.971,-13111.285,52.2338890546401,18.529474204362,31.733112,0,0,0,200,4961,300.0374,-13162.128,,,,,,,,,,,,,0,,,,5.84149645,,,,,,300.00271605,,,,
,5752013.585,300.0057068,-19240.7235,-0.0070908951264477,1.61507279508466E-6,1,4.99626677034896,40.0298881530762,1.99374463901112,9.32999979704618,-0.0757856124285851,-0.013344797468943,2.5,-2.39660709982664E-5,-0.00709066733645795,-2.86587030476312E-5,300.0051575,300.0062561,-19289.59,-19191.857,52.5574832616017,18.531582986993,31.733112,0,0,0,200,4961,300.02165,-19240.7235,,,,,,,,,,,,,0,,,,5.54361795,,,,,,300.0057068,,,,
,5752378.29,300.00445555,-26057.3155,-0.00958699648380263,1.8174670506403E-6,1,4.99626677034896,40.0298881530762,1.99359849805351,9.32000018656254,-0.102451577941116,-0.0180672441082769,2.5,-3.48561246211782E-5,-0.00958668808072626,-4.11918931362285E-5,300.0042419,300.0046692,-26105.193,-26009.438,52.677072425044,18.5324199682219,31.733112,0,0,0,200,4961,300.0168,-26057.3155,,,,,,,,,,,,,0,,,,5.95848965,,,,,,300.00445555,,,,
,5752743.11,299.99890135,-32873.836,-0.0120836053844388,2.08845807423063E-6,1,4.99626677034896,40.0298881530762,1.98275636837275,9.30999964475632,-0.128460078925763,-0.0226388892613083,2.5,-4.25826885898668E-5,-0.0120832208007571,-5.0556837949795E-5,299.9988708,299.9989319,-32922.418,-32825.254,52.7153722224863,18.5272055966971,31.733112,0,0,0,200,4961,300.01545,-32873.836,,,,,,,,,,,,,0,,,,5.5782466,,,,,,299.99890135,,,,
,5753067.8,300.00408935,-38930.949,-0.0143051191516604,2.22347830056492E-6,1,4.99626677034896,40.0298881530762,1.98282843047719,9.30999964475632,-0.152089145878459,-0.0267613467459555,2.5,-4.66135675693958E-5,-0.0143046651078293,-5.60417476980298E-5,300.0039368,300.0042419,-38978.121,-38883.777,52.8756060689287,18.5325294738784,31.733112,0,0,0,200,4961,299.99835,-38930.949,,,,,,,,,,,,,0,,,,5.7048771,,,,,,300.00408935,,,,
,5753437.555,300.0073395,-45820.762,-0.0168322139719186,2.55684696442682E-6,1,4.99626677034896,40.0298881530762,1.99366502670028,9.30999964475632,-0.179888364889026,-0.0316940478257057,2.5,-5.86040971961818E-5,-0.0168316770554166,-6.96808149910931E-5,300.0071106,300.0075684,-45867.934,-45773.59,53.0170808309095,18.5319795714188,31.733112,0,0,0,200,4961,299.98345,-45820.762,,,,,,,,,,,,,0,,,,5.6342516,,,,,,300.0073395,,,,
,5753812.305,300.0006714,-47507.691,-0.0174482760508116,2.77051032403622E-6,1,4.99626677034896,40.0298881530762,1.99374899036778,9.30999964475632,-0.18648343967007,-0.032834829683706,2.5,-5.88307662622257E-5,-0.0174477248978903,-7.03085178922255E-5,300.0004883,300.0008545,-47563.902,-47451.48,52.7669597047556,18.5292611887549,31.733112,0,0,0,200,4961,299.9816,-47507.691,,,,,,,,,,,,,0,,,,5.99168825,,,,,,300.0006714,,,,
,5754182.05,299.99279785,-39769.2325,-0.0145988476666569,2.05276403513609E-6,1,4.99626677034896,40.0298881530762,1.99360924826877,9.29000042378902,-0.156015271640245,-0.02749178259988,2.5,-5.11663759039358E-5,-0.0145983873630478,-6.07866098025464E-5,299.9923706,299.9932251,-39818.805,-39719.66,52.791971817371,18.5341068556107,31.733112,0,0,0,200,4961,299.9884,-39769.2325,,,,,,,,,,,,,0,,,,5.85082505,,,,,,299.99279785,,,,
,5754506.765,299.99757385,-33104.2655,-0.0121490313929341,1.73948385540734E-6,1,4.99626677034896,40.0298881530762,1.99360354675066,9.30000003427267,-0.129838885078392,-0.0228508356788516,2.5,-3.99958351509844E-5,-0.0121486471116091,-4.80131726372123E-5,299.9970703,299.9980774,-33156.379,-33052.152,52.4261696703709,18.5336396459034,31.733112,0,0,0,200,4961,300.0049,-33104.2655,,,,,,,,,,,,,0,,,,6.2633576,,,,,,299.99757385,,,,
,5754871.48,299.99543765,-25623.119,-0.00939927906478396,1.50399482519613E-6,1,4.99626677034896,40.0298881530762,1.98262647060402,9.30000003427267,-0.0999156615009482,-0.0176157256578776,2.5,-3.37796740397738E-5,-0.0093989796333638,-3.9991962296255E-5,299.9949036,299.9959717,-25672.832,-25573.406,52.138530375294,18.5325911610293,31.733112,0,0,0,200,4961,300.0172,-25623.119,,,,,,,,,,,,,0,,,,6.29479955,,,,,,299.99543765,,,,
,5755241.28,300.0020447,-18039.3855,-0.00661138652441767,1.26488800115339E-6,1,4.99626677034896,40.0298881530762,1.98260373797429,9.2799998819828,-0.0702794329058876,-0.012389146515555,2.5,-2.36136710126295E-5,-0.00661117398280869,-2.7989945217899E-5,300.0018921,300.0021973,-18090.652,-17988.119,52.7341313069479,18.5350968693765,31.733112,0,0,0,200,4961,300.02295,-18039.3855,,,,,,,,,,,,,0,,,,6.3579991,,,,,,300.0020447,,,,
,5755565.985,299.99473575,-11371.562,-0.00415462551528381,1.01324905645938E-6,1,4.99626677034896,40.0298881530762,1.98251292531381,9.2799998819828,-0.0441589674032413,-0.00780251936779189,2.5,-1.64776040325548E-5,-0.00415449153416984,-1.92309292802592E-5,299.9945679,299.9949036,-11423.393,-11319.731,52.6880152243133,18.5309641748475,31.733112,0,0,0,200,4961,300.0346,-11371.562,,,,,,,,,,,,,0,,,,6.3897567,,,,,,299.99473575,,,,
,5756043.64,300.0011292,-1483.1245,-0.000530046106730799,8.75450651899114E-7,1,4.99626677034896,40.0298881530762,1.99352467857896,9.2799998819828,-0.00566230213956179,-0.00101965483236229,0.25,-3.84121399471131E-6,-0.000530027700938842,-4.19295282977719E-6,300.0011292,300.0011292,-1489.056,-1477.193,53.0100461742364,18.5287100283288,32.114323,0,0,0,200,4961,300.04765,-1483.1245,,,,,,,,,,,,,0,,,,5.75940015,,,,,,300.0011292,,,,
,5756600.27,300.00314335,9206.8875,0.00338906460052093,0.000188599245380976,1,4.99626677034896,40.0298881530762,1.98265388033195,9.27000027149916,0.0359043463144032,0.00706056959120013,2.5,7.88136687865218E-5,0.0033889109740571,8.10584550356442E-5,300.0028687,300.003418,9169.603,9244.172,53.0897722831979,18.5339243233681,31.733112,0,0,0,200,4961,300.0435,9206.8875,,,,,,,,,,,,,0,,,,5.92282555,,,,,,300.00314335,,,,
,5756924.95,300.00086975,15321.5165,0.00565887249109575,1.04246463275797E-6,1,4.99626677034896,40.0298881530762,1.98259949706885,9.2799998819828,0.060160424415324,0.010567145719963,2.5,1.672626523058E-5,0.00565869292493579,2.04739421107741E-5,300.0007324,300.0010071,15273.074,15369.959,52.9694014912364,18.5347855072859,31.733112,0,0,0,200,4961,300.0335,15321.5165,,,,,,,,,,,,,0,,,,6.4539089,,,,,,300.00086975,,,,
,5757289.68,300.00227355,22218.1755,0.00817959498478055,1.32783363867613E-6,1,4.99626677034896,40.0298881530762,1.99357252764611,9.27000027149916,0.0874214748852504,0.0153498111099806,2.5,2.36646484683661E-5,0.00817933607141316,2.90745163087482E-5,300.0012817,300.0032654,22171.992,22264.359,52.9998850034864,18.5298914263314,31.733112,0,0,0,200,4961,300.02855,22218.1755,,,,,,,,,,,,,0,,,,6.29542805,,,,,,300.00227355,,,,
,5757614.455,300.0045166,28351.01,0.0104289372561828,1.38655786661969E-6,1,4.99626677034896,40.0298881530762,1.99359319388708,9.27000027149916,0.111463379849063,0.0195688808226894,2.5,2.99715394192398E-5,0.0104286072985834,3.68607402904874E-5,300.0037842,300.005249,28304.545,28397.475,53.1249455665633,18.5306824220398,31.733112,0,0,0,200,4961,300.01255,28351.01,,,,,,,,,,,,,0,,,,5.75411295,,,,,,300.0045166,,,,
,5757984.235,300.0049133,35337.289,0.0129933519306492,1.80628272429797E-6,1,4.99626677034896,40.0298881530762,1.99324307204041,9.25999972969294,0.138842961964497,0.0244068979177523,2.5,4.01833482305702E-5,0.0129929399634213,4.87538917678674E-5,300.0045776,300.005249,35290.117,35384.461,53.208579818121,18.5275795245198,31.733112,0,0,0,200,4961,299.9995,35337.289,,,,,,,,,,,,,0,,,,6.5514295,,,,,,300.0049133,,,,
,5758348.96,300.0005493,42218.7655,0.0155144156886708,2.24867588917021E-6,1,4.99626677034896,40.0298881530762,1.99345445101033,9.27000027149916,0.165791417617287,0.0291904497443941,2.5,5.22023283256926E-5,0.0155139246521536,6.24198291471772E-5,299.9994812,300.0016174,42169.758,42267.773,52.5559200045633,18.5307199646452,31.733112,0,0,0,200,4961,299.9984,42218.7655,,,,,,,,,,,,,0,,,,6.5841532,,,,,,300.0005493,,,,
,5758673.68,300.0003052,48332.9395,0.0177555685592982,2.55961623164019E-6,1,4.99626677034896,40.0298881530762,1.99351667213894,9.25999972969294,0.189749444045692,0.0333923421844888,2.5,5.82768410034377E-5,0.0177550091766784,6.99543879550536E-5,300.0003052,300.0003052,48283.934,48381.945,53.0491276001979,18.5274519645087,31.733112,0,0,0,200,4961,299.9844,48332.9395,,,,,,,,,,,,,0,,,,6.5841532,,,,,,300.0003052,,,,
,5771739.08,49.9999409,45082.5725,0.084039861495276,5.69449273938856E-6,1,4.99626677034896,40.0298881530762,1.98201264617462,10.3500001132488,0.892283635962379,0.16739785374746,2.5,0.000677392683116104,0.0841196228698121,0.0012781123542963,49.9998322,50.0000496,45033.141,45132.004,52.9490791497364,18.5110563411151,31.733112,0,0,0,200,4961,49.87655,45082.5725,,,,,,,,,,,,,0,,,,2.7608759,,,,,,49.9999409,,,,
,5772063.815,49.99695015,38455.881,0.0733029375894333,6.1322958931413E-6,1,4.99626677034896,40.0298881530762,1.98194454092461,10.3500001132488,0.777995529462624,0.145956484928948,2.5,0.000584036209956177,0.0733475814583981,0.00111442181545963,49.9969254,49.9969749,38406.309,38505.453,52.6176686575825,18.5176358213658,31.351902,0,0,0,200,4961,49.88225,38455.881,,,,,,,,,,,,,0,,,,2.7471541,,,,,,49.99695015,,,,
,5772388.59,49.9971733,31860.116,0.0623890624557583,5.80935744124186E-6,1,4.99626677034896,40.0298881530762,1.98185904760588,10.3500001132488,0.661895997366234,0.12421282603277,2.5,0.000495616742325124,0.0624051618926888,0.000951562737445351,49.9971123,49.9972343,31811.109,31909.123,52.6215768001786,18.5158122813693,31.733112,0,0,0,200,4961,49.89125,31860.116,,,,,,,,,,,,,0,,,,2.7063967,,,,,,49.9971733,,,,
,5772713.385,49.9973297,25270.8445,0.0512176544442146,4.98995984740366E-6,1,4.99626677034896,40.0298881530762,1.98177742907171,10.3500001132488,0.543148595946994,0.101990910818961,2.5,0.000409390332984642,0.0512123746606776,0.000786585218862721,49.9967766,49.9978828,25218.447,25323.242,52.5168385786017,18.5157338707681,31.351902,0,0,0,200,4961,49.8967,25270.8445,,,,,,,,,,,,,0,,,,2.7062616,,,,,,49.9973297,,,,
,5773040.62,49.99969865,18634.203,0.0395016390987568,4.24929891213953E-6,1,4.99626677034896,40.0298881530762,1.98195530859213,10.3500001132488,0.418809086060051,0.0785075249381322,2.5,0.000301650997696935,0.039483128758597,0.000594111257677145,49.9995613,49.999836,18530.539,18737.867,52.3816168447748,18.522145432058,31.733112,0,0,0,200,4961,49.8982,18634.203,,,,,,,,,,,,,0,,,,2.57761835,,,,,,49.99969865,,,,
,5773372.835,49.99879455,11887.86,0.0272032464983674,4.17673723772234E-6,1,4.99626677034896,40.0298881530762,1.98185407044522,10.3500001132488,0.28829315678255,0.054065011956389,2.5,0.000209138022843354,0.0271804681026636,0.000411108227945148,49.9987602,49.9988289,11836.451,11939.269,52.4324226985248,18.5202982532085,31.351902,0,0,0,200,4961,49.90045,11887.86,,,,,,,,,,,,,0,,,,2.6398071,,,,,,49.99879455,,,,
,5773712.605,49.99835395,4935.4145,0.0132225230749723,4.85612826274195E-6,1,4.99626677034896,40.0298881530762,1.98183796249145,10.3500001132488,0.140080259539022,0.0262591123562982,2.5,0.000100561178358491,0.0132067920475822,0.00019876906959235,49.9982948,49.9984131,4879.909,4990.92,52.3495700754863,18.522965799775,31.733112,0,0,0,200,4961,49.90505,4935.4145,,,,,,,,,,,,,0,,,,2.66604445,,,,,,49.99835395,,,,
,5774077.305,49.99946785,-2394.258,-0.00797789914514952,5.25927573871002E-6,1,4.99626677034896,40.0298881530762,1.98194662457543,10.3599997237325,-0.0845066100521547,-0.0158794064224426,2.5,-6.41473798792218E-5,-0.00796747561772646,-0.000123376107644635,49.9994469,49.9994888,-2447.079,-2341.437,52.7333496784287,18.5215262706992,31.733112,0,0,0,200,4961,49.90435,-2394.258,,,,,,,,,,,,,0,,,,2.66604445,,,,,,49.99946785,,,,
,5774402.095,50.00041965,-8417.1575,-0.0207927034325524,4.6176132353035E-6,1,4.99626677034896,40.0298881530762,1.98210048182036,10.3500001132488,-0.220341542665628,-0.0413254560306735,2.5,-0.000160064991045074,-0.020771524331724,-0.000314512703409293,50.0003586,50.0004807,-8473.792,-8360.523,52.3128335350824,18.5335830930629,32.114323,0,0,0,200,4961,49.9042,-8417.1575,,,,,,,,,,,,,0,,,,2.56314525,,,,,,50.00041965,,,,
,5774726.835,49.9990673,-14472.7565,-0.0322649423243115,4.22401861147714E-6,1,4.99626677034896,40.0298881530762,1.98203615915657,10.3500001132488,-0.342012914723618,-0.0641467660800202,2.5,-0.000248985082924691,-0.0322424744427709,-0.000488348348510476,49.9984016,49.999733,-14521.622,-14423.891,52.0908510356209,18.5258126541298,31.733112,0,0,0,200,4961,49.9051,-14472.7565,,,,,,,,,,,,,0,,,,2.63954365,,,,,,49.9990673,,,,
,5775051.595,50.0003471,-20539.0635,-0.0431378883096792,4.45601500195038E-6,1,4.99626677034896,40.0298881530762,1.98202194544417,10.3500001132488,-0.457414666105116,-0.0858095496637759,2.5,-0.000335847738921911,-0.0431222932109265,-0.000654813991289228,50.000164,50.0005302,-20586.377,-20491.75,52.0275391255632,18.525779523654,32.495537,0,0,0,200,4961,49.90725,-20539.0635,,,,,,,,,,,,,0,,,,2.6263595,,,,,,50.0003471,,,,
,5775381.395,50.00007055,-26700.908,-0.0537867418475021,5.14649476608751E-6,1,4.99626677034896,40.0298881530762,1.98199462687896,10.3500001132488,-0.57052036477281,-0.107009564440437,2.5,-0.000419557924620133,-0.05378564076378,-0.000815074285355384,49.9999275,50.0002136,-26749.775,-26652.041,51.8274422246401,18.526340367298,31.733112,0,0,0,200,4961,49.9049,-26700.908,,,,,,,,,,,,,0,,,,2.5623783,,,,,,50.00007055,,,,
,5775706.18,49.9992714,-32767.35,-0.0639965923890004,5.21125541383966E-6,1,4.99626677034896,40.0298881530762,1.98212661281966,10.3500001132488,-0.679092037013452,-0.127339109914766,2.5,-0.000499895255355897,-0.0640165657336728,-0.000966955814730618,49.9990807,49.9994621,-32812.262,-32722.438,52.6293930853709,18.530155270455,31.351902,0,0,0,200,4961,49.90765,-32767.35,,,,,,,,,,,,,0,,,,2.47800745,,,,,,49.9992714,,,,
,5776030.86,50.00029185,-38823.334,-0.0739724851747439,5.56256066933625E-6,1,4.99626677034896,40.0298881530762,1.98209846169895,10.3500001132488,-0.785201370314803,-0.147185136111281,2.5,-0.000578621380396087,-0.0740194771398549,-0.00111340795825051,50.000042,50.0005417,-38867.68,-38778.988,52.3878698729286,18.5303080913471,31.733112,0,0,0,200,4961,49.90915,-38823.334,,,,,,,,,,,,,0,,,,2.6133063,,,,,,50.00029185,,,,
,5776355.675,49.99980355,-44877.34,-0.0837486271196161,7.01582066424039E-6,1,4.99626677034896,40.0298881530762,1.98216341836573,10.3599997237325,-0.889262141647319,-0.166776665840038,2.5,-0.000669997236278503,-0.0838277970706922,-0.00126872913346908,49.9997635,49.9998436,-44927.617,-44827.063,52.3269028484286,18.5303801534012,29.827055,0,0,0,200,4961,49.90715,-44877.34,,,,,,,,,,,,,0,,,,2.51344515,,,,,,49.99980355,,,,
,5776725.385,49.99948885,-48803.342,-0.0900029649082962,6.38888484628491E-6,1,4.99626677034896,40.0298881530762,1.98213658920521,10.3599997237325,-0.955864545170181,-0.179167252996159,2.5,-0.000716417919932184,-0.090105780389726,-0.00135460466517024,49.9994164,49.9995613,-48864.918,-48741.766,52.013469812217,18.5248562132311,32.495537,0,0,0,200,4961,49.9139,-48803.342,,,,,,,,,,,,,0,,,,2.5124426,,,,,,49.99948885,,,,
,5777050.125,49.9987488,-41832.754,-0.0787792417677231,6.45286824244217E-6,1,4.99626677034896,40.0298881530762,1.98194788511481,10.3500001132488,-0.836306205840203,-0.15669630640334,2.5,-0.000613248869519182,-0.0788417124896234,-0.00117971581146555,49.9985657,49.9989319,-41884.164,-41781.344,52.1729220301401,18.5348766345184,32.495537,0,0,0,200,4961,49.91375,-41832.754,,,,,,,,,,,,,0,,,,2.47664905,,,,,,49.9987488,,,,
,5777374.88,49.99882505,-35164.3985,-0.0678629685284324,5.31966598986802E-6,1,4.99626677034896,40.0298881530762,1.9820136839436,10.3500001132488,-0.720202500904506,-0.134884187233072,2.5,-0.000517087079442961,-0.0678931057281498,-0.00101059829937583,49.998806,49.9988441,-35217.785,-35111.012,52.8279267292556,18.5303699269294,31.733112,0,0,0,200,4961,49.9146,-35164.3985,,,,,,,,,,,,,0,,,,2.58732975,,,,,,49.99882505,,,,
,5777704.615,49.99866105,-28405.087,-0.0565365313010938,5.11457543090068E-6,1,4.99626677034896,40.0298881530762,1.98199491188823,10.3500001132488,-0.599758939547646,-0.11242135521748,2.5,-0.000435331746367009,-0.0565409552338074,-0.000850239272642479,49.9984589,49.9988632,-28455.932,-28354.242,52.2776602517171,18.5260395804759,31.733112,0,0,0,200,4961,49.92115,-28405.087,,,,,,,,,,,,,0,,,,2.51118955,,,,,,49.99866105,,,,
,5778029.38,49.99777035,-21743.3535,-0.0450638138761691,4.62041550751573E-6,1,4.99626677034896,40.0298881530762,1.98211106548053,10.3500001132488,-0.477906834697145,-0.0895590446437754,2.5,-0.000342573957775152,-0.0450507381664826,-0.000675465173772042,49.997654,49.9978867,-21796.033,-21690.674,52.5613914041979,18.527881821819,31.733112,0,0,0,200,4961,49.9187,-21743.3535,,,,,,,,,,,,,0,,,,2.5744064,,,,,,49.99777035,,,,
,5778359.195,49.9987297,-14982.1455,-0.0329604637104722,4.35485637042815E-6,1,4.99626677034896,40.0298881530762,1.98220080866478,10.3500001132488,-0.349437194786142,-0.0654690470456238,2.5,-0.000248030229266618,-0.0329386519475709,-0.00049249950510491,49.9985809,49.9988785,-15033.837,-14930.454,52.7239701361979,18.5312626015391,31.733112,0,0,0,200,4961,49.9236,-14982.1455,,,,,,,,,,,,,0,,,,2.5744064,,,,,,49.9987297,,,,
,5778683.895,49.99929235,-8283.098,-0.0201782647294183,4.57752419600332E-6,1,4.99626677034896,40.0298881530762,1.98217385840897,10.3599997237325,-0.213842923675681,-0.0400781736052788,2.5,-0.000152741162638134,-0.0201577384201864,-0.000302627281704191,49.9989357,49.999649,-8337.474,-8228.722,52.8271451007364,18.5296866260861,31.733112,0,0,0,200,4961,49.92775,-8283.098,,,,,,,,,,,,,0,,,,2.52398455,,,,,,49.99929235,,,,
,5779023.72,49.9991951,-1269.717,-0.00437201913903471,0.00053339298126383,1,4.99626677034896,40.0298881530762,1.98231156031789,10.3500001132488,-0.0459040334394955,-0.0110055840351658,2.5,-0.000252152193413258,-0.00436453397003387,-0.000284326564860271,49.998909,49.9994812,-1316.466,-1222.968,52.7153722224863,18.5324971691432,31.733112,0,0,0,200,4961,49.92775,-1269.717,,,,,,,,,,,,,0,,,,2.5488164,,,,,,49.9991951,,,,
,5779383.4,49.99950985,5733.977,0.0153070684664963,5.82326019747362E-5,1,4.99626677034896,40.0298881530762,1.9822656053767,10.3500001132488,0.162351522353572,0.0295923217788753,2.5,3.96776725981163E-5,0.015290145718753,0.000153460655072627,49.9994164,49.9996033,5689.347,5778.607,53.2046716755249,18.5285452321845,31.351902,0,0,0,200,4961,49.93295,5733.977,,,,,,,,,,,,,0,,,,2.5488164,,,,,,49.99950985,,,,
,5779708.21,50.0003414,11816.431,0.027289244180813,6.08900799399502E-5,1,4.99626677034896,40.0298881530762,1.98222262060248,10.3599997237325,0.289214964642745,0.0544837942652087,2.5,0.000232218852485053,0.0272663697626222,0.000434805610895942,50.0001411,50.0005417,11767.705,11865.157,53.0647601705825,18.5280367680329,31.733112,0,0,0,200,4961,49.9309,11816.431,,,,,,,,,,,,,0,,,,2.48672425,,,,,,50.0003414,,,,
,5780037.905,49.99999045,18039.6555,0.0386865814406617,4.49967378808564E-6,1,4.99626677034896,40.0298881530762,1.98211593339859,10.3500001132488,0.41019240630897,0.076877151175032,2.5,0.000293960327367844,0.0386675466687526,0.000580459861517804,49.9998932,50.0000877,17992.061,18087.25,52.8052595021979,18.5227921817352,31.733112,0,0,0,200,4961,49.93115,18039.6555,,,,,,,,,,,,,0,,,,2.53614865,,,,,,49.99999045,,,,
,5780367.755,50.0000763,24275.924,0.0495884447287268,4.64835685755708E-6,1,4.99626677034896,40.0298881530762,1.98207061019262,10.3500001132488,0.525975119225931,0.0984557382430572,2.5,0.000367761745304179,0.049581205740946,0.000733260129170611,49.9998932,50.0002594,24229.459,24322.389,52.2760969946786,18.5291096515726,31.733112,0,0,0,200,4961,49.9275,24275.924,,,,,,,,,,,,,0,,,,2.510939,,,,,,50.0000763,,,,
,5780697.415,50.000721,30503.2335,0.0601678311025869,5.31368375558228E-6,1,4.99626677034896,40.0298881530762,1.98209153742655,10.3500001132488,0.638386654808659,0.119654435080829,2.5,0.000463876094851346,0.060179564036565,0.000904275385221668,50.0006409,50.0008011,30456.91,30549.557,52.4879183233902,18.5201556284757,31.733112,0,0,0,200,4961,49.92925,30503.2335,,,,,,,,,,,,,0,,,,2.48672425,,,,,,50.000721,,,,
,5781027.295,50.00084115,36732.9355,0.0704851836128267,5.94081683874959E-6,1,4.99626677034896,40.0298881530762,1.98222659450771,10.3500001132488,0.748165426575342,0.140162811357235,2.5,0.000542243685868945,0.0705225344723531,0.00105352199003747,50.0007324,50.0009499,36687.176,36778.695,52.4371124696402,18.5224473124724,31.733112,0,0,0,200,4961,49.9271,36732.9355,,,,,,,,,,,,,0,,,,2.5234809,,,,,,50.00084115,,,,
,5781356.925,49.9995823,42947.9435,0.0805869611468515,5.51495738097984E-6,1,4.99626677034896,40.0298881530762,1.98207848577821,10.3599997237325,0.855612609368428,0.160252831126982,2.5,0.000623130438014495,0.0806557406542153,0.00120131539356659,49.9995575,49.9996071,42899.078,42996.809,51.850891080217,18.5214485898812,31.733112,0,0,0,200,4961,49.9278,42947.9435,,,,,,,,,,,,,0,,,,2.5234809,,,,,,49.9995823,,,,
,5781681.695,49.9991951,49062.6875,0.0903186977925187,6.49379962910204E-6,1,4.99626677034896,40.0298881530762,1.98215841469543,10.3599997237325,0.959253958412531,0.179735405601042,2.5,0.000713268462337821,0.0904232773107945,0.00135326048170775,49.9987183,49.9996719,49016.363,49109.012,52.687233595794,18.5201985197535,31.351902,0,0,0,200,4961,49.9264,49062.6875,,,,,,,,,,,,,0,,,,2.5234809,,,,,,49.9991951,,,,
,5784049.97,25.0023489,44266.682,0.127069742759988,1.15804925337358E-5,1,4.99626677034896,40.0298881530762,1.98190364857781,10.9200002625585,1.34522436346931,0.251049236760387,25,0.000880279555032163,0.126768385055895,0.00180562875840658,25.0021038,25.002594,44216.262,44317.102,52.5824953742171,18.5215063518684,31.733112,0,0,0,200,4961,24.9814,44266.682,,,,,,,,,,,,,0,,,,2.02569175,,,,,,25.0023489,,,,
,5784374.73,25.0003376,37652.699,0.112396356430375,8.24348194834324E-6,1,4.99626677034896,40.0298881530762,1.98177593294733,10.9200002625585,1.18904880765066,0.221621515037868,25,0.000771154724629174,0.112053555105448,0.00157036561036691,25.0000954,25.0005798,37601.574,37703.824,52.311270278044,18.5201081646789,31.733112,0,0,0,200,4961,24.97975,37652.699,,,,,,,,,,,,,0,,,,2.0255907,,,,,,25.0003376,,,,
,5784699.515,25.00524425,31058.913,0.0972001516499187,8.54885634015545E-6,1,4.99626677034896,40.0298881530762,1.98207663700534,10.9200002625585,1.02780377443106,0.191157558988007,25,0.000652227820565944,0.0968376013272706,0.00131976125774947,25.0046387,25.0058498,31010.047,31107.779,52.8029146166402,18.5246082982883,31.351902,0,0,0,200,4961,24.98805,31058.913,,,,,,,,,,,,,0,,,,2.0255907,,,,,,25.00524425,,,,
,5785024.31,24.9988947,24468.368,0.08150989945687,7.63920202763168E-6,1,4.99626677034896,40.0298881530762,1.98211521707254,10.9200002625585,0.861380218993317,0.159905586261883,25,0.000544740585943035,0.0811512923133512,0.001078704030013,24.9986782,24.9991112,24416.254,24520.482,52.1963708857171,18.5276326321772,31.733112,0,0,0,200,4961,24.9825,24468.368,,,,,,,,,,,,,0,,,,2.0255907,,,,,,24.9988947,,,,
,5785354.03,25.0000563,17786.253,0.0648709423818842,7.02565232576764E-6,1,4.99626677034896,40.0298881530762,1.98220788581855,10.9200002625585,0.685175330420896,0.126913897556414,25,0.000432654237575018,0.0645435829666943,0.000832330744417995,25.0000458,25.0000668,17735.125,17837.381,52.7646148191979,18.5271128982027,31.733112,0,0,0,200,4961,24.98315,17786.253,,,,,,,,,,,,,0,,,,1.89883225,,,,,,25.0000563,,,,
,5785688.75,25.00000475,10980.868,0.0468082047747528,7.24257851315758E-6,1,4.99626677034896,40.0298881530762,1.98236381459317,10.9299998730421,0.494149580364164,0.091427080478422,25,0.000323572650086934,0.0465437999257308,0.000590791068794738,24.9998302,25.0001793,10929.46,11032.276,52.4683776104094,18.5296742793398,32.495537,0,0,0,200,4961,24.985,10980.868,,,,,,,,,,,,,0,,,,2.01552335,,,,,,25.00000475,,,,
,5786023.51,24.9998884,4163.0075,0.0257390031525884,8.70761091056284E-6,1,4.99626677034896,40.0298881530762,1.9821178269962,10.9200002625585,0.271492127662927,0.0501060349221153,2.5,0.000178352068823716,0.0255804964404997,0.0003132922766576,24.9998779,24.9998989,4108.209,4217.806,52.7091191943325,18.5247126800697,31.733112,0,0,0,200,4961,24.9857,4163.0075,,,,,,,,,,,,,0,,,,1.97585055,,,,,,24.9998884,,,,
,5786358.28,24.9991493,-2566.4215,-0.0201796023276315,7.12041559219443E-5,1,4.99626677034896,40.0298881530762,1.98218815492346,10.9200002625585,-0.212875725732606,-0.0390689683470072,2.5,-0.000121785191371574,-0.020053428633487,-0.000225648581982013,24.999094,24.9992046,-2604.413,-2528.43,52.4660327248517,18.5271786499969,31.733112,0,0,0,200,4961,24.98495,-2566.4215,,,,,,,,,,,,,0,,,,1.9859179,,,,,,24.9991493,,,,
,5786685.49,25.00034045,-8651.039,-0.0407902264226596,6.9912331248494E-6,1,4.99626677034896,40.0298881530762,1.98211154651966,10.9200002625585,-0.430367413003055,-0.0795581377970151,2.5,-0.000282241441689567,-0.0405521939915899,-0.000508539241678885,25.0001659,25.000515,-8739.592,-8562.486,52.0939775496978,18.523238061609,31.733112,0,0,0,200,4961,24.9863,-8651.039,,,,,,,,,,,,,0,,,,1.891139,,,,,,25.00034045,,,,
,5787012.8,25.00073245,-14742.228,-0.057314679463587,6.43220124079377E-6,1,4.99626677034896,40.0298881530762,1.98225565836471,10.9299998730421,-0.605026603643848,-0.112078941043896,2.5,-0.000394367343223145,-0.0570094715128737,-0.000736163087583399,25.0006981,25.0007668,-14789.683,-14694.773,52.8771693259671,18.5259306225057,31.733112,0,0,0,200,4961,24.98645,-14742.228,,,,,,,,,,,,,0,,,,2.01552335,,,,,,25.00073245,,,,
,5787342.545,25.0004177,-20907.299,-0.0729574438541502,6.75960995267633E-6,1,4.99626677034896,40.0298881530762,1.98227485286408,10.9299998730421,-0.770548172888753,-0.143092021546072,2.5,-0.000506319062372734,-0.072610803810086,-0.000969587998146909,25.0004177,25.0004177,-20954.188,-20860.41,53.1233823095249,18.5229120783714,31.733112,0,0,0,200,4961,24.9841,-20907.299,,,,,,,,,,,,,0,,,,2.0255907,,,,,,25.0004177,,,,
,5787667.32,25.0008516,-26971.6475,-0.0876934313474134,7.3585502933564E-6,1,4.99626677034896,40.0298881530762,1.98224537229742,10.9200002625585,-0.92669212771748,-0.172322779717905,2.5,-0.000601807779928339,-0.0873295937127243,-0.00118750331701698,25.0005531,25.0011501,-27019.525,-26923.77,52.321431448794,18.5270495916298,31.733112,0,0,0,200,4961,24.9831,-26971.6475,,,,,,,,,,,,,0,,,,2.005456,,,,,,25.0008516,,,,
,5787992.095,25.0007572,-33037.947,-0.101913095871083,7.22341666201518E-6,1,4.99626677034896,40.0298881530762,1.98225107285847,10.9299998730421,-1.07759908190991,-0.20058885615615,2.5,-0.000691423311904002,-0.101553685871182,-0.00139952678499535,25.0003986,25.0011158,-33080.316,-32995.578,52.033792153717,18.5334176050671,31.733112,0,0,0,200,4961,24.982,-33037.947,,,,,,,,,,,,,0,,,,2.005456,,,,,,25.0007572,,,,
,5788321.82,24.9997578,-39190.5355,-0.115954010382453,9.81540624266499E-6,1,4.99626677034896,40.0298881530762,1.98230251614261,10.9200002625585,-1.22718092593906,-0.228806520908874,25,-0.000797532964544262,-0.115618772035812,-0.00162740883868481,24.9997311,24.9997845,-39237.141,-39143.93,52.8904570107941,18.5302862897386,31.733112,0,0,0,200,4961,24.98245,-39190.5355,,,,,,,,,,,,,0,,,,2.0255907,,,,,,24.9997578,,,,
,5788651.565,25.0001011,-45335.0665,-0.129519490031731,1.00820390267741E-5,1,4.99626677034896,40.0298881530762,1.98224314307711,10.9200002625585,-1.37151685583501,-0.256049552415775,25,-0.000903237365978421,-0.129226295402562,-0.00184915681973044,25.000082,25.0001202,-45381.813,-45288.32,52.7958799599671,18.5289717907044,31.351902,0,0,0,200,4961,24.9805,-45335.0665,,,,,,,,,,,,,0,,,,1.9463421,,,,,,25.0001011,,,,
,5789026.33,24.99981405,-48094.3635,-0.135457791208256,1.11600785661784E-5,1,4.99626677034896,40.0298881530762,1.98231540938154,10.9200002625585,-1.43481210442976,-0.268073331843306,25,-0.000957744649700502,-0.13518858397949,-0.00195333678246351,24.9996815,24.9999466,-48152.832,-48035.895,52.0330105251978,18.5322436515199,31.351902,0,0,0,200,4961,24.9802,-48094.3635,,,,,,,,,,,,,0,,,,1.9859179,,,,,,24.99981405,,,,
,5789356.03,25.0001078,-41119.3985,-0.120127506432868,1.1052199573386E-5,1,4.99626677034896,40.0298881530762,1.98241712606255,10.9200002625585,-1.2716710575164,-0.237121961490572,25,-0.00082209982583669,-0.119804075136258,-0.00168816870579042,24.9999943,25.0002213,-41169.82,-41068.977,52.3753638166209,18.5327207754299,31.733112,0,0,0,200,4961,24.9823,-41119.3985,,,,,,,,,,,,,0,,,,2.005456,,,,,,25.0001078,,,,
,5789680.8,24.99947645,-34450.055,-0.105080919751597,9.37717496683354E-6,1,4.99626677034896,40.0298881530762,1.98223656058042,10.9200002625585,-1.11159405697363,-0.206851092070699,25,-0.00070146546486614,-0.104725761509097,-0.00143725501506089,24.9994431,24.9995098,-34501.18,-34398.93,52.128369204544,18.5331203129665,31.733112,0,0,0,200,4961,24.98185,-34450.055,,,,,,,,,,,,,0,,,,2.005456,,,,,,24.99947645,,,,
,5790005.63,24.9994345,-27787.764,-0.0895005251250745,8.5946804330213E-6,1,4.99626677034896,40.0298881530762,1.98213775554141,10.9200002625585,-0.946113416865704,-0.175862958082247,25,-0.000604217179249265,-0.0891366712733528,-0.00120558148516688,24.9993458,24.9995232,-27839.313,-27736.215,52.2393604542748,18.5327966676569,31.351902,0,0,0,200,4961,24.9828,-27787.764,,,,,,,,,,,,,0,,,,1.9657851,,,,,,24.9994345,,,,
,5790330.345,24.99932575,-21129.9875,-0.073296898820794,7.70334294249471E-6,1,4.99626677034896,40.0298881530762,1.98218360079878,10.9200002625585,-0.774369038239765,-0.143677674059679,25,-0.000496398940380157,-0.0729503043157707,-0.000962837137581243,24.9992466,24.9994049,-21181.961,-21078.014,51.7438079730824,18.5269701927737,31.733112,0,0,0,200,4961,24.98385,-21129.9875,,,,,,,,,,,,,0,,,,2.005456,,,,,,24.99932575,,,,
,5790660.11,24.9999838,-14369.6245,-0.0559780163570375,7.24225931877518E-6,1,4.99626677034896,40.0298881530762,1.98228401166403,10.9200002625585,-0.591078298974873,-0.10951444378056,25,-0.000388315349540921,-0.055678050988612,-0.000720735230736798,24.9998913,25.0000763,-14422.021,-14317.228,52.0650572944863,18.5270423483642,31.733112,0,0,0,200,4961,24.9849,-14369.6245,,,,,,,,,,,,,0,,,,2.005456,,,,,,24.9999838,,,,
,5790999.85,24.99997525,-7362.546,-0.0363123314605296,6.85852363741937E-6,1,4.99626677034896,40.0298881530762,1.98230876404068,10.9200002625585,-0.383126047742364,-0.0707948243805281,2.5,-0.000251693379274256,-0.0360968628148143,-0.000449913359077664,24.9998589,25.0000916,-7416.355,-7308.737,52.219819741294,18.5240154149013,31.733112,0,0,0,200,4961,24.98635,-7362.546,,,,,,,,,,,,,0,,,,1.9954888,,,,,,24.99997525,,,,
,5791324.625,24.9987917,-673.4195,-0.00712752835359047,2.29618696686609E-5,1,4.99626677034896,40.0298881530762,1.9821262867427,10.9200002625585,-0.0751539645041183,-0.0139381969761504,2.5,-5.7083059875859E-5,-0.00708218479414632,-9.2928656127805E-5,24.998703,24.9988804,-731.467,-615.372,52.7732127329094,18.5263751600228,31.733112,0,0,0,200,4961,24.98715,-673.4195,,,,,,,,,,,,,0,,,,2.005456,,,,,,24.9987917,,,,
,5791659.36,24.9995575,5829.874,0.0321376073812124,7.04286547899811E-6,1,4.99626677034896,40.0298881530762,1.98227470819354,10.9200002625585,0.339051399908451,0.0625578736316544,2.5,0.00021759648252245,0.0319433668542759,0.000389692780906882,24.9993324,24.9997826,5778.889,5880.859,52.4152268711017,18.5281917700488,31.733112,0,0,0,200,4961,24.98875,5829.874,,,,,,,,,,,,,0,,,,2.005456,,,,,,24.9995575,,,,
,5791989.18,25.00021265,12015.991,0.0500705052281326,6.30806052105162E-6,1,4.99626677034896,40.0298881530762,1.98194325803454,10.9200002625585,0.528373677400054,0.0977370702136643,2.5,0.000340573033211882,0.0497920451028138,0.000630005949875901,25.0000629,25.0003624,11969.949,12062.033,52.934228207871,18.5245009941545,31.351902,0,0,0,200,4961,24.988,12015.991,,,,,,,,,,,,,0,,,,1.98562055,,,,,,25.00021265,,,,
,5792318.885,24.99963,18229.045,0.0662561221943461,5.92004077588106E-6,1,4.99626677034896,40.0298881530762,1.98223674369553,10.9200002625585,0.699631589014365,0.129614529864881,2.5,0.000442175453525313,0.0659245242750168,0.000852227559583092,24.999136,25.000124,18179.613,18278.477,52.6848887102363,18.5301221953999,31.733112,0,0,0,200,4961,24.9854,18229.045,,,,,,,,,,,,,0,,,,1.9657851,,,,,,24.99963,,,,
,5792653.635,24.9999094,24556.2675,0.0818927895509225,7.02217690694088E-6,1,4.99626677034896,40.0298881530762,1.982016560335,10.9299998730421,0.865149138273564,0.160518327604887,2.5,0.000538960983459113,0.0815332874152806,0.00107586189290328,24.9997826,25.0000362,24507.967,24604.568,52.4504001544671,18.5282540428945,31.733112,0,0,0,200,4961,24.98605,24556.2675,,,,,,,,,,,,,0,,,,1.9954888,,,,,,24.9999094,,,,
,5792983.43,25.00099755,30787.389,0.0966960448201212,7.63076904147322E-6,1,4.99626677034896,40.0298881530762,1.98200299650526,10.9200002625585,1.0220997686929,0.190109570782962,2.5,0.000651122214675094,0.0963326375482283,0.00131405282439231,25.0005283,25.0014668,30740.219,30834.559,53.1859125910633,18.5225176649598,31.733112,0,0,0,200,4961,24.98385,30787.389,,,,,,,,,,,,,0,,,,1.9954888,,,,,,25.00099755,,,,
,5793313.135,25.0003824,37013.842,0.111033033517337,8.43740066058991E-6,1,4.99626677034896,40.0298881530762,1.98226920508059,10.9200002625585,1.17486548016571,0.218767842048511,25,0.000744772300898222,0.110687196091145,0.0015320825069147,25.0000362,25.0007286,36966.813,37060.871,52.9131242378518,18.5216113360845,32.114323,0,0,0,200,4961,24.98315,37013.842,,,,,,,,,,,,,0,,,,2.005456,,,,,,25.0003824,,,,
,5793637.92,25.00002195,43137.334,0.124702960971232,8.64742537030959E-6,1,4.99626677034896,40.0298881530762,1.98201507808231,10.9200002625585,1.32013289377623,0.24610466698694,25,0.000842807687390261,0.124393041740612,0.00174793901606663,24.9999237,25.0001202,43092.281,43182.387,52.9334465793518,18.5263475973984,31.733112,0,0,0,200,4961,24.9822,43137.334,,,,,,,,,,,,,0,,,,1.93773175,,,,,,25.00002195,,,,
,5793962.7,25.00010205,49250.527,0.137932865566183,9.11555019332576E-6,1,4.99626677034896,40.0298881530762,1.98209463063506,10.9200002625585,1.46107975317529,0.27275760439536,25,0.000952844816994566,0.137674747950507,0.00196890969944196,24.9998951,25.000309,49204.484,49296.57,52.5582648901209,18.524132373045,31.733112,0,0,0,200,4961,24.98015,49250.527,,,,,,,,,,,,,0,,,,1.9011062,,,,,,25.00010205,,,,
,5797485.045,1.9994843,44035.0665,0.152900630085879,1.04910262840471E-5,1,4.99626677034896,40.0298881530762,1.99288422773586,11.0400002449751,1.62721609522925,0.302794741387228,25,0.000985116563602184,0.152517354665596,0.00209260895264372,1.998014,2.0009546,43985.211,44084.922,52.9639300916018,18.5194541182302,31.733112,0,0,0,200,4961,1.9633,44035.0665,,,,,,,,,,,,,0,,,,0.38005945,,,,,,1.9994843,,,,
,5797809.825,1.99725555,37421.791,0.134966626148017,1.21749385836151E-5,1,4.99626677034896,40.0298881530762,1.99312879229154,11.0400002449751,1.43559376418373,0.266719088789685,25,0.000856847223916,0.134534410847863,0.00180797814393374,1.996883,1.9976281,37371.09,37472.492,52.3292477339863,18.5187778326766,31.733112,0,0,0,200,4961,1.96345,37421.791,,,,,,,,,,,,,0,,,,0.3688382,,,,,,1.99725555,,,,
,5798134.605,1.9974272,30827.5775,0.117008439482009,1.01894218471509E-5,1,4.99626677034896,40.0298881530762,1.9931009326751,11.0400002449751,1.24375334570594,0.230712860494319,25,0.000740690942579173,0.116552265153939,0.00153332381426594,1.9962273,1.9986271,30775.604,30879.551,52.2776602517171,18.5213067046903,31.733112,0,0,0,200,4961,1.96665,30827.5775,,,,,,,,,,,,,0,,,,0.3597362,,,,,,1.9974272,,,,
,5798464.35,2.0005702,24137.744,0.0985188822654308,9.7094499458064E-6,1,4.99626677034896,40.0298881530762,1.99305821192026,11.0400002449751,1.0465254972989,0.193790064961866,25,0.000627258632452685,0.0980667678344144,0.00125954756596592,2.0000701,2.0010703,24086.619,24188.869,52.768522961794,18.521481407563,32.114323,0,0,0,200,4961,1.97305,24137.744,,,,,,,,,,,,,0,,,,0.35263765,,,,,,2.0005702,,,,
,5798789.125,1.99660475,17555.4785,0.0798608751758464,8.53865263349164E-6,1,4.99626677034896,40.0298881530762,1.99327115411302,11.0400002449751,0.847926945412062,0.156665433543476,25,0.000509779444423356,0.0794430967580627,0.000988709663040658,1.9958915,1.997318,17506.33,17604.627,52.5301262634286,18.5255020518939,31.733112,0,0,0,200,4961,1.9789,17555.4785,,,,,,,,,,,,,0,,,,0.349115,,,,,,1.99660475,,,,
,5799113.845,1.99519385,10954.4595,0.0602800672496785,8.15562952716349E-6,1,4.99626677034896,40.0298881530762,1.9931559423465,11.0400002449751,0.639655807659255,0.117943870411958,25,0.000391126379283593,0.0599295366429256,0.000724034168234851,1.9949279,1.9954598,10904.04,11004.879,52.626266571294,18.5218412734513,31.733112,0,0,0,200,4961,1.98795,10954.4595,,,,,,,,,,,,,0,,,,0.3456447,,,,,,1.99519385,,,,
,5799448.645,1.99499115,4126.1485,0.03594041410714,1.12307503709811E-5,1,4.99626677034896,40.0298881530762,1.99331122338901,11.0400002449751,0.381127851917759,0.0700976886939503,2.5,0.000234951794311906,0.0357132278133622,0.00041541129380465,1.9944654,1.9955169,4067.254,4185.043,52.2784418802363,18.5194154280962,31.351902,0,0,0,200,4961,1.99655,4126.1485,,,,,,,,,,,,,0,,,,0.3405082,,,,,,1.99499115,,,,
,5799783.385,1.998012,-2591.278,-0.0279530585868774,1.52989355290206E-5,1,4.99626677034896,40.0298881530762,1.99341674800204,11.0400002449751,-0.296405215968052,-0.054563076409797,2.5,-0.000189988391933092,-0.0277737071780109,-0.000327385538122772,1.9978689,1.9981551,-2646.782,-2535.774,52.2643725668901,18.5203362789123,32.114323,0,0,0,200,4961,1.9964,-2591.278,,,,,,,,,,,,,0,,,,0.3354396,,,,,,1.998012,,,,
,5800108.155,2.0003964,-8637.057,-0.0533117379436755,7.67578275065186E-6,1,4.99626677034896,40.0298881530762,1.99349065733217,11.0400002449751,-0.565543880423848,-0.10418731380434,2.5,-0.000346708972848457,-0.05299186027056,-0.000631940267336957,1.9977508,2.003042,-8686.206,-8587.908,52.8779509544864,18.5322935987763,31.733112,0,0,0,200,4961,1.9965,-8637.057,,,,,,,,,,,,,0,,,,0.3321053,,,,,,2.0003964,,,,
,5800432.885,2.0024879,-14677.4,-0.0717769126792085,7.32895079750322E-6,1,4.99626677034896,40.0298881530762,1.9930491591498,11.0400002449751,-0.761590049012601,-0.14067358223485,2.5,-0.000468860763547993,-0.0713824650180625,-0.000884765342811204,2.0023217,2.0026541,-14723.582,-14631.218,52.7341313069479,18.5279532072644,31.733112,0,0,0,200,4961,1.98815,-14677.4,,,,,,,,,,,,,0,,,,0.32395015,,,,,,2.0024879,,,,
,5800757.64,2.00187305,-20747.5625,-0.0891932703759924,7.84481074404274E-6,1,4.99626677034896,40.0298881530762,1.99344318192387,11.0400002449751,-0.94708035093822,-0.175105540669527,2.5,-0.000561644292133155,-0.088753956692111,-0.00111548536749528,2.0017164,2.0020297,-20794.877,-20700.248,52.5527934904863,18.5358118795146,31.733112,0,0,0,200,4961,1.9813,-20747.5625,,,,,,,,,,,,,0,,,,0.3190962,,,,,,2.00187305,,,,
,5801087.44,2.00243655,-26904.704,-0.106345862833013,9.45779879314996E-6,1,4.99626677034896,40.0298881530762,1.9932429229041,11.0400002449751,-1.12970043324031,-0.209490455981286,2.5,-0.000687917337182333,-0.105887766500605,-0.00138705267474343,2.0021701,2.002703,-26950.887,-26858.521,52.9303200652748,18.5315455448664,31.733112,0,0,0,200,4961,1.97405,-26904.704,,,,,,,,,,,,,0,,,,0.312784,,,,,,2.00243655,,,,
,5801417.175,2.001863,-33063.088,-0.123273705699515,1.0030252355313E-5,1,4.99626677034896,40.0298881530762,1.99328255581,11.0400002449751,-1.31074606759412,-0.243310397338808,25,-0.000783704337820136,-0.122822085058331,-0.00163126121673144,2.0016692,2.0020568,-33110.543,-33015.633,52.5441955767748,18.5320870439665,31.733112,0,0,0,200,4961,1.96905,-33063.088,,,,,,,,,,,,,0,,,,0.3096749,,,,,,2.001863,,,,
,5801741.9,2.0015372,-39122.6035,-0.139722292991647,1.07721678245315E-5,1,4.99626677034896,40.0298881530762,1.99320754937348,11.0400002449751,-1.48646622970376,-0.276384787301154,25,-0.000898735284993468,-0.139299905319105,-0.00189141780767804,2.0013983,2.0016761,-39170.48,-39074.727,52.6856703387556,18.5375570690131,31.733112,0,0,0,200,4961,1.9653,-39122.6035,,,,,,,,,,,,,0,,,,0.3050729,,,,,,2.0015372,,,,
,5802071.68,2.00136905,-45267.5605,-0.156334020037171,1.14002523334468E-5,1,4.99626677034896,40.0298881530762,1.99360052975362,11.0400002449751,-1.66450068560891,-0.309979286215218,25,-0.00102545690217403,-0.155962067649999,-0.00216220617831818,1.9985503,2.0041878,-45314.023,-45221.098,52.3034539928517,18.5376273080041,31.351902,0,0,0,200,4961,1.962,-45267.5605,,,,,,,,,,,,,0,,,,0.3005318,,,,,,2.00136905,,,,
,5802441.43,2.00225865,-48305.5035,-0.164550215511842,1.34868100125733E-5,1,4.99626677034896,40.0298881530762,1.99325166911821,11.0400002449751,-1.75220783136779,-0.326474384837585,25,-0.00108493434098291,-0.164210230594483,-0.00229118028481211,2.0001783,2.004339,-48364.398,-48246.609,51.9775149003324,18.5365643822023,31.733112,0,0,0,200,4961,1.96005,-48305.5035,,,,,,,,,,,,,0,,,,0.2975444,,,,,,2.00225865,,,,
,5802771.205,1.99770105,-41304.977,-0.145502544376282,1.23514332195978E-5,1,4.99626677034896,40.0298881530762,1.99334701213429,11.0400002449751,-1.54840377947777,-0.28801067670942,25,-0.000936596067304408,-0.145096174716388,-0.00198004721294115,1.9973874,1.9980147,-41359.352,-41250.602,52.1948076286786,18.5363628568365,31.733112,0,0,0,200,4961,1.9606,-41304.977,,,,,,,,,,,,,0,,,,0.2960656,,,,,,1.99770105,,,,
,5803095.92,1.9979276,-34638.033,-0.127415400473969,9.91428563119353E-6,1,4.99626677034896,40.0298881530762,1.9933310781601,11.0400002449751,-1.35500929111999,-0.251718285674949,25,-0.000819280493921725,-0.126969746827144,-0.00170369044223042,1.9969876,1.9988676,-34688.453,-34587.613,52.4121003570248,18.5350184246641,31.733112,0,0,0,200,4961,1.96395,-34638.033,,,,,,,,,,,,,0,,,,0.28741035,,,,,,1.9979276,,,,
,5803420.68,1.9976275,-27975.745,-0.109150288806693,1.04807240424832E-5,1,4.99626677034896,40.0298881530762,1.99332858576773,11.0400002449751,-1.15998567261091,-0.215279591345069,25,-0.000715698881816727,-0.108692121167993,-0.00143946796724049,1.9960796,1.9991754,-28026.59,-27924.9,51.8516727087362,18.5295221727118,31.733112,0,0,0,200,4961,1.9686,-27975.745,,,,,,,,,,,,,0,,,,0.28590345,,,,,,1.9976275,,,,
,5803745.505,1.9973045,-21315.1415,-0.0905858627575048,9.08072132619096E-6,1,4.99626677034896,40.0298881530762,1.99331961832983,11.0400002449751,-0.962115112200075,-0.178098084851908,25,-0.000586553747738291,-0.0901446223555367,-0.00115224231306165,1.9972419,1.9973671,-21367.82,-21262.463,52.5731158319863,18.5299283945899,31.733112,0,0,0,200,4961,1.9729,-21315.1415,,,,,,,,,,,,,0,,,,0.2873243,,,,,,1.9973045,,,,
,5804075.21,1.99796465,-14556.758,-0.07115500970775,8.31492525499915E-6,1,4.99626677034896,40.0298881530762,1.99304980507032,11.0400002449751,-0.75522154803704,-0.139426150185908,25,-0.000458928998712236,-0.0707632487227685,-0.000870646711689738,1.9970388,1.9988905,-14609.578,-14503.938,52.6121972579479,18.5293674254481,31.733112,0,0,0,200,4961,1.9821,-14556.758,,,,,,,,,,,,,0,,,,0.2858891,,,,,,1.99796465,,,,
,5804399.95,1.99639785,-7851.21,-0.0503106376069023,7.84107706993035E-6,1,4.99626677034896,40.0298881530762,1.99348471576678,11.0400002449751,-0.53383763177894,-0.0983210645074564,25,-0.000327817628664275,-0.0500057484627407,-0.000594049866020456,1.9956487,1.997147,-7903.325,-7799.095,52.2331074261209,18.5390054994953,31.733112,0,0,0,200,4961,1.99025,-7851.21,,,,,,,,,,,,,0,,,,0.28446825,,,,,,1.99639785,,,,
,5804734.72,1.99959855,-939.3685,-0.0135067025234126,2.47786712017487E-5,1,4.99626677034896,40.0298881530762,1.99338037145914,11.0400002449751,-0.143207897303719,-0.0263486832261415,2.5,-9.19280000443857E-5,-0.0134188655905123,-0.000156960302332102,1.9946905,2.0045066,-997.839,-880.898,51.8125912827747,18.5286799757993,31.733112,0,0,0,200,4961,1.99805,-939.3685,,,,,,,,,,,,,0,,,,0.2830474,,,,,,1.99959855,,,,
,5805069.49,1.99992825,5575.0885,0.0426460983468539,3.32224399543395E-5,1,4.99626677034896,40.0298881530762,1.99334384795773,11.0400002449751,0.452251196832291,0.0833997964552728,2.5,0.000294559408544018,0.0423805594273631,0.000512996362423925,1.9991565,2.0007,5536.531,5613.646,51.9564109303132,18.528771628304,31.733112,0,0,0,200,4961,1.99535,5575.0885,,,,,,,,,,,,,0,,,,0.2830474,,,,,,1.99992825,,,,
,5805394.295,2.00229665,11667.855,0.0628783165413049,7.05043075858978E-6,1,4.99626677034896,40.0298881530762,1.9932823907932,11.0400002449751,0.667107873589578,0.12300536047268,2.5,0.000404665825634,0.0625164219117911,0.000755260305027213,2.0008237,2.0037696,11620.262,11715.448,52.1213345478709,18.533118628606,31.733112,0,0,0,200,4961,1.9905,11667.855,,,,,,,,,,,,,0,,,,0.2788411,,,,,,2.00229665,,,,
,5805719.01,2.002116,17774.8455,0.0807719748853134,6.86261195250509E-6,1,4.99626677034896,40.0298881530762,1.99313326998231,11.0400002449751,0.857303833156542,0.15840432650324,2.5,0.000514980970859923,0.0803510952350683,0.00100058957679807,2.0012949,2.0029371,17729.369,17820.322,52.3229947058325,18.5294198223805,31.733112,0,0,0,200,4961,1.9822,17774.8455,,,,,,,,,,,,,0,,,,0.2746904,,,,,,2.002116,,,,
,5806043.73,2.00270495,23913.663,0.0980772281228894,8.36025825977852E-6,1,4.99626677034896,40.0298881530762,1.99315601969611,11.0400002449751,1.04155223143346,0.19284253075864,2.5,0.000623300011902516,0.09762493234064,0.00125146074994989,2.0022559,2.003154,23866.209,23961.117,52.3816168447748,18.5303897011974,31.733112,0,0,0,200,4961,1.97535,23913.663,,,,,,,,,,,,,0,,,,0.2587094,,,,,,2.00270495,,,,
,5806373.49,2.00133505,30144.6475,0.115292527794307,1.14364037485918E-5,1,4.99626677034896,40.0298881530762,1.99323630765527,11.0400002449751,1.22553491519833,0.227163248397929,25,0.000718035777818803,0.114834873895251,0.0014953149803171,2.0009654,2.0017047,30097.617,30191.678,52.2565562816978,18.537176865468,31.733112,0,0,0,200,4961,1.9698,30144.6475,,,,,,,,,,,,,0,,,,0.27196,,,,,,2.00133505,,,,
,5806703.27,2.0004691,36370.3945,0.132220157628859,1.03062236498194E-5,1,4.99626677034896,40.0298881530762,1.99347903082186,11.0400002449751,1.40648530361688,0.261166160456059,25,0.000831127208137868,0.131782077142756,0.00175786716607148,2.0000422,2.000896,36321.387,36419.402,52.3597312462363,18.5339269738809,32.114323,0,0,0,200,4961,1.9637,36370.3945,,,,,,,,,,,,,0,,,,0.2692567,,,,,,2.0004691,,,,
,5807028.035,2.0041194,42495.297,0.148823056825143,1.14637992406113E-5,1,4.99626677034896,40.0298881530762,1.99330087188395,11.0400002449751,1.58390879638113,0.294585596204551,25,0.000950665991031436,0.148426081808854,0.00202284447014875,2.0041108,2.004128,42449.961,42540.633,52.443365497794,18.5316846854374,31.351902,0,0,0,200,4961,1.9605,42495.297,,,,,,,,,,,,,0,,,,0.2665802,,,,,,2.0041194,,,,
,5807352.815,1.99891505,48610.039,0.165349158241256,1.23798320498011E-5,1,4.99626677034896,40.0298881530762,1.99329087223001,11.0400002449751,1.7608327710391,0.32791335530967,25,0.00107417057642844,0.165012789660596,0.00228715550564462,1.9964246,2.0014055,48562.445,48657.633,53.3805380923518,18.5365298761415,31.351902,0,0,0,200,4961,1.9591,48610.039,,,,,,,,,,,,,0,,,,0.260086,,,,,,1.99891505,,,,
,5807457.7,1.9992246,50000.715,0.169165066355825,1.23208111802537E-5,1,4.99626677034896,40.0298881530762,1.99328366931944,11.0400002449751,1.80167857603817,0.335750142317079,25,0.00111651506683096,0.168844749073998,0.00236112420003167,1.999074,1.9993752,50000.512,50000.918,52.8482490707556,18.5305006166852,31.733112,0,0,0,200,4929,1.9569,50000.715,,,,,,,,,,,,,0,,,,0.26261865,,,,,,1.9992246,,,,