File: DataToTest/Dy5MnGa13Ge2_2-20K_230K_2021_07_28.DAT
[Header]
; VSM Data File (default extension .dat)
; Copyright (c) 2003-2013, Quantum Design, Inc. All rights reserved.
TITLE,Dy5MnGa13Ge2_2-20K_230K_2021_07_28
FILEOPENTIME,29494793.22,07/28/2021,11:44 am
BYAPP,VSM,2.0,2.0
INFO,PPMS VSM Option Release 1.4.10 Build 1,APPNAME
INFO,Quantum Design Linear Motor Servo Controller,MOTOR_MODULE_NAME
INFO,3101-100 C1,MOTOR_HW_VERSION
INFO,074,MOTOR_SERIAL_NUMBER
INFO,SRV No X-over 01.01.11,MOTOR_SOFTWARE_VERSION
INFO,Quantum Design VSM Detection Module,VSM_MODULE_NAME
INFO,3101-150 E1,VSM_HW_VERSION
INFO,VSM061,VSM_SERIAL_NUMBER
INFO,VSM No X-over 01.02.05 May 20 2008 13:51:47,VSM_SOFTWARE_VERSION
INFO,113,PREAMP_SERIAL_NUMBER
INFO,Quantum Design VSM Oven,OVEN_MODULE_NAME
INFO,3101-200 B0,OVEN_HW_VERSION
INFO,OVN054,OVEN_SERIAL_NUMBER
INFO,01.01.00,OVEN_SOFTWARE_VERSION
INFO,221,COIL_SERIAL_NUMBER
INFO,0,MOMENT_UNITS
INFO,Dy5MnGa13Ge2,SAMPLE_MATERIAL
INFO,,SAMPLE_COMMENT
INFO,9,SAMPLE_MASS
INFO,,SAMPLE_VOLUME
INFO,,SAMPLE_MOLECULAR_WEIGHT
INFO,,SAMPLE_SIZE
INFO,,SAMPLE_SHAPE
DATATYPE,COMMENT,1
DATATYPE,TIME,2
STARTUPAXIS,X,2
STARTUPAXIS,Y1,5
[Data]
Comment,Time Stamp (sec),Temperature (K),Magnetic Field (Oe),Moment (emu),M. Std. Err. (emu),Transport Action,Averaging Time (sec),Frequency (Hz),Peak Amplitude (mm),Center Position (mm),Coil Signal' (mV),Coil Signal" (mV),Range (mV),M. Quad. Signal (emu),M. Raw' (emu),M. Raw" (emu),Min. Temperature (K),Max. Temperature (K),Min. Field (Oe),Max. Field (Oe),Mass (grams),Motor Lag (deg),Pressure (Torr),VSM Status (code),Motor Status (code),Measure Status (code),Measure Count,PPMS Status (code),System Temp. (K),System Field (Oe),Sample Position (deg),Bridge 1 Resistance (ohms),Bridge 1 Excitation (에),Bridge 2 Resistance (ohms),Bridge 2 Excitation (에),Bridge 3 Resistance (ohms),Bridge 3 Excitation (에),Bridge 4 Resistance (ohms),Bridge 4 Excitation (에),Signal 1 Vin (V),Signal 2 Vin (V),Digital Inputs (code),Drive 1 Iout (mA),Drive 1 Ipower (W),Drive 2 Iout (mA),Drive 2 Ipower (W),Pressure (),Map 20 (),Map 21 (),Map 22 (),Map 23 (),Map 24 (),Map 25 (),Map 26 (),Map 27 (),Map 28 (),Map 29 ()
,29500768.42,2.0006683,999.83,0.271674660455343,2.83166276576183E-5,1,2.99776006220938,40.0298881530762,1.9918096826134,10.2899996563792,2.87999474039341,0.525159033858727,25,0.00141657127058568,0.269910772696341,0.00272833269356644,2.0003269,2.0010097,999.83,999.83,51.5851373836785,18.5391775895813,40.500973,0,0,0,120,4369,1.9972,999.83,,,,,,,,,,,,,0,,,,3.32135495,,,,,,2.0006683,,,,
,29500867.385,3.5210588,999.83,0.271427825345306,3.26080052670157E-5,1,2.99776006220938,40.0298881530762,1.99190981185696,10.2899996563792,2.87752562941047,0.524664675551937,25,0.00141125607042044,0.269665672565845,0.00272185285751373,3.4891343,3.5529833,999.83,999.83,51.9822046714478,18.5380598217397,41.644608,0,0,0,120,4370,3.5435,999.83,,,,,,,,,,,,,0,,,,4.2849197,,,,,,3.5210588,,,,
,29500964.86,5.15030315,999.83,0.270650108376718,3.29253267395661E-5,1,2.99776006220938,40.0298881530762,1.99175317970259,10.2899996563792,2.86895029318806,0.52376311880885,25,0.00146765386116845,0.268892670252266,0.00277410413465173,5.1031075,5.1974988,999.83,999.83,51.962663958467,18.5321724762401,41.644608,0,0,0,120,4370,5.1699,999.83,,,,,,,,,,,,,0,,,,5.4732127,,,,,,5.15030315,,,,
,29501062.305,6.75947905,999.83,0.269949570636968,2.96359292585052E-5,1,2.99776006220938,40.0298881530762,1.99163002065177,10.2899996563792,2.86142477928214,0.521967606782218,25,0.00142535854160218,0.268196666447079,0.00272867416374567,6.7335954,6.7853627,999.83,999.83,52.2034055423901,18.5292205478919,41.644608,0,0,0,120,4370,6.79885,999.83,,,,,,,,,,,,,0,,,,6.3897567,,,,,,6.75947905,,,,
,29501158.17,8.352458,999.83,0.271204922739421,2.46594024952475E-5,1,2.99776006220938,40.0298881530762,1.99179290209127,10.2899996563792,2.87507089401049,0.523769623441876,25,0.0013692427568529,0.269443812496005,0.00267902145502217,8.3276367,8.3772793,999.83,999.83,52.6434623987171,18.532312051396,40.500973,0,0,0,120,4370,8.39735,999.83,,,,,,,,,,,,,0,,,,7.2039132,,,,,,8.352458,,,,
,29501254.165,9.3963208,999.83,0.276178383662479,4.6876843651201E-5,1,2.99776006220938,40.0298881530762,1.99175165406234,10.2899996563792,2.92758996396592,0.534173979869239,25,0.0014707400703326,0.274384279482875,0.00280404050050581,9.2618599,9.5307817,999.83,999.83,52.199497399794,18.5217241498794,41.263397,0,0,0,120,4374,9.77275,999.83,,,,,,,,,,,,,0,,,,8.00031115,,,,,,9.3963208,,,,
,29501350.015,11.5186014,999.83,0.289733290295467,3.65790413292141E-5,1,2.99776006220938,40.0298881530762,1.99170850583611,10.3000001981854,3.07142055136246,0.559149769404084,25,0.00142716931784556,0.287850776545053,0.00282664843934596,11.4910173,11.5461855,999.83,999.83,52.9201588945248,18.5255107423327,40.882183,0,0,0,120,4370,11.58655,999.83,,,,,,,,,,,,,0,,,,9.06473065,,,,,,11.5186014,,,,
,29501445.95,13.07270815,999.83,0.292434147875965,2.84623332347881E-5,1,2.99776006220938,40.0298881530762,1.99175468355345,10.2899996563792,3.10003477563134,0.564807508660957,25,0.00148142793340271,0.290533020185535,0.00289367907840081,13.0484476,13.0969687,999.83,999.83,52.4527450400248,18.5240999814464,41.263397,0,0,0,120,4370,13.1391,999.83,,,,,,,,,,,,,0,,,,9.4342871,,,,,,13.07270815,,,,
,29501541.895,14.65507265,999.83,0.285184844008549,2.72980120047525E-5,1,2.99776006220938,40.0298881530762,1.99178237304861,10.3000001981854,3.02313357031786,0.551276475665124,25,0.00148852043320953,0.283329612739288,0.00286546846720123,14.6325235,14.6776218,999.83,999.83,52.372237302544,18.522710161943,40.500973,0,0,0,120,4370,14.73205,999.83,,,,,,,,,,,,,0,,,,10.01706075,,,,,,14.65507265,,,,
,29501637.83,16.2415819,999.83,0.274818747872793,2.46048607601238E-5,1,2.99776006220938,40.0298881530762,1.99182889087382,10.2899996563792,2.91334723713561,0.530979716875438,25,0.00140913139074928,0.273029936863407,0.00273618159611931,16.2144928,16.268671,999.83,999.83,52.7231885076786,18.5168372833145,41.263397,0,0,0,120,4370,16.3409,999.83,,,,,,,,,,,,,0,,,,10.79600575,,,,,,16.2415819,,,,
,29501733.75,17.84604455,999.83,0.266169841254081,2.83336009361044E-5,1,2.99776006220938,40.0298881530762,1.99177061249776,10.3000001981854,2.82152993254827,0.514451995664088,25,0.00138390437799318,0.264435754585519,0.00266880386755731,17.8207016,17.8713875,999.83,999.83,52.4879183233902,18.5145635010219,41.263397,0,0,0,120,4370,17.9456,999.83,,,,,,,,,,,,,0,,,,11.5201521,,,,,,17.84604455,,,,
,29501829.695,19.4435339,999.83,0.257573256487216,2.56140490341343E-5,1,2.99776006220938,40.0298881530762,1.99179831035955,10.2899996563792,2.73044376450152,0.497980244730445,25,0.00134693838715556,0.255897806547445,0.00259497833863282,19.4172306,19.4698372,999.83,999.83,52.9795626619864,18.5155280482962,41.263397,0,0,0,120,4370,19.55785,999.83,,,,,,,,,,,,,0,,,,12.1101885,,,,,,19.4435339,,,,
,29501928.61,19.99389265,999.83,0.254541542650978,2.52239808126406E-5,1,2.99776006220938,40.0298881530762,1.9917405843399,10.3000001981854,2.69827221470496,0.491956973867575,25,0.00131467739583785,0.252887280245215,0.00255031604531747,19.9933662,19.9944191,999.83,999.83,52.5184018356402,18.511735431005,39.738548,0,0,0,120,4373,20.00035,999.83,,,,,,,,,,,,,0,,,,12.7304459,,,,,,19.99389265,,,,
,29503226.635,2.5134096,999.83,0.274445430195888,2.83187518633438E-5,1,2.99776006220938,40.0298881530762,2.00576613602723,10.2899996563792,2.92899106979114,0.53367101679817,25,0.0013927151063927,0.272663793995297,0.00271810325865555,2.4896474,2.5371718,999.83,999.83,51.2943715745247,18.5447863499545,41.263397,0,0,0,120,4370,2.536,999.83,,,,,,,,,,,,,0,,,,3.35470115,,,,,,2.5134096,,,,
,29503322.55,4.11713025,999.83,0.274016167691345,2.82257921660386E-5,1,2.99776006220938,40.0298881530762,2.0055908849065,10.2899996563792,2.92411250019217,0.533091272222592,25,0.00141857590022588,0.272237245327468,0.00274171030885772,4.0977759,4.1364846,999.83,999.83,51.5272968732554,18.5354599632505,41.263397,0,0,0,120,4370,4.14155,999.83,,,,,,,,,,,,,0,,,,4.41550065,,,,,,4.11713025,,,,
,29503418.5,5.721334,999.83,0.273164613070226,2.62502462546795E-5,1,2.99776006220938,40.0298881530762,2.00553766257993,10.2899996563792,2.91493990046718,0.531478267883186,25,0.00141954053326336,0.27139109354898,0.00273852731353772,5.6975632,5.7451048,999.83,999.83,52.4175717566594,18.541519496109,41.644608,0,0,0,120,4370,5.74285,999.83,,,,,,,,,,,,,0,,,,5.6681781,,,,,,5.721334,,,,
,29503514.415,7.30555175,999.83,0.272434598288401,2.74645336107615E-5,1,2.99776006220938,40.0298881530762,2.00558304656257,10.2899996563792,2.90726607227678,0.529753414041388,25,0.00138620750164553,0.270665705837431,0.00270185785579545,7.28548,7.3256235,999.83,999.83,52.609070743871,18.5275162863755,41.644608,0,0,0,120,4370,7.3353,999.83,,,,,,,,,,,,,0,,,,6.5841532,,,,,,7.30555175,,,,
,29503610.405,8.91097785,999.83,0.275350984291268,2.29214577489583E-5,1,2.99776006220938,40.0298881530762,2.00543931618996,10.2899996563792,2.93816000252256,0.535508885544599,25,0.00141248205241881,0.273562676769368,0.00274213810403936,8.8927956,8.9291601,999.83,999.83,52.6950498809863,18.5249843846313,41.263397,0,0,0,120,4370,8.95465,999.83,,,,,,,,,,,,,0,,,,7.49760605,,,,,,8.91097785,,,,
,29503706.29,10.498703,999.83,0.28467225981593,3.00889047711054E-5,1,2.99776006220938,40.0298881530762,2.00558183274803,10.2899996563792,3.03795957612898,0.552908462381084,25,0.00138865594638262,0.282823164963757,0.00276378163425573,10.4809027,10.5165033,999.83,999.83,51.8344768813132,18.5325779771303,40.500973,0,0,0,120,4370,10.5475,999.83,,,,,,,,,,,,,0,,,,8.4109087,,,,,,10.498703,,,,
,29503802.25,12.1013918,999.83,0.29309300987635,3.38636406144865E-5,1,2.99776006220938,40.0298881530762,2.00563781245693,10.2899996563792,3.12783860438886,0.569619792369754,25,0.00146178238286559,0.291188271903506,0.00287736976282145,12.0735178,12.1292658,999.83,999.83,53.1257271950825,18.5290230529228,42.025818,0,0,0,120,4370,12.17175,999.83,,,,,,,,,,,,,0,,,,9.3405085,,,,,,12.1013918,,,,
,29503898.225,13.6854911,999.83,0.290529683097682,3.01754066406748E-5,1,2.99776006220938,40.0298881530762,2.00567616575018,10.2899996563792,3.10057864339864,0.564371550207064,25,0.00142325333197974,0.288640789782624,0.0028266177858574,13.6655426,13.7054396,999.83,999.83,52.4261696703709,18.5181650985416,41.263397,0,0,0,120,4370,13.76075,999.83,,,,,,,,,,,,,0,,,,10.066844,,,,,,13.6854911,,,,
,29503997.07,15.32412435,999.83,0.280977042890263,2.89976164188222E-5,1,2.99776006220938,40.0298881530762,2.00557210273701,10.2899996563792,2.99844707789255,0.545916964327717,25,0.00138875072352323,0.27914909172341,0.00274588192946589,15.2981186,15.3501301,999.83,999.83,52.6176686575825,18.5279766485904,41.263397,0,0,0,120,4370,15.40915,999.83,,,,,,,,,,,,,0,,,,10.9588633,,,,,,15.32412435,,,,
,29504093.07,16.9179716,999.83,0.271285506610822,2.52821459676504E-5,1,2.99776006220938,40.0298881530762,2.00565588658667,10.2899996563792,2.8951017031012,0.527248633271308,25,0.00135421931613116,0.269519347693163,0.002664441533367,16.8920002,16.943943,999.83,999.83,52.6481521698325,18.531581467055,41.644608,0,0,0,120,4370,17.01915,999.83,,,,,,,,,,,,,0,,,,11.5201521,,,,,,16.9179716,,,,
,29504188.93,18.50941465,999.83,0.262716013775826,2.73796803347402E-5,1,2.99776006220938,40.0298881530762,2.00564422782786,10.2899996563792,2.80356595524477,0.510955632401844,25,0.00134454207330756,0.261005141305373,0.00261426790635404,18.4831562,18.5356731,999.83,999.83,52.3237763343517,18.5223459104844,41.263397,0,0,0,120,4370,18.62165,999.83,,,,,,,,,,,,,0,,,,12.1101885,,,,,,18.50941465,,,,
,29504287.84,20.05440425,999.83,0.254364245730237,1.97876272191356E-5,1,2.99776006220938,40.0298881530762,2.00569522370799,10.3000001981854,2.71458192441053,0.494525586498706,25,0.00127676816772529,0.252711486385574,0.00251204650072658,20.0507641,20.0580444,999.83,999.83,52.5473220908517,18.519307956875,41.263397,0,0,0,120,4373,20.0484,999.83,,,,,,,,,,,,,0,,,,12.7310805,,,,,,20.05440425,,,,
,29504383.79,20.00059605,999.83,0.254627577302792,2.11301569663707E-5,1,2.99776006220938,40.0298881530762,2.00573299297759,10.2899996563792,2.71739290140727,0.495309941774432,25,0.0013030201855948,0.252972829488388,0.00253917879744655,20.000576,20.0006161,999.83,999.83,52.8177655585056,18.5139511335704,41.263397,0,0,0,120,4373,20.0048,999.83,,,,,,,,,,,,,0,,,,13.2494469,,,,,,20.00059605,,,,
,29510106.555,3.17604125,499.989,0.178904234933581,1.70560401475493E-5,1,2.99776006220938,40.0298881530762,1.98094100748346,10.2899996563792,1.8864959578252,0.344424176777693,25,0.000976664483261796,0.17773857173228,0.00183555822587668,3.1504095,3.201673,499.989,499.989,52.7083375658133,18.5444171996795,41.263397,0,0,0,120,4370,3.19015,499.989,,,,,,,,,,,,,0,,,,3.63380955,,,,,,3.17604125,,,,
,29510202.505,4.7792983,499.989,0.178498541602017,1.92155951741318E-5,1,2.99776006220938,40.0298881530762,1.98084758216119,10.3000001981854,1.88222482095277,0.343107304343724,25,0.00092515588926076,0.17733575752559,0.00178242180602331,4.7556224,4.8029742,499.989,499.989,52.616105400544,18.5465093721286,40.500973,0,0,0,120,4370,4.79495,499.989,,,,,,,,,,,,,0,,,,4.7826281,,,,,,4.7792983,,,,
,29510298.415,6.3627756,499.989,0.177924993068705,1.99388966111687E-5,1,2.99776006220938,40.0298881530762,1.98077510501005,10.2899996563792,1.87605688688983,0.342291901564269,25,0.000950540563409859,0.176765701883456,0.00180486682708757,6.3348475,6.3907037,499.989,499.989,51.7907056842362,18.5361707132072,41.644608,0,0,0,120,4370,6.40035,499.989,,,,,,,,,,,,,0,,,,5.69634795,,,,,,6.3627756,,,,
,29510394.375,7.96564265,499.989,0.178501062595621,1.87714109500841E-5,1,2.99776006220938,40.0298881530762,1.98063536150323,10.3000001981854,1.88201746906192,0.343284820050775,25,0.000944933872511656,0.177337847480042,0.00180208039663816,7.9413013,7.989984,499.989,499.989,51.9267090465824,18.5343109051614,40.500973,0,0,0,120,4370,7.98915,499.989,,,,,,,,,,,,,0,,,,6.6502576,,,,,,7.96564265,,,,
,29510490.385,9.5072322,499.989,0.184275806203862,2.5802536151666E-5,1,2.99776006220938,40.0298881530762,1.98067174137985,10.2899996563792,1.94294111310899,0.35435683575197,25,0.000971775704031779,0.18307466468536,0.00185667306816077,9.4794569,9.5350075,499.989,499.989,52.1862097149671,18.5377424816925,40.500973,0,0,0,120,4370,9.5718,499.989,,,,,,,,,,,,,0,,,,7.8028836,,,,,,9.5072322,,,,
,29510586.29,11.09753415,499.989,0.191372671630506,1.62013118662118E-5,1,2.99776006220938,40.0298881530762,1.98078121503535,10.2899996563792,2.01784857149866,0.368146061973558,25,0.00102090203146637,0.190124771583182,0.00193979823892904,11.096446,11.0986223,499.989,499.989,52.0126881836978,18.5291905735823,41.263397,0,0,0,120,4370,11.09995,499.989,,,,,,,,,,,,,0,,,,8.57979015,,,,,,11.09753415,,,,
,29510682.16,12.6554074,499.989,0.192418088916956,1.58874782281512E-5,1,2.99776006220938,40.0298881530762,1.9807849188308,10.2899996563792,2.02886556210346,0.370178519742759,25,0.00102854091982017,0.191162818841989,0.00195243786982315,12.6358919,12.6749229,499.989,499.989,51.9485946451209,18.5249524589133,41.263397,0,0,0,120,4370,12.71325,499.989,,,,,,,,,,,,,0,,,,8.9295759,,,,,,12.6554074,,,,
,29510778.09,14.24461745,499.989,0.188300995375439,2.00294448687026E-5,1,2.99776006220938,40.0298881530762,1.98079886092596,10.2899996563792,1.98553879758197,0.361821014482021,25,0.000965020121876734,0.187072136807934,0.00186941208884027,14.224041,14.2651939,499.989,499.989,52.5004243796979,18.526904763555,41.644608,0,0,0,120,4370,14.3161,499.989,,,,,,,,,,,,,0,,,,9.4342871,,,,,,14.24461745,,,,
,29510873.975,15.84443185,499.989,0.182159010158066,1.71226351639845E-5,1,2.99776006220938,40.0298881530762,1.98071261661691,10.2899996563792,1.9206694641657,0.350099775918117,25,0.000942702331425522,0.180969455682172,0.00181752799934897,15.8171167,15.871747,499.989,499.989,52.504332522294,18.5293792165809,40.882183,0,0,0,120,4370,15.9386,499.989,,,,,,,,,,,,,0,,,,10.26999905,,,,,,15.84443185,,,,
,29510972.945,17.4913759,499.989,0.179265222378077,2.06072237593867E-5,1,2.99776006220938,40.0298881530762,1.98084532591524,10.2899996563792,1.89025624994243,0.344615757668404,25,0.000933616025894638,0.178093339326606,0.00179408714189171,17.4641666,17.5185852,499.989,499.989,52.321431448794,18.5157522578126,41.644608,0,0,0,120,4370,17.59415,499.989,,,,,,,,,,,,,0,,,,11.0688896,,,,,,17.4913759,,,,
,29511068.87,19.08315465,499.989,0.176282778059062,1.92951880840728E-5,1,2.99776006220938,40.0298881530762,1.98079072442416,10.2899996563792,1.85876854273368,0.338889446666201,25,0.000916983128917423,0.175131537169298,0.00176555131585869,19.0603256,19.1059837,499.989,499.989,52.5738974605056,18.5214159561767,40.500973,0,0,0,120,4370,19.18755,499.989,,,,,,,,,,,,,0,,,,11.69422485,,,,,,19.08315465,,,,
,29511167.79,20.0149984,499.989,0.174339134578539,1.45037600051256E-5,1,2.99776006220938,40.0298881530762,1.98082631446664,10.3000001981854,1.83832949155362,0.335130645345436,25,0.000901271503575781,0.173202291067966,0.00174315029365525,20.0149078,20.015089,499.989,499.989,52.6301747138902,18.5174218941299,41.644608,0,0,0,120,4373,20.0206,499.989,,,,,,,,,,,,,0,,,,12.3545799,,,,,,20.0149984,,,,
,29512480.96,2.04484585,499.989,0.184825334276994,2.02614489874581E-5,1,2.99776006220938,40.0298881530762,1.98097599526807,10.2899996563792,1.94903538757989,0.355429760763214,25,0.000971134724461246,0.183621210360997,0.00185869980948051,2.0198913,2.0698004,499.989,499.989,51.9274906751017,18.5374154072861,41.263397,0,0,0,120,4374,2.08455,499.989,,,,,,,,,,,,,0,,,,2.9168512,,,,,,2.04484585,,,,
,29512579.725,3.72368265,499.989,0.184624614555068,1.88655434926482E-5,1,2.99776006220938,40.0298881530762,1.9808977949992,10.2899996563792,1.94686440423178,0.354925003874671,25,0.000960089288165542,0.183421922449974,0.00184675607908978,3.6980863,3.749279,499.989,499.989,51.5312050158516,18.5436726884425,41.263397,0,0,0,120,4370,3.74545,499.989,,,,,,,,,,,,,0,,,,3.9365324,,,,,,3.72368265,,,,
,29512675.75,5.31330565,499.989,0.184053715457138,1.91284645584807E-5,1,2.99776006220938,40.0298881530762,1.98070080768842,10.2899996563792,1.94058147916852,0.354229108543204,25,0.000998383063159821,0.182854503519083,0.00188203992792781,5.2930694,5.3335419,499.989,499.989,52.4730673815248,18.5343708694171,40.882183,0,0,0,120,4370,5.34115,499.989,,,,,,,,,,,,,0,,,,5.2065451,,,,,,5.31330565,,,,
,29512771.62,6.91575095,499.989,0.183324790399456,1.66848929803181E-5,1,2.99776006220938,40.0298881530762,1.98085647948052,10.2899996563792,1.9331096292029,0.352460875353156,25,0.000957317920574609,0.182130359837016,0.00183771449514238,6.8928065,6.9386954,499.989,499.989,52.4597796966979,18.5374744733953,40.882183,0,0,0,120,4370,6.9466,499.989,,,,,,,,,,,,,0,,,,6.2014086,,,,,,6.91575095,,,,
,29512867.535,8.5171037,499.989,0.184402798873822,1.6612441401557E-5,1,2.99776006220938,40.0298881530762,1.9809514618051,10.2899996563792,1.94454158819126,0.354674481828379,25,0.000974808632761702,0.183201030730003,0.00186030263386522,8.4907017,8.5435057,499.989,499.989,52.1924627431209,18.5369260259656,41.263397,0,0,0,120,4370,8.54975,499.989,,,,,,,,,,,,,0,,,,7.2035537,,,,,,8.5171037,,,,
,29512966.505,10.1589589,499.989,0.192519726874951,1.75722092052456E-5,1,2.99776006220938,40.0298881530762,1.9808385323597,10.2899996563792,2.03006624430134,0.370003527183709,25,0.000992915210420018,0.191264788620194,0.00191754341556596,10.1333637,10.1845541,499.989,499.989,52.362076131794,18.5330625689652,40.500973,0,0,0,120,4370,10.19895,499.989,,,,,,,,,,,,,0,,,,8.08063365,,,,,,10.1589589,,,,
,29513062.395,11.74721005,499.989,0.194144407903766,1.81127900465655E-5,1,2.99776006220938,40.0298881530762,1.98083919227512,10.2899996563792,2.04721872445926,0.37298234107519,25,0.000987762363696871,0.192878450099868,0.001920276488035,11.7139225,11.7804976,499.989,499.989,51.9618823299478,18.5301577221351,41.263397,0,0,0,120,4370,11.8029,499.989,,,,,,,,,,,,,0,,,,8.97462605,,,,,,11.74721005,,,,
,29513158.415,13.34741785,499.989,0.191125421483613,1.79485065205057E-5,1,2.99776006220938,40.0298881530762,1.98067650979891,10.2899996563792,2.01520084411235,0.36725336226911,25,0.000981981592896665,0.189878503051861,0.00189992669351268,13.3214598,13.3733759,499.989,499.989,52.9092160952556,18.5237120512077,41.644608,0,0,0,120,4370,13.4115,499.989,,,,,,,,,,,,,0,,,,9.86770725,,,,,,13.34741785,,,,
,29513254.305,14.9319129,499.989,0.185806241826651,1.85169469745035E-5,1,2.99776006220938,40.0298881530762,1.98088282204143,10.2899996563792,1.95931329087027,0.357018996615096,25,0.000950124355789039,0.184593365433707,0.00184254489361828,14.9051428,14.958683,499.989,499.989,52.4324226985248,18.5218344549477,41.644608,0,0,0,120,4370,15.01445,499.989,,,,,,,,,,,,,0,,,,10.7420807,,,,,,14.9319129,,,,
,29513350.18,16.52190015,499.989,0.181123610242149,1.43377504905805E-5,1,2.99776006220938,40.0298881530762,1.98084033583942,10.2899996563792,1.90991507310846,0.347858604424341,25,0.000911564227421428,0.179940601697188,0.0017815816832233,16.4960842,16.5477161,499.989,499.989,52.8052595021979,18.5203588336348,40.500973,0,0,0,120,4370,16.6225,499.989,,,,,,,,,,,,,0,,,,11.3489532,,,,,,16.52190015,,,,
,29513446.14,18.11302375,499.989,0.178266881175621,1.30337099863384E-5,1,2.99776006220938,40.0298881530762,1.9808112828116,10.2899996563792,1.8797606471703,0.342345462090893,25,0.000895121347819747,0.177101798848947,0.00175155733924278,18.0890541,18.1369934,499.989,499.989,52.5965646875633,18.5179911691417,41.263397,0,0,0,120,4370,18.22085,499.989,,,,,,,,,,,,,0,,,,12.0500002,,,,,,18.11302375,,,,
,29513542.025,19.70729065,499.989,0.175124854535452,1.50526597021134E-5,1,2.99776006220938,40.0298881530762,1.98084357191014,10.2899996563792,1.84664126831487,0.336554881798977,25,0.000897679013180856,0.173982518575955,0.00174270257948578,19.6834526,19.7311287,499.989,499.989,52.3081437639671,18.5168819763413,41.263397,0,0,0,120,4370,19.82745,499.989,,,,,,,,,,,,,0,,,,12.3545799,,,,,,19.70729065,,,,
,29513637.95,20.0051985,499.989,0.174512234849363,1.57002461936478E-5,1,2.99776006220938,40.0298881530762,1.98084663747622,10.2899996563792,1.84019638988757,0.335332196754311,25,0.000889466400335913,0.173374297190904,0.00173222468092841,20.0050049,20.0053921,499.989,499.989,52.3222130773132,18.5167450054502,41.644608,0,0,0,120,4373,20.0102,499.989,,,,,,,,,,,,,0,,,,13.05255035,,,,,,20.0051985,,,,
,29519327.765,2.72033,2000.048,0.317963590980793,3.525367643207E-5,1,2.99776006220938,40.0298881530762,1.98109977213495,10.2899996563792,3.35348559575115,0.611436558492853,25,0.0016334512681973,0.31591562477924,0.00318768936234758,2.6959565,2.7447035,2000.048,2000.048,51.7930505697939,18.5382877487848,41.644608,0,0,0,120,4370,2.7435,2000.048,,,,,,,,,,,,,0,,,,3.3883821,,,,,,2.72033,,,,
,29519423.72,4.3260121,2000.048,0.317684024517927,2.99256450408065E-5,1,2.99776006220938,40.0298881530762,1.98098835951118,10.2899996563792,3.35052152571118,0.609934774319383,25,0.00154378955806158,0.31563834223394,0.00309722760474054,4.2959275,4.3560967,2000.048,2000.048,52.1596343453132,18.5404120404822,40.882183,0,0,0,120,4370,4.35125,2000.048,,,,,,,,,,,,,0,,,,4.3713918,,,,,,4.3260121,,,,
,29519519.65,5.9183717,2000.048,0.316997171867454,2.8352265269828E-5,1,2.99776006220938,40.0298881530762,1.98086078454404,10.3000001981854,3.34305782701238,0.608642841737997,25,0.00154658032366868,0.314955744230968,0.00309661906557723,5.8945508,5.9421926,2000.048,2000.048,51.8696501646786,18.5432243911629,42.407028,0,0,0,120,4370,5.94375,2000.048,,,,,,,,,,,,,0,,,,5.3917422,,,,,,5.9183717,,,,
,29519615.565,7.50622225,2000.048,0.316682881932681,3.53524432538172E-5,1,2.99776006220938,40.0298881530762,1.9808293657194,10.2899996563792,3.33959945333219,0.608535591229022,25,0.00159299371599717,0.314642920931405,0.00314118482731605,7.4771056,7.5353389,2000.048,2000.048,51.5265152447362,18.5345388810013,41.644608,0,0,0,120,4370,7.54625,2000.048,,,,,,,,,,,,,0,,,,6.29479955,,,,,,7.50622225,,,,
,29519711.51,9.00389815,2000.048,0.318095720944149,3.17929736575253E-5,1,2.99776006220938,40.0298881530762,1.98080495255394,10.2899996563792,3.35459628120318,0.610438169986152,25,0.00152391037195191,0.316046561318081,0.00307949283508907,8.9834499,9.0243464,2000.048,2000.048,52.6247033142556,18.5322480569362,41.644608,0,0,0,120,4370,9.05915,2000.048,,,,,,,,,,,,,0,,,,7.42307905,,,,,,9.00389815,,,,
,29519807.415,10.7236805,2000.048,0.324033846796685,3.6883851683306E-5,1,2.99776006220938,40.0298881530762,1.98088349634739,10.2899996563792,3.41734888145093,0.621811765632009,25,0.00154817871367728,0.321945698069821,0.00313281983910581,10.673274,10.774087,2000.048,2000.048,52.2846949083902,18.5325920273881,41.263397,0,0,0,120,4370,10.80405,2000.048,,,,,,,,,,,,,0,,,,8.2025299,,,,,,10.7236805,,,,
,29519903.35,12.22677895,2000.048,0.327341642510018,3.49268435171905E-5,1,2.99776006220938,40.0298881530762,1.98082632323572,10.2899996563792,3.45200319750644,0.628851624842258,25,0.00163137708292106,0.32523099884483,0.0032317533725161,12.2016506,12.2519073,2000.048,2000.048,52.8849856111594,18.5241420441005,41.644608,0,0,0,120,4370,12.2852,2000.048,,,,,,,,,,,,,0,,,,8.7092161,,,,,,12.22677895,,,,
,29519999.29,13.8159809,2000.048,0.322948382182674,2.9136897017129E-5,1,2.99776006220938,40.0298881530762,1.98079958807236,10.2899996563792,3.40551637995903,0.62097781543759,25,0.00166406629703116,0.320864735082024,0.00324260255645256,13.7896471,13.8423147,2000.048,2000.048,52.8146390444287,18.5267613399165,41.644608,0,0,0,120,4370,13.9051,2000.048,,,,,,,,,,,,,0,,,,9.247201,,,,,,13.8159809,,,,
,29520095.25,15.3915272,2000.048,0.31466755443177,2.8710789838553E-5,1,2.99776006220938,40.0298881530762,1.98078611682548,10.2899996563792,3.31815936613286,0.605052291896767,25,0.00162172450373518,0.312636132326981,0.00315977074636991,15.3619385,15.4211159,2000.048,2000.048,52.9021814385825,18.526520980458,40.882183,0,0,0,120,4370,15.4998,2000.048,,,,,,,,,,,,,0,,,,9.96677825,,,,,,15.3915272,,,,
,29520191.18,16.991745,2000.048,0.30465055766289,2.87725182332203E-5,1,2.99776006220938,40.0298881530762,1.98088590373627,10.2899996563792,3.21269541443005,0.585681942707064,25,0.0015573011422937,0.302682513299102,0.00304645453916898,16.9682789,17.0152111,2000.048,2000.048,52.5934381734863,18.5190936756641,41.644608,0,0,0,120,4370,17.0963,2000.048,,,,,,,,,,,,,0,,,,10.53011275,,,,,,16.991745,,,,
,29520287.06,18.5793171,2000.048,0.294646023115168,2.88236909088849E-5,1,2.99776006220938,40.0298881530762,1.98077815584636,10.2899996563792,3.10700056330813,0.566573898076952,25,0.00151944915257587,0.292742334170546,0.00296103407171928,18.5557766,18.6028576,2000.048,2000.048,52.6755091680056,18.5181702978708,41.263397,0,0,0,120,4370,18.687,2000.048,,,,,,,,,,,,,0,,,,11.29282995,,,,,,18.5793171,,,,
,29520382.97,20.0738306,2000.048,0.285080821547049,2.35570432814392E-5,1,2.99776006220938,40.0298881530762,1.98086051679188,10.2899996563792,3.00626191937162,0.548421191096317,25,0.0014839043429886,0.283242820314395,0.00288477239645113,20.0646381,20.0830231,2000.048,2000.048,52.4035024433132,18.5176396372079,41.644608,0,0,0,120,4373,20.0513,2000.048,,,,,,,,,,,,,0,,,,12.17098095,,,,,,20.0738306,,,,
,29520478.915,19.99988655,2000.048,0.285589211069252,2.34130051587298E-5,1,2.99776006220938,40.0298881530762,1.98073880840787,10.2899996563792,3.01151276899447,0.54897568880694,25,0.00144979966087204,0.283747948384933,0.00285312820948016,19.9994946,20.0002785,2000.048,2000.048,52.2878214224671,18.5205589474161,41.644608,0,0,0,120,4373,20.0057,2000.048,,,,,,,,,,,,,0,,,,12.3545799,,,,,,19.99988655,,,,
,29521842.925,3.16875815,2000.048,0.319207541057143,3.16327605445976E-5,1,2.99776006220938,40.0298881530762,1.9811166667338,10.2899996563792,3.36681053041532,0.6128317692686,25,0.00154492660207281,0.317152062799537,0.00310585451042128,3.1465831,3.1909332,2000.048,2000.048,51.8547992228132,18.5425311845962,41.644608,0,0,0,120,4370,3.18065,2000.048,,,,,,,,,,,,,0,,,,3.5797191,,,,,,3.16875815,,,,
,29521938.85,4.76342105,2000.048,0.318708299849035,3.65015681500429E-5,1,2.99776006220938,40.0298881530762,1.98072937766823,10.2899996563792,3.36078120327879,0.612507316424658,25,0.00161346449165259,0.316655683942365,0.00317149586687555,4.7451439,4.7816982,2000.048,2000.048,52.8341797574094,18.5314224774902,41.644608,0,0,0,120,4370,4.78365,2000.048,,,,,,,,,,,,,0,,,,4.7353244,,,,,,4.76342105,,,,
,29522034.815,6.3704717,2000.048,0.317929439317336,2.78695323100085E-5,1,2.99776006220938,40.0298881530762,1.98095369319182,10.2899996563792,3.35302920003247,0.610519868523997,25,0.00155678423656824,0.315881906995848,0.00311134453288998,6.3466601,6.3942833,2000.048,2000.048,52.6739459109671,18.5310550143966,41.644608,0,0,0,120,4370,6.3962,2000.048,,,,,,,,,,,,,0,,,,5.7825656,,,,,,6.3704717,,,,
,29522130.725,7.97285605,2000.048,0.317857827595961,3.29255242879452E-5,1,2.99776006220938,40.0298881530762,1.98103052243945,10.2899996563792,3.35232991910221,0.610770684860702,25,0.00159113743938872,0.315810206539292,0.00314512114041172,7.9508681,7.994844,2000.048,2000.048,52.4378940981594,18.5236558483594,41.644608,0,0,0,120,4370,8.00315,2000.048,,,,,,,,,,,,,0,,,,6.81920245,,,,,,7.97285605,,,,
,29522226.635,9.5608592,2000.048,0.320626450700439,3.73838134423405E-5,1,2.99776006220938,40.0298881530762,1.98081531452517,10.3000001981854,3.38124724861017,0.615593650620756,25,0.00156410136114134,0.318560631213791,0.00313187754735051,9.5361233,9.5855951,2000.048,2000.048,51.6468860366978,18.524819683562,40.882183,0,0,0,120,4370,9.60155,2000.048,,,,,,,,,,,,,0,,,,7.84205365,,,,,,9.5608592,,,,
,29522322.58,11.15422485,2000.048,0.326233588904529,3.60345999560206E-5,1,2.99776006220938,40.0298881530762,1.98082174051685,10.2899996563792,3.44047265971756,0.625843882220721,25,0.00154258708241572,0.324131118926125,0.00313808693878893,11.1281185,11.1803312,2000.048,2000.048,52.6723826539286,18.5216081491437,41.644608,0,0,0,120,4370,11.1994,2000.048,,,,,,,,,,,,,0,,,,8.70965055,,,,,,11.15422485,,,,
,29522418.515,12.7484193,2000.048,0.327188625310944,2.90201465795483E-5,1,2.99776006220938,40.0298881530762,1.98076822397148,10.2899996563792,3.45031303257338,0.628402619787162,25,0.00161766282751584,0.325078699309522,0.00321737091430331,12.7235079,12.7733307,2000.048,2000.048,52.5223099782363,18.5185719950048,41.644608,0,0,0,120,4370,12.807,2000.048,,,,,,,,,,,,,0,,,,9.4821196,,,,,,12.7484193,,,,
,29522514.43,14.3319678,2000.048,0.320836717300778,2.44081651271903E-5,1,2.99776006220938,40.0298881530762,1.98087222303807,10.2899996563792,3.38351317239263,0.616094544651133,25,0.0015732368162929,0.31876670651971,0.00314196152695232,14.3005981,14.3633375,2000.048,2000.048,52.4847918093132,18.5109736738603,41.644608,0,0,0,120,4370,14.4106,2000.048,,,,,,,,,,,,,0,,,,10.37310935,,,,,,14.3319678,,,,
,29522610.355,15.92710925,2000.048,0.31176396681592,2.84759444328735E-5,1,2.99776006220938,40.0298881530762,1.98089634302061,10.3000001981854,3.28780461674328,0.59897768180604,25,0.00155724127260365,0.309751089662357,0.00308140924194758,15.9099102,15.9443083,2000.048,2000.048,52.3753638166209,18.5160107736972,40.882183,0,0,0,120,4370,16.016,2000.048,,,,,,,,,,,,,0,,,,11.0688896,,,,,,15.92710925,,,,
,29522706.315,17.5165577,2000.048,0.301652062847143,2.33309922347906E-5,1,2.99776006220938,40.0298881530762,1.9809600802866,10.2899996563792,3.18122383692433,0.579677291157794,25,0.00151809264200676,0.299702459512107,0.00299208483793381,17.4920235,17.5410919,2000.048,2000.048,52.6481521698325,18.5177368817194,41.644608,0,0,0,120,4370,17.62145,2000.048,,,,,,,,,,,,,0,,,,11.69422485,,,,,,17.5165577,,,,
,29522802.23,19.105463,2000.048,0.291585141340478,2.54314580857214E-5,1,2.99776006220938,40.0298881530762,1.98114725233352,10.2899996563792,3.07535743454597,0.56039641903587,25,0.00146427729816254,0.289702678863226,0.00289315700547178,19.0781803,19.1327457,2000.048,2000.048,52.2682807094863,18.5143695297217,41.644608,0,0,0,120,4370,19.2325,2000.048,,,,,,,,,,,,,0,,,,12.3545799,,,,,,19.105463,,,,
,29522898.135,20.011693,2000.048,0.285748161500814,2.60387944783606E-5,1,2.99776006220938,40.0298881530762,1.98105768306733,10.2899996563792,3.01364348640955,0.549433273591539,25,0.00145687027649437,0.283905905259481,0.0028610239385272,20.0110874,20.0122986,2000.048,2000.048,52.4347675840825,18.5103249299194,41.644608,0,0,0,120,4373,20.0198,2000.048,,,,,,,,,,,,,0,,,,12.7310805,,,,,,20.011693,,,,
,29581517.48,2.0442532,200.109,0.0777266544391809,5.67082318797841E-6,1,2.99776006220938,40.0298881530762,1.98123859573502,10.9000001102686,0.819530845137354,0.149266754455054,2.5,0.000392512354012158,0.0772194665972517,0.000764830564435223,2.0195808,2.0689256,200.109,200.109,51.5147908169478,18.5201181788906,40.882183,0,0,0,120,4374,2.0844,200.109,,,,,,,,,,,,,0,,,,3.5089071,,,,,,2.0442532,,,,
,29581616.34,3.72489655,200.109,0.0776517711074053,3.40452007960997E-6,1,2.99776006220938,40.0298881530762,1.98122403699938,10.9099997207522,0.81874338163534,0.149079417552627,2.5,0.000388103165730058,0.0771451232542886,0.000760089197597805,3.6986005,3.7511926,200.109,200.109,51.0411239342939,18.5203373865475,41.644608,0,0,0,120,4370,3.749,200.109,,,,,,,,,,,,,0,,,,5.2850857,,,,,,3.72489655,,,,
,29581715.235,5.36953785,200.109,0.0774479699630068,3.66631677023342E-6,1,2.99776006220938,40.0298881530762,1.98108845139813,10.9000001102686,0.816541319028466,0.148674820761566,2.5,0.000386750556833285,0.076942635508787,0.000757762286464928,5.3419409,5.3971348,200.109,200.109,51.8524543372555,18.5083890966524,41.644608,0,0,0,120,4370,5.39755,200.109,,,,,,,,,,,,,0,,,,6.9213791,,,,,,5.36953785,,,,
,29581811.225,6.97062445,200.109,0.0771997943473912,4.86997080448956E-6,1,2.99776006220938,40.0298881530762,1.98123365341584,10.9000001102686,0.813999165969287,0.148108224604735,2.5,0.000375989256682295,0.0766960615006144,0.000745873391197389,6.9465303,6.9947186,200.109,200.109,52.1166447767555,18.5123530523923,41.644608,0,0,0,120,4370,7.00255,200.109,,,,,,,,,,,,,0,,,,8.2025299,,,,,,6.97062445,,,,
,29581907.095,8.56646825,200.109,0.0776338911683112,4.96006850997322E-6,1,2.99776006220938,40.0298881530762,1.98150324754275,10.9000001102686,0.818677289635039,0.148987502018174,2.5,0.000380681562835487,0.0771272042585307,0.000752627740641268,8.5400381,8.5928984,200.109,200.109,52.6504970553902,18.4991635187088,41.644608,0,0,0,120,4370,8.6043,200.109,,,,,,,,,,,,,0,,,,9.2945495,,,,,,8.56646825,,,,
,29582006.055,10.20934675,200.109,0.0803079933829829,3.99687428537738E-6,1,2.99776006220938,40.0298881530762,1.9812209815406,10.9000001102686,0.846765122652465,0.154063781890058,2.5,0.000390553297372733,0.079783704401557,0.000775330648012445,10.1854868,10.2332067,200.109,200.109,52.3198681917555,18.5036778559412,42.025818,0,0,0,120,4370,10.25245,200.109,,,,,,,,,,,,,0,,,,10.424922,,,,,,10.20934675,,,,
,29582101.97,11.78971575,200.109,0.0808051945838208,5.39648155503956E-6,1,2.99776006220938,40.0298881530762,1.98145184007421,10.9000001102686,0.852108568991976,0.154990299235756,2.5,0.000388777180554156,0.0802774737211928,0.000775962047000009,11.7649965,11.814435,200.109,200.109,52.0838163789478,18.4944267041454,40.882183,0,0,0,120,4370,11.85815,200.109,,,,,,,,,,,,,0,,,,11.4056396,,,,,,11.78971575,,,,
,29582197.96,13.3996906,200.109,0.0806264937297257,3.28848485910775E-6,1,2.99776006220938,40.0298881530762,1.98137210350954,10.9000001102686,0.850177103681409,0.154705809288117,2.5,0.000394051842550951,0.0800996542146969,0.000780338033351551,13.3734903,13.4258909,200.109,200.109,51.9736067577363,18.4909887376123,41.644608,0,0,0,120,4370,13.46665,200.109,,,,,,,,,,,,,0,,,,12.2323842,,,,,,13.3996906,,,,
,29582293.805,14.98209765,200.109,0.0802823902309081,4.44186170027959E-6,1,2.99776006220938,40.0298881530762,1.98148447024643,10.9000001102686,0.846598069489622,0.154016871168169,2.5,0.000388912688781613,0.0797575198629713,0.000773569899033917,14.9579649,15.0062304,200.109,200.109,52.2972009646978,18.4923791752967,41.644608,0,0,0,120,4370,15.06905,200.109,,,,,,,,,,,,,0,,,,13.18359665,,,,,,14.98209765,,,,
,29582389.79,16.57736585,200.109,0.0795994163550525,1.9907917479062E-6,1,2.99776006220938,40.0298881530762,1.98143478812198,10.9000001102686,0.839376631667729,0.15267674915752,2.5,0.00038318384937986,0.0790786820814157,0.00076458119781431,16.5530643,16.6016674,200.109,200.109,52.473849010044,18.4935393564596,41.644608,0,0,0,120,4370,16.67545,200.109,,,,,,,,,,,,,0,,,,13.8588314,,,,,,16.57736585,,,,
,29582485.685,18.16779805,200.109,0.079353309246479,5.1443441516169E-6,1,2.99776006220938,40.0298881530762,1.98157502158657,10.9000001102686,0.836832423214055,0.152229433036478,2.5,0.000383324358885706,0.0788338746554197,0.00076362392959169,18.1428738,18.1927223,200.109,200.109,52.0330105251978,18.496132110879,41.644608,0,0,0,120,4370,18.2766,200.109,,,,,,,,,,,,,0,,,,14.64214945,,,,,,18.16779805,,,,
,29582581.585,19.76111125,200.109,0.0789530874065018,3.31500555711602E-6,1,2.99776006220938,40.0298881530762,1.98150632538079,10.9000001102686,0.832590006744888,0.151490384956998,2.5,0.000382623633763405,0.078437341888451,0.000762764783740407,19.7372513,19.7849712,200.109,200.109,52.6340828564863,18.4947793276647,41.644608,0,0,0,120,4370,19.878,200.109,,,,,,,,,,,,,0,,,,15.4685831,,,,,,19.76111125,,,,
,29582677.515,20.000967,200.109,0.0788740938030381,4.5284033234466E-6,1,2.99776006220938,40.0298881530762,1.98150167732712,10.9000001102686,0.831763574807224,0.151297641964484,2.5,0.000378140940299463,0.0783589957008435,0.000758138534846028,20.0007915,20.0011425,200.109,200.109,53.0342766583325,18.496528966486,41.644608,0,0,0,120,4373,20.0056,200.109,,,,,,,,,,,,,0,,,,15.7019262,,,,,,20.000967,,,,
,29583981.555,2.76911235,200.109,0.0804460235118689,5.69009527285594E-6,1,2.99776006220938,40.0298881530762,1.98136173534063,10.9000001102686,0.848253952654234,0.154498849715475,2.5,0.000406296260382165,0.0799211115279348,0.000791640383929076,2.7434635,2.7947612,200.109,200.109,51.945468131044,18.5240841485597,41.644608,0,0,0,120,4370,2.79575,200.109,,,,,,,,,,,,,0,,,,3.3047652,,,,,,2.76911235,,,,
,29584077.475,4.3680785,200.109,0.080376048239778,4.62426325743624E-6,1,2.99776006220938,40.0298881530762,1.98131866677178,10.9000001102686,0.847502203042657,0.154340521790593,2.5,0.000403977842770997,0.0798516133386092,0.000788999660765164,4.3413997,4.3947573,200.109,200.109,52.1713587731017,18.529535109309,40.882183,0,0,0,120,4370,4.3922,200.109,,,,,,,,,,,,,0,,,,4.664721,,,,,,4.3680785,,,,
,29584173.47,5.9797232,200.109,0.0801245971256982,5.94715135705761E-6,1,2.99776006220938,40.0298881530762,1.98127096408653,10.9000001102686,0.84484307332841,0.153785392040616,2.5,0.000396208266603104,0.0796017973992302,0.000780067499097615,5.9523945,6.0070519,200.109,200.109,52.2471767394671,18.5285976704576,41.644608,0,0,0,120,4370,6.01235,200.109,,,,,,,,,,,,,0,,,,5.95848965,,,,,,5.9797232,,,,
,29584272.355,7.6141145,200.109,0.0798834903985501,3.88885399319811E-6,1,2.99776006220938,40.0298881530762,1.98134858823759,10.9000001102686,0.842296612662799,0.153525931900473,2.5,0.000413748807467234,0.0793620875300374,0.000796330306633457,7.5888953,7.6393337,200.109,200.109,52.3933412725632,18.5068178651753,40.882183,0,0,0,120,4370,7.64935,200.109,,,,,,,,,,,,,0,,,,7.1323054,,,,,,7.6141145,,,,
,29584368.29,9.20943785,200.109,0.0806963534778598,4.04771811930784E-6,1,2.99776006220938,40.0298881530762,1.98124455660785,10.9000001102686,0.850844376956887,0.154960332540525,2.5,0.000406612217966433,0.0801695674638696,0.000793159184945044,9.1838856,9.2349901,200.109,200.109,51.7813261420055,18.5040204422555,41.644608,0,0,0,120,4370,9.25365,200.109,,,,,,,,,,,,,0,,,,8.2848825,,,,,,9.20943785,,,,
,29584464.255,10.8080053,200.109,0.0820948071780876,4.65407922799147E-6,1,2.99776006220938,40.0298881530762,1.9813161007594,10.9000001102686,0.865614816573373,0.15766569945337,2.5,0.000415062808816131,0.0815587028340736,0.000808297627318085,10.7851915,10.8308191,200.109,200.109,52.2932928221017,18.4951889659588,40.882183,0,0,0,120,4370,10.85745,200.109,,,,,,,,,,,,,0,,,,9.11068965,,,,,,10.8080053,,,,
,29584560.165,12.3971162,200.109,0.0814562658195344,4.05078421245346E-6,1,2.99776006220938,40.0298881530762,1.98142038834137,10.9000001102686,0.858933631462869,0.156386652324378,2.5,0.000406132640787705,0.0809241323007101,0.000796343706726757,12.3664246,12.4278078,200.109,200.109,52.7013029091402,18.4986620443628,40.882183,0,0,0,120,4370,12.4587,200.109,,,,,,,,,,,,,0,,,,10.1171265,,,,,,12.3971162,,,,
,29584656.085,13.99027635,200.109,0.0809293119087993,4.41803112518762E-6,1,2.99776006220938,40.0298881530762,1.98133356803474,10.9000001102686,0.853356877163284,0.155262678044516,2.5,0.000393535082650824,0.0804003972309117,0.000781284062325596,13.9675236,14.0130291,200.109,200.109,52.3886515014479,18.5064325064875,41.644608,0,0,0,120,4370,14.0572,200.109,,,,,,,,,,,,,0,,,,10.9588633,,,,,,13.99027635,,,,
,29584752.04,15.5935349,200.109,0.0797303680141448,3.40356895605358E-6,1,2.99776006220938,40.0298881530762,1.9813366884061,10.9000001102686,0.84072481670909,0.152892938779038,2.5,0.000381148726049337,0.0792090057124541,0.000763192978940226,15.5692987,15.6177711,200.109,200.109,52.4504001544671,18.5062350819709,42.025818,0,0,0,120,4370,15.6745,200.109,,,,,,,,,,,,,0,,,,11.63639405,,,,,,15.5935349,,,,
,29584847.96,17.1802559,200.109,0.0795177293539611,4.47557420589934E-6,1,2.99776006220938,40.0298881530762,1.98141982646322,10.9000001102686,0.838497460230803,0.152565095359807,2.5,0.000387436123773967,0.0789971850285184,0.000768194825103694,17.1500912,17.2104206,200.109,200.109,52.3331558765825,18.49676642153,42.025818,0,0,0,120,4370,17.2774,200.109,,,,,,,,,,,,,0,,,,12.41659925,,,,,,17.1802559,,,,
,29584949.92,18.88113785,200.109,0.0791929022756199,4.92471981546119E-6,1,2.99776006220938,40.0298881530762,1.98140259380962,10.9000001102686,0.835067671985058,0.151947209781158,2.5,0.000385531069227622,0.0786748089702226,0.000765622325201268,18.8578472,18.9044285,200.109,200.109,52.7161538510056,18.4961243542232,40.882183,0,0,0,120,4370,18.97945,200.109,,,,,,,,,,,,,0,,,,13.1184006,,,,,,18.88113785,,,,
,29590768.555,2.96326745,100.16,0.0378067357206676,2.30351154867009E-6,1,2.99776006220938,40.0298881530762,1.99225942964054,10.9000001102686,0.400747403418726,0.0730170643151825,2.5,0.000193455911942996,0.0375599150129217,0.000374394214380676,2.9383886,2.9881463,100.16,100.16,52.0916326641401,18.5284779394364,41.644608,0,0,0,120,4370,2.98495,100.16,,,,,,,,,,,,,0,,,,3.50908195,,,,,,2.96326745,,,,
,29590864.485,4.56489755,100.16,0.037785431850665,2.14986657746338E-6,1,2.99776006220938,40.0298881530762,1.99228473475042,10.9000001102686,0.400534892251632,0.0729293339396083,2.5,0.000188871735302408,0.037538774236174,0.000369737209860693,4.5366206,4.5931745,100.16,100.16,52.9772177764287,18.5328712781796,41.263397,0,0,0,120,4370,4.5883,100.16,,,,,,,,,,,,,0,,,,4.664721,,,,,,4.56489755,,,,
,29590960.425,6.17118075,100.16,0.0376905793316686,2.29670317122947E-6,1,2.99776006220938,40.0298881530762,1.99216112107038,10.9000001102686,0.399500966514407,0.0727671358981142,2.5,0.000190777267461449,0.0374445094414965,0.000371173041746914,6.1513863,6.1909752,100.16,100.16,52.656750083544,18.527248736878,42.025818,0,0,0,120,4370,6.1969,100.16,,,,,,,,,,,,,0,,,,5.63972545,,,,,,6.17118075,,,,
,29591057.85,7.77915765,100.16,0.0376638268412821,2.84956864993485E-6,1,2.99776006220938,40.0298881530762,1.99202621740369,10.9000001102686,0.399185607357472,0.072741227842539,2.5,0.000193521549080766,0.0374178753772005,0.000373770126346174,7.7284374,7.8298779,100.16,100.16,52.1549445741978,18.5216259899123,40.882183,0,0,0,120,4370,7.81825,100.16,,,,,,,,,,,,,0,,,,6.5514295,,,,,,7.77915765,,,,
,29591155.275,9.4077215,100.16,0.038265970895162,2.20989772110469E-6,1,2.99776006220938,40.0298881530762,1.99227838155023,10.9099997207522,0.405637986246989,0.0737891386328304,2.5,0.000184939710562188,0.0380160769797269,0.000368145291866064,9.3839979,9.4314451,100.16,100.16,52.0072167840632,18.529953099295,41.263397,0,0,0,120,4370,9.4458,100.16,,,,,,,,,,,,,0,,,,7.46071485,,,,,,9.4077215,,,,
,29591251.26,11.0030227,100.16,0.0391993777480548,2.04726895257861E-6,1,2.99776006220938,40.0298881530762,1.99207910142878,10.9000001102686,0.415480323414502,0.0756460116286728,2.5,0.000195520751604841,0.0389432692934079,0.000383154814535954,10.9775038,11.0285416,100.16,100.16,52.6590949691017,18.5087412570829,41.644608,0,0,0,120,4370,11.05195,100.16,,,,,,,,,,,,,0,,,,8.368062,,,,,,11.0030227,,,,
,29591347.135,12.61461545,100.16,0.0394438821587174,2.19445225188754E-6,1,2.99776006220938,40.0298881530762,1.99223011367668,10.9000001102686,0.418094915013564,0.0761578701433449,2.5,0.000200011503694172,0.0391860462713592,0.000388793499126967,12.5903311,12.6388998,100.16,100.16,52.4761938956017,18.5090896419828,41.644608,0,0,0,120,4370,12.66965,100.16,,,,,,,,,,,,,0,,,,9.1557398,,,,,,12.61461545,,,,
,29591443.095,14.1824479,100.16,0.0395575162257431,2.23679009018806E-6,1,2.99776006220938,40.0298881530762,1.99207135582014,10.9000001102686,0.419275955119548,0.0763144585058183,2.5,0.000195241427771303,0.0392988297657224,0.000384600796149148,14.1643238,14.200572,100.16,100.16,52.6825438246787,18.5048783723535,41.644608,0,0,0,120,4370,14.25735,100.16,,,,,,,,,,,,,0,,,,10.066844,,,,,,14.1824479,,,,
,29591538.98,15.77423525,100.16,0.0394576725621066,2.22945993376296E-6,1,2.99776006220938,40.0298881530762,1.9922368398954,10.9000001102686,0.418254984910471,0.0760957750605216,2.5,0.000191748715838939,0.0391994961289928,0.000380648157413376,15.7444859,15.8039846,100.16,100.16,52.5520118619671,18.5047099401742,41.644608,0,0,0,120,4370,15.8609,100.16,,,,,,,,,,,,,0,,,,10.5295868,,,,,,15.77423525,,,,
,29591634.94,17.3693781,100.16,0.0394718224876211,1.38677619893579E-6,1,2.99776006220938,40.0298881530762,1.99221525843689,10.9099997207522,0.418383104243005,0.0762047883272142,2.5,0.00019974472489433,0.0392132503050136,0.000388557457596011,17.3376045,17.4011517,100.16,100.16,52.731004792871,18.4981769547568,41.644608,0,0,0,120,4370,17.4653,100.16,,,,,,,,,,,,,0,,,,11.3500862,,,,,,17.3693781,,,,
,29591733.9,19.0189457,100.16,0.0394367667198079,2.40520130961293E-6,1,2.99776006220938,40.0298881530762,1.99211883638018,10.9000001102686,0.418007493345545,0.0760607988831223,2.5,0.00019215223017639,0.0391786845798612,0.000381358065157706,18.994936,19.0429554,100.16,100.16,52.4785387811594,18.5053396680059,41.644608,0,0,0,120,4370,19.12095,100.16,,,,,,,,,,,,,0,,,,12.0500002,,,,,,19.0189457,,,,
,29591829.88,19.99580765,100.16,0.0393862331178883,1.67236864594447E-6,1,2.99776006220938,40.0298881530762,1.99218386728068,10.9000001102686,0.417485350824245,0.0759887600863505,2.5,0.000193368948470642,0.0391288788938931,0.000382957355742191,19.9907017,20.0009136,100.16,100.16,52.3386272762171,18.4938894556482,41.263397,0,0,0,120,4373,20.0199,100.16,,,,,,,,,,,,,0,,,,12.4786186,,,,,,19.99580765,,,,
,29593191.16,2.0036917,100.16,0.0389564900966922,3.03549811493755E-6,1,2.99776006220938,40.0298881530762,1.98130513315377,10.9000001102686,0.410767452250853,0.074770186512855,2.5,0.000192679087442651,0.0387021827040681,0.000379163162647177,2.0036917,2.0036917,100.16,100.16,51.6265636951978,18.5324567835245,40.882183,0,0,0,120,4370,2.0287,100.16,,,,,,,,,,,,,0,,,,2.8734326,,,,,,2.0036917,,,,
,29593283.735,3.57001865,100.16,0.0389468223946523,2.22792222375241E-6,1,2.99776006220938,40.0298881530762,1.98131382892175,10.9000001102686,0.410667879378957,0.0747493649194369,2.5,0.000192383710023746,0.0386925956083536,0.00037882327588404,3.5456045,3.5944328,100.16,100.16,51.9782965288517,18.5369482551468,41.644608,0,0,0,120,4370,3.59555,100.16,,,,,,,,,,,,,0,,,,3.8970139,,,,,,3.57001865,,,,
,29593379.67,5.1643679,100.16,0.0388989906126568,1.92693679702265E-6,1,2.99776006220938,40.0298881530762,1.98111816449896,10.9000001102686,0.410119440415753,0.0746794430502598,2.5,0.000194892888432688,0.0386450566666282,0.000381085565822809,5.1394329,5.1893029,100.16,100.16,52.128369204544,18.5300369263828,40.882183,0,0,0,120,4370,5.1966,100.16,,,,,,,,,,,,,0,,,,5.0275841,,,,,,5.1643679,,,,
,29593475.56,6.7605343,100.16,0.038767155427409,2.45592452910835E-6,1,2.99776006220938,40.0298881530762,1.98124694339542,10.9000001102686,0.408772830271855,0.0743283532343022,2.5,0.000184512242662975,0.0385141000520212,0.000370136822809485,6.73594,6.7851286,100.16,100.16,52.9412628645441,18.5364714780533,41.263397,0,0,0,120,4370,6.7946,100.16,,,,,,,,,,,,,0,,,,6.01831245,,,,,,6.7605343,,,,
,29593571.52,8.3583007,100.16,0.0387686478666164,2.6529724121887E-6,1,2.99776006220938,40.0298881530762,1.98118680630453,10.9000001102686,0.408768413434127,0.0743724232901277,2.5,0.000188639039996611,0.0385155112956955,0.000374243467741152,8.3353424,8.381259,100.16,100.16,52.3136151636017,18.5262609799958,42.025818,0,0,0,120,4370,8.3985,100.16,,,,,,,,,,,,,0,,,,7.09650325,,,,,,8.3583007,,,,
,29593670.435,10.0041065,100.16,0.0398932053949937,2.57334023572493E-6,1,2.99776006220938,40.0298881530762,1.98110736443776,10.9000001102686,0.420599782908301,0.0765757750057719,2.5,0.0001987674989266,0.0396326247260536,0.000389724659826871,9.978899,10.029314,100.16,100.16,52.7528903914094,18.5138886942328,40.882183,0,0,0,120,4370,10.0493,100.16,,,,,,,,,,,,,0,,,,8.08063365,,,,,,10.0041065,,,,
,29593766.35,11.60099315,100.16,0.0399611438980957,2.24300048656517E-6,1,2.99776006220938,40.0298881530762,1.98133969984156,10.9099997207522,0.421376711411988,0.0766340152972177,2.5,0.000191467547075534,0.0397000560961941,0.000382798654565988,11.5761642,11.6258221,100.16,100.16,51.8258789676016,18.5065712755042,40.882183,0,0,0,120,4370,11.6528,100.16,,,,,,,,,,,,,0,,,,8.9741783,,,,,,11.60099315,,,,
,29593862.275,13.1961513,100.16,0.0397848888192892,2.15258065413571E-6,1,2.99776006220938,40.0298881530762,1.98136339343796,10.9000001102686,0.419518556755701,0.0763142962985601,2.5,0.000192295255145943,0.0395248221022492,0.0003827703934516,13.1699429,13.2223597,100.16,100.16,52.7911901888517,18.5112349850602,42.025818,0,0,0,120,4370,13.26265,100.16,,,,,,,,,,,,,0,,,,9.7213078,,,,,,13.1961513,,,,
,29593958.24,14.79110195,100.16,0.039649123616929,2.58815822070106E-6,1,2.99776006220938,40.0298881530762,1.98139169125583,10.9000001102686,0.418093954414693,0.0760388239385764,2.5,0.000190140532656887,0.0393898070273872,0.000379974044129195,14.765893,14.8163109,100.16,100.16,51.911858104717,18.5027001184759,40.882183,0,0,0,120,4370,14.86515,100.16,,,,,,,,,,,,,0,,,,10.5295868,,,,,,14.79110195,,,,
,29594054.185,16.38281535,100.16,0.0394431291206623,2.01077594430304E-6,1,2.99776006220938,40.0298881530762,1.98127697003164,10.9000001102686,0.415900512927007,0.0756187719428657,2.5,0.00018721280859114,0.0391850033653671,0.000376071103545739,16.3580093,16.4076214,100.16,100.16,51.854017594294,18.5103612836369,42.025818,0,0,0,120,4370,16.4674,100.16,,,,,,,,,,,,,0,,,,11.1805782,,,,,,16.38281535,,,,
,29594150.135,17.97085095,100.16,0.039436313413687,1.22868534874624E-6,1,2.99776006220938,40.0298881530762,1.98130286323813,10.9000001102686,0.415830676251002,0.0756125952444411,2.5,0.000187788147209121,0.0391780343280277,0.000376598993287736,17.9397526,18.0019493,100.16,100.16,52.9670566056787,18.5000208672423,42.025818,0,0,0,120,4370,18.07285,100.16,,,,,,,,,,,,,0,,,,11.99040985,,,,,,17.97085095,,,,
,29594246.005,19.56021975,100.16,0.039389041628727,1.63038847545995E-6,1,2.99776006220938,40.0298881530762,1.98130587692649,10.9000001102686,0.415334365694999,0.0755418368076378,2.5,0.000188567254608814,0.0391315227212489,0.000377929404388943,19.5432014,19.5772381,100.16,100.16,52.3558231036401,18.5032470318238,42.025818,0,0,0,120,4370,19.67855,100.16,,,,,,,,,,,,,0,,,,12.6039028,,,,,,19.56021975,,,,
,29594342.02,19.99911305,100.16,0.0393647528984759,1.62487225330345E-6,1,2.99776006220938,40.0298881530762,1.98142761895873,10.9000001102686,0.415107247493202,0.0754844410235805,2.5,0.000186710200785233,0.0391075643209522,0.000376230825499181,19.9969978,20.0012283,100.16,100.16,52.074436836717,18.5041208877567,41.644608,0,0,0,120,4373,20.0116,100.16,,,,,,,,,,,,,0,,,,12.9873543,,,,,,19.99911305,,,,
,29594398.95,19.9977894,100.16,0.039365730357913,1.71998649687834E-6,1,2.99776006220938,40.0298881530762,1.98132360745849,10.9000001102686,0.415094822440627,0.0754924107150432,2.5,0.000187660179852011,0.0391085256397004,0.000377173052248398,19.9977055,19.9978733,100.16,100.16,52.6536235694671,18.5002927180111,42.025818,0,0,0,120,4369,20.00415,100.16,,,,,,,,,,,,,0,,,,13.05255035,,,,,,19.9977894,,,,